File: data/DSC/500907_2.csv
[Measurement conditions]
Sample identification,500907_2
Comment,
Anode material,Cu
K-Alpha1 wavelength,1.5405980
K-Alpha2 wavelength,1.5444260
Ratio K-Alpha2/K-Alpha1,0.500
Divergence slit,Fixed,0.38mm
Monochromator used,NO
Generator voltage, 40
Tube current, 15
File date and time,26/Feb/2025 11:13
Unit cell,
h k l, 0 0 0
Scan axis,Gonio
Scan range,5.002000000,49.999928040
Scan step size,0.0108664
No. of points, 4141
Scan type,CONTINUOUS
Time per step,23.970
[Scan points]
Angle, TimePerStep, Intensity, ESD
5.007433220, 23.970, 1443.0, 37.9868
5.050898980, 23.970, 1420.0, 37.6829
5.094364740, 23.970, 1479.0, 38.4578
5.137830500, 23.970, 1493.0, 38.6394
5.181296260, 23.970, 1473.0, 38.3797
5.224762020, 23.970, 1461.0, 38.2230
5.268227780, 23.970, 1480.0, 38.4708
5.311693540, 23.970, 1515.0, 38.9230
5.355159300, 23.970, 1475.0, 38.4057
5.398625060, 23.970, 1590.0, 39.8748
5.442090820, 23.970, 1571.0, 39.6358
5.485556580, 23.970, 1545.0, 39.3065
5.529022340, 23.970, 1550.0, 39.3700
5.572488100, 23.970, 1555.0, 39.4335
5.615953860, 23.970, 1623.0, 40.2865
5.659419620, 23.970, 1600.0, 40.0000
5.702885380, 23.970, 1686.0, 41.0609
5.746351140, 23.970, 1652.0, 40.6448
5.789816900, 23.970, 1782.0, 42.2137
5.833282660, 23.970, 1718.0, 41.4488
5.876748420, 23.970, 1620.0, 40.2492
5.920214180, 23.970, 1738.0, 41.6893
5.963679940, 23.970, 1657.0, 40.7063
6.007145700, 23.970, 1648.0, 40.5956
6.050611460, 23.970, 1654.0, 40.6694
6.094077220, 23.970, 1758.0, 41.9285
6.137542980, 23.970, 1761.0, 41.9643
6.181008740, 23.970, 1816.0, 42.6146
6.224474500, 23.970, 1755.0, 41.8927
6.267940260, 23.970, 1745.0, 41.7732
6.311406020, 23.970, 1740.0, 41.7133
6.354871780, 23.970, 1779.0, 42.1782
6.398337540, 23.970, 1776.0, 42.1426
6.441803300, 23.970, 1800.0, 42.4264
6.485269060, 23.970, 1765.0, 42.0119
6.528734820, 23.970, 1772.0, 42.0951
6.572200580, 23.970, 1824.0, 42.7083
6.615666340, 23.970, 1898.0, 43.5660
6.659132100, 23.970, 1855.0, 43.0697
6.702597860, 23.970, 1852.0, 43.0349
6.746063620, 23.970, 1822.0, 42.6849
6.789529380, 23.970, 1969.0, 44.3734
6.832995140, 23.970, 1915.0, 43.7607
6.876460900, 23.970, 1856.0, 43.0813
6.919926660, 23.970, 1932.0, 43.9545
6.963392420, 23.970, 1846.0, 42.9651
7.006858180, 23.970, 1834.0, 42.8252
7.050323940, 23.970, 1820.0, 42.6615
7.093789700, 23.970, 1935.0, 43.9886
7.137255460, 23.970, 1931.0, 43.9431
7.180721220, 23.970, 1854.0, 43.0581
7.224186980, 23.970, 1950.0, 44.1588
7.267652740, 23.970, 1917.0, 43.7836
7.311118500, 23.970, 1879.0, 43.3474
7.354584260, 23.970, 1993.0, 44.6430
7.398050020, 23.970, 2014.0, 44.8776
7.441515780, 23.970, 1923.0, 43.8520
7.484981540, 23.970, 1929.0, 43.9204
7.528447300, 23.970, 1907.0, 43.6692
7.571913060, 23.970, 1985.0, 44.5533
7.615378820, 23.970, 1970.0, 44.3847
7.658844580, 23.970, 2087.0, 45.6837
7.702310340, 23.970, 2056.0, 45.3431
7.745776100, 23.970, 2082.0, 45.6289
7.789241860, 23.970, 2049.0, 45.2659
7.832707620, 23.970, 1913.0, 43.7379
7.876173380, 23.970, 2093.0, 45.7493
7.919639140, 23.970, 2090.0, 45.7165
7.963104900, 23.970, 2020.0, 44.9444
8.006570660, 23.970, 2055.0, 45.3321
8.050036420, 23.970, 1966.0, 44.3396
8.093502180, 23.970, 2123.0, 46.0760
8.136967940, 23.970, 2026.0, 45.0111
8.180433700, 23.970, 1948.0, 44.1362
8.223899460, 23.970, 1994.0, 44.6542
8.267365220, 23.970, 2105.0, 45.8803
8.310830980, 23.970, 1957.0, 44.2380
8.354296740, 23.970, 2082.0, 45.6289
8.397762500, 23.970, 2061.0, 45.3982
8.441228260, 23.970, 2120.0, 46.0435
8.484694020, 23.970, 1972.0, 44.4072
8.528159780, 23.970, 2062.0, 45.4093
8.571625540, 23.970, 2012.0, 44.8553
8.615091300, 23.970, 2085.0, 45.6618
8.658557060, 23.970, 2098.0, 45.8039
8.702022820, 23.970, 2095.0, 45.7712
8.745488580, 23.970, 2036.0, 45.1221
8.788954340, 23.970, 2058.0, 45.3652
8.832420100, 23.970, 2128.0, 46.1303
8.875885860, 23.970, 2058.0, 45.3652
8.919351620, 23.970, 2140.0, 46.2601
8.962817380, 23.970, 1980.0, 44.4972
9.006283140, 23.970, 2001.0, 44.7325
9.049748900, 23.970, 2124.0, 46.0869
9.093214660, 23.970, 2028.0, 45.0333
9.136680420, 23.970, 2129.0, 46.1411
9.180146180, 23.970, 2131.0, 46.1628
9.223611940, 23.970, 2173.0, 46.6154
9.267077700, 23.970, 2146.0, 46.3249
9.310543460, 23.970, 2118.0, 46.0217
9.354009220, 23.970, 2107.0, 45.9021
9.397474980, 23.970, 2073.0, 45.5302
9.440940740, 23.970, 2211.0, 47.0213
9.484406500, 23.970, 2146.0, 46.3249
9.527872260, 23.970, 2038.0, 45.1442
9.571338020, 23.970, 2067.0, 45.4643
9.614803780, 23.970, 2096.0, 45.7821
9.658269540, 23.970, 2124.0, 46.0869
9.701735300, 23.970, 2093.0, 45.7493
9.745201060, 23.970, 1994.0, 44.6542
9.788666820, 23.970, 2144.0, 46.3033
9.832132580, 23.970, 2030.0, 45.0555
9.875598340, 23.970, 2112.0, 45.9565
9.919064100, 23.970, 2018.0, 44.9222
9.962529860, 23.970, 2065.0, 45.4423
10.005995620, 23.970, 2057.0, 45.3542
10.049461380, 23.970, 2158.0, 46.4543
10.092927140, 23.970, 2071.0, 45.5082
10.136392900, 23.970, 2143.0, 46.2925
10.179858660, 23.970, 2126.0, 46.1086
10.223324420, 23.970, 2046.0, 45.2327
10.266790180, 23.970, 2145.0, 46.3141
10.310255940, 23.970, 2131.0, 46.1628
10.353721700, 23.970, 2176.0, 46.6476
10.397187460, 23.970, 2078.0, 45.5851
10.440653220, 23.970, 2132.0, 46.1736
10.484118980, 23.970, 2082.0, 45.6289
10.527584740, 23.970, 2199.0, 46.8935
10.571050500, 23.970, 2136.0, 46.2169
10.614516260, 23.970, 2209.0, 47.0000
10.657982020, 23.970, 2168.0, 46.5618
10.701447780, 23.970, 2193.0, 46.8295
10.744913540, 23.970, 2258.0, 47.5184
10.788379300, 23.970, 2225.0, 47.1699
10.831845060, 23.970, 2246.0, 47.3920
10.875310820, 23.970, 2148.0, 46.3465
10.918776580, 23.970, 2170.0, 46.5833
10.962242340, 23.970, 2274.0, 47.6865
11.005708100, 23.970, 2241.0, 47.3392
11.049173860, 23.970, 2134.0, 46.1952
11.092639620, 23.970, 2298.0, 47.9375
11.136105380, 23.970, 2256.0, 47.4974
11.179571140, 23.970, 2215.0, 47.0638
11.223036900, 23.970, 2185.0, 46.7440
11.266502660, 23.970, 2338.0, 48.3529
11.309968420, 23.970, 2396.0, 48.9490
11.353434180, 23.970, 2254.0, 47.4763
11.396899940, 23.970, 2267.0, 47.6130
11.440365700, 23.970, 2299.0, 47.9479
11.483831460, 23.970, 2349.0, 48.4665
11.527297220, 23.970, 2286.0, 47.8121
11.570762980, 23.970, 2349.0, 48.4665
11.614228740, 23.970, 2356.0, 48.5386
11.657694500, 23.970, 2374.0, 48.7237
11.701160260, 23.970, 2337.0, 48.3425
11.744626020, 23.970, 2305.0, 48.0104
11.788091780, 23.970, 2367.0, 48.6518
11.831557540, 23.970, 2414.0, 49.1325
11.875023300, 23.970, 2435.0, 49.3457
11.918489060, 23.970, 2539.0, 50.3885
11.961954820, 23.970, 2450.0, 49.4975
12.005420580, 23.970, 2560.0, 50.5964
12.048886340, 23.970, 2477.0, 49.7695
12.092352100, 23.970, 2558.0, 50.5767
12.135817860, 23.970, 2462.0, 49.6185
12.179283620, 23.970, 2561.0, 50.6063
12.222749380, 23.970, 2476.0, 49.7594
12.266215140, 23.970, 2462.0, 49.6185
12.309680900, 23.970, 2526.0, 50.2593
12.353146660, 23.970, 2527.0, 50.2693
12.396612420, 23.970, 2567.0, 50.6656
12.440078180, 23.970, 2597.0, 50.9608
12.483543940, 23.970, 2552.0, 50.5173
12.527009700, 23.970, 2540.0, 50.3984
12.570475460, 23.970, 2711.0, 52.0673
12.613941220, 23.970, 2732.0, 52.2685
12.657406980, 23.970, 2696.0, 51.9230
12.700872740, 23.970, 2677.0, 51.7397
12.744338500, 23.970, 2678.0, 51.7494
12.787804260, 23.970, 2730.0, 52.2494
12.831270020, 23.970, 2838.0, 53.2729
12.874735780, 23.970, 2734.0, 52.2877
12.918201540, 23.970, 2857.0, 53.4509
12.961667300, 23.970, 2822.0, 53.1225
13.005133060, 23.970, 2781.0, 52.7352
13.048598820, 23.970, 2871.0, 53.5817
13.092064580, 23.970, 2778.0, 52.7067
13.135530340, 23.970, 2803.0, 52.9434
13.178996100, 23.970, 2893.0, 53.7866
13.222461860, 23.970, 2944.0, 54.2586
13.265927620, 23.970, 2948.0, 54.2955
13.309393380, 23.970, 3000.0, 54.7723
13.352859140, 23.970, 2978.0, 54.5711
13.396324900, 23.970, 2943.0, 54.2494
13.439790660, 23.970, 2959.0, 54.3967
13.483256420, 23.970, 3181.0, 56.4004
13.526722180, 23.970, 3195.0, 56.5243
13.570187940, 23.970, 3179.0, 56.3826
13.613653700, 23.970, 3163.0, 56.2406
13.657119460, 23.970, 3186.0, 56.4447
13.700585220, 23.970, 3158.0, 56.1961
13.744050980, 23.970, 3108.0, 55.7494
13.787516740, 23.970, 3215.0, 56.7010
13.830982500, 23.970, 3335.0, 57.7495
13.874448260, 23.970, 3289.0, 57.3498
13.917914020, 23.970, 3359.0, 57.9569
13.961379780, 23.970, 3392.0, 58.2409
14.004845540, 23.970, 3332.0, 57.7235
14.048311300, 23.970, 3398.0, 58.2924
14.091777060, 23.970, 3350.0, 57.8792
14.135242820, 23.970, 3457.0, 58.7963
14.178708580, 23.970, 3562.0, 59.6825
14.222174340, 23.970, 3526.0, 59.3801
14.265640100, 23.970, 3615.0, 60.1249
14.309105860, 23.970, 3555.0, 59.6238
14.352571620, 23.970, 3579.0, 59.8247
14.396037380, 23.970, 3666.0, 60.5475
14.439503140, 23.970, 3743.0, 61.1801
14.482968900, 23.970, 3826.0, 61.8547
14.526434660, 23.970, 3746.0, 61.2046
14.569900420, 23.970, 3790.0, 61.5630
14.613366180, 23.970, 3878.0, 62.2736
14.656831940, 23.970, 3780.0, 61.4817
14.700297700, 23.970, 3993.0, 63.1902
14.743763460, 23.970, 3908.0, 62.5140
14.787229220, 23.970, 3898.0, 62.4340
14.830694980, 23.970, 4040.0, 63.5610
14.874160740, 23.970, 4112.0, 64.1249
14.917626500, 23.970, 4176.0, 64.6220
14.961092260, 23.970, 4209.0, 64.8768
15.004558020, 23.970, 4264.0, 65.2993
15.048023780, 23.970, 4216.0, 64.9307
15.091489540, 23.970, 4328.0, 65.7875
15.134955300, 23.970, 4311.0, 65.6582
15.178421060, 23.970, 4291.0, 65.5057
15.221886820, 23.970, 4474.0, 66.8880
15.265352580, 23.970, 4545.0, 67.4166
15.308818340, 23.970, 4371.0, 66.1135
15.352284100, 23.970, 4509.0, 67.1491
15.395749860, 23.970, 4599.0, 67.8159
15.439215620, 23.970, 4719.0, 68.6950
15.482681380, 23.970, 4653.0, 68.2129
15.526147140, 23.970, 4605.0, 67.8602
15.569612900, 23.970, 4654.0, 68.2202
15.613078660, 23.970, 4718.0, 68.6877
15.656544420, 23.970, 5001.0, 70.7177
15.700010180, 23.970, 4910.0, 70.0714
15.743475940, 23.970, 4906.0, 70.0428
15.786941700, 23.970, 4970.0, 70.4982
15.830407460, 23.970, 5032.0, 70.9366
15.873873220, 23.970, 4990.0, 70.6399
15.917338980, 23.970, 5069.0, 71.1969
15.960804740, 23.970, 4968.0, 70.4840
16.004270500, 23.970, 5205.0, 72.1457
16.047736260, 23.970, 5152.0, 71.7774
16.091202020, 23.970, 5261.0, 72.5328
16.134667780, 23.970, 5245.0, 72.4224
16.178133540, 23.970, 5324.0, 72.9657
16.221599300, 23.970, 5415.0, 73.5867
16.265065060, 23.970, 5435.0, 73.7225
16.308530820, 23.970, 5552.0, 74.5117
16.351996580, 23.970, 5610.0, 74.8999
16.395462340, 23.970, 5751.0, 75.8353
16.438928100, 23.970, 5466.0, 73.9324
16.482393860, 23.970, 5593.0, 74.7864
16.525859620, 23.970, 5758.0, 75.8815
16.569325380, 23.970, 5681.0, 75.3724
16.612791140, 23.970, 5966.0, 77.2399
16.656256900, 23.970, 5961.0, 77.2075
16.699722660, 23.970, 5736.0, 75.7364
16.743188420, 23.970, 5837.0, 76.4003
16.786654180, 23.970, 5900.0, 76.8115
16.830119940, 23.970, 5981.0, 77.3369
16.873585700, 23.970, 6180.0, 78.6130
16.917051460, 23.970, 6006.0, 77.4984
16.960517220, 23.970, 6088.0, 78.0256
17.003982980, 23.970, 6211.0, 78.8099
17.047448740, 23.970, 6207.0, 78.7845
17.090914500, 23.970, 6049.0, 77.7753
17.134380260, 23.970, 6272.0, 79.1960
17.177846020, 23.970, 6378.0, 79.8624
17.221311780, 23.970, 6377.0, 79.8561
17.264777540, 23.970, 6349.0, 79.6806
17.308243300, 23.970, 6292.0, 79.3221
17.351709060, 23.970, 6350.0, 79.6869
17.395174820, 23.970, 6462.0, 80.3866
17.438640580, 23.970, 6468.0, 80.4239
17.482106340, 23.970, 6490.0, 80.5605
17.525572100, 23.970, 6456.0, 80.3492
17.569037860, 23.970, 6355.0, 79.7183
17.612503620, 23.970, 6513.0, 80.7032
17.655969380, 23.970, 6448.0, 80.2994
17.699435140, 23.970, 6347.0, 79.6681
17.742900900, 23.970, 6548.0, 80.9197
17.786366660, 23.970, 6481.0, 80.5047
17.829832420, 23.970, 6581.0, 81.1234
17.873298180, 23.970, 6595.0, 81.2096
17.916763940, 23.970, 6454.0, 80.3368
17.960229700, 23.970, 6714.0, 81.9390
18.003695460, 23.970, 6703.0, 81.8719
18.047161220, 23.970, 6614.0, 81.3265
18.090626980, 23.970, 6584.0, 81.1419
18.134092740, 23.970, 6742.0, 82.1097
18.177558500, 23.970, 6506.0, 80.6598
18.221024260, 23.970, 6636.0, 81.4616
18.264490020, 23.970, 6649.0, 81.5414
18.307955780, 23.970, 6429.0, 80.1810
18.351421540, 23.970, 6660.0, 81.6088
18.394887300, 23.970, 6631.0, 81.4310
18.438353060, 23.970, 6582.0, 81.1295
18.481818820, 23.970, 6712.0, 81.9268
18.525284580, 23.970, 6722.0, 81.9878
18.568750340, 23.970, 6477.0, 80.4798
18.612216100, 23.970, 6495.0, 80.5916
18.655681860, 23.970, 6751.0, 82.1645
18.699147620, 23.970, 6741.0, 82.1036
18.742613380, 23.970, 6593.0, 81.1973
18.786079140, 23.970, 6590.0, 81.1788
18.829544900, 23.970, 6445.0, 80.2808
18.873010660, 23.970, 6544.0, 80.8950
18.916476420, 23.970, 6489.0, 80.5543
18.959942180, 23.970, 6457.0, 80.3555
19.003407940, 23.970, 6421.0, 80.1311
19.046873700, 23.970, 6466.0, 80.4114
19.090339460, 23.970, 6307.0, 79.4166
19.133805220, 23.970, 6383.0, 79.8937
19.177270980, 23.970, 6269.0, 79.1770
19.220736740, 23.970, 6339.0, 79.6178
19.264202500, 23.970, 6295.0, 79.3410
19.307668260, 23.970, 6449.0, 80.3057
19.351134020, 23.970, 6207.0, 78.7845
19.394599780, 23.970, 6380.0, 79.8749
19.438065540, 23.970, 6247.0, 79.0380
19.481531300, 23.970, 6165.0, 78.5175
19.524997060, 23.970, 6111.0, 78.1729
19.568462820, 23.970, 6116.0, 78.2049
19.611928580, 23.970, 6244.0, 79.0190
19.655394340, 23.970, 5978.0, 77.3175
19.698860100, 23.970, 6027.0, 77.6338
19.742325860, 23.970, 6023.0, 77.6080
19.785791620, 23.970, 6028.0, 77.6402
19.829257380, 23.970, 5984.0, 77.3563
19.872723140, 23.970, 5974.0, 77.2917
19.916188900, 23.970, 5846.0, 76.4591
19.959654660, 23.970, 5796.0, 76.1315
20.003120420, 23.970, 5885.0, 76.7138
20.046586180, 23.970, 5750.0, 75.8288
20.090051940, 23.970, 5766.0, 75.9342
20.133517700, 23.970, 5755.0, 75.8617
20.176983460, 23.970, 5585.0, 74.7329
20.220449220, 23.970, 5659.0, 75.2263
20.263914980, 23.970, 5512.0, 74.2428
20.307380740, 23.970, 5680.0, 75.3658
20.350846500, 23.970, 5364.0, 73.2393
20.394312260, 23.970, 5501.0, 74.1687
20.437778020, 23.970, 5473.0, 73.9797
20.481243780, 23.970, 5424.0, 73.6478
20.524709540, 23.970, 5423.0, 73.6410
20.568175300, 23.970, 5471.0, 73.9662
20.611641060, 23.970, 5184.0, 72.0000
20.655106820, 23.970, 5249.0, 72.4500
20.698572580, 23.970, 5219.0, 72.2426
20.742038340, 23.970, 5139.0, 71.6868
20.785504100, 23.970, 5094.0, 71.3723
20.828969860, 23.970, 5127.0, 71.6031
20.872435620, 23.970, 5099.0, 71.4073
20.915901380, 23.970, 4985.0, 70.6045
20.959367140, 23.970, 4899.0, 69.9929
21.002832900, 23.970, 5082.0, 71.2881
21.046298660, 23.970, 4917.0, 70.1213
21.089764420, 23.970, 4930.0, 70.2140
21.133230180, 23.970, 4833.0, 69.5198
21.176695940, 23.970, 4932.0, 70.2282
21.220161700, 23.970, 4906.0, 70.0428
21.263627460, 23.970, 4767.0, 69.0435
21.307093220, 23.970, 4729.0, 68.7677
21.350558980, 23.970, 4620.0, 67.9706
21.394024740, 23.970, 4790.0, 69.2098
21.437490500, 23.970, 4722.0, 68.7168
21.480956260, 23.970, 4659.0, 68.2569
21.524422020, 23.970, 4507.0, 67.1342
21.567887780, 23.970, 4556.0, 67.4981
21.611353540, 23.970, 4527.0, 67.2830
21.654819300, 23.970, 4619.0, 67.9632
21.698285060, 23.970, 4357.0, 66.0076
21.741750820, 23.970, 4344.0, 65.9090
21.785216580, 23.970, 4384.0, 66.2118
21.828682340, 23.970, 4345.0, 65.9166
21.872148100, 23.970, 4328.0, 65.7875
21.915613860, 23.970, 4184.0, 64.6838
21.959079620, 23.970, 4075.0, 63.8357
22.002545380, 23.970, 4122.0, 64.2028
22.046011140, 23.970, 4191.0, 64.7379
22.089476900, 23.970, 4127.0, 64.2417
22.132942660, 23.970, 4117.0, 64.1639
22.176408420, 23.970, 4178.0, 64.6375
22.219874180, 23.970, 4083.0, 63.8984
22.263339940, 23.970, 4018.0, 63.3877
22.306805700, 23.970, 3975.0, 63.0476
22.350271460, 23.970, 3955.0, 62.8888
22.393737220, 23.970, 3901.0, 62.4580
22.437202980, 23.970, 3879.0, 62.2816
22.480668740, 23.970, 3935.0, 62.7296
22.524134500, 23.970, 3954.0, 62.8808
22.567600260, 23.970, 3884.0, 62.3217
22.611066020, 23.970, 3815.0, 61.7657
22.654531780, 23.970, 3817.0, 61.7819
22.697997540, 23.970, 3715.0, 60.9508
22.741463300, 23.970, 3651.0, 60.4235
22.784929060, 23.970, 3707.0, 60.8851
22.828394820, 23.970, 3667.0, 60.5558
22.871860580, 23.970, 3683.0, 60.6877
22.915326340, 23.970, 3526.0, 59.3801
22.958792100, 23.970, 3564.0, 59.6992
23.002257860, 23.970, 3524.0, 59.3633
23.045723620, 23.970, 3513.0, 59.2706
23.089189380, 23.970, 3426.0, 58.5320
23.132655140, 23.970, 3398.0, 58.2924
23.176120900, 23.970, 3321.0, 57.6281
23.219586660, 23.970, 3389.0, 58.2151
23.263052420, 23.970, 3363.0, 57.9914
23.306518180, 23.970, 3463.0, 58.8473
23.349983940, 23.970, 3323.0, 57.6455
23.393449700, 23.970, 3337.0, 57.7668
23.436915460, 23.970, 3354.0, 57.9137
23.480381220, 23.970, 3334.0, 57.7408
23.523846980, 23.970, 3191.0, 56.4889
23.567312740, 23.970, 3215.0, 56.7010
23.610778500, 23.970, 3081.0, 55.5068
23.654244260, 23.970, 3020.0, 54.9545
23.697710020, 23.970, 3122.0, 55.8749
23.741175780, 23.970, 3064.0, 55.3534
23.784641540, 23.970, 3111.0, 55.7763
23.828107300, 23.970, 3161.0, 56.2228
23.871573060, 23.970, 3031.0, 55.0545
23.915038820, 23.970, 3117.0, 55.8301
23.958504580, 23.970, 2974.0, 54.5344
24.001970340, 23.970, 2971.0, 54.5069
24.045436100, 23.970, 2986.0, 54.6443
24.088901860, 23.970, 2901.0, 53.8609
24.132367620, 23.970, 2944.0, 54.2586
24.175833380, 23.970, 2938.0, 54.2033
24.219299140, 23.970, 2884.0, 53.7029
24.262764900, 23.970, 2875.0, 53.6190
24.306230660, 23.970, 2872.0, 53.5910
24.349696420, 23.970, 2847.0, 53.3573
24.393162180, 23.970, 2962.0, 54.4243
24.436627940, 23.970, 2856.0, 53.4416
24.480093700, 23.970, 2812.0, 53.0283
24.523559460, 23.970, 2793.0, 52.8488
24.567025220, 23.970, 2665.0, 51.6236
24.610490980, 23.970, 2808.0, 52.9906
24.653956740, 23.970, 2726.0, 52.2111
24.697422500, 23.970, 2695.0, 51.9134
24.740888260, 23.970, 2676.0, 51.7301
24.784354020, 23.970, 2696.0, 51.9230
24.827819780, 23.970, 2701.0, 51.9711
24.871285540, 23.970, 2627.0, 51.2543
24.914751300, 23.970, 2620.0, 51.1859
24.958217060, 23.970, 2655.0, 51.5267
25.001682820, 23.970, 2488.0, 49.8799
25.045148580, 23.970, 2566.0, 50.6557
25.088614340, 23.970, 2581.0, 50.8035
25.132080100, 23.970, 2593.0, 50.9215
25.175545860, 23.970, 2548.0, 50.4777
25.219011620, 23.970, 2521.0, 50.2096
25.262477380, 23.970, 2573.0, 50.7247
25.305943140, 23.970, 2577.0, 50.7642
25.349408900, 23.970, 2461.0, 49.6085
25.392874660, 23.970, 2545.0, 50.4480
25.436340420, 23.970, 2449.0, 49.4874
25.479806180, 23.970, 2463.0, 49.6286
25.523271940, 23.970, 2436.0, 49.3559
25.566737700, 23.970, 2416.0, 49.1528
25.610203460, 23.970, 2433.0, 49.3254
25.653669220, 23.970, 2390.0, 48.8876
25.697134980, 23.970, 2361.0, 48.5901
25.740600740, 23.970, 2363.0, 48.6107
25.784066500, 23.970, 2325.0, 48.2183
25.827532260, 23.970, 2237.0, 47.2969
25.870998020, 23.970, 2375.0, 48.7340
25.914463780, 23.970, 2362.0, 48.6004
25.957929540, 23.970, 2292.0, 47.8748
26.001395300, 23.970, 2275.0, 47.6970
26.044861060, 23.970, 2338.0, 48.3529
26.088326820, 23.970, 2314.0, 48.1041
26.131792580, 23.970, 2251.0, 47.4447
26.175258340, 23.970, 2331.0, 48.2804
26.218724100, 23.970, 2434.0, 49.3356
26.262189860, 23.970, 2250.0, 47.4342
26.305655620, 23.970, 2256.0, 47.4974
26.349121380, 23.970, 2268.0, 47.6235
26.392587140, 23.970, 2196.0, 46.8615
26.436052900, 23.970, 2173.0, 46.6154
26.479518660, 23.970, 2297.0, 47.9270
26.522984420, 23.970, 2231.0, 47.2335
26.566450180, 23.970, 2212.0, 47.0319
26.609915940, 23.970, 2195.0, 46.8508
26.653381700, 23.970, 2190.0, 46.7974
26.696847460, 23.970, 2159.0, 46.4650
26.740313220, 23.970, 2174.0, 46.6262
26.783778980, 23.970, 2181.0, 46.7012
26.827244740, 23.970, 2145.0, 46.3141
26.870710500, 23.970, 2147.0, 46.3357
26.914176260, 23.970, 2098.0, 45.8039
26.957642020, 23.970, 2055.0, 45.3321
27.001107780, 23.970, 2055.0, 45.3321
27.044573540, 23.970, 2111.0, 45.9456
27.088039300, 23.970, 2083.0, 45.6399
27.131505060, 23.970, 2079.0, 45.5961
27.174970820, 23.970, 2083.0, 45.6399
27.218436580, 23.970, 2094.0, 45.7602
27.261902340, 23.970, 2040.0, 45.1664
27.305368100, 23.970, 2048.0, 45.2548
27.348833860, 23.970, 2018.0, 44.9222
27.392299620, 23.970, 1984.0, 44.5421
27.435765380, 23.970, 1985.0, 44.5533
27.479231140, 23.970, 2014.0, 44.8776
27.522696900, 23.970, 2014.0, 44.8776
27.566162660, 23.970, 1995.0, 44.6654
27.609628420, 23.970, 1994.0, 44.6542
27.653094180, 23.970, 1944.0, 44.0908
27.696559940, 23.970, 1994.0, 44.6542
27.740025700, 23.970, 1971.0, 44.3959
27.783491460, 23.970, 1939.0, 44.0341
27.826957220, 23.970, 1846.0, 42.9651
27.870422980, 23.970, 1946.0, 44.1135
27.913888740, 23.970, 1902.0, 43.6119
27.957354500, 23.970, 1910.0, 43.7035
28.000820260, 23.970, 1973.0, 44.4185
28.044286020, 23.970, 1983.0, 44.5309
28.087751780, 23.970, 1852.0, 43.0349
28.131217540, 23.970, 1888.0, 43.4511
28.174683300, 23.970, 1902.0, 43.6119
28.218149060, 23.970, 1870.0, 43.2435
28.261614820, 23.970, 1847.0, 42.9767
28.305080580, 23.970, 1932.0, 43.9545
28.348546340, 23.970, 1985.0, 44.5533
28.392012100, 23.970, 1853.0, 43.0465
28.435477860, 23.970, 1861.0, 43.1393
28.478943620, 23.970, 1884.0, 43.4051
28.522409380, 23.970, 1965.0, 44.3283
28.565875140, 23.970, 1896.0, 43.5431
28.609340900, 23.970, 2057.0, 45.3542
28.652806660, 23.970, 1979.0, 44.4860
28.696272420, 23.970, 2117.0, 46.0109
28.739738180, 23.970, 2063.0, 45.4203
28.783203940, 23.970, 2059.0, 45.3762
28.826669700, 23.970, 2208.0, 46.9894
28.870135460, 23.970, 2314.0, 48.1041
28.913601220, 23.970, 2518.0, 50.1797
28.957066980, 23.970, 2513.0, 50.1298
29.000532740, 23.970, 2367.0, 48.6518
29.043998500, 23.970, 2139.0, 46.2493
29.087464260, 23.970, 1884.0, 43.4051
29.130930020, 23.970, 1786.0, 42.2611
29.174395780, 23.970, 1676.0, 40.9390
29.217861540, 23.970, 1642.0, 40.5216
29.261327300, 23.970, 1679.0, 40.9756
29.304793060, 23.970, 1638.0, 40.4722
29.348258820, 23.970, 1604.0, 40.0500
29.391724580, 23.970, 1666.0, 40.8167
29.435190340, 23.970, 1660.0, 40.7431
29.478656100, 23.970, 1618.0, 40.2244
29.522121860, 23.970, 1598.0, 39.9750
29.565587620, 23.970, 1568.0, 39.5980
29.609053380, 23.970, 1640.0, 40.4969
29.652519140, 23.970, 1655.0, 40.6817
29.695984900, 23.970, 1606.0, 40.0749
29.739450660, 23.970, 1607.0, 40.0874
29.782916420, 23.970, 1503.0, 38.7685
29.826382180, 23.970, 1499.0, 38.7169
29.869847940, 23.970, 1527.0, 39.0768
29.913313700, 23.970, 1545.0, 39.3065
29.956779460, 23.970, 1576.0, 39.6989
30.000245220, 23.970, 1567.0, 39.5854
30.043710980, 23.970, 1564.0, 39.5474
30.087176740, 23.970, 1611.0, 40.1373
30.130642500, 23.970, 1449.0, 38.0657
30.174108260, 23.970, 1483.0, 38.5097
30.217574020, 23.970, 1474.0, 38.3927
30.261039780, 23.970, 1523.0, 39.0256
30.304505540, 23.970, 1508.0, 38.8330
30.347971300, 23.970, 1494.0, 38.6523
30.391437060, 23.970, 1502.0, 38.7556
30.434902820, 23.970, 1446.0, 38.0263
30.478368580, 23.970, 1399.0, 37.4032
30.521834340, 23.970, 1378.0, 37.1214
30.565300100, 23.970, 1437.0, 37.9078
30.608765860, 23.970, 1394.0, 37.3363
30.652231620, 23.970, 1425.0, 37.7492
30.695697380, 23.970, 1405.0, 37.4833
30.739163140, 23.970, 1450.0, 38.0789
30.782628900, 23.970, 1434.0, 37.8682
30.826094660, 23.970, 1402.0, 37.4433
30.869560420, 23.970, 1400.0, 37.4166
30.913026180, 23.970, 1399.0, 37.4032
30.956491940, 23.970, 1411.0, 37.5633
30.999957700, 23.970, 1435.0, 37.8814
31.043423460, 23.970, 1337.0, 36.5650
31.086889220, 23.970, 1351.0, 36.7560
31.130354980, 23.970, 1358.0, 36.8511
31.173820740, 23.970, 1363.0, 36.9188
31.217286500, 23.970, 1349.0, 36.7287
31.260752260, 23.970, 1336.0, 36.5513
31.304218020, 23.970, 1287.0, 35.8748
31.347683780, 23.970, 1283.0, 35.8190
31.391149540, 23.970, 1327.0, 36.4280
31.434615300, 23.970, 1338.0, 36.5787
31.478081060, 23.970, 1258.0, 35.4683
31.521546820, 23.970, 1293.0, 35.9583
31.565012580, 23.970, 1294.0, 35.9722
31.608478340, 23.970, 1217.0, 34.8855
31.651944100, 23.970, 1281.0, 35.7911
31.695409860, 23.970, 1265.0, 35.5668
31.738875620, 23.970, 1276.0, 35.7211
31.782341380, 23.970, 1257.0, 35.4542
31.825807140, 23.970, 1232.0, 35.0999
31.869272900, 23.970, 1225.0, 35.0000
31.912738660, 23.970, 1169.0, 34.1906
31.956204420, 23.970, 1230.0, 35.0714
31.999670180, 23.970, 1267.0, 35.5949
32.043135940, 23.970, 1213.0, 34.8281
32.086601700, 23.970, 1238.0, 35.1852
32.130067460, 23.970, 1247.0, 35.3129
32.173533220, 23.970, 1204.0, 34.6987
32.216998980, 23.970, 1200.0, 34.6410
32.260464740, 23.970, 1189.0, 34.4819
32.303930500, 23.970, 1183.0, 34.3948
32.347396260, 23.970, 1197.0, 34.5977
32.390862020, 23.970, 1147.0, 33.8674
32.434327780, 23.970, 1215.0, 34.8569
32.477793540, 23.970, 1186.0, 34.4384
32.521259300, 23.970, 1171.0, 34.2199
32.564725060, 23.970, 1209.0, 34.7707
32.608190820, 23.970, 1157.0, 34.0147
32.651656580, 23.970, 1141.0, 33.7787
32.695122340, 23.970, 1246.0, 35.2987
32.738588100, 23.970, 1148.0, 33.8821
32.782053860, 23.970, 1087.0, 32.9697
32.825519620, 23.970, 1131.0, 33.6303
32.868985380, 23.970, 1155.0, 33.9853
32.912451140, 23.970, 1145.0, 33.8378
32.955916900, 23.970, 1116.0, 33.4066
32.999382660, 23.970, 1091.0, 33.0303
33.042848420, 23.970, 1152.0, 33.9411
33.086314180, 23.970, 1116.0, 33.4066
33.129779940, 23.970, 1087.0, 32.9697
33.173245700, 23.970, 1096.0, 33.1059
33.216711460, 23.970, 1132.0, 33.6452
33.260177220, 23.970, 1073.0, 32.7567
33.303642980, 23.970, 1097.0, 33.1210
33.347108740, 23.970, 1094.0, 33.0757
33.390574500, 23.970, 1108.0, 33.2866
33.434040260, 23.970, 1122.0, 33.4963
33.477506020, 23.970, 1102.0, 33.1964
33.520971780, 23.970, 1053.0, 32.4500
33.564437540, 23.970, 1059.0, 32.5423
33.607903300, 23.970, 1047.0, 32.3574
33.651369060, 23.970, 1066.0, 32.6497
33.694834820, 23.970, 1036.0, 32.1870
33.738300580, 23.970, 1066.0, 32.6497
33.781766340, 23.970, 1010.0, 31.7805
33.825232100, 23.970, 1043.0, 32.2955
33.868697860, 23.970, 991.0, 31.4802
33.912163620, 23.970, 1016.0, 31.8748
33.955629380, 23.970, 1077.0, 32.8177
33.999095140, 23.970, 1008.0, 31.7490
34.042560900, 23.970, 1010.0, 31.7805
34.086026660, 23.970, 1012.0, 31.8119
34.129492420, 23.970, 1034.0, 32.1559
34.172958180, 23.970, 1057.0, 32.5115
34.216423940, 23.970, 984.0, 31.3688
34.259889700, 23.970, 987.0, 31.4166
34.303355460, 23.970, 1043.0, 32.2955
34.346821220, 23.970, 1007.0, 31.7333
34.390286980, 23.970, 1011.0, 31.7962
34.433752740, 23.970, 947.0, 30.7734
34.477218500, 23.970, 1040.0, 32.2490
34.520684260, 23.970, 1022.0, 31.9687
34.564150020, 23.970, 1017.0, 31.8904
34.607615780, 23.970, 991.0, 31.4802
34.651081540, 23.970, 1011.0, 31.7962
34.694547300, 23.970, 1051.0, 32.4191
34.738013060, 23.970, 1047.0, 32.3574
34.781478820, 23.970, 937.0, 30.6105
34.824944580, 23.970, 918.0, 30.2985
34.868410340, 23.970, 1001.0, 31.6386
34.911876100, 23.970, 944.0, 30.7246
34.955341860, 23.970, 941.0, 30.6757
34.998807620, 23.970, 954.0, 30.8869
35.042273380, 23.970, 1051.0, 32.4191
35.085739140, 23.970, 958.0, 30.9516
35.129204900, 23.970, 971.0, 31.1609
35.172670660, 23.970, 1022.0, 31.9687
35.216136420, 23.970, 970.0, 31.1448
35.259602180, 23.970, 1080.0, 32.8634
35.303067940, 23.970, 998.0, 31.5911
35.346533700, 23.970, 1030.0, 32.0936
35.389999460, 23.970, 1033.0, 32.1403
35.433465220, 23.970, 1068.0, 32.6803
35.476930980, 23.970, 982.0, 31.3369
35.520396740, 23.970, 1054.0, 32.4654
35.563862500, 23.970, 1022.0, 31.9687
35.607328260, 23.970, 991.0, 31.4802
35.650794020, 23.970, 930.0, 30.4959
35.694259780, 23.970, 910.0, 30.1662
35.737725540, 23.970, 912.0, 30.1993
35.781191300, 23.970, 906.0, 30.0998
35.824657060, 23.970, 897.0, 29.9500
35.868122820, 23.970, 887.0, 29.7825
35.911588580, 23.970, 944.0, 30.7246
35.955054340, 23.970, 890.0, 29.8329
35.998520100, 23.970, 928.0, 30.4631
36.041985860, 23.970, 937.0, 30.6105
36.085451620, 23.970, 902.0, 30.0333
36.128917380, 23.970, 966.0, 31.0805
36.172383140, 23.970, 940.0, 30.6594
36.215848900, 23.970, 894.0, 29.8998
36.259314660, 23.970, 871.0, 29.5127
36.302780420, 23.970, 933.0, 30.5450
36.346246180, 23.970, 907.0, 30.1164
36.389711940, 23.970, 836.0, 28.9137
36.433177700, 23.970, 966.0, 31.0805
36.476643460, 23.970, 901.0, 30.0167
36.520109220, 23.970, 905.0, 30.0832
36.563574980, 23.970, 933.0, 30.5450
36.607040740, 23.970, 918.0, 30.2985
36.650506500, 23.970, 891.0, 29.8496
36.693972260, 23.970, 867.0, 29.4449
36.737438020, 23.970, 894.0, 29.8998
36.780903780, 23.970, 887.0, 29.7825
36.824369540, 23.970, 892.0, 29.8664
36.867835300, 23.970, 872.0, 29.5296
36.911301060, 23.970, 893.0, 29.8831
36.954766820, 23.970, 843.0, 29.0345
36.998232580, 23.970, 841.0, 29.0000
37.041698340, 23.970, 847.0, 29.1033
37.085164100, 23.970, 841.0, 29.0000
37.128629860, 23.970, 873.0, 29.5466
37.172095620, 23.970, 855.0, 29.2404
37.215561380, 23.970, 906.0, 30.0998
37.259027140, 23.970, 833.0, 28.8617
37.302492900, 23.970, 916.0, 30.2655
37.345958660, 23.970, 893.0, 29.8831
37.389424420, 23.970, 880.0, 29.6648
37.432890180, 23.970, 863.0, 29.3769
37.476355940, 23.970, 860.0, 29.3258
37.519821700, 23.970, 895.0, 29.9166
37.563287460, 23.970, 880.0, 29.6648
37.606753220, 23.970, 873.0, 29.5466
37.650218980, 23.970, 850.0, 29.1548
37.693684740, 23.970, 862.0, 29.3598
37.737150500, 23.970, 889.0, 29.8161
37.780616260, 23.970, 848.0, 29.1204
37.824082020, 23.970, 871.0, 29.5127
37.867547780, 23.970, 811.0, 28.4781
37.911013540, 23.970, 856.0, 29.2575
37.954479300, 23.970, 900.0, 30.0000
37.997945060, 23.970, 896.0, 29.9333
38.041410820, 23.970, 880.0, 29.6648
38.084876580, 23.970, 839.0, 28.9655
38.128342340, 23.970, 853.0, 29.2062
38.171808100, 23.970, 893.0, 29.8831
38.215273860, 23.970, 867.0, 29.4449
38.258739620, 23.970, 867.0, 29.4449
38.302205380, 23.970, 871.0, 29.5127
38.345671140, 23.970, 819.0, 28.6182
38.389136900, 23.970, 882.0, 29.6985
38.432602660, 23.970, 943.0, 30.7083
38.476068420, 23.970, 855.0, 29.2404
38.519534180, 23.970, 838.0, 28.9482
38.562999940, 23.970, 940.0, 30.6594
38.606465700, 23.970, 990.0, 31.4643
38.649931460, 23.970, 954.0, 30.8869
38.693397220, 23.970, 1025.0, 32.0156
38.736862980, 23.970, 981.0, 31.3209
38.780328740, 23.970, 1058.0, 32.5269
38.823794500, 23.970, 1076.0, 32.8024
38.867260260, 23.970, 1036.0, 32.1870
38.910726020, 23.970, 1030.0, 32.0936
38.954191780, 23.970, 1058.0, 32.5269
38.997657540, 23.970, 1061.0, 32.5730
39.041123300, 23.970, 1024.0, 32.0000
39.084589060, 23.970, 899.0, 29.9833
39.128054820, 23.970, 873.0, 29.5466
39.171520580, 23.970, 876.0, 29.5973
39.214986340, 23.970, 855.0, 29.2404
39.258452100, 23.970, 846.0, 29.0861
39.301917860, 23.970, 834.0, 28.8791
39.345383620, 23.970, 826.0, 28.7402
39.388849380, 23.970, 853.0, 29.2062
39.432315140, 23.970, 848.0, 29.1204
39.475780900, 23.970, 870.0, 29.4958
39.519246660, 23.970, 886.0, 29.7658
39.562712420, 23.970, 848.0, 29.1204
39.606178180, 23.970, 869.0, 29.4788
39.649643940, 23.970, 833.0, 28.8617
39.693109700, 23.970, 839.0, 28.9655
39.736575460, 23.970, 887.0, 29.7825
39.780041220, 23.970, 858.0, 29.2916
39.823506980, 23.970, 879.0, 29.6479
39.866972740, 23.970, 860.0, 29.3258
39.910438500, 23.970, 869.0, 29.4788
39.953904260, 23.970, 884.0, 29.7321
39.997370020, 23.970, 848.0, 29.1204
40.040835780, 23.970, 884.0, 29.7321
40.084301540, 23.970, 916.0, 30.2655
40.127767300, 23.970, 886.0, 29.7658
40.171233060, 23.970, 920.0, 30.3315
40.214698820, 23.970, 858.0, 29.2916
40.258164580, 23.970, 870.0, 29.4958
40.301630340, 23.970, 850.0, 29.1548
40.345096100, 23.970, 839.0, 28.9655
40.388561860, 23.970, 893.0, 29.8831
40.432027620, 23.970, 891.0, 29.8496
40.475493380, 23.970, 893.0, 29.8831
40.518959140, 23.970, 883.0, 29.7153
40.562424900, 23.970, 849.0, 29.1376
40.605890660, 23.970, 848.0, 29.1204
40.649356420, 23.970, 881.0, 29.6816
40.692822180, 23.970, 819.0, 28.6182
40.736287940, 23.970, 923.0, 30.3809
40.779753700, 23.970, 875.0, 29.5804
40.823219460, 23.970, 925.0, 30.4138
40.866685220, 23.970, 824.0, 28.7054
40.910150980, 23.970, 839.0, 28.9655
40.953616740, 23.970, 855.0, 29.2404
40.997082500, 23.970, 821.0, 28.6531
41.040548260, 23.970, 889.0, 29.8161
41.084014020, 23.970, 887.0, 29.7825
41.127479780, 23.970, 871.0, 29.5127
41.170945540, 23.970, 910.0, 30.1662
41.214411300, 23.970, 883.0, 29.7153
41.257877060, 23.970, 784.0, 28.0000
41.301342820, 23.970, 890.0, 29.8329
41.344808580, 23.970, 908.0, 30.1330
41.388274340, 23.970, 856.0, 29.2575
41.431740100, 23.970, 916.0, 30.2655
41.475205860, 23.970, 875.0, 29.5804
41.518671620, 23.970, 887.0, 29.7825
41.562137380, 23.970, 896.0, 29.9333
41.605603140, 23.970, 867.0, 29.4449
41.649068900, 23.970, 896.0, 29.9333
41.692534660, 23.970, 860.0, 29.3258
41.736000420, 23.970, 853.0, 29.2062
41.779466180, 23.970, 872.0, 29.5296
41.822931940, 23.970, 865.0, 29.4109
41.866397700, 23.970, 817.0, 28.5832
41.909863460, 23.970, 852.0, 29.1890
41.953329220, 23.970, 881.0, 29.6816
41.996794980, 23.970, 858.0, 29.2916
42.040260740, 23.970, 914.0, 30.2324
42.083726500, 23.970, 944.0, 30.7246
42.127192260, 23.970, 866.0, 29.4279
42.170658020, 23.970, 947.0, 30.7734
42.214123780, 23.970, 956.0, 30.9192
42.257589540, 23.970, 943.0, 30.7083
42.301055300, 23.970, 848.0, 29.1204
42.344521060, 23.970, 966.0, 31.0805
42.387986820, 23.970, 977.0, 31.2570
42.431452580, 23.970, 901.0, 30.0167
42.474918340, 23.970, 983.0, 31.3528
42.518384100, 23.970, 1010.0, 31.7805
42.561849860, 23.970, 1050.0, 32.4037
42.605315620, 23.970, 1064.0, 32.6190
42.648781380, 23.970, 1022.0, 31.9687
42.692247140, 23.970, 1097.0, 33.1210
42.735712900, 23.970, 1038.0, 32.2180
42.779178660, 23.970, 1039.0, 32.2335
42.822644420, 23.970, 924.0, 30.3974
42.866110180, 23.970, 949.0, 30.8058
42.909575940, 23.970, 909.0, 30.1496
42.953041700, 23.970, 932.0, 30.5287
42.996507460, 23.970, 836.0, 28.9137
43.039973220, 23.970, 910.0, 30.1662
43.083438980, 23.970, 893.0, 29.8831
43.126904740, 23.970, 861.0, 29.3428
43.170370500, 23.970, 863.0, 29.3769
43.213836260, 23.970, 889.0, 29.8161
43.257302020, 23.970, 909.0, 30.1496
43.300767780, 23.970, 850.0, 29.1548
43.344233540, 23.970, 890.0, 29.8329
43.387699300, 23.970, 916.0, 30.2655
43.431165060, 23.970, 865.0, 29.4109
43.474630820, 23.970, 870.0, 29.4958
43.518096580, 23.970, 890.0, 29.8329
43.561562340, 23.970, 860.0, 29.3258
43.605028100, 23.970, 867.0, 29.4449
43.648493860, 23.970, 814.0, 28.5307
43.691959620, 23.970, 818.0, 28.6007
43.735425380, 23.970, 859.0, 29.3087
43.778891140, 23.970, 796.0, 28.2135
43.822356900, 23.970, 816.0, 28.5657
43.865822660, 23.970, 834.0, 28.8791
43.909288420, 23.970, 877.0, 29.6142
43.952754180, 23.970, 862.0, 29.3598
43.996219940, 23.970, 876.0, 29.5973
44.039685700, 23.970, 861.0, 29.3428
44.083151460, 23.970, 786.0, 28.0357
44.126617220, 23.970, 813.0, 28.5132
44.170082980, 23.970, 823.0, 28.6880
44.213548740, 23.970, 846.0, 29.0861
44.257014500, 23.970, 818.0, 28.6007
44.300480260, 23.970, 875.0, 29.5804
44.343946020, 23.970, 801.0, 28.3019
44.387411780, 23.970, 813.0, 28.5132
44.430877540, 23.970, 803.0, 28.3373
44.474343300, 23.970, 805.0, 28.3725
44.517809060, 23.970, 807.0, 28.4077
44.561274820, 23.970, 906.0, 30.0998
44.604740580, 23.970, 826.0, 28.7402
44.648206340, 23.970, 875.0, 29.5804
44.691672100, 23.970, 823.0, 28.6880
44.735137860, 23.970, 833.0, 28.8617
44.778603620, 23.970, 816.0, 28.5657
44.822069380, 23.970, 848.0, 29.1204
44.865535140, 23.970, 857.0, 29.2746
44.909000900, 23.970, 818.0, 28.6007
44.952466660, 23.970, 818.0, 28.6007
44.995932420, 23.970, 771.0, 27.7669
45.039398180, 23.970, 817.0, 28.5832
45.082863940, 23.970, 804.0, 28.3549
45.126329700, 23.970, 841.0, 29.0000
45.169795460, 23.970, 785.0, 28.0179
45.213261220, 23.970, 793.0, 28.1603
45.256726980, 23.970, 839.0, 28.9655
45.300192740, 23.970, 786.0, 28.0357
45.343658500, 23.970, 791.0, 28.1247
45.387124260, 23.970, 843.0, 29.0345
45.430590020, 23.970, 807.0, 28.4077
45.474055780, 23.970, 838.0, 28.9482
45.517521540, 23.970, 778.0, 27.8927
45.560987300, 23.970, 841.0, 29.0000
45.604453060, 23.970, 763.0, 27.6225
45.647918820, 23.970, 824.0, 28.7054
45.691384580, 23.970, 828.0, 28.7750
45.734850340, 23.970, 790.0, 28.1069
45.778316100, 23.970, 812.0, 28.4956
45.821781860, 23.970, 796.0, 28.2135
45.865247620, 23.970, 842.0, 29.0172
45.908713380, 23.970, 850.0, 29.1548
45.952179140, 23.970, 821.0, 28.6531
45.995644900, 23.970, 786.0, 28.0357
46.039110660, 23.970, 766.0, 27.6767
46.082576420, 23.970, 819.0, 28.6182
46.126042180, 23.970, 830.0, 28.8097
46.169507940, 23.970, 800.0, 28.2843
46.212973700, 23.970, 794.0, 28.1780
46.256439460, 23.970, 829.0, 28.7924
46.299905220, 23.970, 891.0, 29.8496
46.343370980, 23.970, 850.0, 29.1548
46.386836740, 23.970, 898.0, 29.9666
46.430302500, 23.970, 891.0, 29.8496
46.473768260, 23.970, 902.0, 30.0333
46.517234020, 23.970, 958.0, 30.9516
46.560699780, 23.970, 944.0, 30.7246
46.604165540, 23.970, 964.0, 31.0483
46.647631300, 23.970, 942.0, 30.6920
46.691097060, 23.970, 971.0, 31.1609
46.734562820, 23.970, 1057.0, 32.5115
46.778028580, 23.970, 1110.0, 33.3167
46.821494340, 23.970, 1019.0, 31.9218
46.864960100, 23.970, 1088.0, 32.9848
46.908425860, 23.970, 1103.0, 33.2114
46.951891620, 23.970, 1191.0, 34.5109
46.995357380, 23.970, 1057.0, 32.5115
47.038823140, 23.970, 1166.0, 34.1467
47.082288900, 23.970, 1119.0, 33.4515
47.125754660, 23.970, 1077.0, 32.8177
47.169220420, 23.970, 982.0, 31.3369
47.212686180, 23.970, 985.0, 31.3847
47.256151940, 23.970, 880.0, 29.6648
47.299617700, 23.970, 828.0, 28.7750
47.343083460, 23.970, 846.0, 29.0861
47.386549220, 23.970, 830.0, 28.8097
47.430014980, 23.970, 825.0, 28.7228
47.473480740, 23.970, 857.0, 29.2746
47.516946500, 23.970, 841.0, 29.0000
47.560412260, 23.970, 875.0, 29.5804
47.603878020, 23.970, 869.0, 29.4788
47.647343780, 23.970, 876.0, 29.5973
47.690809540, 23.970, 878.0, 29.6311
47.734275300, 23.970, 897.0, 29.9500
47.777741060, 23.970, 926.0, 30.4302
47.821206820, 23.970, 936.0, 30.5941
47.864672580, 23.970, 1058.0, 32.5269
47.908138340, 23.970, 1049.0, 32.3883
47.951604100, 23.970, 1023.0, 31.9844
47.995069860, 23.970, 1133.0, 33.6601
48.038535620, 23.970, 1070.0, 32.7109
48.082001380, 23.970, 1069.0, 32.6956
48.125467140, 23.970, 982.0, 31.3369
48.168932900, 23.970, 914.0, 30.2324
48.212398660, 23.970, 908.0, 30.1330
48.255864420, 23.970, 807.0, 28.4077
48.299330180, 23.970, 845.0, 29.0689
48.342795940, 23.970, 693.0, 26.3249
48.386261700, 23.970, 762.0, 27.6043
48.429727460, 23.970, 721.0, 26.8514
48.473193220, 23.970, 641.0, 25.3180
48.516658980, 23.970, 722.0, 26.8701
48.560124740, 23.970, 691.0, 26.2869
48.603590500, 23.970, 707.0, 26.5895
48.647056260, 23.970, 698.0, 26.4197
48.690522020, 23.970, 691.0, 26.2869
48.733987780, 23.970, 686.0, 26.1916
48.777453540, 23.970, 747.0, 27.3313
48.820919300, 23.970, 652.0, 25.5343
48.864385060, 23.970, 660.0, 25.6905
48.907850820, 23.970, 695.0, 26.3629
48.951316580, 23.970, 681.0, 26.0960
48.994782340, 23.970, 671.0, 25.9037
49.038248100, 23.970, 642.0, 25.3377
49.081713860, 23.970, 668.0, 25.8457
49.125179620, 23.970, 658.0, 25.6515
49.168645380, 23.970, 631.0, 25.1197
49.212111140, 23.970, 683.0, 26.1343
49.255576900, 23.970, 663.0, 25.7488
49.299042660, 23.970, 640.0, 25.2982
49.342508420, 23.970, 680.0, 26.0768
49.385974180, 23.970, 659.0, 25.6710
49.429439940, 23.970, 666.0, 25.8070
49.472905700, 23.970, 634.0, 25.1794
49.516371460, 23.970, 682.0, 26.1151
49.559837220, 23.970, 645.0, 25.3969
49.603302980, 23.970, 634.0, 25.1794
49.646768740, 23.970, 700.0, 26.4575
49.690234500, 23.970, 597.0, 24.4336
49.733700260, 23.970, 712.0, 26.6833
49.777166020, 23.970, 597.0, 24.4336
49.820631780, 23.970, 684.0, 26.1534
49.864097540, 23.970, 660.0, 25.6905
49.907563300, 23.970, 623.0, 24.9600
49.951029060, 23.970, 593.0, 24.3516
49.994494820, 23.970, 640.0, 25.2982