File: data/DSC/500907.csv
[Measurement conditions]
Sample identification,500907
Comment,
Anode material,Cu
K-Alpha1 wavelength,1.5405980
K-Alpha2 wavelength,1.5444260
Ratio K-Alpha2/K-Alpha1,0.500
Divergence slit,Fixed,0.38mm
Monochromator used,NO
Generator voltage, 40
Tube current, 15
File date and time,26/Feb/2025 10:21
Unit cell,
h k l, 0 0 0
Scan axis,Gonio
Scan range,5.002000000,49.999928040
Scan step size,0.0108664
No. of points, 4141
Scan type,CONTINUOUS
Time per step,23.970
[Scan points]
Angle, TimePerStep, Intensity, ESD
5.007433220, 23.970, 388.0, 19.6977
5.050898980, 23.970, 373.0, 19.3132
5.094364740, 23.970, 407.0, 20.1742
5.137830500, 23.970, 419.0, 20.4695
5.181296260, 23.970, 388.0, 19.6977
5.224762020, 23.970, 412.0, 20.2978
5.268227780, 23.970, 434.0, 20.8327
5.311693540, 23.970, 422.0, 20.5426
5.355159300, 23.970, 429.0, 20.7123
5.398625060, 23.970, 439.0, 20.9523
5.442090820, 23.970, 445.0, 21.0950
5.485556580, 23.970, 485.0, 22.0227
5.529022340, 23.970, 448.0, 21.1660
5.572488100, 23.970, 468.0, 21.6333
5.615953860, 23.970, 453.0, 21.2838
5.659419620, 23.970, 479.0, 21.8861
5.702885380, 23.970, 497.0, 22.2935
5.746351140, 23.970, 535.0, 23.1301
5.789816900, 23.970, 521.0, 22.8254
5.833282660, 23.970, 498.0, 22.3159
5.876748420, 23.970, 555.0, 23.5584
5.920214180, 23.970, 538.0, 23.1948
5.963679940, 23.970, 586.0, 24.2074
6.007145700, 23.970, 623.0, 24.9600
6.050611460, 23.970, 596.0, 24.4131
6.094077220, 23.970, 625.0, 25.0000
6.137542980, 23.970, 549.0, 23.4307
6.181008740, 23.970, 587.0, 24.2281
6.224474500, 23.970, 634.0, 25.1794
6.267940260, 23.970, 614.0, 24.7790
6.311406020, 23.970, 642.0, 25.3377
6.354871780, 23.970, 637.0, 25.2389
6.398337540, 23.970, 632.0, 25.1396
6.441803300, 23.970, 654.0, 25.5734
6.485269060, 23.970, 681.0, 26.0960
6.528734820, 23.970, 747.0, 27.3313
6.572200580, 23.970, 681.0, 26.0960
6.615666340, 23.970, 833.0, 28.8617
6.659132100, 23.970, 767.0, 27.6948
6.702597860, 23.970, 729.0, 27.0000
6.746063620, 23.970, 741.0, 27.2213
6.789529380, 23.970, 754.0, 27.4591
6.832995140, 23.970, 802.0, 28.3196
6.876460900, 23.970, 852.0, 29.1890
6.919926660, 23.970, 767.0, 27.6948
6.963392420, 23.970, 816.0, 28.5657
7.006858180, 23.970, 807.0, 28.4077
7.050323940, 23.970, 830.0, 28.8097
7.093789700, 23.970, 795.0, 28.1957
7.137255460, 23.970, 858.0, 29.2916
7.180721220, 23.970, 845.0, 29.0689
7.224186980, 23.970, 808.0, 28.4253
7.267652740, 23.970, 839.0, 28.9655
7.311118500, 23.970, 804.0, 28.3549
7.354584260, 23.970, 935.0, 30.5778
7.398050020, 23.970, 896.0, 29.9333
7.441515780, 23.970, 891.0, 29.8496
7.484981540, 23.970, 911.0, 30.1828
7.528447300, 23.970, 891.0, 29.8496
7.571913060, 23.970, 877.0, 29.6142
7.615378820, 23.970, 924.0, 30.3974
7.658844580, 23.970, 893.0, 29.8831
7.702310340, 23.970, 933.0, 30.5450
7.745776100, 23.970, 987.0, 31.4166
7.789241860, 23.970, 964.0, 31.0483
7.832707620, 23.970, 941.0, 30.6757
7.876173380, 23.970, 999.0, 31.6070
7.919639140, 23.970, 976.0, 31.2410
7.963104900, 23.970, 955.0, 30.9031
8.006570660, 23.970, 959.0, 30.9677
8.050036420, 23.970, 964.0, 31.0483
8.093502180, 23.970, 979.0, 31.2890
8.136967940, 23.970, 978.0, 31.2730
8.180433700, 23.970, 1017.0, 31.8904
8.223899460, 23.970, 1133.0, 33.6601
8.267365220, 23.970, 1036.0, 32.1870
8.310830980, 23.970, 1016.0, 31.8748
8.354296740, 23.970, 1035.0, 32.1714
8.397762500, 23.970, 1057.0, 32.5115
8.441228260, 23.970, 1029.0, 32.0780
8.484694020, 23.970, 1078.0, 32.8329
8.528159780, 23.970, 970.0, 31.1448
8.571625540, 23.970, 1034.0, 32.1559
8.615091300, 23.970, 1102.0, 33.1964
8.658557060, 23.970, 1053.0, 32.4500
8.702022820, 23.970, 1008.0, 31.7490
8.745488580, 23.970, 1108.0, 33.2866
8.788954340, 23.970, 988.0, 31.4325
8.832420100, 23.970, 1027.0, 32.0468
8.875885860, 23.970, 1035.0, 32.1714
8.919351620, 23.970, 1072.0, 32.7414
8.962817380, 23.970, 1103.0, 33.2114
9.006283140, 23.970, 1131.0, 33.6303
9.049748900, 23.970, 1082.0, 32.8938
9.093214660, 23.970, 1107.0, 33.2716
9.136680420, 23.970, 1141.0, 33.7787
9.180146180, 23.970, 1071.0, 32.7261
9.223611940, 23.970, 1106.0, 33.2566
9.267077700, 23.970, 1143.0, 33.8083
9.310543460, 23.970, 1135.0, 33.6898
9.354009220, 23.970, 1145.0, 33.8378
9.397474980, 23.970, 1133.0, 33.6601
9.440940740, 23.970, 1122.0, 33.4963
9.484406500, 23.970, 1097.0, 33.1210
9.527872260, 23.970, 1097.0, 33.1210
9.571338020, 23.970, 1057.0, 32.5115
9.614803780, 23.970, 1153.0, 33.9559
9.658269540, 23.970, 1153.0, 33.9559
9.701735300, 23.970, 1187.0, 34.4529
9.745201060, 23.970, 1102.0, 33.1964
9.788666820, 23.970, 1059.0, 32.5423
9.832132580, 23.970, 1158.0, 34.0294
9.875598340, 23.970, 1155.0, 33.9853
9.919064100, 23.970, 1143.0, 33.8083
9.962529860, 23.970, 1123.0, 33.5112
10.005995620, 23.970, 1167.0, 34.1614
10.049461380, 23.970, 1062.0, 32.5883
10.092927140, 23.970, 1096.0, 33.1059
10.136392900, 23.970, 1190.0, 34.4964
10.179858660, 23.970, 1144.0, 33.8231
10.223324420, 23.970, 1176.0, 34.2929
10.266790180, 23.970, 1134.0, 33.6749
10.310255940, 23.970, 1097.0, 33.1210
10.353721700, 23.970, 1124.0, 33.5261
10.397187460, 23.970, 1118.0, 33.4365
10.440653220, 23.970, 1166.0, 34.1467
10.484118980, 23.970, 1173.0, 34.2491
10.527584740, 23.970, 1183.0, 34.3948
10.571050500, 23.970, 1110.0, 33.3167
10.614516260, 23.970, 1200.0, 34.6410
10.657982020, 23.970, 1170.0, 34.2053
10.701447780, 23.970, 1125.0, 33.5410
10.744913540, 23.970, 1179.0, 34.3366
10.788379300, 23.970, 1207.0, 34.7419
10.831845060, 23.970, 1101.0, 33.1813
10.875310820, 23.970, 1193.0, 34.5398
10.918776580, 23.970, 1174.0, 34.2637
10.962242340, 23.970, 1178.0, 34.3220
11.005708100, 23.970, 1167.0, 34.1614
11.049173860, 23.970, 1197.0, 34.5977
11.092639620, 23.970, 1198.0, 34.6121
11.136105380, 23.970, 1167.0, 34.1614
11.179571140, 23.970, 1226.0, 35.0143
11.223036900, 23.970, 1231.0, 35.0856
11.266502660, 23.970, 1224.0, 34.9857
11.309968420, 23.970, 1216.0, 34.8712
11.353434180, 23.970, 1251.0, 35.3695
11.396899940, 23.970, 1200.0, 34.6410
11.440365700, 23.970, 1223.0, 34.9714
11.483831460, 23.970, 1219.0, 34.9142
11.527297220, 23.970, 1200.0, 34.6410
11.570762980, 23.970, 1296.0, 36.0000
11.614228740, 23.970, 1235.0, 35.1426
11.657694500, 23.970, 1286.0, 35.8608
11.701160260, 23.970, 1223.0, 34.9714
11.744626020, 23.970, 1338.0, 36.5787
11.788091780, 23.970, 1239.0, 35.1994
11.831557540, 23.970, 1296.0, 36.0000
11.875023300, 23.970, 1269.0, 35.6230
11.918489060, 23.970, 1281.0, 35.7911
11.961954820, 23.970, 1291.0, 35.9305
12.005420580, 23.970, 1292.0, 35.9444
12.048886340, 23.970, 1312.0, 36.2215
12.092352100, 23.970, 1371.0, 37.0270
12.135817860, 23.970, 1323.0, 36.3731
12.179283620, 23.970, 1397.0, 37.3765
12.222749380, 23.970, 1417.0, 37.6431
12.266215140, 23.970, 1336.0, 36.5513
12.309680900, 23.970, 1335.0, 36.5377
12.353146660, 23.970, 1360.0, 36.8782
12.396612420, 23.970, 1361.0, 36.8917
12.440078180, 23.970, 1321.0, 36.3456
12.483543940, 23.970, 1321.0, 36.3456
12.527009700, 23.970, 1306.0, 36.1386
12.570475460, 23.970, 1353.0, 36.7831
12.613941220, 23.970, 1382.0, 37.1753
12.657406980, 23.970, 1424.0, 37.7359
12.700872740, 23.970, 1373.0, 37.0540
12.744338500, 23.970, 1459.0, 38.1969
12.787804260, 23.970, 1416.0, 37.6298
12.831270020, 23.970, 1498.0, 38.7040
12.874735780, 23.970, 1468.0, 38.3145
12.918201540, 23.970, 1463.0, 38.2492
12.961667300, 23.970, 1452.0, 38.1051
13.005133060, 23.970, 1506.0, 38.8072
13.048598820, 23.970, 1522.0, 39.0128
13.092064580, 23.970, 1501.0, 38.7427
13.135530340, 23.970, 1517.0, 38.9487
13.178996100, 23.970, 1541.0, 39.2556
13.222461860, 23.970, 1595.0, 39.9375
13.265927620, 23.970, 1540.0, 39.2428
13.309393380, 23.970, 1573.0, 39.6611
13.352859140, 23.970, 1594.0, 39.9249
13.396324900, 23.970, 1577.0, 39.7115
13.439790660, 23.970, 1556.0, 39.4462
13.483256420, 23.970, 1606.0, 40.0749
13.526722180, 23.970, 1690.0, 41.1096
13.570187940, 23.970, 1611.0, 40.1373
13.613653700, 23.970, 1657.0, 40.7063
13.657119460, 23.970, 1648.0, 40.5956
13.700585220, 23.970, 1675.0, 40.9268
13.744050980, 23.970, 1711.0, 41.3642
13.787516740, 23.970, 1799.0, 42.4146
13.830982500, 23.970, 1698.0, 41.2068
13.874448260, 23.970, 1781.0, 42.2019
13.917914020, 23.970, 1725.0, 41.5331
13.961379780, 23.970, 1778.0, 42.1663
14.004845540, 23.970, 1813.0, 42.5793
14.048311300, 23.970, 1904.0, 43.6348
14.091777060, 23.970, 1811.0, 42.5558
14.135242820, 23.970, 1799.0, 42.4146
14.178708580, 23.970, 1764.0, 42.0000
14.222174340, 23.970, 1799.0, 42.4146
14.265640100, 23.970, 1842.0, 42.9185
14.309105860, 23.970, 1868.0, 43.2204
14.352571620, 23.970, 1950.0, 44.1588
14.396037380, 23.970, 1901.0, 43.6005
14.439503140, 23.970, 1919.0, 43.8064
14.482968900, 23.970, 1932.0, 43.9545
14.526434660, 23.970, 1973.0, 44.4185
14.569900420, 23.970, 2004.0, 44.7661
14.613366180, 23.970, 1956.0, 44.2267
14.656831940, 23.970, 2106.0, 45.8912
14.700297700, 23.970, 2070.0, 45.4973
14.743763460, 23.970, 2084.0, 45.6508
14.787229220, 23.970, 2153.0, 46.4004
14.830694980, 23.970, 2202.0, 46.9255
14.874160740, 23.970, 2130.0, 46.1519
14.917626500, 23.970, 2117.0, 46.0109
14.961092260, 23.970, 2179.0, 46.6798
15.004558020, 23.970, 2222.0, 47.1381
15.048023780, 23.970, 2203.0, 46.9361
15.091489540, 23.970, 2139.0, 46.2493
15.134955300, 23.970, 2330.0, 48.2701
15.178421060, 23.970, 2275.0, 47.6970
15.221886820, 23.970, 2291.0, 47.8644
15.265352580, 23.970, 2286.0, 47.8121
15.308818340, 23.970, 2284.0, 47.7912
15.352284100, 23.970, 2437.0, 49.3660
15.395749860, 23.970, 2424.0, 49.2341
15.439215620, 23.970, 2380.0, 48.7852
15.482681380, 23.970, 2373.0, 48.7134
15.526147140, 23.970, 2429.0, 49.2849
15.569612900, 23.970, 2547.0, 50.4678
15.613078660, 23.970, 2505.0, 50.0500
15.656544420, 23.970, 2484.0, 49.8397
15.700010180, 23.970, 2535.0, 50.3488
15.743475940, 23.970, 2642.0, 51.4004
15.786941700, 23.970, 2565.0, 50.6458
15.830407460, 23.970, 2661.0, 51.5849
15.873873220, 23.970, 2576.0, 50.7543
15.917338980, 23.970, 2722.0, 52.1728
15.960804740, 23.970, 2762.0, 52.5547
16.004270500, 23.970, 2858.0, 53.4603
16.047736260, 23.970, 2821.0, 53.1131
16.091202020, 23.970, 2750.0, 52.4404
16.134667780, 23.970, 2858.0, 53.4603
16.178133540, 23.970, 2932.0, 54.1479
16.221599300, 23.970, 2857.0, 53.4509
16.265065060, 23.970, 2911.0, 53.9537
16.308530820, 23.970, 2930.0, 54.1295
16.351996580, 23.970, 2897.0, 53.8238
16.395462340, 23.970, 3067.0, 55.3805
16.438928100, 23.970, 3099.0, 55.6687
16.482393860, 23.970, 3129.0, 55.9375
16.525859620, 23.970, 3153.0, 56.1516
16.569325380, 23.970, 3200.0, 56.5685
16.612791140, 23.970, 3318.0, 57.6021
16.656256900, 23.970, 3250.0, 57.0088
16.699722660, 23.970, 3344.0, 57.8273
16.743188420, 23.970, 3371.0, 58.0603
16.786654180, 23.970, 3362.0, 57.9828
16.830119940, 23.970, 3296.0, 57.4108
16.873585700, 23.970, 3406.0, 58.3609
16.917051460, 23.970, 3448.0, 58.7197
16.960517220, 23.970, 3503.0, 59.1861
17.003982980, 23.970, 3518.0, 59.3127
17.047448740, 23.970, 3533.0, 59.4390
17.090914500, 23.970, 3606.0, 60.0500
17.134380260, 23.970, 3567.0, 59.7244
17.177846020, 23.970, 3658.0, 60.4814
17.221311780, 23.970, 3649.0, 60.4070
17.264777540, 23.970, 3718.0, 60.9754
17.308243300, 23.970, 3724.0, 61.0246
17.351709060, 23.970, 3768.0, 61.3840
17.395174820, 23.970, 3887.0, 62.3458
17.438640580, 23.970, 3709.0, 60.9016
17.482106340, 23.970, 3850.0, 62.0484
17.525572100, 23.970, 3831.0, 61.8951
17.569037860, 23.970, 3923.0, 62.6339
17.612503620, 23.970, 3914.0, 62.5620
17.655969380, 23.970, 3923.0, 62.6339
17.699435140, 23.970, 3938.0, 62.7535
17.742900900, 23.970, 4063.0, 63.7417
17.786366660, 23.970, 3982.0, 63.1031
17.829832420, 23.970, 4016.0, 63.3719
17.873298180, 23.970, 4103.0, 64.0547
17.916763940, 23.970, 4148.0, 64.4050
17.960229700, 23.970, 4116.0, 64.1561
18.003695460, 23.970, 4135.0, 64.3040
18.047161220, 23.970, 4105.0, 64.0703
18.090626980, 23.970, 4205.0, 64.8460
18.134092740, 23.970, 4152.0, 64.4360
18.177558500, 23.970, 4266.0, 65.3146
18.221024260, 23.970, 4253.0, 65.2150
18.264490020, 23.970, 4400.0, 66.3325
18.307955780, 23.970, 4262.0, 65.2840
18.351421540, 23.970, 4203.0, 64.8305
18.394887300, 23.970, 4334.0, 65.8331
18.438353060, 23.970, 4361.0, 66.0379
18.481818820, 23.970, 4483.0, 66.9552
18.525284580, 23.970, 4330.0, 65.8027
18.568750340, 23.970, 4322.0, 65.7419
18.612216100, 23.970, 4432.0, 66.5733
18.655681860, 23.970, 4446.0, 66.6783
18.699147620, 23.970, 4387.0, 66.2344
18.742613380, 23.970, 4451.0, 66.7158
18.786079140, 23.970, 4501.0, 67.0895
18.829544900, 23.970, 4644.0, 68.1469
18.873010660, 23.970, 4538.0, 67.3647
18.916476420, 23.970, 4497.0, 67.0597
18.959942180, 23.970, 4542.0, 67.3944
19.003407940, 23.970, 4553.0, 67.4759
19.046873700, 23.970, 4377.0, 66.1589
19.090339460, 23.970, 4380.0, 66.1816
19.133805220, 23.970, 4522.0, 67.2458
19.177270980, 23.970, 4531.0, 67.3127
19.220736740, 23.970, 4416.0, 66.4530
19.264202500, 23.970, 4475.0, 66.8954
19.307668260, 23.970, 4485.0, 66.9701
19.351134020, 23.970, 4626.0, 68.0147
19.394599780, 23.970, 4482.0, 66.9477
19.438065540, 23.970, 4321.0, 65.7343
19.481531300, 23.970, 4466.0, 66.8281
19.524997060, 23.970, 4434.0, 66.5883
19.568462820, 23.970, 4460.0, 66.7832
19.611928580, 23.970, 4448.0, 66.6933
19.655394340, 23.970, 4321.0, 65.7343
19.698860100, 23.970, 4434.0, 66.5883
19.742325860, 23.970, 4415.0, 66.4455
19.785791620, 23.970, 4451.0, 66.7158
19.829257380, 23.970, 4450.0, 66.7083
19.872723140, 23.970, 4463.0, 66.8057
19.916188900, 23.970, 4399.0, 66.3250
19.959654660, 23.970, 4463.0, 66.8057
20.003120420, 23.970, 4348.0, 65.9394
20.046586180, 23.970, 4399.0, 66.3250
20.090051940, 23.970, 4276.0, 65.3911
20.133517700, 23.970, 4311.0, 65.6582
20.176983460, 23.970, 4294.0, 65.5286
20.220449220, 23.970, 4387.0, 66.2344
20.263914980, 23.970, 4324.0, 65.7571
20.307380740, 23.970, 4344.0, 65.9090
20.350846500, 23.970, 4178.0, 64.6375
20.394312260, 23.970, 4201.0, 64.8151
20.437778020, 23.970, 4266.0, 65.3146
20.481243780, 23.970, 4139.0, 64.3351
20.524709540, 23.970, 4154.0, 64.4515
20.568175300, 23.970, 4175.0, 64.6142
20.611641060, 23.970, 4021.0, 63.4114
20.655106820, 23.970, 4226.0, 65.0077
20.698572580, 23.970, 3976.0, 63.0555
20.742038340, 23.970, 4112.0, 64.1249
20.785504100, 23.970, 3984.0, 63.1189
20.828969860, 23.970, 4004.0, 63.2772
20.872435620, 23.970, 4040.0, 63.5610
20.915901380, 23.970, 4037.0, 63.5374
20.959367140, 23.970, 3975.0, 63.0476
21.002832900, 23.970, 3983.0, 63.1110
21.046298660, 23.970, 3878.0, 62.2736
21.089764420, 23.970, 3963.0, 62.9524
21.133230180, 23.970, 3918.0, 62.5939
21.176695940, 23.970, 3841.0, 61.9758
21.220161700, 23.970, 3894.0, 62.4019
21.263627460, 23.970, 3784.0, 61.5142
21.307093220, 23.970, 3749.0, 61.2291
21.350558980, 23.970, 3874.0, 62.2415
21.394024740, 23.970, 3731.0, 61.0819
21.437490500, 23.970, 3771.0, 61.4085
21.480956260, 23.970, 3702.0, 60.8441
21.524422020, 23.970, 3768.0, 61.3840
21.567887780, 23.970, 3627.0, 60.2246
21.611353540, 23.970, 3609.0, 60.0750
21.654819300, 23.970, 3596.0, 59.9667
21.698285060, 23.970, 3482.0, 59.0085
21.741750820, 23.970, 3635.0, 60.2910
21.785216580, 23.970, 3493.0, 59.1016
21.828682340, 23.970, 3515.0, 59.2874
21.872148100, 23.970, 3428.0, 58.5491
21.915613860, 23.970, 3433.0, 58.5918
21.959079620, 23.970, 3445.0, 58.6941
22.002545380, 23.970, 3267.0, 57.1577
22.046011140, 23.970, 3326.0, 57.6715
22.089476900, 23.970, 3420.0, 58.4808
22.132942660, 23.970, 3369.0, 58.0431
22.176408420, 23.970, 3330.0, 57.7062
22.219874180, 23.970, 3316.0, 57.5847
22.263339940, 23.970, 3318.0, 57.6021
22.306805700, 23.970, 3302.0, 57.4630
22.350271460, 23.970, 3171.0, 56.3116
22.393737220, 23.970, 3266.0, 57.1489
22.437202980, 23.970, 3186.0, 56.4447
22.480668740, 23.970, 3203.0, 56.5951
22.524134500, 23.970, 3093.0, 55.6147
22.567600260, 23.970, 3171.0, 56.3116
22.611066020, 23.970, 3097.0, 55.6507
22.654531780, 23.970, 3136.0, 56.0000
22.697997540, 23.970, 3071.0, 55.4166
22.741463300, 23.970, 3017.0, 54.9272
22.784929060, 23.970, 3049.0, 55.2178
22.828394820, 23.970, 3003.0, 54.7996
22.871860580, 23.970, 3000.0, 54.7723
22.915326340, 23.970, 3041.0, 55.1453
22.958792100, 23.970, 2978.0, 54.5711
23.002257860, 23.970, 2974.0, 54.5344
23.045723620, 23.970, 2928.0, 54.1110
23.089189380, 23.970, 2973.0, 54.5252
23.132655140, 23.970, 2873.0, 53.6004
23.176120900, 23.970, 2839.0, 53.2823
23.219586660, 23.970, 2880.0, 53.6656
23.263052420, 23.970, 2893.0, 53.7866
23.306518180, 23.970, 2820.0, 53.1037
23.349983940, 23.970, 2801.0, 52.9245
23.393449700, 23.970, 2736.0, 52.3068
23.436915460, 23.970, 2704.0, 52.0000
23.480381220, 23.970, 2688.0, 51.8459
23.523846980, 23.970, 2596.0, 50.9510
23.567312740, 23.970, 2601.0, 51.0000
23.610778500, 23.970, 2681.0, 51.7784
23.654244260, 23.970, 2601.0, 51.0000
23.697710020, 23.970, 2540.0, 50.3984
23.741175780, 23.970, 2593.0, 50.9215
23.784641540, 23.970, 2568.0, 50.6754
23.828107300, 23.970, 2582.0, 50.8134
23.871573060, 23.970, 2573.0, 50.7247
23.915038820, 23.970, 2597.0, 50.9608
23.958504580, 23.970, 2570.0, 50.6952
24.001970340, 23.970, 2477.0, 49.7695
24.045436100, 23.970, 2476.0, 49.7594
24.088901860, 23.970, 2472.0, 49.7192
24.132367620, 23.970, 2394.0, 48.9285
24.175833380, 23.970, 2431.0, 49.3052
24.219299140, 23.970, 2441.0, 49.4065
24.262764900, 23.970, 2379.0, 48.7750
24.306230660, 23.970, 2384.0, 48.8262
24.349696420, 23.970, 2332.0, 48.2908
24.393162180, 23.970, 2482.0, 49.8197
24.436627940, 23.970, 2273.0, 47.6760
24.480093700, 23.970, 2319.0, 48.1560
24.523559460, 23.970, 2252.0, 47.4552
24.567025220, 23.970, 2270.0, 47.6445
24.610490980, 23.970, 2172.0, 46.6047
24.653956740, 23.970, 2244.0, 47.3709
24.697422500, 23.970, 2202.0, 46.9255
24.740888260, 23.970, 2221.0, 47.1275
24.784354020, 23.970, 2172.0, 46.6047
24.827819780, 23.970, 2174.0, 46.6262
24.871285540, 23.970, 2161.0, 46.4866
24.914751300, 23.970, 2128.0, 46.1303
24.958217060, 23.970, 2188.0, 46.7761
25.001682820, 23.970, 2152.0, 46.3897
25.045148580, 23.970, 2045.0, 45.2217
25.088614340, 23.970, 2120.0, 46.0435
25.132080100, 23.970, 2124.0, 46.0869
25.175545860, 23.970, 2129.0, 46.1411
25.219011620, 23.970, 2084.0, 45.6508
25.262477380, 23.970, 2117.0, 46.0109
25.305943140, 23.970, 2056.0, 45.3431
25.349408900, 23.970, 2023.0, 44.9778
25.392874660, 23.970, 2031.0, 45.0666
25.436340420, 23.970, 1968.0, 44.3621
25.479806180, 23.970, 2032.0, 45.0777
25.523271940, 23.970, 1993.0, 44.6430
25.566737700, 23.970, 1950.0, 44.1588
25.610203460, 23.970, 1973.0, 44.4185
25.653669220, 23.970, 1919.0, 43.8064
25.697134980, 23.970, 1988.0, 44.5870
25.740600740, 23.970, 1982.0, 44.5197
25.784066500, 23.970, 1934.0, 43.9773
25.827532260, 23.970, 1909.0, 43.6921
25.870998020, 23.970, 1920.0, 43.8178
25.914463780, 23.970, 1851.0, 43.0232
25.957929540, 23.970, 1915.0, 43.7607
26.001395300, 23.970, 2023.0, 44.9778
26.044861060, 23.970, 1825.0, 42.7200
26.088326820, 23.970, 1855.0, 43.0697
26.131792580, 23.970, 1879.0, 43.3474
26.175258340, 23.970, 1873.0, 43.2782
26.218724100, 23.970, 1819.0, 42.6497
26.262189860, 23.970, 1825.0, 42.7200
26.305655620, 23.970, 1762.0, 41.9762
26.349121380, 23.970, 1736.0, 41.6653
26.392587140, 23.970, 1862.0, 43.1509
26.436052900, 23.970, 1844.0, 42.9418
26.479518660, 23.970, 1820.0, 42.6615
26.522984420, 23.970, 1711.0, 41.3642
26.566450180, 23.970, 1787.0, 42.2729
26.609915940, 23.970, 1783.0, 42.2256
26.653381700, 23.970, 1714.0, 41.4005
26.696847460, 23.970, 1720.0, 41.4729
26.740313220, 23.970, 1772.0, 42.0951
26.783778980, 23.970, 1759.0, 41.9404
26.827244740, 23.970, 1752.0, 41.8569
26.870710500, 23.970, 1743.0, 41.7493
26.914176260, 23.970, 1815.0, 42.6028
26.957642020, 23.970, 1711.0, 41.3642
27.001107780, 23.970, 1745.0, 41.7732
27.044573540, 23.970, 1680.0, 40.9878
27.088039300, 23.970, 1705.0, 41.2916
27.131505060, 23.970, 1671.0, 40.8779
27.174970820, 23.970, 1660.0, 40.7431
27.218436580, 23.970, 1675.0, 40.9268
27.261902340, 23.970, 1682.0, 41.0122
27.305368100, 23.970, 1659.0, 40.7308
27.348833860, 23.970, 1685.0, 41.0488
27.392299620, 23.970, 1670.0, 40.8656
27.435765380, 23.970, 1636.0, 40.4475
27.479231140, 23.970, 1615.0, 40.1871
27.522696900, 23.970, 1593.0, 39.9124
27.566162660, 23.970, 1580.0, 39.7492
27.609628420, 23.970, 1634.0, 40.4228
27.653094180, 23.970, 1625.0, 40.3113
27.696559940, 23.970, 1568.0, 39.5980
27.740025700, 23.970, 1539.0, 39.2301
27.783491460, 23.970, 1551.0, 39.3827
27.826957220, 23.970, 1629.0, 40.3609
27.870422980, 23.970, 1494.0, 38.6523
27.913888740, 23.970, 1547.0, 39.3319
27.957354500, 23.970, 1588.0, 39.8497
28.000820260, 23.970, 1544.0, 39.2938
28.044286020, 23.970, 1546.0, 39.3192
28.087751780, 23.970, 1574.0, 39.6737
28.131217540, 23.970, 1496.0, 38.6782
28.174683300, 23.970, 1562.0, 39.5221
28.218149060, 23.970, 1581.0, 39.7618
28.261614820, 23.970, 1554.0, 39.4208
28.305080580, 23.970, 1514.0, 38.9102
28.348546340, 23.970, 1456.0, 38.1576
28.392012100, 23.970, 1486.0, 38.5487
28.435477860, 23.970, 1455.0, 38.1445
28.478943620, 23.970, 1558.0, 39.4715
28.522409380, 23.970, 1551.0, 39.3827
28.565875140, 23.970, 1510.0, 38.8587
28.609340900, 23.970, 1514.0, 38.9102
28.652806660, 23.970, 1521.0, 39.0000
28.696272420, 23.970, 1401.0, 37.4299
28.739738180, 23.970, 1446.0, 38.0263
28.783203940, 23.970, 1423.0, 37.7227
28.826669700, 23.970, 1467.0, 38.3014
28.870135460, 23.970, 1448.0, 38.0526
28.913601220, 23.970, 1515.0, 38.9230
28.957066980, 23.970, 1408.0, 37.5233
29.000532740, 23.970, 1510.0, 38.8587
29.043998500, 23.970, 1470.0, 38.3406
29.087464260, 23.970, 1538.0, 39.2173
29.130930020, 23.970, 1465.0, 38.2753
29.174395780, 23.970, 1443.0, 37.9868
29.217861540, 23.970, 1440.0, 37.9473
29.261327300, 23.970, 1467.0, 38.3014
29.304793060, 23.970, 1454.0, 38.1314
29.348258820, 23.970, 1416.0, 37.6298
29.391724580, 23.970, 1514.0, 38.9102
29.435190340, 23.970, 1435.0, 37.8814
29.478656100, 23.970, 1508.0, 38.8330
29.522121860, 23.970, 1490.0, 38.6005
29.565587620, 23.970, 1510.0, 38.8587
29.609053380, 23.970, 1554.0, 39.4208
29.652519140, 23.970, 1584.0, 39.7995
29.695984900, 23.970, 1735.0, 41.6533
29.739450660, 23.970, 1893.0, 43.5086
29.782916420, 23.970, 1980.0, 44.4972
29.826382180, 23.970, 1801.0, 42.4382
29.869847940, 23.970, 1591.0, 39.8873
29.913313700, 23.970, 1414.0, 37.6032
29.956779460, 23.970, 1413.0, 37.5899
30.000245220, 23.970, 1323.0, 36.3731
30.043710980, 23.970, 1343.0, 36.6470
30.087176740, 23.970, 1300.0, 36.0555
30.130642500, 23.970, 1291.0, 35.9305
30.174108260, 23.970, 1294.0, 35.9722
30.217574020, 23.970, 1334.0, 36.5240
30.261039780, 23.970, 1304.0, 36.1109
30.304505540, 23.970, 1240.0, 35.2136
30.347971300, 23.970, 1273.0, 35.6791
30.391437060, 23.970, 1228.0, 35.0428
30.434902820, 23.970, 1229.0, 35.0571
30.478368580, 23.970, 1277.0, 35.7351
30.521834340, 23.970, 1244.0, 35.2704
30.565300100, 23.970, 1210.0, 34.7851
30.608765860, 23.970, 1199.0, 34.6266
30.652231620, 23.970, 1225.0, 35.0000
30.695697380, 23.970, 1266.0, 35.5809
30.739163140, 23.970, 1167.0, 34.1614
30.782628900, 23.970, 1175.0, 34.2783
30.826094660, 23.970, 1172.0, 34.2345
30.869560420, 23.970, 1166.0, 34.1467
30.913026180, 23.970, 1186.0, 34.4384
30.956491940, 23.970, 1160.0, 34.0588
30.999957700, 23.970, 1176.0, 34.2929
31.043423460, 23.970, 1161.0, 34.0735
31.086889220, 23.970, 1149.0, 33.8969
31.130354980, 23.970, 1212.0, 34.8138
31.173820740, 23.970, 1165.0, 34.1321
31.217286500, 23.970, 1119.0, 33.4515
31.260752260, 23.970, 1177.0, 34.3074
31.304218020, 23.970, 1106.0, 33.2566
31.347683780, 23.970, 1107.0, 33.2716
31.391149540, 23.970, 1181.0, 34.3657
31.434615300, 23.970, 1153.0, 33.9559
31.478081060, 23.970, 1101.0, 33.1813
31.521546820, 23.970, 1037.0, 32.2025
31.565012580, 23.970, 1109.0, 33.3017
31.608478340, 23.970, 1075.0, 32.7872
31.651944100, 23.970, 1074.0, 32.7719
31.695409860, 23.970, 1089.0, 33.0000
31.738875620, 23.970, 1072.0, 32.7414
31.782341380, 23.970, 1071.0, 32.7261
31.825807140, 23.970, 1075.0, 32.7872
31.869272900, 23.970, 1107.0, 33.2716
31.912738660, 23.970, 1091.0, 33.0303
31.956204420, 23.970, 1087.0, 32.9697
31.999670180, 23.970, 1018.0, 31.9061
32.043135940, 23.970, 1042.0, 32.2800
32.086601700, 23.970, 1078.0, 32.8329
32.130067460, 23.970, 1012.0, 31.8119
32.173533220, 23.970, 1031.0, 32.1092
32.216998980, 23.970, 1049.0, 32.3883
32.260464740, 23.970, 975.0, 31.2250
32.303930500, 23.970, 1048.0, 32.3728
32.347396260, 23.970, 990.0, 31.4643
32.390862020, 23.970, 1040.0, 32.2490
32.434327780, 23.970, 1028.0, 32.0624
32.477793540, 23.970, 1010.0, 31.7805
32.521259300, 23.970, 995.0, 31.5436
32.564725060, 23.970, 967.0, 31.0966
32.608190820, 23.970, 1061.0, 32.5730
32.651656580, 23.970, 1010.0, 31.7805
32.695122340, 23.970, 936.0, 30.5941
32.738588100, 23.970, 936.0, 30.5941
32.782053860, 23.970, 931.0, 30.5123
32.825519620, 23.970, 971.0, 31.1609
32.868985380, 23.970, 982.0, 31.3369
32.912451140, 23.970, 903.0, 30.0500
32.955916900, 23.970, 929.0, 30.4795
32.999382660, 23.970, 988.0, 31.4325
33.042848420, 23.970, 1000.0, 31.6228
33.086314180, 23.970, 944.0, 30.7246
33.129779940, 23.970, 899.0, 29.9833
33.173245700, 23.970, 936.0, 30.5941
33.216711460, 23.970, 953.0, 30.8707
33.260177220, 23.970, 920.0, 30.3315
33.303642980, 23.970, 933.0, 30.5450
33.347108740, 23.970, 903.0, 30.0500
33.390574500, 23.970, 935.0, 30.5778
33.434040260, 23.970, 909.0, 30.1496
33.477506020, 23.970, 957.0, 30.9354
33.520971780, 23.970, 918.0, 30.2985
33.564437540, 23.970, 908.0, 30.1330
33.607903300, 23.970, 861.0, 29.3428
33.651369060, 23.970, 859.0, 29.3087
33.694834820, 23.970, 915.0, 30.2490
33.738300580, 23.970, 901.0, 30.0167
33.781766340, 23.970, 899.0, 29.9833
33.825232100, 23.970, 917.0, 30.2820
33.868697860, 23.970, 901.0, 30.0167
33.912163620, 23.970, 848.0, 29.1204
33.955629380, 23.970, 816.0, 28.5657
33.999095140, 23.970, 875.0, 29.5804
34.042560900, 23.970, 933.0, 30.5450
34.086026660, 23.970, 855.0, 29.2404
34.129492420, 23.970, 807.0, 28.4077
34.172958180, 23.970, 905.0, 30.0832
34.216423940, 23.970, 846.0, 29.0861
34.259889700, 23.970, 858.0, 29.2916
34.303355460, 23.970, 875.0, 29.5804
34.346821220, 23.970, 866.0, 29.4279
34.390286980, 23.970, 909.0, 30.1496
34.433752740, 23.970, 830.0, 28.8097
34.477218500, 23.970, 848.0, 29.1204
34.520684260, 23.970, 813.0, 28.5132
34.564150020, 23.970, 803.0, 28.3373
34.607615780, 23.970, 817.0, 28.5832
34.651081540, 23.970, 863.0, 29.3769
34.694547300, 23.970, 841.0, 29.0000
34.738013060, 23.970, 844.0, 29.0517
34.781478820, 23.970, 820.0, 28.6356
34.824944580, 23.970, 839.0, 28.9655
34.868410340, 23.970, 867.0, 29.4449
34.911876100, 23.970, 838.0, 28.9482
34.955341860, 23.970, 821.0, 28.6531
34.998807620, 23.970, 809.0, 28.4429
35.042273380, 23.970, 841.0, 29.0000
35.085739140, 23.970, 799.0, 28.2666
35.129204900, 23.970, 834.0, 28.8791
35.172670660, 23.970, 795.0, 28.1957
35.216136420, 23.970, 795.0, 28.1957
35.259602180, 23.970, 796.0, 28.2135
35.303067940, 23.970, 781.0, 27.9464
35.346533700, 23.970, 818.0, 28.6007
35.389999460, 23.970, 817.0, 28.5832
35.433465220, 23.970, 798.0, 28.2489
35.476930980, 23.970, 797.0, 28.2312
35.520396740, 23.970, 744.0, 27.2764
35.563862500, 23.970, 780.0, 27.9285
35.607328260, 23.970, 777.0, 27.8747
35.650794020, 23.970, 860.0, 29.3258
35.694259780, 23.970, 758.0, 27.5318
35.737725540, 23.970, 810.0, 28.4605
35.781191300, 23.970, 834.0, 28.8791
35.824657060, 23.970, 777.0, 27.8747
35.868122820, 23.970, 829.0, 28.7924
35.911588580, 23.970, 761.0, 27.5862
35.955054340, 23.970, 793.0, 28.1603
35.998520100, 23.970, 824.0, 28.7054
36.041985860, 23.970, 826.0, 28.7402
36.085451620, 23.970, 812.0, 28.4956
36.128917380, 23.970, 805.0, 28.3725
36.172383140, 23.970, 776.0, 27.8568
36.215848900, 23.970, 776.0, 27.8568
36.259314660, 23.970, 898.0, 29.9666
36.302780420, 23.970, 917.0, 30.2820
36.346246180, 23.970, 841.0, 29.0000
36.389711940, 23.970, 882.0, 29.6985
36.433177700, 23.970, 796.0, 28.2135
36.476643460, 23.970, 755.0, 27.4773
36.520109220, 23.970, 786.0, 28.0357
36.563574980, 23.970, 756.0, 27.4955
36.607040740, 23.970, 760.0, 27.5681
36.650506500, 23.970, 758.0, 27.5318
36.693972260, 23.970, 765.0, 27.6586
36.737438020, 23.970, 744.0, 27.2764
36.780903780, 23.970, 709.0, 26.6271
36.824369540, 23.970, 733.0, 27.0740
36.867835300, 23.970, 689.0, 26.2488
36.911301060, 23.970, 738.0, 27.1662
36.954766820, 23.970, 722.0, 26.8701
36.998232580, 23.970, 759.0, 27.5500
37.041698340, 23.970, 740.0, 27.2029
37.085164100, 23.970, 723.0, 26.8887
37.128629860, 23.970, 729.0, 27.0000
37.172095620, 23.970, 766.0, 27.6767
37.215561380, 23.970, 722.0, 26.8701
37.259027140, 23.970, 742.0, 27.2397
37.302492900, 23.970, 747.0, 27.3313
37.345958660, 23.970, 736.0, 27.1293
37.389424420, 23.970, 718.0, 26.7955
37.432890180, 23.970, 725.0, 26.9258
37.476355940, 23.970, 693.0, 26.3249
37.519821700, 23.970, 671.0, 25.9037
37.563287460, 23.970, 705.0, 26.5518
37.606753220, 23.970, 685.0, 26.1725
37.650218980, 23.970, 681.0, 26.0960
37.693684740, 23.970, 751.0, 27.4044
37.737150500, 23.970, 682.0, 26.1151
37.780616260, 23.970, 752.0, 27.4226
37.824082020, 23.970, 790.0, 28.1069
37.867547780, 23.970, 739.0, 27.1846
37.911013540, 23.970, 693.0, 26.3249
37.954479300, 23.970, 719.0, 26.8142
37.997945060, 23.970, 643.0, 25.3574
38.041410820, 23.970, 703.0, 26.5141
38.084876580, 23.970, 719.0, 26.8142
38.128342340, 23.970, 716.0, 26.7582
38.171808100, 23.970, 728.0, 26.9815
38.215273860, 23.970, 675.0, 25.9808
38.258739620, 23.970, 705.0, 26.5518
38.302205380, 23.970, 659.0, 25.6710
38.345671140, 23.970, 687.0, 26.2107
38.389136900, 23.970, 718.0, 26.7955
38.432602660, 23.970, 741.0, 27.2213
38.476068420, 23.970, 662.0, 25.7294
38.519534180, 23.970, 724.0, 26.9072
38.562999940, 23.970, 712.0, 26.6833
38.606465700, 23.970, 700.0, 26.4575
38.649931460, 23.970, 701.0, 26.4764
38.693397220, 23.970, 651.0, 25.5147
38.736862980, 23.970, 709.0, 26.6271
38.780328740, 23.970, 679.0, 26.0576
38.823794500, 23.970, 684.0, 26.1534
38.867260260, 23.970, 712.0, 26.6833
38.910726020, 23.970, 675.0, 25.9808
38.954191780, 23.970, 662.0, 25.7294
38.997657540, 23.970, 696.0, 26.3818
39.041123300, 23.970, 661.0, 25.7099
39.084589060, 23.970, 743.0, 27.2580
39.128054820, 23.970, 698.0, 26.4197
39.171520580, 23.970, 710.0, 26.6458
39.214986340, 23.970, 773.0, 27.8029
39.258452100, 23.970, 731.0, 27.0370
39.301917860, 23.970, 709.0, 26.6271
39.345383620, 23.970, 752.0, 27.4226
39.388849380, 23.970, 728.0, 26.9815
39.432315140, 23.970, 744.0, 27.2764
39.475780900, 23.970, 745.0, 27.2947
39.519246660, 23.970, 769.0, 27.7308
39.562712420, 23.970, 778.0, 27.8927
39.606178180, 23.970, 831.0, 28.8271
39.649643940, 23.970, 786.0, 28.0357
39.693109700, 23.970, 833.0, 28.8617
39.736575460, 23.970, 902.0, 30.0333
39.780041220, 23.970, 907.0, 30.1164
39.823506980, 23.970, 856.0, 29.2575
39.866972740, 23.970, 846.0, 29.0861
39.910438500, 23.970, 753.0, 27.4408
39.953904260, 23.970, 699.0, 26.4386
39.997370020, 23.970, 707.0, 26.5895
40.040835780, 23.970, 710.0, 26.6458
40.084301540, 23.970, 723.0, 26.8887
40.127767300, 23.970, 675.0, 25.9808
40.171233060, 23.970, 694.0, 26.3439
40.214698820, 23.970, 728.0, 26.9815
40.258164580, 23.970, 740.0, 27.2029
40.301630340, 23.970, 668.0, 25.8457
40.345096100, 23.970, 689.0, 26.2488
40.388561860, 23.970, 682.0, 26.1151
40.432027620, 23.970, 731.0, 27.0370
40.475493380, 23.970, 664.0, 25.7682
40.518959140, 23.970, 687.0, 26.2107
40.562424900, 23.970, 748.0, 27.3496
40.605890660, 23.970, 727.0, 26.9629
40.649356420, 23.970, 728.0, 26.9815
40.692822180, 23.970, 682.0, 26.1151
40.736287940, 23.970, 763.0, 27.6225
40.779753700, 23.970, 738.0, 27.1662
40.823219460, 23.970, 755.0, 27.4773
40.866685220, 23.970, 704.0, 26.5330
40.910150980, 23.970, 678.0, 26.0384
40.953616740, 23.970, 732.0, 27.0555
40.997082500, 23.970, 710.0, 26.6458
41.040548260, 23.970, 683.0, 26.1343
41.084014020, 23.970, 702.0, 26.4953
41.127479780, 23.970, 688.0, 26.2298
41.170945540, 23.970, 703.0, 26.5141
41.214411300, 23.970, 707.0, 26.5895
41.257877060, 23.970, 691.0, 26.2869
41.301342820, 23.970, 700.0, 26.4575
41.344808580, 23.970, 683.0, 26.1343
41.388274340, 23.970, 714.0, 26.7208
41.431740100, 23.970, 728.0, 26.9815
41.475205860, 23.970, 658.0, 25.6515
41.518671620, 23.970, 712.0, 26.6833
41.562137380, 23.970, 678.0, 26.0384
41.605603140, 23.970, 672.0, 25.9230
41.649068900, 23.970, 700.0, 26.4575
41.692534660, 23.970, 668.0, 25.8457
41.736000420, 23.970, 716.0, 26.7582
41.779466180, 23.970, 717.0, 26.7769
41.822931940, 23.970, 692.0, 26.3059
41.866397700, 23.970, 698.0, 26.4197
41.909863460, 23.970, 725.0, 26.9258
41.953329220, 23.970, 691.0, 26.2869
41.996794980, 23.970, 682.0, 26.1151
42.040260740, 23.970, 687.0, 26.2107
42.083726500, 23.970, 649.0, 25.4755
42.127192260, 23.970, 741.0, 27.2213
42.170658020, 23.970, 687.0, 26.2107
42.214123780, 23.970, 723.0, 26.8887
42.257589540, 23.970, 705.0, 26.5518
42.301055300, 23.970, 699.0, 26.4386
42.344521060, 23.970, 697.0, 26.4008
42.387986820, 23.970, 664.0, 25.7682
42.431452580, 23.970, 692.0, 26.3059
42.474918340, 23.970, 701.0, 26.4764
42.518384100, 23.970, 673.0, 25.9422
42.561849860, 23.970, 731.0, 27.0370
42.605315620, 23.970, 701.0, 26.4764
42.648781380, 23.970, 745.0, 27.2947
42.692247140, 23.970, 755.0, 27.4773
42.735712900, 23.970, 661.0, 25.7099
42.779178660, 23.970, 722.0, 26.8701
42.822644420, 23.970, 696.0, 26.3818
42.866110180, 23.970, 739.0, 27.1846
42.909575940, 23.970, 766.0, 27.6767
42.953041700, 23.970, 777.0, 27.8747
42.996507460, 23.970, 724.0, 26.9072
43.039973220, 23.970, 720.0, 26.8328
43.083438980, 23.970, 756.0, 27.4955
43.126904740, 23.970, 736.0, 27.1293
43.170370500, 23.970, 787.0, 28.0535
43.213836260, 23.970, 751.0, 27.4044
43.257302020, 23.970, 802.0, 28.3196
43.300767780, 23.970, 777.0, 27.8747
43.344233540, 23.970, 770.0, 27.7489
43.387699300, 23.970, 786.0, 28.0357
43.431165060, 23.970, 847.0, 29.1033
43.474630820, 23.970, 896.0, 29.9333
43.518096580, 23.970, 918.0, 30.2985
43.561562340, 23.970, 897.0, 29.9500
43.605028100, 23.970, 838.0, 28.9482
43.648493860, 23.970, 819.0, 28.6182
43.691959620, 23.970, 752.0, 27.4226
43.735425380, 23.970, 725.0, 26.9258
43.778891140, 23.970, 749.0, 27.3679
43.822356900, 23.970, 703.0, 26.5141
43.865822660, 23.970, 698.0, 26.4197
43.909288420, 23.970, 728.0, 26.9815
43.952754180, 23.970, 718.0, 26.7955
43.996219940, 23.970, 695.0, 26.3629
44.039685700, 23.970, 740.0, 27.2029
44.083151460, 23.970, 659.0, 25.6710
44.126617220, 23.970, 704.0, 26.5330
44.170082980, 23.970, 679.0, 26.0576
44.213548740, 23.970, 666.0, 25.8070
44.257014500, 23.970, 722.0, 26.8701
44.300480260, 23.970, 701.0, 26.4764
44.343946020, 23.970, 708.0, 26.6083
44.387411780, 23.970, 685.0, 26.1725
44.430877540, 23.970, 742.0, 27.2397
44.474343300, 23.970, 719.0, 26.8142
44.517809060, 23.970, 711.0, 26.6646
44.561274820, 23.970, 695.0, 26.3629
44.604740580, 23.970, 698.0, 26.4197
44.648206340, 23.970, 694.0, 26.3439
44.691672100, 23.970, 722.0, 26.8701
44.735137860, 23.970, 674.0, 25.9615
44.778603620, 23.970, 665.0, 25.7876
44.822069380, 23.970, 701.0, 26.4764
44.865535140, 23.970, 706.0, 26.5707
44.909000900, 23.970, 708.0, 26.6083
44.952466660, 23.970, 706.0, 26.5707
44.995932420, 23.970, 679.0, 26.0576
45.039398180, 23.970, 666.0, 25.8070
45.082863940, 23.970, 695.0, 26.3629
45.126329700, 23.970, 743.0, 27.2580
45.169795460, 23.970, 672.0, 25.9230
45.213261220, 23.970, 700.0, 26.4575
45.256726980, 23.970, 740.0, 27.2029
45.300192740, 23.970, 657.0, 25.6320
45.343658500, 23.970, 669.0, 25.8650
45.387124260, 23.970, 657.0, 25.6320
45.430590020, 23.970, 676.0, 26.0000
45.474055780, 23.970, 712.0, 26.6833
45.517521540, 23.970, 655.0, 25.5930
45.560987300, 23.970, 705.0, 26.5518
45.604453060, 23.970, 637.0, 25.2389
45.647918820, 23.970, 595.0, 24.3926
45.691384580, 23.970, 665.0, 25.7876
45.734850340, 23.970, 679.0, 26.0576
45.778316100, 23.970, 662.0, 25.7294
45.821781860, 23.970, 697.0, 26.4008
45.865247620, 23.970, 713.0, 26.7021
45.908713380, 23.970, 662.0, 25.7294
45.952179140, 23.970, 711.0, 26.6646
45.995644900, 23.970, 683.0, 26.1343
46.039110660, 23.970, 709.0, 26.6271
46.082576420, 23.970, 680.0, 26.0768
46.126042180, 23.970, 627.0, 25.0400
46.169507940, 23.970, 634.0, 25.1794
46.212973700, 23.970, 656.0, 25.6125
46.256439460, 23.970, 675.0, 25.9808
46.299905220, 23.970, 699.0, 26.4386
46.343370980, 23.970, 671.0, 25.9037
46.386836740, 23.970, 646.0, 25.4165
46.430302500, 23.970, 632.0, 25.1396
46.473768260, 23.970, 694.0, 26.3439
46.517234020, 23.970, 692.0, 26.3059
46.560699780, 23.970, 673.0, 25.9422
46.604165540, 23.970, 673.0, 25.9422
46.647631300, 23.970, 649.0, 25.4755
46.691097060, 23.970, 678.0, 26.0384
46.734562820, 23.970, 689.0, 26.2488
46.778028580, 23.970, 670.0, 25.8844
46.821494340, 23.970, 669.0, 25.8650
46.864960100, 23.970, 663.0, 25.7488
46.908425860, 23.970, 686.0, 26.1916
46.951891620, 23.970, 679.0, 26.0576
46.995357380, 23.970, 694.0, 26.3439
47.038823140, 23.970, 657.0, 25.6320
47.082288900, 23.970, 652.0, 25.5343
47.125754660, 23.970, 687.0, 26.2107
47.169220420, 23.970, 654.0, 25.5734
47.212686180, 23.970, 746.0, 27.3130
47.256151940, 23.970, 686.0, 26.1916
47.299617700, 23.970, 682.0, 26.1151
47.343083460, 23.970, 726.0, 26.9444
47.386549220, 23.970, 780.0, 27.9285
47.430014980, 23.970, 798.0, 28.2489
47.473480740, 23.970, 820.0, 28.6356
47.516946500, 23.970, 772.0, 27.7849
47.560412260, 23.970, 769.0, 27.7308
47.603878020, 23.970, 770.0, 27.7489
47.647343780, 23.970, 769.0, 27.7308
47.690809540, 23.970, 778.0, 27.8927
47.734275300, 23.970, 807.0, 28.4077
47.777741060, 23.970, 884.0, 29.7321
47.821206820, 23.970, 1024.0, 32.0000
47.864672580, 23.970, 1023.0, 31.9844
47.908138340, 23.970, 978.0, 31.2730
47.951604100, 23.970, 877.0, 29.6142
47.995069860, 23.970, 898.0, 29.9666
48.038535620, 23.970, 787.0, 28.0535
48.082001380, 23.970, 680.0, 26.0768
48.125467140, 23.970, 664.0, 25.7682
48.168932900, 23.970, 659.0, 25.6710
48.212398660, 23.970, 618.0, 24.8596
48.255864420, 23.970, 712.0, 26.6833
48.299330180, 23.970, 677.0, 26.0192
48.342795940, 23.970, 631.0, 25.1197
48.386261700, 23.970, 615.0, 24.7992
48.429727460, 23.970, 669.0, 25.8650
48.473193220, 23.970, 651.0, 25.5147
48.516658980, 23.970, 652.0, 25.5343
48.560124740, 23.970, 699.0, 26.4386
48.603590500, 23.970, 675.0, 25.9808
48.647056260, 23.970, 720.0, 26.8328
48.690522020, 23.970, 778.0, 27.8927
48.733987780, 23.970, 790.0, 28.1069
48.777453540, 23.970, 860.0, 29.3258
48.820919300, 23.970, 969.0, 31.1288
48.864385060, 23.970, 969.0, 31.1288
48.907850820, 23.970, 939.0, 30.6431
48.951316580, 23.970, 829.0, 28.7924
48.994782340, 23.970, 808.0, 28.4253
49.038248100, 23.970, 735.0, 27.1109
49.081713860, 23.970, 618.0, 24.8596
49.125179620, 23.970, 605.0, 24.5967
49.168645380, 23.970, 628.0, 25.0599
49.212111140, 23.970, 600.0, 24.4949
49.255576900, 23.970, 588.0, 24.2487
49.299042660, 23.970, 573.0, 23.9374
49.342508420, 23.970, 566.0, 23.7908
49.385974180, 23.970, 564.0, 23.7487
49.429439940, 23.970, 589.0, 24.2693
49.472905700, 23.970, 578.0, 24.0416
49.516371460, 23.970, 524.0, 22.8910
49.559837220, 23.970, 535.0, 23.1301
49.603302980, 23.970, 537.0, 23.1733
49.646768740, 23.970, 581.0, 24.1039
49.690234500, 23.970, 592.0, 24.3311
49.733700260, 23.970, 574.0, 23.9583
49.777166020, 23.970, 546.0, 23.3666
49.820631780, 23.970, 553.0, 23.5160
49.864097540, 23.970, 571.0, 23.8956
49.907563300, 23.970, 577.0, 24.0208
49.951029060, 23.970, 536.0, 23.1517
49.994494820, 23.970, 521.0, 22.8254