File: data/DSC/501023_3.csv
[Measurement conditions]
Sample identification,501203_3
Comment,
Anode material,Cu
K-Alpha1 wavelength,1.5405980
K-Alpha2 wavelength,1.5444260
Ratio K-Alpha2/K-Alpha1,0.500
Divergence slit,Fixed,0.38mm
Monochromator used,NO
Generator voltage, 40
Tube current, 15
File date and time,02/Apr/2025 10:57
Unit cell,
h k l, 0 0 0
Scan axis,Gonio
Scan range,5.002000000,49.999928040
Scan step size,0.0108664
No. of points, 4141
Scan type,CONTINUOUS
Time per step,23.970
[Scan points]
Angle, TimePerStep, Intensity, ESD
5.007433220, 23.970, 1352.0, 36.7696
5.050898980, 23.970, 1390.0, 37.2827
5.094364740, 23.970, 1346.0, 36.6879
5.137830500, 23.970, 1410.0, 37.5500
5.181296260, 23.970, 1406.0, 37.4967
5.224762020, 23.970, 1438.0, 37.9210
5.268227780, 23.970, 1452.0, 38.1051
5.311693540, 23.970, 1430.0, 37.8153
5.355159300, 23.970, 1448.0, 38.0526
5.398625060, 23.970, 1531.0, 39.1280
5.442090820, 23.970, 1516.0, 38.9358
5.485556580, 23.970, 1504.0, 38.7814
5.529022340, 23.970, 1487.0, 38.5616
5.572488100, 23.970, 1509.0, 38.8458
5.615953860, 23.970, 1522.0, 39.0128
5.659419620, 23.970, 1571.0, 39.6358
5.702885380, 23.970, 1546.0, 39.3192
5.746351140, 23.970, 1488.0, 38.5746
5.789816900, 23.970, 1675.0, 40.9268
5.833282660, 23.970, 1525.0, 39.0512
5.876748420, 23.970, 1612.0, 40.1497
5.920214180, 23.970, 1547.0, 39.3319
5.963679940, 23.970, 1584.0, 39.7995
6.007145700, 23.970, 1614.0, 40.1746
6.050611460, 23.970, 1697.0, 41.1947
6.094077220, 23.970, 1581.0, 39.7618
6.137542980, 23.970, 1652.0, 40.6448
6.181008740, 23.970, 1710.0, 41.3521
6.224474500, 23.970, 1558.0, 39.4715
6.267940260, 23.970, 1630.0, 40.3733
6.311406020, 23.970, 1604.0, 40.0500
6.354871780, 23.970, 1673.0, 40.9023
6.398337540, 23.970, 1714.0, 41.4005
6.441803300, 23.970, 1720.0, 41.4729
6.485269060, 23.970, 1691.0, 41.1218
6.528734820, 23.970, 1670.0, 40.8656
6.572200580, 23.970, 1662.0, 40.7676
6.615666340, 23.970, 1748.0, 41.8091
6.659132100, 23.970, 1765.0, 42.0119
6.702597860, 23.970, 1696.0, 41.1825
6.746063620, 23.970, 1671.0, 40.8779
6.789529380, 23.970, 1770.0, 42.0714
6.832995140, 23.970, 1693.0, 41.1461
6.876460900, 23.970, 1749.0, 41.8210
6.919926660, 23.970, 1689.0, 41.0974
6.963392420, 23.970, 1635.0, 40.4351
7.006858180, 23.970, 1693.0, 41.1461
7.050323940, 23.970, 1699.0, 41.2189
7.093789700, 23.970, 1734.0, 41.6413
7.137255460, 23.970, 1656.0, 40.6940
7.180721220, 23.970, 1778.0, 42.1663
7.224186980, 23.970, 1748.0, 41.8091
7.267652740, 23.970, 1785.0, 42.2493
7.311118500, 23.970, 1750.0, 41.8330
7.354584260, 23.970, 1727.0, 41.5572
7.398050020, 23.970, 1771.0, 42.0833
7.441515780, 23.970, 1700.0, 41.2311
7.484981540, 23.970, 1731.0, 41.6053
7.528447300, 23.970, 1724.0, 41.5211
7.571913060, 23.970, 1726.0, 41.5452
7.615378820, 23.970, 1733.0, 41.6293
7.658844580, 23.970, 1769.0, 42.0595
7.702310340, 23.970, 1787.0, 42.2729
7.745776100, 23.970, 1784.0, 42.2374
7.789241860, 23.970, 1776.0, 42.1426
7.832707620, 23.970, 1833.0, 42.8135
7.876173380, 23.970, 1708.0, 41.3280
7.919639140, 23.970, 1833.0, 42.8135
7.963104900, 23.970, 1748.0, 41.8091
8.006570660, 23.970, 1772.0, 42.0951
8.050036420, 23.970, 1813.0, 42.5793
8.093502180, 23.970, 1758.0, 41.9285
8.136967940, 23.970, 1767.0, 42.0357
8.180433700, 23.970, 1810.0, 42.5441
8.223899460, 23.970, 1764.0, 42.0000
8.267365220, 23.970, 1784.0, 42.2374
8.310830980, 23.970, 1740.0, 41.7133
8.354296740, 23.970, 1744.0, 41.7612
8.397762500, 23.970, 1786.0, 42.2611
8.441228260, 23.970, 1851.0, 43.0232
8.484694020, 23.970, 1802.0, 42.4500
8.528159780, 23.970, 1833.0, 42.8135
8.571625540, 23.970, 1857.0, 43.0929
8.615091300, 23.970, 1792.0, 42.3320
8.658557060, 23.970, 1851.0, 43.0232
8.702022820, 23.970, 1766.0, 42.0238
8.745488580, 23.970, 1751.0, 41.8450
8.788954340, 23.970, 1817.0, 42.6263
8.832420100, 23.970, 1779.0, 42.1782
8.875885860, 23.970, 1794.0, 42.3556
8.919351620, 23.970, 1833.0, 42.8135
8.962817380, 23.970, 1786.0, 42.2611
9.006283140, 23.970, 1786.0, 42.2611
9.049748900, 23.970, 1832.0, 42.8019
9.093214660, 23.970, 1844.0, 42.9418
9.136680420, 23.970, 1852.0, 43.0349
9.180146180, 23.970, 1863.0, 43.1625
9.223611940, 23.970, 1810.0, 42.5441
9.267077700, 23.970, 1827.0, 42.7434
9.310543460, 23.970, 1793.0, 42.3438
9.354009220, 23.970, 1815.0, 42.6028
9.397474980, 23.970, 1857.0, 43.0929
9.440940740, 23.970, 1872.0, 43.2666
9.484406500, 23.970, 1837.0, 42.8602
9.527872260, 23.970, 1818.0, 42.6380
9.571338020, 23.970, 1828.0, 42.7551
9.614803780, 23.970, 1810.0, 42.5441
9.658269540, 23.970, 1709.0, 41.3401
9.701735300, 23.970, 1790.0, 42.3084
9.745201060, 23.970, 1869.0, 43.2319
9.788666820, 23.970, 1838.0, 42.8719
9.832132580, 23.970, 1766.0, 42.0238
9.875598340, 23.970, 1863.0, 43.1625
9.919064100, 23.970, 1781.0, 42.2019
9.962529860, 23.970, 1733.0, 41.6293
10.005995620, 23.970, 1798.0, 42.4028
10.049461380, 23.970, 1718.0, 41.4488
10.092927140, 23.970, 1801.0, 42.4382
10.136392900, 23.970, 1835.0, 42.8369
10.179858660, 23.970, 1840.0, 42.8952
10.223324420, 23.970, 1792.0, 42.3320
10.266790180, 23.970, 1857.0, 43.0929
10.310255940, 23.970, 1841.0, 42.9069
10.353721700, 23.970, 1831.0, 42.7902
10.397187460, 23.970, 1776.0, 42.1426
10.440653220, 23.970, 1793.0, 42.3438
10.484118980, 23.970, 1805.0, 42.4853
10.527584740, 23.970, 1839.0, 42.8836
10.571050500, 23.970, 1835.0, 42.8369
10.614516260, 23.970, 1835.0, 42.8369
10.657982020, 23.970, 1818.0, 42.6380
10.701447780, 23.970, 1808.0, 42.5206
10.744913540, 23.970, 1918.0, 43.7950
10.788379300, 23.970, 1760.0, 41.9524
10.831845060, 23.970, 1861.0, 43.1393
10.875310820, 23.970, 1839.0, 42.8836
10.918776580, 23.970, 1844.0, 42.9418
10.962242340, 23.970, 1783.0, 42.2256
11.005708100, 23.970, 1845.0, 42.9535
11.049173860, 23.970, 1973.0, 44.4185
11.092639620, 23.970, 1925.0, 43.8748
11.136105380, 23.970, 1872.0, 43.2666
11.179571140, 23.970, 1870.0, 43.2435
11.223036900, 23.970, 1903.0, 43.6234
11.266502660, 23.970, 1853.0, 43.0465
11.309968420, 23.970, 1906.0, 43.6578
11.353434180, 23.970, 1841.0, 42.9069
11.396899940, 23.970, 1841.0, 42.9069
11.440365700, 23.970, 1840.0, 42.8952
11.483831460, 23.970, 1887.0, 43.4396
11.527297220, 23.970, 1939.0, 44.0341
11.570762980, 23.970, 1977.0, 44.4635
11.614228740, 23.970, 1883.0, 43.3935
11.657694500, 23.970, 1933.0, 43.9659
11.701160260, 23.970, 1998.0, 44.6990
11.744626020, 23.970, 1983.0, 44.5309
11.788091780, 23.970, 1988.0, 44.5870
11.831557540, 23.970, 1903.0, 43.6234
11.875023300, 23.970, 2021.0, 44.9555
11.918489060, 23.970, 1961.0, 44.2832
11.961954820, 23.970, 1907.0, 43.6692
12.005420580, 23.970, 1995.0, 44.6654
12.048886340, 23.970, 1967.0, 44.3509
12.092352100, 23.970, 2004.0, 44.7661
12.135817860, 23.970, 1975.0, 44.4410
12.179283620, 23.970, 1959.0, 44.2606
12.222749380, 23.970, 1977.0, 44.4635
12.266215140, 23.970, 1886.0, 43.4281
12.309680900, 23.970, 1927.0, 43.8976
12.353146660, 23.970, 1969.0, 44.3734
12.396612420, 23.970, 2086.0, 45.6727
12.440078180, 23.970, 2027.0, 45.0222
12.483543940, 23.970, 2025.0, 45.0000
12.527009700, 23.970, 2042.0, 45.1885
12.570475460, 23.970, 2101.0, 45.8367
12.613941220, 23.970, 2040.0, 45.1664
12.657406980, 23.970, 2028.0, 45.0333
12.700872740, 23.970, 2028.0, 45.0333
12.744338500, 23.970, 2089.0, 45.7056
12.787804260, 23.970, 2093.0, 45.7493
12.831270020, 23.970, 2216.0, 47.0744
12.874735780, 23.970, 2158.0, 46.4543
12.918201540, 23.970, 2115.0, 45.9891
12.961667300, 23.970, 2155.0, 46.4220
13.005133060, 23.970, 2134.0, 46.1952
13.048598820, 23.970, 2242.0, 47.3498
13.092064580, 23.970, 2215.0, 47.0638
13.135530340, 23.970, 2211.0, 47.0213
13.178996100, 23.970, 2143.0, 46.2925
13.222461860, 23.970, 2344.0, 48.4149
13.265927620, 23.970, 2288.0, 47.8330
13.309393380, 23.970, 2185.0, 46.7440
13.352859140, 23.970, 2267.0, 47.6130
13.396324900, 23.970, 2377.0, 48.7545
13.439790660, 23.970, 2239.0, 47.3181
13.483256420, 23.970, 2207.0, 46.9787
13.526722180, 23.970, 2263.0, 47.5710
13.570187940, 23.970, 2320.0, 48.1664
13.613653700, 23.970, 2362.0, 48.6004
13.657119460, 23.970, 2384.0, 48.8262
13.700585220, 23.970, 2365.0, 48.6313
13.744050980, 23.970, 2364.0, 48.6210
13.787516740, 23.970, 2395.0, 48.9387
13.830982500, 23.970, 2395.0, 48.9387
13.874448260, 23.970, 2405.0, 49.0408
13.917914020, 23.970, 2550.0, 50.4975
13.961379780, 23.970, 2407.0, 49.0612
14.004845540, 23.970, 2483.0, 49.8297
14.048311300, 23.970, 2485.0, 49.8498
14.091777060, 23.970, 2479.0, 49.7896
14.135242820, 23.970, 2565.0, 50.6458
14.178708580, 23.970, 2607.0, 51.0588
14.222174340, 23.970, 2496.0, 49.9600
14.265640100, 23.970, 2598.0, 50.9706
14.309105860, 23.970, 2621.0, 51.1957
14.352571620, 23.970, 2648.0, 51.4587
14.396037380, 23.970, 2615.0, 51.1371
14.439503140, 23.970, 2679.0, 51.7591
14.482968900, 23.970, 2636.0, 51.3420
14.526434660, 23.970, 2690.0, 51.8652
14.569900420, 23.970, 2680.0, 51.7687
14.613366180, 23.970, 2806.0, 52.9717
14.656831940, 23.970, 2778.0, 52.7067
14.700297700, 23.970, 2838.0, 53.2729
14.743763460, 23.970, 2899.0, 53.8424
14.787229220, 23.970, 2911.0, 53.9537
14.830694980, 23.970, 2896.0, 53.8145
14.874160740, 23.970, 2962.0, 54.4243
14.917626500, 23.970, 2901.0, 53.8609
14.961092260, 23.970, 2937.0, 54.1941
15.004558020, 23.970, 2957.0, 54.3783
15.048023780, 23.970, 2973.0, 54.5252
15.091489540, 23.970, 3049.0, 55.2178
15.134955300, 23.970, 2988.0, 54.6626
15.178421060, 23.970, 3116.0, 55.8211
15.221886820, 23.970, 3111.0, 55.7763
15.265352580, 23.970, 3057.0, 55.2901
15.308818340, 23.970, 3108.0, 55.7494
15.352284100, 23.970, 3021.0, 54.9636
15.395749860, 23.970, 3125.0, 55.9017
15.439215620, 23.970, 3351.0, 57.8878
15.482681380, 23.970, 3261.0, 57.1052
15.526147140, 23.970, 3340.0, 57.7927
15.569612900, 23.970, 3240.0, 56.9210
15.613078660, 23.970, 3364.0, 58.0000
15.656544420, 23.970, 3318.0, 57.6021
15.700010180, 23.970, 3392.0, 58.2409
15.743475940, 23.970, 3319.0, 57.6108
15.786941700, 23.970, 3574.0, 59.7829
15.830407460, 23.970, 3547.0, 59.5567
15.873873220, 23.970, 3463.0, 58.8473
15.917338980, 23.970, 3544.0, 59.5315
15.960804740, 23.970, 3645.0, 60.3738
16.004270500, 23.970, 3515.0, 59.2874
16.047736260, 23.970, 3723.0, 61.0164
16.091202020, 23.970, 3679.0, 60.6548
16.134667780, 23.970, 3628.0, 60.2329
16.178133540, 23.970, 3745.0, 61.1964
16.221599300, 23.970, 3814.0, 61.7576
16.265065060, 23.970, 3766.0, 61.3677
16.308530820, 23.970, 3829.0, 61.8789
16.351996580, 23.970, 3832.0, 61.9032
16.395462340, 23.970, 3973.0, 63.0317
16.438928100, 23.970, 3985.0, 63.1269
16.482393860, 23.970, 3899.0, 62.4420
16.525859620, 23.970, 4018.0, 63.3877
16.569325380, 23.970, 4039.0, 63.5531
16.612791140, 23.970, 3999.0, 63.2376
16.656256900, 23.970, 4185.0, 64.6916
16.699722660, 23.970, 4195.0, 64.7688
16.743188420, 23.970, 4161.0, 64.5058
16.786654180, 23.970, 4263.0, 65.2917
16.830119940, 23.970, 4345.0, 65.9166
16.873585700, 23.970, 4187.0, 64.7070
16.917051460, 23.970, 4265.0, 65.3070
16.960517220, 23.970, 4295.0, 65.5362
17.003982980, 23.970, 4369.0, 66.0984
17.047448740, 23.970, 4380.0, 66.1816
17.090914500, 23.970, 4380.0, 66.1816
17.134380260, 23.970, 4374.0, 66.1362
17.177846020, 23.970, 4462.0, 66.7982
17.221311780, 23.970, 4494.0, 67.0373
17.264777540, 23.970, 4685.0, 68.4471
17.308243300, 23.970, 4694.0, 68.5128
17.351709060, 23.970, 4666.0, 68.3081
17.395174820, 23.970, 4691.0, 68.4909
17.438640580, 23.970, 4812.0, 69.3686
17.482106340, 23.970, 4776.0, 69.1086
17.525572100, 23.970, 4829.0, 69.4910
17.569037860, 23.970, 4921.0, 70.1498
17.612503620, 23.970, 4874.0, 69.8140
17.655969380, 23.970, 5051.0, 71.0704
17.699435140, 23.970, 5089.0, 71.3372
17.742900900, 23.970, 5036.0, 70.9648
17.786366660, 23.970, 5105.0, 71.4493
17.829832420, 23.970, 5207.0, 72.1595
17.873298180, 23.970, 5355.0, 73.1779
17.916763940, 23.970, 5206.0, 72.1526
17.960229700, 23.970, 5215.0, 72.2150
18.003695460, 23.970, 5421.0, 73.6274
18.047161220, 23.970, 5582.0, 74.7128
18.090626980, 23.970, 5643.0, 75.1199
18.134092740, 23.970, 5754.0, 75.8551
18.177558500, 23.970, 5918.0, 76.9285
18.221024260, 23.970, 6190.0, 78.6766
18.264490020, 23.970, 6263.0, 79.1391
18.307955780, 23.970, 6519.0, 80.7403
18.351421540, 23.970, 6677.0, 81.7129
18.394887300, 23.970, 7107.0, 84.3030
18.438353060, 23.970, 7368.0, 85.8371
18.481818820, 23.970, 7519.0, 86.7122
18.525284580, 23.970, 8084.0, 89.9111
18.568750340, 23.970, 8533.0, 92.3742
18.612216100, 23.970, 9095.0, 95.3677
18.655681860, 23.970, 9408.0, 96.9948
18.699147620, 23.970, 9788.0, 98.9343
18.742613380, 23.970, 9999.0, 99.9950
18.786079140, 23.970, 10263.0, 101.3065
18.829544900, 23.970, 10282.0, 101.4002
18.873010660, 23.970, 10252.0, 101.2522
18.916476420, 23.970, 10058.0, 100.2896
18.959942180, 23.970, 9698.0, 98.4784
19.003407940, 23.970, 9213.0, 95.9844
19.046873700, 23.970, 8922.0, 94.4563
19.090339460, 23.970, 8431.0, 91.8205
19.133805220, 23.970, 8061.0, 89.7831
19.177270980, 23.970, 7640.0, 87.4071
19.220736740, 23.970, 7244.0, 85.1117
19.264202500, 23.970, 7193.0, 84.8116
19.307668260, 23.970, 6846.0, 82.7406
19.351134020, 23.970, 6513.0, 80.7032
19.394599780, 23.970, 6358.0, 79.7371
19.438065540, 23.970, 6365.0, 79.7810
19.481531300, 23.970, 6159.0, 78.4793
19.524997060, 23.970, 6030.0, 77.6531
19.568462820, 23.970, 5943.0, 77.0909
19.611928580, 23.970, 5824.0, 76.3151
19.655394340, 23.970, 5728.0, 75.6836
19.698860100, 23.970, 5664.0, 75.2596
19.742325860, 23.970, 5725.0, 75.6637
19.785791620, 23.970, 5578.0, 74.6860
19.829257380, 23.970, 5567.0, 74.6123
19.872723140, 23.970, 5591.0, 74.7730
19.916188900, 23.970, 5478.0, 74.0135
19.959654660, 23.970, 5415.0, 73.5867
20.003120420, 23.970, 5561.0, 74.5721
20.046586180, 23.970, 5467.0, 73.9392
20.090051940, 23.970, 5382.0, 73.3621
20.133517700, 23.970, 5601.0, 74.8398
20.176983460, 23.970, 5324.0, 72.9657
20.220449220, 23.970, 5379.0, 73.3417
20.263914980, 23.970, 5412.0, 73.5663
20.307380740, 23.970, 5710.0, 75.5645
20.350846500, 23.970, 5683.0, 75.3857
20.394312260, 23.970, 5680.0, 75.3658
20.437778020, 23.970, 5838.0, 76.4068
20.481243780, 23.970, 5834.0, 76.3806
20.524709540, 23.970, 5939.0, 77.0649
20.568175300, 23.970, 6109.0, 78.1601
20.611641060, 23.970, 6231.0, 78.9367
20.655106820, 23.970, 6193.0, 78.6956
20.698572580, 23.970, 6201.0, 78.7464
20.742038340, 23.970, 6435.0, 80.2185
20.785504100, 23.970, 6239.0, 78.9873
20.828969860, 23.970, 6316.0, 79.4733
20.872435620, 23.970, 6212.0, 78.8162
20.915901380, 23.970, 6155.0, 78.4538
20.959367140, 23.970, 6060.0, 77.8460
21.002832900, 23.970, 5984.0, 77.3563
21.046298660, 23.970, 5688.0, 75.4188
21.089764420, 23.970, 5771.0, 75.9671
21.133230180, 23.970, 5681.0, 75.3724
21.176695940, 23.970, 5428.0, 73.6750
21.220161700, 23.970, 5317.0, 72.9178
21.263627460, 23.970, 5266.0, 72.5672
21.307093220, 23.970, 5189.0, 72.0347
21.350558980, 23.970, 5106.0, 71.4563
21.394024740, 23.970, 5061.0, 71.1407
21.437490500, 23.970, 4914.0, 70.0999
21.480956260, 23.970, 4825.0, 69.4622
21.524422020, 23.970, 4985.0, 70.6045
21.567887780, 23.970, 4694.0, 68.5128
21.611353540, 23.970, 4763.0, 69.0145
21.654819300, 23.970, 4779.0, 69.1303
21.698285060, 23.970, 4652.0, 68.2056
21.741750820, 23.970, 4623.0, 67.9926
21.785216580, 23.970, 4647.0, 68.1689
21.828682340, 23.970, 4674.0, 68.3667
21.872148100, 23.970, 4665.0, 68.3008
21.915613860, 23.970, 4641.0, 68.1249
21.959079620, 23.970, 4854.0, 69.6707
22.002545380, 23.970, 4735.0, 68.8113
22.046011140, 23.970, 4920.0, 70.1427
22.089476900, 23.970, 4873.0, 69.8069
22.132942660, 23.970, 5124.0, 71.5821
22.176408420, 23.970, 5200.0, 72.1110
22.219874180, 23.970, 5390.0, 73.4166
22.263339940, 23.970, 5495.0, 74.1283
22.306805700, 23.970, 5597.0, 74.8131
22.350271460, 23.970, 5678.0, 75.3525
22.393737220, 23.970, 5917.0, 76.9220
22.437202980, 23.970, 5945.0, 77.1038
22.480668740, 23.970, 6227.0, 78.9113
22.524134500, 23.970, 6219.0, 78.8606
22.567600260, 23.970, 6225.0, 78.8987
22.611066020, 23.970, 6365.0, 79.7810
22.654531780, 23.970, 6170.0, 78.5493
22.697997540, 23.970, 5990.0, 77.3951
22.741463300, 23.970, 6204.0, 78.7655
22.784929060, 23.970, 5952.0, 77.1492
22.828394820, 23.970, 5890.0, 76.7463
22.871860580, 23.970, 5791.0, 76.0986
22.915326340, 23.970, 5754.0, 75.8551
22.958792100, 23.970, 5656.0, 75.2064
23.002257860, 23.970, 5514.0, 74.2563
23.045723620, 23.970, 5251.0, 72.4638
23.089189380, 23.970, 5187.0, 72.0208
23.132655140, 23.970, 4999.0, 70.7036
23.176120900, 23.970, 4853.0, 69.6635
23.219586660, 23.970, 4707.0, 68.6076
23.263052420, 23.970, 4562.0, 67.5426
23.306518180, 23.970, 4494.0, 67.0373
23.349983940, 23.970, 4276.0, 65.3911
23.393449700, 23.970, 4023.0, 63.4271
23.436915460, 23.970, 4174.0, 64.6065
23.480381220, 23.970, 4020.0, 63.4035
23.523846980, 23.970, 3853.0, 62.0725
23.567312740, 23.970, 3729.0, 61.0655
23.610778500, 23.970, 3753.0, 61.2617
23.654244260, 23.970, 3619.0, 60.1581
23.697710020, 23.970, 3502.0, 59.1777
23.741175780, 23.970, 3460.0, 58.8218
23.784641540, 23.970, 3505.0, 59.2030
23.828107300, 23.970, 3372.0, 58.0689
23.871573060, 23.970, 3296.0, 57.4108
23.915038820, 23.970, 3243.0, 56.9473
23.958504580, 23.970, 3212.0, 56.6745
24.001970340, 23.970, 3169.0, 56.2939
24.045436100, 23.970, 3085.0, 55.5428
24.088901860, 23.970, 3109.0, 55.7584
24.132367620, 23.970, 2890.0, 53.7587
24.175833380, 23.970, 2899.0, 53.8424
24.219299140, 23.970, 2858.0, 53.4603
24.262764900, 23.970, 2901.0, 53.8609
24.306230660, 23.970, 2733.0, 52.2781
24.349696420, 23.970, 2740.0, 52.3450
24.393162180, 23.970, 2842.0, 53.3104
24.436627940, 23.970, 2749.0, 52.4309
24.480093700, 23.970, 2726.0, 52.2111
24.523559460, 23.970, 2683.0, 51.7977
24.567025220, 23.970, 2659.0, 51.5655
24.610490980, 23.970, 2574.0, 50.7346
24.653956740, 23.970, 2620.0, 51.1859
24.697422500, 23.970, 2605.0, 51.0392
24.740888260, 23.970, 2522.0, 50.2195
24.784354020, 23.970, 2487.0, 49.8698
24.827819780, 23.970, 2533.0, 50.3289
24.871285540, 23.970, 2513.0, 50.1298
24.914751300, 23.970, 2492.0, 49.9199
24.958217060, 23.970, 2425.0, 49.2443
25.001682820, 23.970, 2428.0, 49.2747
25.045148580, 23.970, 2432.0, 49.3153
25.088614340, 23.970, 2463.0, 49.6286
25.132080100, 23.970, 2434.0, 49.3356
25.175545860, 23.970, 2495.0, 49.9500
25.219011620, 23.970, 2518.0, 50.1797
25.262477380, 23.970, 2516.0, 50.1597
25.305943140, 23.970, 2412.0, 49.1121
25.349408900, 23.970, 2375.0, 48.7340
25.392874660, 23.970, 2308.0, 48.0416
25.436340420, 23.970, 2396.0, 48.9490
25.479806180, 23.970, 2362.0, 48.6004
25.523271940, 23.970, 2312.0, 48.0833
25.566737700, 23.970, 2333.0, 48.3011
25.610203460, 23.970, 2349.0, 48.4665
25.653669220, 23.970, 2349.0, 48.4665
25.697134980, 23.970, 2400.0, 48.9898
25.740600740, 23.970, 2301.0, 47.9687
25.784066500, 23.970, 2162.0, 46.4973
25.827532260, 23.970, 2359.0, 48.5695
25.870998020, 23.970, 2279.0, 47.7389
25.914463780, 23.970, 2196.0, 46.8615
25.957929540, 23.970, 2248.0, 47.4131
26.001395300, 23.970, 2290.0, 47.8539
26.044861060, 23.970, 2239.0, 47.3181
26.088326820, 23.970, 2186.0, 46.7547
26.131792580, 23.970, 2177.0, 46.6583
26.175258340, 23.970, 2170.0, 46.5833
26.218724100, 23.970, 2139.0, 46.2493
26.262189860, 23.970, 2200.0, 46.9042
26.305655620, 23.970, 2089.0, 45.7056
26.349121380, 23.970, 2143.0, 46.2925
26.392587140, 23.970, 2001.0, 44.7325
26.436052900, 23.970, 2128.0, 46.1303
26.479518660, 23.970, 2153.0, 46.4004
26.522984420, 23.970, 2062.0, 45.4093
26.566450180, 23.970, 2085.0, 45.6618
26.609915940, 23.970, 2074.0, 45.5412
26.653381700, 23.970, 2061.0, 45.3982
26.696847460, 23.970, 2141.0, 46.2709
26.740313220, 23.970, 2013.0, 44.8665
26.783778980, 23.970, 2145.0, 46.3141
26.827244740, 23.970, 2031.0, 45.0666
26.870710500, 23.970, 2071.0, 45.5082
26.914176260, 23.970, 2001.0, 44.7325
26.957642020, 23.970, 1965.0, 44.3283
27.001107780, 23.970, 1992.0, 44.6318
27.044573540, 23.970, 1962.0, 44.2945
27.088039300, 23.970, 2040.0, 45.1664
27.131505060, 23.970, 1913.0, 43.7379
27.174970820, 23.970, 1977.0, 44.4635
27.218436580, 23.970, 1955.0, 44.2154
27.261902340, 23.970, 1886.0, 43.4281
27.305368100, 23.970, 1939.0, 44.0341
27.348833860, 23.970, 1967.0, 44.3509
27.392299620, 23.970, 1988.0, 44.5870
27.435765380, 23.970, 1904.0, 43.6348
27.479231140, 23.970, 1993.0, 44.6430
27.522696900, 23.970, 1959.0, 44.2606
27.566162660, 23.970, 1880.0, 43.3590
27.609628420, 23.970, 2021.0, 44.9555
27.653094180, 23.970, 1930.0, 43.9318
27.696559940, 23.970, 1970.0, 44.3847
27.740025700, 23.970, 1957.0, 44.2380
27.783491460, 23.970, 1961.0, 44.2832
27.826957220, 23.970, 1973.0, 44.4185
27.870422980, 23.970, 1990.0, 44.6094
27.913888740, 23.970, 1955.0, 44.2154
27.957354500, 23.970, 2064.0, 45.4313
28.000820260, 23.970, 1949.0, 44.1475
28.044286020, 23.970, 2045.0, 45.2217
28.087751780, 23.970, 2061.0, 45.3982
28.131217540, 23.970, 2114.0, 45.9783
28.174683300, 23.970, 2144.0, 46.3033
28.218149060, 23.970, 2197.0, 46.8722
28.261614820, 23.970, 2206.0, 46.9681
28.305080580, 23.970, 2311.0, 48.0729
28.348546340, 23.970, 2312.0, 48.0833
28.392012100, 23.970, 2397.0, 48.9592
28.435477860, 23.970, 2532.0, 50.3190
28.478943620, 23.970, 2602.0, 51.0098
28.522409380, 23.970, 2558.0, 50.5767
28.565875140, 23.970, 2625.0, 51.2348
28.609340900, 23.970, 2695.0, 51.9134
28.652806660, 23.970, 2709.0, 52.0481
28.696272420, 23.970, 2723.0, 52.1824
28.739738180, 23.970, 2836.0, 53.2541
28.783203940, 23.970, 2764.0, 52.5738
28.826669700, 23.970, 2636.0, 51.3420
28.870135460, 23.970, 2676.0, 51.7301
28.913601220, 23.970, 2664.0, 51.6140
28.957066980, 23.970, 2556.0, 50.5569
29.000532740, 23.970, 2600.0, 50.9902
29.043998500, 23.970, 2686.0, 51.8266
29.087464260, 23.970, 2547.0, 50.4678
29.130930020, 23.970, 2553.0, 50.5272
29.174395780, 23.970, 2614.0, 51.1273
29.217861540, 23.970, 2753.0, 52.4690
29.261327300, 23.970, 3101.0, 55.6866
29.304793060, 23.970, 3747.0, 61.2127
29.348258820, 23.970, 5051.0, 71.0704
29.391724580, 23.970, 5260.0, 72.5259
29.435190340, 23.970, 4026.0, 63.4508
29.478656100, 23.970, 3117.0, 55.8301
29.522121860, 23.970, 2286.0, 47.8121
29.565587620, 23.970, 2170.0, 46.5833
29.609053380, 23.970, 2120.0, 46.0435
29.652519140, 23.970, 2037.0, 45.1331
29.695984900, 23.970, 1834.0, 42.8252
29.739450660, 23.970, 1940.0, 44.0454
29.782916420, 23.970, 1754.0, 41.8808
29.826382180, 23.970, 1757.0, 41.9166
29.869847940, 23.970, 1795.0, 42.3674
29.913313700, 23.970, 1686.0, 41.0609
29.956779460, 23.970, 1773.0, 42.1070
30.000245220, 23.970, 1788.0, 42.2847
30.043710980, 23.970, 1832.0, 42.8019
30.087176740, 23.970, 1734.0, 41.6413
30.130642500, 23.970, 1739.0, 41.7013
30.174108260, 23.970, 1724.0, 41.5211
30.217574020, 23.970, 1635.0, 40.4351
30.261039780, 23.970, 1624.0, 40.2989
30.304505540, 23.970, 1666.0, 40.8167
30.347971300, 23.970, 1682.0, 41.0122
30.391437060, 23.970, 1588.0, 39.8497
30.434902820, 23.970, 1567.0, 39.5854
30.478368580, 23.970, 1553.0, 39.4081
30.521834340, 23.970, 1623.0, 40.2865
30.565300100, 23.970, 1564.0, 39.5474
30.608765860, 23.970, 1587.0, 39.8372
30.652231620, 23.970, 1544.0, 39.2938
30.695697380, 23.970, 1559.0, 39.4842
30.739163140, 23.970, 1530.0, 39.1152
30.782628900, 23.970, 1515.0, 38.9230
30.826094660, 23.970, 1505.0, 38.7943
30.869560420, 23.970, 1525.0, 39.0512
30.913026180, 23.970, 1435.0, 37.8814
30.956491940, 23.970, 1443.0, 37.9868
30.999957700, 23.970, 1414.0, 37.6032
31.043423460, 23.970, 1469.0, 38.3275
31.086889220, 23.970, 1387.0, 37.2424
31.130354980, 23.970, 1399.0, 37.4032
31.173820740, 23.970, 1422.0, 37.7094
31.217286500, 23.970, 1365.0, 36.9459
31.260752260, 23.970, 1360.0, 36.8782
31.304218020, 23.970, 1411.0, 37.5633
31.347683780, 23.970, 1446.0, 38.0263
31.391149540, 23.970, 1465.0, 38.2753
31.434615300, 23.970, 1442.0, 37.9737
31.478081060, 23.970, 1430.0, 37.8153
31.521546820, 23.970, 1331.0, 36.4829
31.565012580, 23.970, 1383.0, 37.1887
31.608478340, 23.970, 1334.0, 36.5240
31.651944100, 23.970, 1299.0, 36.0416
31.695409860, 23.970, 1357.0, 36.8375
31.738875620, 23.970, 1306.0, 36.1386
31.782341380, 23.970, 1306.0, 36.1386
31.825807140, 23.970, 1341.0, 36.6197
31.869272900, 23.970, 1294.0, 35.9722
31.912738660, 23.970, 1339.0, 36.5923
31.956204420, 23.970, 1346.0, 36.6879
31.999670180, 23.970, 1344.0, 36.6606
32.043135940, 23.970, 1362.0, 36.9053
32.086601700, 23.970, 1275.0, 35.7071
32.130067460, 23.970, 1295.0, 35.9861
32.173533220, 23.970, 1219.0, 34.9142
32.216998980, 23.970, 1322.0, 36.3593
32.260464740, 23.970, 1321.0, 36.3456
32.303930500, 23.970, 1340.0, 36.6060
32.347396260, 23.970, 1344.0, 36.6606
32.390862020, 23.970, 1332.0, 36.4966
32.434327780, 23.970, 1333.0, 36.5103
32.477793540, 23.970, 1301.0, 36.0694
32.521259300, 23.970, 1313.0, 36.2353
32.564725060, 23.970, 1321.0, 36.3456
32.608190820, 23.970, 1333.0, 36.5103
32.651656580, 23.970, 1314.0, 36.2491
32.695122340, 23.970, 1329.0, 36.4555
32.738588100, 23.970, 1333.0, 36.5103
32.782053860, 23.970, 1326.0, 36.4143
32.825519620, 23.970, 1257.0, 35.4542
32.868985380, 23.970, 1282.0, 35.8050
32.912451140, 23.970, 1318.0, 36.3043
32.955916900, 23.970, 1269.0, 35.6230
32.999382660, 23.970, 1318.0, 36.3043
33.042848420, 23.970, 1403.0, 37.4566
33.086314180, 23.970, 1311.0, 36.2077
33.129779940, 23.970, 1300.0, 36.0555
33.173245700, 23.970, 1312.0, 36.2215
33.216711460, 23.970, 1236.0, 35.1568
33.260177220, 23.970, 1216.0, 34.8712
33.303642980, 23.970, 1250.0, 35.3553
33.347108740, 23.970, 1292.0, 35.9444
33.390574500, 23.970, 1236.0, 35.1568
33.434040260, 23.970, 1252.0, 35.3836
33.477506020, 23.970, 1252.0, 35.3836
33.520971780, 23.970, 1232.0, 35.0999
33.564437540, 23.970, 1260.0, 35.4965
33.607903300, 23.970, 1254.0, 35.4119
33.651369060, 23.970, 1216.0, 34.8712
33.694834820, 23.970, 1218.0, 34.8999
33.738300580, 23.970, 1174.0, 34.2637
33.781766340, 23.970, 1249.0, 35.3412
33.825232100, 23.970, 1122.0, 33.4963
33.868697860, 23.970, 1197.0, 34.5977
33.912163620, 23.970, 1137.0, 33.7194
33.955629380, 23.970, 1059.0, 32.5423
33.999095140, 23.970, 1144.0, 33.8231
34.042560900, 23.970, 1160.0, 34.0588
34.086026660, 23.970, 1074.0, 32.7719
34.129492420, 23.970, 1172.0, 34.2345
34.172958180, 23.970, 1085.0, 32.9393
34.216423940, 23.970, 1123.0, 33.5112
34.259889700, 23.970, 1023.0, 31.9844
34.303355460, 23.970, 1060.0, 32.5576
34.346821220, 23.970, 1075.0, 32.7872
34.390286980, 23.970, 1061.0, 32.5730
34.433752740, 23.970, 1065.0, 32.6343
34.477218500, 23.970, 1020.0, 31.9374
34.520684260, 23.970, 1085.0, 32.9393
34.564150020, 23.970, 1074.0, 32.7719
34.607615780, 23.970, 1092.0, 33.0454
34.651081540, 23.970, 1056.0, 32.4962
34.694547300, 23.970, 1021.0, 31.9531
34.738013060, 23.970, 998.0, 31.5911
34.781478820, 23.970, 1038.0, 32.2180
34.824944580, 23.970, 1025.0, 32.0156
34.868410340, 23.970, 978.0, 31.2730
34.911876100, 23.970, 986.0, 31.4006
34.955341860, 23.970, 909.0, 30.1496
34.998807620, 23.970, 1008.0, 31.7490
35.042273380, 23.970, 984.0, 31.3688
35.085739140, 23.970, 959.0, 30.9677
35.129204900, 23.970, 954.0, 30.8869
35.172670660, 23.970, 955.0, 30.9031
35.216136420, 23.970, 987.0, 31.4166
35.259602180, 23.970, 992.0, 31.4960
35.303067940, 23.970, 980.0, 31.3050
35.346533700, 23.970, 974.0, 31.2090
35.389999460, 23.970, 949.0, 30.8058
35.433465220, 23.970, 973.0, 31.1929
35.476930980, 23.970, 948.0, 30.7896
35.520396740, 23.970, 970.0, 31.1448
35.563862500, 23.970, 977.0, 31.2570
35.607328260, 23.970, 1036.0, 32.1870
35.650794020, 23.970, 972.0, 31.1769
35.694259780, 23.970, 996.0, 31.5595
35.737725540, 23.970, 958.0, 30.9516
35.781191300, 23.970, 1038.0, 32.2180
35.824657060, 23.970, 1140.0, 33.7639
35.868122820, 23.970, 1137.0, 33.7194
35.911588580, 23.970, 1288.0, 35.8887
35.955054340, 23.970, 1320.0, 36.3318
35.998520100, 23.970, 1168.0, 34.1760
36.041985860, 23.970, 1085.0, 32.9393
36.085451620, 23.970, 1014.0, 31.8434
36.128917380, 23.970, 942.0, 30.6920
36.172383140, 23.970, 1011.0, 31.7962
36.215848900, 23.970, 916.0, 30.2655
36.259314660, 23.970, 961.0, 31.0000
36.302780420, 23.970, 924.0, 30.3974
36.346246180, 23.970, 990.0, 31.4643
36.389711940, 23.970, 960.0, 30.9839
36.433177700, 23.970, 959.0, 30.9677
36.476643460, 23.970, 953.0, 30.8707
36.520109220, 23.970, 902.0, 30.0333
36.563574980, 23.970, 929.0, 30.4795
36.607040740, 23.970, 812.0, 28.4956
36.650506500, 23.970, 958.0, 30.9516
36.693972260, 23.970, 935.0, 30.5778
36.737438020, 23.970, 999.0, 31.6070
36.780903780, 23.970, 984.0, 31.3688
36.824369540, 23.970, 967.0, 31.0966
36.867835300, 23.970, 919.0, 30.3150
36.911301060, 23.970, 997.0, 31.5753
36.954766820, 23.970, 960.0, 30.9839
36.998232580, 23.970, 965.0, 31.0644
37.041698340, 23.970, 910.0, 30.1662
37.085164100, 23.970, 986.0, 31.4006
37.128629860, 23.970, 921.0, 30.3480
37.172095620, 23.970, 888.0, 29.7993
37.215561380, 23.970, 927.0, 30.4467
37.259027140, 23.970, 941.0, 30.6757
37.302492900, 23.970, 960.0, 30.9839
37.345958660, 23.970, 911.0, 30.1828
37.389424420, 23.970, 983.0, 31.3528
37.432890180, 23.970, 894.0, 29.8998
37.476355940, 23.970, 1007.0, 31.7333
37.519821700, 23.970, 942.0, 30.6920
37.563287460, 23.970, 961.0, 31.0000
37.606753220, 23.970, 946.0, 30.7571
37.650218980, 23.970, 1011.0, 31.7962
37.693684740, 23.970, 997.0, 31.5753
37.737150500, 23.970, 1024.0, 32.0000
37.780616260, 23.970, 980.0, 31.3050
37.824082020, 23.970, 1030.0, 32.0936
37.867547780, 23.970, 1023.0, 31.9844
37.911013540, 23.970, 1072.0, 32.7414
37.954479300, 23.970, 1043.0, 32.2955
37.997945060, 23.970, 1146.0, 33.8526
38.041410820, 23.970, 1225.0, 35.0000
38.084876580, 23.970, 1447.0, 38.0395
38.128342340, 23.970, 1837.0, 42.8602
38.171808100, 23.970, 1686.0, 41.0609
38.215273860, 23.970, 1552.0, 39.3954
38.258739620, 23.970, 1483.0, 38.5097
38.302205380, 23.970, 1246.0, 35.2987
38.345671140, 23.970, 1116.0, 33.4066
38.389136900, 23.970, 1092.0, 33.0454
38.432602660, 23.970, 1070.0, 32.7109
38.476068420, 23.970, 1145.0, 33.8378
38.519534180, 23.970, 1118.0, 33.4365
38.562999940, 23.970, 1066.0, 32.6497
38.606465700, 23.970, 1040.0, 32.2490
38.649931460, 23.970, 1133.0, 33.6601
38.693397220, 23.970, 1159.0, 34.0441
38.736862980, 23.970, 1099.0, 33.1512
38.780328740, 23.970, 1083.0, 32.9090
38.823794500, 23.970, 1188.0, 34.4674
38.867260260, 23.970, 1143.0, 33.8083
38.910726020, 23.970, 1116.0, 33.4066
38.954191780, 23.970, 1109.0, 33.3017
38.997657540, 23.970, 1187.0, 34.4529
39.041123300, 23.970, 1132.0, 33.6452
39.084589060, 23.970, 1140.0, 33.7639
39.128054820, 23.970, 1090.0, 33.0151
39.171520580, 23.970, 1213.0, 34.8281
39.214986340, 23.970, 1157.0, 34.0147
39.258452100, 23.970, 1294.0, 35.9722
39.301917860, 23.970, 1326.0, 36.4143
39.345383620, 23.970, 1571.0, 39.6358
39.388849380, 23.970, 1687.0, 41.0731
39.432315140, 23.970, 1429.0, 37.8021
39.475780900, 23.970, 1404.0, 37.4700
39.519246660, 23.970, 1198.0, 34.6121
39.562712420, 23.970, 1103.0, 33.2114
39.606178180, 23.970, 1117.0, 33.4215
39.649643940, 23.970, 1017.0, 31.8904
39.693109700, 23.970, 1092.0, 33.0454
39.736575460, 23.970, 1007.0, 31.7333
39.780041220, 23.970, 945.0, 30.7409
39.823506980, 23.970, 1036.0, 32.1870
39.866972740, 23.970, 963.0, 31.0322
39.910438500, 23.970, 984.0, 31.3688
39.953904260, 23.970, 952.0, 30.8545
39.997370020, 23.970, 992.0, 31.4960
40.040835780, 23.970, 969.0, 31.1288
40.084301540, 23.970, 1013.0, 31.8277
40.127767300, 23.970, 995.0, 31.5436
40.171233060, 23.970, 966.0, 31.0805
40.214698820, 23.970, 1003.0, 31.6702
40.258164580, 23.970, 1003.0, 31.6702
40.301630340, 23.970, 996.0, 31.5595
40.345096100, 23.970, 987.0, 31.4166
40.388561860, 23.970, 970.0, 31.1448
40.432027620, 23.970, 948.0, 30.7896
40.475493380, 23.970, 972.0, 31.1769
40.518959140, 23.970, 895.0, 29.9166
40.562424900, 23.970, 1030.0, 32.0936
40.605890660, 23.970, 941.0, 30.6757
40.649356420, 23.970, 1008.0, 31.7490
40.692822180, 23.970, 1063.0, 32.6037
40.736287940, 23.970, 1001.0, 31.6386
40.779753700, 23.970, 986.0, 31.4006
40.823219460, 23.970, 1007.0, 31.7333
40.866685220, 23.970, 988.0, 31.4325
40.910150980, 23.970, 1005.0, 31.7017
40.953616740, 23.970, 940.0, 30.6594
40.997082500, 23.970, 1010.0, 31.7805
41.040548260, 23.970, 973.0, 31.1929
41.084014020, 23.970, 993.0, 31.5119
41.127479780, 23.970, 1067.0, 32.6650
41.170945540, 23.970, 988.0, 31.4325
41.214411300, 23.970, 924.0, 30.3974
41.257877060, 23.970, 996.0, 31.5595
41.301342820, 23.970, 999.0, 31.6070
41.344808580, 23.970, 1032.0, 32.1248
41.388274340, 23.970, 951.0, 30.8383
41.431740100, 23.970, 981.0, 31.3209
41.475205860, 23.970, 970.0, 31.1448
41.518671620, 23.970, 981.0, 31.3209
41.562137380, 23.970, 924.0, 30.3974
41.605603140, 23.970, 942.0, 30.6920
41.649068900, 23.970, 984.0, 31.3688
41.692534660, 23.970, 990.0, 31.4643
41.736000420, 23.970, 956.0, 30.9192
41.779466180, 23.970, 952.0, 30.8545
41.822931940, 23.970, 937.0, 30.6105
41.866397700, 23.970, 897.0, 29.9500
41.909863460, 23.970, 911.0, 30.1828
41.953329220, 23.970, 876.0, 29.5973
41.996794980, 23.970, 955.0, 30.9031
42.040260740, 23.970, 941.0, 30.6757
42.083726500, 23.970, 936.0, 30.5941
42.127192260, 23.970, 902.0, 30.0333
42.170658020, 23.970, 908.0, 30.1330
42.214123780, 23.970, 901.0, 30.0167
42.257589540, 23.970, 932.0, 30.5287
42.301055300, 23.970, 900.0, 30.0000
42.344521060, 23.970, 902.0, 30.0333
42.387986820, 23.970, 929.0, 30.4795
42.431452580, 23.970, 928.0, 30.4631
42.474918340, 23.970, 941.0, 30.6757
42.518384100, 23.970, 903.0, 30.0500
42.561849860, 23.970, 922.0, 30.3645
42.605315620, 23.970, 880.0, 29.6648
42.648781380, 23.970, 904.0, 30.0666
42.692247140, 23.970, 891.0, 29.8496
42.735712900, 23.970, 907.0, 30.1164
42.779178660, 23.970, 925.0, 30.4138
42.822644420, 23.970, 877.0, 29.6142
42.866110180, 23.970, 893.0, 29.8831
42.909575940, 23.970, 924.0, 30.3974
42.953041700, 23.970, 964.0, 31.0483
42.996507460, 23.970, 944.0, 30.7246
43.039973220, 23.970, 1039.0, 32.2335
43.083438980, 23.970, 1269.0, 35.6230
43.126904740, 23.970, 1420.0, 37.6829
43.170370500, 23.970, 1320.0, 36.3318
43.213836260, 23.970, 1129.0, 33.6006
43.257302020, 23.970, 1140.0, 33.7639
43.300767780, 23.970, 1027.0, 32.0468
43.344233540, 23.970, 901.0, 30.0167
43.387699300, 23.970, 856.0, 29.2575
43.431165060, 23.970, 846.0, 29.0861
43.474630820, 23.970, 917.0, 30.2820
43.518096580, 23.970, 875.0, 29.5804
43.561562340, 23.970, 806.0, 28.3901
43.605028100, 23.970, 856.0, 29.2575
43.648493860, 23.970, 903.0, 30.0500
43.691959620, 23.970, 888.0, 29.7993
43.735425380, 23.970, 869.0, 29.4788
43.778891140, 23.970, 820.0, 28.6356
43.822356900, 23.970, 826.0, 28.7402
43.865822660, 23.970, 924.0, 30.3974
43.909288420, 23.970, 858.0, 29.2916
43.952754180, 23.970, 909.0, 30.1496
43.996219940, 23.970, 818.0, 28.6007
44.039685700, 23.970, 817.0, 28.5832
44.083151460, 23.970, 830.0, 28.8097
44.126617220, 23.970, 874.0, 29.5635
44.170082980, 23.970, 898.0, 29.9666
44.213548740, 23.970, 873.0, 29.5466
44.257014500, 23.970, 1008.0, 31.7490
44.300480260, 23.970, 1054.0, 32.4654
44.343946020, 23.970, 1147.0, 33.8674
44.387411780, 23.970, 1029.0, 32.0780
44.430877540, 23.970, 1030.0, 32.0936
44.474343300, 23.970, 973.0, 31.1929
44.517809060, 23.970, 938.0, 30.6268
44.561274820, 23.970, 950.0, 30.8221
44.604740580, 23.970, 819.0, 28.6182
44.648206340, 23.970, 883.0, 29.7153
44.691672100, 23.970, 904.0, 30.0666
44.735137860, 23.970, 883.0, 29.7153
44.778603620, 23.970, 817.0, 28.5832
44.822069380, 23.970, 849.0, 29.1376
44.865535140, 23.970, 857.0, 29.2746
44.909000900, 23.970, 824.0, 28.7054
44.952466660, 23.970, 837.0, 28.9310
44.995932420, 23.970, 853.0, 29.2062
45.039398180, 23.970, 853.0, 29.2062
45.082863940, 23.970, 864.0, 29.3939
45.126329700, 23.970, 813.0, 28.5132
45.169795460, 23.970, 832.0, 28.8444
45.213261220, 23.970, 860.0, 29.3258
45.256726980, 23.970, 809.0, 28.4429
45.300192740, 23.970, 846.0, 29.0861
45.343658500, 23.970, 889.0, 29.8161
45.387124260, 23.970, 875.0, 29.5804
45.430590020, 23.970, 848.0, 29.1204
45.474055780, 23.970, 853.0, 29.2062
45.517521540, 23.970, 809.0, 28.4429
45.560987300, 23.970, 830.0, 28.8097
45.604453060, 23.970, 854.0, 29.2233
45.647918820, 23.970, 805.0, 28.3725
45.691384580, 23.970, 810.0, 28.4605
45.734850340, 23.970, 872.0, 29.5296
45.778316100, 23.970, 881.0, 29.6816
45.821781860, 23.970, 813.0, 28.5132
45.865247620, 23.970, 825.0, 28.7228
45.908713380, 23.970, 797.0, 28.2312
45.952179140, 23.970, 829.0, 28.7924
45.995644900, 23.970, 842.0, 29.0172
46.039110660, 23.970, 820.0, 28.6356
46.082576420, 23.970, 848.0, 29.1204
46.126042180, 23.970, 840.0, 28.9828
46.169507940, 23.970, 813.0, 28.5132
46.212973700, 23.970, 799.0, 28.2666
46.256439460, 23.970, 836.0, 28.9137
46.299905220, 23.970, 810.0, 28.4605
46.343370980, 23.970, 866.0, 29.4279
46.386836740, 23.970, 814.0, 28.5307
46.430302500, 23.970, 829.0, 28.7924
46.473768260, 23.970, 833.0, 28.8617
46.517234020, 23.970, 845.0, 29.0689
46.560699780, 23.970, 838.0, 28.9482
46.604165540, 23.970, 844.0, 29.0517
46.647631300, 23.970, 833.0, 28.8617
46.691097060, 23.970, 901.0, 30.0167
46.734562820, 23.970, 897.0, 29.9500
46.778028580, 23.970, 843.0, 29.0345
46.821494340, 23.970, 885.0, 29.7489
46.864960100, 23.970, 854.0, 29.2233
46.908425860, 23.970, 975.0, 31.2250
46.951891620, 23.970, 976.0, 31.2410
46.995357380, 23.970, 1009.0, 31.7648
47.038823140, 23.970, 1073.0, 32.7567
47.082288900, 23.970, 1125.0, 33.5410
47.125754660, 23.970, 1103.0, 33.2114
47.169220420, 23.970, 1095.0, 33.0908
47.212686180, 23.970, 1103.0, 33.2114
47.256151940, 23.970, 1082.0, 32.8938
47.299617700, 23.970, 1059.0, 32.5423
47.343083460, 23.970, 1178.0, 34.3220
47.386549220, 23.970, 1295.0, 35.9861
47.430014980, 23.970, 1546.0, 39.3192
47.473480740, 23.970, 1783.0, 42.2256
47.516946500, 23.970, 1579.0, 39.7366
47.560412260, 23.970, 1483.0, 38.5097
47.603878020, 23.970, 1435.0, 37.8814
47.647343780, 23.970, 1293.0, 35.9583
47.690809540, 23.970, 1002.0, 31.6544
47.734275300, 23.970, 1030.0, 32.0936
47.777741060, 23.970, 1004.0, 31.6860
47.821206820, 23.970, 916.0, 30.2655
47.864672580, 23.970, 979.0, 31.2890
47.908138340, 23.970, 923.0, 30.3809
47.951604100, 23.970, 975.0, 31.2250
47.995069860, 23.970, 966.0, 31.0805
48.038535620, 23.970, 1003.0, 31.6702
48.082001380, 23.970, 903.0, 30.0500
48.125467140, 23.970, 904.0, 30.0666
48.168932900, 23.970, 914.0, 30.2324
48.212398660, 23.970, 917.0, 30.2820
48.255864420, 23.970, 855.0, 29.2404
48.299330180, 23.970, 989.0, 31.4484
48.342795940, 23.970, 1078.0, 32.8329
48.386261700, 23.970, 1068.0, 32.6803
48.429727460, 23.970, 1381.0, 37.1618
48.473193220, 23.970, 1516.0, 38.9358
48.516658980, 23.970, 1435.0, 37.8814
48.560124740, 23.970, 1272.0, 35.6651
48.603590500, 23.970, 1211.0, 34.7994
48.647056260, 23.970, 1069.0, 32.6956
48.690522020, 23.970, 880.0, 29.6648
48.733987780, 23.970, 901.0, 30.0167
48.777453540, 23.970, 841.0, 29.0000
48.820919300, 23.970, 804.0, 28.3549
48.864385060, 23.970, 817.0, 28.5832
48.907850820, 23.970, 830.0, 28.8097
48.951316580, 23.970, 834.0, 28.8791
48.994782340, 23.970, 808.0, 28.4253
49.038248100, 23.970, 823.0, 28.6880
49.081713860, 23.970, 775.0, 27.8388
49.125179620, 23.970, 809.0, 28.4429
49.168645380, 23.970, 713.0, 26.7021
49.212111140, 23.970, 710.0, 26.6458
49.255576900, 23.970, 748.0, 27.3496
49.299042660, 23.970, 769.0, 27.7308
49.342508420, 23.970, 763.0, 27.6225
49.385974180, 23.970, 756.0, 27.4955
49.429439940, 23.970, 706.0, 26.5707
49.472905700, 23.970, 754.0, 27.4591
49.516371460, 23.970, 756.0, 27.4955
49.559837220, 23.970, 808.0, 28.4253
49.603302980, 23.970, 759.0, 27.5500
49.646768740, 23.970, 725.0, 26.9258
49.690234500, 23.970, 745.0, 27.2947
49.733700260, 23.970, 768.0, 27.7128
49.777166020, 23.970, 722.0, 26.8701
49.820631780, 23.970, 747.0, 27.3313
49.864097540, 23.970, 756.0, 27.4955
49.907563300, 23.970, 776.0, 27.8568
49.951029060, 23.970, 765.0, 27.6586
49.994494820, 23.970, 756.0, 27.4955