File: data/DSC/501023_2.csv
[Measurement conditions]
Sample identification,501023_2
Comment,
Anode material,Cu
K-Alpha1 wavelength,1.5405980
K-Alpha2 wavelength,1.5444260
Ratio K-Alpha2/K-Alpha1,0.500
Divergence slit,Fixed,0.38mm
Monochromator used,NO
Generator voltage, 40
Tube current, 15
File date and time,26/Feb/2025 11:21
Unit cell,
h k l, 0 0 0
Scan axis,Gonio
Scan range,5.002000000,49.999928040
Scan step size,0.0108664
No. of points, 4141
Scan type,CONTINUOUS
Time per step,23.970
[Scan points]
Angle, TimePerStep, Intensity, ESD
5.007433220, 23.970, 1043.0, 32.2955
5.050898980, 23.970, 1050.0, 32.4037
5.094364740, 23.970, 1114.0, 33.3766
5.137830500, 23.970, 1064.0, 32.6190
5.181296260, 23.970, 1053.0, 32.4500
5.224762020, 23.970, 1046.0, 32.3419
5.268227780, 23.970, 1122.0, 33.4963
5.311693540, 23.970, 1101.0, 33.1813
5.355159300, 23.970, 1132.0, 33.6452
5.398625060, 23.970, 1107.0, 33.2716
5.442090820, 23.970, 1113.0, 33.3617
5.485556580, 23.970, 1209.0, 34.7707
5.529022340, 23.970, 1138.0, 33.7343
5.572488100, 23.970, 1179.0, 34.3366
5.615953860, 23.970, 1168.0, 34.1760
5.659419620, 23.970, 1192.0, 34.5254
5.702885380, 23.970, 1159.0, 34.0441
5.746351140, 23.970, 1250.0, 35.3553
5.789816900, 23.970, 1181.0, 34.3657
5.833282660, 23.970, 1223.0, 34.9714
5.876748420, 23.970, 1131.0, 33.6303
5.920214180, 23.970, 1203.0, 34.6843
5.963679940, 23.970, 1212.0, 34.8138
6.007145700, 23.970, 1265.0, 35.5668
6.050611460, 23.970, 1283.0, 35.8190
6.094077220, 23.970, 1189.0, 34.4819
6.137542980, 23.970, 1198.0, 34.6121
6.181008740, 23.970, 1250.0, 35.3553
6.224474500, 23.970, 1316.0, 36.2767
6.267940260, 23.970, 1170.0, 34.2053
6.311406020, 23.970, 1304.0, 36.1109
6.354871780, 23.970, 1247.0, 35.3129
6.398337540, 23.970, 1364.0, 36.9324
6.441803300, 23.970, 1267.0, 35.5949
6.485269060, 23.970, 1357.0, 36.8375
6.528734820, 23.970, 1317.0, 36.2905
6.572200580, 23.970, 1334.0, 36.5240
6.615666340, 23.970, 1390.0, 37.2827
6.659132100, 23.970, 1409.0, 37.5366
6.702597860, 23.970, 1318.0, 36.3043
6.746063620, 23.970, 1344.0, 36.6606
6.789529380, 23.970, 1450.0, 38.0789
6.832995140, 23.970, 1365.0, 36.9459
6.876460900, 23.970, 1372.0, 37.0405
6.919926660, 23.970, 1352.0, 36.7696
6.963392420, 23.970, 1502.0, 38.7556
7.006858180, 23.970, 1384.0, 37.2022
7.050323940, 23.970, 1435.0, 37.8814
7.093789700, 23.970, 1434.0, 37.8682
7.137255460, 23.970, 1430.0, 37.8153
7.180721220, 23.970, 1464.0, 38.2623
7.224186980, 23.970, 1444.0, 38.0000
7.267652740, 23.970, 1393.0, 37.3229
7.311118500, 23.970, 1486.0, 38.5487
7.354584260, 23.970, 1408.0, 37.5233
7.398050020, 23.970, 1519.0, 38.9744
7.441515780, 23.970, 1444.0, 38.0000
7.484981540, 23.970, 1546.0, 39.3192
7.528447300, 23.970, 1482.0, 38.4968
7.571913060, 23.970, 1464.0, 38.2623
7.615378820, 23.970, 1518.0, 38.9615
7.658844580, 23.970, 1585.0, 39.8121
7.702310340, 23.970, 1491.0, 38.6135
7.745776100, 23.970, 1565.0, 39.5601
7.789241860, 23.970, 1467.0, 38.3014
7.832707620, 23.970, 1563.0, 39.5348
7.876173380, 23.970, 1507.0, 38.8201
7.919639140, 23.970, 1576.0, 39.6989
7.963104900, 23.970, 1567.0, 39.5854
8.006570660, 23.970, 1549.0, 39.3573
8.050036420, 23.970, 1611.0, 40.1373
8.093502180, 23.970, 1588.0, 39.8497
8.136967940, 23.970, 1625.0, 40.3113
8.180433700, 23.970, 1585.0, 39.8121
8.223899460, 23.970, 1500.0, 38.7298
8.267365220, 23.970, 1509.0, 38.8458
8.310830980, 23.970, 1580.0, 39.7492
8.354296740, 23.970, 1590.0, 39.8748
8.397762500, 23.970, 1614.0, 40.1746
8.441228260, 23.970, 1614.0, 40.1746
8.484694020, 23.970, 1653.0, 40.6571
8.528159780, 23.970, 1554.0, 39.4208
8.571625540, 23.970, 1639.0, 40.4846
8.615091300, 23.970, 1648.0, 40.5956
8.658557060, 23.970, 1668.0, 40.8412
8.702022820, 23.970, 1604.0, 40.0500
8.745488580, 23.970, 1696.0, 41.1825
8.788954340, 23.970, 1584.0, 39.7995
8.832420100, 23.970, 1623.0, 40.2865
8.875885860, 23.970, 1666.0, 40.8167
8.919351620, 23.970, 1665.0, 40.8044
8.962817380, 23.970, 1629.0, 40.3609
9.006283140, 23.970, 1661.0, 40.7554
9.049748900, 23.970, 1715.0, 41.4126
9.093214660, 23.970, 1669.0, 40.8534
9.136680420, 23.970, 1603.0, 40.0375
9.180146180, 23.970, 1658.0, 40.7185
9.223611940, 23.970, 1669.0, 40.8534
9.267077700, 23.970, 1690.0, 41.1096
9.310543460, 23.970, 1695.0, 41.1704
9.354009220, 23.970, 1721.0, 41.4849
9.397474980, 23.970, 1687.0, 41.0731
9.440940740, 23.970, 1763.0, 41.9881
9.484406500, 23.970, 1739.0, 41.7013
9.527872260, 23.970, 1682.0, 41.0122
9.571338020, 23.970, 1717.0, 41.4367
9.614803780, 23.970, 1585.0, 39.8121
9.658269540, 23.970, 1781.0, 42.2019
9.701735300, 23.970, 1718.0, 41.4488
9.745201060, 23.970, 1732.0, 41.6173
9.788666820, 23.970, 1733.0, 41.6293
9.832132580, 23.970, 1740.0, 41.7133
9.875598340, 23.970, 1760.0, 41.9524
9.919064100, 23.970, 1747.0, 41.7971
9.962529860, 23.970, 1726.0, 41.5452
10.005995620, 23.970, 1663.0, 40.7799
10.049461380, 23.970, 1714.0, 41.4005
10.092927140, 23.970, 1651.0, 40.6325
10.136392900, 23.970, 1784.0, 42.2374
10.179858660, 23.970, 1752.0, 41.8569
10.223324420, 23.970, 1728.0, 41.5692
10.266790180, 23.970, 1766.0, 42.0238
10.310255940, 23.970, 1786.0, 42.2611
10.353721700, 23.970, 1845.0, 42.9535
10.397187460, 23.970, 1723.0, 41.5090
10.440653220, 23.970, 1794.0, 42.3556
10.484118980, 23.970, 1842.0, 42.9185
10.527584740, 23.970, 1823.0, 42.6966
10.571050500, 23.970, 1816.0, 42.6146
10.614516260, 23.970, 1852.0, 43.0349
10.657982020, 23.970, 1870.0, 43.2435
10.701447780, 23.970, 1841.0, 42.9069
10.744913540, 23.970, 1834.0, 42.8252
10.788379300, 23.970, 1852.0, 43.0349
10.831845060, 23.970, 1775.0, 42.1307
10.875310820, 23.970, 1847.0, 42.9767
10.918776580, 23.970, 1828.0, 42.7551
10.962242340, 23.970, 1871.0, 43.2551
11.005708100, 23.970, 1834.0, 42.8252
11.049173860, 23.970, 1850.0, 43.0116
11.092639620, 23.970, 1763.0, 41.9881
11.136105380, 23.970, 1960.0, 44.2719
11.179571140, 23.970, 1857.0, 43.0929
11.223036900, 23.970, 1908.0, 43.6807
11.266502660, 23.970, 1868.0, 43.2204
11.309968420, 23.970, 1898.0, 43.5660
11.353434180, 23.970, 1915.0, 43.7607
11.396899940, 23.970, 1953.0, 44.1928
11.440365700, 23.970, 1857.0, 43.0929
11.483831460, 23.970, 1979.0, 44.4860
11.527297220, 23.970, 1932.0, 43.9545
11.570762980, 23.970, 1949.0, 44.1475
11.614228740, 23.970, 1955.0, 44.2154
11.657694500, 23.970, 1973.0, 44.4185
11.701160260, 23.970, 1892.0, 43.4971
11.744626020, 23.970, 1927.0, 43.8976
11.788091780, 23.970, 2021.0, 44.9555
11.831557540, 23.970, 2012.0, 44.8553
11.875023300, 23.970, 1926.0, 43.8862
11.918489060, 23.970, 2013.0, 44.8665
11.961954820, 23.970, 2028.0, 45.0333
12.005420580, 23.970, 2030.0, 45.0555
12.048886340, 23.970, 1920.0, 43.8178
12.092352100, 23.970, 2023.0, 44.9778
12.135817860, 23.970, 2011.0, 44.8442
12.179283620, 23.970, 1982.0, 44.5197
12.222749380, 23.970, 1918.0, 43.7950
12.266215140, 23.970, 2071.0, 45.5082
12.309680900, 23.970, 2066.0, 45.4533
12.353146660, 23.970, 2069.0, 45.4863
12.396612420, 23.970, 2003.0, 44.7549
12.440078180, 23.970, 2041.0, 45.1774
12.483543940, 23.970, 2072.0, 45.5192
12.527009700, 23.970, 2161.0, 46.4866
12.570475460, 23.970, 2098.0, 45.8039
12.613941220, 23.970, 2209.0, 47.0000
12.657406980, 23.970, 2040.0, 45.1664
12.700872740, 23.970, 2146.0, 46.3249
12.744338500, 23.970, 2137.0, 46.2277
12.787804260, 23.970, 2277.0, 47.7179
12.831270020, 23.970, 2290.0, 47.8539
12.874735780, 23.970, 2123.0, 46.0760
12.918201540, 23.970, 2270.0, 47.6445
12.961667300, 23.970, 2224.0, 47.1593
13.005133060, 23.970, 2282.0, 47.7703
13.048598820, 23.970, 2260.0, 47.5395
13.092064580, 23.970, 2310.0, 48.0625
13.135530340, 23.970, 2267.0, 47.6130
13.178996100, 23.970, 2307.0, 48.0312
13.222461860, 23.970, 2365.0, 48.6313
13.265927620, 23.970, 2355.0, 48.5283
13.309393380, 23.970, 2372.0, 48.7032
13.352859140, 23.970, 2356.0, 48.5386
13.396324900, 23.970, 2410.0, 49.0918
13.439790660, 23.970, 2413.0, 49.1223
13.483256420, 23.970, 2418.0, 49.1732
13.526722180, 23.970, 2431.0, 49.3052
13.570187940, 23.970, 2528.0, 50.2792
13.613653700, 23.970, 2438.0, 49.3761
13.657119460, 23.970, 2415.0, 49.1426
13.700585220, 23.970, 2455.0, 49.5480
13.744050980, 23.970, 2472.0, 49.7192
13.787516740, 23.970, 2553.0, 50.5272
13.830982500, 23.970, 2654.0, 51.5170
13.874448260, 23.970, 2569.0, 50.6853
13.917914020, 23.970, 2680.0, 51.7687
13.961379780, 23.970, 2642.0, 51.4004
14.004845540, 23.970, 2651.0, 51.4879
14.048311300, 23.970, 2728.0, 52.2303
14.091777060, 23.970, 2693.0, 51.8941
14.135242820, 23.970, 2657.0, 51.5461
14.178708580, 23.970, 2653.0, 51.5073
14.222174340, 23.970, 2744.0, 52.3832
14.265640100, 23.970, 2776.0, 52.6878
14.309105860, 23.970, 2866.0, 53.5350
14.352571620, 23.970, 2839.0, 53.2823
14.396037380, 23.970, 2880.0, 53.6656
14.439503140, 23.970, 2905.0, 53.8981
14.482968900, 23.970, 2916.0, 54.0000
14.526434660, 23.970, 2873.0, 53.6004
14.569900420, 23.970, 2975.0, 54.5436
14.613366180, 23.970, 2954.0, 54.3507
14.656831940, 23.970, 3039.0, 55.1271
14.700297700, 23.970, 3137.0, 56.0089
14.743763460, 23.970, 3078.0, 55.4797
14.787229220, 23.970, 3116.0, 55.8211
14.830694980, 23.970, 3110.0, 55.7674
14.874160740, 23.970, 3104.0, 55.7136
14.917626500, 23.970, 3129.0, 55.9375
14.961092260, 23.970, 3165.0, 56.2583
15.004558020, 23.970, 3227.0, 56.8067
15.048023780, 23.970, 3236.0, 56.8859
15.091489540, 23.970, 3347.0, 57.8533
15.134955300, 23.970, 3318.0, 57.6021
15.178421060, 23.970, 3325.0, 57.6628
15.221886820, 23.970, 3424.0, 58.5150
15.265352580, 23.970, 3325.0, 57.6628
15.308818340, 23.970, 3427.0, 58.5406
15.352284100, 23.970, 3518.0, 59.3127
15.395749860, 23.970, 3499.0, 59.1523
15.439215620, 23.970, 3551.0, 59.5903
15.482681380, 23.970, 3591.0, 59.9250
15.526147140, 23.970, 3631.0, 60.2578
15.569612900, 23.970, 3647.0, 60.3904
15.613078660, 23.970, 3776.0, 61.4492
15.656544420, 23.970, 3653.0, 60.4401
15.700010180, 23.970, 3648.0, 60.3987
15.743475940, 23.970, 3698.0, 60.8112
15.786941700, 23.970, 3789.0, 61.5549
15.830407460, 23.970, 3866.0, 62.1772
15.873873220, 23.970, 3828.0, 61.8708
15.917338980, 23.970, 3845.0, 62.0081
15.960804740, 23.970, 3788.0, 61.5467
16.004270500, 23.970, 3910.0, 62.5300
16.047736260, 23.970, 3972.0, 63.0238
16.091202020, 23.970, 4013.0, 63.3482
16.134667780, 23.970, 3931.0, 62.6977
16.178133540, 23.970, 4102.0, 64.0469
16.221599300, 23.970, 4072.0, 63.8122
16.265065060, 23.970, 4194.0, 64.7611
16.308530820, 23.970, 4296.0, 65.5439
16.351996580, 23.970, 4310.0, 65.6506
16.395462340, 23.970, 4287.0, 65.4752
16.438928100, 23.970, 4506.0, 67.1267
16.482393860, 23.970, 4449.0, 66.7008
16.525859620, 23.970, 4382.0, 66.1967
16.569325380, 23.970, 4396.0, 66.3023
16.612791140, 23.970, 4477.0, 66.9104
16.656256900, 23.970, 4421.0, 66.4906
16.699722660, 23.970, 4492.0, 67.0224
16.743188420, 23.970, 4527.0, 67.2830
16.786654180, 23.970, 4647.0, 68.1689
16.830119940, 23.970, 4676.0, 68.3813
16.873585700, 23.970, 4867.0, 69.7639
16.917051460, 23.970, 4705.0, 68.5930
16.960517220, 23.970, 4730.0, 68.7750
17.003982980, 23.970, 4807.0, 69.3325
17.047448740, 23.970, 4785.0, 69.1737
17.090914500, 23.970, 4968.0, 70.4840
17.134380260, 23.970, 5047.0, 71.0422
17.177846020, 23.970, 4930.0, 70.2140
17.221311780, 23.970, 4918.0, 70.1285
17.264777540, 23.970, 5107.0, 71.4633
17.308243300, 23.970, 4951.0, 70.3633
17.351709060, 23.970, 5091.0, 71.3512
17.395174820, 23.970, 5149.0, 71.7565
17.438640580, 23.970, 5234.0, 72.3464
17.482106340, 23.970, 5406.0, 73.5255
17.525572100, 23.970, 5468.0, 73.9459
17.569037860, 23.970, 5606.0, 74.8732
17.612503620, 23.970, 5603.0, 74.8532
17.655969380, 23.970, 5886.0, 76.7203
17.699435140, 23.970, 5732.0, 75.7100
17.742900900, 23.970, 6006.0, 77.4984
17.786366660, 23.970, 6298.0, 79.3599
17.829832420, 23.970, 6465.0, 80.4052
17.873298180, 23.970, 6695.0, 81.8230
17.916763940, 23.970, 7054.0, 83.9881
17.960229700, 23.970, 7310.0, 85.4985
18.003695460, 23.970, 7592.0, 87.1321
18.047161220, 23.970, 8091.0, 89.9500
18.090626980, 23.970, 8415.0, 91.7333
18.134092740, 23.970, 8670.0, 93.1128
18.177558500, 23.970, 9352.0, 96.7057
18.221024260, 23.970, 9526.0, 97.6012
18.264490020, 23.970, 9811.0, 99.0505
18.307955780, 23.970, 10163.0, 100.8117
18.351421540, 23.970, 10283.0, 101.4051
18.394887300, 23.970, 10356.0, 101.7644
18.438353060, 23.970, 10279.0, 101.3854
18.481818820, 23.970, 9637.0, 98.1682
18.525284580, 23.970, 9474.0, 97.3345
18.568750340, 23.970, 9282.0, 96.3431
18.612216100, 23.970, 9021.0, 94.9789
18.655681860, 23.970, 8359.0, 91.4276
18.699147620, 23.970, 8231.0, 90.7249
18.742613380, 23.970, 7638.0, 87.3957
18.786079140, 23.970, 7455.0, 86.3423
18.829544900, 23.970, 7184.0, 84.7585
18.873010660, 23.970, 6823.0, 82.6015
18.916476420, 23.970, 6602.0, 81.2527
18.959942180, 23.970, 6453.0, 80.3306
19.003407940, 23.970, 6265.0, 79.1518
19.046873700, 23.970, 6287.0, 79.2906
19.090339460, 23.970, 6077.0, 77.9551
19.133805220, 23.970, 5942.0, 77.0844
19.177270980, 23.970, 5850.0, 76.4853
19.220736740, 23.970, 5675.0, 75.3326
19.264202500, 23.970, 5770.0, 75.9605
19.307668260, 23.970, 5640.0, 75.0999
19.351134020, 23.970, 5709.0, 75.5579
19.394599780, 23.970, 5617.0, 74.9466
19.438065540, 23.970, 5584.0, 74.7262
19.481531300, 23.970, 5549.0, 74.4916
19.524997060, 23.970, 5423.0, 73.6410
19.568462820, 23.970, 5386.0, 73.3894
19.611928580, 23.970, 5374.0, 73.3076
19.655394340, 23.970, 5494.0, 74.1215
19.698860100, 23.970, 5587.0, 74.7462
19.742325860, 23.970, 5576.0, 74.6726
19.785791620, 23.970, 5721.0, 75.6373
19.829257380, 23.970, 5748.0, 75.8156
19.872723140, 23.970, 5688.0, 75.4188
19.916188900, 23.970, 5909.0, 76.8700
19.959654660, 23.970, 5973.0, 77.2852
20.003120420, 23.970, 5986.0, 77.3692
20.046586180, 23.970, 5900.0, 76.8115
20.090051940, 23.970, 5937.0, 77.0519
20.133517700, 23.970, 6150.0, 78.4219
20.176983460, 23.970, 6340.0, 79.6241
20.220449220, 23.970, 6353.0, 79.7057
20.263914980, 23.970, 6335.0, 79.5927
20.307380740, 23.970, 6321.0, 79.5047
20.350846500, 23.970, 6324.0, 79.5236
20.394312260, 23.970, 6049.0, 77.7753
20.437778020, 23.970, 6316.0, 79.4733
20.481243780, 23.970, 6064.0, 77.8717
20.524709540, 23.970, 6088.0, 78.0256
20.568175300, 23.970, 6132.0, 78.3071
20.611641060, 23.970, 5678.0, 75.3525
20.655106820, 23.970, 5816.0, 76.2627
20.698572580, 23.970, 5660.0, 75.2330
20.742038340, 23.970, 5519.0, 74.2900
20.785504100, 23.970, 5401.0, 73.4915
20.828969860, 23.970, 5367.0, 73.2598
20.872435620, 23.970, 5088.0, 71.3302
20.915901380, 23.970, 5136.0, 71.6659
20.959367140, 23.970, 5029.0, 70.9154
21.002832900, 23.970, 4938.0, 70.2709
21.046298660, 23.970, 4918.0, 70.1285
21.089764420, 23.970, 4810.0, 69.3542
21.133230180, 23.970, 4811.0, 69.3614
21.176695940, 23.970, 4688.0, 68.4690
21.220161700, 23.970, 4618.0, 67.9559
21.263627460, 23.970, 4620.0, 67.9706
21.307093220, 23.970, 4659.0, 68.2569
21.350558980, 23.970, 4753.0, 68.9420
21.394024740, 23.970, 4751.0, 68.9275
21.437490500, 23.970, 4838.0, 69.5557
21.480956260, 23.970, 4755.0, 68.9565
21.524422020, 23.970, 4970.0, 70.4982
21.567887780, 23.970, 4782.0, 69.1520
21.611353540, 23.970, 4993.0, 70.6612
21.654819300, 23.970, 5099.0, 71.4073
21.698285060, 23.970, 5204.0, 72.1388
21.741750820, 23.970, 5241.0, 72.3948
21.785216580, 23.970, 5336.0, 73.0479
21.828682340, 23.970, 5587.0, 74.7462
21.872148100, 23.970, 5573.0, 74.6525
21.915613860, 23.970, 5805.0, 76.1906
21.959079620, 23.970, 5733.0, 75.7166
22.002545380, 23.970, 6078.0, 77.9615
22.046011140, 23.970, 6020.0, 77.5887
22.089476900, 23.970, 6178.0, 78.6003
22.132942660, 23.970, 6315.0, 79.4670
22.176408420, 23.970, 6189.0, 78.6702
22.219874180, 23.970, 6096.0, 78.0769
22.263339940, 23.970, 6070.0, 77.9102
22.306805700, 23.970, 5931.0, 77.0130
22.350271460, 23.970, 5841.0, 76.4264
22.393737220, 23.970, 5696.0, 75.4718
22.437202980, 23.970, 5671.0, 75.3060
22.480668740, 23.970, 5671.0, 75.3060
22.524134500, 23.970, 5505.0, 74.1957
22.567600260, 23.970, 5379.0, 73.3417
22.611066020, 23.970, 5221.0, 72.2565
22.654531780, 23.970, 5002.0, 70.7248
22.697997540, 23.970, 4963.0, 70.4486
22.741463300, 23.970, 4832.0, 69.5126
22.784929060, 23.970, 4625.0, 68.0074
22.828394820, 23.970, 4390.0, 66.2571
22.871860580, 23.970, 4463.0, 66.8057
22.915326340, 23.970, 4271.0, 65.3529
22.958792100, 23.970, 4131.0, 64.2729
23.002257860, 23.970, 4108.0, 64.0937
23.045723620, 23.970, 4065.0, 63.7574
23.089189380, 23.970, 3977.0, 63.0635
23.132655140, 23.970, 3869.0, 62.2013
23.176120900, 23.970, 3662.0, 60.5145
23.219586660, 23.970, 3635.0, 60.2910
23.263052420, 23.970, 3515.0, 59.2874
23.306518180, 23.970, 3489.0, 59.0678
23.349983940, 23.970, 3311.0, 57.5413
23.393449700, 23.970, 3320.0, 57.6194
23.436915460, 23.970, 3240.0, 56.9210
23.480381220, 23.970, 3241.0, 56.9298
23.523846980, 23.970, 3039.0, 55.1271
23.567312740, 23.970, 3046.0, 55.1906
23.610778500, 23.970, 3098.0, 55.6597
23.654244260, 23.970, 2983.0, 54.6168
23.697710020, 23.970, 2973.0, 54.5252
23.741175780, 23.970, 2938.0, 54.2033
23.784641540, 23.970, 2821.0, 53.1131
23.828107300, 23.970, 2791.0, 52.8299
23.871573060, 23.970, 2813.0, 53.0377
23.915038820, 23.970, 2858.0, 53.4603
23.958504580, 23.970, 2740.0, 52.3450
24.001970340, 23.970, 2609.0, 51.0784
24.045436100, 23.970, 2730.0, 52.2494
24.088901860, 23.970, 2551.0, 50.5074
24.132367620, 23.970, 2629.0, 51.2738
24.175833380, 23.970, 2537.0, 50.3686
24.219299140, 23.970, 2549.0, 50.4876
24.262764900, 23.970, 2580.0, 50.7937
24.306230660, 23.970, 2519.0, 50.1896
24.349696420, 23.970, 2547.0, 50.4678
24.393162180, 23.970, 2395.0, 48.9387
24.436627940, 23.970, 2463.0, 49.6286
24.480093700, 23.970, 2374.0, 48.7237
24.523559460, 23.970, 2445.0, 49.4469
24.567025220, 23.970, 2445.0, 49.4469
24.610490980, 23.970, 2398.0, 48.9694
24.653956740, 23.970, 2502.0, 50.0200
24.697422500, 23.970, 2375.0, 48.7340
24.740888260, 23.970, 2325.0, 48.2183
24.784354020, 23.970, 2357.0, 48.5489
24.827819780, 23.970, 2372.0, 48.7032
24.871285540, 23.970, 2346.0, 48.4355
24.914751300, 23.970, 2260.0, 47.5395
24.958217060, 23.970, 2276.0, 47.7074
25.001682820, 23.970, 2317.0, 48.1352
25.045148580, 23.970, 2350.0, 48.4768
25.088614340, 23.970, 2280.0, 47.7493
25.132080100, 23.970, 2301.0, 47.9687
25.175545860, 23.970, 2256.0, 47.4974
25.219011620, 23.970, 2288.0, 47.8330
25.262477380, 23.970, 2296.0, 47.9166
25.305943140, 23.970, 2165.0, 46.5296
25.349408900, 23.970, 2141.0, 46.2709
25.392874660, 23.970, 2279.0, 47.7389
25.436340420, 23.970, 2146.0, 46.3249
25.479806180, 23.970, 2109.0, 45.9239
25.523271940, 23.970, 2171.0, 46.5940
25.566737700, 23.970, 2208.0, 46.9894
25.610203460, 23.970, 2220.0, 47.1169
25.653669220, 23.970, 2182.0, 46.7119
25.697134980, 23.970, 2087.0, 45.6837
25.740600740, 23.970, 2096.0, 45.7821
25.784066500, 23.970, 2117.0, 46.0109
25.827532260, 23.970, 2055.0, 45.3321
25.870998020, 23.970, 2124.0, 46.0869
25.914463780, 23.970, 2049.0, 45.2659
25.957929540, 23.970, 2082.0, 45.6289
26.001395300, 23.970, 2106.0, 45.8912
26.044861060, 23.970, 2089.0, 45.7056
26.088326820, 23.970, 2093.0, 45.7493
26.131792580, 23.970, 2017.0, 44.9110
26.175258340, 23.970, 1983.0, 44.5309
26.218724100, 23.970, 2049.0, 45.2659
26.262189860, 23.970, 2030.0, 45.0555
26.305655620, 23.970, 2051.0, 45.2880
26.349121380, 23.970, 2040.0, 45.1664
26.392587140, 23.970, 2056.0, 45.3431
26.436052900, 23.970, 1956.0, 44.2267
26.479518660, 23.970, 2010.0, 44.8330
26.522984420, 23.970, 1875.0, 43.3013
26.566450180, 23.970, 1945.0, 44.1022
26.609915940, 23.970, 1927.0, 43.8976
26.653381700, 23.970, 1871.0, 43.2551
26.696847460, 23.970, 1944.0, 44.0908
26.740313220, 23.970, 1997.0, 44.6878
26.783778980, 23.970, 1867.0, 43.2088
26.827244740, 23.970, 1896.0, 43.5431
26.870710500, 23.970, 1914.0, 43.7493
26.914176260, 23.970, 1965.0, 44.3283
26.957642020, 23.970, 1946.0, 44.1135
27.001107780, 23.970, 1843.0, 42.9302
27.044573540, 23.970, 1931.0, 43.9431
27.088039300, 23.970, 1915.0, 43.7607
27.131505060, 23.970, 1946.0, 44.1135
27.174970820, 23.970, 1952.0, 44.1814
27.218436580, 23.970, 1907.0, 43.6692
27.261902340, 23.970, 1911.0, 43.7150
27.305368100, 23.970, 1935.0, 43.9886
27.348833860, 23.970, 1905.0, 43.6463
27.392299620, 23.970, 1866.0, 43.1972
27.435765380, 23.970, 1946.0, 44.1135
27.479231140, 23.970, 2008.0, 44.8107
27.522696900, 23.970, 1978.0, 44.4747
27.566162660, 23.970, 2002.0, 44.7437
27.609628420, 23.970, 1959.0, 44.2606
27.653094180, 23.970, 2062.0, 45.4093
27.696559940, 23.970, 2098.0, 45.8039
27.740025700, 23.970, 2141.0, 46.2709
27.783491460, 23.970, 2148.0, 46.3465
27.826957220, 23.970, 2102.0, 45.8476
27.870422980, 23.970, 2300.0, 47.9583
27.913888740, 23.970, 2333.0, 48.3011
27.957354500, 23.970, 2431.0, 49.3052
28.000820260, 23.970, 2459.0, 49.5883
28.044286020, 23.970, 2481.0, 49.8096
28.087751780, 23.970, 2494.0, 49.9400
28.131217540, 23.970, 2521.0, 50.2096
28.174683300, 23.970, 2683.0, 51.7977
28.218149060, 23.970, 2634.0, 51.3225
28.261614820, 23.970, 2689.0, 51.8556
28.305080580, 23.970, 2635.0, 51.3323
28.348546340, 23.970, 2680.0, 51.7687
28.392012100, 23.970, 2603.0, 51.0196
28.435477860, 23.970, 2607.0, 51.0588
28.478943620, 23.970, 2699.0, 51.9519
28.522409380, 23.970, 2530.0, 50.2991
28.565875140, 23.970, 2455.0, 49.5480
28.609340900, 23.970, 2468.0, 49.6790
28.652806660, 23.970, 2475.0, 49.7494
28.696272420, 23.970, 2419.0, 49.1833
28.739738180, 23.970, 2374.0, 48.7237
28.783203940, 23.970, 2458.0, 49.5782
28.826669700, 23.970, 2470.0, 49.6991
28.870135460, 23.970, 2563.0, 50.6261
28.913601220, 23.970, 2620.0, 51.1859
28.957066980, 23.970, 2395.0, 48.9387
29.000532740, 23.970, 2299.0, 47.9479
29.043998500, 23.970, 2241.0, 47.3392
29.087464260, 23.970, 2020.0, 44.9444
29.130930020, 23.970, 2005.0, 44.7772
29.174395780, 23.970, 1839.0, 42.8836
29.217861540, 23.970, 1878.0, 43.3359
29.261327300, 23.970, 1839.0, 42.8836
29.304793060, 23.970, 1790.0, 42.3084
29.348258820, 23.970, 1854.0, 43.0581
29.391724580, 23.970, 1732.0, 41.6173
29.435190340, 23.970, 1737.0, 41.6773
29.478656100, 23.970, 1694.0, 41.1582
29.522121860, 23.970, 1587.0, 39.8372
29.565587620, 23.970, 1655.0, 40.6817
29.609053380, 23.970, 1693.0, 41.1461
29.652519140, 23.970, 1652.0, 40.6448
29.695984900, 23.970, 1667.0, 40.8289
29.739450660, 23.970, 1660.0, 40.7431
29.782916420, 23.970, 1672.0, 40.8901
29.826382180, 23.970, 1602.0, 40.0250
29.869847940, 23.970, 1607.0, 40.0874
29.913313700, 23.970, 1594.0, 39.9249
29.956779460, 23.970, 1604.0, 40.0500
30.000245220, 23.970, 1572.0, 39.6485
30.043710980, 23.970, 1570.0, 39.6232
30.087176740, 23.970, 1545.0, 39.3065
30.130642500, 23.970, 1523.0, 39.0256
30.174108260, 23.970, 1526.0, 39.0640
30.217574020, 23.970, 1451.0, 38.0920
30.261039780, 23.970, 1442.0, 37.9737
30.304505540, 23.970, 1440.0, 37.9473
30.347971300, 23.970, 1356.0, 36.8239
30.391437060, 23.970, 1366.0, 36.9594
30.434902820, 23.970, 1369.0, 37.0000
30.478368580, 23.970, 1363.0, 36.9188
30.521834340, 23.970, 1400.0, 37.4166
30.565300100, 23.970, 1390.0, 37.2827
30.608765860, 23.970, 1325.0, 36.4005
30.652231620, 23.970, 1348.0, 36.7151
30.695697380, 23.970, 1333.0, 36.5103
30.739163140, 23.970, 1329.0, 36.4555
30.782628900, 23.970, 1287.0, 35.8748
30.826094660, 23.970, 1366.0, 36.9594
30.869560420, 23.970, 1251.0, 35.3695
30.913026180, 23.970, 1289.0, 35.9026
30.956491940, 23.970, 1382.0, 37.1753
30.999957700, 23.970, 1307.0, 36.1525
31.043423460, 23.970, 1347.0, 36.7015
31.086889220, 23.970, 1276.0, 35.7211
31.130354980, 23.970, 1249.0, 35.3412
31.173820740, 23.970, 1283.0, 35.8190
31.217286500, 23.970, 1202.0, 34.6699
31.260752260, 23.970, 1281.0, 35.7911
31.304218020, 23.970, 1291.0, 35.9305
31.347683780, 23.970, 1269.0, 35.6230
31.391149540, 23.970, 1245.0, 35.2846
31.434615300, 23.970, 1261.0, 35.5106
31.478081060, 23.970, 1266.0, 35.5809
31.521546820, 23.970, 1241.0, 35.2278
31.565012580, 23.970, 1292.0, 35.9444
31.608478340, 23.970, 1235.0, 35.1426
31.651944100, 23.970, 1245.0, 35.2846
31.695409860, 23.970, 1231.0, 35.0856
31.738875620, 23.970, 1297.0, 36.0139
31.782341380, 23.970, 1227.0, 35.0286
31.825807140, 23.970, 1249.0, 35.3412
31.869272900, 23.970, 1198.0, 34.6121
31.912738660, 23.970, 1310.0, 36.1939
31.956204420, 23.970, 1300.0, 36.0555
31.999670180, 23.970, 1245.0, 35.2846
32.043135940, 23.970, 1347.0, 36.7015
32.086601700, 23.970, 1270.0, 35.6371
32.130067460, 23.970, 1313.0, 36.2353
32.173533220, 23.970, 1243.0, 35.2562
32.216998980, 23.970, 1264.0, 35.5528
32.260464740, 23.970, 1321.0, 36.3456
32.303930500, 23.970, 1266.0, 35.5809
32.347396260, 23.970, 1212.0, 34.8138
32.390862020, 23.970, 1272.0, 35.6651
32.434327780, 23.970, 1234.0, 35.1283
32.477793540, 23.970, 1185.0, 34.4238
32.521259300, 23.970, 1325.0, 36.4005
32.564725060, 23.970, 1154.0, 33.9706
32.608190820, 23.970, 1244.0, 35.2704
32.651656580, 23.970, 1213.0, 34.8281
32.695122340, 23.970, 1220.0, 34.9285
32.738588100, 23.970, 1187.0, 34.4529
32.782053860, 23.970, 1225.0, 35.0000
32.825519620, 23.970, 1178.0, 34.3220
32.868985380, 23.970, 1287.0, 35.8748
32.912451140, 23.970, 1239.0, 35.1994
32.955916900, 23.970, 1212.0, 34.8138
32.999382660, 23.970, 1192.0, 34.5254
33.042848420, 23.970, 1173.0, 34.2491
33.086314180, 23.970, 1213.0, 34.8281
33.129779940, 23.970, 1166.0, 34.1467
33.173245700, 23.970, 1141.0, 33.7787
33.216711460, 23.970, 1159.0, 34.0441
33.260177220, 23.970, 1106.0, 33.2566
33.303642980, 23.970, 1092.0, 33.0454
33.347108740, 23.970, 1157.0, 34.0147
33.390574500, 23.970, 1132.0, 33.6452
33.434040260, 23.970, 1094.0, 33.0757
33.477506020, 23.970, 1143.0, 33.8083
33.520971780, 23.970, 1121.0, 33.4813
33.564437540, 23.970, 1073.0, 32.7567
33.607903300, 23.970, 1133.0, 33.6601
33.651369060, 23.970, 1062.0, 32.5883
33.694834820, 23.970, 1146.0, 33.8526
33.738300580, 23.970, 1061.0, 32.5730
33.781766340, 23.970, 1001.0, 31.6386
33.825232100, 23.970, 1063.0, 32.6037
33.868697860, 23.970, 975.0, 31.2250
33.912163620, 23.970, 1075.0, 32.7872
33.955629380, 23.970, 969.0, 31.1288
33.999095140, 23.970, 954.0, 30.8869
34.042560900, 23.970, 921.0, 30.3480
34.086026660, 23.970, 1060.0, 32.5576
34.129492420, 23.970, 1051.0, 32.4191
34.172958180, 23.970, 954.0, 30.8869
34.216423940, 23.970, 952.0, 30.8545
34.259889700, 23.970, 933.0, 30.5450
34.303355460, 23.970, 945.0, 30.7409
34.346821220, 23.970, 963.0, 31.0322
34.390286980, 23.970, 928.0, 30.4631
34.433752740, 23.970, 954.0, 30.8869
34.477218500, 23.970, 920.0, 30.3315
34.520684260, 23.970, 946.0, 30.7571
34.564150020, 23.970, 981.0, 31.3209
34.607615780, 23.970, 924.0, 30.3974
34.651081540, 23.970, 924.0, 30.3974
34.694547300, 23.970, 920.0, 30.3315
34.738013060, 23.970, 931.0, 30.5123
34.781478820, 23.970, 895.0, 29.9166
34.824944580, 23.970, 901.0, 30.0167
34.868410340, 23.970, 942.0, 30.6920
34.911876100, 23.970, 919.0, 30.3150
34.955341860, 23.970, 860.0, 29.3258
34.998807620, 23.970, 890.0, 29.8329
35.042273380, 23.970, 869.0, 29.4788
35.085739140, 23.970, 915.0, 30.2490
35.129204900, 23.970, 895.0, 29.9166
35.172670660, 23.970, 950.0, 30.8221
35.216136420, 23.970, 907.0, 30.1164
35.259602180, 23.970, 916.0, 30.2655
35.303067940, 23.970, 970.0, 31.1448
35.346533700, 23.970, 862.0, 29.3598
35.389999460, 23.970, 916.0, 30.2655
35.433465220, 23.970, 983.0, 31.3528
35.476930980, 23.970, 930.0, 30.4959
35.520396740, 23.970, 991.0, 31.4802
35.563862500, 23.970, 933.0, 30.5450
35.607328260, 23.970, 936.0, 30.5941
35.650794020, 23.970, 893.0, 29.8831
35.694259780, 23.970, 876.0, 29.5973
35.737725540, 23.970, 850.0, 29.1548
35.781191300, 23.970, 887.0, 29.7825
35.824657060, 23.970, 874.0, 29.5635
35.868122820, 23.970, 850.0, 29.1548
35.911588580, 23.970, 890.0, 29.8329
35.955054340, 23.970, 916.0, 30.2655
35.998520100, 23.970, 868.0, 29.4618
36.041985860, 23.970, 902.0, 30.0333
36.085451620, 23.970, 855.0, 29.2404
36.128917380, 23.970, 891.0, 29.8496
36.172383140, 23.970, 938.0, 30.6268
36.215848900, 23.970, 880.0, 29.6648
36.259314660, 23.970, 844.0, 29.0517
36.302780420, 23.970, 841.0, 29.0000
36.346246180, 23.970, 823.0, 28.6880
36.389711940, 23.970, 873.0, 29.5466
36.433177700, 23.970, 894.0, 29.8998
36.476643460, 23.970, 848.0, 29.1204
36.520109220, 23.970, 854.0, 29.2233
36.563574980, 23.970, 911.0, 30.1828
36.607040740, 23.970, 914.0, 30.2324
36.650506500, 23.970, 868.0, 29.4618
36.693972260, 23.970, 892.0, 29.8664
36.737438020, 23.970, 887.0, 29.7825
36.780903780, 23.970, 866.0, 29.4279
36.824369540, 23.970, 849.0, 29.1376
36.867835300, 23.970, 862.0, 29.3598
36.911301060, 23.970, 861.0, 29.3428
36.954766820, 23.970, 905.0, 30.0832
36.998232580, 23.970, 898.0, 29.9666
37.041698340, 23.970, 890.0, 29.8329
37.085164100, 23.970, 930.0, 30.4959
37.128629860, 23.970, 949.0, 30.8058
37.172095620, 23.970, 891.0, 29.8496
37.215561380, 23.970, 871.0, 29.5127
37.259027140, 23.970, 956.0, 30.9192
37.302492900, 23.970, 938.0, 30.6268
37.345958660, 23.970, 916.0, 30.2655
37.389424420, 23.970, 942.0, 30.6920
37.432890180, 23.970, 933.0, 30.5450
37.476355940, 23.970, 919.0, 30.3150
37.519821700, 23.970, 958.0, 30.9516
37.563287460, 23.970, 916.0, 30.2655
37.606753220, 23.970, 1022.0, 31.9687
37.650218980, 23.970, 948.0, 30.7896
37.693684740, 23.970, 992.0, 31.4960
37.737150500, 23.970, 965.0, 31.0644
37.780616260, 23.970, 980.0, 31.3050
37.824082020, 23.970, 1000.0, 31.6228
37.867547780, 23.970, 990.0, 31.4643
37.911013540, 23.970, 931.0, 30.5123
37.954479300, 23.970, 1004.0, 31.6860
37.997945060, 23.970, 980.0, 31.3050
38.041410820, 23.970, 1019.0, 31.9218
38.084876580, 23.970, 1016.0, 31.8748
38.128342340, 23.970, 991.0, 31.4802
38.171808100, 23.970, 1035.0, 32.1714
38.215273860, 23.970, 1124.0, 33.5261
38.258739620, 23.970, 992.0, 31.4960
38.302205380, 23.970, 1046.0, 32.3419
38.345671140, 23.970, 1038.0, 32.2180
38.389136900, 23.970, 1019.0, 31.9218
38.432602660, 23.970, 997.0, 31.5753
38.476068420, 23.970, 1070.0, 32.7109
38.519534180, 23.970, 1101.0, 33.1813
38.562999940, 23.970, 1059.0, 32.5423
38.606465700, 23.970, 1053.0, 32.4500
38.649931460, 23.970, 1049.0, 32.3883
38.693397220, 23.970, 1088.0, 32.9848
38.736862980, 23.970, 994.0, 31.5278
38.780328740, 23.970, 1131.0, 33.6303
38.823794500, 23.970, 1138.0, 33.7343
38.867260260, 23.970, 1094.0, 33.0757
38.910726020, 23.970, 1156.0, 34.0000
38.954191780, 23.970, 1153.0, 33.9559
38.997657540, 23.970, 1104.0, 33.2265
39.041123300, 23.970, 1089.0, 33.0000
39.084589060, 23.970, 1042.0, 32.2800
39.128054820, 23.970, 1018.0, 31.9061
39.171520580, 23.970, 989.0, 31.4484
39.214986340, 23.970, 947.0, 30.7734
39.258452100, 23.970, 919.0, 30.3150
39.301917860, 23.970, 900.0, 30.0000
39.345383620, 23.970, 900.0, 30.0000
39.388849380, 23.970, 940.0, 30.6594
39.432315140, 23.970, 931.0, 30.5123
39.475780900, 23.970, 947.0, 30.7734
39.519246660, 23.970, 951.0, 30.8383
39.562712420, 23.970, 998.0, 31.5911
39.606178180, 23.970, 982.0, 31.3369
39.649643940, 23.970, 922.0, 30.3645
39.693109700, 23.970, 977.0, 31.2570
39.736575460, 23.970, 924.0, 30.3974
39.780041220, 23.970, 944.0, 30.7246
39.823506980, 23.970, 902.0, 30.0333
39.866972740, 23.970, 906.0, 30.0998
39.910438500, 23.970, 922.0, 30.3645
39.953904260, 23.970, 961.0, 31.0000
39.997370020, 23.970, 950.0, 30.8221
40.040835780, 23.970, 950.0, 30.8221
40.084301540, 23.970, 913.0, 30.2159
40.127767300, 23.970, 884.0, 29.7321
40.171233060, 23.970, 907.0, 30.1164
40.214698820, 23.970, 952.0, 30.8545
40.258164580, 23.970, 921.0, 30.3480
40.301630340, 23.970, 911.0, 30.1828
40.345096100, 23.970, 924.0, 30.3974
40.388561860, 23.970, 930.0, 30.4959
40.432027620, 23.970, 926.0, 30.4302
40.475493380, 23.970, 918.0, 30.2985
40.518959140, 23.970, 921.0, 30.3480
40.562424900, 23.970, 934.0, 30.5614
40.605890660, 23.970, 980.0, 31.3050
40.649356420, 23.970, 929.0, 30.4795
40.692822180, 23.970, 938.0, 30.6268
40.736287940, 23.970, 971.0, 31.1609
40.779753700, 23.970, 944.0, 30.7246
40.823219460, 23.970, 921.0, 30.3480
40.866685220, 23.970, 897.0, 29.9500
40.910150980, 23.970, 938.0, 30.6268
40.953616740, 23.970, 922.0, 30.3645
40.997082500, 23.970, 883.0, 29.7153
41.040548260, 23.970, 894.0, 29.8998
41.084014020, 23.970, 914.0, 30.2324
41.127479780, 23.970, 868.0, 29.4618
41.170945540, 23.970, 904.0, 30.0666
41.214411300, 23.970, 908.0, 30.1330
41.257877060, 23.970, 917.0, 30.2820
41.301342820, 23.970, 881.0, 29.6816
41.344808580, 23.970, 909.0, 30.1496
41.388274340, 23.970, 906.0, 30.0998
41.431740100, 23.970, 883.0, 29.7153
41.475205860, 23.970, 874.0, 29.5635
41.518671620, 23.970, 866.0, 29.4279
41.562137380, 23.970, 918.0, 30.2985
41.605603140, 23.970, 804.0, 28.3549
41.649068900, 23.970, 850.0, 29.1548
41.692534660, 23.970, 867.0, 29.4449
41.736000420, 23.970, 821.0, 28.6531
41.779466180, 23.970, 858.0, 29.2916
41.822931940, 23.970, 847.0, 29.1033
41.866397700, 23.970, 806.0, 28.3901
41.909863460, 23.970, 844.0, 29.0517
41.953329220, 23.970, 833.0, 28.8617
41.996794980, 23.970, 864.0, 29.3939
42.040260740, 23.970, 865.0, 29.4109
42.083726500, 23.970, 823.0, 28.6880
42.127192260, 23.970, 829.0, 28.7924
42.170658020, 23.970, 852.0, 29.1890
42.214123780, 23.970, 823.0, 28.6880
42.257589540, 23.970, 830.0, 28.8097
42.301055300, 23.970, 859.0, 29.3087
42.344521060, 23.970, 852.0, 29.1890
42.387986820, 23.970, 841.0, 29.0000
42.431452580, 23.970, 908.0, 30.1330
42.474918340, 23.970, 905.0, 30.0832
42.518384100, 23.970, 957.0, 30.9354
42.561849860, 23.970, 954.0, 30.8869
42.605315620, 23.970, 966.0, 31.0805
42.648781380, 23.970, 976.0, 31.2410
42.692247140, 23.970, 1002.0, 31.6544
42.735712900, 23.970, 938.0, 30.6268
42.779178660, 23.970, 958.0, 30.9516
42.822644420, 23.970, 845.0, 29.0689
42.866110180, 23.970, 876.0, 29.5973
42.909575940, 23.970, 801.0, 28.3019
42.953041700, 23.970, 857.0, 29.2746
42.996507460, 23.970, 827.0, 28.7576
43.039973220, 23.970, 783.0, 27.9821
43.083438980, 23.970, 759.0, 27.5500
43.126904740, 23.970, 832.0, 28.8444
43.170370500, 23.970, 857.0, 29.2746
43.213836260, 23.970, 758.0, 27.5318
43.257302020, 23.970, 808.0, 28.4253
43.300767780, 23.970, 776.0, 27.8568
43.344233540, 23.970, 800.0, 28.2843
43.387699300, 23.970, 813.0, 28.5132
43.431165060, 23.970, 830.0, 28.8097
43.474630820, 23.970, 777.0, 27.8747
43.518096580, 23.970, 766.0, 27.6767
43.561562340, 23.970, 845.0, 29.0689
43.605028100, 23.970, 794.0, 28.1780
43.648493860, 23.970, 795.0, 28.1957
43.691959620, 23.970, 808.0, 28.4253
43.735425380, 23.970, 775.0, 27.8388
43.778891140, 23.970, 764.0, 27.6405
43.822356900, 23.970, 775.0, 27.8388
43.865822660, 23.970, 838.0, 28.9482
43.909288420, 23.970, 806.0, 28.3901
43.952754180, 23.970, 799.0, 28.2666
43.996219940, 23.970, 816.0, 28.5657
44.039685700, 23.970, 823.0, 28.6880
44.083151460, 23.970, 775.0, 27.8388
44.126617220, 23.970, 798.0, 28.2489
44.170082980, 23.970, 765.0, 27.6586
44.213548740, 23.970, 781.0, 27.9464
44.257014500, 23.970, 808.0, 28.4253
44.300480260, 23.970, 758.0, 27.5318
44.343946020, 23.970, 768.0, 27.7128
44.387411780, 23.970, 781.0, 27.9464
44.430877540, 23.970, 806.0, 28.3901
44.474343300, 23.970, 821.0, 28.6531
44.517809060, 23.970, 771.0, 27.7669
44.561274820, 23.970, 755.0, 27.4773
44.604740580, 23.970, 753.0, 27.4408
44.648206340, 23.970, 823.0, 28.6880
44.691672100, 23.970, 742.0, 27.2397
44.735137860, 23.970, 755.0, 27.4773
44.778603620, 23.970, 824.0, 28.7054
44.822069380, 23.970, 765.0, 27.6586
44.865535140, 23.970, 806.0, 28.3901
44.909000900, 23.970, 761.0, 27.5862
44.952466660, 23.970, 771.0, 27.7669
44.995932420, 23.970, 791.0, 28.1247
45.039398180, 23.970, 758.0, 27.5318
45.082863940, 23.970, 717.0, 26.7769
45.126329700, 23.970, 827.0, 28.7576
45.169795460, 23.970, 759.0, 27.5500
45.213261220, 23.970, 756.0, 27.4955
45.256726980, 23.970, 751.0, 27.4044
45.300192740, 23.970, 774.0, 27.8209
45.343658500, 23.970, 791.0, 28.1247
45.387124260, 23.970, 752.0, 27.4226
45.430590020, 23.970, 810.0, 28.4605
45.474055780, 23.970, 759.0, 27.5500
45.517521540, 23.970, 748.0, 27.3496
45.560987300, 23.970, 747.0, 27.3313
45.604453060, 23.970, 771.0, 27.7669
45.647918820, 23.970, 803.0, 28.3373
45.691384580, 23.970, 801.0, 28.3019
45.734850340, 23.970, 770.0, 27.7489
45.778316100, 23.970, 778.0, 27.8927
45.821781860, 23.970, 741.0, 27.2213
45.865247620, 23.970, 809.0, 28.4429
45.908713380, 23.970, 718.0, 26.7955
45.952179140, 23.970, 819.0, 28.6182
45.995644900, 23.970, 819.0, 28.6182
46.039110660, 23.970, 770.0, 27.7489
46.082576420, 23.970, 719.0, 26.8142
46.126042180, 23.970, 803.0, 28.3373
46.169507940, 23.970, 832.0, 28.8444
46.212973700, 23.970, 829.0, 28.7924
46.256439460, 23.970, 834.0, 28.8791
46.299905220, 23.970, 792.0, 28.1425
46.343370980, 23.970, 887.0, 29.7825
46.386836740, 23.970, 862.0, 29.3598
46.430302500, 23.970, 908.0, 30.1330
46.473768260, 23.970, 886.0, 29.7658
46.517234020, 23.970, 901.0, 30.0167
46.560699780, 23.970, 959.0, 30.9677
46.604165540, 23.970, 956.0, 30.9192
46.647631300, 23.970, 955.0, 30.9031
46.691097060, 23.970, 1023.0, 31.9844
46.734562820, 23.970, 975.0, 31.2250
46.778028580, 23.970, 995.0, 31.5436
46.821494340, 23.970, 1048.0, 32.3728
46.864960100, 23.970, 1053.0, 32.4500
46.908425860, 23.970, 1084.0, 32.9242
46.951891620, 23.970, 1092.0, 33.0454
46.995357380, 23.970, 1160.0, 34.0588
47.038823140, 23.970, 1201.0, 34.6554
47.082288900, 23.970, 1169.0, 34.1906
47.125754660, 23.970, 1128.0, 33.5857
47.169220420, 23.970, 1100.0, 33.1662
47.212686180, 23.970, 1013.0, 31.8277
47.256151940, 23.970, 967.0, 31.0966
47.299617700, 23.970, 947.0, 30.7734
47.343083460, 23.970, 926.0, 30.4302
47.386549220, 23.970, 935.0, 30.5778
47.430014980, 23.970, 858.0, 29.2916
47.473480740, 23.970, 959.0, 30.9677
47.516946500, 23.970, 896.0, 29.9333
47.560412260, 23.970, 920.0, 30.3315
47.603878020, 23.970, 880.0, 29.6648
47.647343780, 23.970, 868.0, 29.4618
47.690809540, 23.970, 916.0, 30.2655
47.734275300, 23.970, 900.0, 30.0000
47.777741060, 23.970, 934.0, 30.5614
47.821206820, 23.970, 927.0, 30.4467
47.864672580, 23.970, 1005.0, 31.7017
47.908138340, 23.970, 969.0, 31.1288
47.951604100, 23.970, 1033.0, 32.1403
47.995069860, 23.970, 1012.0, 31.8119
48.038535620, 23.970, 1079.0, 32.8481
48.082001380, 23.970, 1024.0, 32.0000
48.125467140, 23.970, 1037.0, 32.2025
48.168932900, 23.970, 973.0, 31.1929
48.212398660, 23.970, 852.0, 29.1890
48.255864420, 23.970, 782.0, 27.9643
48.299330180, 23.970, 749.0, 27.3679
48.342795940, 23.970, 748.0, 27.3496
48.386261700, 23.970, 773.0, 27.8029
48.429727460, 23.970, 741.0, 27.2213
48.473193220, 23.970, 718.0, 26.7955
48.516658980, 23.970, 729.0, 27.0000
48.560124740, 23.970, 766.0, 27.6767
48.603590500, 23.970, 731.0, 27.0370
48.647056260, 23.970, 708.0, 26.6083
48.690522020, 23.970, 716.0, 26.7582
48.733987780, 23.970, 717.0, 26.7769
48.777453540, 23.970, 707.0, 26.5895
48.820919300, 23.970, 767.0, 27.6948
48.864385060, 23.970, 690.0, 26.2679
48.907850820, 23.970, 722.0, 26.8701
48.951316580, 23.970, 729.0, 27.0000
48.994782340, 23.970, 732.0, 27.0555
49.038248100, 23.970, 713.0, 26.7021
49.081713860, 23.970, 780.0, 27.9285
49.125179620, 23.970, 749.0, 27.3679
49.168645380, 23.970, 710.0, 26.6458
49.212111140, 23.970, 756.0, 27.4955
49.255576900, 23.970, 717.0, 26.7769
49.299042660, 23.970, 694.0, 26.3439
49.342508420, 23.970, 713.0, 26.7021
49.385974180, 23.970, 718.0, 26.7955
49.429439940, 23.970, 751.0, 27.4044
49.472905700, 23.970, 716.0, 26.7582
49.516371460, 23.970, 727.0, 26.9629
49.559837220, 23.970, 673.0, 25.9422
49.603302980, 23.970, 721.0, 26.8514
49.646768740, 23.970, 729.0, 27.0000
49.690234500, 23.970, 712.0, 26.6833
49.733700260, 23.970, 645.0, 25.3969
49.777166020, 23.970, 677.0, 26.0192
49.820631780, 23.970, 654.0, 25.5734
49.864097540, 23.970, 716.0, 26.7582
49.907563300, 23.970, 691.0, 26.2869
49.951029060, 23.970, 637.0, 25.2389
49.994494820, 23.970, 675.0, 25.9808