File: data/DSC/501024_2.csv
[Measurement conditions]
Sample identification,501024_2
Comment,
Anode material,Cu
K-Alpha1 wavelength,1.5405980
K-Alpha2 wavelength,1.5444260
Ratio K-Alpha2/K-Alpha1,0.500
Divergence slit,Fixed,0.38mm
Monochromator used,NO
Generator voltage, 40
Tube current, 15
File date and time,26/Feb/2025 11:29
Unit cell,
h k l, 0 0 0
Scan axis,Gonio
Scan range,5.002000000,49.999928040
Scan step size,0.0108664
No. of points, 4141
Scan type,CONTINUOUS
Time per step,23.970
[Scan points]
Angle, TimePerStep, Intensity, ESD
5.007433220, 23.970, 1705.0, 41.2916
5.050898980, 23.970, 1756.0, 41.9047
5.094364740, 23.970, 1708.0, 41.3280
5.137830500, 23.970, 1782.0, 42.2137
5.181296260, 23.970, 1759.0, 41.9404
5.224762020, 23.970, 1778.0, 42.1663
5.268227780, 23.970, 1859.0, 43.1161
5.311693540, 23.970, 1818.0, 42.6380
5.355159300, 23.970, 1836.0, 42.8486
5.398625060, 23.970, 1869.0, 43.2319
5.442090820, 23.970, 1834.0, 42.8252
5.485556580, 23.970, 1831.0, 42.7902
5.529022340, 23.970, 1889.0, 43.4626
5.572488100, 23.970, 1930.0, 43.9318
5.615953860, 23.970, 1920.0, 43.8178
5.659419620, 23.970, 2035.0, 45.1110
5.702885380, 23.970, 1848.0, 42.9884
5.746351140, 23.970, 1941.0, 44.0568
5.789816900, 23.970, 2003.0, 44.7549
5.833282660, 23.970, 2031.0, 45.0666
5.876748420, 23.970, 1938.0, 44.0227
5.920214180, 23.970, 1996.0, 44.6766
5.963679940, 23.970, 2113.0, 45.9674
6.007145700, 23.970, 2077.0, 45.5741
6.050611460, 23.970, 2063.0, 45.4203
6.094077220, 23.970, 2081.0, 45.6180
6.137542980, 23.970, 2034.0, 45.0999
6.181008740, 23.970, 2030.0, 45.0555
6.224474500, 23.970, 2080.0, 45.6070
6.267940260, 23.970, 2144.0, 46.3033
6.311406020, 23.970, 2131.0, 46.1628
6.354871780, 23.970, 2060.0, 45.3872
6.398337540, 23.970, 2045.0, 45.2217
6.441803300, 23.970, 2120.0, 46.0435
6.485269060, 23.970, 2216.0, 47.0744
6.528734820, 23.970, 2208.0, 46.9894
6.572200580, 23.970, 2150.0, 46.3681
6.615666340, 23.970, 2198.0, 46.8828
6.659132100, 23.970, 2104.0, 45.8694
6.702597860, 23.970, 2227.0, 47.1911
6.746063620, 23.970, 2282.0, 47.7703
6.789529380, 23.970, 2268.0, 47.6235
6.832995140, 23.970, 2212.0, 47.0319
6.876460900, 23.970, 2141.0, 46.2709
6.919926660, 23.970, 2238.0, 47.3075
6.963392420, 23.970, 2328.0, 48.2494
7.006858180, 23.970, 2160.0, 46.4758
7.050323940, 23.970, 2210.0, 47.0106
7.093789700, 23.970, 2216.0, 47.0744
7.137255460, 23.970, 2265.0, 47.5920
7.180721220, 23.970, 2307.0, 48.0312
7.224186980, 23.970, 2426.0, 49.2544
7.267652740, 23.970, 2234.0, 47.2652
7.311118500, 23.970, 2347.0, 48.4458
7.354584260, 23.970, 2310.0, 48.0625
7.398050020, 23.970, 2301.0, 47.9687
7.441515780, 23.970, 2364.0, 48.6210
7.484981540, 23.970, 2257.0, 47.5079
7.528447300, 23.970, 2375.0, 48.7340
7.571913060, 23.970, 2346.0, 48.4355
7.615378820, 23.970, 2368.0, 48.6621
7.658844580, 23.970, 2384.0, 48.8262
7.702310340, 23.970, 2338.0, 48.3529
7.745776100, 23.970, 2323.0, 48.1975
7.789241860, 23.970, 2444.0, 49.4368
7.832707620, 23.970, 2408.0, 49.0714
7.876173380, 23.970, 2394.0, 48.9285
7.919639140, 23.970, 2415.0, 49.1426
7.963104900, 23.970, 2338.0, 48.3529
8.006570660, 23.970, 2403.0, 49.0204
8.050036420, 23.970, 2302.0, 47.9792
8.093502180, 23.970, 2386.0, 48.8467
8.136967940, 23.970, 2380.0, 48.7852
8.180433700, 23.970, 2402.0, 49.0102
8.223899460, 23.970, 2391.0, 48.8979
8.267365220, 23.970, 2348.0, 48.4562
8.310830980, 23.970, 2427.0, 49.2646
8.354296740, 23.970, 2335.0, 48.3218
8.397762500, 23.970, 2371.0, 48.6929
8.441228260, 23.970, 2390.0, 48.8876
8.484694020, 23.970, 2427.0, 49.2646
8.528159780, 23.970, 2344.0, 48.4149
8.571625540, 23.970, 2318.0, 48.1456
8.615091300, 23.970, 2341.0, 48.3839
8.658557060, 23.970, 2395.0, 48.9387
8.702022820, 23.970, 2410.0, 49.0918
8.745488580, 23.970, 2308.0, 48.0416
8.788954340, 23.970, 2435.0, 49.3457
8.832420100, 23.970, 2371.0, 48.6929
8.875885860, 23.970, 2347.0, 48.4458
8.919351620, 23.970, 2334.0, 48.3115
8.962817380, 23.970, 2354.0, 48.5180
9.006283140, 23.970, 2302.0, 47.9792
9.049748900, 23.970, 2454.0, 49.5379
9.093214660, 23.970, 2373.0, 48.7134
9.136680420, 23.970, 2349.0, 48.4665
9.180146180, 23.970, 2419.0, 49.1833
9.223611940, 23.970, 2340.0, 48.3735
9.267077700, 23.970, 2318.0, 48.1456
9.310543460, 23.970, 2383.0, 48.8160
9.354009220, 23.970, 2410.0, 49.0918
9.397474980, 23.970, 2365.0, 48.6313
9.440940740, 23.970, 2397.0, 48.9592
9.484406500, 23.970, 2328.0, 48.2494
9.527872260, 23.970, 2430.0, 49.2950
9.571338020, 23.970, 2309.0, 48.0521
9.614803780, 23.970, 2365.0, 48.6313
9.658269540, 23.970, 2309.0, 48.0521
9.701735300, 23.970, 2261.0, 47.5500
9.745201060, 23.970, 2335.0, 48.3218
9.788666820, 23.970, 2328.0, 48.2494
9.832132580, 23.970, 2281.0, 47.7598
9.875598340, 23.970, 2422.0, 49.2138
9.919064100, 23.970, 2346.0, 48.4355
9.962529860, 23.970, 2297.0, 47.9270
10.005995620, 23.970, 2292.0, 47.8748
10.049461380, 23.970, 2388.0, 48.8672
10.092927140, 23.970, 2313.0, 48.0937
10.136392900, 23.970, 2391.0, 48.8979
10.179858660, 23.970, 2222.0, 47.1381
10.223324420, 23.970, 2266.0, 47.6025
10.266790180, 23.970, 2289.0, 47.8435
10.310255940, 23.970, 2253.0, 47.4658
10.353721700, 23.970, 2272.0, 47.6655
10.397187460, 23.970, 2263.0, 47.5710
10.440653220, 23.970, 2288.0, 47.8330
10.484118980, 23.970, 2324.0, 48.2079
10.527584740, 23.970, 2247.0, 47.4025
10.571050500, 23.970, 2270.0, 47.6445
10.614516260, 23.970, 2286.0, 47.8121
10.657982020, 23.970, 2357.0, 48.5489
10.701447780, 23.970, 2215.0, 47.0638
10.744913540, 23.970, 2335.0, 48.3218
10.788379300, 23.970, 2335.0, 48.3218
10.831845060, 23.970, 2272.0, 47.6655
10.875310820, 23.970, 2297.0, 47.9270
10.918776580, 23.970, 2317.0, 48.1352
10.962242340, 23.970, 2218.0, 47.0956
11.005708100, 23.970, 2318.0, 48.1456
11.049173860, 23.970, 2289.0, 47.8435
11.092639620, 23.970, 2422.0, 49.2138
11.136105380, 23.970, 2314.0, 48.1041
11.179571140, 23.970, 2357.0, 48.5489
11.223036900, 23.970, 2277.0, 47.7179
11.266502660, 23.970, 2375.0, 48.7340
11.309968420, 23.970, 2316.0, 48.1248
11.353434180, 23.970, 2381.0, 48.7955
11.396899940, 23.970, 2317.0, 48.1352
11.440365700, 23.970, 2335.0, 48.3218
11.483831460, 23.970, 2330.0, 48.2701
11.527297220, 23.970, 2350.0, 48.4768
11.570762980, 23.970, 2381.0, 48.7955
11.614228740, 23.970, 2410.0, 49.0918
11.657694500, 23.970, 2280.0, 47.7493
11.701160260, 23.970, 2394.0, 48.9285
11.744626020, 23.970, 2329.0, 48.2597
11.788091780, 23.970, 2393.0, 48.9183
11.831557540, 23.970, 2365.0, 48.6313
11.875023300, 23.970, 2371.0, 48.6929
11.918489060, 23.970, 2395.0, 48.9387
11.961954820, 23.970, 2356.0, 48.5386
12.005420580, 23.970, 2318.0, 48.1456
12.048886340, 23.970, 2325.0, 48.2183
12.092352100, 23.970, 2456.0, 49.5580
12.135817860, 23.970, 2476.0, 49.7594
12.179283620, 23.970, 2510.0, 50.0999
12.222749380, 23.970, 2468.0, 49.6790
12.266215140, 23.970, 2498.0, 49.9800
12.309680900, 23.970, 2406.0, 49.0510
12.353146660, 23.970, 2482.0, 49.8197
12.396612420, 23.970, 2338.0, 48.3529
12.440078180, 23.970, 2504.0, 50.0400
12.483543940, 23.970, 2480.0, 49.7996
12.527009700, 23.970, 2550.0, 50.4975
12.570475460, 23.970, 2456.0, 49.5580
12.613941220, 23.970, 2491.0, 49.9099
12.657406980, 23.970, 2390.0, 48.8876
12.700872740, 23.970, 2509.0, 50.0899
12.744338500, 23.970, 2463.0, 49.6286
12.787804260, 23.970, 2583.0, 50.8232
12.831270020, 23.970, 2588.0, 50.8724
12.874735780, 23.970, 2465.0, 49.6488
12.918201540, 23.970, 2524.0, 50.2394
12.961667300, 23.970, 2587.0, 50.8626
13.005133060, 23.970, 2577.0, 50.7642
13.048598820, 23.970, 2482.0, 49.8197
13.092064580, 23.970, 2606.0, 51.0490
13.135530340, 23.970, 2531.0, 50.3090
13.178996100, 23.970, 2609.0, 51.0784
13.222461860, 23.970, 2673.0, 51.7011
13.265927620, 23.970, 2612.0, 51.1077
13.309393380, 23.970, 2577.0, 50.7642
13.352859140, 23.970, 2670.0, 51.6720
13.396324900, 23.970, 2666.0, 51.6333
13.439790660, 23.970, 2707.0, 52.0288
13.483256420, 23.970, 2755.0, 52.4881
13.526722180, 23.970, 2754.0, 52.4786
13.570187940, 23.970, 2751.0, 52.4500
13.613653700, 23.970, 2779.0, 52.7162
13.657119460, 23.970, 2843.0, 53.3198
13.700585220, 23.970, 2888.0, 53.7401
13.744050980, 23.970, 2792.0, 52.8394
13.787516740, 23.970, 2832.0, 53.2165
13.830982500, 23.970, 2895.0, 53.8052
13.874448260, 23.970, 2923.0, 54.0648
13.917914020, 23.970, 2901.0, 53.8609
13.961379780, 23.970, 3041.0, 55.1453
14.004845540, 23.970, 2964.0, 54.4426
14.048311300, 23.970, 2964.0, 54.4426
14.091777060, 23.970, 3030.0, 55.0454
14.135242820, 23.970, 3027.0, 55.0182
14.178708580, 23.970, 3042.0, 55.1543
14.222174340, 23.970, 3035.0, 55.0908
14.265640100, 23.970, 3052.0, 55.2449
14.309105860, 23.970, 3105.0, 55.7225
14.352571620, 23.970, 3077.0, 55.4707
14.396037380, 23.970, 3318.0, 57.6021
14.439503140, 23.970, 3199.0, 56.5597
14.482968900, 23.970, 3201.0, 56.5774
14.526434660, 23.970, 3197.0, 56.5420
14.569900420, 23.970, 3248.0, 56.9912
14.613366180, 23.970, 3285.0, 57.3149
14.656831940, 23.970, 3400.0, 58.3095
14.700297700, 23.970, 3441.0, 58.6600
14.743763460, 23.970, 3392.0, 58.2409
14.787229220, 23.970, 3358.0, 57.9483
14.830694980, 23.970, 3483.0, 59.0169
14.874160740, 23.970, 3531.0, 59.4222
14.917626500, 23.970, 3488.0, 59.0593
14.961092260, 23.970, 3497.0, 59.1354
15.004558020, 23.970, 3455.0, 58.7792
15.048023780, 23.970, 3698.0, 60.8112
15.091489540, 23.970, 3552.0, 59.5987
15.134955300, 23.970, 3694.0, 60.7783
15.178421060, 23.970, 3688.0, 60.7289
15.221886820, 23.970, 3759.0, 61.3107
15.265352580, 23.970, 3867.0, 62.1852
15.308818340, 23.970, 3826.0, 61.8547
15.352284100, 23.970, 3812.0, 61.7414
15.395749860, 23.970, 3764.0, 61.3514
15.439215620, 23.970, 3765.0, 61.3596
15.482681380, 23.970, 3820.0, 61.8061
15.526147140, 23.970, 3882.0, 62.3057
15.569612900, 23.970, 3948.0, 62.8331
15.613078660, 23.970, 4022.0, 63.4192
15.656544420, 23.970, 4014.0, 63.3561
15.700010180, 23.970, 4039.0, 63.5531
15.743475940, 23.970, 4152.0, 64.4360
15.786941700, 23.970, 4130.0, 64.2651
15.830407460, 23.970, 4206.0, 64.8537
15.873873220, 23.970, 4296.0, 65.5439
15.917338980, 23.970, 4371.0, 66.1135
15.960804740, 23.970, 4286.0, 65.4675
16.004270500, 23.970, 4377.0, 66.1589
16.047736260, 23.970, 4322.0, 65.7419
16.091202020, 23.970, 4463.0, 66.8057
16.134667780, 23.970, 4399.0, 66.3250
16.178133540, 23.970, 4505.0, 67.1193
16.221599300, 23.970, 4459.0, 66.7757
16.265065060, 23.970, 4637.0, 68.0955
16.308530820, 23.970, 4585.0, 67.7126
16.351996580, 23.970, 4614.0, 67.9264
16.395462340, 23.970, 4727.0, 68.7532
16.438928100, 23.970, 4666.0, 68.3081
16.482393860, 23.970, 4734.0, 68.8041
16.525859620, 23.970, 4797.0, 69.2604
16.569325380, 23.970, 4964.0, 70.4557
16.612791140, 23.970, 4899.0, 69.9929
16.656256900, 23.970, 5027.0, 70.9013
16.699722660, 23.970, 4873.0, 69.8069
16.743188420, 23.970, 5070.0, 71.2039
16.786654180, 23.970, 5043.0, 71.0141
16.830119940, 23.970, 4975.0, 70.5337
16.873585700, 23.970, 5121.0, 71.5612
16.917051460, 23.970, 5146.0, 71.7356
16.960517220, 23.970, 5367.0, 73.2598
17.003982980, 23.970, 5347.0, 73.1232
17.047448740, 23.970, 5317.0, 72.9178
17.090914500, 23.970, 5436.0, 73.7292
17.134380260, 23.970, 5544.0, 74.4580
17.177846020, 23.970, 5548.0, 74.4849
17.221311780, 23.970, 5445.0, 73.7902
17.264777540, 23.970, 5524.0, 74.3236
17.308243300, 23.970, 5653.0, 75.1864
17.351709060, 23.970, 5675.0, 75.3326
17.395174820, 23.970, 5698.0, 75.4851
17.438640580, 23.970, 5817.0, 76.2693
17.482106340, 23.970, 5740.0, 75.7628
17.525572100, 23.970, 5956.0, 77.1751
17.569037860, 23.970, 5973.0, 77.2852
17.612503620, 23.970, 6199.0, 78.7337
17.655969380, 23.970, 6314.0, 79.4607
17.699435140, 23.970, 6206.0, 78.7782
17.742900900, 23.970, 6479.0, 80.4922
17.786366660, 23.970, 6535.0, 80.8393
17.829832420, 23.970, 6626.0, 81.4002
17.873298180, 23.970, 6953.0, 83.3847
17.916763940, 23.970, 6996.0, 83.6421
17.960229700, 23.970, 7364.0, 85.8138
18.003695460, 23.970, 7666.0, 87.5557
18.047161220, 23.970, 8036.0, 89.6437
18.090626980, 23.970, 8388.0, 91.5860
18.134092740, 23.970, 8604.0, 92.7577
18.177558500, 23.970, 9346.0, 96.6747
18.221024260, 23.970, 9733.0, 98.6560
18.264490020, 23.970, 10274.0, 101.3607
18.307955780, 23.970, 10781.0, 103.8316
18.351421540, 23.970, 11184.0, 105.7544
18.394887300, 23.970, 11536.0, 107.4058
18.438353060, 23.970, 11802.0, 108.6370
18.481818820, 23.970, 11994.0, 109.5171
18.525284580, 23.970, 11807.0, 108.6600
18.568750340, 23.970, 11797.0, 108.6140
18.612216100, 23.970, 11516.0, 107.3126
18.655681860, 23.970, 11224.0, 105.9434
18.699147620, 23.970, 10618.0, 103.0437
18.742613380, 23.970, 10051.0, 100.2547
18.786079140, 23.970, 9624.0, 98.1020
18.829544900, 23.970, 9223.0, 96.0365
18.873010660, 23.970, 8814.0, 93.8829
18.916476420, 23.970, 8334.0, 91.2907
18.959942180, 23.970, 8103.0, 90.0167
19.003407940, 23.970, 7803.0, 88.3346
19.046873700, 23.970, 7397.0, 86.0058
19.090339460, 23.970, 7244.0, 85.1117
19.133805220, 23.970, 7104.0, 84.2852
19.177270980, 23.970, 6929.0, 83.2406
19.220736740, 23.970, 6659.0, 81.6027
19.264202500, 23.970, 6658.0, 81.5966
19.307668260, 23.970, 6643.0, 81.5046
19.351134020, 23.970, 6418.0, 80.1124
19.394599780, 23.970, 6549.0, 80.9259
19.438065540, 23.970, 6517.0, 80.7279
19.481531300, 23.970, 6253.0, 79.0759
19.524997060, 23.970, 6370.0, 79.8123
19.568462820, 23.970, 6299.0, 79.3662
19.611928580, 23.970, 6399.0, 79.9937
19.655394340, 23.970, 6376.0, 79.8499
19.698860100, 23.970, 6246.0, 79.0316
19.742325860, 23.970, 6421.0, 80.1311
19.785791620, 23.970, 6323.0, 79.5173
19.829257380, 23.970, 6391.0, 79.9437
19.872723140, 23.970, 6468.0, 80.4239
19.916188900, 23.970, 6464.0, 80.3990
19.959654660, 23.970, 6429.0, 80.1810
20.003120420, 23.970, 6668.0, 81.6578
20.046586180, 23.970, 6542.0, 80.8826
20.090051940, 23.970, 6809.0, 82.5167
20.133517700, 23.970, 6806.0, 82.4985
20.176983460, 23.970, 7348.0, 85.7205
20.220449220, 23.970, 7137.0, 84.4808
20.263914980, 23.970, 7343.0, 85.6913
20.307380740, 23.970, 7282.0, 85.3346
20.350846500, 23.970, 7578.0, 87.0517
20.394312260, 23.970, 7345.0, 85.7030
20.437778020, 23.970, 7385.0, 85.9360
20.481243780, 23.970, 7401.0, 86.0291
20.524709540, 23.970, 7437.0, 86.2380
20.568175300, 23.970, 7359.0, 85.7846
20.611641060, 23.970, 7176.0, 84.7113
20.655106820, 23.970, 7148.0, 84.5458
20.698572580, 23.970, 7061.0, 84.0298
20.742038340, 23.970, 6747.0, 82.1401
20.785504100, 23.970, 6793.0, 82.4197
20.828969860, 23.970, 6460.0, 80.3741
20.872435620, 23.970, 6368.0, 79.7997
20.915901380, 23.970, 6240.0, 78.9937
20.959367140, 23.970, 6302.0, 79.3851
21.002832900, 23.970, 5959.0, 77.1946
21.046298660, 23.970, 6011.0, 77.5306
21.089764420, 23.970, 5932.0, 77.0195
21.133230180, 23.970, 5774.0, 75.9868
21.176695940, 23.970, 5705.0, 75.5315
21.220161700, 23.970, 5726.0, 75.6703
21.263627460, 23.970, 5554.0, 74.5252
21.307093220, 23.970, 5615.0, 74.9333
21.350558980, 23.970, 5530.0, 74.3640
21.394024740, 23.970, 5640.0, 75.0999
21.437490500, 23.970, 5556.0, 74.5386
21.480956260, 23.970, 5613.0, 74.9200
21.524422020, 23.970, 5650.0, 75.1665
21.567887780, 23.970, 5745.0, 75.7958
21.611353540, 23.970, 5735.0, 75.7298
21.654819300, 23.970, 5730.0, 75.6968
21.698285060, 23.970, 5681.0, 75.3724
21.741750820, 23.970, 6041.0, 77.7239
21.785216580, 23.970, 6305.0, 79.4040
21.828682340, 23.970, 6313.0, 79.4544
21.872148100, 23.970, 6545.0, 80.9012
21.915613860, 23.970, 6714.0, 81.9390
21.959079620, 23.970, 6943.0, 83.3247
22.002545380, 23.970, 7194.0, 84.8175
22.046011140, 23.970, 7422.0, 86.1510
22.089476900, 23.970, 7436.0, 86.2322
22.132942660, 23.970, 7706.0, 87.7838
22.176408420, 23.970, 7743.0, 87.9943
22.219874180, 23.970, 7961.0, 89.2244
22.263339940, 23.970, 7900.0, 88.8819
22.306805700, 23.970, 7876.0, 88.7468
22.350271460, 23.970, 7864.0, 88.6792
22.393737220, 23.970, 7894.0, 88.8482
22.437202980, 23.970, 7853.0, 88.6172
22.480668740, 23.970, 7497.0, 86.5852
22.524134500, 23.970, 7749.0, 88.0284
22.567600260, 23.970, 7286.0, 85.3581
22.611066020, 23.970, 7135.0, 84.4689
22.654531780, 23.970, 6756.0, 82.1949
22.697997540, 23.970, 6653.0, 81.5659
22.741463300, 23.970, 6495.0, 80.5916
22.784929060, 23.970, 6211.0, 78.8099
22.828394820, 23.970, 6145.0, 78.3901
22.871860580, 23.970, 5940.0, 77.0714
22.915326340, 23.970, 5864.0, 76.5768
22.958792100, 23.970, 5623.0, 74.9867
23.002257860, 23.970, 5419.0, 73.6139
23.045723620, 23.970, 5306.0, 72.8423
23.089189380, 23.970, 5186.0, 72.0139
23.132655140, 23.970, 4980.0, 70.5691
23.176120900, 23.970, 4817.0, 69.4046
23.219586660, 23.970, 4803.0, 69.3037
23.263052420, 23.970, 4536.0, 67.3498
23.306518180, 23.970, 4470.0, 66.8581
23.349983940, 23.970, 4462.0, 66.7982
23.393449700, 23.970, 4336.0, 65.8483
23.436915460, 23.970, 4169.0, 64.5678
23.480381220, 23.970, 4144.0, 64.3739
23.523846980, 23.970, 3897.0, 62.4260
23.567312740, 23.970, 3897.0, 62.4260
23.610778500, 23.970, 3904.0, 62.4820
23.654244260, 23.970, 3773.0, 61.4248
23.697710020, 23.970, 3756.0, 61.2862
23.741175780, 23.970, 3656.0, 60.4649
23.784641540, 23.970, 3576.0, 59.7997
23.828107300, 23.970, 3535.0, 59.4559
23.871573060, 23.970, 3526.0, 59.3801
23.915038820, 23.970, 3420.0, 58.4808
23.958504580, 23.970, 3285.0, 57.3149
24.001970340, 23.970, 3333.0, 57.7321
24.045436100, 23.970, 3342.0, 57.8100
24.088901860, 23.970, 3399.0, 58.3009
24.132367620, 23.970, 3182.0, 56.4092
24.175833380, 23.970, 3277.0, 57.2451
24.219299140, 23.970, 3175.0, 56.3471
24.262764900, 23.970, 3133.0, 55.9732
24.306230660, 23.970, 3106.0, 55.7315
24.349696420, 23.970, 3273.0, 57.2101
24.393162180, 23.970, 3104.0, 55.7136
24.436627940, 23.970, 3117.0, 55.8301
24.480093700, 23.970, 3093.0, 55.6147
24.523559460, 23.970, 3086.0, 55.5518
24.567025220, 23.970, 2966.0, 54.4610
24.610490980, 23.970, 2958.0, 54.3875
24.653956740, 23.970, 2928.0, 54.1110
24.697422500, 23.970, 2905.0, 53.8981
24.740888260, 23.970, 2901.0, 53.8609
24.784354020, 23.970, 2905.0, 53.8981
24.827819780, 23.970, 2918.0, 54.0185
24.871285540, 23.970, 2844.0, 53.3292
24.914751300, 23.970, 2835.0, 53.2447
24.958217060, 23.970, 2884.0, 53.7029
25.001682820, 23.970, 2887.0, 53.7308
25.045148580, 23.970, 2820.0, 53.1037
25.088614340, 23.970, 2828.0, 53.1789
25.132080100, 23.970, 2963.0, 54.4334
25.175545860, 23.970, 2803.0, 52.9434
25.219011620, 23.970, 2852.0, 53.4041
25.262477380, 23.970, 2719.0, 52.1440
25.305943140, 23.970, 2860.0, 53.4790
25.349408900, 23.970, 2799.0, 52.9056
25.392874660, 23.970, 2744.0, 52.3832
25.436340420, 23.970, 2795.0, 52.8678
25.479806180, 23.970, 2724.0, 52.1920
25.523271940, 23.970, 2740.0, 52.3450
25.566737700, 23.970, 2660.0, 51.5752
25.610203460, 23.970, 2705.0, 52.0096
25.653669220, 23.970, 2659.0, 51.5655
25.697134980, 23.970, 2709.0, 52.0481
25.740600740, 23.970, 2638.0, 51.3615
25.784066500, 23.970, 2616.0, 51.1468
25.827532260, 23.970, 2614.0, 51.1273
25.870998020, 23.970, 2602.0, 51.0098
25.914463780, 23.970, 2511.0, 50.1099
25.957929540, 23.970, 2536.0, 50.3587
26.001395300, 23.970, 2479.0, 49.7896
26.044861060, 23.970, 2501.0, 50.0100
26.088326820, 23.970, 2501.0, 50.0100
26.131792580, 23.970, 2550.0, 50.4975
26.175258340, 23.970, 2467.0, 49.6689
26.218724100, 23.970, 2578.0, 50.7740
26.262189860, 23.970, 2542.0, 50.4183
26.305655620, 23.970, 2504.0, 50.0400
26.349121380, 23.970, 2440.0, 49.3964
26.392587140, 23.970, 2436.0, 49.3559
26.436052900, 23.970, 2428.0, 49.2747
26.479518660, 23.970, 2447.0, 49.4672
26.522984420, 23.970, 2443.0, 49.4267
26.566450180, 23.970, 2423.0, 49.2240
26.609915940, 23.970, 2341.0, 48.3839
26.653381700, 23.970, 2377.0, 48.7545
26.696847460, 23.970, 2391.0, 48.8979
26.740313220, 23.970, 2342.0, 48.3942
26.783778980, 23.970, 2387.0, 48.8569
26.827244740, 23.970, 2429.0, 49.2849
26.870710500, 23.970, 2404.0, 49.0306
26.914176260, 23.970, 2275.0, 47.6970
26.957642020, 23.970, 2377.0, 48.7545
27.001107780, 23.970, 2339.0, 48.3632
27.044573540, 23.970, 2365.0, 48.6313
27.088039300, 23.970, 2291.0, 47.8644
27.131505060, 23.970, 2398.0, 48.9694
27.174970820, 23.970, 2311.0, 48.0729
27.218436580, 23.970, 2216.0, 47.0744
27.261902340, 23.970, 2328.0, 48.2494
27.305368100, 23.970, 2229.0, 47.2123
27.348833860, 23.970, 2280.0, 47.7493
27.392299620, 23.970, 2376.0, 48.7442
27.435765380, 23.970, 2308.0, 48.0416
27.479231140, 23.970, 2354.0, 48.5180
27.522696900, 23.970, 2441.0, 49.4065
27.566162660, 23.970, 2451.0, 49.5076
27.609628420, 23.970, 2540.0, 50.3984
27.653094180, 23.970, 2531.0, 50.3090
27.696559940, 23.970, 2532.0, 50.3190
27.740025700, 23.970, 2540.0, 50.3984
27.783491460, 23.970, 2671.0, 51.6817
27.826957220, 23.970, 2713.0, 52.0865
27.870422980, 23.970, 2766.0, 52.5928
27.913888740, 23.970, 2841.0, 53.3010
27.957354500, 23.970, 2949.0, 54.3047
28.000820260, 23.970, 3045.0, 55.1815
28.044286020, 23.970, 3080.0, 55.4977
28.087751780, 23.970, 3120.0, 55.8570
28.131217540, 23.970, 3271.0, 57.1927
28.174683300, 23.970, 3263.0, 57.1227
28.218149060, 23.970, 3481.0, 59.0000
28.261614820, 23.970, 3490.0, 59.0762
28.305080580, 23.970, 3571.0, 59.7578
28.348546340, 23.970, 3501.0, 59.1692
28.392012100, 23.970, 3579.0, 59.8247
28.435477860, 23.970, 3479.0, 58.9830
28.478943620, 23.970, 3526.0, 59.3801
28.522409380, 23.970, 3529.0, 59.4054
28.565875140, 23.970, 3528.0, 59.3970
28.609340900, 23.970, 3505.0, 59.2030
28.652806660, 23.970, 3452.0, 58.7537
28.696272420, 23.970, 3335.0, 57.7495
28.739738180, 23.970, 3256.0, 57.0614
28.783203940, 23.970, 3350.0, 57.8792
28.826669700, 23.970, 3205.0, 56.6127
28.870135460, 23.970, 3114.0, 55.8032
28.913601220, 23.970, 3032.0, 55.0636
28.957066980, 23.970, 3021.0, 54.9636
29.000532740, 23.970, 2873.0, 53.6004
29.043998500, 23.970, 2783.0, 52.7541
29.087464260, 23.970, 2723.0, 52.1824
29.130930020, 23.970, 2666.0, 51.6333
29.174395780, 23.970, 2537.0, 50.3686
29.217861540, 23.970, 2503.0, 50.0300
29.261327300, 23.970, 2473.0, 49.7293
29.304793060, 23.970, 2370.0, 48.6826
29.348258820, 23.970, 2317.0, 48.1352
29.391724580, 23.970, 2300.0, 47.9583
29.435190340, 23.970, 2215.0, 47.0638
29.478656100, 23.970, 2231.0, 47.2335
29.522121860, 23.970, 2229.0, 47.2123
29.565587620, 23.970, 2201.0, 46.9148
29.609053380, 23.970, 2130.0, 46.1519
29.652519140, 23.970, 2296.0, 47.9166
29.695984900, 23.970, 2228.0, 47.2017
29.739450660, 23.970, 2068.0, 45.4753
29.782916420, 23.970, 2148.0, 46.3465
29.826382180, 23.970, 2167.0, 46.5510
29.869847940, 23.970, 2059.0, 45.3762
29.913313700, 23.970, 2015.0, 44.8888
29.956779460, 23.970, 2034.0, 45.0999
30.000245220, 23.970, 2053.0, 45.3100
30.043710980, 23.970, 2007.0, 44.7996
30.087176740, 23.970, 2040.0, 45.1664
30.130642500, 23.970, 2000.0, 44.7214
30.174108260, 23.970, 2012.0, 44.8553
30.217574020, 23.970, 1850.0, 43.0116
30.261039780, 23.970, 1869.0, 43.2319
30.304505540, 23.970, 1876.0, 43.3128
30.347971300, 23.970, 1819.0, 42.6497
30.391437060, 23.970, 1815.0, 42.6028
30.434902820, 23.970, 1870.0, 43.2435
30.478368580, 23.970, 1773.0, 42.1070
30.521834340, 23.970, 1784.0, 42.2374
30.565300100, 23.970, 1745.0, 41.7732
30.608765860, 23.970, 1741.0, 41.7253
30.652231620, 23.970, 1716.0, 41.4246
30.695697380, 23.970, 1731.0, 41.6053
30.739163140, 23.970, 1759.0, 41.9404
30.782628900, 23.970, 1679.0, 40.9756
30.826094660, 23.970, 1640.0, 40.4969
30.869560420, 23.970, 1736.0, 41.6653
30.913026180, 23.970, 1758.0, 41.9285
30.956491940, 23.970, 1655.0, 40.6817
30.999957700, 23.970, 1750.0, 41.8330
31.043423460, 23.970, 1715.0, 41.4126
31.086889220, 23.970, 1694.0, 41.1582
31.130354980, 23.970, 1651.0, 40.6325
31.173820740, 23.970, 1577.0, 39.7115
31.217286500, 23.970, 1674.0, 40.9145
31.260752260, 23.970, 1718.0, 41.4488
31.304218020, 23.970, 1650.0, 40.6202
31.347683780, 23.970, 1612.0, 40.1497
31.391149540, 23.970, 1550.0, 39.3700
31.434615300, 23.970, 1601.0, 40.0125
31.478081060, 23.970, 1623.0, 40.2865
31.521546820, 23.970, 1635.0, 40.4351
31.565012580, 23.970, 1588.0, 39.8497
31.608478340, 23.970, 1530.0, 39.1152
31.651944100, 23.970, 1582.0, 39.7744
31.695409860, 23.970, 1623.0, 40.2865
31.738875620, 23.970, 1616.0, 40.1995
31.782341380, 23.970, 1635.0, 40.4351
31.825807140, 23.970, 1626.0, 40.3237
31.869272900, 23.970, 1534.0, 39.1663
31.912738660, 23.970, 1568.0, 39.5980
31.956204420, 23.970, 1564.0, 39.5474
31.999670180, 23.970, 1656.0, 40.6940
32.043135940, 23.970, 1629.0, 40.3609
32.086601700, 23.970, 1681.0, 41.0000
32.130067460, 23.970, 1598.0, 39.9750
32.173533220, 23.970, 1610.0, 40.1248
32.216998980, 23.970, 1726.0, 41.5452
32.260464740, 23.970, 1613.0, 40.1622
32.303930500, 23.970, 1647.0, 40.5832
32.347396260, 23.970, 1634.0, 40.4228
32.390862020, 23.970, 1586.0, 39.8246
32.434327780, 23.970, 1662.0, 40.7676
32.477793540, 23.970, 1723.0, 41.5090
32.521259300, 23.970, 1675.0, 40.9268
32.564725060, 23.970, 1685.0, 41.0488
32.608190820, 23.970, 1753.0, 41.8688
32.651656580, 23.970, 1670.0, 40.8656
32.695122340, 23.970, 1650.0, 40.6202
32.738588100, 23.970, 1640.0, 40.4969
32.782053860, 23.970, 1581.0, 39.7618
32.825519620, 23.970, 1647.0, 40.5832
32.868985380, 23.970, 1563.0, 39.5348
32.912451140, 23.970, 1577.0, 39.7115
32.955916900, 23.970, 1635.0, 40.4351
32.999382660, 23.970, 1520.0, 38.9872
33.042848420, 23.970, 1584.0, 39.7995
33.086314180, 23.970, 1575.0, 39.6863
33.129779940, 23.970, 1603.0, 40.0375
33.173245700, 23.970, 1463.0, 38.2492
33.216711460, 23.970, 1534.0, 39.1663
33.260177220, 23.970, 1566.0, 39.5727
33.303642980, 23.970, 1553.0, 39.4081
33.347108740, 23.970, 1557.0, 39.4588
33.390574500, 23.970, 1467.0, 38.3014
33.434040260, 23.970, 1504.0, 38.7814
33.477506020, 23.970, 1480.0, 38.4708
33.520971780, 23.970, 1520.0, 38.9872
33.564437540, 23.970, 1503.0, 38.7685
33.607903300, 23.970, 1419.0, 37.6696
33.651369060, 23.970, 1426.0, 37.7624
33.694834820, 23.970, 1403.0, 37.4566
33.738300580, 23.970, 1440.0, 37.9473
33.781766340, 23.970, 1317.0, 36.2905
33.825232100, 23.970, 1380.0, 37.1484
33.868697860, 23.970, 1338.0, 36.5787
33.912163620, 23.970, 1329.0, 36.4555
33.955629380, 23.970, 1302.0, 36.0832
33.999095140, 23.970, 1333.0, 36.5103
34.042560900, 23.970, 1287.0, 35.8748
34.086026660, 23.970, 1309.0, 36.1801
34.129492420, 23.970, 1307.0, 36.1525
34.172958180, 23.970, 1271.0, 35.6511
34.216423940, 23.970, 1239.0, 35.1994
34.259889700, 23.970, 1225.0, 35.0000
34.303355460, 23.970, 1280.0, 35.7771
34.346821220, 23.970, 1286.0, 35.8608
34.390286980, 23.970, 1266.0, 35.5809
34.433752740, 23.970, 1287.0, 35.8748
34.477218500, 23.970, 1256.0, 35.4401
34.520684260, 23.970, 1233.0, 35.1141
34.564150020, 23.970, 1314.0, 36.2491
34.607615780, 23.970, 1303.0, 36.0971
34.651081540, 23.970, 1226.0, 35.0143
34.694547300, 23.970, 1245.0, 35.2846
34.738013060, 23.970, 1250.0, 35.3553
34.781478820, 23.970, 1226.0, 35.0143
34.824944580, 23.970, 1200.0, 34.6410
34.868410340, 23.970, 1282.0, 35.8050
34.911876100, 23.970, 1160.0, 34.0588
34.955341860, 23.970, 1217.0, 34.8855
34.998807620, 23.970, 1268.0, 35.6090
35.042273380, 23.970, 1203.0, 34.6843
35.085739140, 23.970, 1173.0, 34.2491
35.129204900, 23.970, 1212.0, 34.8138
35.172670660, 23.970, 1203.0, 34.6843
35.216136420, 23.970, 1267.0, 35.5949
35.259602180, 23.970, 1212.0, 34.8138
35.303067940, 23.970, 1184.0, 34.4093
35.346533700, 23.970, 1231.0, 35.0856
35.389999460, 23.970, 1237.0, 35.1710
35.433465220, 23.970, 1232.0, 35.0999
35.476930980, 23.970, 1217.0, 34.8855
35.520396740, 23.970, 1250.0, 35.3553
35.563862500, 23.970, 1119.0, 33.4515
35.607328260, 23.970, 1186.0, 34.4384
35.650794020, 23.970, 1120.0, 33.4664
35.694259780, 23.970, 1196.0, 34.5832
35.737725540, 23.970, 1223.0, 34.9714
35.781191300, 23.970, 1169.0, 34.1906
35.824657060, 23.970, 1124.0, 33.5261
35.868122820, 23.970, 1162.0, 34.0881
35.911588580, 23.970, 1194.0, 34.5543
35.955054340, 23.970, 1143.0, 33.8083
35.998520100, 23.970, 1162.0, 34.0881
36.041985860, 23.970, 1100.0, 33.1662
36.085451620, 23.970, 1095.0, 33.0908
36.128917380, 23.970, 1097.0, 33.1210
36.172383140, 23.970, 1178.0, 34.3220
36.215848900, 23.970, 1190.0, 34.4964
36.259314660, 23.970, 1156.0, 34.0000
36.302780420, 23.970, 1184.0, 34.4093
36.346246180, 23.970, 1141.0, 33.7787
36.389711940, 23.970, 1165.0, 34.1321
36.433177700, 23.970, 1169.0, 34.1906
36.476643460, 23.970, 1130.0, 33.6155
36.520109220, 23.970, 1214.0, 34.8425
36.563574980, 23.970, 1132.0, 33.6452
36.607040740, 23.970, 1201.0, 34.6554
36.650506500, 23.970, 1170.0, 34.2053
36.693972260, 23.970, 1169.0, 34.1906
36.737438020, 23.970, 1193.0, 34.5398
36.780903780, 23.970, 1135.0, 33.6898
36.824369540, 23.970, 1186.0, 34.4384
36.867835300, 23.970, 1128.0, 33.5857
36.911301060, 23.970, 1174.0, 34.2637
36.954766820, 23.970, 1234.0, 35.1283
36.998232580, 23.970, 1186.0, 34.4384
37.041698340, 23.970, 1222.0, 34.9571
37.085164100, 23.970, 1227.0, 35.0286
37.128629860, 23.970, 1212.0, 34.8138
37.172095620, 23.970, 1205.0, 34.7131
37.215561380, 23.970, 1227.0, 35.0286
37.259027140, 23.970, 1259.0, 35.4824
37.302492900, 23.970, 1273.0, 35.6791
37.345958660, 23.970, 1206.0, 34.7275
37.389424420, 23.970, 1294.0, 35.9722
37.432890180, 23.970, 1250.0, 35.3553
37.476355940, 23.970, 1193.0, 34.5398
37.519821700, 23.970, 1297.0, 36.0139
37.563287460, 23.970, 1275.0, 35.7071
37.606753220, 23.970, 1323.0, 36.3731
37.650218980, 23.970, 1278.0, 35.7491
37.693684740, 23.970, 1313.0, 36.2353
37.737150500, 23.970, 1315.0, 36.2629
37.780616260, 23.970, 1277.0, 35.7351
37.824082020, 23.970, 1374.0, 37.0675
37.867547780, 23.970, 1364.0, 36.9324
37.911013540, 23.970, 1347.0, 36.7015
37.954479300, 23.970, 1422.0, 37.7094
37.997945060, 23.970, 1384.0, 37.2022
38.041410820, 23.970, 1332.0, 36.4966
38.084876580, 23.970, 1448.0, 38.0526
38.128342340, 23.970, 1375.0, 37.0810
38.171808100, 23.970, 1379.0, 37.1349
38.215273860, 23.970, 1397.0, 37.3765
38.258739620, 23.970, 1434.0, 37.8682
38.302205380, 23.970, 1418.0, 37.6563
38.345671140, 23.970, 1500.0, 38.7298
38.389136900, 23.970, 1439.0, 37.9342
38.432602660, 23.970, 1466.0, 38.2884
38.476068420, 23.970, 1430.0, 37.8153
38.519534180, 23.970, 1399.0, 37.4032
38.562999940, 23.970, 1425.0, 37.7492
38.606465700, 23.970, 1525.0, 39.0512
38.649931460, 23.970, 1442.0, 37.9737
38.693397220, 23.970, 1524.0, 39.0384
38.736862980, 23.970, 1520.0, 38.9872
38.780328740, 23.970, 1513.0, 38.8973
38.823794500, 23.970, 1428.0, 37.7889
38.867260260, 23.970, 1447.0, 38.0395
38.910726020, 23.970, 1491.0, 38.6135
38.954191780, 23.970, 1443.0, 37.9868
38.997657540, 23.970, 1453.0, 38.1182
39.041123300, 23.970, 1449.0, 38.0657
39.084589060, 23.970, 1477.0, 38.4318
39.128054820, 23.970, 1406.0, 37.4967
39.171520580, 23.970, 1351.0, 36.7560
39.214986340, 23.970, 1334.0, 36.5240
39.258452100, 23.970, 1386.0, 37.2290
39.301917860, 23.970, 1255.0, 35.4260
39.345383620, 23.970, 1314.0, 36.2491
39.388849380, 23.970, 1282.0, 35.8050
39.432315140, 23.970, 1344.0, 36.6606
39.475780900, 23.970, 1216.0, 34.8712
39.519246660, 23.970, 1194.0, 34.5543
39.562712420, 23.970, 1281.0, 35.7911
39.606178180, 23.970, 1268.0, 35.6090
39.649643940, 23.970, 1321.0, 36.3456
39.693109700, 23.970, 1285.0, 35.8469
39.736575460, 23.970, 1230.0, 35.0714
39.780041220, 23.970, 1321.0, 36.3456
39.823506980, 23.970, 1253.0, 35.3977
39.866972740, 23.970, 1203.0, 34.6843
39.910438500, 23.970, 1214.0, 34.8425
39.953904260, 23.970, 1217.0, 34.8855
39.997370020, 23.970, 1277.0, 35.7351
40.040835780, 23.970, 1236.0, 35.1568
40.084301540, 23.970, 1249.0, 35.3412
40.127767300, 23.970, 1220.0, 34.9285
40.171233060, 23.970, 1231.0, 35.0856
40.214698820, 23.970, 1248.0, 35.3270
40.258164580, 23.970, 1210.0, 34.7851
40.301630340, 23.970, 1221.0, 34.9428
40.345096100, 23.970, 1235.0, 35.1426
40.388561860, 23.970, 1281.0, 35.7911
40.432027620, 23.970, 1318.0, 36.3043
40.475493380, 23.970, 1326.0, 36.4143
40.518959140, 23.970, 1199.0, 34.6266
40.562424900, 23.970, 1259.0, 35.4824
40.605890660, 23.970, 1290.0, 35.9166
40.649356420, 23.970, 1290.0, 35.9166
40.692822180, 23.970, 1261.0, 35.5106
40.736287940, 23.970, 1247.0, 35.3129
40.779753700, 23.970, 1259.0, 35.4824
40.823219460, 23.970, 1304.0, 36.1109
40.866685220, 23.970, 1285.0, 35.8469
40.910150980, 23.970, 1258.0, 35.4683
40.953616740, 23.970, 1308.0, 36.1663
40.997082500, 23.970, 1285.0, 35.8469
41.040548260, 23.970, 1262.0, 35.5246
41.084014020, 23.970, 1269.0, 35.6230
41.127479780, 23.970, 1280.0, 35.7771
41.170945540, 23.970, 1221.0, 34.9428
41.214411300, 23.970, 1236.0, 35.1568
41.257877060, 23.970, 1261.0, 35.5106
41.301342820, 23.970, 1275.0, 35.7071
41.344808580, 23.970, 1230.0, 35.0714
41.388274340, 23.970, 1244.0, 35.2704
41.431740100, 23.970, 1188.0, 34.4674
41.475205860, 23.970, 1193.0, 34.5398
41.518671620, 23.970, 1134.0, 33.6749
41.562137380, 23.970, 1233.0, 35.1141
41.605603140, 23.970, 1157.0, 34.0147
41.649068900, 23.970, 1166.0, 34.1467
41.692534660, 23.970, 1183.0, 34.3948
41.736000420, 23.970, 1183.0, 34.3948
41.779466180, 23.970, 1187.0, 34.4529
41.822931940, 23.970, 1158.0, 34.0294
41.866397700, 23.970, 1198.0, 34.6121
41.909863460, 23.970, 1178.0, 34.3220
41.953329220, 23.970, 1173.0, 34.2491
41.996794980, 23.970, 1107.0, 33.2716
42.040260740, 23.970, 1132.0, 33.6452
42.083726500, 23.970, 1157.0, 34.0147
42.127192260, 23.970, 1136.0, 33.7046
42.170658020, 23.970, 1120.0, 33.4664
42.214123780, 23.970, 1142.0, 33.7935
42.257589540, 23.970, 1128.0, 33.5857
42.301055300, 23.970, 1177.0, 34.3074
42.344521060, 23.970, 1135.0, 33.6898
42.387986820, 23.970, 1185.0, 34.4238
42.431452580, 23.970, 1224.0, 34.9857
42.474918340, 23.970, 1116.0, 33.4066
42.518384100, 23.970, 1196.0, 34.5832
42.561849860, 23.970, 1202.0, 34.6699
42.605315620, 23.970, 1222.0, 34.9571
42.648781380, 23.970, 1213.0, 34.8281
42.692247140, 23.970, 1173.0, 34.2491
42.735712900, 23.970, 1165.0, 34.1321
42.779178660, 23.970, 1111.0, 33.3317
42.822644420, 23.970, 1104.0, 33.2265
42.866110180, 23.970, 1007.0, 31.7333
42.909575940, 23.970, 1065.0, 32.6343
42.953041700, 23.970, 1092.0, 33.0454
42.996507460, 23.970, 1140.0, 33.7639
43.039973220, 23.970, 1144.0, 33.8231
43.083438980, 23.970, 1132.0, 33.6452
43.126904740, 23.970, 1057.0, 32.5115
43.170370500, 23.970, 1115.0, 33.3916
43.213836260, 23.970, 1084.0, 32.9242
43.257302020, 23.970, 1038.0, 32.2180
43.300767780, 23.970, 1069.0, 32.6956
43.344233540, 23.970, 1074.0, 32.7719
43.387699300, 23.970, 1053.0, 32.4500
43.431165060, 23.970, 1098.0, 33.1361
43.474630820, 23.970, 1095.0, 33.0908
43.518096580, 23.970, 1096.0, 33.1059
43.561562340, 23.970, 1062.0, 32.5883
43.605028100, 23.970, 1087.0, 32.9697
43.648493860, 23.970, 1078.0, 32.8329
43.691959620, 23.970, 1053.0, 32.4500
43.735425380, 23.970, 1097.0, 33.1210
43.778891140, 23.970, 1059.0, 32.5423
43.822356900, 23.970, 1088.0, 32.9848
43.865822660, 23.970, 1082.0, 32.8938
43.909288420, 23.970, 1038.0, 32.2180
43.952754180, 23.970, 1059.0, 32.5423
43.996219940, 23.970, 1131.0, 33.6303
44.039685700, 23.970, 1013.0, 31.8277
44.083151460, 23.970, 1012.0, 31.8119
44.126617220, 23.970, 1093.0, 33.0606
44.170082980, 23.970, 1155.0, 33.9853
44.213548740, 23.970, 1051.0, 32.4191
44.257014500, 23.970, 1089.0, 33.0000
44.300480260, 23.970, 1035.0, 32.1714
44.343946020, 23.970, 1063.0, 32.6037
44.387411780, 23.970, 1146.0, 33.8526
44.430877540, 23.970, 1097.0, 33.1210
44.474343300, 23.970, 1078.0, 32.8329
44.517809060, 23.970, 1057.0, 32.5115
44.561274820, 23.970, 1080.0, 32.8634
44.604740580, 23.970, 1085.0, 32.9393
44.648206340, 23.970, 1078.0, 32.8329
44.691672100, 23.970, 1113.0, 33.3617
44.735137860, 23.970, 1094.0, 33.0757
44.778603620, 23.970, 1101.0, 33.1813
44.822069380, 23.970, 1034.0, 32.1559
44.865535140, 23.970, 1068.0, 32.6803
44.909000900, 23.970, 1052.0, 32.4345
44.952466660, 23.970, 1047.0, 32.3574
44.995932420, 23.970, 1067.0, 32.6650
45.039398180, 23.970, 1076.0, 32.8024
45.082863940, 23.970, 1125.0, 33.5410
45.126329700, 23.970, 1057.0, 32.5115
45.169795460, 23.970, 1088.0, 32.9848
45.213261220, 23.970, 1062.0, 32.5883
45.256726980, 23.970, 1024.0, 32.0000
45.300192740, 23.970, 1057.0, 32.5115
45.343658500, 23.970, 1053.0, 32.4500
45.387124260, 23.970, 1087.0, 32.9697
45.430590020, 23.970, 1081.0, 32.8786
45.474055780, 23.970, 1046.0, 32.3419
45.517521540, 23.970, 1107.0, 33.2716
45.560987300, 23.970, 1080.0, 32.8634
45.604453060, 23.970, 1045.0, 32.3265
45.647918820, 23.970, 1083.0, 32.9090
45.691384580, 23.970, 1067.0, 32.6650
45.734850340, 23.970, 1181.0, 34.3657
45.778316100, 23.970, 1077.0, 32.8177
45.821781860, 23.970, 1102.0, 33.1964
45.865247620, 23.970, 1124.0, 33.5261
45.908713380, 23.970, 1081.0, 32.8786
45.952179140, 23.970, 1083.0, 32.9090
45.995644900, 23.970, 1091.0, 33.0303
46.039110660, 23.970, 1137.0, 33.7194
46.082576420, 23.970, 1141.0, 33.7787
46.126042180, 23.970, 1160.0, 34.0588
46.169507940, 23.970, 1162.0, 34.0881
46.212973700, 23.970, 1129.0, 33.6006
46.256439460, 23.970, 1101.0, 33.1813
46.299905220, 23.970, 1184.0, 34.4093
46.343370980, 23.970, 1160.0, 34.0588
46.386836740, 23.970, 1144.0, 33.8231
46.430302500, 23.970, 1158.0, 34.0294
46.473768260, 23.970, 1133.0, 33.6601
46.517234020, 23.970, 1173.0, 34.2491
46.560699780, 23.970, 1141.0, 33.7787
46.604165540, 23.970, 1236.0, 35.1568
46.647631300, 23.970, 1251.0, 35.3695
46.691097060, 23.970, 1243.0, 35.2562
46.734562820, 23.970, 1260.0, 35.4965
46.778028580, 23.970, 1321.0, 36.3456
46.821494340, 23.970, 1348.0, 36.7151
46.864960100, 23.970, 1357.0, 36.8375
46.908425860, 23.970, 1362.0, 36.9053
46.951891620, 23.970, 1406.0, 37.4967
46.995357380, 23.970, 1397.0, 37.3765
47.038823140, 23.970, 1404.0, 37.4700
47.082288900, 23.970, 1331.0, 36.4829
47.125754660, 23.970, 1358.0, 36.8511
47.169220420, 23.970, 1285.0, 35.8469
47.212686180, 23.970, 1234.0, 35.1283
47.256151940, 23.970, 1252.0, 35.3836
47.299617700, 23.970, 1240.0, 35.2136
47.343083460, 23.970, 1257.0, 35.4542
47.386549220, 23.970, 1247.0, 35.3129
47.430014980, 23.970, 1235.0, 35.1426
47.473480740, 23.970, 1211.0, 34.7994
47.516946500, 23.970, 1260.0, 35.4965
47.560412260, 23.970, 1257.0, 35.4542
47.603878020, 23.970, 1188.0, 34.4674
47.647343780, 23.970, 1264.0, 35.5528
47.690809540, 23.970, 1223.0, 34.9714
47.734275300, 23.970, 1170.0, 34.2053
47.777741060, 23.970, 1264.0, 35.5528
47.821206820, 23.970, 1271.0, 35.6511
47.864672580, 23.970, 1214.0, 34.8425
47.908138340, 23.970, 1282.0, 35.8050
47.951604100, 23.970, 1294.0, 35.9722
47.995069860, 23.970, 1286.0, 35.8608
48.038535620, 23.970, 1161.0, 34.0735
48.082001380, 23.970, 1216.0, 34.8712
48.125467140, 23.970, 1182.0, 34.3802
48.168932900, 23.970, 1122.0, 33.4963
48.212398660, 23.970, 1104.0, 33.2265
48.255864420, 23.970, 1060.0, 32.5576
48.299330180, 23.970, 1034.0, 32.1559
48.342795940, 23.970, 1007.0, 31.7333
48.386261700, 23.970, 1053.0, 32.4500
48.429727460, 23.970, 1056.0, 32.4962
48.473193220, 23.970, 1013.0, 31.8277
48.516658980, 23.970, 984.0, 31.3688
48.560124740, 23.970, 1047.0, 32.3574
48.603590500, 23.970, 1031.0, 32.1092
48.647056260, 23.970, 1013.0, 31.8277
48.690522020, 23.970, 994.0, 31.5278
48.733987780, 23.970, 982.0, 31.3369
48.777453540, 23.970, 1039.0, 32.2335
48.820919300, 23.970, 1020.0, 31.9374
48.864385060, 23.970, 986.0, 31.4006
48.907850820, 23.970, 1059.0, 32.5423
48.951316580, 23.970, 963.0, 31.0322
48.994782340, 23.970, 1000.0, 31.6228
49.038248100, 23.970, 1025.0, 32.0156
49.081713860, 23.970, 1008.0, 31.7490
49.125179620, 23.970, 1021.0, 31.9531
49.168645380, 23.970, 1008.0, 31.7490
49.212111140, 23.970, 991.0, 31.4802
49.255576900, 23.970, 1106.0, 33.2566
49.299042660, 23.970, 983.0, 31.3528
49.342508420, 23.970, 1011.0, 31.7962
49.385974180, 23.970, 1057.0, 32.5115
49.429439940, 23.970, 1023.0, 31.9844
49.472905700, 23.970, 1029.0, 32.0780
49.516371460, 23.970, 954.0, 30.8869
49.559837220, 23.970, 997.0, 31.5753
49.603302980, 23.970, 1030.0, 32.0936
49.646768740, 23.970, 979.0, 31.2890
49.690234500, 23.970, 971.0, 31.1609
49.733700260, 23.970, 1031.0, 32.1092
49.777166020, 23.970, 1040.0, 32.2490
49.820631780, 23.970, 969.0, 31.1288
49.864097540, 23.970, 1005.0, 31.7017
49.907563300, 23.970, 1030.0, 32.0936
49.951029060, 23.970, 1020.0, 31.9374
49.994494820, 23.970, 938.0, 30.6268