File: data/DSC/HDPE_6 (cal).csv
[Measurement conditions]
Sample identification,HDPE_6 (cal)
Comment,
Anode material,Cu
K-Alpha1 wavelength,1.5405980
K-Alpha2 wavelength,1.5444260
Ratio K-Alpha2/K-Alpha1,0.500
Divergence slit,Fixed,0.38mm
Monochromator used,NO
Generator voltage, 40
Tube current, 15
File date and time,02/Apr/2025 17:43
Unit cell,
h k l, 0 0 0
Scan axis,Gonio
Scan range,3.000000000,79.999593840
Scan step size,0.0108664
No. of points, 7086
Scan type,CONTINUOUS
Time per step,23.970
[Scan points]
Angle, TimePerStep, Intensity, ESD
3.005433220, 23.970, 1449.0, 38.0657
3.070631860, 23.970, 1420.0, 37.6829
3.135830500, 23.970, 1355.0, 36.8103
3.201029140, 23.970, 1354.0, 36.7967
3.266227780, 23.970, 1199.0, 34.6266
3.331426420, 23.970, 1205.0, 34.7131
3.396625060, 23.970, 1228.0, 35.0428
3.461823700, 23.970, 1099.0, 33.1512
3.527022340, 23.970, 1107.0, 33.2716
3.592220980, 23.970, 1122.0, 33.4963
3.657419620, 23.970, 1034.0, 32.1559
3.722618260, 23.970, 1021.0, 31.9531
3.787816900, 23.970, 1001.0, 31.6386
3.853015540, 23.970, 988.0, 31.4325
3.918214180, 23.970, 1030.0, 32.0936
3.983412820, 23.970, 988.0, 31.4325
4.048611460, 23.970, 1003.0, 31.6702
4.113810100, 23.970, 992.0, 31.4960
4.179008740, 23.970, 1021.0, 31.9531
4.244207380, 23.970, 1074.0, 32.7719
4.309406020, 23.970, 1079.0, 32.8481
4.374604660, 23.970, 1071.0, 32.7261
4.439803300, 23.970, 1174.0, 34.2637
4.505001940, 23.970, 1192.0, 34.5254
4.570200580, 23.970, 1171.0, 34.2199
4.635399220, 23.970, 1200.0, 34.6410
4.700597860, 23.970, 1252.0, 35.3836
4.765796500, 23.970, 1271.0, 35.6511
4.830995140, 23.970, 1310.0, 36.1939
4.896193780, 23.970, 1301.0, 36.0694
4.961392420, 23.970, 1365.0, 36.9459
5.026591060, 23.970, 1417.0, 37.6431
5.091789700, 23.970, 1468.0, 38.3145
5.156988340, 23.970, 1472.0, 38.3667
5.222186980, 23.970, 1477.0, 38.4318
5.287385620, 23.970, 1560.0, 39.4968
5.352584260, 23.970, 1554.0, 39.4208
5.417782900, 23.970, 1591.0, 39.8873
5.482981540, 23.970, 1634.0, 40.4228
5.548180180, 23.970, 1608.0, 40.0999
5.613378820, 23.970, 1712.0, 41.3763
5.678577460, 23.970, 1704.0, 41.2795
5.743776100, 23.970, 1692.0, 41.1339
5.808974740, 23.970, 1814.0, 42.5911
5.874173380, 23.970, 1851.0, 43.0232
5.939372020, 23.970, 1880.0, 43.3590
6.004570660, 23.970, 1863.0, 43.1625
6.069769300, 23.970, 1946.0, 44.1135
6.134967940, 23.970, 1972.0, 44.4072
6.200166580, 23.970, 1955.0, 44.2154
6.265365220, 23.970, 1890.0, 43.4741
6.330563860, 23.970, 1963.0, 44.3058
6.395762500, 23.970, 2040.0, 45.1664
6.460961140, 23.970, 2044.0, 45.2106
6.526159780, 23.970, 2124.0, 46.0869
6.591358420, 23.970, 2042.0, 45.1885
6.656557060, 23.970, 2083.0, 45.6399
6.721755700, 23.970, 2122.0, 46.0652
6.786954340, 23.970, 2207.0, 46.9787
6.852152980, 23.970, 2182.0, 46.7119
6.917351620, 23.970, 2232.0, 47.2440
6.982550260, 23.970, 2136.0, 46.2169
7.047748900, 23.970, 2285.0, 47.8017
7.112947540, 23.970, 2330.0, 48.2701
7.178146180, 23.970, 2256.0, 47.4974
7.243344820, 23.970, 2250.0, 47.4342
7.308543460, 23.970, 2279.0, 47.7389
7.373742100, 23.970, 2345.0, 48.4252
7.438940740, 23.970, 2391.0, 48.8979
7.504139380, 23.970, 2319.0, 48.1560
7.569338020, 23.970, 2386.0, 48.8467
7.634536660, 23.970, 2383.0, 48.8160
7.699735300, 23.970, 2346.0, 48.4355
7.764933940, 23.970, 2490.0, 49.8999
7.830132580, 23.970, 2371.0, 48.6929
7.895331220, 23.970, 2394.0, 48.9285
7.960529860, 23.970, 2503.0, 50.0300
8.025728500, 23.970, 2452.0, 49.5177
8.090927140, 23.970, 2482.0, 49.8197
8.156125780, 23.970, 2580.0, 50.7937
8.221324420, 23.970, 2524.0, 50.2394
8.286523060, 23.970, 2511.0, 50.1099
8.351721700, 23.970, 2606.0, 51.0490
8.416920340, 23.970, 2580.0, 50.7937
8.482118980, 23.970, 2517.0, 50.1697
8.547317620, 23.970, 2479.0, 49.7896
8.612516260, 23.970, 2523.0, 50.2295
8.677714900, 23.970, 2484.0, 49.8397
8.742913540, 23.970, 2461.0, 49.6085
8.808112180, 23.970, 2553.0, 50.5272
8.873310820, 23.970, 2540.0, 50.3984
8.938509460, 23.970, 2540.0, 50.3984
9.003708100, 23.970, 2476.0, 49.7594
9.068906740, 23.970, 2461.0, 49.6085
9.134105380, 23.970, 2518.0, 50.1797
9.199304020, 23.970, 2552.0, 50.5173
9.264502660, 23.970, 2533.0, 50.3289
9.329701300, 23.970, 2504.0, 50.0400
9.394899940, 23.970, 2498.0, 49.9800
9.460098580, 23.970, 2482.0, 49.8197
9.525297220, 23.970, 2489.0, 49.8899
9.590495860, 23.970, 2444.0, 49.4368
9.655694500, 23.970, 2445.0, 49.4469
9.720893140, 23.970, 2390.0, 48.8876
9.786091780, 23.970, 2476.0, 49.7594
9.851290420, 23.970, 2416.0, 49.1528
9.916489060, 23.970, 2337.0, 48.3425
9.981687700, 23.970, 2553.0, 50.5272
10.046886340, 23.970, 2382.0, 48.8057
10.112084980, 23.970, 2345.0, 48.4252
10.177283620, 23.970, 2317.0, 48.1352
10.242482260, 23.970, 2372.0, 48.7032
10.307680900, 23.970, 2283.0, 47.7807
10.372879540, 23.970, 2326.0, 48.2286
10.438078180, 23.970, 2320.0, 48.1664
10.503276820, 23.970, 2358.0, 48.5592
10.568475460, 23.970, 2301.0, 47.9687
10.633674100, 23.970, 2278.0, 47.7284
10.698872740, 23.970, 2240.0, 47.3286
10.764071380, 23.970, 2203.0, 46.9361
10.829270020, 23.970, 2229.0, 47.2123
10.894468660, 23.970, 2281.0, 47.7598
10.959667300, 23.970, 2270.0, 47.6445
11.024865940, 23.970, 2219.0, 47.1063
11.090064580, 23.970, 2269.0, 47.6340
11.155263220, 23.970, 2185.0, 46.7440
11.220461860, 23.970, 2193.0, 46.8295
11.285660500, 23.970, 2156.0, 46.4327
11.350859140, 23.970, 2251.0, 47.4447
11.416057780, 23.970, 2141.0, 46.2709
11.481256420, 23.970, 2153.0, 46.4004
11.546455060, 23.970, 2126.0, 46.1086
11.611653700, 23.970, 2266.0, 47.6025
11.676852340, 23.970, 2118.0, 46.0217
11.742050980, 23.970, 2099.0, 45.8148
11.807249620, 23.970, 2098.0, 45.8039
11.872448260, 23.970, 2205.0, 46.9574
11.937646900, 23.970, 1978.0, 44.4747
12.002845540, 23.970, 2071.0, 45.5082
12.068044180, 23.970, 2060.0, 45.3872
12.133242820, 23.970, 2101.0, 45.8367
12.198441460, 23.970, 2065.0, 45.4423
12.263640100, 23.970, 2000.0, 44.7214
12.328838740, 23.970, 2114.0, 45.9783
12.394037380, 23.970, 2035.0, 45.1110
12.459236020, 23.970, 1949.0, 44.1475
12.524434660, 23.970, 1996.0, 44.6766
12.589633300, 23.970, 1961.0, 44.2832
12.654831940, 23.970, 2030.0, 45.0555
12.720030580, 23.970, 1992.0, 44.6318
12.785229220, 23.970, 1969.0, 44.3734
12.850427860, 23.970, 2037.0, 45.1331
12.915626500, 23.970, 1976.0, 44.4522
12.980825140, 23.970, 1933.0, 43.9659
13.046023780, 23.970, 1903.0, 43.6234
13.111222420, 23.970, 1933.0, 43.9659
13.176421060, 23.970, 1878.0, 43.3359
13.241619700, 23.970, 2050.0, 45.2769
13.306818340, 23.970, 1940.0, 44.0454
13.372016980, 23.970, 2022.0, 44.9667
13.437215620, 23.970, 2047.0, 45.2438
13.502414260, 23.970, 1918.0, 43.7950
13.567612900, 23.970, 1924.0, 43.8634
13.632811540, 23.970, 1879.0, 43.3474
13.698010180, 23.970, 1895.0, 43.5316
13.763208820, 23.970, 1941.0, 44.0568
13.828407460, 23.970, 1890.0, 43.4741
13.893606100, 23.970, 1999.0, 44.7102
13.958804740, 23.970, 1949.0, 44.1475
14.024003380, 23.970, 2053.0, 45.3100
14.089202020, 23.970, 1887.0, 43.4396
14.154400660, 23.970, 1921.0, 43.8292
14.219599300, 23.970, 1945.0, 44.1022
14.284797940, 23.970, 2002.0, 44.7437
14.349996580, 23.970, 1929.0, 43.9204
14.415195220, 23.970, 1960.0, 44.2719
14.480393860, 23.970, 1995.0, 44.6654
14.545592500, 23.970, 1980.0, 44.4972
14.610791140, 23.970, 2000.0, 44.7214
14.675989780, 23.970, 2057.0, 45.3542
14.741188420, 23.970, 2118.0, 46.0217
14.806387060, 23.970, 2084.0, 45.6508
14.871585700, 23.970, 2090.0, 45.7165
14.936784340, 23.970, 2072.0, 45.5192
15.001982980, 23.970, 2058.0, 45.3652
15.067181620, 23.970, 2125.0, 46.0977
15.132380260, 23.970, 2106.0, 45.8912
15.197578900, 23.970, 2099.0, 45.8148
15.262777540, 23.970, 2037.0, 45.1331
15.327976180, 23.970, 2247.0, 47.4025
15.393174820, 23.970, 2203.0, 46.9361
15.458373460, 23.970, 2190.0, 46.7974
15.523572100, 23.970, 2259.0, 47.5289
15.588770740, 23.970, 2250.0, 47.4342
15.653969380, 23.970, 2325.0, 48.2183
15.719168020, 23.970, 2230.0, 47.2229
15.784366660, 23.970, 2336.0, 48.3322
15.849565300, 23.970, 2300.0, 47.9583
15.914763940, 23.970, 2281.0, 47.7598
15.979962580, 23.970, 2295.0, 47.9062
16.045161220, 23.970, 2395.0, 48.9387
16.110359860, 23.970, 2404.0, 49.0306
16.175558500, 23.970, 2412.0, 49.1121
16.240757140, 23.970, 2399.0, 48.9796
16.305955780, 23.970, 2417.0, 49.1630
16.371154420, 23.970, 2481.0, 49.8096
16.436353060, 23.970, 2591.0, 50.9019
16.501551700, 23.970, 2602.0, 51.0098
16.566750340, 23.970, 2620.0, 51.1859
16.631948980, 23.970, 2696.0, 51.9230
16.697147620, 23.970, 2708.0, 52.0384
16.762346260, 23.970, 2812.0, 53.0283
16.827544900, 23.970, 2843.0, 53.3198
16.892743540, 23.970, 2849.0, 53.3760
16.957942180, 23.970, 2857.0, 53.4509
17.023140820, 23.970, 2965.0, 54.4518
17.088339460, 23.970, 3039.0, 55.1271
17.153538100, 23.970, 2984.0, 54.6260
17.218736740, 23.970, 3110.0, 55.7674
17.283935380, 23.970, 3131.0, 55.9553
17.349134020, 23.970, 3156.0, 56.1783
17.414332660, 23.970, 3220.0, 56.7450
17.479531300, 23.970, 3305.0, 57.4891
17.544729940, 23.970, 3378.0, 58.1206
17.609928580, 23.970, 3335.0, 57.7495
17.675127220, 23.970, 3469.0, 58.8982
17.740325860, 23.970, 3424.0, 58.5150
17.805524500, 23.970, 3698.0, 60.8112
17.870723140, 23.970, 3643.0, 60.3573
17.935921780, 23.970, 3706.0, 60.8769
18.001120420, 23.970, 3869.0, 62.2013
18.066319060, 23.970, 3953.0, 62.8729
18.131517700, 23.970, 3936.0, 62.7375
18.196716340, 23.970, 3991.0, 63.1744
18.261914980, 23.970, 4099.0, 64.0234
18.327113620, 23.970, 4197.0, 64.7843
18.392312260, 23.970, 4307.0, 65.6277
18.457510900, 23.970, 4349.0, 65.9469
18.522709540, 23.970, 4513.0, 67.1789
18.587908180, 23.970, 4514.0, 67.1863
18.653106820, 23.970, 4411.0, 66.4154
18.718305460, 23.970, 4608.0, 67.8823
18.783504100, 23.970, 4684.0, 68.4398
18.848702740, 23.970, 4832.0, 69.5126
18.913901380, 23.970, 4798.0, 69.2676
18.979100020, 23.970, 5120.0, 71.5542
19.044298660, 23.970, 5140.0, 71.6938
19.109497300, 23.970, 5216.0, 72.2219
19.174695940, 23.970, 5206.0, 72.1526
19.239894580, 23.970, 5397.0, 73.4643
19.305093220, 23.970, 5485.0, 74.0608
19.370291860, 23.970, 5399.0, 73.4779
19.435490500, 23.970, 5676.0, 75.3392
19.500689140, 23.970, 5621.0, 74.9733
19.565887780, 23.970, 5628.0, 75.0200
19.631086420, 23.970, 5754.0, 75.8551
19.696285060, 23.970, 5836.0, 76.3937
19.761483700, 23.970, 5994.0, 77.4209
19.826682340, 23.970, 5765.0, 75.9276
19.891880980, 23.970, 5922.0, 76.9545
19.957079620, 23.970, 6151.0, 78.4283
20.022278260, 23.970, 6004.0, 77.4855
20.087476900, 23.970, 6032.0, 77.6660
20.152675540, 23.970, 6096.0, 78.0769
20.217874180, 23.970, 6126.0, 78.2688
20.283072820, 23.970, 6185.0, 78.6448
20.348271460, 23.970, 6263.0, 79.1391
20.413470100, 23.970, 6251.0, 79.0633
20.478668740, 23.970, 6398.0, 79.9875
20.543867380, 23.970, 6527.0, 80.7899
20.609066020, 23.970, 6834.0, 82.6680
20.674264660, 23.970, 7060.0, 84.0238
20.739463300, 23.970, 7273.0, 85.2819
20.804661940, 23.970, 7704.0, 87.7724
20.869860580, 23.970, 8048.0, 89.7106
20.935059220, 23.970, 9109.0, 95.4411
21.000257860, 23.970, 10237.0, 101.1781
21.065456500, 23.970, 12136.0, 110.1635
21.130655140, 23.970, 14757.0, 121.4784
21.195853780, 23.970, 18314.0, 135.3292
21.261052420, 23.970, 22299.0, 149.3285
21.326251060, 23.970, 26150.0, 161.7096
21.391449700, 23.970, 30630.0, 175.0143
21.456648340, 23.970, 36703.0, 191.5803
21.521846980, 23.970, 44450.0, 210.8317
21.587045620, 23.970, 53471.0, 231.2380
21.652244260, 23.970, 63082.0, 251.1613
21.717442900, 23.970, 71539.0, 267.4678
21.782641540, 23.970, 73544.0, 271.1900
21.847840180, 23.970, 66307.0, 257.5015
21.913038820, 23.970, 49574.0, 222.6522
21.978237460, 23.970, 31424.0, 177.2682
22.043436100, 23.970, 18607.0, 136.4075
22.108634740, 23.970, 12248.0, 110.6707
22.173833380, 23.970, 9116.0, 95.4777
22.239032020, 23.970, 7418.0, 86.1278
22.304230660, 23.970, 6585.0, 81.1480
22.369429300, 23.970, 5994.0, 77.4209
22.434627940, 23.970, 5587.0, 74.7462
22.499826580, 23.970, 5145.0, 71.7287
22.565025220, 23.970, 5037.0, 70.9718
22.630223860, 23.970, 4757.0, 68.9710
22.695422500, 23.970, 4553.0, 67.4759
22.760621140, 23.970, 4552.0, 67.4685
22.825819780, 23.970, 4449.0, 66.7008
22.891018420, 23.970, 4289.0, 65.4905
22.956217060, 23.970, 4282.0, 65.4370
23.021415700, 23.970, 4234.0, 65.0692
23.086614340, 23.970, 4238.0, 65.0999
23.151812980, 23.970, 4377.0, 66.1589
23.217011620, 23.970, 4321.0, 65.7343
23.282210260, 23.970, 4666.0, 68.3081
23.347408900, 23.970, 4818.0, 69.4118
23.412607540, 23.970, 5003.0, 70.7319
23.477806180, 23.970, 5754.0, 75.8551
23.543004820, 23.970, 6291.0, 79.3158
23.608203460, 23.970, 6969.0, 83.4805
23.673402100, 23.970, 7695.0, 87.7211
23.738600740, 23.970, 8419.0, 91.7551
23.803799380, 23.970, 9353.0, 96.7109
23.868998020, 23.970, 10518.0, 102.5573
23.934196660, 23.970, 11876.0, 108.9771
23.999395300, 23.970, 12746.0, 112.8982
24.064593940, 23.970, 13197.0, 114.8782
24.129792580, 23.970, 12968.0, 113.8771
24.194991220, 23.970, 12060.0, 109.8180
24.260189860, 23.970, 10151.0, 100.7522
24.325388500, 23.970, 8087.0, 89.9277
24.390587140, 23.970, 6328.0, 79.5487
24.455785780, 23.970, 4832.0, 69.5126
24.520984420, 23.970, 4004.0, 63.2772
24.586183060, 23.970, 3564.0, 59.6992
24.651381700, 23.970, 3099.0, 55.6687
24.716580340, 23.970, 2950.0, 54.3139
24.781778980, 23.970, 2799.0, 52.9056
24.846977620, 23.970, 2593.0, 50.9215
24.912176260, 23.970, 2516.0, 50.1597
24.977374900, 23.970, 2453.0, 49.5278
25.042573540, 23.970, 2360.0, 48.5798
25.107772180, 23.970, 2296.0, 47.9166
25.172970820, 23.970, 2218.0, 47.0956
25.238169460, 23.970, 2180.0, 46.6905
25.303368100, 23.970, 2086.0, 45.6727
25.368566740, 23.970, 2042.0, 45.1885
25.433765380, 23.970, 2111.0, 45.9456
25.498964020, 23.970, 2105.0, 45.8803
25.564162660, 23.970, 1928.0, 43.9090
25.629361300, 23.970, 1928.0, 43.9090
25.694559940, 23.970, 1926.0, 43.8862
25.759758580, 23.970, 1839.0, 42.8836
25.824957220, 23.970, 1861.0, 43.1393
25.890155860, 23.970, 1903.0, 43.6234
25.955354500, 23.970, 1871.0, 43.2551
26.020553140, 23.970, 2004.0, 44.7661
26.085751780, 23.970, 1814.0, 42.5911
26.150950420, 23.970, 1695.0, 41.1704
26.216149060, 23.970, 1805.0, 42.4853
26.281347700, 23.970, 1795.0, 42.3674
26.346546340, 23.970, 1655.0, 40.6817
26.411744980, 23.970, 1687.0, 41.0731
26.476943620, 23.970, 1704.0, 41.2795
26.542142260, 23.970, 1754.0, 41.8808
26.607340900, 23.970, 1610.0, 40.1248
26.672539540, 23.970, 1721.0, 41.4849
26.737738180, 23.970, 1598.0, 39.9750
26.802936820, 23.970, 1623.0, 40.2865
26.868135460, 23.970, 1617.0, 40.2119
26.933334100, 23.970, 1509.0, 38.8458
26.998532740, 23.970, 1560.0, 39.4968
27.063731380, 23.970, 1535.0, 39.1791
27.128930020, 23.970, 1500.0, 38.7298
27.194128660, 23.970, 1511.0, 38.8716
27.259327300, 23.970, 1536.0, 39.1918
27.324525940, 23.970, 1500.0, 38.7298
27.389724580, 23.970, 1463.0, 38.2492
27.454923220, 23.970, 1467.0, 38.3014
27.520121860, 23.970, 1471.0, 38.3536
27.585320500, 23.970, 1308.0, 36.1663
27.650519140, 23.970, 1416.0, 37.6298
27.715717780, 23.970, 1488.0, 38.5746
27.780916420, 23.970, 1369.0, 37.0000
27.846115060, 23.970, 1314.0, 36.2491
27.911313700, 23.970, 1413.0, 37.5899
27.976512340, 23.970, 1353.0, 36.7831
28.041710980, 23.970, 1334.0, 36.5240
28.106909620, 23.970, 1361.0, 36.8917
28.172108260, 23.970, 1325.0, 36.4005
28.237306900, 23.970, 1362.0, 36.9053
28.302505540, 23.970, 1397.0, 37.3765
28.367704180, 23.970, 1310.0, 36.1939
28.432902820, 23.970, 1324.0, 36.3868
28.498101460, 23.970, 1338.0, 36.5787
28.563300100, 23.970, 1285.0, 35.8469
28.628498740, 23.970, 1308.0, 36.1663
28.693697380, 23.970, 1398.0, 37.3898
28.758896020, 23.970, 1466.0, 38.2884
28.824094660, 23.970, 1511.0, 38.8716
28.889293300, 23.970, 1755.0, 41.8927
28.954491940, 23.970, 2127.0, 46.1194
29.019690580, 23.970, 1884.0, 43.4051
29.084889220, 23.970, 1492.0, 38.6264
29.150087860, 23.970, 1348.0, 36.7151
29.215286500, 23.970, 1327.0, 36.4280
29.280485140, 23.970, 1314.0, 36.2491
29.345683780, 23.970, 1334.0, 36.5240
29.410882420, 23.970, 1345.0, 36.6742
29.476081060, 23.970, 1279.0, 35.7631
29.541279700, 23.970, 1234.0, 35.1283
29.606478340, 23.970, 1429.0, 37.8021
29.671676980, 23.970, 1409.0, 37.5366
29.736875620, 23.970, 1479.0, 38.4578
29.802074260, 23.970, 1591.0, 39.8873
29.867272900, 23.970, 1565.0, 39.5601
29.932471540, 23.970, 1678.0, 40.9634
29.997670180, 23.970, 1671.0, 40.8779
30.062868820, 23.970, 1715.0, 41.4126
30.128067460, 23.970, 1748.0, 41.8091
30.193266100, 23.970, 1803.0, 42.4617
30.258464740, 23.970, 1775.0, 42.1307
30.323663380, 23.970, 1803.0, 42.4617
30.388862020, 23.970, 1719.0, 41.4608
30.454060660, 23.970, 1444.0, 38.0000
30.519259300, 23.970, 1409.0, 37.5366
30.584457940, 23.970, 1381.0, 37.1618
30.649656580, 23.970, 1242.0, 35.2420
30.714855220, 23.970, 1262.0, 35.5246
30.780053860, 23.970, 1160.0, 34.0588
30.845252500, 23.970, 1112.0, 33.3467
30.910451140, 23.970, 1157.0, 34.0147
30.975649780, 23.970, 1143.0, 33.8083
31.040848420, 23.970, 1190.0, 34.4964
31.106047060, 23.970, 1135.0, 33.6898
31.171245700, 23.970, 1139.0, 33.7491
31.236444340, 23.970, 1135.0, 33.6898
31.301642980, 23.970, 1109.0, 33.3017
31.366841620, 23.970, 1074.0, 32.7719
31.432040260, 23.970, 1161.0, 34.0735
31.497238900, 23.970, 1104.0, 33.2265
31.562437540, 23.970, 1077.0, 32.8177
31.627636180, 23.970, 1100.0, 33.1662
31.692834820, 23.970, 1095.0, 33.0908
31.758033460, 23.970, 1042.0, 32.2800
31.823232100, 23.970, 1142.0, 33.7935
31.888430740, 23.970, 1088.0, 32.9848
31.953629380, 23.970, 1031.0, 32.1092
32.018828020, 23.970, 1072.0, 32.7414
32.084026660, 23.970, 1092.0, 33.0454
32.149225300, 23.970, 1066.0, 32.6497
32.214423940, 23.970, 1079.0, 32.8481
32.279622580, 23.970, 1119.0, 33.4515
32.344821220, 23.970, 1064.0, 32.6190
32.410019860, 23.970, 1096.0, 33.1059
32.475218500, 23.970, 1037.0, 32.2025
32.540417140, 23.970, 1089.0, 33.0000
32.605615780, 23.970, 1097.0, 33.1210
32.670814420, 23.970, 1115.0, 33.3916
32.736013060, 23.970, 1034.0, 32.1559
32.801211700, 23.970, 1080.0, 32.8634
32.866410340, 23.970, 1075.0, 32.7872
32.931608980, 23.970, 1039.0, 32.2335
32.996807620, 23.970, 1048.0, 32.3728
33.062006260, 23.970, 1105.0, 33.2415
33.127204900, 23.970, 1100.0, 33.1662
33.192403540, 23.970, 1027.0, 32.0468
33.257602180, 23.970, 1034.0, 32.1559
33.322800820, 23.970, 1127.0, 33.5708
33.387999460, 23.970, 1062.0, 32.5883
33.453198100, 23.970, 1089.0, 33.0000
33.518396740, 23.970, 1079.0, 32.8481
33.583595380, 23.970, 1061.0, 32.5730
33.648794020, 23.970, 1094.0, 33.0757
33.713992660, 23.970, 994.0, 31.5278
33.779191300, 23.970, 1079.0, 32.8481
33.844389940, 23.970, 1112.0, 33.3467
33.909588580, 23.970, 1082.0, 32.8938
33.974787220, 23.970, 1092.0, 33.0454
34.039985860, 23.970, 1065.0, 32.6343
34.105184500, 23.970, 1091.0, 33.0303
34.170383140, 23.970, 1022.0, 31.9687
34.235581780, 23.970, 1118.0, 33.4365
34.300780420, 23.970, 1080.0, 32.8634
34.365979060, 23.970, 1121.0, 33.4813
34.431177700, 23.970, 1084.0, 32.9242
34.496376340, 23.970, 1080.0, 32.8634
34.561574980, 23.970, 1078.0, 32.8329
34.626773620, 23.970, 1097.0, 33.1210
34.691972260, 23.970, 1132.0, 33.6452
34.757170900, 23.970, 1128.0, 33.5857
34.822369540, 23.970, 1184.0, 34.4093
34.887568180, 23.970, 1073.0, 32.7567
34.952766820, 23.970, 1080.0, 32.8634
35.017965460, 23.970, 1180.0, 34.3511
35.083164100, 23.970, 1035.0, 32.1714
35.148362740, 23.970, 1093.0, 33.0606
35.213561380, 23.970, 1151.0, 33.9264
35.278760020, 23.970, 1169.0, 34.1906
35.343958660, 23.970, 1140.0, 33.7639
35.409157300, 23.970, 1131.0, 33.6303
35.474355940, 23.970, 1328.0, 36.4417
35.539554580, 23.970, 1378.0, 37.1214
35.604753220, 23.970, 1379.0, 37.1349
35.669951860, 23.970, 1424.0, 37.7359
35.735150500, 23.970, 1403.0, 37.4566
35.800349140, 23.970, 1567.0, 39.5854
35.865547780, 23.970, 1689.0, 41.0974
35.930746420, 23.970, 2049.0, 45.2659
35.995945060, 23.970, 2243.0, 47.3603
36.061143700, 23.970, 2546.0, 50.4579
36.126342340, 23.970, 2894.0, 53.7959
36.191540980, 23.970, 3372.0, 58.0689
36.256739620, 23.970, 3743.0, 61.1801
36.321938260, 23.970, 3925.0, 62.6498
36.387136900, 23.970, 4303.0, 65.5973
36.452335540, 23.970, 4557.0, 67.5056
36.517534180, 23.970, 4211.0, 64.8922
36.582732820, 23.970, 3799.0, 61.6360
36.647931460, 23.970, 3204.0, 56.6039
36.713130100, 23.970, 2582.0, 50.8134
36.778328740, 23.970, 2079.0, 45.5961
36.843527380, 23.970, 1806.0, 42.4971
36.908726020, 23.970, 1584.0, 39.7995
36.973924660, 23.970, 1472.0, 38.3667
37.039123300, 23.970, 1339.0, 36.5923
37.104321940, 23.970, 1296.0, 36.0000
37.169520580, 23.970, 1261.0, 35.5106
37.234719220, 23.970, 1271.0, 35.6511
37.299917860, 23.970, 1233.0, 35.1141
37.365116500, 23.970, 1245.0, 35.2846
37.430315140, 23.970, 1220.0, 34.9285
37.495513780, 23.970, 1228.0, 35.0428
37.560712420, 23.970, 1197.0, 34.5977
37.625911060, 23.970, 1282.0, 35.8050
37.691109700, 23.970, 1240.0, 35.2136
37.756308340, 23.970, 1145.0, 33.8378
37.821506980, 23.970, 1210.0, 34.7851
37.886705620, 23.970, 1240.0, 35.2136
37.951904260, 23.970, 1231.0, 35.0856
38.017102900, 23.970, 1253.0, 35.3977
38.082301540, 23.970, 1366.0, 36.9594
38.147500180, 23.970, 1290.0, 35.9166
38.212698820, 23.970, 1414.0, 37.6032
38.277897460, 23.970, 1565.0, 39.5601
38.343096100, 23.970, 1510.0, 38.8587
38.408294740, 23.970, 1525.0, 39.0512
38.473493380, 23.970, 1549.0, 39.3573
38.538692020, 23.970, 1613.0, 40.1622
38.603890660, 23.970, 1488.0, 38.5746
38.669089300, 23.970, 1506.0, 38.8072
38.734287940, 23.970, 1425.0, 37.7492
38.799486580, 23.970, 1370.0, 37.0135
38.864685220, 23.970, 1416.0, 37.6298
38.929883860, 23.970, 1463.0, 38.2492
38.995082500, 23.970, 1591.0, 39.8873
39.060281140, 23.970, 1475.0, 38.4057
39.125479780, 23.970, 1493.0, 38.6394
39.190678420, 23.970, 1409.0, 37.5366
39.255877060, 23.970, 1394.0, 37.3363
39.321075700, 23.970, 1548.0, 39.3446
39.386274340, 23.970, 1656.0, 40.6940
39.451472980, 23.970, 1761.0, 41.9643
39.516671620, 23.970, 1863.0, 43.1625
39.581870260, 23.970, 2023.0, 44.9778
39.647068900, 23.970, 2201.0, 46.9148
39.712267540, 23.970, 2437.0, 49.3660
39.777466180, 23.970, 2474.0, 49.7393
39.842664820, 23.970, 2617.0, 51.1566
39.907863460, 23.970, 2674.0, 51.7107
39.973062100, 23.970, 2517.0, 50.1697
40.038260740, 23.970, 2384.0, 48.8262
40.103459380, 23.970, 2321.0, 48.1768
40.168658020, 23.970, 2181.0, 46.7012
40.233856660, 23.970, 2100.0, 45.8258
40.299055300, 23.970, 1961.0, 44.2832
40.364253940, 23.970, 1914.0, 43.7493
40.429452580, 23.970, 1927.0, 43.8976
40.494651220, 23.970, 1948.0, 44.1362
40.559849860, 23.970, 1980.0, 44.4972
40.625048500, 23.970, 1993.0, 44.6430
40.690247140, 23.970, 2092.0, 45.7384
40.755445780, 23.970, 2112.0, 45.9565
40.820644420, 23.970, 2020.0, 44.9444
40.885843060, 23.970, 2189.0, 46.7868
40.951041700, 23.970, 2033.0, 45.0888
41.016240340, 23.970, 2042.0, 45.1885
41.081438980, 23.970, 1824.0, 42.7083
41.146637620, 23.970, 1811.0, 42.5558
41.211836260, 23.970, 1746.0, 41.7852
41.277034900, 23.970, 1707.0, 41.3159
41.342233540, 23.970, 1730.0, 41.5933
41.407432180, 23.970, 1816.0, 42.6146
41.472630820, 23.970, 1813.0, 42.5793
41.537829460, 23.970, 1939.0, 44.0341
41.603028100, 23.970, 1961.0, 44.2832
41.668226740, 23.970, 2115.0, 45.9891
41.733425380, 23.970, 2102.0, 45.8476
41.798624020, 23.970, 2161.0, 46.4866
41.863822660, 23.970, 2063.0, 45.4203
41.929021300, 23.970, 2065.0, 45.4423
41.994219940, 23.970, 1909.0, 43.6921
42.059418580, 23.970, 1766.0, 42.0238
42.124617220, 23.970, 1719.0, 41.4608
42.189815860, 23.970, 1565.0, 39.5601
42.255014500, 23.970, 1483.0, 38.5097
42.320213140, 23.970, 1467.0, 38.3014
42.385411780, 23.970, 1394.0, 37.3363
42.450610420, 23.970, 1532.0, 39.1408
42.515809060, 23.970, 1501.0, 38.7427
42.581007700, 23.970, 1591.0, 39.8873
42.646206340, 23.970, 1761.0, 41.9643
42.711404980, 23.970, 1971.0, 44.3959
42.776603620, 23.970, 2061.0, 45.3982
42.841802260, 23.970, 2134.0, 46.1952
42.907000900, 23.970, 2055.0, 45.3321
42.972199540, 23.970, 2062.0, 45.4093
43.037398180, 23.970, 2135.0, 46.2061
43.102596820, 23.970, 2217.0, 47.0850
43.167795460, 23.970, 2186.0, 46.7547
43.232994100, 23.970, 2118.0, 46.0217
43.298192740, 23.970, 2120.0, 46.0435
43.363391380, 23.970, 1977.0, 44.4635
43.428590020, 23.970, 1832.0, 42.8019
43.493788660, 23.970, 1823.0, 42.6966
43.558987300, 23.970, 1670.0, 40.8656
43.624185940, 23.970, 1679.0, 40.9756
43.689384580, 23.970, 1601.0, 40.0125
43.754583220, 23.970, 1676.0, 40.9390
43.819781860, 23.970, 1677.0, 40.9512
43.884980500, 23.970, 1652.0, 40.6448
43.950179140, 23.970, 1670.0, 40.8656
44.015377780, 23.970, 1775.0, 42.1307
44.080576420, 23.970, 1676.0, 40.9390
44.145775060, 23.970, 1706.0, 41.3038
44.210973700, 23.970, 1699.0, 41.2189
44.276172340, 23.970, 1534.0, 39.1663
44.341370980, 23.970, 1480.0, 38.4708
44.406569620, 23.970, 1361.0, 36.8917
44.471768260, 23.970, 1257.0, 35.4542
44.536966900, 23.970, 1255.0, 35.4260
44.602165540, 23.970, 1189.0, 34.4819
44.667364180, 23.970, 1172.0, 34.2345
44.732562820, 23.970, 1171.0, 34.2199
44.797761460, 23.970, 1144.0, 33.8231
44.862960100, 23.970, 1108.0, 33.2866
44.928158740, 23.970, 1082.0, 32.8938
44.993357380, 23.970, 1103.0, 33.2114
45.058556020, 23.970, 1032.0, 32.1248
45.123754660, 23.970, 1065.0, 32.6343
45.188953300, 23.970, 1076.0, 32.8024
45.254151940, 23.970, 1074.0, 32.7719
45.319350580, 23.970, 1131.0, 33.6303
45.384549220, 23.970, 1127.0, 33.5708
45.449747860, 23.970, 1038.0, 32.2180
45.514946500, 23.970, 1054.0, 32.4654
45.580145140, 23.970, 1070.0, 32.7109
45.645343780, 23.970, 1088.0, 32.9848
45.710542420, 23.970, 1045.0, 32.3265
45.775741060, 23.970, 1106.0, 33.2566
45.840939700, 23.970, 1019.0, 31.9218
45.906138340, 23.970, 1022.0, 31.9687
45.971336980, 23.970, 1040.0, 32.2490
46.036535620, 23.970, 1027.0, 32.0468
46.101734260, 23.970, 1013.0, 31.8277
46.166932900, 23.970, 1097.0, 33.1210
46.232131540, 23.970, 1038.0, 32.2180
46.297330180, 23.970, 1142.0, 33.7935
46.362528820, 23.970, 1104.0, 33.2265
46.427727460, 23.970, 1140.0, 33.7639
46.492926100, 23.970, 1248.0, 35.3270
46.558124740, 23.970, 1253.0, 35.3977
46.623323380, 23.970, 1284.0, 35.8329
46.688522020, 23.970, 1433.0, 37.8550
46.753720660, 23.970, 1508.0, 38.8330
46.818919300, 23.970, 1539.0, 39.2301
46.884117940, 23.970, 1576.0, 39.6989
46.949316580, 23.970, 1678.0, 40.9634
47.014515220, 23.970, 1849.0, 43.0000
47.079713860, 23.970, 2022.0, 44.9667
47.144912500, 23.970, 2015.0, 44.8888
47.210111140, 23.970, 1806.0, 42.4971
47.275309780, 23.970, 1560.0, 39.4968
47.340508420, 23.970, 1397.0, 37.3765
47.405707060, 23.970, 1290.0, 35.9166
47.470905700, 23.970, 1250.0, 35.3553
47.536104340, 23.970, 1191.0, 34.5109
47.601302980, 23.970, 1088.0, 32.9848
47.666501620, 23.970, 1115.0, 33.3916
47.731700260, 23.970, 1063.0, 32.6037
47.796898900, 23.970, 1078.0, 32.8329
47.862097540, 23.970, 1075.0, 32.7872
47.927296180, 23.970, 1102.0, 33.1964
47.992494820, 23.970, 1221.0, 34.9428
48.057693460, 23.970, 1309.0, 36.1801
48.122892100, 23.970, 1376.0, 37.0945
48.188090740, 23.970, 1273.0, 35.6791
48.253289380, 23.970, 1150.0, 33.9116
48.318488020, 23.970, 1063.0, 32.6037
48.383686660, 23.970, 1033.0, 32.1403
48.448885300, 23.970, 1000.0, 31.6228
48.514083940, 23.970, 980.0, 31.3050
48.579282580, 23.970, 951.0, 30.8383
48.644481220, 23.970, 973.0, 31.1929
48.709679860, 23.970, 1022.0, 31.9687
48.774878500, 23.970, 1074.0, 32.7719
48.840077140, 23.970, 1002.0, 31.6544
48.905275780, 23.970, 1026.0, 32.0312
48.970474420, 23.970, 1100.0, 33.1662
49.035673060, 23.970, 1063.0, 32.6037
49.100871700, 23.970, 1070.0, 32.7109
49.166070340, 23.970, 1025.0, 32.0156
49.231268980, 23.970, 1067.0, 32.6650
49.296467620, 23.970, 1066.0, 32.6497
49.361666260, 23.970, 1055.0, 32.4808
49.426864900, 23.970, 1050.0, 32.4037
49.492063540, 23.970, 1022.0, 31.9687
49.557262180, 23.970, 961.0, 31.0000
49.622460820, 23.970, 895.0, 29.9166
49.687659460, 23.970, 935.0, 30.5778
49.752858100, 23.970, 904.0, 30.0666
49.818056740, 23.970, 917.0, 30.2820
49.883255380, 23.970, 860.0, 29.3258
49.948454020, 23.970, 890.0, 29.8329
50.013652660, 23.970, 921.0, 30.3480
50.078851300, 23.970, 830.0, 28.8097
50.144049940, 23.970, 916.0, 30.2655
50.209248580, 23.970, 844.0, 29.0517
50.274447220, 23.970, 944.0, 30.7246
50.339645860, 23.970, 873.0, 29.5466
50.404844500, 23.970, 908.0, 30.1330
50.470043140, 23.970, 915.0, 30.2490
50.535241780, 23.970, 923.0, 30.3809
50.600440420, 23.970, 869.0, 29.4788
50.665639060, 23.970, 864.0, 29.3939
50.730837700, 23.970, 861.0, 29.3428
50.796036340, 23.970, 890.0, 29.8329
50.861234980, 23.970, 898.0, 29.9666
50.926433620, 23.970, 858.0, 29.2916
50.991632260, 23.970, 910.0, 30.1662
51.056830900, 23.970, 910.0, 30.1662
51.122029540, 23.970, 878.0, 29.6311
51.187228180, 23.970, 900.0, 30.0000
51.252426820, 23.970, 892.0, 29.8664
51.317625460, 23.970, 910.0, 30.1662
51.382824100, 23.970, 892.0, 29.8664
51.448022740, 23.970, 971.0, 31.1609
51.513221380, 23.970, 903.0, 30.0500
51.578420020, 23.970, 960.0, 30.9839
51.643618660, 23.970, 987.0, 31.4166
51.708817300, 23.970, 945.0, 30.7409
51.774015940, 23.970, 955.0, 30.9031
51.839214580, 23.970, 991.0, 31.4802
51.904413220, 23.970, 1011.0, 31.7962
51.969611860, 23.970, 1003.0, 31.6702
52.034810500, 23.970, 1006.0, 31.7175
52.100009140, 23.970, 1054.0, 32.4654
52.165207780, 23.970, 1063.0, 32.6037
52.230406420, 23.970, 1151.0, 33.9264
52.295605060, 23.970, 1136.0, 33.7046
52.360803700, 23.970, 1158.0, 34.0294
52.426002340, 23.970, 1226.0, 35.0143
52.491200980, 23.970, 1193.0, 34.5398
52.556399620, 23.970, 1269.0, 35.6230
52.621598260, 23.970, 1286.0, 35.8608
52.686796900, 23.970, 1373.0, 37.0540
52.751995540, 23.970, 1507.0, 38.8201
52.817194180, 23.970, 1497.0, 38.6911
52.882392820, 23.970, 1548.0, 39.3446
52.947591460, 23.970, 1599.0, 39.9875
53.012790100, 23.970, 1726.0, 41.5452
53.077988740, 23.970, 1809.0, 42.5323
53.143187380, 23.970, 1724.0, 41.5211
53.208386020, 23.970, 1628.0, 40.3485
53.273584660, 23.970, 1675.0, 40.9268
53.338783300, 23.970, 1653.0, 40.6571
53.403981940, 23.970, 1549.0, 39.3573
53.469180580, 23.970, 1426.0, 37.7624
53.534379220, 23.970, 1279.0, 35.7631
53.599577860, 23.970, 1171.0, 34.2199
53.664776500, 23.970, 1108.0, 33.2866
53.729975140, 23.970, 1036.0, 32.1870
53.795173780, 23.970, 952.0, 30.8545
53.860372420, 23.970, 968.0, 31.1127
53.925571060, 23.970, 943.0, 30.7083
53.990769700, 23.970, 931.0, 30.5123
54.055968340, 23.970, 925.0, 30.4138
54.121166980, 23.970, 879.0, 29.6479
54.186365620, 23.970, 941.0, 30.6757
54.251564260, 23.970, 921.0, 30.3480
54.316762900, 23.970, 905.0, 30.0832
54.381961540, 23.970, 946.0, 30.7571
54.447160180, 23.970, 1008.0, 31.7490
54.512358820, 23.970, 1033.0, 32.1403
54.577557460, 23.970, 1033.0, 32.1403
54.642756100, 23.970, 1125.0, 33.5410
54.707954740, 23.970, 1135.0, 33.6898
54.773153380, 23.970, 1175.0, 34.2783
54.838352020, 23.970, 1192.0, 34.5254
54.903550660, 23.970, 1243.0, 35.2562
54.968749300, 23.970, 1195.0, 34.5688
55.033947940, 23.970, 1244.0, 35.2704
55.099146580, 23.970, 1301.0, 36.0694
55.164345220, 23.970, 1200.0, 34.6410
55.229543860, 23.970, 1160.0, 34.0588
55.294742500, 23.970, 1157.0, 34.0147
55.359941140, 23.970, 985.0, 31.3847
55.425139780, 23.970, 1030.0, 32.0936
55.490338420, 23.970, 953.0, 30.8707
55.555537060, 23.970, 918.0, 30.2985
55.620735700, 23.970, 883.0, 29.7153
55.685934340, 23.970, 868.0, 29.4618
55.751132980, 23.970, 926.0, 30.4302
55.816331620, 23.970, 889.0, 29.8161
55.881530260, 23.970, 813.0, 28.5132
55.946728900, 23.970, 793.0, 28.1603
56.011927540, 23.970, 829.0, 28.7924
56.077126180, 23.970, 830.0, 28.8097
56.142324820, 23.970, 876.0, 29.5973
56.207523460, 23.970, 840.0, 28.9828
56.272722100, 23.970, 874.0, 29.5635
56.337920740, 23.970, 829.0, 28.7924
56.403119380, 23.970, 798.0, 28.2489
56.468318020, 23.970, 866.0, 29.4279
56.533516660, 23.970, 835.0, 28.8964
56.598715300, 23.970, 857.0, 29.2746
56.663913940, 23.970, 917.0, 30.2820
56.729112580, 23.970, 912.0, 30.1993
56.794311220, 23.970, 906.0, 30.0998
56.859509860, 23.970, 931.0, 30.5123
56.924708500, 23.970, 1035.0, 32.1714
56.989907140, 23.970, 1117.0, 33.4215
57.055105780, 23.970, 1029.0, 32.0780
57.120304420, 23.970, 1116.0, 33.4066
57.185503060, 23.970, 1074.0, 32.7719
57.250701700, 23.970, 1088.0, 32.9848
57.315900340, 23.970, 1104.0, 33.2265
57.381098980, 23.970, 1111.0, 33.3317
57.446297620, 23.970, 1021.0, 31.9531
57.511496260, 23.970, 1098.0, 33.1361
57.576694900, 23.970, 1021.0, 31.9531
57.641893540, 23.970, 1078.0, 32.8329
57.707092180, 23.970, 1025.0, 32.0156
57.772290820, 23.970, 987.0, 31.4166
57.837489460, 23.970, 994.0, 31.5278
57.902688100, 23.970, 912.0, 30.1993
57.967886740, 23.970, 831.0, 28.8271
58.033085380, 23.970, 898.0, 29.9666
58.098284020, 23.970, 799.0, 28.2666
58.163482660, 23.970, 792.0, 28.1425
58.228681300, 23.970, 825.0, 28.7228
58.293879940, 23.970, 771.0, 27.7669
58.359078580, 23.970, 763.0, 27.6225
58.424277220, 23.970, 743.0, 27.2580
58.489475860, 23.970, 738.0, 27.1662
58.554674500, 23.970, 749.0, 27.3679
58.619873140, 23.970, 722.0, 26.8701
58.685071780, 23.970, 766.0, 27.6767
58.750270420, 23.970, 757.0, 27.5136
58.815469060, 23.970, 731.0, 27.0370
58.880667700, 23.970, 756.0, 27.4955
58.945866340, 23.970, 713.0, 26.7021
59.011064980, 23.970, 719.0, 26.8142
59.076263620, 23.970, 653.0, 25.5539
59.141462260, 23.970, 757.0, 27.5136
59.206660900, 23.970, 684.0, 26.1534
59.271859540, 23.970, 750.0, 27.3861
59.337058180, 23.970, 708.0, 26.6083
59.402256820, 23.970, 651.0, 25.5147
59.467455460, 23.970, 699.0, 26.4386
59.532654100, 23.970, 718.0, 26.7955
59.597852740, 23.970, 712.0, 26.6833
59.663051380, 23.970, 737.0, 27.1477
59.728250020, 23.970, 735.0, 27.1109
59.793448660, 23.970, 729.0, 27.0000
59.858647300, 23.970, 764.0, 27.6405
59.923845940, 23.970, 767.0, 27.6948
59.989044580, 23.970, 675.0, 25.9808
60.054243220, 23.970, 716.0, 26.7582
60.119441860, 23.970, 736.0, 27.1293
60.184640500, 23.970, 720.0, 26.8328
60.249839140, 23.970, 821.0, 28.6531
60.315037780, 23.970, 819.0, 28.6182
60.380236420, 23.970, 748.0, 27.3496
60.445435060, 23.970, 805.0, 28.3725
60.510633700, 23.970, 754.0, 27.4591
60.575832340, 23.970, 776.0, 27.8568
60.641030980, 23.970, 735.0, 27.1109
60.706229620, 23.970, 752.0, 27.4226
60.771428260, 23.970, 784.0, 28.0000
60.836626900, 23.970, 773.0, 27.8029
60.901825540, 23.970, 778.0, 27.8927
60.967024180, 23.970, 780.0, 27.9285
61.032222820, 23.970, 812.0, 28.4956
61.097421460, 23.970, 837.0, 28.9310
61.162620100, 23.970, 797.0, 28.2312
61.227818740, 23.970, 775.0, 27.8388
61.293017380, 23.970, 787.0, 28.0535
61.358216020, 23.970, 787.0, 28.0535
61.423414660, 23.970, 868.0, 29.4618
61.488613300, 23.970, 839.0, 28.9655
61.553811940, 23.970, 866.0, 29.4279
61.619010580, 23.970, 862.0, 29.3598
61.684209220, 23.970, 893.0, 29.8831
61.749407860, 23.970, 854.0, 29.2233
61.814606500, 23.970, 911.0, 30.1828
61.879805140, 23.970, 814.0, 28.5307
61.945003780, 23.970, 830.0, 28.8097
62.010202420, 23.970, 876.0, 29.5973
62.075401060, 23.970, 760.0, 27.5681
62.140599700, 23.970, 791.0, 28.1247
62.205798340, 23.970, 771.0, 27.7669
62.270996980, 23.970, 766.0, 27.6767
62.336195620, 23.970, 753.0, 27.4408
62.401394260, 23.970, 752.0, 27.4226
62.466592900, 23.970, 722.0, 26.8701
62.531791540, 23.970, 746.0, 27.3130
62.596990180, 23.970, 763.0, 27.6225
62.662188820, 23.970, 783.0, 27.9821
62.727387460, 23.970, 679.0, 26.0576
62.792586100, 23.970, 731.0, 27.0370
62.857784740, 23.970, 708.0, 26.6083
62.922983380, 23.970, 686.0, 26.1916
62.988182020, 23.970, 683.0, 26.1343
63.053380660, 23.970, 646.0, 25.4165
63.118579300, 23.970, 661.0, 25.7099
63.183777940, 23.970, 618.0, 24.8596
63.248976580, 23.970, 656.0, 25.6125
63.314175220, 23.970, 723.0, 26.8887
63.379373860, 23.970, 706.0, 26.5707
63.444572500, 23.970, 675.0, 25.9808
63.509771140, 23.970, 644.0, 25.3772
63.574969780, 23.970, 711.0, 26.6646
63.640168420, 23.970, 630.0, 25.0998
63.705367060, 23.970, 627.0, 25.0400
63.770565700, 23.970, 719.0, 26.8142
63.835764340, 23.970, 661.0, 25.7099
63.900962980, 23.970, 700.0, 26.4575
63.966161620, 23.970, 704.0, 26.5330
64.031360260, 23.970, 698.0, 26.4197
64.096558900, 23.970, 743.0, 27.2580
64.161757540, 23.970, 739.0, 27.1846
64.226956180, 23.970, 818.0, 28.6007
64.292154820, 23.970, 803.0, 28.3373
64.357353460, 23.970, 813.0, 28.5132
64.422552100, 23.970, 743.0, 27.2580
64.487750740, 23.970, 811.0, 28.4781
64.552949380, 23.970, 786.0, 28.0357
64.618148020, 23.970, 828.0, 28.7750
64.683346660, 23.970, 742.0, 27.2397
64.748545300, 23.970, 807.0, 28.4077
64.813743940, 23.970, 750.0, 27.3861
64.878942580, 23.970, 774.0, 27.8209
64.944141220, 23.970, 713.0, 26.7021
65.009339860, 23.970, 715.0, 26.7395
65.074538500, 23.970, 736.0, 27.1293
65.139737140, 23.970, 823.0, 28.6880
65.204935780, 23.970, 808.0, 28.4253
65.270134420, 23.970, 781.0, 27.9464
65.335333060, 23.970, 755.0, 27.4773
65.400531700, 23.970, 719.0, 26.8142
65.465730340, 23.970, 674.0, 25.9615
65.530928980, 23.970, 719.0, 26.8142
65.596127620, 23.970, 633.0, 25.1595
65.661326260, 23.970, 651.0, 25.5147
65.726524900, 23.970, 618.0, 24.8596
65.791723540, 23.970, 628.0, 25.0599
65.856922180, 23.970, 676.0, 26.0000
65.922120820, 23.970, 634.0, 25.1794
65.987319460, 23.970, 632.0, 25.1396
66.052518100, 23.970, 642.0, 25.3377
66.117716740, 23.970, 613.0, 24.7588
66.182915380, 23.970, 655.0, 25.5930
66.248114020, 23.970, 602.0, 24.5357
66.313312660, 23.970, 632.0, 25.1396
66.378511300, 23.970, 615.0, 24.7992
66.443709940, 23.970, 609.0, 24.6779
66.508908580, 23.970, 649.0, 25.4755
66.574107220, 23.970, 675.0, 25.9808
66.639305860, 23.970, 655.0, 25.5930
66.704504500, 23.970, 660.0, 25.6905
66.769703140, 23.970, 676.0, 26.0000
66.834901780, 23.970, 590.0, 24.2899
66.900100420, 23.970, 620.0, 24.8998
66.965299060, 23.970, 626.0, 25.0200
67.030497700, 23.970, 627.0, 25.0400
67.095696340, 23.970, 679.0, 26.0576
67.160894980, 23.970, 672.0, 25.9230
67.226093620, 23.970, 654.0, 25.5734
67.291292260, 23.970, 707.0, 26.5895
67.356490900, 23.970, 679.0, 26.0576
67.421689540, 23.970, 660.0, 25.6905
67.486888180, 23.970, 726.0, 26.9444
67.552086820, 23.970, 735.0, 27.1109
67.617285460, 23.970, 725.0, 26.9258
67.682484100, 23.970, 787.0, 28.0535
67.747682740, 23.970, 773.0, 27.8029
67.812881380, 23.970, 762.0, 27.6043
67.878080020, 23.970, 771.0, 27.7669
67.943278660, 23.970, 716.0, 26.7582
68.008477300, 23.970, 707.0, 26.5895
68.073675940, 23.970, 696.0, 26.3818
68.138874580, 23.970, 674.0, 25.9615
68.204073220, 23.970, 694.0, 26.3439
68.269271860, 23.970, 674.0, 25.9615
68.334470500, 23.970, 646.0, 25.4165
68.399669140, 23.970, 641.0, 25.3180
68.464867780, 23.970, 647.0, 25.4362
68.530066420, 23.970, 691.0, 26.2869
68.595265060, 23.970, 603.0, 24.5561
68.660463700, 23.970, 636.0, 25.2190
68.725662340, 23.970, 591.0, 24.3105
68.790860980, 23.970, 620.0, 24.8998
68.856059620, 23.970, 668.0, 25.8457
68.921258260, 23.970, 622.0, 24.9399
68.986456900, 23.970, 680.0, 26.0768
69.051655540, 23.970, 662.0, 25.7294
69.116854180, 23.970, 608.0, 24.6577
69.182052820, 23.970, 577.0, 24.0208
69.247251460, 23.970, 606.0, 24.6171
69.312450100, 23.970, 648.0, 25.4558
69.377648740, 23.970, 622.0, 24.9399
69.442847380, 23.970, 582.0, 24.1247
69.508046020, 23.970, 540.0, 23.2379
69.573244660, 23.970, 626.0, 25.0200
69.638443300, 23.970, 628.0, 25.0599
69.703641940, 23.970, 643.0, 25.3574
69.768840580, 23.970, 600.0, 24.4949
69.834039220, 23.970, 618.0, 24.8596
69.899237860, 23.970, 621.0, 24.9199
69.964436500, 23.970, 620.0, 24.8998
70.029635140, 23.970, 602.0, 24.5357
70.094833780, 23.970, 603.0, 24.5561
70.160032420, 23.970, 618.0, 24.8596
70.225231060, 23.970, 591.0, 24.3105
70.290429700, 23.970, 565.0, 23.7697
70.355628340, 23.970, 567.0, 23.8118
70.420826980, 23.970, 600.0, 24.4949
70.486025620, 23.970, 557.0, 23.6008
70.551224260, 23.970, 539.0, 23.2164
70.616422900, 23.970, 591.0, 24.3105
70.681621540, 23.970, 583.0, 24.1454
70.746820180, 23.970, 600.0, 24.4949
70.812018820, 23.970, 564.0, 23.7487
70.877217460, 23.970, 594.0, 24.3721
70.942416100, 23.970, 551.0, 23.4734
71.007614740, 23.970, 494.0, 22.2261
71.072813380, 23.970, 613.0, 24.7588
71.138012020, 23.970, 603.0, 24.5561
71.203210660, 23.970, 597.0, 24.4336
71.268409300, 23.970, 595.0, 24.3926
71.333607940, 23.970, 621.0, 24.9199
71.398806580, 23.970, 566.0, 23.7908
71.464005220, 23.970, 585.0, 24.1868
71.529203860, 23.970, 599.0, 24.4745
71.594402500, 23.970, 549.0, 23.4307
71.659601140, 23.970, 608.0, 24.6577
71.724799780, 23.970, 577.0, 24.0208
71.789998420, 23.970, 592.0, 24.3311
71.855197060, 23.970, 586.0, 24.2074
71.920395700, 23.970, 576.0, 24.0000
71.985594340, 23.970, 618.0, 24.8596
72.050792980, 23.970, 560.0, 23.6643
72.115991620, 23.970, 583.0, 24.1454
72.181190260, 23.970, 613.0, 24.7588
72.246388900, 23.970, 646.0, 25.4165
72.311587540, 23.970, 616.0, 24.8193
72.376786180, 23.970, 659.0, 25.6710
72.441984820, 23.970, 671.0, 25.9037
72.507183460, 23.970, 710.0, 26.6458
72.572382100, 23.970, 708.0, 26.6083
72.637580740, 23.970, 737.0, 27.1477
72.702779380, 23.970, 661.0, 25.7099
72.767978020, 23.970, 696.0, 26.3818
72.833176660, 23.970, 713.0, 26.7021
72.898375300, 23.970, 694.0, 26.3439
72.963573940, 23.970, 703.0, 26.5141
73.028772580, 23.970, 728.0, 26.9815
73.093971220, 23.970, 738.0, 27.1662
73.159169860, 23.970, 701.0, 26.4764
73.224368500, 23.970, 643.0, 25.3574
73.289567140, 23.970, 700.0, 26.4575
73.354765780, 23.970, 703.0, 26.5141
73.419964420, 23.970, 666.0, 25.8070
73.485163060, 23.970, 668.0, 25.8457
73.550361700, 23.970, 688.0, 26.2298
73.615560340, 23.970, 667.0, 25.8263
73.680758980, 23.970, 636.0, 25.2190
73.745957620, 23.970, 690.0, 26.2679
73.811156260, 23.970, 690.0, 26.2679
73.876354900, 23.970, 671.0, 25.9037
73.941553540, 23.970, 621.0, 24.9199
74.006752180, 23.970, 652.0, 25.5343
74.071950820, 23.970, 665.0, 25.7876
74.137149460, 23.970, 720.0, 26.8328
74.202348100, 23.970, 725.0, 26.9258
74.267546740, 23.970, 705.0, 26.5518
74.332745380, 23.970, 776.0, 27.8568
74.397944020, 23.970, 750.0, 27.3861
74.463142660, 23.970, 783.0, 27.9821
74.528341300, 23.970, 807.0, 28.4077
74.593539940, 23.970, 767.0, 27.6948
74.658738580, 23.970, 795.0, 28.1957
74.723937220, 23.970, 750.0, 27.3861
74.789135860, 23.970, 724.0, 26.9072
74.854334500, 23.970, 745.0, 27.2947
74.919533140, 23.970, 660.0, 25.6905
74.984731780, 23.970, 655.0, 25.5930
75.049930420, 23.970, 677.0, 26.0192
75.115129060, 23.970, 574.0, 23.9583
75.180327700, 23.970, 632.0, 25.1396
75.245526340, 23.970, 631.0, 25.1197
75.310724980, 23.970, 577.0, 24.0208
75.375923620, 23.970, 609.0, 24.6779
75.441122260, 23.970, 628.0, 25.0599
75.506320900, 23.970, 588.0, 24.2487
75.571519540, 23.970, 579.0, 24.0624
75.636718180, 23.970, 597.0, 24.4336
75.701916820, 23.970, 633.0, 25.1595
75.767115460, 23.970, 629.0, 25.0799
75.832314100, 23.970, 648.0, 25.4558
75.897512740, 23.970, 634.0, 25.1794
75.962711380, 23.970, 629.0, 25.0799
76.027910020, 23.970, 693.0, 26.3249
76.093108660, 23.970, 619.0, 24.8797
76.158307300, 23.970, 667.0, 25.8263
76.223505940, 23.970, 678.0, 26.0384
76.288704580, 23.970, 630.0, 25.0998
76.353903220, 23.970, 685.0, 26.1725
76.419101860, 23.970, 642.0, 25.3377
76.484300500, 23.970, 642.0, 25.3377
76.549499140, 23.970, 641.0, 25.3180
76.614697780, 23.970, 694.0, 26.3439
76.679896420, 23.970, 710.0, 26.6458
76.745095060, 23.970, 683.0, 26.1343
76.810293700, 23.970, 721.0, 26.8514
76.875492340, 23.970, 716.0, 26.7582
76.940690980, 23.970, 706.0, 26.5707
77.005889620, 23.970, 710.0, 26.6458
77.071088260, 23.970, 719.0, 26.8142
77.136286900, 23.970, 669.0, 25.8650
77.201485540, 23.970, 666.0, 25.8070
77.266684180, 23.970, 690.0, 26.2679
77.331882820, 23.970, 669.0, 25.8650
77.397081460, 23.970, 676.0, 26.0000
77.462280100, 23.970, 634.0, 25.1794
77.527478740, 23.970, 629.0, 25.0799
77.592677380, 23.970, 651.0, 25.5147
77.657876020, 23.970, 646.0, 25.4165
77.723074660, 23.970, 628.0, 25.0599
77.788273300, 23.970, 571.0, 23.8956
77.853471940, 23.970, 644.0, 25.3772
77.918670580, 23.970, 685.0, 26.1725
77.983869220, 23.970, 681.0, 26.0960
78.049067860, 23.970, 654.0, 25.5734
78.114266500, 23.970, 670.0, 25.8844
78.179465140, 23.970, 699.0, 26.4386
78.244663780, 23.970, 675.0, 25.9808
78.309862420, 23.970, 741.0, 27.2213
78.375061060, 23.970, 738.0, 27.1662
78.440259700, 23.970, 719.0, 26.8142
78.505458340, 23.970, 767.0, 27.6948
78.570656980, 23.970, 799.0, 28.2666
78.635855620, 23.970, 813.0, 28.5132
78.701054260, 23.970, 761.0, 27.5862
78.766252900, 23.970, 743.0, 27.2580
78.831451540, 23.970, 765.0, 27.6586
78.896650180, 23.970, 738.0, 27.1662
78.961848820, 23.970, 748.0, 27.3496
79.027047460, 23.970, 713.0, 26.7021
79.092246100, 23.970, 704.0, 26.5330
79.157444740, 23.970, 720.0, 26.8328
79.222643380, 23.970, 690.0, 26.2679
79.287842020, 23.970, 696.0, 26.3818
79.353040660, 23.970, 712.0, 26.6833
79.418239300, 23.970, 694.0, 26.3439
79.483437940, 23.970, 672.0, 25.9230
79.548636580, 23.970, 629.0, 25.0799
79.613835220, 23.970, 651.0, 25.5147
79.679033860, 23.970, 648.0, 25.4558
79.744232500, 23.970, 610.0, 24.6982
79.809431140, 23.970, 622.0, 24.9399
79.874629780, 23.970, 616.0, 24.8193
79.939828420, 23.970, 602.0, 24.5357
79.994160620, 23.970, 563.0, 23.7276