File: data/DSC/HDPE_5 (cal).csv
[Measurement conditions]
Sample identification,HDPE_5 (cal)
Comment,
Anode material,Cu
K-Alpha1 wavelength,1.5405980
K-Alpha2 wavelength,1.5444260
Ratio K-Alpha2/K-Alpha1,0.500
Divergence slit,Fixed,0.38mm
Monochromator used,NO
Generator voltage, 40
Tube current, 15
File date and time,02/Apr/2025 17:25
Unit cell,
h k l, 0 0 0
Scan axis,Gonio
Scan range,3.000000000,79.999593840
Scan step size,0.0108664
No. of points, 7086
Scan type,CONTINUOUS
Time per step,23.970
[Scan points]
Angle, TimePerStep, Intensity, ESD
3.005433220, 23.970, 869.0, 29.4788
3.070631860, 23.970, 837.0, 28.9310
3.135830500, 23.970, 790.0, 28.1069
3.201029140, 23.970, 757.0, 27.5136
3.266227780, 23.970, 763.0, 27.6225
3.331426420, 23.970, 657.0, 25.6320
3.396625060, 23.970, 626.0, 25.0200
3.461823700, 23.970, 643.0, 25.3574
3.527022340, 23.970, 616.0, 24.8193
3.592220980, 23.970, 552.0, 23.4947
3.657419620, 23.970, 511.0, 22.6053
3.722618260, 23.970, 500.0, 22.3607
3.787816900, 23.970, 509.0, 22.5610
3.853015540, 23.970, 499.0, 22.3383
3.918214180, 23.970, 554.0, 23.5372
3.983412820, 23.970, 493.0, 22.2036
4.048611460, 23.970, 450.0, 21.2132
4.113810100, 23.970, 493.0, 22.2036
4.179008740, 23.970, 455.0, 21.3307
4.244207380, 23.970, 502.0, 22.4054
4.309406020, 23.970, 446.0, 21.1187
4.374604660, 23.970, 520.0, 22.8035
4.439803300, 23.970, 527.0, 22.9565
4.505001940, 23.970, 617.0, 24.8395
4.570200580, 23.970, 598.0, 24.4540
4.635399220, 23.970, 619.0, 24.8797
4.700597860, 23.970, 605.0, 24.5967
4.765796500, 23.970, 650.0, 25.4951
4.830995140, 23.970, 651.0, 25.5147
4.896193780, 23.970, 649.0, 25.4755
4.961392420, 23.970, 708.0, 26.6083
5.026591060, 23.970, 751.0, 27.4044
5.091789700, 23.970, 768.0, 27.7128
5.156988340, 23.970, 756.0, 27.4955
5.222186980, 23.970, 825.0, 28.7228
5.287385620, 23.970, 790.0, 28.1069
5.352584260, 23.970, 869.0, 29.4788
5.417782900, 23.970, 811.0, 28.4781
5.482981540, 23.970, 852.0, 29.1890
5.548180180, 23.970, 881.0, 29.6816
5.613378820, 23.970, 942.0, 30.6920
5.678577460, 23.970, 936.0, 30.5941
5.743776100, 23.970, 1004.0, 31.6860
5.808974740, 23.970, 962.0, 31.0161
5.874173380, 23.970, 1035.0, 32.1714
5.939372020, 23.970, 1136.0, 33.7046
6.004570660, 23.970, 1059.0, 32.5423
6.069769300, 23.970, 1134.0, 33.6749
6.134967940, 23.970, 1046.0, 32.3419
6.200166580, 23.970, 1157.0, 34.0147
6.265365220, 23.970, 1160.0, 34.0588
6.330563860, 23.970, 1149.0, 33.8969
6.395762500, 23.970, 1176.0, 34.2929
6.460961140, 23.970, 1239.0, 35.1994
6.526159780, 23.970, 1307.0, 36.1525
6.591358420, 23.970, 1320.0, 36.3318
6.656557060, 23.970, 1285.0, 35.8469
6.721755700, 23.970, 1388.0, 37.2559
6.786954340, 23.970, 1296.0, 36.0000
6.852152980, 23.970, 1367.0, 36.9730
6.917351620, 23.970, 1402.0, 37.4433
6.982550260, 23.970, 1392.0, 37.3095
7.047748900, 23.970, 1454.0, 38.1314
7.112947540, 23.970, 1449.0, 38.0657
7.178146180, 23.970, 1479.0, 38.4578
7.243344820, 23.970, 1495.0, 38.6652
7.308543460, 23.970, 1584.0, 39.7995
7.373742100, 23.970, 1514.0, 38.9102
7.438940740, 23.970, 1596.0, 39.9500
7.504139380, 23.970, 1542.0, 39.2683
7.569338020, 23.970, 1678.0, 40.9634
7.634536660, 23.970, 1668.0, 40.8412
7.699735300, 23.970, 1713.0, 41.3884
7.764933940, 23.970, 1670.0, 40.8656
7.830132580, 23.970, 1620.0, 40.2492
7.895331220, 23.970, 1719.0, 41.4608
7.960529860, 23.970, 1705.0, 41.2916
8.025728500, 23.970, 1723.0, 41.5090
8.090927140, 23.970, 1716.0, 41.4246
8.156125780, 23.970, 1815.0, 42.6028
8.221324420, 23.970, 1801.0, 42.4382
8.286523060, 23.970, 1866.0, 43.1972
8.351721700, 23.970, 1898.0, 43.5660
8.416920340, 23.970, 1823.0, 42.6966
8.482118980, 23.970, 1897.0, 43.5546
8.547317620, 23.970, 1837.0, 42.8602
8.612516260, 23.970, 1848.0, 42.9884
8.677714900, 23.970, 1852.0, 43.0349
8.742913540, 23.970, 1901.0, 43.6005
8.808112180, 23.970, 1819.0, 42.6497
8.873310820, 23.970, 1923.0, 43.8520
8.938509460, 23.970, 1903.0, 43.6234
9.003708100, 23.970, 1919.0, 43.8064
9.068906740, 23.970, 2019.0, 44.9333
9.134105380, 23.970, 1944.0, 44.0908
9.199304020, 23.970, 1830.0, 42.7785
9.264502660, 23.970, 1931.0, 43.9431
9.329701300, 23.970, 1880.0, 43.3590
9.394899940, 23.970, 1974.0, 44.4297
9.460098580, 23.970, 1939.0, 44.0341
9.525297220, 23.970, 1907.0, 43.6692
9.590495860, 23.970, 1943.0, 44.0795
9.655694500, 23.970, 1969.0, 44.3734
9.720893140, 23.970, 1988.0, 44.5870
9.786091780, 23.970, 1962.0, 44.2945
9.851290420, 23.970, 1903.0, 43.6234
9.916489060, 23.970, 1956.0, 44.2267
9.981687700, 23.970, 1982.0, 44.5197
10.046886340, 23.970, 2050.0, 45.2769
10.112084980, 23.970, 1905.0, 43.6463
10.177283620, 23.970, 1988.0, 44.5870
10.242482260, 23.970, 1997.0, 44.6878
10.307680900, 23.970, 1945.0, 44.1022
10.372879540, 23.970, 1897.0, 43.5546
10.438078180, 23.970, 1928.0, 43.9090
10.503276820, 23.970, 1930.0, 43.9318
10.568475460, 23.970, 1924.0, 43.8634
10.633674100, 23.970, 1882.0, 43.3820
10.698872740, 23.970, 1901.0, 43.6005
10.764071380, 23.970, 1917.0, 43.7836
10.829270020, 23.970, 1853.0, 43.0465
10.894468660, 23.970, 1987.0, 44.5758
10.959667300, 23.970, 1900.0, 43.5890
11.024865940, 23.970, 1940.0, 44.0454
11.090064580, 23.970, 1850.0, 43.0116
11.155263220, 23.970, 1850.0, 43.0116
11.220461860, 23.970, 1908.0, 43.6807
11.285660500, 23.970, 1895.0, 43.5316
11.350859140, 23.970, 1906.0, 43.6578
11.416057780, 23.970, 1838.0, 42.8719
11.481256420, 23.970, 1742.0, 41.7373
11.546455060, 23.970, 1750.0, 41.8330
11.611653700, 23.970, 1887.0, 43.4396
11.676852340, 23.970, 1850.0, 43.0116
11.742050980, 23.970, 1809.0, 42.5323
11.807249620, 23.970, 1869.0, 43.2319
11.872448260, 23.970, 1693.0, 41.1461
11.937646900, 23.970, 1821.0, 42.6732
12.002845540, 23.970, 1753.0, 41.8688
12.068044180, 23.970, 1761.0, 41.9643
12.133242820, 23.970, 1728.0, 41.5692
12.198441460, 23.970, 1843.0, 42.9302
12.263640100, 23.970, 1673.0, 40.9023
12.328838740, 23.970, 1703.0, 41.2674
12.394037380, 23.970, 1742.0, 41.7373
12.459236020, 23.970, 1714.0, 41.4005
12.524434660, 23.970, 1721.0, 41.4849
12.589633300, 23.970, 1664.0, 40.7922
12.654831940, 23.970, 1717.0, 41.4367
12.720030580, 23.970, 1696.0, 41.1825
12.785229220, 23.970, 1666.0, 40.8167
12.850427860, 23.970, 1614.0, 40.1746
12.915626500, 23.970, 1601.0, 40.0125
12.980825140, 23.970, 1676.0, 40.9390
13.046023780, 23.970, 1721.0, 41.4849
13.111222420, 23.970, 1615.0, 40.1871
13.176421060, 23.970, 1699.0, 41.2189
13.241619700, 23.970, 1646.0, 40.5709
13.306818340, 23.970, 1602.0, 40.0250
13.372016980, 23.970, 1637.0, 40.4599
13.437215620, 23.970, 1642.0, 40.5216
13.502414260, 23.970, 1596.0, 39.9500
13.567612900, 23.970, 1705.0, 41.2916
13.632811540, 23.970, 1629.0, 40.3609
13.698010180, 23.970, 1594.0, 39.9249
13.763208820, 23.970, 1573.0, 39.6611
13.828407460, 23.970, 1594.0, 39.9249
13.893606100, 23.970, 1713.0, 41.3884
13.958804740, 23.970, 1711.0, 41.3642
14.024003380, 23.970, 1633.0, 40.4104
14.089202020, 23.970, 1637.0, 40.4599
14.154400660, 23.970, 1567.0, 39.5854
14.219599300, 23.970, 1537.0, 39.2046
14.284797940, 23.970, 1731.0, 41.6053
14.349996580, 23.970, 1676.0, 40.9390
14.415195220, 23.970, 1647.0, 40.5832
14.480393860, 23.970, 1638.0, 40.4722
14.545592500, 23.970, 1577.0, 39.7115
14.610791140, 23.970, 1677.0, 40.9512
14.675989780, 23.970, 1760.0, 41.9524
14.741188420, 23.970, 1657.0, 40.7063
14.806387060, 23.970, 1708.0, 41.3280
14.871585700, 23.970, 1641.0, 40.5093
14.936784340, 23.970, 1613.0, 40.1622
15.001982980, 23.970, 1710.0, 41.3521
15.067181620, 23.970, 1719.0, 41.4608
15.132380260, 23.970, 1699.0, 41.2189
15.197578900, 23.970, 1780.0, 42.1900
15.262777540, 23.970, 1792.0, 42.3320
15.327976180, 23.970, 1759.0, 41.9404
15.393174820, 23.970, 1683.0, 41.0244
15.458373460, 23.970, 1738.0, 41.6893
15.523572100, 23.970, 1748.0, 41.8091
15.588770740, 23.970, 1801.0, 42.4382
15.653969380, 23.970, 1870.0, 43.2435
15.719168020, 23.970, 1758.0, 41.9285
15.784366660, 23.970, 1861.0, 43.1393
15.849565300, 23.970, 1891.0, 43.4856
15.914763940, 23.970, 1890.0, 43.4741
15.979962580, 23.970, 1827.0, 42.7434
16.045161220, 23.970, 1896.0, 43.5431
16.110359860, 23.970, 1901.0, 43.6005
16.175558500, 23.970, 1912.0, 43.7264
16.240757140, 23.970, 2020.0, 44.9444
16.305955780, 23.970, 1923.0, 43.8520
16.371154420, 23.970, 2060.0, 45.3872
16.436353060, 23.970, 1944.0, 44.0908
16.501551700, 23.970, 2109.0, 45.9239
16.566750340, 23.970, 2028.0, 45.0333
16.631948980, 23.970, 2099.0, 45.8148
16.697147620, 23.970, 2134.0, 46.1952
16.762346260, 23.970, 2149.0, 46.3573
16.827544900, 23.970, 2219.0, 47.1063
16.892743540, 23.970, 2182.0, 46.7119
16.957942180, 23.970, 2227.0, 47.1911
17.023140820, 23.970, 2265.0, 47.5920
17.088339460, 23.970, 2296.0, 47.9166
17.153538100, 23.970, 2242.0, 47.3498
17.218736740, 23.970, 2434.0, 49.3356
17.283935380, 23.970, 2347.0, 48.4458
17.349134020, 23.970, 2461.0, 49.6085
17.414332660, 23.970, 2508.0, 50.0799
17.479531300, 23.970, 2546.0, 50.4579
17.544729940, 23.970, 2629.0, 51.2738
17.609928580, 23.970, 2666.0, 51.6333
17.675127220, 23.970, 2592.0, 50.9117
17.740325860, 23.970, 2706.0, 52.0192
17.805524500, 23.970, 2725.0, 52.2015
17.870723140, 23.970, 2885.0, 53.7122
17.935921780, 23.970, 2795.0, 52.8678
18.001120420, 23.970, 2944.0, 54.2586
18.066319060, 23.970, 2996.0, 54.7357
18.131517700, 23.970, 3109.0, 55.7584
18.196716340, 23.970, 3072.0, 55.4256
18.261914980, 23.970, 3254.0, 57.0438
18.327113620, 23.970, 3272.0, 57.2014
18.392312260, 23.970, 3123.0, 55.8838
18.457510900, 23.970, 3348.0, 57.8619
18.522709540, 23.970, 3397.0, 58.2838
18.587908180, 23.970, 3476.0, 58.9576
18.653106820, 23.970, 3450.0, 58.7367
18.718305460, 23.970, 3493.0, 59.1016
18.783504100, 23.970, 3652.0, 60.4318
18.848702740, 23.970, 3658.0, 60.4814
18.913901380, 23.970, 3729.0, 61.0655
18.979100020, 23.970, 3776.0, 61.4492
19.044298660, 23.970, 3883.0, 62.3137
19.109497300, 23.970, 4046.0, 63.6082
19.174695940, 23.970, 4078.0, 63.8592
19.239894580, 23.970, 4148.0, 64.4050
19.305093220, 23.970, 4241.0, 65.1230
19.370291860, 23.970, 4171.0, 64.5833
19.435490500, 23.970, 4380.0, 66.1816
19.500689140, 23.970, 4453.0, 66.7308
19.565887780, 23.970, 4427.0, 66.5357
19.631086420, 23.970, 4596.0, 67.7938
19.696285060, 23.970, 4613.0, 67.9191
19.761483700, 23.970, 4733.0, 68.7968
19.826682340, 23.970, 4823.0, 69.4478
19.891880980, 23.970, 4904.0, 70.0286
19.957079620, 23.970, 4920.0, 70.1427
20.022278260, 23.970, 4941.0, 70.2922
20.087476900, 23.970, 4956.0, 70.3989
20.152675540, 23.970, 4925.0, 70.1783
20.217874180, 23.970, 4871.0, 69.7925
20.283072820, 23.970, 4884.0, 69.8856
20.348271460, 23.970, 5113.0, 71.5052
20.413470100, 23.970, 5093.0, 71.3653
20.478668740, 23.970, 5069.0, 71.1969
20.543867380, 23.970, 5199.0, 72.1041
20.609066020, 23.970, 5171.0, 71.9097
20.674264660, 23.970, 5342.0, 73.0890
20.739463300, 23.970, 5353.0, 73.1642
20.804661940, 23.970, 5605.0, 74.8665
20.869860580, 23.970, 5525.0, 74.3303
20.935059220, 23.970, 5915.0, 76.9090
21.000257860, 23.970, 6123.0, 78.2496
21.065456500, 23.970, 6437.0, 80.2309
21.130655140, 23.970, 6738.0, 82.0853
21.195853780, 23.970, 7492.0, 86.5563
21.261052420, 23.970, 8120.0, 90.1110
21.326251060, 23.970, 9357.0, 96.7316
21.391449700, 23.970, 11144.0, 105.5651
21.456648340, 23.970, 13720.0, 117.1324
21.521846980, 23.970, 17151.0, 130.9618
21.587045620, 23.970, 20984.0, 144.8586
21.652244260, 23.970, 25546.0, 159.8312
21.717442900, 23.970, 31907.0, 178.6253
21.782641540, 23.970, 39730.0, 199.3239
21.847840180, 23.970, 49290.0, 222.0135
21.913038820, 23.970, 61146.0, 247.2772
21.978237460, 23.970, 73888.0, 271.8235
22.043436100, 23.970, 79370.0, 281.7268
22.108634740, 23.970, 70663.0, 265.8251
22.173833380, 23.970, 50797.0, 225.3819
22.239032020, 23.970, 30143.0, 173.6174
22.304230660, 23.970, 17814.0, 133.4691
22.369429300, 23.970, 11903.0, 109.1009
22.434627940, 23.970, 9057.0, 95.1683
22.499826580, 23.970, 7246.0, 85.1234
22.565025220, 23.970, 6238.0, 78.9810
22.630223860, 23.970, 5541.0, 74.4379
22.695422500, 23.970, 5009.0, 70.7743
22.760621140, 23.970, 4781.0, 69.1448
22.825819780, 23.970, 4611.0, 67.9043
22.891018420, 23.970, 4338.0, 65.8635
22.956217060, 23.970, 4143.0, 64.3661
23.021415700, 23.970, 4087.0, 63.9296
23.086614340, 23.970, 3931.0, 62.6977
23.151812980, 23.970, 3917.0, 62.5859
23.217011620, 23.970, 3926.0, 62.6578
23.282210260, 23.970, 3868.0, 62.1932
23.347408900, 23.970, 3830.0, 61.8870
23.412607540, 23.970, 3952.0, 62.8649
23.477806180, 23.970, 3923.0, 62.6339
23.543004820, 23.970, 4104.0, 64.0625
23.608203460, 23.970, 4156.0, 64.4670
23.673402100, 23.970, 4359.0, 66.0227
23.738600740, 23.970, 4601.0, 67.8307
23.803799380, 23.970, 5121.0, 71.5612
23.868998020, 23.970, 5786.0, 76.0658
23.934196660, 23.970, 6545.0, 80.9012
23.999395300, 23.970, 7248.0, 85.1352
24.064593940, 23.970, 8379.0, 91.5369
24.129792580, 23.970, 9894.0, 99.4686
24.194991220, 23.970, 11269.0, 106.1555
24.260189860, 23.970, 13049.0, 114.2322
24.325388500, 23.970, 14774.0, 121.5483
24.390587140, 23.970, 16248.0, 127.4676
24.455785780, 23.970, 16339.0, 127.8241
24.520984420, 23.970, 14922.0, 122.1556
24.586183060, 23.970, 11690.0, 108.1203
24.651381700, 23.970, 8661.0, 93.0645
24.716580340, 23.970, 6362.0, 79.7621
24.781778980, 23.970, 4697.0, 68.5347
24.846977620, 23.970, 3854.0, 62.0806
24.912176260, 23.970, 3275.0, 57.2276
24.977374900, 23.970, 3031.0, 55.0545
25.042573540, 23.970, 2736.0, 52.3068
25.107772180, 23.970, 2588.0, 50.8724
25.172970820, 23.970, 2516.0, 50.1597
25.238169460, 23.970, 2256.0, 47.4974
25.303368100, 23.970, 2205.0, 46.9574
25.368566740, 23.970, 2158.0, 46.4543
25.433765380, 23.970, 2080.0, 45.6070
25.498964020, 23.970, 2059.0, 45.3762
25.564162660, 23.970, 1962.0, 44.2945
25.629361300, 23.970, 1966.0, 44.3396
25.694559940, 23.970, 1850.0, 43.0116
25.759758580, 23.970, 1842.0, 42.9185
25.824957220, 23.970, 1884.0, 43.4051
25.890155860, 23.970, 1819.0, 42.6497
25.955354500, 23.970, 1718.0, 41.4488
26.020553140, 23.970, 1771.0, 42.0833
26.085751780, 23.970, 1682.0, 41.0122
26.150950420, 23.970, 1704.0, 41.2795
26.216149060, 23.970, 1635.0, 40.4351
26.281347700, 23.970, 1626.0, 40.3237
26.346546340, 23.970, 1633.0, 40.4104
26.411744980, 23.970, 1616.0, 40.1995
26.476943620, 23.970, 1596.0, 39.9500
26.542142260, 23.970, 1567.0, 39.5854
26.607340900, 23.970, 1550.0, 39.3700
26.672539540, 23.970, 1578.0, 39.7240
26.737738180, 23.970, 1511.0, 38.8716
26.802936820, 23.970, 1575.0, 39.6863
26.868135460, 23.970, 1408.0, 37.5233
26.933334100, 23.970, 1522.0, 39.0128
26.998532740, 23.970, 1384.0, 37.2022
27.063731380, 23.970, 1486.0, 38.5487
27.128930020, 23.970, 1417.0, 37.6431
27.194128660, 23.970, 1414.0, 37.6032
27.259327300, 23.970, 1451.0, 38.0920
27.324525940, 23.970, 1407.0, 37.5100
27.389724580, 23.970, 1351.0, 36.7560
27.454923220, 23.970, 1358.0, 36.8511
27.520121860, 23.970, 1313.0, 36.2353
27.585320500, 23.970, 1316.0, 36.2767
27.650519140, 23.970, 1346.0, 36.6879
27.715717780, 23.970, 1299.0, 36.0416
27.780916420, 23.970, 1373.0, 37.0540
27.846115060, 23.970, 1330.0, 36.4692
27.911313700, 23.970, 1273.0, 35.6791
27.976512340, 23.970, 1281.0, 35.7911
28.041710980, 23.970, 1231.0, 35.0856
28.106909620, 23.970, 1228.0, 35.0428
28.172108260, 23.970, 1268.0, 35.6090
28.237306900, 23.970, 1227.0, 35.0286
28.302505540, 23.970, 1260.0, 35.4965
28.367704180, 23.970, 1286.0, 35.8608
28.432902820, 23.970, 1204.0, 34.6987
28.498101460, 23.970, 1200.0, 34.6410
28.563300100, 23.970, 1241.0, 35.2278
28.628498740, 23.970, 1136.0, 33.7046
28.693697380, 23.970, 1166.0, 34.1467
28.758896020, 23.970, 1114.0, 33.3766
28.824094660, 23.970, 1071.0, 32.7261
28.889293300, 23.970, 1141.0, 33.7787
28.954491940, 23.970, 1150.0, 33.9116
29.019690580, 23.970, 1191.0, 34.5109
29.084889220, 23.970, 1227.0, 35.0286
29.150087860, 23.970, 1204.0, 34.6987
29.215286500, 23.970, 1440.0, 37.9473
29.280485140, 23.970, 1918.0, 43.7950
29.345683780, 23.970, 1738.0, 41.6893
29.410882420, 23.970, 1307.0, 36.1525
29.476081060, 23.970, 1137.0, 33.7194
29.541279700, 23.970, 1127.0, 33.5708
29.606478340, 23.970, 1185.0, 34.4238
29.671676980, 23.970, 1187.0, 34.4529
29.736875620, 23.970, 1184.0, 34.4093
29.802074260, 23.970, 1160.0, 34.0588
29.867272900, 23.970, 1194.0, 34.5543
29.932471540, 23.970, 1232.0, 35.0999
29.997670180, 23.970, 1262.0, 35.5246
30.062868820, 23.970, 1389.0, 37.2693
30.128067460, 23.970, 1383.0, 37.1887
30.193266100, 23.970, 1489.0, 38.5876
30.258464740, 23.970, 1526.0, 39.0640
30.323663380, 23.970, 1662.0, 40.7676
30.388862020, 23.970, 1679.0, 40.9756
30.454060660, 23.970, 1838.0, 42.8719
30.519259300, 23.970, 1869.0, 43.2319
30.584457940, 23.970, 1943.0, 44.0795
30.649656580, 23.970, 1755.0, 41.8927
30.714855220, 23.970, 1607.0, 40.0874
30.780053860, 23.970, 1454.0, 38.1314
30.845252500, 23.970, 1248.0, 35.3270
30.910451140, 23.970, 1155.0, 33.9853
30.975649780, 23.970, 1146.0, 33.8526
31.040848420, 23.970, 1063.0, 32.6037
31.106047060, 23.970, 1072.0, 32.7414
31.171245700, 23.970, 1058.0, 32.5269
31.236444340, 23.970, 1052.0, 32.4345
31.301642980, 23.970, 1019.0, 31.9218
31.366841620, 23.970, 1086.0, 32.9545
31.432040260, 23.970, 1044.0, 32.3110
31.497238900, 23.970, 968.0, 31.1127
31.562437540, 23.970, 988.0, 31.4325
31.627636180, 23.970, 1012.0, 31.8119
31.692834820, 23.970, 1003.0, 31.6702
31.758033460, 23.970, 987.0, 31.4166
31.823232100, 23.970, 943.0, 30.7083
31.888430740, 23.970, 1005.0, 31.7017
31.953629380, 23.970, 1014.0, 31.8434
32.018828020, 23.970, 936.0, 30.5941
32.084026660, 23.970, 981.0, 31.3209
32.149225300, 23.970, 1006.0, 31.7175
32.214423940, 23.970, 921.0, 30.3480
32.279622580, 23.970, 987.0, 31.4166
32.344821220, 23.970, 1008.0, 31.7490
32.410019860, 23.970, 967.0, 31.0966
32.475218500, 23.970, 986.0, 31.4006
32.540417140, 23.970, 972.0, 31.1769
32.605615780, 23.970, 893.0, 29.8831
32.670814420, 23.970, 937.0, 30.6105
32.736013060, 23.970, 935.0, 30.5778
32.801211700, 23.970, 1016.0, 31.8748
32.866410340, 23.970, 978.0, 31.2730
32.931608980, 23.970, 922.0, 30.3645
32.996807620, 23.970, 926.0, 30.4302
33.062006260, 23.970, 883.0, 29.7153
33.127204900, 23.970, 994.0, 31.5278
33.192403540, 23.970, 982.0, 31.3369
33.257602180, 23.970, 977.0, 31.2570
33.322800820, 23.970, 935.0, 30.5778
33.387999460, 23.970, 956.0, 30.9192
33.453198100, 23.970, 944.0, 30.7246
33.518396740, 23.970, 965.0, 31.0644
33.583595380, 23.970, 953.0, 30.8707
33.648794020, 23.970, 929.0, 30.4795
33.713992660, 23.970, 957.0, 30.9354
33.779191300, 23.970, 938.0, 30.6268
33.844389940, 23.970, 938.0, 30.6268
33.909588580, 23.970, 877.0, 29.6142
33.974787220, 23.970, 908.0, 30.1330
34.039985860, 23.970, 936.0, 30.5941
34.105184500, 23.970, 961.0, 31.0000
34.170383140, 23.970, 906.0, 30.0998
34.235581780, 23.970, 929.0, 30.4795
34.300780420, 23.970, 950.0, 30.8221
34.365979060, 23.970, 940.0, 30.6594
34.431177700, 23.970, 947.0, 30.7734
34.496376340, 23.970, 905.0, 30.0832
34.561574980, 23.970, 907.0, 30.1164
34.626773620, 23.970, 905.0, 30.0832
34.691972260, 23.970, 989.0, 31.4484
34.757170900, 23.970, 990.0, 31.4643
34.822369540, 23.970, 943.0, 30.7083
34.887568180, 23.970, 971.0, 31.1609
34.952766820, 23.970, 957.0, 30.9354
35.017965460, 23.970, 953.0, 30.8707
35.083164100, 23.970, 946.0, 30.7571
35.148362740, 23.970, 938.0, 30.6268
35.213561380, 23.970, 941.0, 30.6757
35.278760020, 23.970, 953.0, 30.8707
35.343958660, 23.970, 987.0, 31.4166
35.409157300, 23.970, 984.0, 31.3688
35.474355940, 23.970, 1084.0, 32.9242
35.539554580, 23.970, 1026.0, 32.0312
35.604753220, 23.970, 1082.0, 32.8938
35.669951860, 23.970, 1092.0, 33.0454
35.735150500, 23.970, 1079.0, 32.8481
35.800349140, 23.970, 1196.0, 34.5832
35.865547780, 23.970, 1215.0, 34.8569
35.930746420, 23.970, 1225.0, 35.0000
35.995945060, 23.970, 1349.0, 36.7287
36.061143700, 23.970, 1424.0, 37.7359
36.126342340, 23.970, 1502.0, 38.7556
36.191540980, 23.970, 1763.0, 41.9881
36.256739620, 23.970, 2064.0, 45.4313
36.321938260, 23.970, 2272.0, 47.6655
36.387136900, 23.970, 2670.0, 51.6720
36.452335540, 23.970, 3016.0, 54.9181
36.517534180, 23.970, 3184.0, 56.4269
36.582732820, 23.970, 3448.0, 58.7197
36.647931460, 23.970, 3601.0, 60.0083
36.713130100, 23.970, 3613.0, 60.1082
36.778328740, 23.970, 3311.0, 57.5413
36.843527380, 23.970, 2843.0, 53.3198
36.908726020, 23.970, 2458.0, 49.5782
36.973924660, 23.970, 2109.0, 45.9239
37.039123300, 23.970, 1691.0, 41.1218
37.104321940, 23.970, 1455.0, 38.1445
37.169520580, 23.970, 1359.0, 36.8646
37.234719220, 23.970, 1263.0, 35.5387
37.299917860, 23.970, 1217.0, 34.8855
37.365116500, 23.970, 1138.0, 33.7343
37.430315140, 23.970, 1093.0, 33.0606
37.495513780, 23.970, 1153.0, 33.9559
37.560712420, 23.970, 1066.0, 32.6497
37.625911060, 23.970, 1141.0, 33.7787
37.691109700, 23.970, 1073.0, 32.7567
37.756308340, 23.970, 1109.0, 33.3017
37.821506980, 23.970, 1164.0, 34.1174
37.886705620, 23.970, 1076.0, 32.8024
37.951904260, 23.970, 1128.0, 33.5857
38.017102900, 23.970, 1244.0, 35.2704
38.082301540, 23.970, 1235.0, 35.1426
38.147500180, 23.970, 1289.0, 35.9026
38.212698820, 23.970, 1188.0, 34.4674
38.277897460, 23.970, 1232.0, 35.0999
38.343096100, 23.970, 1168.0, 34.1760
38.408294740, 23.970, 1205.0, 34.7131
38.473493380, 23.970, 1295.0, 35.9861
38.538692020, 23.970, 1308.0, 36.1663
38.603890660, 23.970, 1314.0, 36.2491
38.669089300, 23.970, 1294.0, 35.9722
38.734287940, 23.970, 1364.0, 36.9324
38.799486580, 23.970, 1367.0, 36.9730
38.864685220, 23.970, 1327.0, 36.4280
38.929883860, 23.970, 1292.0, 35.9444
38.995082500, 23.970, 1239.0, 35.1994
39.060281140, 23.970, 1197.0, 34.5977
39.125479780, 23.970, 1198.0, 34.6121
39.190678420, 23.970, 1296.0, 36.0000
39.255877060, 23.970, 1260.0, 35.4965
39.321075700, 23.970, 1393.0, 37.3229
39.386274340, 23.970, 1328.0, 36.4417
39.451472980, 23.970, 1228.0, 35.0428
39.516671620, 23.970, 1285.0, 35.8469
39.581870260, 23.970, 1344.0, 36.6606
39.647068900, 23.970, 1467.0, 38.3014
39.712267540, 23.970, 1569.0, 39.6106
39.777466180, 23.970, 1631.0, 40.3856
39.842664820, 23.970, 1847.0, 42.9767
39.907863460, 23.970, 1924.0, 43.8634
39.973062100, 23.970, 2045.0, 45.2217
40.038260740, 23.970, 2164.0, 46.5188
40.103459380, 23.970, 2180.0, 46.6905
40.168658020, 23.970, 2365.0, 48.6313
40.233856660, 23.970, 2131.0, 46.1628
40.299055300, 23.970, 2036.0, 45.1221
40.364253940, 23.970, 2014.0, 44.8776
40.429452580, 23.970, 1887.0, 43.4396
40.494651220, 23.970, 1637.0, 40.4599
40.559849860, 23.970, 1636.0, 40.4475
40.625048500, 23.970, 1588.0, 39.8497
40.690247140, 23.970, 1583.0, 39.7869
40.755445780, 23.970, 1662.0, 40.7676
40.820644420, 23.970, 1668.0, 40.8412
40.885843060, 23.970, 1740.0, 41.7133
40.951041700, 23.970, 1821.0, 42.6732
41.016240340, 23.970, 1920.0, 43.8178
41.081438980, 23.970, 1989.0, 44.5982
41.146637620, 23.970, 2108.0, 45.9130
41.211836260, 23.970, 2103.0, 45.8585
41.277034900, 23.970, 1996.0, 44.6766
41.342233540, 23.970, 1935.0, 43.9886
41.407432180, 23.970, 1858.0, 43.1045
41.472630820, 23.970, 1722.0, 41.4970
41.537829460, 23.970, 1567.0, 39.5854
41.603028100, 23.970, 1610.0, 40.1248
41.668226740, 23.970, 1527.0, 39.0768
41.733425380, 23.970, 1675.0, 40.9268
41.798624020, 23.970, 1747.0, 41.7971
41.863822660, 23.970, 1762.0, 41.9762
41.929021300, 23.970, 1897.0, 43.5546
41.994219940, 23.970, 1890.0, 43.4741
42.059418580, 23.970, 1894.0, 43.5201
42.124617220, 23.970, 1842.0, 42.9185
42.189815860, 23.970, 1738.0, 41.6893
42.255014500, 23.970, 1646.0, 40.5709
42.320213140, 23.970, 1480.0, 38.4708
42.385411780, 23.970, 1398.0, 37.3898
42.450610420, 23.970, 1340.0, 36.6060
42.515809060, 23.970, 1391.0, 37.2961
42.581007700, 23.970, 1305.0, 36.1248
42.646206340, 23.970, 1336.0, 36.5513
42.711404980, 23.970, 1335.0, 36.5377
42.776603620, 23.970, 1368.0, 36.9865
42.841802260, 23.970, 1453.0, 38.1182
42.907000900, 23.970, 1450.0, 38.0789
42.972199540, 23.970, 1647.0, 40.5832
43.037398180, 23.970, 1748.0, 41.8091
43.102596820, 23.970, 1824.0, 42.7083
43.167795460, 23.970, 1899.0, 43.5775
43.232994100, 23.970, 1813.0, 42.5793
43.298192740, 23.970, 1930.0, 43.9318
43.363391380, 23.970, 1964.0, 44.3170
43.428590020, 23.970, 1862.0, 43.1509
43.493788660, 23.970, 1885.0, 43.4166
43.558987300, 23.970, 1694.0, 41.1582
43.624185940, 23.970, 1673.0, 40.9023
43.689384580, 23.970, 1452.0, 38.1051
43.754583220, 23.970, 1441.0, 37.9605
43.819781860, 23.970, 1453.0, 38.1182
43.884980500, 23.970, 1409.0, 37.5366
43.950179140, 23.970, 1459.0, 38.1969
44.015377780, 23.970, 1446.0, 38.0263
44.080576420, 23.970, 1481.0, 38.4838
44.145775060, 23.970, 1517.0, 38.9487
44.210973700, 23.970, 1603.0, 40.0375
44.276172340, 23.970, 1560.0, 39.4968
44.341370980, 23.970, 1696.0, 41.1825
44.406569620, 23.970, 1661.0, 40.7554
44.471768260, 23.970, 1712.0, 41.3763
44.536966900, 23.970, 1453.0, 38.1182
44.602165540, 23.970, 1354.0, 36.7967
44.667364180, 23.970, 1216.0, 34.8712
44.732562820, 23.970, 1236.0, 35.1568
44.797761460, 23.970, 1105.0, 33.2415
44.862960100, 23.970, 1135.0, 33.6898
44.928158740, 23.970, 992.0, 31.4960
44.993357380, 23.970, 1042.0, 32.2800
45.058556020, 23.970, 1004.0, 31.6860
45.123754660, 23.970, 954.0, 30.8869
45.188953300, 23.970, 951.0, 30.8383
45.254151940, 23.970, 1007.0, 31.7333
45.319350580, 23.970, 993.0, 31.5119
45.384549220, 23.970, 959.0, 30.9677
45.449747860, 23.970, 988.0, 31.4325
45.514946500, 23.970, 967.0, 31.0966
45.580145140, 23.970, 972.0, 31.1769
45.645343780, 23.970, 962.0, 31.0161
45.710542420, 23.970, 999.0, 31.6070
45.775741060, 23.970, 882.0, 29.6985
45.840939700, 23.970, 949.0, 30.8058
45.906138340, 23.970, 971.0, 31.1609
45.971336980, 23.970, 951.0, 30.8383
46.036535620, 23.970, 941.0, 30.6757
46.101734260, 23.970, 916.0, 30.2655
46.166932900, 23.970, 980.0, 31.3050
46.232131540, 23.970, 913.0, 30.2159
46.297330180, 23.970, 921.0, 30.3480
46.362528820, 23.970, 947.0, 30.7734
46.427727460, 23.970, 993.0, 31.5119
46.492926100, 23.970, 971.0, 31.1609
46.558124740, 23.970, 1014.0, 31.8434
46.623323380, 23.970, 993.0, 31.5119
46.688522020, 23.970, 956.0, 30.9192
46.753720660, 23.970, 1055.0, 32.4808
46.818919300, 23.970, 1139.0, 33.7491
46.884117940, 23.970, 1165.0, 34.1321
46.949316580, 23.970, 1152.0, 33.9411
47.014515220, 23.970, 1340.0, 36.6060
47.079713860, 23.970, 1373.0, 37.0540
47.144912500, 23.970, 1393.0, 37.3229
47.210111140, 23.970, 1417.0, 37.6431
47.275309780, 23.970, 1516.0, 38.9358
47.340508420, 23.970, 1586.0, 39.8246
47.405707060, 23.970, 1676.0, 40.9390
47.470905700, 23.970, 1508.0, 38.8330
47.536104340, 23.970, 1396.0, 37.3631
47.601302980, 23.970, 1221.0, 34.9428
47.666501620, 23.970, 1088.0, 32.9848
47.731700260, 23.970, 1055.0, 32.4808
47.796898900, 23.970, 967.0, 31.0966
47.862097540, 23.970, 970.0, 31.1448
47.927296180, 23.970, 931.0, 30.5123
47.992494820, 23.970, 944.0, 30.7246
48.057693460, 23.970, 965.0, 31.0644
48.122892100, 23.970, 931.0, 30.5123
48.188090740, 23.970, 940.0, 30.6594
48.253289380, 23.970, 973.0, 31.1929
48.318488020, 23.970, 1047.0, 32.3574
48.383686660, 23.970, 1187.0, 34.4529
48.448885300, 23.970, 1092.0, 33.0454
48.514083940, 23.970, 1068.0, 32.6803
48.579282580, 23.970, 1013.0, 31.8277
48.644481220, 23.970, 871.0, 29.5127
48.709679860, 23.970, 881.0, 29.6816
48.774878500, 23.970, 935.0, 30.5778
48.840077140, 23.970, 896.0, 29.9333
48.905275780, 23.970, 927.0, 30.4467
48.970474420, 23.970, 923.0, 30.3809
49.035673060, 23.970, 886.0, 29.7658
49.100871700, 23.970, 923.0, 30.3809
49.166070340, 23.970, 924.0, 30.3974
49.231268980, 23.970, 952.0, 30.8545
49.296467620, 23.970, 939.0, 30.6431
49.361666260, 23.970, 976.0, 31.2410
49.426864900, 23.970, 984.0, 31.3688
49.492063540, 23.970, 971.0, 31.1609
49.557262180, 23.970, 1052.0, 32.4345
49.622460820, 23.970, 1008.0, 31.7490
49.687659460, 23.970, 883.0, 29.7153
49.752858100, 23.970, 939.0, 30.6431
49.818056740, 23.970, 893.0, 29.8831
49.883255380, 23.970, 878.0, 29.6311
49.948454020, 23.970, 840.0, 28.9828
50.013652660, 23.970, 901.0, 30.0167
50.078851300, 23.970, 877.0, 29.6142
50.144049940, 23.970, 850.0, 29.1548
50.209248580, 23.970, 852.0, 29.1890
50.274447220, 23.970, 799.0, 28.2666
50.339645860, 23.970, 902.0, 30.0333
50.404844500, 23.970, 786.0, 28.0357
50.470043140, 23.970, 854.0, 29.2233
50.535241780, 23.970, 830.0, 28.8097
50.600440420, 23.970, 774.0, 27.8209
50.665639060, 23.970, 784.0, 28.0000
50.730837700, 23.970, 849.0, 29.1376
50.796036340, 23.970, 805.0, 28.3725
50.861234980, 23.970, 799.0, 28.2666
50.926433620, 23.970, 821.0, 28.6531
50.991632260, 23.970, 817.0, 28.5832
51.056830900, 23.970, 799.0, 28.2666
51.122029540, 23.970, 737.0, 27.1477
51.187228180, 23.970, 808.0, 28.4253
51.252426820, 23.970, 817.0, 28.5832
51.317625460, 23.970, 831.0, 28.8271
51.382824100, 23.970, 716.0, 26.7582
51.448022740, 23.970, 754.0, 27.4591
51.513221380, 23.970, 806.0, 28.3901
51.578420020, 23.970, 777.0, 27.8747
51.643618660, 23.970, 835.0, 28.8964
51.708817300, 23.970, 837.0, 28.9310
51.774015940, 23.970, 838.0, 28.9482
51.839214580, 23.970, 860.0, 29.3258
51.904413220, 23.970, 836.0, 28.9137
51.969611860, 23.970, 870.0, 29.4958
52.034810500, 23.970, 836.0, 28.9137
52.100009140, 23.970, 875.0, 29.5804
52.165207780, 23.970, 859.0, 29.3087
52.230406420, 23.970, 833.0, 28.8617
52.295605060, 23.970, 946.0, 30.7571
52.360803700, 23.970, 942.0, 30.6920
52.426002340, 23.970, 977.0, 31.2570
52.491200980, 23.970, 989.0, 31.4484
52.556399620, 23.970, 1023.0, 31.9844
52.621598260, 23.970, 1150.0, 33.9116
52.686796900, 23.970, 1086.0, 32.9545
52.751995540, 23.970, 1083.0, 32.9090
52.817194180, 23.970, 1212.0, 34.8138
52.882392820, 23.970, 1209.0, 34.7707
52.947591460, 23.970, 1302.0, 36.0832
53.012790100, 23.970, 1346.0, 36.6879
53.077988740, 23.970, 1400.0, 37.4166
53.143187380, 23.970, 1423.0, 37.7227
53.208386020, 23.970, 1505.0, 38.7943
53.273584660, 23.970, 1586.0, 39.8246
53.338783300, 23.970, 1585.0, 39.8121
53.403981940, 23.970, 1552.0, 39.3954
53.469180580, 23.970, 1543.0, 39.2810
53.534379220, 23.970, 1450.0, 38.0789
53.599577860, 23.970, 1349.0, 36.7287
53.664776500, 23.970, 1264.0, 35.5528
53.729975140, 23.970, 1149.0, 33.8969
53.795173780, 23.970, 1063.0, 32.6037
53.860372420, 23.970, 1096.0, 33.1059
53.925571060, 23.970, 952.0, 30.8545
53.990769700, 23.970, 934.0, 30.5614
54.055968340, 23.970, 885.0, 29.7489
54.121166980, 23.970, 835.0, 28.8964
54.186365620, 23.970, 830.0, 28.8097
54.251564260, 23.970, 813.0, 28.5132
54.316762900, 23.970, 814.0, 28.5307
54.381961540, 23.970, 853.0, 29.2062
54.447160180, 23.970, 832.0, 28.8444
54.512358820, 23.970, 881.0, 29.6816
54.577557460, 23.970, 888.0, 29.7993
54.642756100, 23.970, 874.0, 29.5635
54.707954740, 23.970, 890.0, 29.8329
54.773153380, 23.970, 916.0, 30.2655
54.838352020, 23.970, 988.0, 31.4325
54.903550660, 23.970, 1017.0, 31.8904
54.968749300, 23.970, 1064.0, 32.6190
55.033947940, 23.970, 1073.0, 32.7567
55.099146580, 23.970, 1155.0, 33.9853
55.164345220, 23.970, 1157.0, 34.0147
55.229543860, 23.970, 1111.0, 33.3317
55.294742500, 23.970, 1094.0, 33.0757
55.359941140, 23.970, 1103.0, 33.2114
55.425139780, 23.970, 1041.0, 32.2645
55.490338420, 23.970, 993.0, 31.5119
55.555537060, 23.970, 955.0, 30.9031
55.620735700, 23.970, 966.0, 31.0805
55.685934340, 23.970, 892.0, 29.8664
55.751132980, 23.970, 797.0, 28.2312
55.816331620, 23.970, 824.0, 28.7054
55.881530260, 23.970, 766.0, 27.6767
55.946728900, 23.970, 776.0, 27.8568
56.011927540, 23.970, 806.0, 28.3901
56.077126180, 23.970, 833.0, 28.8617
56.142324820, 23.970, 776.0, 27.8568
56.207523460, 23.970, 780.0, 27.9285
56.272722100, 23.970, 788.0, 28.0713
56.337920740, 23.970, 734.0, 27.0924
56.403119380, 23.970, 749.0, 27.3679
56.468318020, 23.970, 754.0, 27.4591
56.533516660, 23.970, 773.0, 27.8029
56.598715300, 23.970, 764.0, 27.6405
56.663913940, 23.970, 776.0, 27.8568
56.729112580, 23.970, 740.0, 27.2029
56.794311220, 23.970, 777.0, 27.8747
56.859509860, 23.970, 790.0, 28.1069
56.924708500, 23.970, 792.0, 28.1425
56.989907140, 23.970, 794.0, 28.1780
57.055105780, 23.970, 809.0, 28.4429
57.120304420, 23.970, 845.0, 29.0689
57.185503060, 23.970, 860.0, 29.3258
57.250701700, 23.970, 1003.0, 31.6702
57.315900340, 23.970, 1070.0, 32.7109
57.381098980, 23.970, 1050.0, 32.4037
57.446297620, 23.970, 1069.0, 32.6956
57.511496260, 23.970, 969.0, 31.1288
57.576694900, 23.970, 1006.0, 31.7175
57.641893540, 23.970, 941.0, 30.6757
57.707092180, 23.970, 912.0, 30.1993
57.772290820, 23.970, 914.0, 30.2324
57.837489460, 23.970, 914.0, 30.2324
57.902688100, 23.970, 875.0, 29.5804
57.967886740, 23.970, 863.0, 29.3769
58.033085380, 23.970, 905.0, 30.0832
58.098284020, 23.970, 838.0, 28.9482
58.163482660, 23.970, 845.0, 29.0689
58.228681300, 23.970, 760.0, 27.5681
58.293879940, 23.970, 704.0, 26.5330
58.359078580, 23.970, 712.0, 26.6833
58.424277220, 23.970, 739.0, 27.1846
58.489475860, 23.970, 689.0, 26.2488
58.554674500, 23.970, 727.0, 26.9629
58.619873140, 23.970, 660.0, 25.6905
58.685071780, 23.970, 662.0, 25.7294
58.750270420, 23.970, 714.0, 26.7208
58.815469060, 23.970, 681.0, 26.0960
58.880667700, 23.970, 638.0, 25.2587
58.945866340, 23.970, 649.0, 25.4755
59.011064980, 23.970, 673.0, 25.9422
59.076263620, 23.970, 652.0, 25.5343
59.141462260, 23.970, 645.0, 25.3969
59.206660900, 23.970, 691.0, 26.2869
59.271859540, 23.970, 672.0, 25.9230
59.337058180, 23.970, 662.0, 25.7294
59.402256820, 23.970, 646.0, 25.4165
59.467455460, 23.970, 659.0, 25.6710
59.532654100, 23.970, 659.0, 25.6710
59.597852740, 23.970, 683.0, 26.1343
59.663051380, 23.970, 631.0, 25.1197
59.728250020, 23.970, 670.0, 25.8844
59.793448660, 23.970, 645.0, 25.3969
59.858647300, 23.970, 634.0, 25.1794
59.923845940, 23.970, 640.0, 25.2982
59.989044580, 23.970, 640.0, 25.2982
60.054243220, 23.970, 614.0, 24.7790
60.119441860, 23.970, 651.0, 25.5147
60.184640500, 23.970, 646.0, 25.4165
60.249839140, 23.970, 725.0, 26.9258
60.315037780, 23.970, 628.0, 25.0599
60.380236420, 23.970, 666.0, 25.8070
60.445435060, 23.970, 669.0, 25.8650
60.510633700, 23.970, 721.0, 26.8514
60.575832340, 23.970, 755.0, 27.4773
60.641030980, 23.970, 692.0, 26.3059
60.706229620, 23.970, 755.0, 27.4773
60.771428260, 23.970, 695.0, 26.3629
60.836626900, 23.970, 722.0, 26.8701
60.901825540, 23.970, 738.0, 27.1662
60.967024180, 23.970, 730.0, 27.0185
61.032222820, 23.970, 690.0, 26.2679
61.097421460, 23.970, 690.0, 26.2679
61.162620100, 23.970, 725.0, 26.9258
61.227818740, 23.970, 693.0, 26.3249
61.293017380, 23.970, 726.0, 26.9444
61.358216020, 23.970, 707.0, 26.5895
61.423414660, 23.970, 775.0, 27.8388
61.488613300, 23.970, 639.0, 25.2784
61.553811940, 23.970, 745.0, 27.2947
61.619010580, 23.970, 733.0, 27.0740
61.684209220, 23.970, 681.0, 26.0960
61.749407860, 23.970, 724.0, 26.9072
61.814606500, 23.970, 753.0, 27.4408
61.879805140, 23.970, 733.0, 27.0740
61.945003780, 23.970, 824.0, 28.7054
62.010202420, 23.970, 808.0, 28.4253
62.075401060, 23.970, 804.0, 28.3549
62.140599700, 23.970, 805.0, 28.3725
62.205798340, 23.970, 802.0, 28.3196
62.270996980, 23.970, 763.0, 27.6225
62.336195620, 23.970, 742.0, 27.2397
62.401394260, 23.970, 746.0, 27.3130
62.466592900, 23.970, 710.0, 26.6458
62.531791540, 23.970, 668.0, 25.8457
62.596990180, 23.970, 723.0, 26.8887
62.662188820, 23.970, 657.0, 25.6320
62.727387460, 23.970, 667.0, 25.8263
62.792586100, 23.970, 727.0, 26.9629
62.857784740, 23.970, 687.0, 26.2107
62.922983380, 23.970, 696.0, 26.3818
62.988182020, 23.970, 687.0, 26.2107
63.053380660, 23.970, 674.0, 25.9615
63.118579300, 23.970, 686.0, 26.1916
63.183777940, 23.970, 636.0, 25.2190
63.248976580, 23.970, 600.0, 24.4949
63.314175220, 23.970, 629.0, 25.0799
63.379373860, 23.970, 608.0, 24.6577
63.444572500, 23.970, 650.0, 25.4951
63.509771140, 23.970, 609.0, 24.6779
63.574969780, 23.970, 591.0, 24.3105
63.640168420, 23.970, 654.0, 25.5734
63.705367060, 23.970, 587.0, 24.2281
63.770565700, 23.970, 624.0, 24.9800
63.835764340, 23.970, 614.0, 24.7790
63.900962980, 23.970, 626.0, 25.0200
63.966161620, 23.970, 578.0, 24.0416
64.031360260, 23.970, 567.0, 23.8118
64.096558900, 23.970, 586.0, 24.2074
64.161757540, 23.970, 639.0, 25.2784
64.226956180, 23.970, 573.0, 23.9374
64.292154820, 23.970, 602.0, 24.5357
64.357353460, 23.970, 656.0, 25.6125
64.422552100, 23.970, 740.0, 27.2029
64.487750740, 23.970, 807.0, 28.4077
64.552949380, 23.970, 781.0, 27.9464
64.618148020, 23.970, 774.0, 27.8209
64.683346660, 23.970, 749.0, 27.3679
64.748545300, 23.970, 754.0, 27.4591
64.813743940, 23.970, 746.0, 27.3130
64.878942580, 23.970, 687.0, 26.2107
64.944141220, 23.970, 707.0, 26.5895
65.009339860, 23.970, 759.0, 27.5500
65.074538500, 23.970, 737.0, 27.1477
65.139737140, 23.970, 702.0, 26.4953
65.204935780, 23.970, 685.0, 26.1725
65.270134420, 23.970, 666.0, 25.8070
65.335333060, 23.970, 665.0, 25.7876
65.400531700, 23.970, 677.0, 26.0192
65.465730340, 23.970, 702.0, 26.4953
65.530928980, 23.970, 691.0, 26.2869
65.596127620, 23.970, 655.0, 25.5930
65.661326260, 23.970, 646.0, 25.4165
65.726524900, 23.970, 588.0, 24.2487
65.791723540, 23.970, 643.0, 25.3574
65.856922180, 23.970, 566.0, 23.7908
65.922120820, 23.970, 628.0, 25.0599
65.987319460, 23.970, 584.0, 24.1661
66.052518100, 23.970, 583.0, 24.1454
66.117716740, 23.970, 590.0, 24.2899
66.182915380, 23.970, 603.0, 24.5561
66.248114020, 23.970, 588.0, 24.2487
66.313312660, 23.970, 553.0, 23.5160
66.378511300, 23.970, 563.0, 23.7276
66.443709940, 23.970, 592.0, 24.3311
66.508908580, 23.970, 574.0, 23.9583
66.574107220, 23.970, 582.0, 24.1247
66.639305860, 23.970, 610.0, 24.6982
66.704504500, 23.970, 621.0, 24.9199
66.769703140, 23.970, 547.0, 23.3880
66.834901780, 23.970, 607.0, 24.6374
66.900100420, 23.970, 581.0, 24.1039
66.965299060, 23.970, 560.0, 23.6643
67.030497700, 23.970, 596.0, 24.4131
67.095696340, 23.970, 595.0, 24.3926
67.160894980, 23.970, 575.0, 23.9792
67.226093620, 23.970, 566.0, 23.7908
67.291292260, 23.970, 588.0, 24.2487
67.356490900, 23.970, 574.0, 23.9583
67.421689540, 23.970, 588.0, 24.2487
67.486888180, 23.970, 647.0, 25.4362
67.552086820, 23.970, 637.0, 25.2389
67.617285460, 23.970, 650.0, 25.4951
67.682484100, 23.970, 682.0, 26.1151
67.747682740, 23.970, 669.0, 25.8650
67.812881380, 23.970, 683.0, 26.1343
67.878080020, 23.970, 719.0, 26.8142
67.943278660, 23.970, 724.0, 26.9072
68.008477300, 23.970, 668.0, 25.8457
68.073675940, 23.970, 708.0, 26.6083
68.138874580, 23.970, 713.0, 26.7021
68.204073220, 23.970, 673.0, 25.9422
68.269271860, 23.970, 646.0, 25.4165
68.334470500, 23.970, 668.0, 25.8457
68.399669140, 23.970, 636.0, 25.2190
68.464867780, 23.970, 674.0, 25.9615
68.530066420, 23.970, 626.0, 25.0200
68.595265060, 23.970, 608.0, 24.6577
68.660463700, 23.970, 586.0, 24.2074
68.725662340, 23.970, 565.0, 23.7697
68.790860980, 23.970, 595.0, 24.3926
68.856059620, 23.970, 595.0, 24.3926
68.921258260, 23.970, 578.0, 24.0416
68.986456900, 23.970, 586.0, 24.2074
69.051655540, 23.970, 585.0, 24.1868
69.116854180, 23.970, 596.0, 24.4131
69.182052820, 23.970, 577.0, 24.0208
69.247251460, 23.970, 617.0, 24.8395
69.312450100, 23.970, 605.0, 24.5967
69.377648740, 23.970, 595.0, 24.3926
69.442847380, 23.970, 509.0, 22.5610
69.508046020, 23.970, 557.0, 23.6008
69.573244660, 23.970, 554.0, 23.5372
69.638443300, 23.970, 563.0, 23.7276
69.703641940, 23.970, 571.0, 23.8956
69.768840580, 23.970, 563.0, 23.7276
69.834039220, 23.970, 537.0, 23.1733
69.899237860, 23.970, 533.0, 23.0868
69.964436500, 23.970, 620.0, 24.8998
70.029635140, 23.970, 584.0, 24.1661
70.094833780, 23.970, 617.0, 24.8395
70.160032420, 23.970, 577.0, 24.0208
70.225231060, 23.970, 569.0, 23.8537
70.290429700, 23.970, 588.0, 24.2487
70.355628340, 23.970, 565.0, 23.7697
70.420826980, 23.970, 530.0, 23.0217
70.486025620, 23.970, 605.0, 24.5967
70.551224260, 23.970, 524.0, 22.8910
70.616422900, 23.970, 505.0, 22.4722
70.681621540, 23.970, 554.0, 23.5372
70.746820180, 23.970, 521.0, 22.8254
70.812018820, 23.970, 541.0, 23.2594
70.877217460, 23.970, 551.0, 23.4734
70.942416100, 23.970, 565.0, 23.7697
71.007614740, 23.970, 530.0, 23.0217
71.072813380, 23.970, 564.0, 23.7487
71.138012020, 23.970, 530.0, 23.0217
71.203210660, 23.970, 544.0, 23.3238
71.268409300, 23.970, 539.0, 23.2164
71.333607940, 23.970, 500.0, 22.3607
71.398806580, 23.970, 513.0, 22.6495
71.464005220, 23.970, 548.0, 23.4094
71.529203860, 23.970, 538.0, 23.1948
71.594402500, 23.970, 550.0, 23.4521
71.659601140, 23.970, 517.0, 22.7376
71.724799780, 23.970, 549.0, 23.4307
71.789998420, 23.970, 524.0, 22.8910
71.855197060, 23.970, 526.0, 22.9347
71.920395700, 23.970, 536.0, 23.1517
71.985594340, 23.970, 549.0, 23.4307
72.050792980, 23.970, 501.0, 22.3830
72.115991620, 23.970, 568.0, 23.8328
72.181190260, 23.970, 501.0, 22.3830
72.246388900, 23.970, 564.0, 23.7487
72.311587540, 23.970, 536.0, 23.1517
72.376786180, 23.970, 548.0, 23.4094
72.441984820, 23.970, 577.0, 24.0208
72.507183460, 23.970, 587.0, 24.2281
72.572382100, 23.970, 597.0, 24.4336
72.637580740, 23.970, 587.0, 24.2281
72.702779380, 23.970, 631.0, 25.1197
72.767978020, 23.970, 658.0, 25.6515
72.833176660, 23.970, 646.0, 25.4165
72.898375300, 23.970, 676.0, 26.0000
72.963573940, 23.970, 628.0, 25.0599
73.028772580, 23.970, 640.0, 25.2982
73.093971220, 23.970, 661.0, 25.7099
73.159169860, 23.970, 630.0, 25.0998
73.224368500, 23.970, 656.0, 25.6125
73.289567140, 23.970, 656.0, 25.6125
73.354765780, 23.970, 621.0, 24.9199
73.419964420, 23.970, 645.0, 25.3969
73.485163060, 23.970, 695.0, 26.3629
73.550361700, 23.970, 688.0, 26.2298
73.615560340, 23.970, 606.0, 24.6171
73.680758980, 23.970, 653.0, 25.5539
73.745957620, 23.970, 627.0, 25.0400
73.811156260, 23.970, 594.0, 24.3721
73.876354900, 23.970, 607.0, 24.6374
73.941553540, 23.970, 589.0, 24.2693
74.006752180, 23.970, 604.0, 24.5764
74.071950820, 23.970, 605.0, 24.5967
74.137149460, 23.970, 580.0, 24.0832
74.202348100, 23.970, 622.0, 24.9399
74.267546740, 23.970, 673.0, 25.9422
74.332745380, 23.970, 646.0, 25.4165
74.397944020, 23.970, 705.0, 26.5518
74.463142660, 23.970, 685.0, 26.1725
74.528341300, 23.970, 655.0, 25.5930
74.593539940, 23.970, 685.0, 26.1725
74.658738580, 23.970, 723.0, 26.8887
74.723937220, 23.970, 690.0, 26.2679
74.789135860, 23.970, 726.0, 26.9444
74.854334500, 23.970, 676.0, 26.0000
74.919533140, 23.970, 643.0, 25.3574
74.984731780, 23.970, 646.0, 25.4165
75.049930420, 23.970, 655.0, 25.5930
75.115129060, 23.970, 660.0, 25.6905
75.180327700, 23.970, 590.0, 24.2899
75.245526340, 23.970, 606.0, 24.6171
75.310724980, 23.970, 549.0, 23.4307
75.375923620, 23.970, 604.0, 24.5764
75.441122260, 23.970, 592.0, 24.3311
75.506320900, 23.970, 531.0, 23.0434
75.571519540, 23.970, 588.0, 24.2487
75.636718180, 23.970, 606.0, 24.6171
75.701916820, 23.970, 556.0, 23.5797
75.767115460, 23.970, 520.0, 22.8035
75.832314100, 23.970, 582.0, 24.1247
75.897512740, 23.970, 588.0, 24.2487
75.962711380, 23.970, 596.0, 24.4131
76.027910020, 23.970, 582.0, 24.1247
76.093108660, 23.970, 571.0, 23.8956
76.158307300, 23.970, 578.0, 24.0416
76.223505940, 23.970, 566.0, 23.7908
76.288704580, 23.970, 562.0, 23.7065
76.353903220, 23.970, 572.0, 23.9165
76.419101860, 23.970, 581.0, 24.1039
76.484300500, 23.970, 544.0, 23.3238
76.549499140, 23.970, 589.0, 24.2693
76.614697780, 23.970, 563.0, 23.7276
76.679896420, 23.970, 617.0, 24.8395
76.745095060, 23.970, 590.0, 24.2899
76.810293700, 23.970, 599.0, 24.4745
76.875492340, 23.970, 633.0, 25.1595
76.940690980, 23.970, 608.0, 24.6577
77.005889620, 23.970, 658.0, 25.6515
77.071088260, 23.970, 700.0, 26.4575
77.136286900, 23.970, 662.0, 25.7294
77.201485540, 23.970, 637.0, 25.2389
77.266684180, 23.970, 654.0, 25.5734
77.331882820, 23.970, 679.0, 26.0576
77.397081460, 23.970, 672.0, 25.9230
77.462280100, 23.970, 688.0, 26.2298
77.527478740, 23.970, 664.0, 25.7682
77.592677380, 23.970, 678.0, 26.0384
77.657876020, 23.970, 653.0, 25.5539
77.723074660, 23.970, 686.0, 26.1916
77.788273300, 23.970, 594.0, 24.3721
77.853471940, 23.970, 607.0, 24.6374
77.918670580, 23.970, 516.0, 22.7156
77.983869220, 23.970, 571.0, 23.8956
78.049067860, 23.970, 574.0, 23.9583
78.114266500, 23.970, 633.0, 25.1595
78.179465140, 23.970, 596.0, 24.4131
78.244663780, 23.970, 587.0, 24.2281
78.309862420, 23.970, 642.0, 25.3377
78.375061060, 23.970, 641.0, 25.3180
78.440259700, 23.970, 651.0, 25.5147
78.505458340, 23.970, 631.0, 25.1197
78.570656980, 23.970, 655.0, 25.5930
78.635855620, 23.970, 692.0, 26.3059
78.701054260, 23.970, 694.0, 26.3439
78.766252900, 23.970, 691.0, 26.2869
78.831451540, 23.970, 702.0, 26.4953
78.896650180, 23.970, 701.0, 26.4764
78.961848820, 23.970, 702.0, 26.4953
79.027047460, 23.970, 716.0, 26.7582
79.092246100, 23.970, 705.0, 26.5518
79.157444740, 23.970, 683.0, 26.1343
79.222643380, 23.970, 681.0, 26.0960
79.287842020, 23.970, 634.0, 25.1794
79.353040660, 23.970, 625.0, 25.0000
79.418239300, 23.970, 654.0, 25.5734
79.483437940, 23.970, 647.0, 25.4362
79.548636580, 23.970, 574.0, 23.9583
79.613835220, 23.970, 613.0, 24.7588
79.679033860, 23.970, 601.0, 24.5153
79.744232500, 23.970, 625.0, 25.0000
79.809431140, 23.970, 575.0, 23.9792
79.874629780, 23.970, 588.0, 24.2487
79.939828420, 23.970, 623.0, 24.9600
79.994160620, 23.970, 597.0, 24.4336