File: data/DSC/HDPE_3.csv
[Measurement conditions]
Sample identification,HDPE_3
Comment,
Anode material,Cu
K-Alpha1 wavelength,1.5405980
K-Alpha2 wavelength,1.5444260
Ratio K-Alpha2/K-Alpha1,0.500
Divergence slit,Fixed,0.38mm
Monochromator used,NO
Generator voltage, 40
Tube current, 15
File date and time,02/Apr/2025 11:13
Unit cell,
h k l, 0 0 0
Scan axis,Gonio
Scan range,5.002000000,49.999928040
Scan step size,0.0108664
No. of points, 4141
Scan type,CONTINUOUS
Time per step,23.970
[Scan points]
Angle, TimePerStep, Intensity, ESD
5.007433220, 23.970, 1390.0, 37.2827
5.050898980, 23.970, 1400.0, 37.4166
5.094364740, 23.970, 1448.0, 38.0526
5.137830500, 23.970, 1356.0, 36.8239
5.181296260, 23.970, 1535.0, 39.1791
5.224762020, 23.970, 1476.0, 38.4187
5.268227780, 23.970, 1491.0, 38.6135
5.311693540, 23.970, 1517.0, 38.9487
5.355159300, 23.970, 1507.0, 38.8201
5.398625060, 23.970, 1436.0, 37.8946
5.442090820, 23.970, 1570.0, 39.6232
5.485556580, 23.970, 1545.0, 39.3065
5.529022340, 23.970, 1622.0, 40.2741
5.572488100, 23.970, 1563.0, 39.5348
5.615953860, 23.970, 1642.0, 40.5216
5.659419620, 23.970, 1744.0, 41.7612
5.702885380, 23.970, 1693.0, 41.1461
5.746351140, 23.970, 1637.0, 40.4599
5.789816900, 23.970, 1755.0, 41.8927
5.833282660, 23.970, 1748.0, 41.8091
5.876748420, 23.970, 1735.0, 41.6533
5.920214180, 23.970, 1809.0, 42.5323
5.963679940, 23.970, 1843.0, 42.9302
6.007145700, 23.970, 1804.0, 42.4735
6.050611460, 23.970, 1862.0, 43.1509
6.094077220, 23.970, 1802.0, 42.4500
6.137542980, 23.970, 1857.0, 43.0929
6.181008740, 23.970, 1837.0, 42.8602
6.224474500, 23.970, 1954.0, 44.2041
6.267940260, 23.970, 1974.0, 44.4297
6.311406020, 23.970, 2036.0, 45.1221
6.354871780, 23.970, 1978.0, 44.4747
6.398337540, 23.970, 1995.0, 44.6654
6.441803300, 23.970, 1996.0, 44.6766
6.485269060, 23.970, 2127.0, 46.1194
6.528734820, 23.970, 2064.0, 45.4313
6.572200580, 23.970, 2040.0, 45.1664
6.615666340, 23.970, 2013.0, 44.8665
6.659132100, 23.970, 2121.0, 46.0543
6.702597860, 23.970, 2089.0, 45.7056
6.746063620, 23.970, 2035.0, 45.1110
6.789529380, 23.970, 2118.0, 46.0217
6.832995140, 23.970, 2124.0, 46.0869
6.876460900, 23.970, 2140.0, 46.2601
6.919926660, 23.970, 2216.0, 47.0744
6.963392420, 23.970, 2122.0, 46.0652
7.006858180, 23.970, 2129.0, 46.1411
7.050323940, 23.970, 2094.0, 45.7602
7.093789700, 23.970, 2219.0, 47.1063
7.137255460, 23.970, 2261.0, 47.5500
7.180721220, 23.970, 2228.0, 47.2017
7.224186980, 23.970, 2384.0, 48.8262
7.267652740, 23.970, 2285.0, 47.8017
7.311118500, 23.970, 2209.0, 47.0000
7.354584260, 23.970, 2238.0, 47.3075
7.398050020, 23.970, 2240.0, 47.3286
7.441515780, 23.970, 2281.0, 47.7598
7.484981540, 23.970, 2321.0, 48.1768
7.528447300, 23.970, 2261.0, 47.5500
7.571913060, 23.970, 2350.0, 48.4768
7.615378820, 23.970, 2319.0, 48.1560
7.658844580, 23.970, 2351.0, 48.4871
7.702310340, 23.970, 2355.0, 48.5283
7.745776100, 23.970, 2311.0, 48.0729
7.789241860, 23.970, 2332.0, 48.2908
7.832707620, 23.970, 2431.0, 49.3052
7.876173380, 23.970, 2304.0, 48.0000
7.919639140, 23.970, 2394.0, 48.9285
7.963104900, 23.970, 2306.0, 48.0208
8.006570660, 23.970, 2376.0, 48.7442
8.050036420, 23.970, 2408.0, 49.0714
8.093502180, 23.970, 2532.0, 50.3190
8.136967940, 23.970, 2397.0, 48.9592
8.180433700, 23.970, 2423.0, 49.2240
8.223899460, 23.970, 2468.0, 49.6790
8.267365220, 23.970, 2532.0, 50.3190
8.310830980, 23.970, 2464.0, 49.6387
8.354296740, 23.970, 2464.0, 49.6387
8.397762500, 23.970, 2491.0, 49.9099
8.441228260, 23.970, 2509.0, 50.0899
8.484694020, 23.970, 2482.0, 49.8197
8.528159780, 23.970, 2484.0, 49.8397
8.571625540, 23.970, 2498.0, 49.9800
8.615091300, 23.970, 2451.0, 49.5076
8.658557060, 23.970, 2582.0, 50.8134
8.702022820, 23.970, 2439.0, 49.3862
8.745488580, 23.970, 2408.0, 49.0714
8.788954340, 23.970, 2499.0, 49.9900
8.832420100, 23.970, 2457.0, 49.5681
8.875885860, 23.970, 2471.0, 49.7092
8.919351620, 23.970, 2518.0, 50.1797
8.962817380, 23.970, 2372.0, 48.7032
9.006283140, 23.970, 2508.0, 50.0799
9.049748900, 23.970, 2517.0, 50.1697
9.093214660, 23.970, 2574.0, 50.7346
9.136680420, 23.970, 2445.0, 49.4469
9.180146180, 23.970, 2488.0, 49.8799
9.223611940, 23.970, 2427.0, 49.2646
9.267077700, 23.970, 2438.0, 49.3761
9.310543460, 23.970, 2481.0, 49.8096
9.354009220, 23.970, 2492.0, 49.9199
9.397474980, 23.970, 2456.0, 49.5580
9.440940740, 23.970, 2475.0, 49.7494
9.484406500, 23.970, 2471.0, 49.7092
9.527872260, 23.970, 2455.0, 49.5480
9.571338020, 23.970, 2407.0, 49.0612
9.614803780, 23.970, 2374.0, 48.7237
9.658269540, 23.970, 2465.0, 49.6488
9.701735300, 23.970, 2464.0, 49.6387
9.745201060, 23.970, 2472.0, 49.7192
9.788666820, 23.970, 2430.0, 49.2950
9.832132580, 23.970, 2447.0, 49.4672
9.875598340, 23.970, 2428.0, 49.2747
9.919064100, 23.970, 2426.0, 49.2544
9.962529860, 23.970, 2483.0, 49.8297
10.005995620, 23.970, 2388.0, 48.8672
10.049461380, 23.970, 2375.0, 48.7340
10.092927140, 23.970, 2299.0, 47.9479
10.136392900, 23.970, 2350.0, 48.4768
10.179858660, 23.970, 2429.0, 49.2849
10.223324420, 23.970, 2325.0, 48.2183
10.266790180, 23.970, 2452.0, 49.5177
10.310255940, 23.970, 2290.0, 47.8539
10.353721700, 23.970, 2311.0, 48.0729
10.397187460, 23.970, 2223.0, 47.1487
10.440653220, 23.970, 2290.0, 47.8539
10.484118980, 23.970, 2391.0, 48.8979
10.527584740, 23.970, 2436.0, 49.3559
10.571050500, 23.970, 2261.0, 47.5500
10.614516260, 23.970, 2357.0, 48.5489
10.657982020, 23.970, 2238.0, 47.3075
10.701447780, 23.970, 2204.0, 46.9468
10.744913540, 23.970, 2251.0, 47.4447
10.788379300, 23.970, 2348.0, 48.4562
10.831845060, 23.970, 2207.0, 46.9787
10.875310820, 23.970, 2274.0, 47.6865
10.918776580, 23.970, 2308.0, 48.0416
10.962242340, 23.970, 2305.0, 48.0104
11.005708100, 23.970, 2372.0, 48.7032
11.049173860, 23.970, 2265.0, 47.5920
11.092639620, 23.970, 2228.0, 47.2017
11.136105380, 23.970, 2308.0, 48.0416
11.179571140, 23.970, 2278.0, 47.7284
11.223036900, 23.970, 2332.0, 48.2908
11.266502660, 23.970, 2111.0, 45.9456
11.309968420, 23.970, 2183.0, 46.7226
11.353434180, 23.970, 2138.0, 46.2385
11.396899940, 23.970, 2188.0, 46.7761
11.440365700, 23.970, 2165.0, 46.5296
11.483831460, 23.970, 2161.0, 46.4866
11.527297220, 23.970, 2157.0, 46.4435
11.570762980, 23.970, 2096.0, 45.7821
11.614228740, 23.970, 2143.0, 46.2925
11.657694500, 23.970, 2071.0, 45.5082
11.701160260, 23.970, 2159.0, 46.4650
11.744626020, 23.970, 2203.0, 46.9361
11.788091780, 23.970, 2060.0, 45.3872
11.831557540, 23.970, 2073.0, 45.5302
11.875023300, 23.970, 2076.0, 45.5631
11.918489060, 23.970, 2031.0, 45.0666
11.961954820, 23.970, 1988.0, 44.5870
12.005420580, 23.970, 2088.0, 45.6946
12.048886340, 23.970, 2035.0, 45.1110
12.092352100, 23.970, 2046.0, 45.2327
12.135817860, 23.970, 2004.0, 44.7661
12.179283620, 23.970, 1971.0, 44.3959
12.222749380, 23.970, 2089.0, 45.7056
12.266215140, 23.970, 2068.0, 45.4753
12.309680900, 23.970, 1988.0, 44.5870
12.353146660, 23.970, 1998.0, 44.6990
12.396612420, 23.970, 2012.0, 44.8553
12.440078180, 23.970, 1924.0, 43.8634
12.483543940, 23.970, 2041.0, 45.1774
12.527009700, 23.970, 2058.0, 45.3652
12.570475460, 23.970, 2041.0, 45.1774
12.613941220, 23.970, 2052.0, 45.2990
12.657406980, 23.970, 2074.0, 45.5412
12.700872740, 23.970, 2042.0, 45.1885
12.744338500, 23.970, 2086.0, 45.6727
12.787804260, 23.970, 1997.0, 44.6878
12.831270020, 23.970, 1934.0, 43.9773
12.874735780, 23.970, 1971.0, 44.3959
12.918201540, 23.970, 2010.0, 44.8330
12.961667300, 23.970, 1902.0, 43.6119
13.005133060, 23.970, 2009.0, 44.8219
13.048598820, 23.970, 1991.0, 44.6206
13.092064580, 23.970, 1915.0, 43.7607
13.135530340, 23.970, 1965.0, 44.3283
13.178996100, 23.970, 2050.0, 45.2769
13.222461860, 23.970, 1993.0, 44.6430
13.265927620, 23.970, 1928.0, 43.9090
13.309393380, 23.970, 1998.0, 44.6990
13.352859140, 23.970, 1915.0, 43.7607
13.396324900, 23.970, 1862.0, 43.1509
13.439790660, 23.970, 1914.0, 43.7493
13.483256420, 23.970, 1943.0, 44.0795
13.526722180, 23.970, 1985.0, 44.5533
13.570187940, 23.970, 1981.0, 44.5084
13.613653700, 23.970, 1828.0, 42.7551
13.657119460, 23.970, 1885.0, 43.4166
13.700585220, 23.970, 1911.0, 43.7150
13.744050980, 23.970, 1942.0, 44.0681
13.787516740, 23.970, 1917.0, 43.7836
13.830982500, 23.970, 1978.0, 44.4747
13.874448260, 23.970, 1967.0, 44.3509
13.917914020, 23.970, 2028.0, 45.0333
13.961379780, 23.970, 1975.0, 44.4410
14.004845540, 23.970, 1885.0, 43.4166
14.048311300, 23.970, 1985.0, 44.5533
14.091777060, 23.970, 1995.0, 44.6654
14.135242820, 23.970, 1935.0, 43.9886
14.178708580, 23.970, 1926.0, 43.8862
14.222174340, 23.970, 1987.0, 44.5758
14.265640100, 23.970, 1982.0, 44.5197
14.309105860, 23.970, 2012.0, 44.8553
14.352571620, 23.970, 1985.0, 44.5533
14.396037380, 23.970, 2102.0, 45.8476
14.439503140, 23.970, 1949.0, 44.1475
14.482968900, 23.970, 2035.0, 45.1110
14.526434660, 23.970, 2085.0, 45.6618
14.569900420, 23.970, 2049.0, 45.2659
14.613366180, 23.970, 2074.0, 45.5412
14.656831940, 23.970, 2053.0, 45.3100
14.700297700, 23.970, 1999.0, 44.7102
14.743763460, 23.970, 2116.0, 46.0000
14.787229220, 23.970, 2050.0, 45.2769
14.830694980, 23.970, 2133.0, 46.1844
14.874160740, 23.970, 2090.0, 45.7165
14.917626500, 23.970, 2093.0, 45.7493
14.961092260, 23.970, 2110.0, 45.9347
15.004558020, 23.970, 2127.0, 46.1194
15.048023780, 23.970, 2147.0, 46.3357
15.091489540, 23.970, 2168.0, 46.5618
15.134955300, 23.970, 2166.0, 46.5403
15.178421060, 23.970, 2133.0, 46.1844
15.221886820, 23.970, 2155.0, 46.4220
15.265352580, 23.970, 2190.0, 46.7974
15.308818340, 23.970, 2138.0, 46.2385
15.352284100, 23.970, 2179.0, 46.6798
15.395749860, 23.970, 2212.0, 47.0319
15.439215620, 23.970, 2219.0, 47.1063
15.482681380, 23.970, 2290.0, 47.8539
15.526147140, 23.970, 2218.0, 47.0956
15.569612900, 23.970, 2185.0, 46.7440
15.613078660, 23.970, 2231.0, 47.2335
15.656544420, 23.970, 2330.0, 48.2701
15.700010180, 23.970, 2305.0, 48.0104
15.743475940, 23.970, 2337.0, 48.3425
15.786941700, 23.970, 2363.0, 48.6107
15.830407460, 23.970, 2307.0, 48.0312
15.873873220, 23.970, 2255.0, 47.4868
15.917338980, 23.970, 2315.0, 48.1144
15.960804740, 23.970, 2355.0, 48.5283
16.004270500, 23.970, 2392.0, 48.9081
16.047736260, 23.970, 2372.0, 48.7032
16.091202020, 23.970, 2375.0, 48.7340
16.134667780, 23.970, 2484.0, 49.8397
16.178133540, 23.970, 2491.0, 49.9099
16.221599300, 23.970, 2510.0, 50.0999
16.265065060, 23.970, 2553.0, 50.5272
16.308530820, 23.970, 2539.0, 50.3885
16.351996580, 23.970, 2614.0, 51.1273
16.395462340, 23.970, 2548.0, 50.4777
16.438928100, 23.970, 2642.0, 51.4004
16.482393860, 23.970, 2565.0, 50.6458
16.525859620, 23.970, 2607.0, 51.0588
16.569325380, 23.970, 2635.0, 51.3323
16.612791140, 23.970, 2713.0, 52.0865
16.656256900, 23.970, 2698.0, 51.9423
16.699722660, 23.970, 2632.0, 51.3030
16.743188420, 23.970, 2726.0, 52.2111
16.786654180, 23.970, 2804.0, 52.9528
16.830119940, 23.970, 2765.0, 52.5833
16.873585700, 23.970, 2836.0, 53.2541
16.917051460, 23.970, 2797.0, 52.8867
16.960517220, 23.970, 2959.0, 54.3967
17.003982980, 23.970, 2831.0, 53.2071
17.047448740, 23.970, 2969.0, 54.4885
17.090914500, 23.970, 3039.0, 55.1271
17.134380260, 23.970, 2979.0, 54.5802
17.177846020, 23.970, 3116.0, 55.8211
17.221311780, 23.970, 3112.0, 55.7853
17.264777540, 23.970, 3075.0, 55.4527
17.308243300, 23.970, 3230.0, 56.8331
17.351709060, 23.970, 3174.0, 56.3383
17.395174820, 23.970, 3336.0, 57.7581
17.438640580, 23.970, 3341.0, 57.8014
17.482106340, 23.970, 3368.0, 58.0345
17.525572100, 23.970, 3404.0, 58.3438
17.569037860, 23.970, 3419.0, 58.4722
17.612503620, 23.970, 3463.0, 58.8473
17.655969380, 23.970, 3483.0, 59.0169
17.699435140, 23.970, 3619.0, 60.1581
17.742900900, 23.970, 3663.0, 60.5227
17.786366660, 23.970, 3594.0, 59.9500
17.829832420, 23.970, 3665.0, 60.5392
17.873298180, 23.970, 3773.0, 61.4248
17.916763940, 23.970, 3674.0, 60.6135
17.960229700, 23.970, 3716.0, 60.9590
18.003695460, 23.970, 3867.0, 62.1852
18.047161220, 23.970, 3832.0, 61.9032
18.090626980, 23.970, 3867.0, 62.1852
18.134092740, 23.970, 4064.0, 63.7495
18.177558500, 23.970, 4017.0, 63.3798
18.221024260, 23.970, 4060.0, 63.7181
18.264490020, 23.970, 3998.0, 63.2297
18.307955780, 23.970, 4144.0, 64.3739
18.351421540, 23.970, 4182.0, 64.6684
18.394887300, 23.970, 4417.0, 66.4605
18.438353060, 23.970, 4405.0, 66.3702
18.481818820, 23.970, 4274.0, 65.3758
18.525284580, 23.970, 4365.0, 66.0681
18.568750340, 23.970, 4487.0, 66.9851
18.612216100, 23.970, 4462.0, 66.7982
18.655681860, 23.970, 4589.0, 67.7422
18.699147620, 23.970, 4725.0, 68.7386
18.742613380, 23.970, 4585.0, 67.7126
18.786079140, 23.970, 4801.0, 69.2892
18.829544900, 23.970, 4777.0, 69.1158
18.873010660, 23.970, 4890.0, 69.9285
18.916476420, 23.970, 4890.0, 69.9285
18.959942180, 23.970, 5090.0, 71.3442
19.003407940, 23.970, 5036.0, 70.9648
19.046873700, 23.970, 5193.0, 72.0625
19.090339460, 23.970, 5253.0, 72.4776
19.133805220, 23.970, 5250.0, 72.4569
19.177270980, 23.970, 5236.0, 72.3602
19.220736740, 23.970, 5306.0, 72.8423
19.264202500, 23.970, 5441.0, 73.7631
19.307668260, 23.970, 5565.0, 74.5989
19.351134020, 23.970, 5554.0, 74.5252
19.394599780, 23.970, 5530.0, 74.3640
19.438065540, 23.970, 5705.0, 75.5315
19.481531300, 23.970, 5584.0, 74.7262
19.524997060, 23.970, 5689.0, 75.4255
19.568462820, 23.970, 5621.0, 74.9733
19.611928580, 23.970, 5865.0, 76.5833
19.655394340, 23.970, 5971.0, 77.2722
19.698860100, 23.970, 5772.0, 75.9737
19.742325860, 23.970, 5854.0, 76.5114
19.785791620, 23.970, 5940.0, 77.0714
19.829257380, 23.970, 5913.0, 76.8960
19.872723140, 23.970, 5935.0, 77.0390
19.916188900, 23.970, 5839.0, 76.4133
19.959654660, 23.970, 6049.0, 77.7753
20.003120420, 23.970, 5993.0, 77.4145
20.046586180, 23.970, 5831.0, 76.3610
20.090051940, 23.970, 5913.0, 76.8960
20.133517700, 23.970, 6114.0, 78.1921
20.176983460, 23.970, 6090.0, 78.0385
20.220449220, 23.970, 6001.0, 77.4661
20.263914980, 23.970, 6025.0, 77.6209
20.307380740, 23.970, 6215.0, 78.8353
20.350846500, 23.970, 6218.0, 78.8543
20.394312260, 23.970, 6335.0, 79.5927
20.437778020, 23.970, 6322.0, 79.5110
20.481243780, 23.970, 6397.0, 79.9812
20.524709540, 23.970, 6481.0, 80.5047
20.568175300, 23.970, 6744.0, 82.1219
20.611641060, 23.970, 6774.0, 82.3043
20.655106820, 23.970, 7025.0, 83.8153
20.698572580, 23.970, 7010.0, 83.7257
20.742038340, 23.970, 7190.0, 84.7939
20.785504100, 23.970, 7533.0, 86.7929
20.828969860, 23.970, 7971.0, 89.2805
20.872435620, 23.970, 8346.0, 91.3564
20.915901380, 23.970, 8876.0, 94.2125
20.959367140, 23.970, 9654.0, 98.2548
21.002832900, 23.970, 10430.0, 102.1274
21.046298660, 23.970, 12035.0, 109.7041
21.089764420, 23.970, 13550.0, 116.4045
21.133230180, 23.970, 15686.0, 125.2438
21.176695940, 23.970, 18073.0, 134.4359
21.220161700, 23.970, 20476.0, 143.0944
21.263627460, 23.970, 23333.0, 152.7514
21.307093220, 23.970, 25974.0, 161.1645
21.350558980, 23.970, 28559.0, 168.9941
21.394024740, 23.970, 32305.0, 179.7359
21.437490500, 23.970, 36429.0, 190.8638
21.480956260, 23.970, 41279.0, 203.1723
21.524422020, 23.970, 46775.0, 216.2753
21.567887780, 23.970, 53301.0, 230.8701
21.611353540, 23.970, 59036.0, 242.9732
21.654819300, 23.970, 65163.0, 255.2704
21.698285060, 23.970, 69769.0, 264.1382
21.741750820, 23.970, 72303.0, 268.8922
21.785216580, 23.970, 71171.0, 266.7789
21.828682340, 23.970, 65416.0, 255.7655
21.872148100, 23.970, 55287.0, 235.1319
21.915613860, 23.970, 42921.0, 207.1738
21.959079620, 23.970, 31232.0, 176.7258
22.002545380, 23.970, 21941.0, 148.1249
22.046011140, 23.970, 15861.0, 125.9405
22.089476900, 23.970, 12386.0, 111.2924
22.132942660, 23.970, 9886.0, 99.4284
22.176408420, 23.970, 8453.0, 91.9402
22.219874180, 23.970, 7519.0, 86.7122
22.263339940, 23.970, 6885.0, 82.9759
22.306805700, 23.970, 6292.0, 79.3221
22.350271460, 23.970, 5713.0, 75.5844
22.393737220, 23.970, 5477.0, 74.0068
22.437202980, 23.970, 5259.0, 72.5190
22.480668740, 23.970, 5288.0, 72.7186
22.524134500, 23.970, 4989.0, 70.6329
22.567600260, 23.970, 4885.0, 69.8928
22.611066020, 23.970, 4768.0, 69.0507
22.654531780, 23.970, 4611.0, 67.9043
22.697997540, 23.970, 4554.0, 67.4833
22.741463300, 23.970, 4628.0, 68.0294
22.784929060, 23.970, 4403.0, 66.3551
22.828394820, 23.970, 4378.0, 66.1665
22.871860580, 23.970, 4328.0, 65.7875
22.915326340, 23.970, 4348.0, 65.9394
22.958792100, 23.970, 4384.0, 66.2118
23.002257860, 23.970, 4179.0, 64.6452
23.045723620, 23.970, 4280.0, 65.4217
23.089189380, 23.970, 4274.0, 65.3758
23.132655140, 23.970, 4342.0, 65.8939
23.176120900, 23.970, 4310.0, 65.6506
23.219586660, 23.970, 4407.0, 66.3852
23.263052420, 23.970, 4726.0, 68.7459
23.306518180, 23.970, 4658.0, 68.2495
23.349983940, 23.970, 4967.0, 70.4769
23.393449700, 23.970, 5322.0, 72.9520
23.436915460, 23.970, 5505.0, 74.1957
23.480381220, 23.970, 5805.0, 76.1906
23.523846980, 23.970, 6250.0, 79.0569
23.567312740, 23.970, 6665.0, 81.6395
23.610778500, 23.970, 7154.0, 84.5813
23.654244260, 23.970, 7639.0, 87.4014
23.697710020, 23.970, 7980.0, 89.3308
23.741175780, 23.970, 8484.0, 92.1086
23.784641540, 23.970, 8965.0, 94.6837
23.828107300, 23.970, 9782.0, 98.9040
23.871573060, 23.970, 10653.0, 103.2134
23.915038820, 23.970, 11321.0, 106.4002
23.958504580, 23.970, 11957.0, 109.3481
24.001970340, 23.970, 12174.0, 110.3359
24.045436100, 23.970, 12459.0, 111.6199
24.088901860, 23.970, 12538.0, 111.9732
24.132367620, 23.970, 12203.0, 110.4672
24.175833380, 23.970, 11501.0, 107.2427
24.219299140, 23.970, 10421.0, 102.0833
24.262764900, 23.970, 9145.0, 95.6295
24.306230660, 23.970, 7840.0, 88.5438
24.349696420, 23.970, 6705.0, 81.8841
24.393162180, 23.970, 5524.0, 74.3236
24.436627940, 23.970, 4643.0, 68.1396
24.480093700, 23.970, 4261.0, 65.2763
24.523559460, 23.970, 3705.0, 60.8687
24.567025220, 23.970, 3448.0, 58.7197
24.610490980, 23.970, 3181.0, 56.4004
24.653956740, 23.970, 3116.0, 55.8211
24.697422500, 23.970, 2806.0, 52.9717
24.740888260, 23.970, 2637.0, 51.3517
24.784354020, 23.970, 2650.0, 51.4782
24.827819780, 23.970, 2509.0, 50.0899
24.871285540, 23.970, 2529.0, 50.2892
24.914751300, 23.970, 2432.0, 49.3153
24.958217060, 23.970, 2417.0, 49.1630
25.001682820, 23.970, 2342.0, 48.3942
25.045148580, 23.970, 2387.0, 48.8569
25.088614340, 23.970, 2339.0, 48.3632
25.132080100, 23.970, 2278.0, 47.7284
25.175545860, 23.970, 2180.0, 46.6905
25.219011620, 23.970, 2109.0, 45.9239
25.262477380, 23.970, 2166.0, 46.5403
25.305943140, 23.970, 2150.0, 46.3681
25.349408900, 23.970, 2116.0, 46.0000
25.392874660, 23.970, 2119.0, 46.0326
25.436340420, 23.970, 2037.0, 45.1331
25.479806180, 23.970, 1983.0, 44.5309
25.523271940, 23.970, 1958.0, 44.2493
25.566737700, 23.970, 2085.0, 45.6618
25.610203460, 23.970, 2087.0, 45.6837
25.653669220, 23.970, 1985.0, 44.5533
25.697134980, 23.970, 1897.0, 43.5546
25.740600740, 23.970, 1958.0, 44.2493
25.784066500, 23.970, 1936.0, 44.0000
25.827532260, 23.970, 1850.0, 43.0116
25.870998020, 23.970, 1881.0, 43.3705
25.914463780, 23.970, 1817.0, 42.6263
25.957929540, 23.970, 1799.0, 42.4146
26.001395300, 23.970, 1841.0, 42.9069
26.044861060, 23.970, 1828.0, 42.7551
26.088326820, 23.970, 1873.0, 43.2782
26.131792580, 23.970, 1792.0, 42.3320
26.175258340, 23.970, 1738.0, 41.6893
26.218724100, 23.970, 1824.0, 42.7083
26.262189860, 23.970, 1820.0, 42.6615
26.305655620, 23.970, 1676.0, 40.9390
26.349121380, 23.970, 1686.0, 41.0609
26.392587140, 23.970, 1652.0, 40.6448
26.436052900, 23.970, 1674.0, 40.9145
26.479518660, 23.970, 1604.0, 40.0500
26.522984420, 23.970, 1639.0, 40.4846
26.566450180, 23.970, 1645.0, 40.5586
26.609915940, 23.970, 1706.0, 41.3038
26.653381700, 23.970, 1690.0, 41.1096
26.696847460, 23.970, 1658.0, 40.7185
26.740313220, 23.970, 1605.0, 40.0625
26.783778980, 23.970, 1579.0, 39.7366
26.827244740, 23.970, 1540.0, 39.2428
26.870710500, 23.970, 1509.0, 38.8458
26.914176260, 23.970, 1603.0, 40.0375
26.957642020, 23.970, 1580.0, 39.7492
27.001107780, 23.970, 1635.0, 40.4351
27.044573540, 23.970, 1466.0, 38.2884
27.088039300, 23.970, 1549.0, 39.3573
27.131505060, 23.970, 1508.0, 38.8330
27.174970820, 23.970, 1489.0, 38.5876
27.218436580, 23.970, 1489.0, 38.5876
27.261902340, 23.970, 1519.0, 38.9744
27.305368100, 23.970, 1411.0, 37.5633
27.348833860, 23.970, 1463.0, 38.2492
27.392299620, 23.970, 1489.0, 38.5876
27.435765380, 23.970, 1431.0, 37.8286
27.479231140, 23.970, 1455.0, 38.1445
27.522696900, 23.970, 1418.0, 37.6563
27.566162660, 23.970, 1422.0, 37.7094
27.609628420, 23.970, 1412.0, 37.5766
27.653094180, 23.970, 1352.0, 36.7696
27.696559940, 23.970, 1422.0, 37.7094
27.740025700, 23.970, 1379.0, 37.1349
27.783491460, 23.970, 1372.0, 37.0405
27.826957220, 23.970, 1403.0, 37.4566
27.870422980, 23.970, 1335.0, 36.5377
27.913888740, 23.970, 1345.0, 36.6742
27.957354500, 23.970, 1427.0, 37.7757
28.000820260, 23.970, 1410.0, 37.5500
28.044286020, 23.970, 1401.0, 37.4299
28.087751780, 23.970, 1444.0, 38.0000
28.131217540, 23.970, 1393.0, 37.3229
28.174683300, 23.970, 1361.0, 36.8917
28.218149060, 23.970, 1286.0, 35.8608
28.261614820, 23.970, 1279.0, 35.7631
28.305080580, 23.970, 1284.0, 35.8329
28.348546340, 23.970, 1353.0, 36.7831
28.392012100, 23.970, 1315.0, 36.2629
28.435477860, 23.970, 1350.0, 36.7423
28.478943620, 23.970, 1367.0, 36.9730
28.522409380, 23.970, 1262.0, 35.5246
28.565875140, 23.970, 1220.0, 34.9285
28.609340900, 23.970, 1372.0, 37.0405
28.652806660, 23.970, 1265.0, 35.5668
28.696272420, 23.970, 1391.0, 37.2961
28.739738180, 23.970, 1349.0, 36.7287
28.783203940, 23.970, 1366.0, 36.9594
28.826669700, 23.970, 1437.0, 37.9078
28.870135460, 23.970, 1659.0, 40.7308
28.913601220, 23.970, 1750.0, 41.8330
28.957066980, 23.970, 2033.0, 45.0888
29.000532740, 23.970, 1953.0, 44.1928
29.043998500, 23.970, 1788.0, 42.2847
29.087464260, 23.970, 1516.0, 38.9358
29.130930020, 23.970, 1326.0, 36.4143
29.174395780, 23.970, 1301.0, 36.0694
29.217861540, 23.970, 1274.0, 35.6931
29.261327300, 23.970, 1295.0, 35.9861
29.304793060, 23.970, 1331.0, 36.4829
29.348258820, 23.970, 1342.0, 36.6333
29.391724580, 23.970, 1259.0, 35.4824
29.435190340, 23.970, 1269.0, 35.6230
29.478656100, 23.970, 1380.0, 37.1484
29.522121860, 23.970, 1339.0, 36.5923
29.565587620, 23.970, 1339.0, 36.5923
29.609053380, 23.970, 1382.0, 37.1753
29.652519140, 23.970, 1471.0, 38.3536
29.695984900, 23.970, 1489.0, 38.5876
29.739450660, 23.970, 1466.0, 38.2884
29.782916420, 23.970, 1501.0, 38.7427
29.826382180, 23.970, 1647.0, 40.5832
29.869847940, 23.970, 1692.0, 41.1339
29.913313700, 23.970, 1563.0, 39.5348
29.956779460, 23.970, 1634.0, 40.4228
30.000245220, 23.970, 1693.0, 41.1461
30.043710980, 23.970, 1784.0, 42.2374
30.087176740, 23.970, 1761.0, 41.9643
30.130642500, 23.970, 1723.0, 41.5090
30.174108260, 23.970, 1841.0, 42.9069
30.217574020, 23.970, 1784.0, 42.2374
30.261039780, 23.970, 1813.0, 42.5793
30.304505540, 23.970, 1799.0, 42.4146
30.347971300, 23.970, 1635.0, 40.4351
30.391437060, 23.970, 1586.0, 39.8246
30.434902820, 23.970, 1408.0, 37.5233
30.478368580, 23.970, 1471.0, 38.3536
30.521834340, 23.970, 1338.0, 36.5787
30.565300100, 23.970, 1355.0, 36.8103
30.608765860, 23.970, 1246.0, 35.2987
30.652231620, 23.970, 1213.0, 34.8281
30.695697380, 23.970, 1217.0, 34.8855
30.739163140, 23.970, 1168.0, 34.1760
30.782628900, 23.970, 1132.0, 33.6452
30.826094660, 23.970, 1167.0, 34.1614
30.869560420, 23.970, 1166.0, 34.1467
30.913026180, 23.970, 1175.0, 34.2783
30.956491940, 23.970, 1128.0, 33.5857
30.999957700, 23.970, 1132.0, 33.6452
31.043423460, 23.970, 1215.0, 34.8569
31.086889220, 23.970, 1101.0, 33.1813
31.130354980, 23.970, 1075.0, 32.7872
31.173820740, 23.970, 1188.0, 34.4674
31.217286500, 23.970, 1142.0, 33.7935
31.260752260, 23.970, 1132.0, 33.6452
31.304218020, 23.970, 1062.0, 32.5883
31.347683780, 23.970, 1109.0, 33.3017
31.391149540, 23.970, 1061.0, 32.5730
31.434615300, 23.970, 1073.0, 32.7567
31.478081060, 23.970, 1092.0, 33.0454
31.521546820, 23.970, 1110.0, 33.3167
31.565012580, 23.970, 1129.0, 33.6006
31.608478340, 23.970, 1091.0, 33.0303
31.651944100, 23.970, 1110.0, 33.3167
31.695409860, 23.970, 1080.0, 32.8634
31.738875620, 23.970, 1104.0, 33.2265
31.782341380, 23.970, 1135.0, 33.6898
31.825807140, 23.970, 1101.0, 33.1813
31.869272900, 23.970, 1083.0, 32.9090
31.912738660, 23.970, 1070.0, 32.7109
31.956204420, 23.970, 1133.0, 33.6601
31.999670180, 23.970, 1076.0, 32.8024
32.043135940, 23.970, 1129.0, 33.6006
32.086601700, 23.970, 1147.0, 33.8674
32.130067460, 23.970, 1012.0, 31.8119
32.173533220, 23.970, 1059.0, 32.5423
32.216998980, 23.970, 1104.0, 33.2265
32.260464740, 23.970, 1059.0, 32.5423
32.303930500, 23.970, 1037.0, 32.2025
32.347396260, 23.970, 1130.0, 33.6155
32.390862020, 23.970, 1077.0, 32.8177
32.434327780, 23.970, 1000.0, 31.6228
32.477793540, 23.970, 1091.0, 33.0303
32.521259300, 23.970, 1088.0, 32.9848
32.564725060, 23.970, 1070.0, 32.7109
32.608190820, 23.970, 1024.0, 32.0000
32.651656580, 23.970, 1069.0, 32.6956
32.695122340, 23.970, 1059.0, 32.5423
32.738588100, 23.970, 1071.0, 32.7261
32.782053860, 23.970, 1099.0, 33.1512
32.825519620, 23.970, 1144.0, 33.8231
32.868985380, 23.970, 1135.0, 33.6898
32.912451140, 23.970, 1102.0, 33.1964
32.955916900, 23.970, 1116.0, 33.4066
32.999382660, 23.970, 1065.0, 32.6343
33.042848420, 23.970, 1072.0, 32.7414
33.086314180, 23.970, 1055.0, 32.4808
33.129779940, 23.970, 1044.0, 32.3110
33.173245700, 23.970, 1096.0, 33.1059
33.216711460, 23.970, 1091.0, 33.0303
33.260177220, 23.970, 1072.0, 32.7414
33.303642980, 23.970, 1066.0, 32.6497
33.347108740, 23.970, 1105.0, 33.2415
33.390574500, 23.970, 1105.0, 33.2415
33.434040260, 23.970, 1039.0, 32.2335
33.477506020, 23.970, 1045.0, 32.3265
33.520971780, 23.970, 1039.0, 32.2335
33.564437540, 23.970, 1050.0, 32.4037
33.607903300, 23.970, 1032.0, 32.1248
33.651369060, 23.970, 997.0, 31.5753
33.694834820, 23.970, 1060.0, 32.5576
33.738300580, 23.970, 1057.0, 32.5115
33.781766340, 23.970, 1126.0, 33.5559
33.825232100, 23.970, 1047.0, 32.3574
33.868697860, 23.970, 1076.0, 32.8024
33.912163620, 23.970, 1042.0, 32.2800
33.955629380, 23.970, 1004.0, 31.6860
33.999095140, 23.970, 1057.0, 32.5115
34.042560900, 23.970, 1058.0, 32.5269
34.086026660, 23.970, 1016.0, 31.8748
34.129492420, 23.970, 1005.0, 31.7017
34.172958180, 23.970, 1068.0, 32.6803
34.216423940, 23.970, 1018.0, 31.9061
34.259889700, 23.970, 1133.0, 33.6601
34.303355460, 23.970, 1039.0, 32.2335
34.346821220, 23.970, 1061.0, 32.5730
34.390286980, 23.970, 1042.0, 32.2800
34.433752740, 23.970, 1063.0, 32.6037
34.477218500, 23.970, 1067.0, 32.6650
34.520684260, 23.970, 1053.0, 32.4500
34.564150020, 23.970, 1063.0, 32.6037
34.607615780, 23.970, 1053.0, 32.4500
34.651081540, 23.970, 1119.0, 33.4515
34.694547300, 23.970, 1088.0, 32.9848
34.738013060, 23.970, 1115.0, 33.3916
34.781478820, 23.970, 1107.0, 33.2716
34.824944580, 23.970, 1193.0, 34.5398
34.868410340, 23.970, 1063.0, 32.6037
34.911876100, 23.970, 1152.0, 33.9411
34.955341860, 23.970, 1128.0, 33.5857
34.998807620, 23.970, 1162.0, 34.0881
35.042273380, 23.970, 1079.0, 32.8481
35.085739140, 23.970, 1164.0, 34.1174
35.129204900, 23.970, 1162.0, 34.0881
35.172670660, 23.970, 1130.0, 33.6155
35.216136420, 23.970, 1134.0, 33.6749
35.259602180, 23.970, 1140.0, 33.7639
35.303067940, 23.970, 1188.0, 34.4674
35.346533700, 23.970, 1196.0, 34.5832
35.389999460, 23.970, 1246.0, 35.2987
35.433465220, 23.970, 1226.0, 35.0143
35.476930980, 23.970, 1295.0, 35.9861
35.520396740, 23.970, 1380.0, 37.1484
35.563862500, 23.970, 1369.0, 37.0000
35.607328260, 23.970, 1456.0, 38.1576
35.650794020, 23.970, 1363.0, 36.9188
35.694259780, 23.970, 1425.0, 37.7492
35.737725540, 23.970, 1460.0, 38.2099
35.781191300, 23.970, 1515.0, 38.9230
35.824657060, 23.970, 1742.0, 41.7373
35.868122820, 23.970, 1811.0, 42.5558
35.911588580, 23.970, 1974.0, 44.4297
35.955054340, 23.970, 2148.0, 46.3465
35.998520100, 23.970, 2364.0, 48.6210
36.041985860, 23.970, 2536.0, 50.3587
36.085451620, 23.970, 2906.0, 53.9073
36.128917380, 23.970, 3122.0, 55.8749
36.172383140, 23.970, 3412.0, 58.4123
36.215848900, 23.970, 3670.0, 60.5805
36.259314660, 23.970, 3835.0, 61.9274
36.302780420, 23.970, 4068.0, 63.7809
36.346246180, 23.970, 4294.0, 65.5286
36.389711940, 23.970, 4477.0, 66.9104
36.433177700, 23.970, 4585.0, 67.7126
36.476643460, 23.970, 4433.0, 66.5808
36.520109220, 23.970, 4154.0, 64.4515
36.563574980, 23.970, 3860.0, 62.1289
36.607040740, 23.970, 3475.0, 58.9491
36.650506500, 23.970, 3020.0, 54.9545
36.693972260, 23.970, 2718.0, 52.1344
36.737438020, 23.970, 2350.0, 48.4768
36.780903780, 23.970, 2001.0, 44.7325
36.824369540, 23.970, 1775.0, 42.1307
36.867835300, 23.970, 1672.0, 40.8901
36.911301060, 23.970, 1501.0, 38.7427
36.954766820, 23.970, 1420.0, 37.6829
36.998232580, 23.970, 1418.0, 37.6563
37.041698340, 23.970, 1224.0, 34.9857
37.085164100, 23.970, 1314.0, 36.2491
37.128629860, 23.970, 1331.0, 36.4829
37.172095620, 23.970, 1268.0, 35.6090
37.215561380, 23.970, 1200.0, 34.6410
37.259027140, 23.970, 1231.0, 35.0856
37.302492900, 23.970, 1265.0, 35.5668
37.345958660, 23.970, 1243.0, 35.2562
37.389424420, 23.970, 1239.0, 35.1994
37.432890180, 23.970, 1241.0, 35.2278
37.476355940, 23.970, 1178.0, 34.3220
37.519821700, 23.970, 1237.0, 35.1710
37.563287460, 23.970, 1173.0, 34.2491
37.606753220, 23.970, 1239.0, 35.1994
37.650218980, 23.970, 1163.0, 34.1028
37.693684740, 23.970, 1205.0, 34.7131
37.737150500, 23.970, 1270.0, 35.6371
37.780616260, 23.970, 1163.0, 34.1028
37.824082020, 23.970, 1170.0, 34.2053
37.867547780, 23.970, 1214.0, 34.8425
37.911013540, 23.970, 1220.0, 34.9285
37.954479300, 23.970, 1230.0, 35.0714
37.997945060, 23.970, 1306.0, 36.1386
38.041410820, 23.970, 1340.0, 36.6060
38.084876580, 23.970, 1350.0, 36.7423
38.128342340, 23.970, 1361.0, 36.8917
38.171808100, 23.970, 1440.0, 37.9473
38.215273860, 23.970, 1437.0, 37.9078
38.258739620, 23.970, 1435.0, 37.8814
38.302205380, 23.970, 1401.0, 37.4299
38.345671140, 23.970, 1563.0, 39.5348
38.389136900, 23.970, 1527.0, 39.0768
38.432602660, 23.970, 1551.0, 39.3827
38.476068420, 23.970, 1535.0, 39.1791
38.519534180, 23.970, 1622.0, 40.2741
38.562999940, 23.970, 1507.0, 38.8201
38.606465700, 23.970, 1548.0, 39.3446
38.649931460, 23.970, 1484.0, 38.5227
38.693397220, 23.970, 1415.0, 37.6165
38.736862980, 23.970, 1420.0, 37.6829
38.780328740, 23.970, 1392.0, 37.3095
38.823794500, 23.970, 1352.0, 36.7696
38.867260260, 23.970, 1401.0, 37.4299
38.910726020, 23.970, 1481.0, 38.4838
38.954191780, 23.970, 1533.0, 39.1535
38.997657540, 23.970, 1532.0, 39.1408
39.041123300, 23.970, 1567.0, 39.5854
39.084589060, 23.970, 1461.0, 38.2230
39.128054820, 23.970, 1484.0, 38.5227
39.171520580, 23.970, 1472.0, 38.3667
39.214986340, 23.970, 1393.0, 37.3229
39.258452100, 23.970, 1499.0, 38.7169
39.301917860, 23.970, 1529.0, 39.1024
39.345383620, 23.970, 1579.0, 39.7366
39.388849380, 23.970, 1531.0, 39.1280
39.432315140, 23.970, 1731.0, 41.6053
39.475780900, 23.970, 1786.0, 42.2611
39.519246660, 23.970, 1871.0, 43.2551
39.562712420, 23.970, 2010.0, 44.8330
39.606178180, 23.970, 2072.0, 45.5192
39.649643940, 23.970, 2223.0, 47.1487
39.693109700, 23.970, 2473.0, 49.7293
39.736575460, 23.970, 2472.0, 49.7192
39.780041220, 23.970, 2479.0, 49.7896
39.823506980, 23.970, 2622.0, 51.2055
39.866972740, 23.970, 2582.0, 50.8134
39.910438500, 23.970, 2648.0, 51.4587
39.953904260, 23.970, 2593.0, 50.9215
39.997370020, 23.970, 2632.0, 51.3030
40.040835780, 23.970, 2442.0, 49.4166
40.084301540, 23.970, 2314.0, 48.1041
40.127767300, 23.970, 2346.0, 48.4355
40.171233060, 23.970, 2133.0, 46.1844
40.214698820, 23.970, 2114.0, 45.9783
40.258164580, 23.970, 1935.0, 43.9886
40.301630340, 23.970, 1978.0, 44.4747
40.345096100, 23.970, 2041.0, 45.1774
40.388561860, 23.970, 1890.0, 43.4741
40.432027620, 23.970, 1893.0, 43.5086
40.475493380, 23.970, 1984.0, 44.5421
40.518959140, 23.970, 1929.0, 43.9204
40.562424900, 23.970, 2014.0, 44.8776
40.605890660, 23.970, 1988.0, 44.5870
40.649356420, 23.970, 2018.0, 44.9222
40.692822180, 23.970, 2067.0, 45.4643
40.736287940, 23.970, 2030.0, 45.0555
40.779753700, 23.970, 2080.0, 45.6070
40.823219460, 23.970, 2053.0, 45.3100
40.866685220, 23.970, 2049.0, 45.2659
40.910150980, 23.970, 2092.0, 45.7384
40.953616740, 23.970, 2045.0, 45.2217
40.997082500, 23.970, 1980.0, 44.4972
41.040548260, 23.970, 1833.0, 42.8135
41.084014020, 23.970, 1760.0, 41.9524
41.127479780, 23.970, 1785.0, 42.2493
41.170945540, 23.970, 1757.0, 41.9166
41.214411300, 23.970, 1727.0, 41.5572
41.257877060, 23.970, 1634.0, 40.4228
41.301342820, 23.970, 1703.0, 41.2674
41.344808580, 23.970, 1713.0, 41.3884
41.388274340, 23.970, 1725.0, 41.5331
41.431740100, 23.970, 1750.0, 41.8330
41.475205860, 23.970, 1892.0, 43.4971
41.518671620, 23.970, 1966.0, 44.3396
41.562137380, 23.970, 1969.0, 44.3734
41.605603140, 23.970, 1971.0, 44.3959
41.649068900, 23.970, 2029.0, 45.0444
41.692534660, 23.970, 2128.0, 46.1303
41.736000420, 23.970, 2155.0, 46.4220
41.779466180, 23.970, 2087.0, 45.6837
41.822931940, 23.970, 2083.0, 45.6399
41.866397700, 23.970, 2132.0, 46.1736
41.909863460, 23.970, 1998.0, 44.6990
41.953329220, 23.970, 1974.0, 44.4297
41.996794980, 23.970, 1875.0, 43.3013
42.040260740, 23.970, 1782.0, 42.2137
42.083726500, 23.970, 1675.0, 40.9268
42.127192260, 23.970, 1664.0, 40.7922
42.170658020, 23.970, 1612.0, 40.1497
42.214123780, 23.970, 1590.0, 39.8748
42.257589540, 23.970, 1500.0, 38.7298
42.301055300, 23.970, 1439.0, 37.9342
42.344521060, 23.970, 1475.0, 38.4057
42.387986820, 23.970, 1492.0, 38.6264
42.431452580, 23.970, 1459.0, 38.1969
42.474918340, 23.970, 1439.0, 37.9342
42.518384100, 23.970, 1474.0, 38.3927
42.561849860, 23.970, 1557.0, 39.4588
42.605315620, 23.970, 1611.0, 40.1373
42.648781380, 23.970, 1805.0, 42.4853
42.692247140, 23.970, 1847.0, 42.9767
42.735712900, 23.970, 2024.0, 44.9889
42.779178660, 23.970, 2066.0, 45.4533
42.822644420, 23.970, 2024.0, 44.9889
42.866110180, 23.970, 2017.0, 44.9110
42.909575940, 23.970, 2051.0, 45.2880
42.953041700, 23.970, 2016.0, 44.8999
42.996507460, 23.970, 2084.0, 45.6508
43.039973220, 23.970, 2141.0, 46.2709
43.083438980, 23.970, 2230.0, 47.2229
43.126904740, 23.970, 2197.0, 46.8722
43.170370500, 23.970, 2224.0, 47.1593
43.213836260, 23.970, 2181.0, 46.7012
43.257302020, 23.970, 2039.0, 45.1553
43.300767780, 23.970, 1955.0, 44.2154
43.344233540, 23.970, 1930.0, 43.9318
43.387699300, 23.970, 1905.0, 43.6463
43.431165060, 23.970, 1817.0, 42.6263
43.474630820, 23.970, 1806.0, 42.4971
43.518096580, 23.970, 1708.0, 41.3280
43.561562340, 23.970, 1612.0, 40.1497
43.605028100, 23.970, 1679.0, 40.9756
43.648493860, 23.970, 1615.0, 40.1871
43.691959620, 23.970, 1668.0, 40.8412
43.735425380, 23.970, 1665.0, 40.8044
43.778891140, 23.970, 1665.0, 40.8044
43.822356900, 23.970, 1674.0, 40.9145
43.865822660, 23.970, 1657.0, 40.7063
43.909288420, 23.970, 1684.0, 41.0366
43.952754180, 23.970, 1660.0, 40.7431
43.996219940, 23.970, 1699.0, 41.2189
44.039685700, 23.970, 1663.0, 40.7799
44.083151460, 23.970, 1758.0, 41.9285
44.126617220, 23.970, 1789.0, 42.2966
44.170082980, 23.970, 1642.0, 40.5216
44.213548740, 23.970, 1650.0, 40.6202
44.257014500, 23.970, 1602.0, 40.0250
44.300480260, 23.970, 1595.0, 39.9375
44.343946020, 23.970, 1429.0, 37.8021
44.387411780, 23.970, 1401.0, 37.4299
44.430877540, 23.970, 1314.0, 36.2491
44.474343300, 23.970, 1212.0, 34.8138
44.517809060, 23.970, 1258.0, 35.4683
44.561274820, 23.970, 1232.0, 35.0999
44.604740580, 23.970, 1146.0, 33.8526
44.648206340, 23.970, 1135.0, 33.6898
44.691672100, 23.970, 1196.0, 34.5832
44.735137860, 23.970, 1150.0, 33.9116
44.778603620, 23.970, 1097.0, 33.1210
44.822069380, 23.970, 1138.0, 33.7343
44.865535140, 23.970, 1148.0, 33.8821
44.909000900, 23.970, 1148.0, 33.8821
44.952466660, 23.970, 1082.0, 32.8938
44.995932420, 23.970, 1133.0, 33.6601
45.039398180, 23.970, 1105.0, 33.2415
45.082863940, 23.970, 1058.0, 32.5269
45.126329700, 23.970, 1134.0, 33.6749
45.169795460, 23.970, 1083.0, 32.9090
45.213261220, 23.970, 1091.0, 33.0303
45.256726980, 23.970, 1066.0, 32.6497
45.300192740, 23.970, 1046.0, 32.3419
45.343658500, 23.970, 1057.0, 32.5115
45.387124260, 23.970, 1069.0, 32.6956
45.430590020, 23.970, 1093.0, 33.0606
45.474055780, 23.970, 1084.0, 32.9242
45.517521540, 23.970, 1043.0, 32.2955
45.560987300, 23.970, 1066.0, 32.6497
45.604453060, 23.970, 1074.0, 32.7719
45.647918820, 23.970, 1063.0, 32.6037
45.691384580, 23.970, 991.0, 31.4802
45.734850340, 23.970, 1075.0, 32.7872
45.778316100, 23.970, 1032.0, 32.1248
45.821781860, 23.970, 1028.0, 32.0624
45.865247620, 23.970, 1030.0, 32.0936
45.908713380, 23.970, 1095.0, 33.0908
45.952179140, 23.970, 1122.0, 33.4963
45.995644900, 23.970, 1058.0, 32.5269
46.039110660, 23.970, 1068.0, 32.6803
46.082576420, 23.970, 1028.0, 32.0624
46.126042180, 23.970, 1060.0, 32.5576
46.169507940, 23.970, 1093.0, 33.0606
46.212973700, 23.970, 1112.0, 33.3467
46.256439460, 23.970, 1064.0, 32.6190
46.299905220, 23.970, 1065.0, 32.6343
46.343370980, 23.970, 1054.0, 32.4654
46.386836740, 23.970, 1145.0, 33.8378
46.430302500, 23.970, 1178.0, 34.3220
46.473768260, 23.970, 1166.0, 34.1467
46.517234020, 23.970, 1163.0, 34.1028
46.560699780, 23.970, 1210.0, 34.7851
46.604165540, 23.970, 1305.0, 36.1248
46.647631300, 23.970, 1362.0, 36.9053
46.691097060, 23.970, 1443.0, 37.9868
46.734562820, 23.970, 1457.0, 38.1707
46.778028580, 23.970, 1554.0, 39.4208
46.821494340, 23.970, 1556.0, 39.4462
46.864960100, 23.970, 1641.0, 40.5093
46.908425860, 23.970, 1575.0, 39.6863
46.951891620, 23.970, 1672.0, 40.8901
46.995357380, 23.970, 1702.0, 41.2553
47.038823140, 23.970, 1951.0, 44.1701
47.082288900, 23.970, 2127.0, 46.1194
47.125754660, 23.970, 1998.0, 44.6990
47.169220420, 23.970, 1806.0, 42.4971
47.212686180, 23.970, 1758.0, 41.9285
47.256151940, 23.970, 1635.0, 40.4351
47.299617700, 23.970, 1564.0, 39.5474
47.343083460, 23.970, 1425.0, 37.7492
47.386549220, 23.970, 1271.0, 35.6511
47.430014980, 23.970, 1256.0, 35.4401
47.473480740, 23.970, 1164.0, 34.1174
47.516946500, 23.970, 1176.0, 34.2929
47.560412260, 23.970, 1113.0, 33.3617
47.603878020, 23.970, 1128.0, 33.5857
47.647343780, 23.970, 1091.0, 33.0303
47.690809540, 23.970, 1044.0, 32.3110
47.734275300, 23.970, 1007.0, 31.7333
47.777741060, 23.970, 1071.0, 32.7261
47.821206820, 23.970, 1026.0, 32.0312
47.864672580, 23.970, 1044.0, 32.3110
47.908138340, 23.970, 1049.0, 32.3883
47.951604100, 23.970, 1096.0, 33.1059
47.995069860, 23.970, 1179.0, 34.3366
48.038535620, 23.970, 1284.0, 35.8329
48.082001380, 23.970, 1366.0, 36.9594
48.125467140, 23.970, 1272.0, 35.6651
48.168932900, 23.970, 1242.0, 35.2420
48.212398660, 23.970, 1177.0, 34.3074
48.255864420, 23.970, 1126.0, 33.5559
48.299330180, 23.970, 1073.0, 32.7567
48.342795940, 23.970, 998.0, 31.5911
48.386261700, 23.970, 1007.0, 31.7333
48.429727460, 23.970, 971.0, 31.1609
48.473193220, 23.970, 934.0, 30.5614
48.516658980, 23.970, 1018.0, 31.9061
48.560124740, 23.970, 1039.0, 32.2335
48.603590500, 23.970, 1042.0, 32.2800
48.647056260, 23.970, 1006.0, 31.7175
48.690522020, 23.970, 1056.0, 32.4962
48.733987780, 23.970, 1077.0, 32.8177
48.777453540, 23.970, 1060.0, 32.5576
48.820919300, 23.970, 1010.0, 31.7805
48.864385060, 23.970, 1054.0, 32.4654
48.907850820, 23.970, 1019.0, 31.9218
48.951316580, 23.970, 1104.0, 33.2265
48.994782340, 23.970, 989.0, 31.4484
49.038248100, 23.970, 1056.0, 32.4962
49.081713860, 23.970, 1076.0, 32.8024
49.125179620, 23.970, 1070.0, 32.7109
49.168645380, 23.970, 997.0, 31.5753
49.212111140, 23.970, 1040.0, 32.2490
49.255576900, 23.970, 1032.0, 32.1248
49.299042660, 23.970, 1022.0, 31.9687
49.342508420, 23.970, 1018.0, 31.9061
49.385974180, 23.970, 1029.0, 32.0780
49.429439940, 23.970, 911.0, 30.1828
49.472905700, 23.970, 1000.0, 31.6228
49.516371460, 23.970, 954.0, 30.8869
49.559837220, 23.970, 926.0, 30.4302
49.603302980, 23.970, 936.0, 30.5941
49.646768740, 23.970, 942.0, 30.6920
49.690234500, 23.970, 930.0, 30.4959
49.733700260, 23.970, 896.0, 29.9333
49.777166020, 23.970, 913.0, 30.2159
49.820631780, 23.970, 904.0, 30.0666
49.864097540, 23.970, 853.0, 29.2062
49.907563300, 23.970, 928.0, 30.4631
49.951029060, 23.970, 902.0, 30.0333
49.994494820, 23.970, 861.0, 29.3428