File: data/DSC/HDPE_4.csv
[Measurement conditions]
Sample identification,HDPE_4
Comment,
Anode material,Cu
K-Alpha1 wavelength,1.5405980
K-Alpha2 wavelength,1.5444260
Ratio K-Alpha2/K-Alpha1,0.500
Divergence slit,Fixed,0.38mm
Monochromator used,NO
Generator voltage, 40
Tube current, 15
File date and time,02/Apr/2025 11:21
Unit cell,
h k l, 0 0 0
Scan axis,Gonio
Scan range,5.002000000,49.999928040
Scan step size,0.0108664
No. of points, 4141
Scan type,CONTINUOUS
Time per step,23.970
[Scan points]
Angle, TimePerStep, Intensity, ESD
5.007433220, 23.970, 1570.0, 39.6232
5.050898980, 23.970, 1549.0, 39.3573
5.094364740, 23.970, 1597.0, 39.9625
5.137830500, 23.970, 1598.0, 39.9750
5.181296260, 23.970, 1681.0, 41.0000
5.224762020, 23.970, 1713.0, 41.3884
5.268227780, 23.970, 1657.0, 40.7063
5.311693540, 23.970, 1631.0, 40.3856
5.355159300, 23.970, 1790.0, 42.3084
5.398625060, 23.970, 1743.0, 41.7493
5.442090820, 23.970, 1766.0, 42.0238
5.485556580, 23.970, 1775.0, 42.1307
5.529022340, 23.970, 1813.0, 42.5793
5.572488100, 23.970, 1751.0, 41.8450
5.615953860, 23.970, 1846.0, 42.9651
5.659419620, 23.970, 1861.0, 43.1393
5.702885380, 23.970, 1911.0, 43.7150
5.746351140, 23.970, 1911.0, 43.7150
5.789816900, 23.970, 1888.0, 43.4511
5.833282660, 23.970, 1919.0, 43.8064
5.876748420, 23.970, 1993.0, 44.6430
5.920214180, 23.970, 2004.0, 44.7661
5.963679940, 23.970, 1956.0, 44.2267
6.007145700, 23.970, 2040.0, 45.1664
6.050611460, 23.970, 2041.0, 45.1774
6.094077220, 23.970, 2148.0, 46.3465
6.137542980, 23.970, 2077.0, 45.5741
6.181008740, 23.970, 2109.0, 45.9239
6.224474500, 23.970, 2201.0, 46.9148
6.267940260, 23.970, 2197.0, 46.8722
6.311406020, 23.970, 2186.0, 46.7547
6.354871780, 23.970, 2152.0, 46.3897
6.398337540, 23.970, 2188.0, 46.7761
6.441803300, 23.970, 2277.0, 47.7179
6.485269060, 23.970, 2206.0, 46.9681
6.528734820, 23.970, 2211.0, 47.0213
6.572200580, 23.970, 2298.0, 47.9375
6.615666340, 23.970, 2207.0, 46.9787
6.659132100, 23.970, 2270.0, 47.6445
6.702597860, 23.970, 2350.0, 48.4768
6.746063620, 23.970, 2254.0, 47.4763
6.789529380, 23.970, 2465.0, 49.6488
6.832995140, 23.970, 2317.0, 48.1352
6.876460900, 23.970, 2336.0, 48.3322
6.919926660, 23.970, 2395.0, 48.9387
6.963392420, 23.970, 2496.0, 49.9600
7.006858180, 23.970, 2321.0, 48.1768
7.050323940, 23.970, 2469.0, 49.6890
7.093789700, 23.970, 2391.0, 48.8979
7.137255460, 23.970, 2338.0, 48.3529
7.180721220, 23.970, 2502.0, 50.0200
7.224186980, 23.970, 2480.0, 49.7996
7.267652740, 23.970, 2588.0, 50.8724
7.311118500, 23.970, 2582.0, 50.8134
7.354584260, 23.970, 2537.0, 50.3686
7.398050020, 23.970, 2577.0, 50.7642
7.441515780, 23.970, 2493.0, 49.9300
7.484981540, 23.970, 2644.0, 51.4198
7.528447300, 23.970, 2560.0, 50.5964
7.571913060, 23.970, 2608.0, 51.0686
7.615378820, 23.970, 2633.0, 51.3128
7.658844580, 23.970, 2599.0, 50.9804
7.702310340, 23.970, 2535.0, 50.3488
7.745776100, 23.970, 2639.0, 51.3712
7.789241860, 23.970, 2495.0, 49.9500
7.832707620, 23.970, 2817.0, 53.0754
7.876173380, 23.970, 2547.0, 50.4678
7.919639140, 23.970, 2653.0, 51.5073
7.963104900, 23.970, 2683.0, 51.7977
8.006570660, 23.970, 2628.0, 51.2640
8.050036420, 23.970, 2670.0, 51.6720
8.093502180, 23.970, 2674.0, 51.7107
8.136967940, 23.970, 2697.0, 51.9326
8.180433700, 23.970, 2653.0, 51.5073
8.223899460, 23.970, 2734.0, 52.2877
8.267365220, 23.970, 2591.0, 50.9019
8.310830980, 23.970, 2738.0, 52.3259
8.354296740, 23.970, 2668.0, 51.6527
8.397762500, 23.970, 2703.0, 51.9904
8.441228260, 23.970, 2666.0, 51.6333
8.484694020, 23.970, 2752.0, 52.4595
8.528159780, 23.970, 2823.0, 53.1319
8.571625540, 23.970, 2754.0, 52.4786
8.615091300, 23.970, 2678.0, 51.7494
8.658557060, 23.970, 2786.0, 52.7826
8.702022820, 23.970, 2766.0, 52.5928
8.745488580, 23.970, 2721.0, 52.1632
8.788954340, 23.970, 2808.0, 52.9906
8.832420100, 23.970, 2781.0, 52.7352
8.875885860, 23.970, 2744.0, 52.3832
8.919351620, 23.970, 2725.0, 52.2015
8.962817380, 23.970, 2770.0, 52.6308
9.006283140, 23.970, 2707.0, 52.0288
9.049748900, 23.970, 2653.0, 51.5073
9.093214660, 23.970, 2707.0, 52.0288
9.136680420, 23.970, 2684.0, 51.8073
9.180146180, 23.970, 2714.0, 52.0961
9.223611940, 23.970, 2758.0, 52.5167
9.267077700, 23.970, 2750.0, 52.4404
9.310543460, 23.970, 2672.0, 51.6914
9.354009220, 23.970, 2747.0, 52.4118
9.397474980, 23.970, 2637.0, 51.3517
9.440940740, 23.970, 2689.0, 51.8556
9.484406500, 23.970, 2663.0, 51.6043
9.527872260, 23.970, 2636.0, 51.3420
9.571338020, 23.970, 2777.0, 52.6972
9.614803780, 23.970, 2645.0, 51.4296
9.658269540, 23.970, 2665.0, 51.6236
9.701735300, 23.970, 2661.0, 51.5849
9.745201060, 23.970, 2825.0, 53.1507
9.788666820, 23.970, 2598.0, 50.9706
9.832132580, 23.970, 2634.0, 51.3225
9.875598340, 23.970, 2637.0, 51.3517
9.919064100, 23.970, 2715.0, 52.1057
9.962529860, 23.970, 2489.0, 49.8899
10.005995620, 23.970, 2572.0, 50.7149
10.049461380, 23.970, 2569.0, 50.6853
10.092927140, 23.970, 2493.0, 49.9300
10.136392900, 23.970, 2604.0, 51.0294
10.179858660, 23.970, 2543.0, 50.4282
10.223324420, 23.970, 2524.0, 50.2394
10.266790180, 23.970, 2484.0, 49.8397
10.310255940, 23.970, 2615.0, 51.1371
10.353721700, 23.970, 2535.0, 50.3488
10.397187460, 23.970, 2472.0, 49.7192
10.440653220, 23.970, 2531.0, 50.3090
10.484118980, 23.970, 2473.0, 49.7293
10.527584740, 23.970, 2485.0, 49.8498
10.571050500, 23.970, 2537.0, 50.3686
10.614516260, 23.970, 2464.0, 49.6387
10.657982020, 23.970, 2546.0, 50.4579
10.701447780, 23.970, 2407.0, 49.0612
10.744913540, 23.970, 2521.0, 50.2096
10.788379300, 23.970, 2396.0, 48.9490
10.831845060, 23.970, 2473.0, 49.7293
10.875310820, 23.970, 2326.0, 48.2286
10.918776580, 23.970, 2355.0, 48.5283
10.962242340, 23.970, 2474.0, 49.7393
11.005708100, 23.970, 2391.0, 48.8979
11.049173860, 23.970, 2340.0, 48.3735
11.092639620, 23.970, 2340.0, 48.3735
11.136105380, 23.970, 2413.0, 49.1223
11.179571140, 23.970, 2418.0, 49.1732
11.223036900, 23.970, 2295.0, 47.9062
11.266502660, 23.970, 2431.0, 49.3052
11.309968420, 23.970, 2345.0, 48.4252
11.353434180, 23.970, 2348.0, 48.4562
11.396899940, 23.970, 2428.0, 49.2747
11.440365700, 23.970, 2326.0, 48.2286
11.483831460, 23.970, 2317.0, 48.1352
11.527297220, 23.970, 2311.0, 48.0729
11.570762980, 23.970, 2302.0, 47.9792
11.614228740, 23.970, 2200.0, 46.9042
11.657694500, 23.970, 2164.0, 46.5188
11.701160260, 23.970, 2269.0, 47.6340
11.744626020, 23.970, 2115.0, 45.9891
11.788091780, 23.970, 2205.0, 46.9574
11.831557540, 23.970, 2317.0, 48.1352
11.875023300, 23.970, 2202.0, 46.9255
11.918489060, 23.970, 2219.0, 47.1063
11.961954820, 23.970, 2185.0, 46.7440
12.005420580, 23.970, 2237.0, 47.2969
12.048886340, 23.970, 2203.0, 46.9361
12.092352100, 23.970, 2046.0, 45.2327
12.135817860, 23.970, 2117.0, 46.0109
12.179283620, 23.970, 2181.0, 46.7012
12.222749380, 23.970, 2194.0, 46.8402
12.266215140, 23.970, 2132.0, 46.1736
12.309680900, 23.970, 2142.0, 46.2817
12.353146660, 23.970, 2230.0, 47.2229
12.396612420, 23.970, 2099.0, 45.8148
12.440078180, 23.970, 2088.0, 45.6946
12.483543940, 23.970, 2018.0, 44.9222
12.527009700, 23.970, 2216.0, 47.0744
12.570475460, 23.970, 2119.0, 46.0326
12.613941220, 23.970, 2156.0, 46.4327
12.657406980, 23.970, 2110.0, 45.9347
12.700872740, 23.970, 2068.0, 45.4753
12.744338500, 23.970, 2026.0, 45.0111
12.787804260, 23.970, 2071.0, 45.5082
12.831270020, 23.970, 2068.0, 45.4753
12.874735780, 23.970, 2050.0, 45.2769
12.918201540, 23.970, 2057.0, 45.3542
12.961667300, 23.970, 2096.0, 45.7821
13.005133060, 23.970, 2071.0, 45.5082
13.048598820, 23.970, 2023.0, 44.9778
13.092064580, 23.970, 2081.0, 45.6180
13.135530340, 23.970, 2074.0, 45.5412
13.178996100, 23.970, 2044.0, 45.2106
13.222461860, 23.970, 2063.0, 45.4203
13.265927620, 23.970, 2117.0, 46.0109
13.309393380, 23.970, 2084.0, 45.6508
13.352859140, 23.970, 1957.0, 44.2380
13.396324900, 23.970, 2075.0, 45.5522
13.439790660, 23.970, 2117.0, 46.0109
13.483256420, 23.970, 2039.0, 45.1553
13.526722180, 23.970, 2174.0, 46.6262
13.570187940, 23.970, 2047.0, 45.2438
13.613653700, 23.970, 2101.0, 45.8367
13.657119460, 23.970, 2091.0, 45.7275
13.700585220, 23.970, 1998.0, 44.6990
13.744050980, 23.970, 2078.0, 45.5851
13.787516740, 23.970, 2035.0, 45.1110
13.830982500, 23.970, 2164.0, 46.5188
13.874448260, 23.970, 2075.0, 45.5522
13.917914020, 23.970, 2079.0, 45.5961
13.961379780, 23.970, 2126.0, 46.1086
14.004845540, 23.970, 2020.0, 44.9444
14.048311300, 23.970, 2151.0, 46.3789
14.091777060, 23.970, 2038.0, 45.1442
14.135242820, 23.970, 2156.0, 46.4327
14.178708580, 23.970, 2067.0, 45.4643
14.222174340, 23.970, 2082.0, 45.6289
14.265640100, 23.970, 2087.0, 45.6837
14.309105860, 23.970, 2096.0, 45.7821
14.352571620, 23.970, 2036.0, 45.1221
14.396037380, 23.970, 2088.0, 45.6946
14.439503140, 23.970, 2131.0, 46.1628
14.482968900, 23.970, 2120.0, 46.0435
14.526434660, 23.970, 2102.0, 45.8476
14.569900420, 23.970, 2106.0, 45.8912
14.613366180, 23.970, 2190.0, 46.7974
14.656831940, 23.970, 2173.0, 46.6154
14.700297700, 23.970, 2194.0, 46.8402
14.743763460, 23.970, 2110.0, 45.9347
14.787229220, 23.970, 2186.0, 46.7547
14.830694980, 23.970, 2141.0, 46.2709
14.874160740, 23.970, 2262.0, 47.5605
14.917626500, 23.970, 2219.0, 47.1063
14.961092260, 23.970, 2183.0, 46.7226
15.004558020, 23.970, 2246.0, 47.3920
15.048023780, 23.970, 2291.0, 47.8644
15.091489540, 23.970, 2274.0, 47.6865
15.134955300, 23.970, 2175.0, 46.6369
15.178421060, 23.970, 2250.0, 47.4342
15.221886820, 23.970, 2302.0, 47.9792
15.265352580, 23.970, 2351.0, 48.4871
15.308818340, 23.970, 2221.0, 47.1275
15.352284100, 23.970, 2343.0, 48.4045
15.395749860, 23.970, 2383.0, 48.8160
15.439215620, 23.970, 2394.0, 48.9285
15.482681380, 23.970, 2303.0, 47.9896
15.526147140, 23.970, 2291.0, 47.8644
15.569612900, 23.970, 2398.0, 48.9694
15.613078660, 23.970, 2405.0, 49.0408
15.656544420, 23.970, 2343.0, 48.4045
15.700010180, 23.970, 2437.0, 49.3660
15.743475940, 23.970, 2361.0, 48.5901
15.786941700, 23.970, 2367.0, 48.6518
15.830407460, 23.970, 2470.0, 49.6991
15.873873220, 23.970, 2433.0, 49.3254
15.917338980, 23.970, 2368.0, 48.6621
15.960804740, 23.970, 2426.0, 49.2544
16.004270500, 23.970, 2528.0, 50.2792
16.047736260, 23.970, 2477.0, 49.7695
16.091202020, 23.970, 2597.0, 50.9608
16.134667780, 23.970, 2546.0, 50.4579
16.178133540, 23.970, 2525.0, 50.2494
16.221599300, 23.970, 2569.0, 50.6853
16.265065060, 23.970, 2644.0, 51.4198
16.308530820, 23.970, 2623.0, 51.2152
16.351996580, 23.970, 2641.0, 51.3907
16.395462340, 23.970, 2693.0, 51.8941
16.438928100, 23.970, 2686.0, 51.8266
16.482393860, 23.970, 2814.0, 53.0471
16.525859620, 23.970, 2810.0, 53.0094
16.569325380, 23.970, 2894.0, 53.7959
16.612791140, 23.970, 2755.0, 52.4881
16.656256900, 23.970, 2832.0, 53.2165
16.699722660, 23.970, 2907.0, 53.9166
16.743188420, 23.970, 2838.0, 53.2729
16.786654180, 23.970, 2853.0, 53.4135
16.830119940, 23.970, 2903.0, 53.8795
16.873585700, 23.970, 3004.0, 54.8088
16.917051460, 23.970, 2964.0, 54.4426
16.960517220, 23.970, 3089.0, 55.5788
17.003982980, 23.970, 3129.0, 55.9375
17.047448740, 23.970, 3094.0, 55.6237
17.090914500, 23.970, 3206.0, 56.6216
17.134380260, 23.970, 3206.0, 56.6216
17.177846020, 23.970, 3328.0, 57.6888
17.221311780, 23.970, 3324.0, 57.6541
17.264777540, 23.970, 3308.0, 57.5152
17.308243300, 23.970, 3369.0, 58.0431
17.351709060, 23.970, 3405.0, 58.3524
17.395174820, 23.970, 3572.0, 59.7662
17.438640580, 23.970, 3511.0, 59.2537
17.482106340, 23.970, 3619.0, 60.1581
17.525572100, 23.970, 3609.0, 60.0750
17.569037860, 23.970, 3521.0, 59.3380
17.612503620, 23.970, 3622.0, 60.1831
17.655969380, 23.970, 3727.0, 61.0492
17.699435140, 23.970, 3845.0, 62.0081
17.742900900, 23.970, 3779.0, 61.4736
17.786366660, 23.970, 3950.0, 62.8490
17.829832420, 23.970, 3902.0, 62.4660
17.873298180, 23.970, 3891.0, 62.3779
17.916763940, 23.970, 3971.0, 63.0159
17.960229700, 23.970, 4050.0, 63.6396
18.003695460, 23.970, 4083.0, 63.8984
18.047161220, 23.970, 4144.0, 64.3739
18.090626980, 23.970, 4207.0, 64.8614
18.134092740, 23.970, 4103.0, 64.0547
18.177558500, 23.970, 4393.0, 66.2797
18.221024260, 23.970, 4335.0, 65.8407
18.264490020, 23.970, 4449.0, 66.7008
18.307955780, 23.970, 4444.0, 66.6633
18.351421540, 23.970, 4603.0, 67.8454
18.394887300, 23.970, 4519.0, 67.2235
18.438353060, 23.970, 4705.0, 68.5930
18.481818820, 23.970, 4729.0, 68.7677
18.525284580, 23.970, 4691.0, 68.4909
18.568750340, 23.970, 4758.0, 68.9783
18.612216100, 23.970, 4855.0, 69.6778
18.655681860, 23.970, 4850.0, 69.6419
18.699147620, 23.970, 4963.0, 70.4486
18.742613380, 23.970, 5057.0, 71.1126
18.786079140, 23.970, 5220.0, 72.2496
18.829544900, 23.970, 5227.0, 72.2980
18.873010660, 23.970, 5178.0, 71.9583
18.916476420, 23.970, 5211.0, 72.1873
18.959942180, 23.970, 5461.0, 73.8986
19.003407940, 23.970, 5369.0, 73.2735
19.046873700, 23.970, 5530.0, 74.3640
19.090339460, 23.970, 5531.0, 74.3707
19.133805220, 23.970, 5474.0, 73.9865
19.177270980, 23.970, 5646.0, 75.1399
19.220736740, 23.970, 5603.0, 74.8532
19.264202500, 23.970, 5648.0, 75.1532
19.307668260, 23.970, 5731.0, 75.7034
19.351134020, 23.970, 5859.0, 76.5441
19.394599780, 23.970, 5963.0, 77.2205
19.438065540, 23.970, 5831.0, 76.3610
19.481531300, 23.970, 6145.0, 78.3901
19.524997060, 23.970, 6278.0, 79.2338
19.568462820, 23.970, 6263.0, 79.1391
19.611928580, 23.970, 6180.0, 78.6130
19.655394340, 23.970, 6300.0, 79.3725
19.698860100, 23.970, 6109.0, 78.1601
19.742325860, 23.970, 6292.0, 79.3221
19.785791620, 23.970, 6200.0, 78.7401
19.829257380, 23.970, 6302.0, 79.3851
19.872723140, 23.970, 6151.0, 78.4283
19.916188900, 23.970, 6042.0, 77.7303
19.959654660, 23.970, 6221.0, 78.8733
20.003120420, 23.970, 6392.0, 79.9500
20.046586180, 23.970, 6399.0, 79.9937
20.090051940, 23.970, 6414.0, 80.0875
20.133517700, 23.970, 6591.0, 81.1850
20.176983460, 23.970, 6554.0, 80.9568
20.220449220, 23.970, 6664.0, 81.6333
20.263914980, 23.970, 6671.0, 81.6762
20.307380740, 23.970, 6670.0, 81.6701
20.350846500, 23.970, 6744.0, 82.1219
20.394312260, 23.970, 6820.0, 82.5833
20.437778020, 23.970, 6909.0, 83.1204
20.481243780, 23.970, 7257.0, 85.1880
20.524709540, 23.970, 7140.0, 84.4985
20.568175300, 23.970, 7377.0, 85.8895
20.611641060, 23.970, 7623.0, 87.3098
20.655106820, 23.970, 7883.0, 88.7863
20.698572580, 23.970, 8171.0, 90.3936
20.742038340, 23.970, 8868.0, 94.1701
20.785504100, 23.970, 9216.0, 96.0000
20.828969860, 23.970, 10155.0, 100.7720
20.872435620, 23.970, 10964.0, 104.7091
20.915901380, 23.970, 12128.0, 110.1272
20.959367140, 23.970, 13479.0, 116.0991
21.002832900, 23.970, 15451.0, 124.3021
21.046298660, 23.970, 17395.0, 131.8901
21.089764420, 23.970, 19631.0, 140.1107
21.133230180, 23.970, 22161.0, 148.8657
21.176695940, 23.970, 25200.0, 158.7451
21.220161700, 23.970, 28351.0, 168.3776
21.263627460, 23.970, 32099.0, 179.1619
21.307093220, 23.970, 36741.0, 191.6794
21.350558980, 23.970, 41970.0, 204.8658
21.394024740, 23.970, 47699.0, 218.4010
21.437490500, 23.970, 55464.0, 235.5080
21.480956260, 23.970, 64288.0, 253.5508
21.524422020, 23.970, 75009.0, 273.8777
21.567887780, 23.970, 87337.0, 295.5283
21.611353540, 23.970, 98420.0, 313.7196
21.654819300, 23.970, 102306.0, 319.8531
21.698285060, 23.970, 97465.0, 312.1939
21.741750820, 23.970, 82980.0, 288.0625
21.785216580, 23.970, 62732.0, 250.4636
21.828682340, 23.970, 43797.0, 209.2773
21.872148100, 23.970, 29770.0, 172.5399
21.915613860, 23.970, 20854.0, 144.4091
21.959079620, 23.970, 15496.0, 124.4829
22.002545380, 23.970, 12548.0, 112.0179
22.046011140, 23.970, 10660.0, 103.2473
22.089476900, 23.970, 9306.0, 96.4676
22.132942660, 23.970, 8240.0, 90.7744
22.176408420, 23.970, 7437.0, 86.2380
22.219874180, 23.970, 6746.0, 82.1340
22.263339940, 23.970, 6445.0, 80.2808
22.306805700, 23.970, 6130.0, 78.2943
22.350271460, 23.970, 5933.0, 77.0260
22.393737220, 23.970, 5757.0, 75.8749
22.437202980, 23.970, 5490.0, 74.0945
22.480668740, 23.970, 5354.0, 73.1710
22.524134500, 23.970, 5324.0, 72.9657
22.567600260, 23.970, 5121.0, 71.5612
22.611066020, 23.970, 5136.0, 71.6659
22.654531780, 23.970, 5088.0, 71.3302
22.697997540, 23.970, 5028.0, 70.9084
22.741463300, 23.970, 4855.0, 69.6778
22.784929060, 23.970, 4853.0, 69.6635
22.828394820, 23.970, 4914.0, 70.0999
22.871860580, 23.970, 4856.0, 69.6850
22.915326340, 23.970, 4805.0, 69.3181
22.958792100, 23.970, 4769.0, 69.0579
23.002257860, 23.970, 4851.0, 69.6491
23.045723620, 23.970, 5034.0, 70.9507
23.089189380, 23.970, 4994.0, 70.6682
23.132655140, 23.970, 5014.0, 70.8096
23.176120900, 23.970, 5223.0, 72.2703
23.219586660, 23.970, 5225.0, 72.2842
23.263052420, 23.970, 5577.0, 74.6793
23.306518180, 23.970, 5603.0, 74.8532
23.349983940, 23.970, 6004.0, 77.4855
23.393449700, 23.970, 6270.0, 79.1833
23.436915460, 23.970, 6872.0, 82.8975
23.480381220, 23.970, 7372.0, 85.8604
23.523846980, 23.970, 7907.0, 88.9213
23.567312740, 23.970, 8446.0, 91.9021
23.610778500, 23.970, 9271.0, 96.2860
23.654244260, 23.970, 10042.0, 100.2098
23.697710020, 23.970, 10916.0, 104.4797
23.741175780, 23.970, 11958.0, 109.3526
23.784641540, 23.970, 13108.0, 114.4902
23.828107300, 23.970, 14756.0, 121.4743
23.871573060, 23.970, 16488.0, 128.4056
23.915038820, 23.970, 18145.0, 134.7034
23.958504580, 23.970, 20450.0, 143.0035
24.001970340, 23.970, 21801.0, 147.6516
24.045436100, 23.970, 22533.0, 150.1100
24.088901860, 23.970, 22486.0, 149.9533
24.132367620, 23.970, 20664.0, 143.7498
24.175833380, 23.970, 17968.0, 134.0448
24.219299140, 23.970, 14580.0, 120.7477
24.262764900, 23.970, 11839.0, 108.8072
24.306230660, 23.970, 9324.0, 96.5609
24.349696420, 23.970, 7345.0, 85.7030
24.393162180, 23.970, 5947.0, 77.1168
24.436627940, 23.970, 5225.0, 72.2842
24.480093700, 23.970, 4635.0, 68.0808
24.523559460, 23.970, 3944.0, 62.8013
24.567025220, 23.970, 3765.0, 61.3596
24.610490980, 23.970, 3497.0, 59.1354
24.653956740, 23.970, 3272.0, 57.2014
24.697422500, 23.970, 3163.0, 56.2406
24.740888260, 23.970, 2935.0, 54.1756
24.784354020, 23.970, 2835.0, 53.2447
24.827819780, 23.970, 2766.0, 52.5928
24.871285540, 23.970, 2688.0, 51.8459
24.914751300, 23.970, 2681.0, 51.7784
24.958217060, 23.970, 2756.0, 52.4976
25.001682820, 23.970, 2582.0, 50.8134
25.045148580, 23.970, 2561.0, 50.6063
25.088614340, 23.970, 2412.0, 49.1121
25.132080100, 23.970, 2434.0, 49.3356
25.175545860, 23.970, 2418.0, 49.1732
25.219011620, 23.970, 2352.0, 48.4974
25.262477380, 23.970, 2254.0, 47.4763
25.305943140, 23.970, 2244.0, 47.3709
25.349408900, 23.970, 2297.0, 47.9270
25.392874660, 23.970, 2256.0, 47.4974
25.436340420, 23.970, 2255.0, 47.4868
25.479806180, 23.970, 2181.0, 46.7012
25.523271940, 23.970, 2183.0, 46.7226
25.566737700, 23.970, 2152.0, 46.3897
25.610203460, 23.970, 2189.0, 46.7868
25.653669220, 23.970, 2186.0, 46.7547
25.697134980, 23.970, 2076.0, 45.5631
25.740600740, 23.970, 1959.0, 44.2606
25.784066500, 23.970, 2020.0, 44.9444
25.827532260, 23.970, 1960.0, 44.2719
25.870998020, 23.970, 1912.0, 43.7264
25.914463780, 23.970, 2000.0, 44.7214
25.957929540, 23.970, 1991.0, 44.6206
26.001395300, 23.970, 1930.0, 43.9318
26.044861060, 23.970, 1872.0, 43.2666
26.088326820, 23.970, 1841.0, 42.9069
26.131792580, 23.970, 1809.0, 42.5323
26.175258340, 23.970, 1873.0, 43.2782
26.218724100, 23.970, 1840.0, 42.8952
26.262189860, 23.970, 1907.0, 43.6692
26.305655620, 23.970, 1893.0, 43.5086
26.349121380, 23.970, 1840.0, 42.8952
26.392587140, 23.970, 1773.0, 42.1070
26.436052900, 23.970, 1803.0, 42.4617
26.479518660, 23.970, 1837.0, 42.8602
26.522984420, 23.970, 1692.0, 41.1339
26.566450180, 23.970, 1707.0, 41.3159
26.609915940, 23.970, 1698.0, 41.2068
26.653381700, 23.970, 1706.0, 41.3038
26.696847460, 23.970, 1696.0, 41.1825
26.740313220, 23.970, 1626.0, 40.3237
26.783778980, 23.970, 1683.0, 41.0244
26.827244740, 23.970, 1623.0, 40.2865
26.870710500, 23.970, 1713.0, 41.3884
26.914176260, 23.970, 1678.0, 40.9634
26.957642020, 23.970, 1661.0, 40.7554
27.001107780, 23.970, 1611.0, 40.1373
27.044573540, 23.970, 1650.0, 40.6202
27.088039300, 23.970, 1650.0, 40.6202
27.131505060, 23.970, 1664.0, 40.7922
27.174970820, 23.970, 1646.0, 40.5709
27.218436580, 23.970, 1542.0, 39.2683
27.261902340, 23.970, 1553.0, 39.4081
27.305368100, 23.970, 1552.0, 39.3954
27.348833860, 23.970, 1514.0, 38.9102
27.392299620, 23.970, 1527.0, 39.0768
27.435765380, 23.970, 1579.0, 39.7366
27.479231140, 23.970, 1480.0, 38.4708
27.522696900, 23.970, 1501.0, 38.7427
27.566162660, 23.970, 1539.0, 39.2301
27.609628420, 23.970, 1494.0, 38.6523
27.653094180, 23.970, 1479.0, 38.4578
27.696559940, 23.970, 1489.0, 38.5876
27.740025700, 23.970, 1526.0, 39.0640
27.783491460, 23.970, 1407.0, 37.5100
27.826957220, 23.970, 1459.0, 38.1969
27.870422980, 23.970, 1458.0, 38.1838
27.913888740, 23.970, 1415.0, 37.6165
27.957354500, 23.970, 1429.0, 37.8021
28.000820260, 23.970, 1368.0, 36.9865
28.044286020, 23.970, 1459.0, 38.1969
28.087751780, 23.970, 1339.0, 36.5923
28.131217540, 23.970, 1383.0, 37.1887
28.174683300, 23.970, 1477.0, 38.4318
28.218149060, 23.970, 1373.0, 37.0540
28.261614820, 23.970, 1390.0, 37.2827
28.305080580, 23.970, 1380.0, 37.1484
28.348546340, 23.970, 1400.0, 37.4166
28.392012100, 23.970, 1449.0, 38.0657
28.435477860, 23.970, 1425.0, 37.7492
28.478943620, 23.970, 1362.0, 36.9053
28.522409380, 23.970, 1411.0, 37.5633
28.565875140, 23.970, 1439.0, 37.9342
28.609340900, 23.970, 1404.0, 37.4700
28.652806660, 23.970, 1385.0, 37.2156
28.696272420, 23.970, 1418.0, 37.6563
28.739738180, 23.970, 1369.0, 37.0000
28.783203940, 23.970, 1539.0, 39.2301
28.826669700, 23.970, 1608.0, 40.0999
28.870135460, 23.970, 1759.0, 41.9404
28.913601220, 23.970, 1742.0, 41.7373
28.957066980, 23.970, 1557.0, 39.4588
29.000532740, 23.970, 1300.0, 36.0555
29.043998500, 23.970, 1315.0, 36.2629
29.087464260, 23.970, 1371.0, 37.0270
29.130930020, 23.970, 1355.0, 36.8103
29.174395780, 23.970, 1327.0, 36.4280
29.217861540, 23.970, 1316.0, 36.2767
29.261327300, 23.970, 1333.0, 36.5103
29.304793060, 23.970, 1400.0, 37.4166
29.348258820, 23.970, 1319.0, 36.3180
29.391724580, 23.970, 1340.0, 36.6060
29.435190340, 23.970, 1374.0, 37.0675
29.478656100, 23.970, 1408.0, 37.5233
29.522121860, 23.970, 1497.0, 38.6911
29.565587620, 23.970, 1436.0, 37.8946
29.609053380, 23.970, 1434.0, 37.8682
29.652519140, 23.970, 1561.0, 39.5095
29.695984900, 23.970, 1551.0, 39.3827
29.739450660, 23.970, 1599.0, 39.9875
29.782916420, 23.970, 1774.0, 42.1189
29.826382180, 23.970, 1651.0, 40.6325
29.869847940, 23.970, 1736.0, 41.6653
29.913313700, 23.970, 1848.0, 42.9884
29.956779460, 23.970, 1771.0, 42.0833
30.000245220, 23.970, 1976.0, 44.4522
30.043710980, 23.970, 2081.0, 45.6180
30.087176740, 23.970, 2206.0, 46.9681
30.130642500, 23.970, 2208.0, 46.9894
30.174108260, 23.970, 2288.0, 47.8330
30.217574020, 23.970, 2207.0, 46.9787
30.261039780, 23.970, 2165.0, 46.5296
30.304505540, 23.970, 2034.0, 45.0999
30.347971300, 23.970, 1749.0, 41.8210
30.391437060, 23.970, 1591.0, 39.8873
30.434902820, 23.970, 1512.0, 38.8844
30.478368580, 23.970, 1435.0, 37.8814
30.521834340, 23.970, 1316.0, 36.2767
30.565300100, 23.970, 1253.0, 35.3977
30.608765860, 23.970, 1281.0, 35.7911
30.652231620, 23.970, 1198.0, 34.6121
30.695697380, 23.970, 1216.0, 34.8712
30.739163140, 23.970, 1199.0, 34.6266
30.782628900, 23.970, 1157.0, 34.0147
30.826094660, 23.970, 1180.0, 34.3511
30.869560420, 23.970, 1152.0, 33.9411
30.913026180, 23.970, 1179.0, 34.3366
30.956491940, 23.970, 1230.0, 35.0714
30.999957700, 23.970, 1198.0, 34.6121
31.043423460, 23.970, 1089.0, 33.0000
31.086889220, 23.970, 1106.0, 33.2566
31.130354980, 23.970, 1119.0, 33.4515
31.173820740, 23.970, 1102.0, 33.1964
31.217286500, 23.970, 1109.0, 33.3017
31.260752260, 23.970, 1119.0, 33.4515
31.304218020, 23.970, 1171.0, 34.2199
31.347683780, 23.970, 1160.0, 34.0588
31.391149540, 23.970, 1135.0, 33.6898
31.434615300, 23.970, 1127.0, 33.5708
31.478081060, 23.970, 1140.0, 33.7639
31.521546820, 23.970, 1065.0, 32.6343
31.565012580, 23.970, 1104.0, 33.2265
31.608478340, 23.970, 1127.0, 33.5708
31.651944100, 23.970, 1139.0, 33.7491
31.695409860, 23.970, 1080.0, 32.8634
31.738875620, 23.970, 1114.0, 33.3766
31.782341380, 23.970, 1126.0, 33.5559
31.825807140, 23.970, 1129.0, 33.6006
31.869272900, 23.970, 1062.0, 32.5883
31.912738660, 23.970, 1117.0, 33.4215
31.956204420, 23.970, 1158.0, 34.0294
31.999670180, 23.970, 1183.0, 34.3948
32.043135940, 23.970, 1053.0, 32.4500
32.086601700, 23.970, 1157.0, 34.0147
32.130067460, 23.970, 1132.0, 33.6452
32.173533220, 23.970, 1077.0, 32.8177
32.216998980, 23.970, 1053.0, 32.4500
32.260464740, 23.970, 1075.0, 32.7872
32.303930500, 23.970, 1075.0, 32.7872
32.347396260, 23.970, 1104.0, 33.2265
32.390862020, 23.970, 1124.0, 33.5261
32.434327780, 23.970, 1147.0, 33.8674
32.477793540, 23.970, 1095.0, 33.0908
32.521259300, 23.970, 1072.0, 32.7414
32.564725060, 23.970, 1115.0, 33.3916
32.608190820, 23.970, 1066.0, 32.6497
32.651656580, 23.970, 1069.0, 32.6956
32.695122340, 23.970, 1086.0, 32.9545
32.738588100, 23.970, 1122.0, 33.4963
32.782053860, 23.970, 1036.0, 32.1870
32.825519620, 23.970, 1046.0, 32.3419
32.868985380, 23.970, 1054.0, 32.4654
32.912451140, 23.970, 1058.0, 32.5269
32.955916900, 23.970, 1091.0, 33.0303
32.999382660, 23.970, 1034.0, 32.1559
33.042848420, 23.970, 1116.0, 33.4066
33.086314180, 23.970, 1063.0, 32.6037
33.129779940, 23.970, 1047.0, 32.3574
33.173245700, 23.970, 1019.0, 31.9218
33.216711460, 23.970, 1039.0, 32.2335
33.260177220, 23.970, 1090.0, 33.0151
33.303642980, 23.970, 1116.0, 33.4066
33.347108740, 23.970, 1032.0, 32.1248
33.390574500, 23.970, 1080.0, 32.8634
33.434040260, 23.970, 1139.0, 33.7491
33.477506020, 23.970, 1068.0, 32.6803
33.520971780, 23.970, 1149.0, 33.8969
33.564437540, 23.970, 1088.0, 32.9848
33.607903300, 23.970, 1104.0, 33.2265
33.651369060, 23.970, 1062.0, 32.5883
33.694834820, 23.970, 1054.0, 32.4654
33.738300580, 23.970, 1089.0, 33.0000
33.781766340, 23.970, 1101.0, 33.1813
33.825232100, 23.970, 1086.0, 32.9545
33.868697860, 23.970, 1080.0, 32.8634
33.912163620, 23.970, 1063.0, 32.6037
33.955629380, 23.970, 1057.0, 32.5115
33.999095140, 23.970, 1043.0, 32.2955
34.042560900, 23.970, 1050.0, 32.4037
34.086026660, 23.970, 1034.0, 32.1559
34.129492420, 23.970, 1054.0, 32.4654
34.172958180, 23.970, 1096.0, 33.1059
34.216423940, 23.970, 1066.0, 32.6497
34.259889700, 23.970, 1078.0, 32.8329
34.303355460, 23.970, 1113.0, 33.3617
34.346821220, 23.970, 1063.0, 32.6037
34.390286980, 23.970, 1049.0, 32.3883
34.433752740, 23.970, 1080.0, 32.8634
34.477218500, 23.970, 1053.0, 32.4500
34.520684260, 23.970, 1043.0, 32.2955
34.564150020, 23.970, 1069.0, 32.6956
34.607615780, 23.970, 1072.0, 32.7414
34.651081540, 23.970, 1128.0, 33.5857
34.694547300, 23.970, 1136.0, 33.7046
34.738013060, 23.970, 1134.0, 33.6749
34.781478820, 23.970, 1107.0, 33.2716
34.824944580, 23.970, 1079.0, 32.8481
34.868410340, 23.970, 1135.0, 33.6898
34.911876100, 23.970, 1117.0, 33.4215
34.955341860, 23.970, 1113.0, 33.3617
34.998807620, 23.970, 1119.0, 33.4515
35.042273380, 23.970, 1136.0, 33.7046
35.085739140, 23.970, 1187.0, 34.4529
35.129204900, 23.970, 1156.0, 34.0000
35.172670660, 23.970, 1242.0, 35.2420
35.216136420, 23.970, 1151.0, 33.9264
35.259602180, 23.970, 1143.0, 33.8083
35.303067940, 23.970, 1209.0, 34.7707
35.346533700, 23.970, 1198.0, 34.6121
35.389999460, 23.970, 1277.0, 35.7351
35.433465220, 23.970, 1287.0, 35.8748
35.476930980, 23.970, 1330.0, 36.4692
35.520396740, 23.970, 1444.0, 38.0000
35.563862500, 23.970, 1436.0, 37.8946
35.607328260, 23.970, 1467.0, 38.3014
35.650794020, 23.970, 1528.0, 39.0896
35.694259780, 23.970, 1701.0, 41.2432
35.737725540, 23.970, 1820.0, 42.6615
35.781191300, 23.970, 1898.0, 43.5660
35.824657060, 23.970, 2160.0, 46.4758
35.868122820, 23.970, 2254.0, 47.4763
35.911588580, 23.970, 2584.0, 50.8331
35.955054340, 23.970, 2760.0, 52.5357
35.998520100, 23.970, 2955.0, 54.3599
36.041985860, 23.970, 3000.0, 54.7723
36.085451620, 23.970, 3302.0, 57.4630
36.128917380, 23.970, 3597.0, 59.9750
36.172383140, 23.970, 3751.0, 61.2454
36.215848900, 23.970, 3855.0, 62.0886
36.259314660, 23.970, 4030.0, 63.4823
36.302780420, 23.970, 3963.0, 62.9524
36.346246180, 23.970, 4011.0, 63.3325
36.389711940, 23.970, 3741.0, 61.1637
36.433177700, 23.970, 3466.0, 58.8727
36.476643460, 23.970, 3179.0, 56.3826
36.520109220, 23.970, 2700.0, 51.9615
36.563574980, 23.970, 2456.0, 49.5580
36.607040740, 23.970, 2125.0, 46.0977
36.650506500, 23.970, 1829.0, 42.7668
36.693972260, 23.970, 1674.0, 40.9145
36.737438020, 23.970, 1657.0, 40.7063
36.780903780, 23.970, 1443.0, 37.9868
36.824369540, 23.970, 1339.0, 36.5923
36.867835300, 23.970, 1326.0, 36.4143
36.911301060, 23.970, 1265.0, 35.5668
36.954766820, 23.970, 1308.0, 36.1663
36.998232580, 23.970, 1308.0, 36.1663
37.041698340, 23.970, 1208.0, 34.7563
37.085164100, 23.970, 1245.0, 35.2846
37.128629860, 23.970, 1194.0, 34.5543
37.172095620, 23.970, 1269.0, 35.6230
37.215561380, 23.970, 1210.0, 34.7851
37.259027140, 23.970, 1270.0, 35.6371
37.302492900, 23.970, 1195.0, 34.5688
37.345958660, 23.970, 1228.0, 35.0428
37.389424420, 23.970, 1214.0, 34.8425
37.432890180, 23.970, 1210.0, 34.7851
37.476355940, 23.970, 1165.0, 34.1321
37.519821700, 23.970, 1231.0, 35.0856
37.563287460, 23.970, 1259.0, 35.4824
37.606753220, 23.970, 1395.0, 37.3497
37.650218980, 23.970, 1497.0, 38.6911
37.693684740, 23.970, 1525.0, 39.0512
37.737150500, 23.970, 1414.0, 37.6032
37.780616260, 23.970, 1480.0, 38.4708
37.824082020, 23.970, 1328.0, 36.4417
37.867547780, 23.970, 1344.0, 36.6606
37.911013540, 23.970, 1325.0, 36.4005
37.954479300, 23.970, 1364.0, 36.9324
37.997945060, 23.970, 1393.0, 37.3229
38.041410820, 23.970, 1289.0, 35.9026
38.084876580, 23.970, 1396.0, 37.3631
38.128342340, 23.970, 1494.0, 38.6523
38.171808100, 23.970, 1377.0, 37.1080
38.215273860, 23.970, 1452.0, 38.1051
38.258739620, 23.970, 1551.0, 39.3827
38.302205380, 23.970, 1516.0, 38.9358
38.345671140, 23.970, 1575.0, 39.6863
38.389136900, 23.970, 1499.0, 38.7169
38.432602660, 23.970, 1542.0, 39.2683
38.476068420, 23.970, 1537.0, 39.2046
38.519534180, 23.970, 1479.0, 38.4578
38.562999940, 23.970, 1464.0, 38.2623
38.606465700, 23.970, 1321.0, 36.3456
38.649931460, 23.970, 1367.0, 36.9730
38.693397220, 23.970, 1336.0, 36.5513
38.736862980, 23.970, 1332.0, 36.4966
38.780328740, 23.970, 1295.0, 35.9861
38.823794500, 23.970, 1415.0, 37.6165
38.867260260, 23.970, 1527.0, 39.0768
38.910726020, 23.970, 1462.0, 38.2361
38.954191780, 23.970, 1421.0, 37.6962
38.997657540, 23.970, 1398.0, 37.3898
39.041123300, 23.970, 1439.0, 37.9342
39.084589060, 23.970, 1450.0, 38.0789
39.128054820, 23.970, 1448.0, 38.0526
39.171520580, 23.970, 1529.0, 39.1024
39.214986340, 23.970, 1596.0, 39.9500
39.258452100, 23.970, 1618.0, 40.2244
39.301917860, 23.970, 1694.0, 41.1582
39.345383620, 23.970, 1786.0, 42.2611
39.388849380, 23.970, 1837.0, 42.8602
39.432315140, 23.970, 1913.0, 43.7379
39.475780900, 23.970, 1960.0, 44.2719
39.519246660, 23.970, 2046.0, 45.2327
39.562712420, 23.970, 2334.0, 48.3115
39.606178180, 23.970, 2285.0, 47.8017
39.649643940, 23.970, 2442.0, 49.4166
39.693109700, 23.970, 2483.0, 49.8297
39.736575460, 23.970, 2469.0, 49.6890
39.780041220, 23.970, 2543.0, 50.4282
39.823506980, 23.970, 2451.0, 49.5076
39.866972740, 23.970, 2386.0, 48.8467
39.910438500, 23.970, 2335.0, 48.3218
39.953904260, 23.970, 2272.0, 47.6655
39.997370020, 23.970, 2118.0, 46.0217
40.040835780, 23.970, 2018.0, 44.9222
40.084301540, 23.970, 1917.0, 43.7836
40.127767300, 23.970, 1863.0, 43.1625
40.171233060, 23.970, 1855.0, 43.0697
40.214698820, 23.970, 1790.0, 42.3084
40.258164580, 23.970, 1806.0, 42.4971
40.301630340, 23.970, 1869.0, 43.2319
40.345096100, 23.970, 1741.0, 41.7253
40.388561860, 23.970, 1829.0, 42.7668
40.432027620, 23.970, 1885.0, 43.4166
40.475493380, 23.970, 1939.0, 44.0341
40.518959140, 23.970, 1991.0, 44.6206
40.562424900, 23.970, 2177.0, 46.6583
40.605890660, 23.970, 2170.0, 46.5833
40.649356420, 23.970, 2173.0, 46.6154
40.692822180, 23.970, 2326.0, 48.2286
40.736287940, 23.970, 2367.0, 48.6518
40.779753700, 23.970, 2449.0, 49.4874
40.823219460, 23.970, 2489.0, 49.8899
40.866685220, 23.970, 2484.0, 49.8397
40.910150980, 23.970, 2460.0, 49.5984
40.953616740, 23.970, 2317.0, 48.1352
40.997082500, 23.970, 2204.0, 46.9468
41.040548260, 23.970, 2158.0, 46.4543
41.084014020, 23.970, 2000.0, 44.7214
41.127479780, 23.970, 1965.0, 44.3283
41.170945540, 23.970, 1808.0, 42.5206
41.214411300, 23.970, 1715.0, 41.4126
41.257877060, 23.970, 1868.0, 43.2204
41.301342820, 23.970, 1883.0, 43.3935
41.344808580, 23.970, 1850.0, 43.0116
41.388274340, 23.970, 1858.0, 43.1045
41.431740100, 23.970, 2020.0, 44.9444
41.475205860, 23.970, 1977.0, 44.4635
41.518671620, 23.970, 2058.0, 45.3652
41.562137380, 23.970, 2079.0, 45.5961
41.605603140, 23.970, 2076.0, 45.5631
41.649068900, 23.970, 2076.0, 45.5631
41.692534660, 23.970, 2071.0, 45.5082
41.736000420, 23.970, 2057.0, 45.3542
41.779466180, 23.970, 2081.0, 45.6180
41.822931940, 23.970, 1919.0, 43.8064
41.866397700, 23.970, 1838.0, 42.8719
41.909863460, 23.970, 1724.0, 41.5211
41.953329220, 23.970, 1681.0, 41.0000
41.996794980, 23.970, 1564.0, 39.5474
42.040260740, 23.970, 1544.0, 39.2938
42.083726500, 23.970, 1499.0, 38.7169
42.127192260, 23.970, 1501.0, 38.7427
42.170658020, 23.970, 1380.0, 37.1484
42.214123780, 23.970, 1534.0, 39.1663
42.257589540, 23.970, 1392.0, 37.3095
42.301055300, 23.970, 1517.0, 38.9487
42.344521060, 23.970, 1498.0, 38.7040
42.387986820, 23.970, 1512.0, 38.8844
42.431452580, 23.970, 1589.0, 39.8623
42.474918340, 23.970, 1565.0, 39.5601
42.518384100, 23.970, 1718.0, 41.4488
42.561849860, 23.970, 1793.0, 42.3438
42.605315620, 23.970, 1836.0, 42.8486
42.648781380, 23.970, 1968.0, 44.3621
42.692247140, 23.970, 1946.0, 44.1135
42.735712900, 23.970, 1921.0, 43.8292
42.779178660, 23.970, 1958.0, 44.2493
42.822644420, 23.970, 1986.0, 44.5646
42.866110180, 23.970, 1992.0, 44.6318
42.909575940, 23.970, 2129.0, 46.1411
42.953041700, 23.970, 2130.0, 46.1519
42.996507460, 23.970, 2134.0, 46.1952
43.039973220, 23.970, 2182.0, 46.7119
43.083438980, 23.970, 2114.0, 45.9783
43.126904740, 23.970, 2001.0, 44.7325
43.170370500, 23.970, 1915.0, 43.7607
43.213836260, 23.970, 1940.0, 44.0454
43.257302020, 23.970, 1750.0, 41.8330
43.300767780, 23.970, 1753.0, 41.8688
43.344233540, 23.970, 1643.0, 40.5339
43.387699300, 23.970, 1653.0, 40.6571
43.431165060, 23.970, 1615.0, 40.1871
43.474630820, 23.970, 1631.0, 40.3856
43.518096580, 23.970, 1494.0, 38.6523
43.561562340, 23.970, 1654.0, 40.6694
43.605028100, 23.970, 1611.0, 40.1373
43.648493860, 23.970, 1610.0, 40.1248
43.691959620, 23.970, 1723.0, 41.5090
43.735425380, 23.970, 1772.0, 42.0951
43.778891140, 23.970, 1724.0, 41.5211
43.822356900, 23.970, 1829.0, 42.7668
43.865822660, 23.970, 1870.0, 43.2435
43.909288420, 23.970, 1887.0, 43.4396
43.952754180, 23.970, 1877.0, 43.3244
43.996219940, 23.970, 1849.0, 43.0000
44.039685700, 23.970, 1868.0, 43.2204
44.083151460, 23.970, 2004.0, 44.7661
44.126617220, 23.970, 1783.0, 42.2256
44.170082980, 23.970, 1698.0, 41.2068
44.213548740, 23.970, 1612.0, 40.1497
44.257014500, 23.970, 1552.0, 39.3954
44.300480260, 23.970, 1413.0, 37.5899
44.343946020, 23.970, 1308.0, 36.1663
44.387411780, 23.970, 1190.0, 34.4964
44.430877540, 23.970, 1244.0, 35.2704
44.474343300, 23.970, 1185.0, 34.4238
44.517809060, 23.970, 1255.0, 35.4260
44.561274820, 23.970, 1236.0, 35.1568
44.604740580, 23.970, 1201.0, 34.6554
44.648206340, 23.970, 1106.0, 33.2566
44.691672100, 23.970, 1096.0, 33.1059
44.735137860, 23.970, 1200.0, 34.6410
44.778603620, 23.970, 1101.0, 33.1813
44.822069380, 23.970, 1084.0, 32.9242
44.865535140, 23.970, 1085.0, 32.9393
44.909000900, 23.970, 1083.0, 32.9090
44.952466660, 23.970, 1078.0, 32.8329
44.995932420, 23.970, 1075.0, 32.7872
45.039398180, 23.970, 1129.0, 33.6006
45.082863940, 23.970, 1093.0, 33.0606
45.126329700, 23.970, 1046.0, 32.3419
45.169795460, 23.970, 1092.0, 33.0454
45.213261220, 23.970, 1043.0, 32.2955
45.256726980, 23.970, 1052.0, 32.4345
45.300192740, 23.970, 1100.0, 33.1662
45.343658500, 23.970, 1026.0, 32.0312
45.387124260, 23.970, 1060.0, 32.5576
45.430590020, 23.970, 1068.0, 32.6803
45.474055780, 23.970, 1065.0, 32.6343
45.517521540, 23.970, 1010.0, 31.7805
45.560987300, 23.970, 1144.0, 33.8231
45.604453060, 23.970, 1077.0, 32.8177
45.647918820, 23.970, 1004.0, 31.6860
45.691384580, 23.970, 1028.0, 32.0624
45.734850340, 23.970, 1073.0, 32.7567
45.778316100, 23.970, 1086.0, 32.9545
45.821781860, 23.970, 1037.0, 32.2025
45.865247620, 23.970, 1007.0, 31.7333
45.908713380, 23.970, 1036.0, 32.1870
45.952179140, 23.970, 1066.0, 32.6497
45.995644900, 23.970, 1036.0, 32.1870
46.039110660, 23.970, 1051.0, 32.4191
46.082576420, 23.970, 1080.0, 32.8634
46.126042180, 23.970, 1063.0, 32.6037
46.169507940, 23.970, 1029.0, 32.0780
46.212973700, 23.970, 1103.0, 33.2114
46.256439460, 23.970, 1108.0, 33.2866
46.299905220, 23.970, 1165.0, 34.1321
46.343370980, 23.970, 1171.0, 34.2199
46.386836740, 23.970, 1111.0, 33.3317
46.430302500, 23.970, 1157.0, 34.0147
46.473768260, 23.970, 1294.0, 35.9722
46.517234020, 23.970, 1298.0, 36.0278
46.560699780, 23.970, 1307.0, 36.1525
46.604165540, 23.970, 1405.0, 37.4833
46.647631300, 23.970, 1403.0, 37.4566
46.691097060, 23.970, 1486.0, 38.5487
46.734562820, 23.970, 1413.0, 37.5899
46.778028580, 23.970, 1494.0, 38.6523
46.821494340, 23.970, 1540.0, 39.2428
46.864960100, 23.970, 1626.0, 40.3237
46.908425860, 23.970, 1633.0, 40.4104
46.951891620, 23.970, 1836.0, 42.8486
46.995357380, 23.970, 1949.0, 44.1475
47.038823140, 23.970, 1812.0, 42.5676
47.082288900, 23.970, 1662.0, 40.7676
47.125754660, 23.970, 1622.0, 40.2741
47.169220420, 23.970, 1460.0, 38.2099
47.212686180, 23.970, 1330.0, 36.4692
47.256151940, 23.970, 1298.0, 36.0278
47.299617700, 23.970, 1188.0, 34.4674
47.343083460, 23.970, 1232.0, 35.0999
47.386549220, 23.970, 1187.0, 34.4529
47.430014980, 23.970, 1166.0, 34.1467
47.473480740, 23.970, 1121.0, 33.4813
47.516946500, 23.970, 1106.0, 33.2566
47.560412260, 23.970, 1126.0, 33.5559
47.603878020, 23.970, 1052.0, 32.4345
47.647343780, 23.970, 1080.0, 32.8634
47.690809540, 23.970, 1022.0, 31.9687
47.734275300, 23.970, 1039.0, 32.2335
47.777741060, 23.970, 1042.0, 32.2800
47.821206820, 23.970, 1078.0, 32.8329
47.864672580, 23.970, 1079.0, 32.8481
47.908138340, 23.970, 1057.0, 32.5115
47.951604100, 23.970, 1224.0, 34.9857
47.995069860, 23.970, 1263.0, 35.5387
48.038535620, 23.970, 1269.0, 35.6230
48.082001380, 23.970, 1144.0, 33.8231
48.125467140, 23.970, 1213.0, 34.8281
48.168932900, 23.970, 1102.0, 33.1964
48.212398660, 23.970, 1016.0, 31.8748
48.255864420, 23.970, 1002.0, 31.6544
48.299330180, 23.970, 1019.0, 31.9218
48.342795940, 23.970, 975.0, 31.2250
48.386261700, 23.970, 1056.0, 32.4962
48.429727460, 23.970, 975.0, 31.2250
48.473193220, 23.970, 942.0, 30.6920
48.516658980, 23.970, 1005.0, 31.7017
48.560124740, 23.970, 961.0, 31.0000
48.603590500, 23.970, 1046.0, 32.3419
48.647056260, 23.970, 1002.0, 31.6544
48.690522020, 23.970, 1026.0, 32.0312
48.733987780, 23.970, 1074.0, 32.7719
48.777453540, 23.970, 1049.0, 32.3883
48.820919300, 23.970, 1088.0, 32.9848
48.864385060, 23.970, 1094.0, 33.0757
48.907850820, 23.970, 1147.0, 33.8674
48.951316580, 23.970, 1052.0, 32.4345
48.994782340, 23.970, 1086.0, 32.9545
49.038248100, 23.970, 1064.0, 32.6190
49.081713860, 23.970, 1129.0, 33.6006
49.125179620, 23.970, 1152.0, 33.9411
49.168645380, 23.970, 1166.0, 34.1467
49.212111140, 23.970, 1093.0, 33.0606
49.255576900, 23.970, 1106.0, 33.2566
49.299042660, 23.970, 1016.0, 31.8748
49.342508420, 23.970, 1071.0, 32.7261
49.385974180, 23.970, 1014.0, 31.8434
49.429439940, 23.970, 1031.0, 32.1092
49.472905700, 23.970, 980.0, 31.3050
49.516371460, 23.970, 951.0, 30.8383
49.559837220, 23.970, 959.0, 30.9677
49.603302980, 23.970, 957.0, 30.9354
49.646768740, 23.970, 964.0, 31.0483
49.690234500, 23.970, 915.0, 30.2490
49.733700260, 23.970, 953.0, 30.8707
49.777166020, 23.970, 894.0, 29.8998
49.820631780, 23.970, 902.0, 30.0333
49.864097540, 23.970, 927.0, 30.4467
49.907563300, 23.970, 898.0, 29.9666
49.951029060, 23.970, 905.0, 30.0832
49.994494820, 23.970, 902.0, 30.0333