File: data/XRD/501024.csv
[Measurement conditions]
Sample identification,501024
Comment,
Anode material,Cu
K-Alpha1 wavelength,1.5405980
K-Alpha2 wavelength,1.5444260
Ratio K-Alpha2/K-Alpha1,0.500
Divergence slit,Fixed,0.38mm
Monochromator used,NO
Generator voltage, 40
Tube current, 15
File date and time,26/Feb/2025 10:49
Unit cell,
h k l, 0 0 0
Scan axis,Gonio
Scan range,5.002000000,49.999928040
Scan step size,0.0108664
No. of points, 4141
Scan type,CONTINUOUS
Time per step,23.970
[Scan points]
Angle, TimePerStep, Intensity, ESD
5.007433220, 23.970, 1218.0, 34.8999
5.050898980, 23.970, 1290.0, 35.9166
5.094364740, 23.970, 1283.0, 35.8190
5.137830500, 23.970, 1311.0, 36.2077
5.181296260, 23.970, 1402.0, 37.4433
5.224762020, 23.970, 1350.0, 36.7423
5.268227780, 23.970, 1303.0, 36.0971
5.311693540, 23.970, 1331.0, 36.4829
5.355159300, 23.970, 1429.0, 37.8021
5.398625060, 23.970, 1379.0, 37.1349
5.442090820, 23.970, 1402.0, 37.4433
5.485556580, 23.970, 1438.0, 37.9210
5.529022340, 23.970, 1406.0, 37.4967
5.572488100, 23.970, 1528.0, 39.0896
5.615953860, 23.970, 1515.0, 38.9230
5.659419620, 23.970, 1539.0, 39.2301
5.702885380, 23.970, 1502.0, 38.7556
5.746351140, 23.970, 1487.0, 38.5616
5.789816900, 23.970, 1599.0, 39.9875
5.833282660, 23.970, 1576.0, 39.6989
5.876748420, 23.970, 1568.0, 39.5980
5.920214180, 23.970, 1565.0, 39.5601
5.963679940, 23.970, 1535.0, 39.1791
6.007145700, 23.970, 1714.0, 41.4005
6.050611460, 23.970, 1602.0, 40.0250
6.094077220, 23.970, 1663.0, 40.7799
6.137542980, 23.970, 1731.0, 41.6053
6.181008740, 23.970, 1720.0, 41.4729
6.224474500, 23.970, 1796.0, 42.3792
6.267940260, 23.970, 1746.0, 41.7852
6.311406020, 23.970, 1799.0, 42.4146
6.354871780, 23.970, 1744.0, 41.7612
6.398337540, 23.970, 1848.0, 42.9884
6.441803300, 23.970, 1760.0, 41.9524
6.485269060, 23.970, 1796.0, 42.3792
6.528734820, 23.970, 1827.0, 42.7434
6.572200580, 23.970, 1785.0, 42.2493
6.615666340, 23.970, 1801.0, 42.4382
6.659132100, 23.970, 1830.0, 42.7785
6.702597860, 23.970, 1807.0, 42.5088
6.746063620, 23.970, 1835.0, 42.8369
6.789529380, 23.970, 1860.0, 43.1277
6.832995140, 23.970, 1860.0, 43.1277
6.876460900, 23.970, 1884.0, 43.4051
6.919926660, 23.970, 1945.0, 44.1022
6.963392420, 23.970, 1833.0, 42.8135
7.006858180, 23.970, 1960.0, 44.2719
7.050323940, 23.970, 1805.0, 42.4853
7.093789700, 23.970, 1946.0, 44.1135
7.137255460, 23.970, 1883.0, 43.3935
7.180721220, 23.970, 1898.0, 43.5660
7.224186980, 23.970, 1950.0, 44.1588
7.267652740, 23.970, 1881.0, 43.3705
7.311118500, 23.970, 2059.0, 45.3762
7.354584260, 23.970, 1954.0, 44.2041
7.398050020, 23.970, 2106.0, 45.8912
7.441515780, 23.970, 2056.0, 45.3431
7.484981540, 23.970, 1982.0, 44.5197
7.528447300, 23.970, 2002.0, 44.7437
7.571913060, 23.970, 2007.0, 44.7996
7.615378820, 23.970, 1983.0, 44.5309
7.658844580, 23.970, 2097.0, 45.7930
7.702310340, 23.970, 2074.0, 45.5412
7.745776100, 23.970, 2091.0, 45.7275
7.789241860, 23.970, 2055.0, 45.3321
7.832707620, 23.970, 2084.0, 45.6508
7.876173380, 23.970, 2125.0, 46.0977
7.919639140, 23.970, 1998.0, 44.6990
7.963104900, 23.970, 2045.0, 45.2217
8.006570660, 23.970, 2098.0, 45.8039
8.050036420, 23.970, 2052.0, 45.2990
8.093502180, 23.970, 2120.0, 46.0435
8.136967940, 23.970, 2156.0, 46.4327
8.180433700, 23.970, 2143.0, 46.2925
8.223899460, 23.970, 2067.0, 45.4643
8.267365220, 23.970, 2001.0, 44.7325
8.310830980, 23.970, 2069.0, 45.4863
8.354296740, 23.970, 2099.0, 45.8148
8.397762500, 23.970, 2028.0, 45.0333
8.441228260, 23.970, 2058.0, 45.3652
8.484694020, 23.970, 2110.0, 45.9347
8.528159780, 23.970, 2059.0, 45.3762
8.571625540, 23.970, 2047.0, 45.2438
8.615091300, 23.970, 2105.0, 45.8803
8.658557060, 23.970, 2063.0, 45.4203
8.702022820, 23.970, 2081.0, 45.6180
8.745488580, 23.970, 2244.0, 47.3709
8.788954340, 23.970, 2113.0, 45.9674
8.832420100, 23.970, 2096.0, 45.7821
8.875885860, 23.970, 2097.0, 45.7930
8.919351620, 23.970, 2218.0, 47.0956
8.962817380, 23.970, 2112.0, 45.9565
9.006283140, 23.970, 2209.0, 47.0000
9.049748900, 23.970, 2202.0, 46.9255
9.093214660, 23.970, 2149.0, 46.3573
9.136680420, 23.970, 2164.0, 46.5188
9.180146180, 23.970, 2178.0, 46.6690
9.223611940, 23.970, 2106.0, 45.8912
9.267077700, 23.970, 2122.0, 46.0652
9.310543460, 23.970, 2088.0, 45.6946
9.354009220, 23.970, 2107.0, 45.9021
9.397474980, 23.970, 2121.0, 46.0543
9.440940740, 23.970, 2084.0, 45.6508
9.484406500, 23.970, 2178.0, 46.6690
9.527872260, 23.970, 2115.0, 45.9891
9.571338020, 23.970, 2122.0, 46.0652
9.614803780, 23.970, 2099.0, 45.8148
9.658269540, 23.970, 2028.0, 45.0333
9.701735300, 23.970, 2140.0, 46.2601
9.745201060, 23.970, 2195.0, 46.8508
9.788666820, 23.970, 2092.0, 45.7384
9.832132580, 23.970, 2128.0, 46.1303
9.875598340, 23.970, 2088.0, 45.6946
9.919064100, 23.970, 2042.0, 45.1885
9.962529860, 23.970, 2095.0, 45.7712
10.005995620, 23.970, 2079.0, 45.5961
10.049461380, 23.970, 2158.0, 46.4543
10.092927140, 23.970, 2003.0, 44.7549
10.136392900, 23.970, 2009.0, 44.8219
10.179858660, 23.970, 2094.0, 45.7602
10.223324420, 23.970, 2048.0, 45.2548
10.266790180, 23.970, 2112.0, 45.9565
10.310255940, 23.970, 2027.0, 45.0222
10.353721700, 23.970, 2087.0, 45.6837
10.397187460, 23.970, 2105.0, 45.8803
10.440653220, 23.970, 2100.0, 45.8258
10.484118980, 23.970, 2100.0, 45.8258
10.527584740, 23.970, 1952.0, 44.1814
10.571050500, 23.970, 2144.0, 46.3033
10.614516260, 23.970, 2004.0, 44.7661
10.657982020, 23.970, 2151.0, 46.3789
10.701447780, 23.970, 2051.0, 45.2880
10.744913540, 23.970, 2051.0, 45.2880
10.788379300, 23.970, 2027.0, 45.0222
10.831845060, 23.970, 2036.0, 45.1221
10.875310820, 23.970, 2134.0, 46.1952
10.918776580, 23.970, 2032.0, 45.0777
10.962242340, 23.970, 2056.0, 45.3431
11.005708100, 23.970, 2018.0, 44.9222
11.049173860, 23.970, 2133.0, 46.1844
11.092639620, 23.970, 2088.0, 45.6946
11.136105380, 23.970, 2069.0, 45.4863
11.179571140, 23.970, 2066.0, 45.4533
11.223036900, 23.970, 2123.0, 46.0760
11.266502660, 23.970, 2080.0, 45.6070
11.309968420, 23.970, 2006.0, 44.7884
11.353434180, 23.970, 2102.0, 45.8476
11.396899940, 23.970, 2051.0, 45.2880
11.440365700, 23.970, 2114.0, 45.9783
11.483831460, 23.970, 2024.0, 44.9889
11.527297220, 23.970, 2003.0, 44.7549
11.570762980, 23.970, 2023.0, 44.9778
11.614228740, 23.970, 2126.0, 46.1086
11.657694500, 23.970, 2063.0, 45.4203
11.701160260, 23.970, 2107.0, 45.9021
11.744626020, 23.970, 2042.0, 45.1885
11.788091780, 23.970, 2043.0, 45.1996
11.831557540, 23.970, 2086.0, 45.6727
11.875023300, 23.970, 2165.0, 46.5296
11.918489060, 23.970, 2074.0, 45.5412
11.961954820, 23.970, 2044.0, 45.2106
12.005420580, 23.970, 2184.0, 46.7333
12.048886340, 23.970, 1985.0, 44.5533
12.092352100, 23.970, 2131.0, 46.1628
12.135817860, 23.970, 2176.0, 46.6476
12.179283620, 23.970, 2213.0, 47.0425
12.222749380, 23.970, 2159.0, 46.4650
12.266215140, 23.970, 2193.0, 46.8295
12.309680900, 23.970, 2147.0, 46.3357
12.353146660, 23.970, 2228.0, 47.2017
12.396612420, 23.970, 2113.0, 45.9674
12.440078180, 23.970, 2110.0, 45.9347
12.483543940, 23.970, 2144.0, 46.3033
12.527009700, 23.970, 2129.0, 46.1411
12.570475460, 23.970, 2224.0, 47.1593
12.613941220, 23.970, 2304.0, 48.0000
12.657406980, 23.970, 2236.0, 47.2864
12.700872740, 23.970, 2210.0, 47.0106
12.744338500, 23.970, 2205.0, 46.9574
12.787804260, 23.970, 2286.0, 47.8121
12.831270020, 23.970, 2220.0, 47.1169
12.874735780, 23.970, 2230.0, 47.2229
12.918201540, 23.970, 2124.0, 46.0869
12.961667300, 23.970, 2263.0, 47.5710
13.005133060, 23.970, 2168.0, 46.5618
13.048598820, 23.970, 2343.0, 48.4045
13.092064580, 23.970, 2334.0, 48.3115
13.135530340, 23.970, 2214.0, 47.0532
13.178996100, 23.970, 2331.0, 48.2804
13.222461860, 23.970, 2292.0, 47.8748
13.265927620, 23.970, 2288.0, 47.8330
13.309393380, 23.970, 2374.0, 48.7237
13.352859140, 23.970, 2407.0, 49.0612
13.396324900, 23.970, 2399.0, 48.9796
13.439790660, 23.970, 2394.0, 48.9285
13.483256420, 23.970, 2356.0, 48.5386
13.526722180, 23.970, 2358.0, 48.5592
13.570187940, 23.970, 2392.0, 48.9081
13.613653700, 23.970, 2312.0, 48.0833
13.657119460, 23.970, 2509.0, 50.0899
13.700585220, 23.970, 2474.0, 49.7393
13.744050980, 23.970, 2537.0, 50.3686
13.787516740, 23.970, 2537.0, 50.3686
13.830982500, 23.970, 2485.0, 49.8498
13.874448260, 23.970, 2504.0, 50.0400
13.917914020, 23.970, 2572.0, 50.7149
13.961379780, 23.970, 2486.0, 49.8598
14.004845540, 23.970, 2659.0, 51.5655
14.048311300, 23.970, 2613.0, 51.1175
14.091777060, 23.970, 2629.0, 51.2738
14.135242820, 23.970, 2542.0, 50.4183
14.178708580, 23.970, 2549.0, 50.4876
14.222174340, 23.970, 2547.0, 50.4678
14.265640100, 23.970, 2714.0, 52.0961
14.309105860, 23.970, 2626.0, 51.2445
14.352571620, 23.970, 2651.0, 51.4879
14.396037380, 23.970, 2759.0, 52.5262
14.439503140, 23.970, 2703.0, 51.9904
14.482968900, 23.970, 2717.0, 52.1249
14.526434660, 23.970, 2820.0, 53.1037
14.569900420, 23.970, 2768.0, 52.6118
14.613366180, 23.970, 2802.0, 52.9339
14.656831940, 23.970, 2832.0, 53.2165
14.700297700, 23.970, 2829.0, 53.1883
14.743763460, 23.970, 2748.0, 52.4214
14.787229220, 23.970, 2865.0, 53.5257
14.830694980, 23.970, 2912.0, 53.9630
14.874160740, 23.970, 2891.0, 53.7680
14.917626500, 23.970, 2969.0, 54.4885
14.961092260, 23.970, 3043.0, 55.1634
15.004558020, 23.970, 3004.0, 54.8088
15.048023780, 23.970, 3008.0, 54.8452
15.091489540, 23.970, 3119.0, 55.8480
15.134955300, 23.970, 3113.0, 55.7943
15.178421060, 23.970, 3164.0, 56.2494
15.221886820, 23.970, 3132.0, 55.9643
15.265352580, 23.970, 3222.0, 56.7627
15.308818340, 23.970, 3237.0, 56.8946
15.352284100, 23.970, 3303.0, 57.4717
15.395749860, 23.970, 3130.0, 55.9464
15.439215620, 23.970, 3237.0, 56.8946
15.482681380, 23.970, 3309.0, 57.5239
15.526147140, 23.970, 3308.0, 57.5152
15.569612900, 23.970, 3349.0, 57.8705
15.613078660, 23.970, 3404.0, 58.3438
15.656544420, 23.970, 3320.0, 57.6194
15.700010180, 23.970, 3430.0, 58.5662
15.743475940, 23.970, 3478.0, 58.9746
15.786941700, 23.970, 3421.0, 58.4893
15.830407460, 23.970, 3531.0, 59.4222
15.873873220, 23.970, 3759.0, 61.3107
15.917338980, 23.970, 3679.0, 60.6548
15.960804740, 23.970, 3552.0, 59.5987
16.004270500, 23.970, 3763.0, 61.3433
16.047736260, 23.970, 3771.0, 61.4085
16.091202020, 23.970, 3725.0, 61.0328
16.134667780, 23.970, 3739.0, 61.1474
16.178133540, 23.970, 3853.0, 62.0725
16.221599300, 23.970, 3804.0, 61.6766
16.265065060, 23.970, 3807.0, 61.7009
16.308530820, 23.970, 3986.0, 63.1348
16.351996580, 23.970, 3985.0, 63.1269
16.395462340, 23.970, 3963.0, 62.9524
16.438928100, 23.970, 4025.0, 63.4429
16.482393860, 23.970, 4030.0, 63.4823
16.525859620, 23.970, 4067.0, 63.7730
16.569325380, 23.970, 4168.0, 64.5600
16.612791140, 23.970, 4182.0, 64.6684
16.656256900, 23.970, 4217.0, 64.9384
16.699722660, 23.970, 4286.0, 65.4675
16.743188420, 23.970, 4316.0, 65.6963
16.786654180, 23.970, 4378.0, 66.1665
16.830119940, 23.970, 4332.0, 65.8179
16.873585700, 23.970, 4424.0, 66.5132
16.917051460, 23.970, 4493.0, 67.0298
16.960517220, 23.970, 4456.0, 66.7533
17.003982980, 23.970, 4581.0, 67.6831
17.047448740, 23.970, 4609.0, 67.8896
17.090914500, 23.970, 4605.0, 67.8602
17.134380260, 23.970, 4728.0, 68.7605
17.177846020, 23.970, 4579.0, 67.6683
17.221311780, 23.970, 4745.0, 68.8840
17.264777540, 23.970, 4842.0, 69.5845
17.308243300, 23.970, 4838.0, 69.5557
17.351709060, 23.970, 4863.0, 69.7352
17.395174820, 23.970, 4952.0, 70.3704
17.438640580, 23.970, 4958.0, 70.4131
17.482106340, 23.970, 4963.0, 70.4486
17.525572100, 23.970, 4990.0, 70.6399
17.569037860, 23.970, 5084.0, 71.3022
17.612503620, 23.970, 5104.0, 71.4423
17.655969380, 23.970, 5143.0, 71.7147
17.699435140, 23.970, 5157.0, 71.8123
17.742900900, 23.970, 5339.0, 73.0685
17.786366660, 23.970, 5263.0, 72.5465
17.829832420, 23.970, 5269.0, 72.5879
17.873298180, 23.970, 5432.0, 73.7021
17.916763940, 23.970, 5421.0, 73.6274
17.960229700, 23.970, 5551.0, 74.5050
18.003695460, 23.970, 5672.0, 75.3127
18.047161220, 23.970, 5702.0, 75.5116
18.090626980, 23.970, 5844.0, 76.4461
18.134092740, 23.970, 5912.0, 76.8895
18.177558500, 23.970, 6012.0, 77.5371
18.221024260, 23.970, 6016.0, 77.5629
18.264490020, 23.970, 6194.0, 78.7020
18.307955780, 23.970, 6344.0, 79.6492
18.351421540, 23.970, 6419.0, 80.1187
18.394887300, 23.970, 6783.0, 82.3590
18.438353060, 23.970, 6871.0, 82.8915
18.481818820, 23.970, 7104.0, 84.2852
18.525284580, 23.970, 7390.0, 85.9651
18.568750340, 23.970, 8094.0, 89.9667
18.612216100, 23.970, 8140.0, 90.2219
18.655681860, 23.970, 8611.0, 92.7955
18.699147620, 23.970, 8999.0, 94.8631
18.742613380, 23.970, 9766.0, 98.8231
18.786079140, 23.970, 10171.0, 100.8514
18.829544900, 23.970, 10607.0, 102.9903
18.873010660, 23.970, 10897.0, 104.3887
18.916476420, 23.970, 11212.0, 105.8867
18.959942180, 23.970, 11191.0, 105.7875
19.003407940, 23.970, 11240.0, 106.0189
19.046873700, 23.970, 11025.0, 105.0000
19.090339460, 23.970, 11115.0, 105.4277
19.133805220, 23.970, 10316.0, 101.5677
19.177270980, 23.970, 10167.0, 100.8315
19.220736740, 23.970, 9688.0, 98.4276
19.264202500, 23.970, 9343.0, 96.6592
19.307668260, 23.970, 8912.0, 94.4034
19.351134020, 23.970, 8245.0, 90.8020
19.394599780, 23.970, 8231.0, 90.7249
19.438065540, 23.970, 7861.0, 88.6623
19.481531300, 23.970, 7472.0, 86.4407
19.524997060, 23.970, 7281.0, 85.3288
19.568462820, 23.970, 7083.0, 84.1606
19.611928580, 23.970, 6970.0, 83.4865
19.655394340, 23.970, 6908.0, 83.1144
19.698860100, 23.970, 6571.0, 81.0617
19.742325860, 23.970, 6597.0, 81.2219
19.785791620, 23.970, 6479.0, 80.4922
19.829257380, 23.970, 6439.0, 80.2434
19.872723140, 23.970, 6343.0, 79.6430
19.916188900, 23.970, 6272.0, 79.1960
19.959654660, 23.970, 6139.0, 78.3518
20.003120420, 23.970, 6197.0, 78.7210
20.046586180, 23.970, 6136.0, 78.3326
20.090051940, 23.970, 6033.0, 77.6724
20.133517700, 23.970, 6238.0, 78.9810
20.176983460, 23.970, 6084.0, 78.0000
20.220449220, 23.970, 6077.0, 77.9551
20.263914980, 23.970, 6104.0, 78.1281
20.307380740, 23.970, 6111.0, 78.1729
20.350846500, 23.970, 6243.0, 79.0127
20.394312260, 23.970, 6257.0, 79.1012
20.437778020, 23.970, 6281.0, 79.2528
20.481243780, 23.970, 6345.0, 79.6555
20.524709540, 23.970, 6571.0, 81.0617
20.568175300, 23.970, 6577.0, 81.0987
20.611641060, 23.970, 6651.0, 81.5537
20.655106820, 23.970, 6735.0, 82.0670
20.698572580, 23.970, 6748.0, 82.1462
20.742038340, 23.970, 6845.0, 82.7345
20.785504100, 23.970, 7115.0, 84.3505
20.828969860, 23.970, 6959.0, 83.4206
20.872435620, 23.970, 7160.0, 84.6168
20.915901380, 23.970, 7247.0, 85.1293
20.959367140, 23.970, 7209.0, 84.9058
21.002832900, 23.970, 7085.0, 84.1724
21.046298660, 23.970, 6943.0, 83.3247
21.089764420, 23.970, 6743.0, 82.1158
21.133230180, 23.970, 6763.0, 82.2375
21.176695940, 23.970, 6564.0, 81.0185
21.220161700, 23.970, 6650.0, 81.5475
21.263627460, 23.970, 6525.0, 80.7775
21.307093220, 23.970, 6248.0, 79.0443
21.350558980, 23.970, 6230.0, 78.9303
21.394024740, 23.970, 6012.0, 77.5371
21.437490500, 23.970, 6178.0, 78.6003
21.480956260, 23.970, 5951.0, 77.1427
21.524422020, 23.970, 5829.0, 76.3479
21.567887780, 23.970, 5752.0, 75.8419
21.611353540, 23.970, 5749.0, 75.8222
21.654819300, 23.970, 5657.0, 75.2130
21.698285060, 23.970, 5465.0, 73.9256
21.741750820, 23.970, 5548.0, 74.4849
21.785216580, 23.970, 5336.0, 73.0479
21.828682340, 23.970, 5392.0, 73.4302
21.872148100, 23.970, 5383.0, 73.3689
21.915613860, 23.970, 5497.0, 74.1418
21.959079620, 23.970, 5405.0, 73.5187
22.002545380, 23.970, 5343.0, 73.0958
22.046011140, 23.970, 5335.0, 73.0411
22.089476900, 23.970, 5431.0, 73.6953
22.132942660, 23.970, 5613.0, 74.9200
22.176408420, 23.970, 5732.0, 75.7100
22.219874180, 23.970, 5893.0, 76.7659
22.263339940, 23.970, 5844.0, 76.4461
22.306805700, 23.970, 6046.0, 77.7560
22.350271460, 23.970, 6250.0, 79.0569
22.393737220, 23.970, 6275.0, 79.2149
22.437202980, 23.970, 6529.0, 80.8022
22.480668740, 23.970, 6759.0, 82.2131
22.524134500, 23.970, 6726.0, 82.0122
22.567600260, 23.970, 7179.0, 84.7290
22.611066020, 23.970, 7219.0, 84.9647
22.654531780, 23.970, 7020.0, 83.7854
22.697997540, 23.970, 7112.0, 84.3327
22.741463300, 23.970, 7403.0, 86.0407
22.784929060, 23.970, 7166.0, 84.6522
22.828394820, 23.970, 7436.0, 86.2322
22.871860580, 23.970, 7142.0, 84.5104
22.915326340, 23.970, 7058.0, 84.0119
22.958792100, 23.970, 7006.0, 83.7019
23.002257860, 23.970, 6984.0, 83.5703
23.045723620, 23.970, 6735.0, 82.0670
23.089189380, 23.970, 6534.0, 80.8332
23.132655140, 23.970, 6346.0, 79.6618
23.176120900, 23.970, 6154.0, 78.4474
23.219586660, 23.970, 6123.0, 78.2496
23.263052420, 23.970, 5956.0, 77.1751
23.306518180, 23.970, 5703.0, 75.5182
23.349983940, 23.970, 5583.0, 74.7195
23.393449700, 23.970, 5260.0, 72.5259
23.436915460, 23.970, 5311.0, 72.8766
23.480381220, 23.970, 5240.0, 72.3878
23.523846980, 23.970, 4929.0, 70.2068
23.567312740, 23.970, 4794.0, 69.2387
23.610778500, 23.970, 4668.0, 68.3228
23.654244260, 23.970, 4534.0, 67.3350
23.697710020, 23.970, 4547.0, 67.4314
23.741175780, 23.970, 4413.0, 66.4304
23.784641540, 23.970, 4341.0, 65.8863
23.828107300, 23.970, 4223.0, 64.9846
23.871573060, 23.970, 4120.0, 64.1872
23.915038820, 23.970, 4082.0, 63.8905
23.958504580, 23.970, 3932.0, 62.7057
24.001970340, 23.970, 3965.0, 62.9682
24.045436100, 23.970, 3857.0, 62.1048
24.088901860, 23.970, 3747.0, 61.2127
24.132367620, 23.970, 3590.0, 59.9166
24.175833380, 23.970, 3548.0, 59.5651
24.219299140, 23.970, 3548.0, 59.5651
24.262764900, 23.970, 3502.0, 59.1777
24.306230660, 23.970, 3432.0, 58.5833
24.349696420, 23.970, 3419.0, 58.4722
24.393162180, 23.970, 3342.0, 57.8100
24.436627940, 23.970, 3307.0, 57.5065
24.480093700, 23.970, 3209.0, 56.6480
24.523559460, 23.970, 3177.0, 56.3649
24.567025220, 23.970, 3191.0, 56.4889
24.610490980, 23.970, 3105.0, 55.7225
24.653956740, 23.970, 3070.0, 55.4076
24.697422500, 23.970, 3122.0, 55.8749
24.740888260, 23.970, 3117.0, 55.8301
24.784354020, 23.970, 3006.0, 54.8270
24.827819780, 23.970, 3092.0, 55.6058
24.871285540, 23.970, 3115.0, 55.8122
24.914751300, 23.970, 2974.0, 54.5344
24.958217060, 23.970, 2920.0, 54.0370
25.001682820, 23.970, 2923.0, 54.0648
25.045148580, 23.970, 2852.0, 53.4041
25.088614340, 23.970, 2982.0, 54.6077
25.132080100, 23.970, 2792.0, 52.8394
25.175545860, 23.970, 2835.0, 53.2447
25.219011620, 23.970, 2768.0, 52.6118
25.262477380, 23.970, 2849.0, 53.3760
25.305943140, 23.970, 2794.0, 52.8583
25.349408900, 23.970, 2909.0, 53.9351
25.392874660, 23.970, 2736.0, 52.3068
25.436340420, 23.970, 2894.0, 53.7959
25.479806180, 23.970, 2779.0, 52.7162
25.523271940, 23.970, 2719.0, 52.1440
25.566737700, 23.970, 2716.0, 52.1153
25.610203460, 23.970, 2634.0, 51.3225
25.653669220, 23.970, 2758.0, 52.5167
25.697134980, 23.970, 2667.0, 51.6430
25.740600740, 23.970, 2652.0, 51.4976
25.784066500, 23.970, 2623.0, 51.2152
25.827532260, 23.970, 2655.0, 51.5267
25.870998020, 23.970, 2670.0, 51.6720
25.914463780, 23.970, 2583.0, 50.8232
25.957929540, 23.970, 2601.0, 51.0000
26.001395300, 23.970, 2617.0, 51.1566
26.044861060, 23.970, 2680.0, 51.7687
26.088326820, 23.970, 2648.0, 51.4587
26.131792580, 23.970, 2470.0, 49.6991
26.175258340, 23.970, 2572.0, 50.7149
26.218724100, 23.970, 2611.0, 51.0979
26.262189860, 23.970, 2580.0, 50.7937
26.305655620, 23.970, 2632.0, 51.3030
26.349121380, 23.970, 2557.0, 50.5668
26.392587140, 23.970, 2427.0, 49.2646
26.436052900, 23.970, 2522.0, 50.2195
26.479518660, 23.970, 2555.0, 50.5470
26.522984420, 23.970, 2501.0, 50.0100
26.566450180, 23.970, 2474.0, 49.7393
26.609915940, 23.970, 2528.0, 50.2792
26.653381700, 23.970, 2445.0, 49.4469
26.696847460, 23.970, 2508.0, 50.0799
26.740313220, 23.970, 2444.0, 49.4368
26.783778980, 23.970, 2368.0, 48.6621
26.827244740, 23.970, 2425.0, 49.2443
26.870710500, 23.970, 2447.0, 49.4672
26.914176260, 23.970, 2418.0, 49.1732
26.957642020, 23.970, 2443.0, 49.4267
27.001107780, 23.970, 2462.0, 49.6185
27.044573540, 23.970, 2359.0, 48.5695
27.088039300, 23.970, 2372.0, 48.7032
27.131505060, 23.970, 2387.0, 48.8569
27.174970820, 23.970, 2332.0, 48.2908
27.218436580, 23.970, 2369.0, 48.6724
27.261902340, 23.970, 2297.0, 47.9270
27.305368100, 23.970, 2404.0, 49.0306
27.348833860, 23.970, 2345.0, 48.4252
27.392299620, 23.970, 2292.0, 47.8748
27.435765380, 23.970, 2414.0, 49.1325
27.479231140, 23.970, 2281.0, 47.7598
27.522696900, 23.970, 2313.0, 48.0937
27.566162660, 23.970, 2320.0, 48.1664
27.609628420, 23.970, 2223.0, 47.1487
27.653094180, 23.970, 2405.0, 49.0408
27.696559940, 23.970, 2308.0, 48.0416
27.740025700, 23.970, 2245.0, 47.3814
27.783491460, 23.970, 2296.0, 47.9166
27.826957220, 23.970, 2333.0, 48.3011
27.870422980, 23.970, 2352.0, 48.4974
27.913888740, 23.970, 2308.0, 48.0416
27.957354500, 23.970, 2262.0, 47.5605
28.000820260, 23.970, 2298.0, 47.9375
28.044286020, 23.970, 2460.0, 49.5984
28.087751780, 23.970, 2421.0, 49.2037
28.131217540, 23.970, 2517.0, 50.1697
28.174683300, 23.970, 2417.0, 49.1630
28.218149060, 23.970, 2524.0, 50.2394
28.261614820, 23.970, 2617.0, 51.1566
28.305080580, 23.970, 2694.0, 51.9038
28.348546340, 23.970, 2845.0, 53.3385
28.392012100, 23.970, 2794.0, 52.8583
28.435477860, 23.970, 2865.0, 53.5257
28.478943620, 23.970, 2848.0, 53.3667
28.522409380, 23.970, 3062.0, 55.3353
28.565875140, 23.970, 3194.0, 56.5155
28.609340900, 23.970, 3128.0, 55.9285
28.652806660, 23.970, 3184.0, 56.4269
28.696272420, 23.970, 3274.0, 57.2189
28.739738180, 23.970, 3346.0, 57.8446
28.783203940, 23.970, 3390.0, 58.2237
28.826669700, 23.970, 3445.0, 58.6941
28.870135460, 23.970, 3444.0, 58.6856
28.913601220, 23.970, 3406.0, 58.3609
28.957066980, 23.970, 3359.0, 57.9569
29.000532740, 23.970, 3375.0, 58.0948
29.043998500, 23.970, 3296.0, 57.4108
29.087464260, 23.970, 3325.0, 57.6628
29.130930020, 23.970, 3193.0, 56.5066
29.174395780, 23.970, 3289.0, 57.3498
29.217861540, 23.970, 3216.0, 56.7098
29.261327300, 23.970, 3295.0, 57.4021
29.304793060, 23.970, 3349.0, 57.8705
29.348258820, 23.970, 3443.0, 58.6771
29.391724580, 23.970, 3490.0, 59.0762
29.435190340, 23.970, 3141.0, 56.0446
29.478656100, 23.970, 2967.0, 54.4702
29.522121860, 23.970, 2715.0, 52.1057
29.565587620, 23.970, 2611.0, 51.0979
29.609053380, 23.970, 2544.0, 50.4381
29.652519140, 23.970, 2491.0, 49.9099
29.695984900, 23.970, 2418.0, 49.1732
29.739450660, 23.970, 2441.0, 49.4065
29.782916420, 23.970, 2400.0, 48.9898
29.826382180, 23.970, 2334.0, 48.3115
29.869847940, 23.970, 2246.0, 47.3920
29.913313700, 23.970, 2233.0, 47.2546
29.956779460, 23.970, 2189.0, 46.7868
30.000245220, 23.970, 2188.0, 46.7761
30.043710980, 23.970, 2224.0, 47.1593
30.087176740, 23.970, 2121.0, 46.0543
30.130642500, 23.970, 2181.0, 46.7012
30.174108260, 23.970, 2080.0, 45.6070
30.217574020, 23.970, 2118.0, 46.0217
30.261039780, 23.970, 2112.0, 45.9565
30.304505540, 23.970, 2031.0, 45.0666
30.347971300, 23.970, 1992.0, 44.6318
30.391437060, 23.970, 2050.0, 45.2769
30.434902820, 23.970, 2079.0, 45.5961
30.478368580, 23.970, 1958.0, 44.2493
30.521834340, 23.970, 2004.0, 44.7661
30.565300100, 23.970, 2016.0, 44.8999
30.608765860, 23.970, 1964.0, 44.3170
30.652231620, 23.970, 1938.0, 44.0227
30.695697380, 23.970, 1887.0, 43.4396
30.739163140, 23.970, 1964.0, 44.3170
30.782628900, 23.970, 1860.0, 43.1277
30.826094660, 23.970, 1876.0, 43.3128
30.869560420, 23.970, 1758.0, 41.9285
30.913026180, 23.970, 1772.0, 42.0951
30.956491940, 23.970, 1834.0, 42.8252
30.999957700, 23.970, 1792.0, 42.3320
31.043423460, 23.970, 1816.0, 42.6146
31.086889220, 23.970, 1753.0, 41.8688
31.130354980, 23.970, 1767.0, 42.0357
31.173820740, 23.970, 1786.0, 42.2611
31.217286500, 23.970, 1774.0, 42.1189
31.260752260, 23.970, 1699.0, 41.2189
31.304218020, 23.970, 1710.0, 41.3521
31.347683780, 23.970, 1777.0, 42.1545
31.391149540, 23.970, 1706.0, 41.3038
31.434615300, 23.970, 1710.0, 41.3521
31.478081060, 23.970, 1695.0, 41.1704
31.521546820, 23.970, 1703.0, 41.2674
31.565012580, 23.970, 1618.0, 40.2244
31.608478340, 23.970, 1647.0, 40.5832
31.651944100, 23.970, 1690.0, 41.1096
31.695409860, 23.970, 1673.0, 40.9023
31.738875620, 23.970, 1576.0, 39.6989
31.782341380, 23.970, 1638.0, 40.4722
31.825807140, 23.970, 1551.0, 39.3827
31.869272900, 23.970, 1627.0, 40.3361
31.912738660, 23.970, 1603.0, 40.0375
31.956204420, 23.970, 1569.0, 39.6106
31.999670180, 23.970, 1624.0, 40.2989
32.043135940, 23.970, 1619.0, 40.2368
32.086601700, 23.970, 1575.0, 39.6863
32.130067460, 23.970, 1592.0, 39.8999
32.173533220, 23.970, 1620.0, 40.2492
32.216998980, 23.970, 1557.0, 39.4588
32.260464740, 23.970, 1513.0, 38.8973
32.303930500, 23.970, 1633.0, 40.4104
32.347396260, 23.970, 1626.0, 40.3237
32.390862020, 23.970, 1614.0, 40.1746
32.434327780, 23.970, 1600.0, 40.0000
32.477793540, 23.970, 1647.0, 40.5832
32.521259300, 23.970, 1548.0, 39.3446
32.564725060, 23.970, 1647.0, 40.5832
32.608190820, 23.970, 1623.0, 40.2865
32.651656580, 23.970, 1552.0, 39.3954
32.695122340, 23.970, 1655.0, 40.6817
32.738588100, 23.970, 1705.0, 41.2916
32.782053860, 23.970, 1646.0, 40.5709
32.825519620, 23.970, 1653.0, 40.6571
32.868985380, 23.970, 1576.0, 39.6989
32.912451140, 23.970, 1650.0, 40.6202
32.955916900, 23.970, 1674.0, 40.9145
32.999382660, 23.970, 1640.0, 40.4969
33.042848420, 23.970, 1590.0, 39.8748
33.086314180, 23.970, 1610.0, 40.1248
33.129779940, 23.970, 1652.0, 40.6448
33.173245700, 23.970, 1587.0, 39.8372
33.216711460, 23.970, 1560.0, 39.4968
33.260177220, 23.970, 1598.0, 39.9750
33.303642980, 23.970, 1608.0, 40.0999
33.347108740, 23.970, 1611.0, 40.1373
33.390574500, 23.970, 1545.0, 39.3065
33.434040260, 23.970, 1555.0, 39.4335
33.477506020, 23.970, 1545.0, 39.3065
33.520971780, 23.970, 1578.0, 39.7240
33.564437540, 23.970, 1523.0, 39.0256
33.607903300, 23.970, 1496.0, 38.6782
33.651369060, 23.970, 1551.0, 39.3827
33.694834820, 23.970, 1610.0, 40.1248
33.738300580, 23.970, 1583.0, 39.7869
33.781766340, 23.970, 1428.0, 37.7889
33.825232100, 23.970, 1487.0, 38.5616
33.868697860, 23.970, 1441.0, 37.9605
33.912163620, 23.970, 1439.0, 37.9342
33.955629380, 23.970, 1513.0, 38.8973
33.999095140, 23.970, 1491.0, 38.6135
34.042560900, 23.970, 1424.0, 37.7359
34.086026660, 23.970, 1423.0, 37.7227
34.129492420, 23.970, 1438.0, 37.9210
34.172958180, 23.970, 1405.0, 37.4833
34.216423940, 23.970, 1441.0, 37.9605
34.259889700, 23.970, 1353.0, 36.7831
34.303355460, 23.970, 1421.0, 37.6962
34.346821220, 23.970, 1338.0, 36.5787
34.390286980, 23.970, 1359.0, 36.8646
34.433752740, 23.970, 1321.0, 36.3456
34.477218500, 23.970, 1329.0, 36.4555
34.520684260, 23.970, 1310.0, 36.1939
34.564150020, 23.970, 1383.0, 37.1887
34.607615780, 23.970, 1413.0, 37.5899
34.651081540, 23.970, 1258.0, 35.4683
34.694547300, 23.970, 1243.0, 35.2562
34.738013060, 23.970, 1285.0, 35.8469
34.781478820, 23.970, 1265.0, 35.5668
34.824944580, 23.970, 1329.0, 36.4555
34.868410340, 23.970, 1293.0, 35.9583
34.911876100, 23.970, 1320.0, 36.3318
34.955341860, 23.970, 1252.0, 35.3836
34.998807620, 23.970, 1309.0, 36.1801
35.042273380, 23.970, 1284.0, 35.8329
35.085739140, 23.970, 1238.0, 35.1852
35.129204900, 23.970, 1203.0, 34.6843
35.172670660, 23.970, 1266.0, 35.5809
35.216136420, 23.970, 1262.0, 35.5246
35.259602180, 23.970, 1283.0, 35.8190
35.303067940, 23.970, 1230.0, 35.0714
35.346533700, 23.970, 1198.0, 34.6121
35.389999460, 23.970, 1189.0, 34.4819
35.433465220, 23.970, 1214.0, 34.8425
35.476930980, 23.970, 1231.0, 35.0856
35.520396740, 23.970, 1226.0, 35.0143
35.563862500, 23.970, 1206.0, 34.7275
35.607328260, 23.970, 1182.0, 34.3802
35.650794020, 23.970, 1190.0, 34.4964
35.694259780, 23.970, 1188.0, 34.4674
35.737725540, 23.970, 1195.0, 34.5688
35.781191300, 23.970, 1252.0, 35.3836
35.824657060, 23.970, 1237.0, 35.1710
35.868122820, 23.970, 1254.0, 35.4119
35.911588580, 23.970, 1281.0, 35.7911
35.955054340, 23.970, 1214.0, 34.8425
35.998520100, 23.970, 1202.0, 34.6699
36.041985860, 23.970, 1193.0, 34.5398
36.085451620, 23.970, 1193.0, 34.5398
36.128917380, 23.970, 1148.0, 33.8821
36.172383140, 23.970, 1172.0, 34.2345
36.215848900, 23.970, 1157.0, 34.0147
36.259314660, 23.970, 1172.0, 34.2345
36.302780420, 23.970, 1223.0, 34.9714
36.346246180, 23.970, 1159.0, 34.0441
36.389711940, 23.970, 1181.0, 34.3657
36.433177700, 23.970, 1156.0, 34.0000
36.476643460, 23.970, 1169.0, 34.1906
36.520109220, 23.970, 1119.0, 33.4515
36.563574980, 23.970, 1184.0, 34.4093
36.607040740, 23.970, 1108.0, 33.2866
36.650506500, 23.970, 1150.0, 33.9116
36.693972260, 23.970, 1110.0, 33.3167
36.737438020, 23.970, 1193.0, 34.5398
36.780903780, 23.970, 1158.0, 34.0294
36.824369540, 23.970, 1150.0, 33.9116
36.867835300, 23.970, 1193.0, 34.5398
36.911301060, 23.970, 1197.0, 34.5977
36.954766820, 23.970, 1194.0, 34.5543
36.998232580, 23.970, 1190.0, 34.4964
37.041698340, 23.970, 1148.0, 33.8821
37.085164100, 23.970, 1189.0, 34.4819
37.128629860, 23.970, 1174.0, 34.2637
37.172095620, 23.970, 1184.0, 34.4093
37.215561380, 23.970, 1144.0, 33.8231
37.259027140, 23.970, 1173.0, 34.2491
37.302492900, 23.970, 1208.0, 34.7563
37.345958660, 23.970, 1146.0, 33.8526
37.389424420, 23.970, 1200.0, 34.6410
37.432890180, 23.970, 1138.0, 33.7343
37.476355940, 23.970, 1177.0, 34.3074
37.519821700, 23.970, 1094.0, 33.0757
37.563287460, 23.970, 1242.0, 35.2420
37.606753220, 23.970, 1209.0, 34.7707
37.650218980, 23.970, 1176.0, 34.2929
37.693684740, 23.970, 1225.0, 35.0000
37.737150500, 23.970, 1226.0, 35.0143
37.780616260, 23.970, 1242.0, 35.2420
37.824082020, 23.970, 1288.0, 35.8887
37.867547780, 23.970, 1229.0, 35.0571
37.911013540, 23.970, 1258.0, 35.4683
37.954479300, 23.970, 1283.0, 35.8190
37.997945060, 23.970, 1236.0, 35.1568
38.041410820, 23.970, 1288.0, 35.8887
38.084876580, 23.970, 1267.0, 35.5949
38.128342340, 23.970, 1241.0, 35.2278
38.171808100, 23.970, 1302.0, 36.0832
38.215273860, 23.970, 1218.0, 34.8999
38.258739620, 23.970, 1408.0, 37.5233
38.302205380, 23.970, 1251.0, 35.3695
38.345671140, 23.970, 1350.0, 36.7423
38.389136900, 23.970, 1374.0, 37.0675
38.432602660, 23.970, 1285.0, 35.8469
38.476068420, 23.970, 1381.0, 37.1618
38.519534180, 23.970, 1413.0, 37.5899
38.562999940, 23.970, 1474.0, 38.3927
38.606465700, 23.970, 1437.0, 37.9078
38.649931460, 23.970, 1404.0, 37.4700
38.693397220, 23.970, 1442.0, 37.9737
38.736862980, 23.970, 1393.0, 37.3229
38.780328740, 23.970, 1366.0, 36.9594
38.823794500, 23.970, 1477.0, 38.4318
38.867260260, 23.970, 1518.0, 38.9615
38.910726020, 23.970, 1478.0, 38.4448
38.954191780, 23.970, 1468.0, 38.3145
38.997657540, 23.970, 1445.0, 38.0132
39.041123300, 23.970, 1361.0, 36.8917
39.084589060, 23.970, 1420.0, 37.6829
39.128054820, 23.970, 1411.0, 37.5633
39.171520580, 23.970, 1480.0, 38.4708
39.214986340, 23.970, 1403.0, 37.4566
39.258452100, 23.970, 1570.0, 39.6232
39.301917860, 23.970, 1502.0, 38.7556
39.345383620, 23.970, 1509.0, 38.8458
39.388849380, 23.970, 1629.0, 40.3609
39.432315140, 23.970, 1532.0, 39.1408
39.475780900, 23.970, 1499.0, 38.7169
39.519246660, 23.970, 1345.0, 36.6742
39.562712420, 23.970, 1365.0, 36.9459
39.606178180, 23.970, 1326.0, 36.4143
39.649643940, 23.970, 1328.0, 36.4417
39.693109700, 23.970, 1346.0, 36.6879
39.736575460, 23.970, 1367.0, 36.9730
39.780041220, 23.970, 1294.0, 35.9722
39.823506980, 23.970, 1297.0, 36.0139
39.866972740, 23.970, 1301.0, 36.0694
39.910438500, 23.970, 1264.0, 35.5528
39.953904260, 23.970, 1283.0, 35.8190
39.997370020, 23.970, 1278.0, 35.7491
40.040835780, 23.970, 1245.0, 35.2846
40.084301540, 23.970, 1271.0, 35.6511
40.127767300, 23.970, 1220.0, 34.9285
40.171233060, 23.970, 1241.0, 35.2278
40.214698820, 23.970, 1232.0, 35.0999
40.258164580, 23.970, 1255.0, 35.4260
40.301630340, 23.970, 1279.0, 35.7631
40.345096100, 23.970, 1200.0, 34.6410
40.388561860, 23.970, 1265.0, 35.5668
40.432027620, 23.970, 1239.0, 35.1994
40.475493380, 23.970, 1249.0, 35.3412
40.518959140, 23.970, 1229.0, 35.0571
40.562424900, 23.970, 1318.0, 36.3043
40.605890660, 23.970, 1205.0, 34.7131
40.649356420, 23.970, 1254.0, 35.4119
40.692822180, 23.970, 1279.0, 35.7631
40.736287940, 23.970, 1239.0, 35.1994
40.779753700, 23.970, 1223.0, 34.9714
40.823219460, 23.970, 1262.0, 35.5246
40.866685220, 23.970, 1202.0, 34.6699
40.910150980, 23.970, 1260.0, 35.4965
40.953616740, 23.970, 1327.0, 36.4280
40.997082500, 23.970, 1252.0, 35.3836
41.040548260, 23.970, 1306.0, 36.1386
41.084014020, 23.970, 1208.0, 34.7563
41.127479780, 23.970, 1249.0, 35.3412
41.170945540, 23.970, 1185.0, 34.4238
41.214411300, 23.970, 1278.0, 35.7491
41.257877060, 23.970, 1301.0, 36.0694
41.301342820, 23.970, 1233.0, 35.1141
41.344808580, 23.970, 1242.0, 35.2420
41.388274340, 23.970, 1241.0, 35.2278
41.431740100, 23.970, 1232.0, 35.0999
41.475205860, 23.970, 1298.0, 36.0278
41.518671620, 23.970, 1265.0, 35.5668
41.562137380, 23.970, 1299.0, 36.0416
41.605603140, 23.970, 1209.0, 34.7707
41.649068900, 23.970, 1201.0, 34.6554
41.692534660, 23.970, 1225.0, 35.0000
41.736000420, 23.970, 1242.0, 35.2420
41.779466180, 23.970, 1197.0, 34.5977
41.822931940, 23.970, 1215.0, 34.8569
41.866397700, 23.970, 1217.0, 34.8855
41.909863460, 23.970, 1179.0, 34.3366
41.953329220, 23.970, 1268.0, 35.6090
41.996794980, 23.970, 1197.0, 34.5977
42.040260740, 23.970, 1195.0, 34.5688
42.083726500, 23.970, 1214.0, 34.8425
42.127192260, 23.970, 1167.0, 34.1614
42.170658020, 23.970, 1116.0, 33.4066
42.214123780, 23.970, 1077.0, 32.8177
42.257589540, 23.970, 1219.0, 34.9142
42.301055300, 23.970, 1143.0, 33.8083
42.344521060, 23.970, 1159.0, 34.0441
42.387986820, 23.970, 1164.0, 34.1174
42.431452580, 23.970, 1109.0, 33.3017
42.474918340, 23.970, 1122.0, 33.4963
42.518384100, 23.970, 1123.0, 33.5112
42.561849860, 23.970, 1166.0, 34.1467
42.605315620, 23.970, 1150.0, 33.9116
42.648781380, 23.970, 1146.0, 33.8526
42.692247140, 23.970, 1167.0, 34.1614
42.735712900, 23.970, 1112.0, 33.3467
42.779178660, 23.970, 1105.0, 33.2415
42.822644420, 23.970, 1163.0, 34.1028
42.866110180, 23.970, 1127.0, 33.5708
42.909575940, 23.970, 1133.0, 33.6601
42.953041700, 23.970, 1136.0, 33.7046
42.996507460, 23.970, 1111.0, 33.3317
43.039973220, 23.970, 1207.0, 34.7419
43.083438980, 23.970, 1192.0, 34.5254
43.126904740, 23.970, 1265.0, 35.5668
43.170370500, 23.970, 1242.0, 35.2420
43.213836260, 23.970, 1225.0, 35.0000
43.257302020, 23.970, 1201.0, 34.6554
43.300767780, 23.970, 1202.0, 34.6699
43.344233540, 23.970, 1053.0, 32.4500
43.387699300, 23.970, 1127.0, 33.5708
43.431165060, 23.970, 1026.0, 32.0312
43.474630820, 23.970, 1062.0, 32.5883
43.518096580, 23.970, 1162.0, 34.0881
43.561562340, 23.970, 1103.0, 33.2114
43.605028100, 23.970, 1117.0, 33.4215
43.648493860, 23.970, 1076.0, 32.8024
43.691959620, 23.970, 1080.0, 32.8634
43.735425380, 23.970, 1091.0, 33.0303
43.778891140, 23.970, 1091.0, 33.0303
43.822356900, 23.970, 1159.0, 34.0441
43.865822660, 23.970, 1081.0, 32.8786
43.909288420, 23.970, 1071.0, 32.7261
43.952754180, 23.970, 1118.0, 33.4365
43.996219940, 23.970, 1079.0, 32.8481
44.039685700, 23.970, 1088.0, 32.9848
44.083151460, 23.970, 1094.0, 33.0757
44.126617220, 23.970, 1078.0, 32.8329
44.170082980, 23.970, 1021.0, 31.9531
44.213548740, 23.970, 1071.0, 32.7261
44.257014500, 23.970, 1119.0, 33.4515
44.300480260, 23.970, 1055.0, 32.4808
44.343946020, 23.970, 1064.0, 32.6190
44.387411780, 23.970, 1082.0, 32.8938
44.430877540, 23.970, 1094.0, 33.0757
44.474343300, 23.970, 1094.0, 33.0757
44.517809060, 23.970, 1131.0, 33.6303
44.561274820, 23.970, 1115.0, 33.3916
44.604740580, 23.970, 1024.0, 32.0000
44.648206340, 23.970, 1059.0, 32.5423
44.691672100, 23.970, 1042.0, 32.2800
44.735137860, 23.970, 1065.0, 32.6343
44.778603620, 23.970, 1058.0, 32.5269
44.822069380, 23.970, 1105.0, 33.2415
44.865535140, 23.970, 1156.0, 34.0000
44.909000900, 23.970, 1078.0, 32.8329
44.952466660, 23.970, 1126.0, 33.5559
44.995932420, 23.970, 1062.0, 32.5883
45.039398180, 23.970, 1019.0, 31.9218
45.082863940, 23.970, 1082.0, 32.8938
45.126329700, 23.970, 1101.0, 33.1813
45.169795460, 23.970, 1036.0, 32.1870
45.213261220, 23.970, 1050.0, 32.4037
45.256726980, 23.970, 1106.0, 33.2566
45.300192740, 23.970, 1085.0, 32.9393
45.343658500, 23.970, 1075.0, 32.7872
45.387124260, 23.970, 1044.0, 32.3110
45.430590020, 23.970, 1052.0, 32.4345
45.474055780, 23.970, 1073.0, 32.7567
45.517521540, 23.970, 1041.0, 32.2645
45.560987300, 23.970, 1049.0, 32.3883
45.604453060, 23.970, 1069.0, 32.6956
45.647918820, 23.970, 1116.0, 33.4066
45.691384580, 23.970, 1094.0, 33.0757
45.734850340, 23.970, 1057.0, 32.5115
45.778316100, 23.970, 1073.0, 32.7567
45.821781860, 23.970, 1058.0, 32.5269
45.865247620, 23.970, 1038.0, 32.2180
45.908713380, 23.970, 1106.0, 33.2566
45.952179140, 23.970, 1129.0, 33.6006
45.995644900, 23.970, 1056.0, 32.4962
46.039110660, 23.970, 1062.0, 32.5883
46.082576420, 23.970, 1019.0, 31.9218
46.126042180, 23.970, 1129.0, 33.6006
46.169507940, 23.970, 1029.0, 32.0780
46.212973700, 23.970, 1026.0, 32.0312
46.256439460, 23.970, 1044.0, 32.3110
46.299905220, 23.970, 1064.0, 32.6190
46.343370980, 23.970, 1101.0, 33.1813
46.386836740, 23.970, 1059.0, 32.5423
46.430302500, 23.970, 1038.0, 32.2180
46.473768260, 23.970, 1134.0, 33.6749
46.517234020, 23.970, 1095.0, 33.0908
46.560699780, 23.970, 1095.0, 33.0908
46.604165540, 23.970, 1097.0, 33.1210
46.647631300, 23.970, 1016.0, 31.8748
46.691097060, 23.970, 1084.0, 32.9242
46.734562820, 23.970, 1159.0, 34.0441
46.778028580, 23.970, 1177.0, 34.3074
46.821494340, 23.970, 1144.0, 33.8231
46.864960100, 23.970, 1099.0, 33.1512
46.908425860, 23.970, 1187.0, 34.4529
46.951891620, 23.970, 1212.0, 34.8138
46.995357380, 23.970, 1209.0, 34.7707
47.038823140, 23.970, 1140.0, 33.7639
47.082288900, 23.970, 1314.0, 36.2491
47.125754660, 23.970, 1248.0, 35.3270
47.169220420, 23.970, 1230.0, 35.0714
47.212686180, 23.970, 1332.0, 36.4966
47.256151940, 23.970, 1245.0, 35.2846
47.299617700, 23.970, 1314.0, 36.2491
47.343083460, 23.970, 1354.0, 36.7967
47.386549220, 23.970, 1410.0, 37.5500
47.430014980, 23.970, 1452.0, 38.1051
47.473480740, 23.970, 1550.0, 39.3700
47.516946500, 23.970, 1493.0, 38.6394
47.560412260, 23.970, 1442.0, 37.9737
47.603878020, 23.970, 1364.0, 36.9324
47.647343780, 23.970, 1339.0, 36.5923
47.690809540, 23.970, 1261.0, 35.5106
47.734275300, 23.970, 1285.0, 35.8469
47.777741060, 23.970, 1208.0, 34.7563
47.821206820, 23.970, 1277.0, 35.7351
47.864672580, 23.970, 1219.0, 34.9142
47.908138340, 23.970, 1225.0, 35.0000
47.951604100, 23.970, 1199.0, 34.6266
47.995069860, 23.970, 1221.0, 34.9428
48.038535620, 23.970, 1191.0, 34.5109
48.082001380, 23.970, 1203.0, 34.6843
48.125467140, 23.970, 1152.0, 33.9411
48.168932900, 23.970, 1183.0, 34.3948
48.212398660, 23.970, 1209.0, 34.7707
48.255864420, 23.970, 1192.0, 34.5254
48.299330180, 23.970, 1195.0, 34.5688
48.342795940, 23.970, 1133.0, 33.6601
48.386261700, 23.970, 1249.0, 35.3412
48.429727460, 23.970, 1311.0, 36.2077
48.473193220, 23.970, 1333.0, 36.5103
48.516658980, 23.970, 1379.0, 37.1349
48.560124740, 23.970, 1239.0, 35.1994
48.603590500, 23.970, 1192.0, 34.5254
48.647056260, 23.970, 1125.0, 33.5410
48.690522020, 23.970, 1118.0, 33.4365
48.733987780, 23.970, 1093.0, 33.0606
48.777453540, 23.970, 1124.0, 33.5261
48.820919300, 23.970, 991.0, 31.4802
48.864385060, 23.970, 981.0, 31.3209
48.907850820, 23.970, 1025.0, 32.0156
48.951316580, 23.970, 1029.0, 32.0780
48.994782340, 23.970, 998.0, 31.5911
49.038248100, 23.970, 1013.0, 31.8277
49.081713860, 23.970, 996.0, 31.5595
49.125179620, 23.970, 987.0, 31.4166
49.168645380, 23.970, 1033.0, 32.1403
49.212111140, 23.970, 1001.0, 31.6386
49.255576900, 23.970, 1038.0, 32.2180
49.299042660, 23.970, 1019.0, 31.9218
49.342508420, 23.970, 1045.0, 32.3265
49.385974180, 23.970, 988.0, 31.4325
49.429439940, 23.970, 973.0, 31.1929
49.472905700, 23.970, 993.0, 31.5119
49.516371460, 23.970, 1025.0, 32.0156
49.559837220, 23.970, 976.0, 31.2410
49.603302980, 23.970, 975.0, 31.2250
49.646768740, 23.970, 994.0, 31.5278
49.690234500, 23.970, 997.0, 31.5753
49.733700260, 23.970, 1074.0, 32.7719
49.777166020, 23.970, 949.0, 30.8058
49.820631780, 23.970, 1036.0, 32.1870
49.864097540, 23.970, 1109.0, 33.3017
49.907563300, 23.970, 957.0, 30.9354
49.951029060, 23.970, 971.0, 31.1609
49.994494820, 23.970, 959.0, 30.9677