File: data/XRD/501023_4.csv
[Measurement conditions]
Sample identification,501203_4
Comment,
Anode material,Cu
K-Alpha1 wavelength,1.5405980
K-Alpha2 wavelength,1.5444260
Ratio K-Alpha2/K-Alpha1,0.500
Divergence slit,Fixed,0.38mm
Monochromator used,NO
Generator voltage, 40
Tube current, 15
File date and time,02/Apr/2025 11:05
Unit cell,
h k l, 0 0 0
Scan axis,Gonio
Scan range,5.002000000,49.999928040
Scan step size,0.0108664
No. of points, 4141
Scan type,CONTINUOUS
Time per step,23.970
[Scan points]
Angle, TimePerStep, Intensity, ESD
5.007433220, 23.970, 1478.0, 38.4448
5.050898980, 23.970, 1496.0, 38.6782
5.094364740, 23.970, 1574.0, 39.6737
5.137830500, 23.970, 1551.0, 39.3827
5.181296260, 23.970, 1567.0, 39.5854
5.224762020, 23.970, 1472.0, 38.3667
5.268227780, 23.970, 1563.0, 39.5348
5.311693540, 23.970, 1663.0, 40.7799
5.355159300, 23.970, 1626.0, 40.3237
5.398625060, 23.970, 1596.0, 39.9500
5.442090820, 23.970, 1574.0, 39.6737
5.485556580, 23.970, 1585.0, 39.8121
5.529022340, 23.970, 1607.0, 40.0874
5.572488100, 23.970, 1583.0, 39.7869
5.615953860, 23.970, 1633.0, 40.4104
5.659419620, 23.970, 1602.0, 40.0250
5.702885380, 23.970, 1683.0, 41.0244
5.746351140, 23.970, 1586.0, 39.8246
5.789816900, 23.970, 1695.0, 41.1704
5.833282660, 23.970, 1616.0, 40.1995
5.876748420, 23.970, 1712.0, 41.3763
5.920214180, 23.970, 1659.0, 40.7308
5.963679940, 23.970, 1619.0, 40.2368
6.007145700, 23.970, 1749.0, 41.8210
6.050611460, 23.970, 1766.0, 42.0238
6.094077220, 23.970, 1727.0, 41.5572
6.137542980, 23.970, 1668.0, 40.8412
6.181008740, 23.970, 1710.0, 41.3521
6.224474500, 23.970, 1745.0, 41.7732
6.267940260, 23.970, 1700.0, 41.2311
6.311406020, 23.970, 1646.0, 40.5709
6.354871780, 23.970, 1762.0, 41.9762
6.398337540, 23.970, 1686.0, 41.0609
6.441803300, 23.970, 1720.0, 41.4729
6.485269060, 23.970, 1730.0, 41.5933
6.528734820, 23.970, 1782.0, 42.2137
6.572200580, 23.970, 1786.0, 42.2611
6.615666340, 23.970, 1809.0, 42.5323
6.659132100, 23.970, 1776.0, 42.1426
6.702597860, 23.970, 1727.0, 41.5572
6.746063620, 23.970, 1834.0, 42.8252
6.789529380, 23.970, 1776.0, 42.1426
6.832995140, 23.970, 1802.0, 42.4500
6.876460900, 23.970, 1771.0, 42.0833
6.919926660, 23.970, 1714.0, 41.4005
6.963392420, 23.970, 1787.0, 42.2729
7.006858180, 23.970, 1759.0, 41.9404
7.050323940, 23.970, 1703.0, 41.2674
7.093789700, 23.970, 1848.0, 42.9884
7.137255460, 23.970, 1787.0, 42.2729
7.180721220, 23.970, 1725.0, 41.5331
7.224186980, 23.970, 1836.0, 42.8486
7.267652740, 23.970, 1789.0, 42.2966
7.311118500, 23.970, 1851.0, 43.0232
7.354584260, 23.970, 1902.0, 43.6119
7.398050020, 23.970, 1775.0, 42.1307
7.441515780, 23.970, 1854.0, 43.0581
7.484981540, 23.970, 1852.0, 43.0349
7.528447300, 23.970, 1861.0, 43.1393
7.571913060, 23.970, 1797.0, 42.3910
7.615378820, 23.970, 1848.0, 42.9884
7.658844580, 23.970, 1741.0, 41.7253
7.702310340, 23.970, 1749.0, 41.8210
7.745776100, 23.970, 1819.0, 42.6497
7.789241860, 23.970, 1803.0, 42.4617
7.832707620, 23.970, 1845.0, 42.9535
7.876173380, 23.970, 1813.0, 42.5793
7.919639140, 23.970, 1821.0, 42.6732
7.963104900, 23.970, 1821.0, 42.6732
8.006570660, 23.970, 1753.0, 41.8688
8.050036420, 23.970, 1769.0, 42.0595
8.093502180, 23.970, 1881.0, 43.3705
8.136967940, 23.970, 1739.0, 41.7013
8.180433700, 23.970, 1833.0, 42.8135
8.223899460, 23.970, 1784.0, 42.2374
8.267365220, 23.970, 1877.0, 43.3244
8.310830980, 23.970, 1825.0, 42.7200
8.354296740, 23.970, 1822.0, 42.6849
8.397762500, 23.970, 1865.0, 43.1856
8.441228260, 23.970, 1796.0, 42.3792
8.484694020, 23.970, 1852.0, 43.0349
8.528159780, 23.970, 1875.0, 43.3013
8.571625540, 23.970, 1845.0, 42.9535
8.615091300, 23.970, 1844.0, 42.9418
8.658557060, 23.970, 1819.0, 42.6497
8.702022820, 23.970, 1832.0, 42.8019
8.745488580, 23.970, 1823.0, 42.6966
8.788954340, 23.970, 1835.0, 42.8369
8.832420100, 23.970, 1843.0, 42.9302
8.875885860, 23.970, 1826.0, 42.7317
8.919351620, 23.970, 1816.0, 42.6146
8.962817380, 23.970, 1849.0, 43.0000
9.006283140, 23.970, 1817.0, 42.6263
9.049748900, 23.970, 1779.0, 42.1782
9.093214660, 23.970, 1867.0, 43.2088
9.136680420, 23.970, 1794.0, 42.3556
9.180146180, 23.970, 1754.0, 41.8808
9.223611940, 23.970, 1842.0, 42.9185
9.267077700, 23.970, 1859.0, 43.1161
9.310543460, 23.970, 1794.0, 42.3556
9.354009220, 23.970, 1847.0, 42.9767
9.397474980, 23.970, 1769.0, 42.0595
9.440940740, 23.970, 1863.0, 43.1625
9.484406500, 23.970, 1797.0, 42.3910
9.527872260, 23.970, 1821.0, 42.6732
9.571338020, 23.970, 1871.0, 43.2551
9.614803780, 23.970, 1865.0, 43.1856
9.658269540, 23.970, 1820.0, 42.6615
9.701735300, 23.970, 1902.0, 43.6119
9.745201060, 23.970, 1759.0, 41.9404
9.788666820, 23.970, 1782.0, 42.2137
9.832132580, 23.970, 1827.0, 42.7434
9.875598340, 23.970, 1811.0, 42.5558
9.919064100, 23.970, 1817.0, 42.6263
9.962529860, 23.970, 1838.0, 42.8719
10.005995620, 23.970, 1832.0, 42.8019
10.049461380, 23.970, 1882.0, 43.3820
10.092927140, 23.970, 1836.0, 42.8486
10.136392900, 23.970, 1879.0, 43.3474
10.179858660, 23.970, 1788.0, 42.2847
10.223324420, 23.970, 1826.0, 42.7317
10.266790180, 23.970, 1852.0, 43.0349
10.310255940, 23.970, 1824.0, 42.7083
10.353721700, 23.970, 1948.0, 44.1362
10.397187460, 23.970, 1847.0, 42.9767
10.440653220, 23.970, 1834.0, 42.8252
10.484118980, 23.970, 1843.0, 42.9302
10.527584740, 23.970, 1810.0, 42.5441
10.571050500, 23.970, 1851.0, 43.0232
10.614516260, 23.970, 1808.0, 42.5206
10.657982020, 23.970, 1832.0, 42.8019
10.701447780, 23.970, 1816.0, 42.6146
10.744913540, 23.970, 1917.0, 43.7836
10.788379300, 23.970, 1895.0, 43.5316
10.831845060, 23.970, 1938.0, 44.0227
10.875310820, 23.970, 1839.0, 42.8836
10.918776580, 23.970, 1903.0, 43.6234
10.962242340, 23.970, 1855.0, 43.0697
11.005708100, 23.970, 1926.0, 43.8862
11.049173860, 23.970, 1945.0, 44.1022
11.092639620, 23.970, 1755.0, 41.8927
11.136105380, 23.970, 1835.0, 42.8369
11.179571140, 23.970, 1891.0, 43.4856
11.223036900, 23.970, 1854.0, 43.0581
11.266502660, 23.970, 1945.0, 44.1022
11.309968420, 23.970, 1974.0, 44.4297
11.353434180, 23.970, 1947.0, 44.1248
11.396899940, 23.970, 1938.0, 44.0227
11.440365700, 23.970, 1953.0, 44.1928
11.483831460, 23.970, 1862.0, 43.1509
11.527297220, 23.970, 1897.0, 43.5546
11.570762980, 23.970, 1976.0, 44.4522
11.614228740, 23.970, 1979.0, 44.4860
11.657694500, 23.970, 1899.0, 43.5775
11.701160260, 23.970, 1926.0, 43.8862
11.744626020, 23.970, 1954.0, 44.2041
11.788091780, 23.970, 1958.0, 44.2493
11.831557540, 23.970, 1896.0, 43.5431
11.875023300, 23.970, 1856.0, 43.0813
11.918489060, 23.970, 1926.0, 43.8862
11.961954820, 23.970, 1879.0, 43.3474
12.005420580, 23.970, 2041.0, 45.1774
12.048886340, 23.970, 1912.0, 43.7264
12.092352100, 23.970, 1936.0, 44.0000
12.135817860, 23.970, 2035.0, 45.1110
12.179283620, 23.970, 1902.0, 43.6119
12.222749380, 23.970, 2023.0, 44.9778
12.266215140, 23.970, 2070.0, 45.4973
12.309680900, 23.970, 2035.0, 45.1110
12.353146660, 23.970, 2092.0, 45.7384
12.396612420, 23.970, 2035.0, 45.1110
12.440078180, 23.970, 2012.0, 44.8553
12.483543940, 23.970, 2138.0, 46.2385
12.527009700, 23.970, 2018.0, 44.9222
12.570475460, 23.970, 2070.0, 45.4973
12.613941220, 23.970, 2017.0, 44.9110
12.657406980, 23.970, 2070.0, 45.4973
12.700872740, 23.970, 2169.0, 46.5725
12.744338500, 23.970, 2025.0, 45.0000
12.787804260, 23.970, 2110.0, 45.9347
12.831270020, 23.970, 2094.0, 45.7602
12.874735780, 23.970, 2061.0, 45.3982
12.918201540, 23.970, 2181.0, 46.7012
12.961667300, 23.970, 2182.0, 46.7119
13.005133060, 23.970, 2186.0, 46.7547
13.048598820, 23.970, 2116.0, 46.0000
13.092064580, 23.970, 2164.0, 46.5188
13.135530340, 23.970, 2194.0, 46.8402
13.178996100, 23.970, 2223.0, 47.1487
13.222461860, 23.970, 2207.0, 46.9787
13.265927620, 23.970, 2206.0, 46.9681
13.309393380, 23.970, 2229.0, 47.2123
13.352859140, 23.970, 2341.0, 48.3839
13.396324900, 23.970, 2295.0, 47.9062
13.439790660, 23.970, 2251.0, 47.4447
13.483256420, 23.970, 2348.0, 48.4562
13.526722180, 23.970, 2301.0, 47.9687
13.570187940, 23.970, 2339.0, 48.3632
13.613653700, 23.970, 2317.0, 48.1352
13.657119460, 23.970, 2465.0, 49.6488
13.700585220, 23.970, 2401.0, 49.0000
13.744050980, 23.970, 2409.0, 49.0816
13.787516740, 23.970, 2424.0, 49.2341
13.830982500, 23.970, 2329.0, 48.2597
13.874448260, 23.970, 2439.0, 49.3862
13.917914020, 23.970, 2417.0, 49.1630
13.961379780, 23.970, 2529.0, 50.2892
14.004845540, 23.970, 2535.0, 50.3488
14.048311300, 23.970, 2540.0, 50.3984
14.091777060, 23.970, 2540.0, 50.3984
14.135242820, 23.970, 2472.0, 49.7192
14.178708580, 23.970, 2603.0, 51.0196
14.222174340, 23.970, 2572.0, 50.7149
14.265640100, 23.970, 2750.0, 52.4404
14.309105860, 23.970, 2656.0, 51.5364
14.352571620, 23.970, 2678.0, 51.7494
14.396037380, 23.970, 2721.0, 52.1632
14.439503140, 23.970, 2778.0, 52.7067
14.482968900, 23.970, 2694.0, 51.9038
14.526434660, 23.970, 2718.0, 52.1344
14.569900420, 23.970, 2786.0, 52.7826
14.613366180, 23.970, 2870.0, 53.5724
14.656831940, 23.970, 2749.0, 52.4309
14.700297700, 23.970, 2913.0, 53.9722
14.743763460, 23.970, 2867.0, 53.5444
14.787229220, 23.970, 2814.0, 53.0471
14.830694980, 23.970, 2857.0, 53.4509
14.874160740, 23.970, 2863.0, 53.5070
14.917626500, 23.970, 2957.0, 54.3783
14.961092260, 23.970, 2970.0, 54.4977
15.004558020, 23.970, 3039.0, 55.1271
15.048023780, 23.970, 3111.0, 55.7763
15.091489540, 23.970, 3019.0, 54.9454
15.134955300, 23.970, 3025.0, 55.0000
15.178421060, 23.970, 3104.0, 55.7136
15.221886820, 23.970, 3103.0, 55.7046
15.265352580, 23.970, 3125.0, 55.9017
15.308818340, 23.970, 3165.0, 56.2583
15.352284100, 23.970, 3299.0, 57.4369
15.395749860, 23.970, 3201.0, 56.5774
15.439215620, 23.970, 3342.0, 57.8100
15.482681380, 23.970, 3286.0, 57.3236
15.526147140, 23.970, 3334.0, 57.7408
15.569612900, 23.970, 3425.0, 58.5235
15.613078660, 23.970, 3346.0, 57.8446
15.656544420, 23.970, 3288.0, 57.3411
15.700010180, 23.970, 3435.0, 58.6089
15.743475940, 23.970, 3481.0, 59.0000
15.786941700, 23.970, 3486.0, 59.0424
15.830407460, 23.970, 3586.0, 59.8832
15.873873220, 23.970, 3640.0, 60.3324
15.917338980, 23.970, 3696.0, 60.7947
15.960804740, 23.970, 3626.0, 60.2163
16.004270500, 23.970, 3656.0, 60.4649
16.047736260, 23.970, 3750.0, 61.2372
16.091202020, 23.970, 3535.0, 59.4559
16.134667780, 23.970, 3613.0, 60.1082
16.178133540, 23.970, 3965.0, 62.9682
16.221599300, 23.970, 3796.0, 61.6117
16.265065060, 23.970, 3786.0, 61.5305
16.308530820, 23.970, 3838.0, 61.9516
16.351996580, 23.970, 4061.0, 63.7260
16.395462340, 23.970, 3910.0, 62.5300
16.438928100, 23.970, 3841.0, 61.9758
16.482393860, 23.970, 3885.0, 62.3298
16.525859620, 23.970, 4039.0, 63.5531
16.569325380, 23.970, 4103.0, 64.0547
16.612791140, 23.970, 4061.0, 63.7260
16.656256900, 23.970, 4154.0, 64.4515
16.699722660, 23.970, 4225.0, 65.0000
16.743188420, 23.970, 4216.0, 64.9307
16.786654180, 23.970, 4521.0, 67.2384
16.830119940, 23.970, 4330.0, 65.8027
16.873585700, 23.970, 4336.0, 65.8483
16.917051460, 23.970, 4524.0, 67.2607
16.960517220, 23.970, 4394.0, 66.2873
17.003982980, 23.970, 4446.0, 66.6783
17.047448740, 23.970, 4409.0, 66.4003
17.090914500, 23.970, 4563.0, 67.5500
17.134380260, 23.970, 4667.0, 68.3154
17.177846020, 23.970, 4712.0, 68.6440
17.221311780, 23.970, 4591.0, 67.7569
17.264777540, 23.970, 4596.0, 67.7938
17.308243300, 23.970, 4781.0, 69.1448
17.351709060, 23.970, 4762.0, 69.0072
17.395174820, 23.970, 4731.0, 68.7823
17.438640580, 23.970, 4836.0, 69.5414
17.482106340, 23.970, 4862.0, 69.7280
17.525572100, 23.970, 4864.0, 69.7424
17.569037860, 23.970, 4926.0, 70.1855
17.612503620, 23.970, 5060.0, 71.1337
17.655969380, 23.970, 5141.0, 71.7008
17.699435140, 23.970, 4989.0, 70.6329
17.742900900, 23.970, 5102.0, 71.4283
17.786366660, 23.970, 5244.0, 72.4155
17.829832420, 23.970, 5239.0, 72.3809
17.873298180, 23.970, 5281.0, 72.6705
17.916763940, 23.970, 5369.0, 73.2735
17.960229700, 23.970, 5485.0, 74.0608
18.003695460, 23.970, 5477.0, 74.0068
18.047161220, 23.970, 5582.0, 74.7128
18.090626980, 23.970, 5790.0, 76.0920
18.134092740, 23.970, 6035.0, 77.6853
18.177558500, 23.970, 6041.0, 77.7239
18.221024260, 23.970, 6241.0, 79.0000
18.264490020, 23.970, 6524.0, 80.7713
18.307955780, 23.970, 6619.0, 81.3572
18.351421540, 23.970, 7049.0, 83.9583
18.394887300, 23.970, 7307.0, 85.4810
18.438353060, 23.970, 7746.0, 88.0114
18.481818820, 23.970, 8197.0, 90.5373
18.525284580, 23.970, 8450.0, 91.9239
18.568750340, 23.970, 9066.0, 95.2155
18.612216100, 23.970, 9478.0, 97.3550
18.655681860, 23.970, 9944.0, 99.7196
18.699147620, 23.970, 10323.0, 101.6022
18.742613380, 23.970, 10382.0, 101.8921
18.786079140, 23.970, 10279.0, 101.3854
18.829544900, 23.970, 10295.0, 101.4643
18.873010660, 23.970, 9875.0, 99.3730
18.916476420, 23.970, 9720.0, 98.5901
18.959942180, 23.970, 9221.0, 96.0260
19.003407940, 23.970, 8813.0, 93.8776
19.046873700, 23.970, 8432.0, 91.8259
19.090339460, 23.970, 8089.0, 89.9389
19.133805220, 23.970, 7653.0, 87.4814
19.177270980, 23.970, 7440.0, 86.2554
19.220736740, 23.970, 7188.0, 84.7821
19.264202500, 23.970, 6834.0, 82.6680
19.307668260, 23.970, 6629.0, 81.4187
19.351134020, 23.970, 6530.0, 80.8084
19.394599780, 23.970, 6212.0, 78.8162
19.438065540, 23.970, 6234.0, 78.9557
19.481531300, 23.970, 5988.0, 77.3822
19.524997060, 23.970, 5835.0, 76.3872
19.568462820, 23.970, 5723.0, 75.6505
19.611928580, 23.970, 5690.0, 75.4321
19.655394340, 23.970, 5730.0, 75.6968
19.698860100, 23.970, 5751.0, 75.8353
19.742325860, 23.970, 5573.0, 74.6525
19.785791620, 23.970, 5530.0, 74.3640
19.829257380, 23.970, 5415.0, 73.5867
19.872723140, 23.970, 5351.0, 73.1505
19.916188900, 23.970, 5387.0, 73.3962
19.959654660, 23.970, 5435.0, 73.7225
20.003120420, 23.970, 5444.0, 73.7835
20.046586180, 23.970, 5555.0, 74.5319
20.090051940, 23.970, 5433.0, 73.7089
20.133517700, 23.970, 5628.0, 75.0200
20.176983460, 23.970, 5554.0, 74.5252
20.220449220, 23.970, 5690.0, 75.4321
20.263914980, 23.970, 5513.0, 74.2496
20.307380740, 23.970, 5812.0, 76.2365
20.350846500, 23.970, 5870.0, 76.6159
20.394312260, 23.970, 5782.0, 76.0395
20.437778020, 23.970, 5834.0, 76.3806
20.481243780, 23.970, 6056.0, 77.8203
20.524709540, 23.970, 6014.0, 77.5500
20.568175300, 23.970, 6130.0, 78.2943
20.611641060, 23.970, 6328.0, 79.5487
20.655106820, 23.970, 6218.0, 78.8543
20.698572580, 23.970, 6379.0, 79.8686
20.742038340, 23.970, 6303.0, 79.3914
20.785504100, 23.970, 6216.0, 78.8416
20.828969860, 23.970, 6331.0, 79.5676
20.872435620, 23.970, 6181.0, 78.6193
20.915901380, 23.970, 6013.0, 77.5435
20.959367140, 23.970, 6008.0, 77.5113
21.002832900, 23.970, 5753.0, 75.8485
21.046298660, 23.970, 5810.0, 76.2234
21.089764420, 23.970, 5814.0, 76.2496
21.133230180, 23.970, 5507.0, 74.2092
21.176695940, 23.970, 5440.0, 73.7564
21.220161700, 23.970, 5282.0, 72.6774
21.263627460, 23.970, 5156.0, 71.8053
21.307093220, 23.970, 4976.0, 70.5408
21.350558980, 23.970, 5042.0, 71.0070
21.394024740, 23.970, 4844.0, 69.5989
21.437490500, 23.970, 4785.0, 69.1737
21.480956260, 23.970, 4953.0, 70.3776
21.524422020, 23.970, 4762.0, 69.0072
21.567887780, 23.970, 4820.0, 69.4262
21.611353540, 23.970, 4783.0, 69.1592
21.654819300, 23.970, 4844.0, 69.5989
21.698285060, 23.970, 4684.0, 68.4398
21.741750820, 23.970, 4657.0, 68.2422
21.785216580, 23.970, 4641.0, 68.1249
21.828682340, 23.970, 4607.0, 67.8749
21.872148100, 23.970, 4663.0, 68.2862
21.915613860, 23.970, 4902.0, 70.0143
21.959079620, 23.970, 4952.0, 70.3704
22.002545380, 23.970, 4977.0, 70.5479
22.046011140, 23.970, 4936.0, 70.2567
22.089476900, 23.970, 5042.0, 71.0070
22.132942660, 23.970, 5209.0, 72.1734
22.176408420, 23.970, 5441.0, 73.7631
22.219874180, 23.970, 5512.0, 74.2428
22.263339940, 23.970, 5678.0, 75.3525
22.306805700, 23.970, 5688.0, 75.4188
22.350271460, 23.970, 5868.0, 76.6029
22.393737220, 23.970, 5951.0, 77.1427
22.437202980, 23.970, 6257.0, 79.1012
22.480668740, 23.970, 6138.0, 78.3454
22.524134500, 23.970, 6187.0, 78.6575
22.567600260, 23.970, 6203.0, 78.7591
22.611066020, 23.970, 6224.0, 78.8923
22.654531780, 23.970, 6145.0, 78.3901
22.697997540, 23.970, 6117.0, 78.2113
22.741463300, 23.970, 6067.0, 77.8909
22.784929060, 23.970, 6077.0, 77.9551
22.828394820, 23.970, 5964.0, 77.2269
22.871860580, 23.970, 5608.0, 74.8866
22.915326340, 23.970, 5563.0, 74.5855
22.958792100, 23.970, 5540.0, 74.4312
23.002257860, 23.970, 5335.0, 73.0411
23.045723620, 23.970, 5208.0, 72.1665
23.089189380, 23.970, 4971.0, 70.5053
23.132655140, 23.970, 4888.0, 69.9142
23.176120900, 23.970, 4650.0, 68.1909
23.219586660, 23.970, 4540.0, 67.3795
23.263052420, 23.970, 4537.0, 67.3573
23.306518180, 23.970, 4333.0, 65.8255
23.349983940, 23.970, 4219.0, 64.9538
23.393449700, 23.970, 4110.0, 64.1093
23.436915460, 23.970, 4079.0, 63.8670
23.480381220, 23.970, 3846.0, 62.0161
23.523846980, 23.970, 3746.0, 61.2046
23.567312740, 23.970, 3753.0, 61.2617
23.610778500, 23.970, 3642.0, 60.3490
23.654244260, 23.970, 3614.0, 60.1166
23.697710020, 23.970, 3471.0, 58.9152
23.741175780, 23.970, 3415.0, 58.4380
23.784641540, 23.970, 3403.0, 58.3352
23.828107300, 23.970, 3273.0, 57.2101
23.871573060, 23.970, 3277.0, 57.2451
23.915038820, 23.970, 3195.0, 56.5243
23.958504580, 23.970, 3115.0, 55.8122
24.001970340, 23.970, 3128.0, 55.9285
24.045436100, 23.970, 3017.0, 54.9272
24.088901860, 23.970, 3018.0, 54.9363
24.132367620, 23.970, 2945.0, 54.2679
24.175833380, 23.970, 2889.0, 53.7494
24.219299140, 23.970, 2871.0, 53.5817
24.262764900, 23.970, 2853.0, 53.4135
24.306230660, 23.970, 2792.0, 52.8394
24.349696420, 23.970, 2835.0, 53.2447
24.393162180, 23.970, 2726.0, 52.2111
24.436627940, 23.970, 2744.0, 52.3832
24.480093700, 23.970, 2593.0, 50.9215
24.523559460, 23.970, 2597.0, 50.9608
24.567025220, 23.970, 2683.0, 51.7977
24.610490980, 23.970, 2529.0, 50.2892
24.653956740, 23.970, 2648.0, 51.4587
24.697422500, 23.970, 2484.0, 49.8397
24.740888260, 23.970, 2490.0, 49.8999
24.784354020, 23.970, 2486.0, 49.8598
24.827819780, 23.970, 2505.0, 50.0500
24.871285540, 23.970, 2435.0, 49.3457
24.914751300, 23.970, 2462.0, 49.6185
24.958217060, 23.970, 2492.0, 49.9199
25.001682820, 23.970, 2461.0, 49.6085
25.045148580, 23.970, 2433.0, 49.3254
25.088614340, 23.970, 2474.0, 49.7393
25.132080100, 23.970, 2382.0, 48.8057
25.175545860, 23.970, 2337.0, 48.3425
25.219011620, 23.970, 2435.0, 49.3457
25.262477380, 23.970, 2373.0, 48.7134
25.305943140, 23.970, 2341.0, 48.3839
25.349408900, 23.970, 2342.0, 48.3942
25.392874660, 23.970, 2291.0, 47.8644
25.436340420, 23.970, 2253.0, 47.4658
25.479806180, 23.970, 2299.0, 47.9479
25.523271940, 23.970, 2227.0, 47.1911
25.566737700, 23.970, 2342.0, 48.3942
25.610203460, 23.970, 2308.0, 48.0416
25.653669220, 23.970, 2294.0, 47.8957
25.697134980, 23.970, 2190.0, 46.7974
25.740600740, 23.970, 2184.0, 46.7333
25.784066500, 23.970, 2318.0, 48.1456
25.827532260, 23.970, 2178.0, 46.6690
25.870998020, 23.970, 2334.0, 48.3115
25.914463780, 23.970, 2176.0, 46.6476
25.957929540, 23.970, 2263.0, 47.5710
26.001395300, 23.970, 2199.0, 46.8935
26.044861060, 23.970, 2271.0, 47.6550
26.088326820, 23.970, 2165.0, 46.5296
26.131792580, 23.970, 2147.0, 46.3357
26.175258340, 23.970, 2143.0, 46.2925
26.218724100, 23.970, 2181.0, 46.7012
26.262189860, 23.970, 2200.0, 46.9042
26.305655620, 23.970, 2105.0, 45.8803
26.349121380, 23.970, 1982.0, 44.5197
26.392587140, 23.970, 2144.0, 46.3033
26.436052900, 23.970, 2099.0, 45.8148
26.479518660, 23.970, 2065.0, 45.4423
26.522984420, 23.970, 2145.0, 46.3141
26.566450180, 23.970, 2023.0, 44.9778
26.609915940, 23.970, 2150.0, 46.3681
26.653381700, 23.970, 2097.0, 45.7930
26.696847460, 23.970, 2030.0, 45.0555
26.740313220, 23.970, 2037.0, 45.1331
26.783778980, 23.970, 2069.0, 45.4863
26.827244740, 23.970, 1996.0, 44.6766
26.870710500, 23.970, 1977.0, 44.4635
26.914176260, 23.970, 2037.0, 45.1331
26.957642020, 23.970, 1855.0, 43.0697
27.001107780, 23.970, 1877.0, 43.3244
27.044573540, 23.970, 1923.0, 43.8520
27.088039300, 23.970, 1946.0, 44.1135
27.131505060, 23.970, 1976.0, 44.4522
27.174970820, 23.970, 1955.0, 44.2154
27.218436580, 23.970, 1983.0, 44.5309
27.261902340, 23.970, 1865.0, 43.1856
27.305368100, 23.970, 1927.0, 43.8976
27.348833860, 23.970, 1948.0, 44.1362
27.392299620, 23.970, 1866.0, 43.1972
27.435765380, 23.970, 1953.0, 44.1928
27.479231140, 23.970, 1825.0, 42.7200
27.522696900, 23.970, 1945.0, 44.1022
27.566162660, 23.970, 1971.0, 44.3959
27.609628420, 23.970, 1937.0, 44.0114
27.653094180, 23.970, 1943.0, 44.0795
27.696559940, 23.970, 1965.0, 44.3283
27.740025700, 23.970, 1890.0, 43.4741
27.783491460, 23.970, 1909.0, 43.6921
27.826957220, 23.970, 1909.0, 43.6921
27.870422980, 23.970, 1977.0, 44.4635
27.913888740, 23.970, 1959.0, 44.2606
27.957354500, 23.970, 2103.0, 45.8585
28.000820260, 23.970, 2079.0, 45.5961
28.044286020, 23.970, 2076.0, 45.5631
28.087751780, 23.970, 2056.0, 45.3431
28.131217540, 23.970, 2242.0, 47.3498
28.174683300, 23.970, 2205.0, 46.9574
28.218149060, 23.970, 2257.0, 47.5079
28.261614820, 23.970, 2339.0, 48.3632
28.305080580, 23.970, 2407.0, 49.0612
28.348546340, 23.970, 2476.0, 49.7594
28.392012100, 23.970, 2478.0, 49.7795
28.435477860, 23.970, 2559.0, 50.5866
28.478943620, 23.970, 2558.0, 50.5767
28.522409380, 23.970, 2736.0, 52.3068
28.565875140, 23.970, 2654.0, 51.5170
28.609340900, 23.970, 2705.0, 52.0096
28.652806660, 23.970, 2704.0, 52.0000
28.696272420, 23.970, 2691.0, 51.8748
28.739738180, 23.970, 2625.0, 51.2348
28.783203940, 23.970, 2737.0, 52.3163
28.826669700, 23.970, 2520.0, 50.1996
28.870135460, 23.970, 2771.0, 52.6403
28.913601220, 23.970, 2606.0, 51.0490
28.957066980, 23.970, 2606.0, 51.0490
29.000532740, 23.970, 2473.0, 49.7293
29.043998500, 23.970, 2615.0, 51.1371
29.087464260, 23.970, 2470.0, 49.6991
29.130930020, 23.970, 2615.0, 51.1371
29.174395780, 23.970, 2734.0, 52.2877
29.217861540, 23.970, 2930.0, 54.1295
29.261327300, 23.970, 3505.0, 59.2030
29.304793060, 23.970, 4366.0, 66.0757
29.348258820, 23.970, 3982.0, 63.1031
29.391724580, 23.970, 3351.0, 57.8878
29.435190340, 23.970, 2729.0, 52.2398
29.478656100, 23.970, 2231.0, 47.2335
29.522121860, 23.970, 2027.0, 45.0222
29.565587620, 23.970, 1882.0, 43.3820
29.609053380, 23.970, 1888.0, 43.4511
29.652519140, 23.970, 1887.0, 43.4396
29.695984900, 23.970, 1876.0, 43.3128
29.739450660, 23.970, 1902.0, 43.6119
29.782916420, 23.970, 1861.0, 43.1393
29.826382180, 23.970, 1743.0, 41.7493
29.869847940, 23.970, 1772.0, 42.0951
29.913313700, 23.970, 1781.0, 42.2019
29.956779460, 23.970, 1768.0, 42.0476
30.000245220, 23.970, 1767.0, 42.0357
30.043710980, 23.970, 1763.0, 41.9881
30.087176740, 23.970, 1672.0, 40.8901
30.130642500, 23.970, 1721.0, 41.4849
30.174108260, 23.970, 1629.0, 40.3609
30.217574020, 23.970, 1715.0, 41.4126
30.261039780, 23.970, 1570.0, 39.6232
30.304505540, 23.970, 1628.0, 40.3485
30.347971300, 23.970, 1610.0, 40.1248
30.391437060, 23.970, 1698.0, 41.2068
30.434902820, 23.970, 1569.0, 39.6106
30.478368580, 23.970, 1546.0, 39.3192
30.521834340, 23.970, 1516.0, 38.9358
30.565300100, 23.970, 1509.0, 38.8458
30.608765860, 23.970, 1502.0, 38.7556
30.652231620, 23.970, 1478.0, 38.4448
30.695697380, 23.970, 1492.0, 38.6264
30.739163140, 23.970, 1470.0, 38.3406
30.782628900, 23.970, 1499.0, 38.7169
30.826094660, 23.970, 1437.0, 37.9078
30.869560420, 23.970, 1439.0, 37.9342
30.913026180, 23.970, 1433.0, 37.8550
30.956491940, 23.970, 1482.0, 38.4968
30.999957700, 23.970, 1381.0, 37.1618
31.043423460, 23.970, 1472.0, 38.3667
31.086889220, 23.970, 1375.0, 37.0810
31.130354980, 23.970, 1356.0, 36.8239
31.173820740, 23.970, 1342.0, 36.6333
31.217286500, 23.970, 1412.0, 37.5766
31.260752260, 23.970, 1412.0, 37.5766
31.304218020, 23.970, 1438.0, 37.9210
31.347683780, 23.970, 1430.0, 37.8153
31.391149540, 23.970, 1378.0, 37.1214
31.434615300, 23.970, 1329.0, 36.4555
31.478081060, 23.970, 1373.0, 37.0540
31.521546820, 23.970, 1362.0, 36.9053
31.565012580, 23.970, 1387.0, 37.2424
31.608478340, 23.970, 1298.0, 36.0278
31.651944100, 23.970, 1315.0, 36.2629
31.695409860, 23.970, 1315.0, 36.2629
31.738875620, 23.970, 1249.0, 35.3412
31.782341380, 23.970, 1283.0, 35.8190
31.825807140, 23.970, 1358.0, 36.8511
31.869272900, 23.970, 1283.0, 35.8190
31.912738660, 23.970, 1269.0, 35.6230
31.956204420, 23.970, 1301.0, 36.0694
31.999670180, 23.970, 1290.0, 35.9166
32.043135940, 23.970, 1301.0, 36.0694
32.086601700, 23.970, 1328.0, 36.4417
32.130067460, 23.970, 1329.0, 36.4555
32.173533220, 23.970, 1324.0, 36.3868
32.216998980, 23.970, 1276.0, 35.7211
32.260464740, 23.970, 1347.0, 36.7015
32.303930500, 23.970, 1293.0, 35.9583
32.347396260, 23.970, 1319.0, 36.3180
32.390862020, 23.970, 1341.0, 36.6197
32.434327780, 23.970, 1309.0, 36.1801
32.477793540, 23.970, 1341.0, 36.6197
32.521259300, 23.970, 1297.0, 36.0139
32.564725060, 23.970, 1281.0, 35.7911
32.608190820, 23.970, 1342.0, 36.6333
32.651656580, 23.970, 1402.0, 37.4433
32.695122340, 23.970, 1332.0, 36.4966
32.738588100, 23.970, 1249.0, 35.3412
32.782053860, 23.970, 1327.0, 36.4280
32.825519620, 23.970, 1334.0, 36.5240
32.868985380, 23.970, 1238.0, 35.1852
32.912451140, 23.970, 1233.0, 35.1141
32.955916900, 23.970, 1260.0, 35.4965
32.999382660, 23.970, 1224.0, 34.9857
33.042848420, 23.970, 1323.0, 36.3731
33.086314180, 23.970, 1295.0, 35.9861
33.129779940, 23.970, 1273.0, 35.6791
33.173245700, 23.970, 1242.0, 35.2420
33.216711460, 23.970, 1268.0, 35.6090
33.260177220, 23.970, 1303.0, 36.0971
33.303642980, 23.970, 1213.0, 34.8281
33.347108740, 23.970, 1259.0, 35.4824
33.390574500, 23.970, 1253.0, 35.3977
33.434040260, 23.970, 1275.0, 35.7071
33.477506020, 23.970, 1176.0, 34.2929
33.520971780, 23.970, 1194.0, 34.5543
33.564437540, 23.970, 1214.0, 34.8425
33.607903300, 23.970, 1238.0, 35.1852
33.651369060, 23.970, 1177.0, 34.3074
33.694834820, 23.970, 1185.0, 34.4238
33.738300580, 23.970, 1191.0, 34.5109
33.781766340, 23.970, 1156.0, 34.0000
33.825232100, 23.970, 1178.0, 34.3220
33.868697860, 23.970, 1130.0, 33.6155
33.912163620, 23.970, 1090.0, 33.0151
33.955629380, 23.970, 1154.0, 33.9706
33.999095140, 23.970, 1095.0, 33.0908
34.042560900, 23.970, 1104.0, 33.2265
34.086026660, 23.970, 1130.0, 33.6155
34.129492420, 23.970, 1095.0, 33.0908
34.172958180, 23.970, 1042.0, 32.2800
34.216423940, 23.970, 1081.0, 32.8786
34.259889700, 23.970, 1057.0, 32.5115
34.303355460, 23.970, 1087.0, 32.9697
34.346821220, 23.970, 1095.0, 33.0908
34.390286980, 23.970, 989.0, 31.4484
34.433752740, 23.970, 1025.0, 32.0156
34.477218500, 23.970, 1024.0, 32.0000
34.520684260, 23.970, 1014.0, 31.8434
34.564150020, 23.970, 1020.0, 31.9374
34.607615780, 23.970, 976.0, 31.2410
34.651081540, 23.970, 1045.0, 32.3265
34.694547300, 23.970, 954.0, 30.8869
34.738013060, 23.970, 993.0, 31.5119
34.781478820, 23.970, 1024.0, 32.0000
34.824944580, 23.970, 1024.0, 32.0000
34.868410340, 23.970, 970.0, 31.1448
34.911876100, 23.970, 982.0, 31.3369
34.955341860, 23.970, 951.0, 30.8383
34.998807620, 23.970, 1001.0, 31.6386
35.042273380, 23.970, 999.0, 31.6070
35.085739140, 23.970, 1001.0, 31.6386
35.129204900, 23.970, 993.0, 31.5119
35.172670660, 23.970, 991.0, 31.4802
35.216136420, 23.970, 923.0, 30.3809
35.259602180, 23.970, 1002.0, 31.6544
35.303067940, 23.970, 961.0, 31.0000
35.346533700, 23.970, 943.0, 30.7083
35.389999460, 23.970, 967.0, 31.0966
35.433465220, 23.970, 907.0, 30.1164
35.476930980, 23.970, 953.0, 30.8707
35.520396740, 23.970, 1001.0, 31.6386
35.563862500, 23.970, 955.0, 30.9031
35.607328260, 23.970, 1002.0, 31.6544
35.650794020, 23.970, 936.0, 30.5941
35.694259780, 23.970, 971.0, 31.1609
35.737725540, 23.970, 1039.0, 32.2335
35.781191300, 23.970, 1110.0, 33.3167
35.824657060, 23.970, 1106.0, 33.2566
35.868122820, 23.970, 1234.0, 35.1283
35.911588580, 23.970, 1203.0, 34.6843
35.955054340, 23.970, 1126.0, 33.5559
35.998520100, 23.970, 1076.0, 32.8024
36.041985860, 23.970, 976.0, 31.2410
36.085451620, 23.970, 1014.0, 31.8434
36.128917380, 23.970, 887.0, 29.7825
36.172383140, 23.970, 933.0, 30.5450
36.215848900, 23.970, 942.0, 30.6920
36.259314660, 23.970, 941.0, 30.6757
36.302780420, 23.970, 937.0, 30.6105
36.346246180, 23.970, 933.0, 30.5450
36.389711940, 23.970, 945.0, 30.7409
36.433177700, 23.970, 913.0, 30.2159
36.476643460, 23.970, 915.0, 30.2490
36.520109220, 23.970, 898.0, 29.9666
36.563574980, 23.970, 837.0, 28.9310
36.607040740, 23.970, 923.0, 30.3809
36.650506500, 23.970, 961.0, 31.0000
36.693972260, 23.970, 873.0, 29.5466
36.737438020, 23.970, 910.0, 30.1662
36.780903780, 23.970, 925.0, 30.4138
36.824369540, 23.970, 916.0, 30.2655
36.867835300, 23.970, 859.0, 29.3087
36.911301060, 23.970, 935.0, 30.5778
36.954766820, 23.970, 891.0, 29.8496
36.998232580, 23.970, 960.0, 30.9839
37.041698340, 23.970, 943.0, 30.7083
37.085164100, 23.970, 971.0, 31.1609
37.128629860, 23.970, 966.0, 31.0805
37.172095620, 23.970, 938.0, 30.6268
37.215561380, 23.970, 960.0, 30.9839
37.259027140, 23.970, 909.0, 30.1496
37.302492900, 23.970, 949.0, 30.8058
37.345958660, 23.970, 941.0, 30.6757
37.389424420, 23.970, 967.0, 31.0966
37.432890180, 23.970, 957.0, 30.9354
37.476355940, 23.970, 889.0, 29.8161
37.519821700, 23.970, 944.0, 30.7246
37.563287460, 23.970, 923.0, 30.3809
37.606753220, 23.970, 942.0, 30.6920
37.650218980, 23.970, 938.0, 30.6268
37.693684740, 23.970, 1042.0, 32.2800
37.737150500, 23.970, 1079.0, 32.8481
37.780616260, 23.970, 1032.0, 32.1248
37.824082020, 23.970, 984.0, 31.3688
37.867547780, 23.970, 1019.0, 31.9218
37.911013540, 23.970, 1101.0, 33.1813
37.954479300, 23.970, 1139.0, 33.7491
37.997945060, 23.970, 1178.0, 34.3220
38.041410820, 23.970, 1330.0, 36.4692
38.084876580, 23.970, 1476.0, 38.4187
38.128342340, 23.970, 1367.0, 36.9730
38.171808100, 23.970, 1361.0, 36.8917
38.215273860, 23.970, 1198.0, 34.6121
38.258739620, 23.970, 1220.0, 34.9285
38.302205380, 23.970, 1117.0, 33.4215
38.345671140, 23.970, 1095.0, 33.0908
38.389136900, 23.970, 1097.0, 33.1210
38.432602660, 23.970, 1036.0, 32.1870
38.476068420, 23.970, 1053.0, 32.4500
38.519534180, 23.970, 1106.0, 33.2566
38.562999940, 23.970, 1151.0, 33.9264
38.606465700, 23.970, 1123.0, 33.5112
38.649931460, 23.970, 1089.0, 33.0000
38.693397220, 23.970, 1106.0, 33.2566
38.736862980, 23.970, 1082.0, 32.8938
38.780328740, 23.970, 1107.0, 33.2716
38.823794500, 23.970, 1063.0, 32.6037
38.867260260, 23.970, 1135.0, 33.6898
38.910726020, 23.970, 1150.0, 33.9116
38.954191780, 23.970, 1119.0, 33.4515
38.997657540, 23.970, 1126.0, 33.5559
39.041123300, 23.970, 1095.0, 33.0908
39.084589060, 23.970, 1105.0, 33.2415
39.128054820, 23.970, 1146.0, 33.8526
39.171520580, 23.970, 1170.0, 34.2053
39.214986340, 23.970, 1232.0, 35.0999
39.258452100, 23.970, 1359.0, 36.8646
39.301917860, 23.970, 1464.0, 38.2623
39.345383620, 23.970, 1517.0, 38.9487
39.388849380, 23.970, 1350.0, 36.7423
39.432315140, 23.970, 1302.0, 36.0832
39.475780900, 23.970, 1150.0, 33.9116
39.519246660, 23.970, 1069.0, 32.6956
39.562712420, 23.970, 1036.0, 32.1870
39.606178180, 23.970, 1018.0, 31.9061
39.649643940, 23.970, 1015.0, 31.8591
39.693109700, 23.970, 1027.0, 32.0468
39.736575460, 23.970, 952.0, 30.8545
39.780041220, 23.970, 1026.0, 32.0312
39.823506980, 23.970, 922.0, 30.3645
39.866972740, 23.970, 968.0, 31.1127
39.910438500, 23.970, 1000.0, 31.6228
39.953904260, 23.970, 966.0, 31.0805
39.997370020, 23.970, 994.0, 31.5278
40.040835780, 23.970, 950.0, 30.8221
40.084301540, 23.970, 994.0, 31.5278
40.127767300, 23.970, 962.0, 31.0161
40.171233060, 23.970, 989.0, 31.4484
40.214698820, 23.970, 940.0, 30.6594
40.258164580, 23.970, 977.0, 31.2570
40.301630340, 23.970, 996.0, 31.5595
40.345096100, 23.970, 1018.0, 31.9061
40.388561860, 23.970, 969.0, 31.1288
40.432027620, 23.970, 977.0, 31.2570
40.475493380, 23.970, 1018.0, 31.9061
40.518959140, 23.970, 999.0, 31.6070
40.562424900, 23.970, 937.0, 30.6105
40.605890660, 23.970, 984.0, 31.3688
40.649356420, 23.970, 1014.0, 31.8434
40.692822180, 23.970, 1025.0, 32.0156
40.736287940, 23.970, 1006.0, 31.7175
40.779753700, 23.970, 1011.0, 31.7962
40.823219460, 23.970, 931.0, 30.5123
40.866685220, 23.970, 942.0, 30.6920
40.910150980, 23.970, 999.0, 31.6070
40.953616740, 23.970, 988.0, 31.4325
40.997082500, 23.970, 949.0, 30.8058
41.040548260, 23.970, 956.0, 30.9192
41.084014020, 23.970, 974.0, 31.2090
41.127479780, 23.970, 1029.0, 32.0780
41.170945540, 23.970, 1003.0, 31.6702
41.214411300, 23.970, 953.0, 30.8707
41.257877060, 23.970, 972.0, 31.1769
41.301342820, 23.970, 928.0, 30.4631
41.344808580, 23.970, 904.0, 30.0666
41.388274340, 23.970, 944.0, 30.7246
41.431740100, 23.970, 994.0, 31.5278
41.475205860, 23.970, 951.0, 30.8383
41.518671620, 23.970, 981.0, 31.3209
41.562137380, 23.970, 965.0, 31.0644
41.605603140, 23.970, 991.0, 31.4802
41.649068900, 23.970, 967.0, 31.0966
41.692534660, 23.970, 930.0, 30.4959
41.736000420, 23.970, 936.0, 30.5941
41.779466180, 23.970, 947.0, 30.7734
41.822931940, 23.970, 968.0, 31.1127
41.866397700, 23.970, 981.0, 31.3209
41.909863460, 23.970, 901.0, 30.0167
41.953329220, 23.970, 910.0, 30.1662
41.996794980, 23.970, 888.0, 29.7993
42.040260740, 23.970, 895.0, 29.9166
42.083726500, 23.970, 949.0, 30.8058
42.127192260, 23.970, 887.0, 29.7825
42.170658020, 23.970, 920.0, 30.3315
42.214123780, 23.970, 919.0, 30.3150
42.257589540, 23.970, 823.0, 28.6880
42.301055300, 23.970, 899.0, 29.9833
42.344521060, 23.970, 911.0, 30.1828
42.387986820, 23.970, 878.0, 29.6311
42.431452580, 23.970, 851.0, 29.1719
42.474918340, 23.970, 900.0, 30.0000
42.518384100, 23.970, 906.0, 30.0998
42.561849860, 23.970, 890.0, 29.8329
42.605315620, 23.970, 891.0, 29.8496
42.648781380, 23.970, 848.0, 29.1204
42.692247140, 23.970, 877.0, 29.6142
42.735712900, 23.970, 868.0, 29.4618
42.779178660, 23.970, 893.0, 29.8831
42.822644420, 23.970, 994.0, 31.5278
42.866110180, 23.970, 956.0, 30.9192
42.909575940, 23.970, 886.0, 29.7658
42.953041700, 23.970, 978.0, 31.2730
42.996507460, 23.970, 1004.0, 31.6860
43.039973220, 23.970, 1288.0, 35.8887
43.083438980, 23.970, 1298.0, 36.0278
43.126904740, 23.970, 1201.0, 34.6554
43.170370500, 23.970, 1175.0, 34.2783
43.213836260, 23.970, 1074.0, 32.7719
43.257302020, 23.970, 959.0, 30.9677
43.300767780, 23.970, 907.0, 30.1164
43.344233540, 23.970, 929.0, 30.4795
43.387699300, 23.970, 874.0, 29.5635
43.431165060, 23.970, 828.0, 28.7750
43.474630820, 23.970, 840.0, 28.9828
43.518096580, 23.970, 871.0, 29.5127
43.561562340, 23.970, 909.0, 30.1496
43.605028100, 23.970, 855.0, 29.2404
43.648493860, 23.970, 841.0, 29.0000
43.691959620, 23.970, 825.0, 28.7228
43.735425380, 23.970, 835.0, 28.8964
43.778891140, 23.970, 830.0, 28.8097
43.822356900, 23.970, 838.0, 28.9482
43.865822660, 23.970, 872.0, 29.5296
43.909288420, 23.970, 861.0, 29.3428
43.952754180, 23.970, 940.0, 30.6594
43.996219940, 23.970, 877.0, 29.6142
44.039685700, 23.970, 893.0, 29.8831
44.083151460, 23.970, 904.0, 30.0666
44.126617220, 23.970, 918.0, 30.2985
44.170082980, 23.970, 841.0, 29.0000
44.213548740, 23.970, 959.0, 30.9677
44.257014500, 23.970, 986.0, 31.4006
44.300480260, 23.970, 965.0, 31.0644
44.343946020, 23.970, 929.0, 30.4795
44.387411780, 23.970, 937.0, 30.6105
44.430877540, 23.970, 917.0, 30.2820
44.474343300, 23.970, 868.0, 29.4618
44.517809060, 23.970, 894.0, 29.8998
44.561274820, 23.970, 818.0, 28.6007
44.604740580, 23.970, 888.0, 29.7993
44.648206340, 23.970, 865.0, 29.4109
44.691672100, 23.970, 872.0, 29.5296
44.735137860, 23.970, 865.0, 29.4109
44.778603620, 23.970, 821.0, 28.6531
44.822069380, 23.970, 874.0, 29.5635
44.865535140, 23.970, 808.0, 28.4253
44.909000900, 23.970, 833.0, 28.8617
44.952466660, 23.970, 822.0, 28.6705
44.995932420, 23.970, 799.0, 28.2666
45.039398180, 23.970, 850.0, 29.1548
45.082863940, 23.970, 834.0, 28.8791
45.126329700, 23.970, 835.0, 28.8964
45.169795460, 23.970, 823.0, 28.6880
45.213261220, 23.970, 817.0, 28.5832
45.256726980, 23.970, 877.0, 29.6142
45.300192740, 23.970, 806.0, 28.3901
45.343658500, 23.970, 872.0, 29.5296
45.387124260, 23.970, 824.0, 28.7054
45.430590020, 23.970, 836.0, 28.9137
45.474055780, 23.970, 818.0, 28.6007
45.517521540, 23.970, 813.0, 28.5132
45.560987300, 23.970, 837.0, 28.9310
45.604453060, 23.970, 842.0, 29.0172
45.647918820, 23.970, 790.0, 28.1069
45.691384580, 23.970, 787.0, 28.0535
45.734850340, 23.970, 863.0, 29.3769
45.778316100, 23.970, 847.0, 29.1033
45.821781860, 23.970, 835.0, 28.8964
45.865247620, 23.970, 845.0, 29.0689
45.908713380, 23.970, 766.0, 27.6767
45.952179140, 23.970, 827.0, 28.7576
45.995644900, 23.970, 839.0, 28.9655
46.039110660, 23.970, 849.0, 29.1376
46.082576420, 23.970, 770.0, 27.7489
46.126042180, 23.970, 809.0, 28.4429
46.169507940, 23.970, 838.0, 28.9482
46.212973700, 23.970, 838.0, 28.9482
46.256439460, 23.970, 828.0, 28.7750
46.299905220, 23.970, 781.0, 27.9464
46.343370980, 23.970, 822.0, 28.6705
46.386836740, 23.970, 856.0, 29.2575
46.430302500, 23.970, 846.0, 29.0861
46.473768260, 23.970, 802.0, 28.3196
46.517234020, 23.970, 847.0, 29.1033
46.560699780, 23.970, 830.0, 28.8097
46.604165540, 23.970, 894.0, 29.8998
46.647631300, 23.970, 879.0, 29.6479
46.691097060, 23.970, 902.0, 30.0333
46.734562820, 23.970, 944.0, 30.7246
46.778028580, 23.970, 844.0, 29.0517
46.821494340, 23.970, 911.0, 30.1828
46.864960100, 23.970, 868.0, 29.4618
46.908425860, 23.970, 922.0, 30.3645
46.951891620, 23.970, 1001.0, 31.6386
46.995357380, 23.970, 1083.0, 32.9090
47.038823140, 23.970, 1017.0, 31.8904
47.082288900, 23.970, 1147.0, 33.8674
47.125754660, 23.970, 1100.0, 33.1662
47.169220420, 23.970, 1066.0, 32.6497
47.212686180, 23.970, 1017.0, 31.8904
47.256151940, 23.970, 1096.0, 33.1059
47.299617700, 23.970, 1079.0, 32.8481
47.343083460, 23.970, 1186.0, 34.4384
47.386549220, 23.970, 1417.0, 37.6431
47.430014980, 23.970, 1621.0, 40.2616
47.473480740, 23.970, 1411.0, 37.5633
47.516946500, 23.970, 1317.0, 36.2905
47.560412260, 23.970, 1260.0, 35.4965
47.603878020, 23.970, 1111.0, 33.3317
47.647343780, 23.970, 1029.0, 32.0780
47.690809540, 23.970, 952.0, 30.8545
47.734275300, 23.970, 940.0, 30.6594
47.777741060, 23.970, 924.0, 30.3974
47.821206820, 23.970, 892.0, 29.8664
47.864672580, 23.970, 890.0, 29.8329
47.908138340, 23.970, 886.0, 29.7658
47.951604100, 23.970, 914.0, 30.2324
47.995069860, 23.970, 895.0, 29.9166
48.038535620, 23.970, 949.0, 30.8058
48.082001380, 23.970, 924.0, 30.3974
48.125467140, 23.970, 947.0, 30.7734
48.168932900, 23.970, 874.0, 29.5635
48.212398660, 23.970, 920.0, 30.3315
48.255864420, 23.970, 902.0, 30.0333
48.299330180, 23.970, 964.0, 31.0483
48.342795940, 23.970, 1141.0, 33.7787
48.386261700, 23.970, 1318.0, 36.3043
48.429727460, 23.970, 1505.0, 38.7943
48.473193220, 23.970, 1301.0, 36.0694
48.516658980, 23.970, 1116.0, 33.4066
48.560124740, 23.970, 1113.0, 33.3617
48.603590500, 23.970, 1022.0, 31.9687
48.647056260, 23.970, 893.0, 29.8831
48.690522020, 23.970, 852.0, 29.1890
48.733987780, 23.970, 821.0, 28.6531
48.777453540, 23.970, 787.0, 28.0535
48.820919300, 23.970, 746.0, 27.3130
48.864385060, 23.970, 770.0, 27.7489
48.907850820, 23.970, 743.0, 27.2580
48.951316580, 23.970, 779.0, 27.9106
48.994782340, 23.970, 773.0, 27.8029
49.038248100, 23.970, 728.0, 26.9815
49.081713860, 23.970, 753.0, 27.4408
49.125179620, 23.970, 760.0, 27.5681
49.168645380, 23.970, 715.0, 26.7395
49.212111140, 23.970, 785.0, 28.0179
49.255576900, 23.970, 769.0, 27.7308
49.299042660, 23.970, 780.0, 27.9285
49.342508420, 23.970, 763.0, 27.6225
49.385974180, 23.970, 735.0, 27.1109
49.429439940, 23.970, 801.0, 28.3019
49.472905700, 23.970, 753.0, 27.4408
49.516371460, 23.970, 757.0, 27.5136
49.559837220, 23.970, 753.0, 27.4408
49.603302980, 23.970, 799.0, 28.2666
49.646768740, 23.970, 742.0, 27.2397
49.690234500, 23.970, 760.0, 27.5681
49.733700260, 23.970, 751.0, 27.4044
49.777166020, 23.970, 742.0, 27.2397
49.820631780, 23.970, 699.0, 26.4386
49.864097540, 23.970, 813.0, 28.5132
49.907563300, 23.970, 723.0, 26.8887
49.951029060, 23.970, 728.0, 26.9815
49.994494820, 23.970, 770.0, 27.7489