File: data/XRD/501023.csv
[Measurement conditions]
Sample identification,501023
Comment,
Anode material,Cu
K-Alpha1 wavelength,1.5405980
K-Alpha2 wavelength,1.5444260
Ratio K-Alpha2/K-Alpha1,0.500
Divergence slit,Fixed,0.38mm
Monochromator used,NO
Generator voltage, 40
Tube current, 15
File date and time,26/Feb/2025 10:39
Unit cell,
h k l, 0 0 0
Scan axis,Gonio
Scan range,5.002000000,49.999928040
Scan step size,0.0108664
No. of points, 4141
Scan type,CONTINUOUS
Time per step,23.970
[Scan points]
Angle, TimePerStep, Intensity, ESD
5.007433220, 23.970, 747.0, 27.3313
5.050898980, 23.970, 804.0, 28.3549
5.094364740, 23.970, 790.0, 28.1069
5.137830500, 23.970, 796.0, 28.2135
5.181296260, 23.970, 825.0, 28.7228
5.224762020, 23.970, 770.0, 27.7489
5.268227780, 23.970, 815.0, 28.5482
5.311693540, 23.970, 760.0, 27.5681
5.355159300, 23.970, 810.0, 28.4605
5.398625060, 23.970, 758.0, 27.5318
5.442090820, 23.970, 761.0, 27.5862
5.485556580, 23.970, 821.0, 28.6531
5.529022340, 23.970, 782.0, 27.9643
5.572488100, 23.970, 871.0, 29.5127
5.615953860, 23.970, 854.0, 29.2233
5.659419620, 23.970, 837.0, 28.9310
5.702885380, 23.970, 788.0, 28.0713
5.746351140, 23.970, 800.0, 28.2843
5.789816900, 23.970, 843.0, 29.0345
5.833282660, 23.970, 865.0, 29.4109
5.876748420, 23.970, 798.0, 28.2489
5.920214180, 23.970, 809.0, 28.4429
5.963679940, 23.970, 875.0, 29.5804
6.007145700, 23.970, 818.0, 28.6007
6.050611460, 23.970, 854.0, 29.2233
6.094077220, 23.970, 823.0, 28.6880
6.137542980, 23.970, 843.0, 29.0345
6.181008740, 23.970, 832.0, 28.8444
6.224474500, 23.970, 907.0, 30.1164
6.267940260, 23.970, 866.0, 29.4279
6.311406020, 23.970, 933.0, 30.5450
6.354871780, 23.970, 887.0, 29.7825
6.398337540, 23.970, 900.0, 30.0000
6.441803300, 23.970, 846.0, 29.0861
6.485269060, 23.970, 913.0, 30.2159
6.528734820, 23.970, 945.0, 30.7409
6.572200580, 23.970, 848.0, 29.1204
6.615666340, 23.970, 858.0, 29.2916
6.659132100, 23.970, 863.0, 29.3769
6.702597860, 23.970, 887.0, 29.7825
6.746063620, 23.970, 940.0, 30.6594
6.789529380, 23.970, 855.0, 29.2404
6.832995140, 23.970, 895.0, 29.9166
6.876460900, 23.970, 999.0, 31.6070
6.919926660, 23.970, 940.0, 30.6594
6.963392420, 23.970, 975.0, 31.2250
7.006858180, 23.970, 914.0, 30.2324
7.050323940, 23.970, 943.0, 30.7083
7.093789700, 23.970, 992.0, 31.4960
7.137255460, 23.970, 970.0, 31.1448
7.180721220, 23.970, 994.0, 31.5278
7.224186980, 23.970, 981.0, 31.3209
7.267652740, 23.970, 948.0, 30.7896
7.311118500, 23.970, 1076.0, 32.8024
7.354584260, 23.970, 967.0, 31.0966
7.398050020, 23.970, 1051.0, 32.4191
7.441515780, 23.970, 978.0, 31.2730
7.484981540, 23.970, 1002.0, 31.6544
7.528447300, 23.970, 1061.0, 32.5730
7.571913060, 23.970, 1058.0, 32.5269
7.615378820, 23.970, 1029.0, 32.0780
7.658844580, 23.970, 1109.0, 33.3017
7.702310340, 23.970, 1046.0, 32.3419
7.745776100, 23.970, 1044.0, 32.3110
7.789241860, 23.970, 1035.0, 32.1714
7.832707620, 23.970, 1048.0, 32.3728
7.876173380, 23.970, 1086.0, 32.9545
7.919639140, 23.970, 1066.0, 32.6497
7.963104900, 23.970, 1111.0, 33.3317
8.006570660, 23.970, 1090.0, 33.0151
8.050036420, 23.970, 1100.0, 33.1662
8.093502180, 23.970, 1156.0, 34.0000
8.136967940, 23.970, 1114.0, 33.3766
8.180433700, 23.970, 1181.0, 34.3657
8.223899460, 23.970, 1180.0, 34.3511
8.267365220, 23.970, 1137.0, 33.7194
8.310830980, 23.970, 1179.0, 34.3366
8.354296740, 23.970, 1112.0, 33.3467
8.397762500, 23.970, 1181.0, 34.3657
8.441228260, 23.970, 1128.0, 33.5857
8.484694020, 23.970, 1164.0, 34.1174
8.528159780, 23.970, 1252.0, 35.3836
8.571625540, 23.970, 1200.0, 34.6410
8.615091300, 23.970, 1220.0, 34.9285
8.658557060, 23.970, 1206.0, 34.7275
8.702022820, 23.970, 1179.0, 34.3366
8.745488580, 23.970, 1262.0, 35.5246
8.788954340, 23.970, 1259.0, 35.4824
8.832420100, 23.970, 1244.0, 35.2704
8.875885860, 23.970, 1206.0, 34.7275
8.919351620, 23.970, 1263.0, 35.5387
8.962817380, 23.970, 1231.0, 35.0856
9.006283140, 23.970, 1281.0, 35.7911
9.049748900, 23.970, 1228.0, 35.0428
9.093214660, 23.970, 1245.0, 35.2846
9.136680420, 23.970, 1289.0, 35.9026
9.180146180, 23.970, 1346.0, 36.6879
9.223611940, 23.970, 1303.0, 36.0971
9.267077700, 23.970, 1243.0, 35.2562
9.310543460, 23.970, 1335.0, 36.5377
9.354009220, 23.970, 1290.0, 35.9166
9.397474980, 23.970, 1278.0, 35.7491
9.440940740, 23.970, 1353.0, 36.7831
9.484406500, 23.970, 1352.0, 36.7696
9.527872260, 23.970, 1425.0, 37.7492
9.571338020, 23.970, 1364.0, 36.9324
9.614803780, 23.970, 1392.0, 37.3095
9.658269540, 23.970, 1404.0, 37.4700
9.701735300, 23.970, 1343.0, 36.6470
9.745201060, 23.970, 1425.0, 37.7492
9.788666820, 23.970, 1415.0, 37.6165
9.832132580, 23.970, 1414.0, 37.6032
9.875598340, 23.970, 1441.0, 37.9605
9.919064100, 23.970, 1420.0, 37.6829
9.962529860, 23.970, 1521.0, 39.0000
10.005995620, 23.970, 1446.0, 38.0263
10.049461380, 23.970, 1420.0, 37.6829
10.092927140, 23.970, 1515.0, 38.9230
10.136392900, 23.970, 1502.0, 38.7556
10.179858660, 23.970, 1538.0, 39.2173
10.223324420, 23.970, 1545.0, 39.3065
10.266790180, 23.970, 1529.0, 39.1024
10.310255940, 23.970, 1626.0, 40.3237
10.353721700, 23.970, 1519.0, 38.9744
10.397187460, 23.970, 1629.0, 40.3609
10.440653220, 23.970, 1607.0, 40.0874
10.484118980, 23.970, 1662.0, 40.7676
10.527584740, 23.970, 1526.0, 39.0640
10.571050500, 23.970, 1631.0, 40.3856
10.614516260, 23.970, 1603.0, 40.0375
10.657982020, 23.970, 1632.0, 40.3980
10.701447780, 23.970, 1672.0, 40.8901
10.744913540, 23.970, 1636.0, 40.4475
10.788379300, 23.970, 1570.0, 39.6232
10.831845060, 23.970, 1676.0, 40.9390
10.875310820, 23.970, 1627.0, 40.3361
10.918776580, 23.970, 1624.0, 40.2989
10.962242340, 23.970, 1699.0, 41.2189
11.005708100, 23.970, 1770.0, 42.0714
11.049173860, 23.970, 1755.0, 41.8927
11.092639620, 23.970, 1704.0, 41.2795
11.136105380, 23.970, 1651.0, 40.6325
11.179571140, 23.970, 1739.0, 41.7013
11.223036900, 23.970, 1718.0, 41.4488
11.266502660, 23.970, 1769.0, 42.0595
11.309968420, 23.970, 1824.0, 42.7083
11.353434180, 23.970, 1805.0, 42.4853
11.396899940, 23.970, 1869.0, 43.2319
11.440365700, 23.970, 1826.0, 42.7317
11.483831460, 23.970, 1884.0, 43.4051
11.527297220, 23.970, 1862.0, 43.1509
11.570762980, 23.970, 1871.0, 43.2551
11.614228740, 23.970, 1933.0, 43.9659
11.657694500, 23.970, 1931.0, 43.9431
11.701160260, 23.970, 1932.0, 43.9545
11.744626020, 23.970, 1977.0, 44.4635
11.788091780, 23.970, 2024.0, 44.9889
11.831557540, 23.970, 2074.0, 45.5412
11.875023300, 23.970, 2031.0, 45.0666
11.918489060, 23.970, 2077.0, 45.5741
11.961954820, 23.970, 2050.0, 45.2769
12.005420580, 23.970, 2051.0, 45.2880
12.048886340, 23.970, 2083.0, 45.6399
12.092352100, 23.970, 2152.0, 46.3897
12.135817860, 23.970, 2153.0, 46.4004
12.179283620, 23.970, 2215.0, 47.0638
12.222749380, 23.970, 2096.0, 45.7821
12.266215140, 23.970, 2215.0, 47.0638
12.309680900, 23.970, 2131.0, 46.1628
12.353146660, 23.970, 2191.0, 46.8081
12.396612420, 23.970, 2263.0, 47.5710
12.440078180, 23.970, 2221.0, 47.1275
12.483543940, 23.970, 2313.0, 48.0937
12.527009700, 23.970, 2304.0, 48.0000
12.570475460, 23.970, 2343.0, 48.4045
12.613941220, 23.970, 2345.0, 48.4252
12.657406980, 23.970, 2325.0, 48.2183
12.700872740, 23.970, 2414.0, 49.1325
12.744338500, 23.970, 2432.0, 49.3153
12.787804260, 23.970, 2444.0, 49.4368
12.831270020, 23.970, 2467.0, 49.6689
12.874735780, 23.970, 2571.0, 50.7050
12.918201540, 23.970, 2495.0, 49.9500
12.961667300, 23.970, 2509.0, 50.0899
13.005133060, 23.970, 2594.0, 50.9313
13.048598820, 23.970, 2382.0, 48.8057
13.092064580, 23.970, 2462.0, 49.6185
13.135530340, 23.970, 2629.0, 51.2738
13.178996100, 23.970, 2519.0, 50.1896
13.222461860, 23.970, 2647.0, 51.4490
13.265927620, 23.970, 2696.0, 51.9230
13.309393380, 23.970, 2631.0, 51.2933
13.352859140, 23.970, 2799.0, 52.9056
13.396324900, 23.970, 2669.0, 51.6624
13.439790660, 23.970, 2743.0, 52.3737
13.483256420, 23.970, 2792.0, 52.8394
13.526722180, 23.970, 2836.0, 53.2541
13.570187940, 23.970, 2898.0, 53.8331
13.613653700, 23.970, 2897.0, 53.8238
13.657119460, 23.970, 2875.0, 53.6190
13.700585220, 23.970, 2901.0, 53.8609
13.744050980, 23.970, 2967.0, 54.4702
13.787516740, 23.970, 2976.0, 54.5527
13.830982500, 23.970, 3089.0, 55.5788
13.874448260, 23.970, 3069.0, 55.3986
13.917914020, 23.970, 3064.0, 55.3534
13.961379780, 23.970, 3193.0, 56.5066
14.004845540, 23.970, 3109.0, 55.7584
14.048311300, 23.970, 3100.0, 55.6776
14.091777060, 23.970, 3235.0, 56.8771
14.135242820, 23.970, 3280.0, 57.2713
14.178708580, 23.970, 3277.0, 57.2451
14.222174340, 23.970, 3398.0, 58.2924
14.265640100, 23.970, 3269.0, 57.1752
14.309105860, 23.970, 3336.0, 57.7581
14.352571620, 23.970, 3319.0, 57.6108
14.396037380, 23.970, 3488.0, 59.0593
14.439503140, 23.970, 3324.0, 57.6541
14.482968900, 23.970, 3375.0, 58.0948
14.526434660, 23.970, 3556.0, 59.6322
14.569900420, 23.970, 3550.0, 59.5819
14.613366180, 23.970, 3631.0, 60.2578
14.656831940, 23.970, 3684.0, 60.6960
14.700297700, 23.970, 3606.0, 60.0500
14.743763460, 23.970, 3785.0, 61.5224
14.787229220, 23.970, 3728.0, 61.0574
14.830694980, 23.970, 3621.0, 60.1747
14.874160740, 23.970, 3675.0, 60.6218
14.917626500, 23.970, 3863.0, 62.1530
14.961092260, 23.970, 3880.0, 62.2896
15.004558020, 23.970, 3883.0, 62.3137
15.048023780, 23.970, 3950.0, 62.8490
15.091489540, 23.970, 3954.0, 62.8808
15.134955300, 23.970, 3855.0, 62.0886
15.178421060, 23.970, 4047.0, 63.6160
15.221886820, 23.970, 4037.0, 63.5374
15.265352580, 23.970, 4065.0, 63.7574
15.308818340, 23.970, 4190.0, 64.7302
15.352284100, 23.970, 4306.0, 65.6201
15.395749860, 23.970, 4202.0, 64.8228
15.439215620, 23.970, 4267.0, 65.3223
15.482681380, 23.970, 4351.0, 65.9621
15.526147140, 23.970, 4353.0, 65.9773
15.569612900, 23.970, 4287.0, 65.4752
15.613078660, 23.970, 4494.0, 67.0373
15.656544420, 23.970, 4313.0, 65.6734
15.700010180, 23.970, 4564.0, 67.5574
15.743475940, 23.970, 4525.0, 67.2681
15.786941700, 23.970, 4582.0, 67.6905
15.830407460, 23.970, 4443.0, 66.6558
15.873873220, 23.970, 4698.0, 68.5420
15.917338980, 23.970, 4838.0, 69.5557
15.960804740, 23.970, 4831.0, 69.5054
16.004270500, 23.970, 4793.0, 69.2315
16.047736260, 23.970, 4740.0, 68.8477
16.091202020, 23.970, 4851.0, 69.6491
16.134667780, 23.970, 4925.0, 70.1783
16.178133540, 23.970, 4830.0, 69.4982
16.221599300, 23.970, 4978.0, 70.5549
16.265065060, 23.970, 5045.0, 71.0282
16.308530820, 23.970, 5130.0, 71.6240
16.351996580, 23.970, 4990.0, 70.6399
16.395462340, 23.970, 5104.0, 71.4423
16.438928100, 23.970, 5175.0, 71.9375
16.482393860, 23.970, 5205.0, 72.1457
16.525859620, 23.970, 5258.0, 72.5121
16.569325380, 23.970, 5321.0, 72.9452
16.612791140, 23.970, 5303.0, 72.8217
16.656256900, 23.970, 5422.0, 73.6342
16.699722660, 23.970, 5418.0, 73.6071
16.743188420, 23.970, 5538.0, 74.4177
16.786654180, 23.970, 5571.0, 74.6391
16.830119940, 23.970, 5429.0, 73.6817
16.873585700, 23.970, 5442.0, 73.7699
16.917051460, 23.970, 5739.0, 75.7562
16.960517220, 23.970, 5635.0, 75.0666
17.003982980, 23.970, 5711.0, 75.5712
17.047448740, 23.970, 5779.0, 76.0197
17.090914500, 23.970, 5851.0, 76.4918
17.134380260, 23.970, 5906.0, 76.8505
17.177846020, 23.970, 5978.0, 77.3175
17.221311780, 23.970, 6180.0, 78.6130
17.264777540, 23.970, 6393.0, 79.9562
17.308243300, 23.970, 6253.0, 79.0759
17.351709060, 23.970, 6327.0, 79.5424
17.395174820, 23.970, 6423.0, 80.1436
17.438640580, 23.970, 6685.0, 81.7618
17.482106340, 23.970, 6781.0, 82.3468
17.525572100, 23.970, 7119.0, 84.3742
17.569037860, 23.970, 6927.0, 83.2286
17.612503620, 23.970, 7534.0, 86.7986
17.655969380, 23.970, 7605.0, 87.2067
17.699435140, 23.970, 7760.0, 88.0909
17.742900900, 23.970, 8196.0, 90.5318
17.786366660, 23.970, 8525.0, 92.3309
17.829832420, 23.970, 8848.0, 94.0638
17.873298180, 23.970, 9101.0, 95.3992
17.916763940, 23.970, 9375.0, 96.8246
17.960229700, 23.970, 9885.0, 99.4233
18.003695460, 23.970, 9864.0, 99.3177
18.047161220, 23.970, 10150.0, 100.7472
18.090626980, 23.970, 10572.0, 102.8202
18.134092740, 23.970, 10721.0, 103.5423
18.177558500, 23.970, 10834.0, 104.0865
18.221024260, 23.970, 10867.0, 104.2449
18.264490020, 23.970, 10844.0, 104.1345
18.307955780, 23.970, 10779.0, 103.8220
18.351421540, 23.970, 10648.0, 103.1891
18.394887300, 23.970, 10411.0, 102.0343
18.438353060, 23.970, 10096.0, 100.4789
18.481818820, 23.970, 9443.0, 97.1751
18.525284580, 23.970, 9275.0, 96.3068
18.568750340, 23.970, 8902.0, 94.3504
18.612216100, 23.970, 8488.0, 92.1303
18.655681860, 23.970, 8205.0, 90.5815
18.699147620, 23.970, 7965.0, 89.2468
18.742613380, 23.970, 7845.0, 88.5720
18.786079140, 23.970, 7351.0, 85.7380
18.829544900, 23.970, 7063.0, 84.0417
18.873010660, 23.970, 7016.0, 83.7616
18.916476420, 23.970, 6913.0, 83.1445
18.959942180, 23.970, 6672.0, 81.6823
19.003407940, 23.970, 6479.0, 80.4922
19.046873700, 23.970, 6507.0, 80.6660
19.090339460, 23.970, 6501.0, 80.6288
19.133805220, 23.970, 6417.0, 80.1062
19.177270980, 23.970, 6369.0, 79.8060
19.220736740, 23.970, 6151.0, 78.4283
19.264202500, 23.970, 6278.0, 79.2338
19.307668260, 23.970, 6292.0, 79.3221
19.351134020, 23.970, 6186.0, 78.6511
19.394599780, 23.970, 6193.0, 78.6956
19.438065540, 23.970, 6270.0, 79.1833
19.481531300, 23.970, 6160.0, 78.4857
19.524997060, 23.970, 6200.0, 78.7401
19.568462820, 23.970, 6231.0, 78.9367
19.611928580, 23.970, 6269.0, 79.1770
19.655394340, 23.970, 6512.0, 80.6970
19.698860100, 23.970, 6477.0, 80.4798
19.742325860, 23.970, 6546.0, 80.9074
19.785791620, 23.970, 6509.0, 80.6784
19.829257380, 23.970, 6405.0, 80.0312
19.872723140, 23.970, 6533.0, 80.8270
19.916188900, 23.970, 6662.0, 81.6211
19.959654660, 23.970, 6571.0, 81.0617
20.003120420, 23.970, 6712.0, 81.9268
20.046586180, 23.970, 6881.0, 82.9518
20.090051940, 23.970, 6720.0, 81.9756
20.133517700, 23.970, 6913.0, 83.1445
20.176983460, 23.970, 7112.0, 84.3327
20.220449220, 23.970, 6942.0, 83.3187
20.263914980, 23.970, 6780.0, 82.3408
20.307380740, 23.970, 6710.0, 81.9146
20.350846500, 23.970, 6578.0, 81.1049
20.394312260, 23.970, 6605.0, 81.2712
20.437778020, 23.970, 6431.0, 80.1935
20.481243780, 23.970, 6380.0, 79.8749
20.524709540, 23.970, 6335.0, 79.5927
20.568175300, 23.970, 6307.0, 79.4166
20.611641060, 23.970, 5916.0, 76.9155
20.655106820, 23.970, 5946.0, 77.1103
20.698572580, 23.970, 5668.0, 75.2861
20.742038340, 23.970, 5723.0, 75.6505
20.785504100, 23.970, 5660.0, 75.2330
20.828969860, 23.970, 5500.0, 74.1620
20.872435620, 23.970, 5271.0, 72.6017
20.915901380, 23.970, 5435.0, 73.7225
20.959367140, 23.970, 5303.0, 72.8217
21.002832900, 23.970, 5249.0, 72.4500
21.046298660, 23.970, 5339.0, 73.0685
21.089764420, 23.970, 5277.0, 72.6430
21.133230180, 23.970, 5211.0, 72.1873
21.176695940, 23.970, 5118.0, 71.5402
21.220161700, 23.970, 5293.0, 72.7530
21.263627460, 23.970, 5138.0, 71.6798
21.307093220, 23.970, 5270.0, 72.5948
21.350558980, 23.970, 5333.0, 73.0274
21.394024740, 23.970, 5400.0, 73.4847
21.437490500, 23.970, 5391.0, 73.4234
21.480956260, 23.970, 5685.0, 75.3989
21.524422020, 23.970, 5655.0, 75.1997
21.567887780, 23.970, 5790.0, 76.0920
21.611353540, 23.970, 5824.0, 76.3151
21.654819300, 23.970, 5985.0, 77.3628
21.698285060, 23.970, 6132.0, 78.3071
21.741750820, 23.970, 6357.0, 79.7308
21.785216580, 23.970, 6432.0, 80.1998
21.828682340, 23.970, 6517.0, 80.7279
21.872148100, 23.970, 6541.0, 80.8764
21.915613860, 23.970, 6382.0, 79.8874
21.959079620, 23.970, 6528.0, 80.7960
22.002545380, 23.970, 6744.0, 82.1219
22.046011140, 23.970, 6695.0, 81.8230
22.089476900, 23.970, 6644.0, 81.5107
22.132942660, 23.970, 6505.0, 80.6536
22.176408420, 23.970, 6603.0, 81.2588
22.219874180, 23.970, 6381.0, 79.8812
22.263339940, 23.970, 6251.0, 79.0633
22.306805700, 23.970, 6115.0, 78.1985
22.350271460, 23.970, 6112.0, 78.1793
22.393737220, 23.970, 6004.0, 77.4855
22.437202980, 23.970, 5834.0, 76.3806
22.480668740, 23.970, 5626.0, 75.0067
22.524134500, 23.970, 5604.0, 74.8599
22.567600260, 23.970, 5235.0, 72.3533
22.611066020, 23.970, 5235.0, 72.3533
22.654531780, 23.970, 4957.0, 70.4060
22.697997540, 23.970, 4990.0, 70.6399
22.741463300, 23.970, 4696.0, 68.5274
22.784929060, 23.970, 4742.0, 68.8622
22.828394820, 23.970, 4599.0, 67.8159
22.871860580, 23.970, 4352.0, 65.9697
22.915326340, 23.970, 4435.0, 66.5958
22.958792100, 23.970, 4228.0, 65.0231
23.002257860, 23.970, 4012.0, 63.3404
23.045723620, 23.970, 4042.0, 63.5767
23.089189380, 23.970, 3897.0, 62.4260
23.132655140, 23.970, 3755.0, 61.2781
23.176120900, 23.970, 3617.0, 60.1415
23.219586660, 23.970, 3603.0, 60.0250
23.263052420, 23.970, 3652.0, 60.4318
23.306518180, 23.970, 3618.0, 60.1498
23.349983940, 23.970, 3483.0, 59.0169
23.393449700, 23.970, 3262.0, 57.1139
23.436915460, 23.970, 3372.0, 58.0689
23.480381220, 23.970, 3226.0, 56.7979
23.523846980, 23.970, 3197.0, 56.5420
23.567312740, 23.970, 3220.0, 56.7450
23.610778500, 23.970, 3169.0, 56.2939
23.654244260, 23.970, 3114.0, 55.8032
23.697710020, 23.970, 3025.0, 55.0000
23.741175780, 23.970, 2962.0, 54.4243
23.784641540, 23.970, 3028.0, 55.0273
23.828107300, 23.970, 2861.0, 53.4883
23.871573060, 23.970, 2882.0, 53.6843
23.915038820, 23.970, 2848.0, 53.3667
23.958504580, 23.970, 2799.0, 52.9056
24.001970340, 23.970, 2793.0, 52.8488
24.045436100, 23.970, 2777.0, 52.6972
24.088901860, 23.970, 2777.0, 52.6972
24.132367620, 23.970, 2765.0, 52.5833
24.175833380, 23.970, 2676.0, 51.7301
24.219299140, 23.970, 2635.0, 51.3323
24.262764900, 23.970, 2738.0, 52.3259
24.306230660, 23.970, 2716.0, 52.1153
24.349696420, 23.970, 2625.0, 51.2348
24.393162180, 23.970, 2580.0, 50.7937
24.436627940, 23.970, 2636.0, 51.3420
24.480093700, 23.970, 2463.0, 49.6286
24.523559460, 23.970, 2574.0, 50.7346
24.567025220, 23.970, 2574.0, 50.7346
24.610490980, 23.970, 2476.0, 49.7594
24.653956740, 23.970, 2511.0, 50.1099
24.697422500, 23.970, 2509.0, 50.0899
24.740888260, 23.970, 2458.0, 49.5782
24.784354020, 23.970, 2587.0, 50.8626
24.827819780, 23.970, 2407.0, 49.0612
24.871285540, 23.970, 2394.0, 48.9285
24.914751300, 23.970, 2428.0, 49.2747
24.958217060, 23.970, 2491.0, 49.9099
25.001682820, 23.970, 2411.0, 49.1019
25.045148580, 23.970, 2481.0, 49.8096
25.088614340, 23.970, 2426.0, 49.2544
25.132080100, 23.970, 2412.0, 49.1121
25.175545860, 23.970, 2351.0, 48.4871
25.219011620, 23.970, 2465.0, 49.6488
25.262477380, 23.970, 2315.0, 48.1144
25.305943140, 23.970, 2382.0, 48.8057
25.349408900, 23.970, 2265.0, 47.5920
25.392874660, 23.970, 2359.0, 48.5695
25.436340420, 23.970, 2377.0, 48.7545
25.479806180, 23.970, 2265.0, 47.5920
25.523271940, 23.970, 2313.0, 48.0937
25.566737700, 23.970, 2281.0, 47.7598
25.610203460, 23.970, 2175.0, 46.6369
25.653669220, 23.970, 2262.0, 47.5605
25.697134980, 23.970, 2143.0, 46.2925
25.740600740, 23.970, 2249.0, 47.4236
25.784066500, 23.970, 2354.0, 48.5180
25.827532260, 23.970, 2146.0, 46.3249
25.870998020, 23.970, 2244.0, 47.3709
25.914463780, 23.970, 2172.0, 46.6047
25.957929540, 23.970, 2153.0, 46.4004
26.001395300, 23.970, 2105.0, 45.8803
26.044861060, 23.970, 2108.0, 45.9130
26.088326820, 23.970, 2129.0, 46.1411
26.131792580, 23.970, 2042.0, 45.1885
26.175258340, 23.970, 2145.0, 46.3141
26.218724100, 23.970, 2137.0, 46.2277
26.262189860, 23.970, 2010.0, 44.8330
26.305655620, 23.970, 2117.0, 46.0109
26.349121380, 23.970, 2013.0, 44.8665
26.392587140, 23.970, 2058.0, 45.3652
26.436052900, 23.970, 1994.0, 44.6542
26.479518660, 23.970, 2105.0, 45.8803
26.522984420, 23.970, 2049.0, 45.2659
26.566450180, 23.970, 2024.0, 44.9889
26.609915940, 23.970, 1986.0, 44.5646
26.653381700, 23.970, 2016.0, 44.8999
26.696847460, 23.970, 2016.0, 44.8999
26.740313220, 23.970, 1941.0, 44.0568
26.783778980, 23.970, 2024.0, 44.9889
26.827244740, 23.970, 1965.0, 44.3283
26.870710500, 23.970, 2035.0, 45.1110
26.914176260, 23.970, 1970.0, 44.3847
26.957642020, 23.970, 1940.0, 44.0454
27.001107780, 23.970, 2011.0, 44.8442
27.044573540, 23.970, 2031.0, 45.0666
27.088039300, 23.970, 2009.0, 44.8219
27.131505060, 23.970, 2011.0, 44.8442
27.174970820, 23.970, 2042.0, 45.1885
27.218436580, 23.970, 2013.0, 44.8665
27.261902340, 23.970, 2048.0, 45.2548
27.305368100, 23.970, 2091.0, 45.7275
27.348833860, 23.970, 2072.0, 45.5192
27.392299620, 23.970, 2036.0, 45.1221
27.435765380, 23.970, 2189.0, 46.7868
27.479231140, 23.970, 2178.0, 46.6690
27.522696900, 23.970, 2214.0, 47.0532
27.566162660, 23.970, 2239.0, 47.3181
27.609628420, 23.970, 2293.0, 47.8853
27.653094180, 23.970, 2349.0, 48.4665
27.696559940, 23.970, 2332.0, 48.2908
27.740025700, 23.970, 2429.0, 49.2849
27.783491460, 23.970, 2449.0, 49.4874
27.826957220, 23.970, 2492.0, 49.9199
27.870422980, 23.970, 2466.0, 49.6588
27.913888740, 23.970, 2640.0, 51.3809
27.957354500, 23.970, 2692.0, 51.8845
28.000820260, 23.970, 2823.0, 53.1319
28.044286020, 23.970, 2713.0, 52.0865
28.087751780, 23.970, 2663.0, 51.6043
28.131217540, 23.970, 2724.0, 52.1920
28.174683300, 23.970, 2765.0, 52.5833
28.218149060, 23.970, 2743.0, 52.3737
28.261614820, 23.970, 2758.0, 52.5167
28.305080580, 23.970, 2780.0, 52.7257
28.348546340, 23.970, 2776.0, 52.6878
28.392012100, 23.970, 2779.0, 52.7162
28.435477860, 23.970, 2582.0, 50.8134
28.478943620, 23.970, 2481.0, 49.8096
28.522409380, 23.970, 2566.0, 50.6557
28.565875140, 23.970, 2441.0, 49.4065
28.609340900, 23.970, 2488.0, 49.8799
28.652806660, 23.970, 2542.0, 50.4183
28.696272420, 23.970, 2410.0, 49.0918
28.739738180, 23.970, 2412.0, 49.1121
28.783203940, 23.970, 2273.0, 47.6760
28.826669700, 23.970, 2249.0, 47.4236
28.870135460, 23.970, 2185.0, 46.7440
28.913601220, 23.970, 2062.0, 45.4093
28.957066980, 23.970, 2142.0, 46.2817
29.000532740, 23.970, 1975.0, 44.4410
29.043998500, 23.970, 2007.0, 44.7996
29.087464260, 23.970, 1986.0, 44.5646
29.130930020, 23.970, 1872.0, 43.2666
29.174395780, 23.970, 1880.0, 43.3590
29.217861540, 23.970, 1837.0, 42.8602
29.261327300, 23.970, 1752.0, 41.8569
29.304793060, 23.970, 1823.0, 42.6966
29.348258820, 23.970, 1831.0, 42.7902
29.391724580, 23.970, 1794.0, 42.3556
29.435190340, 23.970, 1707.0, 41.3159
29.478656100, 23.970, 1777.0, 42.1545
29.522121860, 23.970, 1783.0, 42.2256
29.565587620, 23.970, 1686.0, 41.0609
29.609053380, 23.970, 1708.0, 41.3280
29.652519140, 23.970, 1749.0, 41.8210
29.695984900, 23.970, 1716.0, 41.4246
29.739450660, 23.970, 1733.0, 41.6293
29.782916420, 23.970, 1627.0, 40.3361
29.826382180, 23.970, 1578.0, 39.7240
29.869847940, 23.970, 1634.0, 40.4228
29.913313700, 23.970, 1581.0, 39.7618
29.956779460, 23.970, 1628.0, 40.3485
30.000245220, 23.970, 1556.0, 39.4462
30.043710980, 23.970, 1650.0, 40.6202
30.087176740, 23.970, 1480.0, 38.4708
30.130642500, 23.970, 1488.0, 38.5746
30.174108260, 23.970, 1428.0, 37.7889
30.217574020, 23.970, 1482.0, 38.4968
30.261039780, 23.970, 1420.0, 37.6829
30.304505540, 23.970, 1433.0, 37.8550
30.347971300, 23.970, 1420.0, 37.6829
30.391437060, 23.970, 1403.0, 37.4566
30.434902820, 23.970, 1445.0, 38.0132
30.478368580, 23.970, 1321.0, 36.3456
30.521834340, 23.970, 1413.0, 37.5899
30.565300100, 23.970, 1397.0, 37.3765
30.608765860, 23.970, 1411.0, 37.5633
30.652231620, 23.970, 1373.0, 37.0540
30.695697380, 23.970, 1373.0, 37.0540
30.739163140, 23.970, 1430.0, 37.8153
30.782628900, 23.970, 1403.0, 37.4566
30.826094660, 23.970, 1307.0, 36.1525
30.869560420, 23.970, 1315.0, 36.2629
30.913026180, 23.970, 1320.0, 36.3318
30.956491940, 23.970, 1350.0, 36.7423
30.999957700, 23.970, 1340.0, 36.6060
31.043423460, 23.970, 1379.0, 37.1349
31.086889220, 23.970, 1284.0, 35.8329
31.130354980, 23.970, 1257.0, 35.4542
31.173820740, 23.970, 1386.0, 37.2290
31.217286500, 23.970, 1273.0, 35.6791
31.260752260, 23.970, 1332.0, 36.4966
31.304218020, 23.970, 1349.0, 36.7287
31.347683780, 23.970, 1324.0, 36.3868
31.391149540, 23.970, 1299.0, 36.0416
31.434615300, 23.970, 1259.0, 35.4824
31.478081060, 23.970, 1225.0, 35.0000
31.521546820, 23.970, 1385.0, 37.2156
31.565012580, 23.970, 1242.0, 35.2420
31.608478340, 23.970, 1275.0, 35.7071
31.651944100, 23.970, 1241.0, 35.2278
31.695409860, 23.970, 1355.0, 36.8103
31.738875620, 23.970, 1290.0, 35.9166
31.782341380, 23.970, 1321.0, 36.3456
31.825807140, 23.970, 1251.0, 35.3695
31.869272900, 23.970, 1277.0, 35.7351
31.912738660, 23.970, 1392.0, 37.3095
31.956204420, 23.970, 1281.0, 35.7911
31.999670180, 23.970, 1292.0, 35.9444
32.043135940, 23.970, 1362.0, 36.9053
32.086601700, 23.970, 1292.0, 35.9444
32.130067460, 23.970, 1365.0, 36.9459
32.173533220, 23.970, 1230.0, 35.0714
32.216998980, 23.970, 1257.0, 35.4542
32.260464740, 23.970, 1290.0, 35.9166
32.303930500, 23.970, 1315.0, 36.2629
32.347396260, 23.970, 1293.0, 35.9583
32.390862020, 23.970, 1291.0, 35.9305
32.434327780, 23.970, 1251.0, 35.3695
32.477793540, 23.970, 1253.0, 35.3977
32.521259300, 23.970, 1300.0, 36.0555
32.564725060, 23.970, 1321.0, 36.3456
32.608190820, 23.970, 1234.0, 35.1283
32.651656580, 23.970, 1276.0, 35.7211
32.695122340, 23.970, 1240.0, 35.2136
32.738588100, 23.970, 1276.0, 35.7211
32.782053860, 23.970, 1244.0, 35.2704
32.825519620, 23.970, 1206.0, 34.7275
32.868985380, 23.970, 1244.0, 35.2704
32.912451140, 23.970, 1273.0, 35.6791
32.955916900, 23.970, 1237.0, 35.1710
32.999382660, 23.970, 1214.0, 34.8425
33.042848420, 23.970, 1205.0, 34.7131
33.086314180, 23.970, 1151.0, 33.9264
33.129779940, 23.970, 1158.0, 34.0294
33.173245700, 23.970, 1152.0, 33.9411
33.216711460, 23.970, 1242.0, 35.2420
33.260177220, 23.970, 1218.0, 34.8999
33.303642980, 23.970, 1140.0, 33.7639
33.347108740, 23.970, 1130.0, 33.6155
33.390574500, 23.970, 1094.0, 33.0757
33.434040260, 23.970, 1107.0, 33.2716
33.477506020, 23.970, 1087.0, 32.9697
33.520971780, 23.970, 1103.0, 33.2114
33.564437540, 23.970, 1023.0, 31.9844
33.607903300, 23.970, 1059.0, 32.5423
33.651369060, 23.970, 1069.0, 32.6956
33.694834820, 23.970, 1083.0, 32.9090
33.738300580, 23.970, 1068.0, 32.6803
33.781766340, 23.970, 1012.0, 31.8119
33.825232100, 23.970, 978.0, 31.2730
33.868697860, 23.970, 990.0, 31.4643
33.912163620, 23.970, 1000.0, 31.6228
33.955629380, 23.970, 948.0, 30.7896
33.999095140, 23.970, 1054.0, 32.4654
34.042560900, 23.970, 976.0, 31.2410
34.086026660, 23.970, 1025.0, 32.0156
34.129492420, 23.970, 913.0, 30.2159
34.172958180, 23.970, 917.0, 30.2820
34.216423940, 23.970, 980.0, 31.3050
34.259889700, 23.970, 963.0, 31.0322
34.303355460, 23.970, 997.0, 31.5753
34.346821220, 23.970, 948.0, 30.7896
34.390286980, 23.970, 969.0, 31.1288
34.433752740, 23.970, 927.0, 30.4467
34.477218500, 23.970, 1008.0, 31.7490
34.520684260, 23.970, 915.0, 30.2490
34.564150020, 23.970, 876.0, 29.5973
34.607615780, 23.970, 1002.0, 31.6544
34.651081540, 23.970, 940.0, 30.6594
34.694547300, 23.970, 922.0, 30.3645
34.738013060, 23.970, 947.0, 30.7734
34.781478820, 23.970, 866.0, 29.4279
34.824944580, 23.970, 945.0, 30.7409
34.868410340, 23.970, 942.0, 30.6920
34.911876100, 23.970, 946.0, 30.7571
34.955341860, 23.970, 951.0, 30.8383
34.998807620, 23.970, 992.0, 31.4960
35.042273380, 23.970, 947.0, 30.7734
35.085739140, 23.970, 953.0, 30.8707
35.129204900, 23.970, 970.0, 31.1448
35.172670660, 23.970, 985.0, 31.3847
35.216136420, 23.970, 901.0, 30.0167
35.259602180, 23.970, 937.0, 30.6105
35.303067940, 23.970, 934.0, 30.5614
35.346533700, 23.970, 859.0, 29.3087
35.389999460, 23.970, 903.0, 30.0500
35.433465220, 23.970, 869.0, 29.4788
35.476930980, 23.970, 940.0, 30.6594
35.520396740, 23.970, 916.0, 30.2655
35.563862500, 23.970, 938.0, 30.6268
35.607328260, 23.970, 912.0, 30.1993
35.650794020, 23.970, 868.0, 29.4618
35.694259780, 23.970, 837.0, 28.9310
35.737725540, 23.970, 867.0, 29.4449
35.781191300, 23.970, 883.0, 29.7153
35.824657060, 23.970, 882.0, 29.6985
35.868122820, 23.970, 946.0, 30.7571
35.911588580, 23.970, 867.0, 29.4449
35.955054340, 23.970, 881.0, 29.6816
35.998520100, 23.970, 885.0, 29.7489
36.041985860, 23.970, 897.0, 29.9500
36.085451620, 23.970, 907.0, 30.1164
36.128917380, 23.970, 867.0, 29.4449
36.172383140, 23.970, 831.0, 28.8271
36.215848900, 23.970, 840.0, 28.9828
36.259314660, 23.970, 876.0, 29.5973
36.302780420, 23.970, 891.0, 29.8496
36.346246180, 23.970, 876.0, 29.5973
36.389711940, 23.970, 809.0, 28.4429
36.433177700, 23.970, 847.0, 29.1033
36.476643460, 23.970, 949.0, 30.8058
36.520109220, 23.970, 892.0, 29.8664
36.563574980, 23.970, 891.0, 29.8496
36.607040740, 23.970, 920.0, 30.3315
36.650506500, 23.970, 987.0, 31.4166
36.693972260, 23.970, 897.0, 29.9500
36.737438020, 23.970, 862.0, 29.3598
36.780903780, 23.970, 858.0, 29.2916
36.824369540, 23.970, 982.0, 31.3369
36.867835300, 23.970, 914.0, 30.2324
36.911301060, 23.970, 857.0, 29.2746
36.954766820, 23.970, 860.0, 29.3258
36.998232580, 23.970, 899.0, 29.9833
37.041698340, 23.970, 858.0, 29.2916
37.085164100, 23.970, 881.0, 29.6816
37.128629860, 23.970, 961.0, 31.0000
37.172095620, 23.970, 968.0, 31.1127
37.215561380, 23.970, 893.0, 29.8831
37.259027140, 23.970, 952.0, 30.8545
37.302492900, 23.970, 964.0, 31.0483
37.345958660, 23.970, 919.0, 30.3150
37.389424420, 23.970, 979.0, 31.2890
37.432890180, 23.970, 956.0, 30.9192
37.476355940, 23.970, 937.0, 30.6105
37.519821700, 23.970, 972.0, 31.1769
37.563287460, 23.970, 930.0, 30.4959
37.606753220, 23.970, 1031.0, 32.1092
37.650218980, 23.970, 969.0, 31.1288
37.693684740, 23.970, 1004.0, 31.6860
37.737150500, 23.970, 919.0, 30.3150
37.780616260, 23.970, 1020.0, 31.9374
37.824082020, 23.970, 1056.0, 32.4962
37.867547780, 23.970, 1029.0, 32.0780
37.911013540, 23.970, 1014.0, 31.8434
37.954479300, 23.970, 1007.0, 31.7333
37.997945060, 23.970, 1075.0, 32.7872
38.041410820, 23.970, 1071.0, 32.7261
38.084876580, 23.970, 1017.0, 31.8904
38.128342340, 23.970, 1107.0, 33.2716
38.171808100, 23.970, 1033.0, 32.1403
38.215273860, 23.970, 1044.0, 32.3110
38.258739620, 23.970, 1086.0, 32.9545
38.302205380, 23.970, 1060.0, 32.5576
38.345671140, 23.970, 1030.0, 32.0936
38.389136900, 23.970, 1071.0, 32.7261
38.432602660, 23.970, 1090.0, 33.0151
38.476068420, 23.970, 1110.0, 33.3167
38.519534180, 23.970, 1058.0, 32.5269
38.562999940, 23.970, 1155.0, 33.9853
38.606465700, 23.970, 1019.0, 31.9218
38.649931460, 23.970, 1067.0, 32.6650
38.693397220, 23.970, 1061.0, 32.5730
38.736862980, 23.970, 1086.0, 32.9545
38.780328740, 23.970, 1067.0, 32.6650
38.823794500, 23.970, 1066.0, 32.6497
38.867260260, 23.970, 1024.0, 32.0000
38.910726020, 23.970, 1092.0, 33.0454
38.954191780, 23.970, 1080.0, 32.8634
38.997657540, 23.970, 955.0, 30.9031
39.041123300, 23.970, 1026.0, 32.0312
39.084589060, 23.970, 987.0, 31.4166
39.128054820, 23.970, 933.0, 30.5450
39.171520580, 23.970, 931.0, 30.5123
39.214986340, 23.970, 1003.0, 31.6702
39.258452100, 23.970, 1003.0, 31.6702
39.301917860, 23.970, 1009.0, 31.7648
39.345383620, 23.970, 950.0, 30.8221
39.388849380, 23.970, 998.0, 31.5911
39.432315140, 23.970, 883.0, 29.7153
39.475780900, 23.970, 929.0, 30.4795
39.519246660, 23.970, 894.0, 29.8998
39.562712420, 23.970, 948.0, 30.7896
39.606178180, 23.970, 938.0, 30.6268
39.649643940, 23.970, 920.0, 30.3315
39.693109700, 23.970, 929.0, 30.4795
39.736575460, 23.970, 909.0, 30.1496
39.780041220, 23.970, 953.0, 30.8707
39.823506980, 23.970, 938.0, 30.6268
39.866972740, 23.970, 949.0, 30.8058
39.910438500, 23.970, 924.0, 30.3974
39.953904260, 23.970, 939.0, 30.6431
39.997370020, 23.970, 935.0, 30.5778
40.040835780, 23.970, 878.0, 29.6311
40.084301540, 23.970, 943.0, 30.7083
40.127767300, 23.970, 968.0, 31.1127
40.171233060, 23.970, 957.0, 30.9354
40.214698820, 23.970, 977.0, 31.2570
40.258164580, 23.970, 915.0, 30.2490
40.301630340, 23.970, 926.0, 30.4302
40.345096100, 23.970, 999.0, 31.6070
40.388561860, 23.970, 998.0, 31.5911
40.432027620, 23.970, 913.0, 30.2159
40.475493380, 23.970, 888.0, 29.7993
40.518959140, 23.970, 918.0, 30.2985
40.562424900, 23.970, 926.0, 30.4302
40.605890660, 23.970, 938.0, 30.6268
40.649356420, 23.970, 953.0, 30.8707
40.692822180, 23.970, 903.0, 30.0500
40.736287940, 23.970, 886.0, 29.7658
40.779753700, 23.970, 932.0, 30.5287
40.823219460, 23.970, 948.0, 30.7896
40.866685220, 23.970, 961.0, 31.0000
40.910150980, 23.970, 965.0, 31.0644
40.953616740, 23.970, 888.0, 29.7993
40.997082500, 23.970, 885.0, 29.7489
41.040548260, 23.970, 977.0, 31.2570
41.084014020, 23.970, 884.0, 29.7321
41.127479780, 23.970, 951.0, 30.8383
41.170945540, 23.970, 902.0, 30.0333
41.214411300, 23.970, 880.0, 29.6648
41.257877060, 23.970, 887.0, 29.7825
41.301342820, 23.970, 903.0, 30.0500
41.344808580, 23.970, 874.0, 29.5635
41.388274340, 23.970, 931.0, 30.5123
41.431740100, 23.970, 900.0, 30.0000
41.475205860, 23.970, 908.0, 30.1330
41.518671620, 23.970, 825.0, 28.7228
41.562137380, 23.970, 849.0, 29.1376
41.605603140, 23.970, 826.0, 28.7402
41.649068900, 23.970, 844.0, 29.0517
41.692534660, 23.970, 799.0, 28.2666
41.736000420, 23.970, 866.0, 29.4279
41.779466180, 23.970, 808.0, 28.4253
41.822931940, 23.970, 813.0, 28.5132
41.866397700, 23.970, 888.0, 29.7993
41.909863460, 23.970, 844.0, 29.0517
41.953329220, 23.970, 833.0, 28.8617
41.996794980, 23.970, 861.0, 29.3428
42.040260740, 23.970, 865.0, 29.4109
42.083726500, 23.970, 849.0, 29.1376
42.127192260, 23.970, 808.0, 28.4253
42.170658020, 23.970, 837.0, 28.9310
42.214123780, 23.970, 868.0, 29.4618
42.257589540, 23.970, 851.0, 29.1719
42.301055300, 23.970, 867.0, 29.4449
42.344521060, 23.970, 860.0, 29.3258
42.387986820, 23.970, 906.0, 30.0998
42.431452580, 23.970, 877.0, 29.6142
42.474918340, 23.970, 894.0, 29.8998
42.518384100, 23.970, 935.0, 30.5778
42.561849860, 23.970, 936.0, 30.5941
42.605315620, 23.970, 891.0, 29.8496
42.648781380, 23.970, 883.0, 29.7153
42.692247140, 23.970, 801.0, 28.3019
42.735712900, 23.970, 815.0, 28.5482
42.779178660, 23.970, 791.0, 28.1247
42.822644420, 23.970, 777.0, 27.8747
42.866110180, 23.970, 779.0, 27.9106
42.909575940, 23.970, 780.0, 27.9285
42.953041700, 23.970, 794.0, 28.1780
42.996507460, 23.970, 782.0, 27.9643
43.039973220, 23.970, 807.0, 28.4077
43.083438980, 23.970, 780.0, 27.9285
43.126904740, 23.970, 803.0, 28.3373
43.170370500, 23.970, 799.0, 28.2666
43.213836260, 23.970, 768.0, 27.7128
43.257302020, 23.970, 798.0, 28.2489
43.300767780, 23.970, 818.0, 28.6007
43.344233540, 23.970, 747.0, 27.3313
43.387699300, 23.970, 820.0, 28.6356
43.431165060, 23.970, 768.0, 27.7128
43.474630820, 23.970, 825.0, 28.7228
43.518096580, 23.970, 818.0, 28.6007
43.561562340, 23.970, 775.0, 27.8388
43.605028100, 23.970, 756.0, 27.4955
43.648493860, 23.970, 790.0, 28.1069
43.691959620, 23.970, 742.0, 27.2397
43.735425380, 23.970, 841.0, 29.0000
43.778891140, 23.970, 797.0, 28.2312
43.822356900, 23.970, 791.0, 28.1247
43.865822660, 23.970, 805.0, 28.3725
43.909288420, 23.970, 771.0, 27.7669
43.952754180, 23.970, 773.0, 27.8029
43.996219940, 23.970, 776.0, 27.8568
44.039685700, 23.970, 776.0, 27.8568
44.083151460, 23.970, 776.0, 27.8568
44.126617220, 23.970, 800.0, 28.2843
44.170082980, 23.970, 814.0, 28.5307
44.213548740, 23.970, 782.0, 27.9643
44.257014500, 23.970, 746.0, 27.3130
44.300480260, 23.970, 810.0, 28.4605
44.343946020, 23.970, 723.0, 26.8887
44.387411780, 23.970, 799.0, 28.2666
44.430877540, 23.970, 809.0, 28.4429
44.474343300, 23.970, 786.0, 28.0357
44.517809060, 23.970, 784.0, 28.0000
44.561274820, 23.970, 746.0, 27.3130
44.604740580, 23.970, 796.0, 28.2135
44.648206340, 23.970, 732.0, 27.0555
44.691672100, 23.970, 780.0, 27.9285
44.735137860, 23.970, 775.0, 27.8388
44.778603620, 23.970, 765.0, 27.6586
44.822069380, 23.970, 756.0, 27.4955
44.865535140, 23.970, 808.0, 28.4253
44.909000900, 23.970, 761.0, 27.5862
44.952466660, 23.970, 774.0, 27.8209
44.995932420, 23.970, 806.0, 28.3901
45.039398180, 23.970, 720.0, 26.8328
45.082863940, 23.970, 795.0, 28.1957
45.126329700, 23.970, 782.0, 27.9643
45.169795460, 23.970, 748.0, 27.3496
45.213261220, 23.970, 771.0, 27.7669
45.256726980, 23.970, 754.0, 27.4591
45.300192740, 23.970, 781.0, 27.9464
45.343658500, 23.970, 782.0, 27.9643
45.387124260, 23.970, 777.0, 27.8747
45.430590020, 23.970, 733.0, 27.0740
45.474055780, 23.970, 757.0, 27.5136
45.517521540, 23.970, 795.0, 28.1957
45.560987300, 23.970, 828.0, 28.7750
45.604453060, 23.970, 757.0, 27.5136
45.647918820, 23.970, 831.0, 28.8271
45.691384580, 23.970, 796.0, 28.2135
45.734850340, 23.970, 780.0, 27.9285
45.778316100, 23.970, 789.0, 28.0891
45.821781860, 23.970, 780.0, 27.9285
45.865247620, 23.970, 802.0, 28.3196
45.908713380, 23.970, 818.0, 28.6007
45.952179140, 23.970, 792.0, 28.1425
45.995644900, 23.970, 807.0, 28.4077
46.039110660, 23.970, 794.0, 28.1780
46.082576420, 23.970, 882.0, 29.6985
46.126042180, 23.970, 863.0, 29.3769
46.169507940, 23.970, 814.0, 28.5307
46.212973700, 23.970, 837.0, 28.9310
46.256439460, 23.970, 819.0, 28.6182
46.299905220, 23.970, 916.0, 30.2655
46.343370980, 23.970, 837.0, 28.9310
46.386836740, 23.970, 862.0, 29.3598
46.430302500, 23.970, 877.0, 29.6142
46.473768260, 23.970, 943.0, 30.7083
46.517234020, 23.970, 943.0, 30.7083
46.560699780, 23.970, 960.0, 30.9839
46.604165540, 23.970, 968.0, 31.1127
46.647631300, 23.970, 982.0, 31.3369
46.691097060, 23.970, 998.0, 31.5911
46.734562820, 23.970, 1003.0, 31.6702
46.778028580, 23.970, 1049.0, 32.3883
46.821494340, 23.970, 1072.0, 32.7414
46.864960100, 23.970, 1077.0, 32.8177
46.908425860, 23.970, 1055.0, 32.4808
46.951891620, 23.970, 1130.0, 33.6155
46.995357380, 23.970, 1066.0, 32.6497
47.038823140, 23.970, 982.0, 31.3369
47.082288900, 23.970, 942.0, 30.6920
47.125754660, 23.970, 948.0, 30.7896
47.169220420, 23.970, 885.0, 29.7489
47.212686180, 23.970, 846.0, 29.0861
47.256151940, 23.970, 889.0, 29.8161
47.299617700, 23.970, 867.0, 29.4449
47.343083460, 23.970, 940.0, 30.6594
47.386549220, 23.970, 914.0, 30.2324
47.430014980, 23.970, 870.0, 29.4958
47.473480740, 23.970, 912.0, 30.1993
47.516946500, 23.970, 897.0, 29.9500
47.560412260, 23.970, 869.0, 29.4788
47.603878020, 23.970, 877.0, 29.6142
47.647343780, 23.970, 905.0, 30.0832
47.690809540, 23.970, 888.0, 29.7993
47.734275300, 23.970, 973.0, 31.1929
47.777741060, 23.970, 931.0, 30.5123
47.821206820, 23.970, 915.0, 30.2490
47.864672580, 23.970, 920.0, 30.3315
47.908138340, 23.970, 924.0, 30.3974
47.951604100, 23.970, 888.0, 29.7993
47.995069860, 23.970, 915.0, 30.2490
48.038535620, 23.970, 819.0, 28.6182
48.082001380, 23.970, 761.0, 27.5862
48.125467140, 23.970, 786.0, 28.0357
48.168932900, 23.970, 750.0, 27.3861
48.212398660, 23.970, 766.0, 27.6767
48.255864420, 23.970, 756.0, 27.4955
48.299330180, 23.970, 738.0, 27.1662
48.342795940, 23.970, 737.0, 27.1477
48.386261700, 23.970, 743.0, 27.2580
48.429727460, 23.970, 766.0, 27.6767
48.473193220, 23.970, 699.0, 26.4386
48.516658980, 23.970, 739.0, 27.1846
48.560124740, 23.970, 715.0, 26.7395
48.603590500, 23.970, 704.0, 26.5330
48.647056260, 23.970, 734.0, 27.0924
48.690522020, 23.970, 696.0, 26.3818
48.733987780, 23.970, 753.0, 27.4408
48.777453540, 23.970, 679.0, 26.0576
48.820919300, 23.970, 737.0, 27.1477
48.864385060, 23.970, 738.0, 27.1662
48.907850820, 23.970, 746.0, 27.3130
48.951316580, 23.970, 745.0, 27.2947
48.994782340, 23.970, 750.0, 27.3861
49.038248100, 23.970, 690.0, 26.2679
49.081713860, 23.970, 738.0, 27.1662
49.125179620, 23.970, 687.0, 26.2107
49.168645380, 23.970, 739.0, 27.1846
49.212111140, 23.970, 737.0, 27.1477
49.255576900, 23.970, 690.0, 26.2679
49.299042660, 23.970, 719.0, 26.8142
49.342508420, 23.970, 698.0, 26.4197
49.385974180, 23.970, 678.0, 26.0384
49.429439940, 23.970, 740.0, 27.2029
49.472905700, 23.970, 685.0, 26.1725
49.516371460, 23.970, 746.0, 27.3130
49.559837220, 23.970, 682.0, 26.1151
49.603302980, 23.970, 645.0, 25.3969
49.646768740, 23.970, 690.0, 26.2679
49.690234500, 23.970, 699.0, 26.4386
49.733700260, 23.970, 680.0, 26.0768
49.777166020, 23.970, 691.0, 26.2869
49.820631780, 23.970, 625.0, 25.0000
49.864097540, 23.970, 748.0, 27.3496
49.907563300, 23.970, 672.0, 25.9230
49.951029060, 23.970, 645.0, 25.3969
49.994494820, 23.970, 692.0, 26.3059