File: data/XRD/HDPE_2.csv
[Measurement conditions]
Sample identification,HDPE_2
Comment,
Anode material,Cu
K-Alpha1 wavelength,1.5405980
K-Alpha2 wavelength,1.5444260
Ratio K-Alpha2/K-Alpha1,0.500
Divergence slit,Fixed,0.38mm
Monochromator used,NO
Generator voltage, 40
Tube current, 15
File date and time,26/Feb/2025 11:37
Unit cell,
h k l, 0 0 0
Scan axis,Gonio
Scan range,5.002000000,49.999928040
Scan step size,0.0108664
No. of points, 4141
Scan type,CONTINUOUS
Time per step,23.970
[Scan points]
Angle, TimePerStep, Intensity, ESD
5.007433220, 23.970, 1607.0, 40.0874
5.050898980, 23.970, 1485.0, 38.5357
5.094364740, 23.970, 1605.0, 40.0625
5.137830500, 23.970, 1640.0, 40.4969
5.181296260, 23.970, 1628.0, 40.3485
5.224762020, 23.970, 1684.0, 41.0366
5.268227780, 23.970, 1748.0, 41.8091
5.311693540, 23.970, 1682.0, 41.0122
5.355159300, 23.970, 1701.0, 41.2432
5.398625060, 23.970, 1690.0, 41.1096
5.442090820, 23.970, 1792.0, 42.3320
5.485556580, 23.970, 1812.0, 42.5676
5.529022340, 23.970, 1792.0, 42.3320
5.572488100, 23.970, 1818.0, 42.6380
5.615953860, 23.970, 1889.0, 43.4626
5.659419620, 23.970, 1861.0, 43.1393
5.702885380, 23.970, 1895.0, 43.5316
5.746351140, 23.970, 1899.0, 43.5775
5.789816900, 23.970, 1868.0, 43.2204
5.833282660, 23.970, 1951.0, 44.1701
5.876748420, 23.970, 1978.0, 44.4747
5.920214180, 23.970, 1909.0, 43.6921
5.963679940, 23.970, 2037.0, 45.1331
6.007145700, 23.970, 1926.0, 43.8862
6.050611460, 23.970, 2067.0, 45.4643
6.094077220, 23.970, 2042.0, 45.1885
6.137542980, 23.970, 2067.0, 45.4643
6.181008740, 23.970, 2027.0, 45.0222
6.224474500, 23.970, 2103.0, 45.8585
6.267940260, 23.970, 2040.0, 45.1664
6.311406020, 23.970, 2187.0, 46.7654
6.354871780, 23.970, 2216.0, 47.0744
6.398337540, 23.970, 2167.0, 46.5510
6.441803300, 23.970, 2204.0, 46.9468
6.485269060, 23.970, 2143.0, 46.2925
6.528734820, 23.970, 2201.0, 46.9148
6.572200580, 23.970, 2180.0, 46.6905
6.615666340, 23.970, 2349.0, 48.4665
6.659132100, 23.970, 2245.0, 47.3814
6.702597860, 23.970, 2329.0, 48.2597
6.746063620, 23.970, 2354.0, 48.5180
6.789529380, 23.970, 2182.0, 46.7119
6.832995140, 23.970, 2309.0, 48.0521
6.876460900, 23.970, 2339.0, 48.3632
6.919926660, 23.970, 2305.0, 48.0104
6.963392420, 23.970, 2281.0, 47.7598
7.006858180, 23.970, 2331.0, 48.2804
7.050323940, 23.970, 2392.0, 48.9081
7.093789700, 23.970, 2513.0, 50.1298
7.137255460, 23.970, 2452.0, 49.5177
7.180721220, 23.970, 2530.0, 50.2991
7.224186980, 23.970, 2512.0, 50.1199
7.267652740, 23.970, 2435.0, 49.3457
7.311118500, 23.970, 2502.0, 50.0200
7.354584260, 23.970, 2434.0, 49.3356
7.398050020, 23.970, 2536.0, 50.3587
7.441515780, 23.970, 2475.0, 49.7494
7.484981540, 23.970, 2670.0, 51.6720
7.528447300, 23.970, 2588.0, 50.8724
7.571913060, 23.970, 2606.0, 51.0490
7.615378820, 23.970, 2588.0, 50.8724
7.658844580, 23.970, 2625.0, 51.2348
7.702310340, 23.970, 2682.0, 51.7880
7.745776100, 23.970, 2641.0, 51.3907
7.789241860, 23.970, 2642.0, 51.4004
7.832707620, 23.970, 2683.0, 51.7977
7.876173380, 23.970, 2628.0, 51.2640
7.919639140, 23.970, 2677.0, 51.7397
7.963104900, 23.970, 2660.0, 51.5752
8.006570660, 23.970, 2678.0, 51.7494
8.050036420, 23.970, 2712.0, 52.0769
8.093502180, 23.970, 2619.0, 51.1762
8.136967940, 23.970, 2725.0, 52.2015
8.180433700, 23.970, 2698.0, 51.9423
8.223899460, 23.970, 2712.0, 52.0769
8.267365220, 23.970, 2887.0, 53.7308
8.310830980, 23.970, 2714.0, 52.0961
8.354296740, 23.970, 2713.0, 52.0865
8.397762500, 23.970, 2649.0, 51.4684
8.441228260, 23.970, 2668.0, 51.6527
8.484694020, 23.970, 2721.0, 52.1632
8.528159780, 23.970, 2791.0, 52.8299
8.571625540, 23.970, 2831.0, 53.2071
8.615091300, 23.970, 2773.0, 52.6593
8.658557060, 23.970, 2758.0, 52.5167
8.702022820, 23.970, 2824.0, 53.1413
8.745488580, 23.970, 2671.0, 51.6817
8.788954340, 23.970, 2823.0, 53.1319
8.832420100, 23.970, 2696.0, 51.9230
8.875885860, 23.970, 2774.0, 52.6688
8.919351620, 23.970, 2642.0, 51.4004
8.962817380, 23.970, 2761.0, 52.5452
9.006283140, 23.970, 2775.0, 52.6783
9.049748900, 23.970, 2747.0, 52.4118
9.093214660, 23.970, 2834.0, 53.2353
9.136680420, 23.970, 2790.0, 52.8205
9.180146180, 23.970, 2694.0, 51.9038
9.223611940, 23.970, 2881.0, 53.6749
9.267077700, 23.970, 2747.0, 52.4118
9.310543460, 23.970, 2683.0, 51.7977
9.354009220, 23.970, 2672.0, 51.6914
9.397474980, 23.970, 2817.0, 53.0754
9.440940740, 23.970, 2632.0, 51.3030
9.484406500, 23.970, 2890.0, 53.7587
9.527872260, 23.970, 2664.0, 51.6140
9.571338020, 23.970, 2669.0, 51.6624
9.614803780, 23.970, 2716.0, 52.1153
9.658269540, 23.970, 2775.0, 52.6783
9.701735300, 23.970, 2636.0, 51.3420
9.745201060, 23.970, 2674.0, 51.7107
9.788666820, 23.970, 2696.0, 51.9230
9.832132580, 23.970, 2694.0, 51.9038
9.875598340, 23.970, 2693.0, 51.8941
9.919064100, 23.970, 2696.0, 51.9230
9.962529860, 23.970, 2673.0, 51.7011
10.005995620, 23.970, 2747.0, 52.4118
10.049461380, 23.970, 2611.0, 51.0979
10.092927140, 23.970, 2637.0, 51.3517
10.136392900, 23.970, 2668.0, 51.6527
10.179858660, 23.970, 2564.0, 50.6360
10.223324420, 23.970, 2657.0, 51.5461
10.266790180, 23.970, 2618.0, 51.1664
10.310255940, 23.970, 2488.0, 49.8799
10.353721700, 23.970, 2614.0, 51.1273
10.397187460, 23.970, 2510.0, 50.0999
10.440653220, 23.970, 2536.0, 50.3587
10.484118980, 23.970, 2573.0, 50.7247
10.527584740, 23.970, 2485.0, 49.8498
10.571050500, 23.970, 2566.0, 50.6557
10.614516260, 23.970, 2583.0, 50.8232
10.657982020, 23.970, 2538.0, 50.3786
10.701447780, 23.970, 2512.0, 50.1199
10.744913540, 23.970, 2529.0, 50.2892
10.788379300, 23.970, 2500.0, 50.0000
10.831845060, 23.970, 2497.0, 49.9700
10.875310820, 23.970, 2442.0, 49.4166
10.918776580, 23.970, 2525.0, 50.2494
10.962242340, 23.970, 2508.0, 50.0799
11.005708100, 23.970, 2416.0, 49.1528
11.049173860, 23.970, 2466.0, 49.6588
11.092639620, 23.970, 2440.0, 49.3964
11.136105380, 23.970, 2482.0, 49.8197
11.179571140, 23.970, 2407.0, 49.0612
11.223036900, 23.970, 2419.0, 49.1833
11.266502660, 23.970, 2423.0, 49.2240
11.309968420, 23.970, 2483.0, 49.8297
11.353434180, 23.970, 2390.0, 48.8876
11.396899940, 23.970, 2458.0, 49.5782
11.440365700, 23.970, 2406.0, 49.0510
11.483831460, 23.970, 2363.0, 48.6107
11.527297220, 23.970, 2420.0, 49.1935
11.570762980, 23.970, 2351.0, 48.4871
11.614228740, 23.970, 2334.0, 48.3115
11.657694500, 23.970, 2285.0, 47.8017
11.701160260, 23.970, 2282.0, 47.7703
11.744626020, 23.970, 2271.0, 47.6550
11.788091780, 23.970, 2265.0, 47.5920
11.831557540, 23.970, 2342.0, 48.3942
11.875023300, 23.970, 2304.0, 48.0000
11.918489060, 23.970, 2259.0, 47.5289
11.961954820, 23.970, 2278.0, 47.7284
12.005420580, 23.970, 2170.0, 46.5833
12.048886340, 23.970, 2273.0, 47.6760
12.092352100, 23.970, 2278.0, 47.7284
12.135817860, 23.970, 2194.0, 46.8402
12.179283620, 23.970, 2250.0, 47.4342
12.222749380, 23.970, 2210.0, 47.0106
12.266215140, 23.970, 2218.0, 47.0956
12.309680900, 23.970, 2159.0, 46.4650
12.353146660, 23.970, 2200.0, 46.9042
12.396612420, 23.970, 2054.0, 45.3211
12.440078180, 23.970, 2169.0, 46.5725
12.483543940, 23.970, 2238.0, 47.3075
12.527009700, 23.970, 2219.0, 47.1063
12.570475460, 23.970, 2173.0, 46.6154
12.613941220, 23.970, 2246.0, 47.3920
12.657406980, 23.970, 2101.0, 45.8367
12.700872740, 23.970, 2130.0, 46.1519
12.744338500, 23.970, 2178.0, 46.6690
12.787804260, 23.970, 2128.0, 46.1303
12.831270020, 23.970, 2209.0, 47.0000
12.874735780, 23.970, 2159.0, 46.4650
12.918201540, 23.970, 2170.0, 46.5833
12.961667300, 23.970, 2277.0, 47.7179
13.005133060, 23.970, 1999.0, 44.7102
13.048598820, 23.970, 2149.0, 46.3573
13.092064580, 23.970, 2137.0, 46.2277
13.135530340, 23.970, 2174.0, 46.6262
13.178996100, 23.970, 2164.0, 46.5188
13.222461860, 23.970, 2154.0, 46.4112
13.265927620, 23.970, 2168.0, 46.5618
13.309393380, 23.970, 2124.0, 46.0869
13.352859140, 23.970, 2161.0, 46.4866
13.396324900, 23.970, 2143.0, 46.2925
13.439790660, 23.970, 2074.0, 45.5412
13.483256420, 23.970, 2125.0, 46.0977
13.526722180, 23.970, 2080.0, 45.6070
13.570187940, 23.970, 2171.0, 46.5940
13.613653700, 23.970, 2182.0, 46.7119
13.657119460, 23.970, 2092.0, 45.7384
13.700585220, 23.970, 2104.0, 45.8694
13.744050980, 23.970, 2122.0, 46.0652
13.787516740, 23.970, 2181.0, 46.7012
13.830982500, 23.970, 2149.0, 46.3573
13.874448260, 23.970, 2062.0, 45.4093
13.917914020, 23.970, 2097.0, 45.7930
13.961379780, 23.970, 2136.0, 46.2169
14.004845540, 23.970, 2135.0, 46.2061
14.048311300, 23.970, 2088.0, 45.6946
14.091777060, 23.970, 2173.0, 46.6154
14.135242820, 23.970, 2185.0, 46.7440
14.178708580, 23.970, 2175.0, 46.6369
14.222174340, 23.970, 2242.0, 47.3498
14.265640100, 23.970, 2235.0, 47.2758
14.309105860, 23.970, 2140.0, 46.2601
14.352571620, 23.970, 2263.0, 47.5710
14.396037380, 23.970, 2156.0, 46.4327
14.439503140, 23.970, 2253.0, 47.4658
14.482968900, 23.970, 2205.0, 46.9574
14.526434660, 23.970, 2138.0, 46.2385
14.569900420, 23.970, 2199.0, 46.8935
14.613366180, 23.970, 2268.0, 47.6235
14.656831940, 23.970, 2227.0, 47.1911
14.700297700, 23.970, 2253.0, 47.4658
14.743763460, 23.970, 2278.0, 47.7284
14.787229220, 23.970, 2238.0, 47.3075
14.830694980, 23.970, 2276.0, 47.7074
14.874160740, 23.970, 2172.0, 46.6047
14.917626500, 23.970, 2289.0, 47.8435
14.961092260, 23.970, 2207.0, 46.9787
15.004558020, 23.970, 2424.0, 49.2341
15.048023780, 23.970, 2315.0, 48.1144
15.091489540, 23.970, 2311.0, 48.0729
15.134955300, 23.970, 2337.0, 48.3425
15.178421060, 23.970, 2337.0, 48.3425
15.221886820, 23.970, 2380.0, 48.7852
15.265352580, 23.970, 2349.0, 48.4665
15.308818340, 23.970, 2358.0, 48.5592
15.352284100, 23.970, 2369.0, 48.6724
15.395749860, 23.970, 2411.0, 49.1019
15.439215620, 23.970, 2323.0, 48.1975
15.482681380, 23.970, 2356.0, 48.5386
15.526147140, 23.970, 2461.0, 49.6085
15.569612900, 23.970, 2442.0, 49.4166
15.613078660, 23.970, 2489.0, 49.8899
15.656544420, 23.970, 2491.0, 49.9099
15.700010180, 23.970, 2459.0, 49.5883
15.743475940, 23.970, 2545.0, 50.4480
15.786941700, 23.970, 2514.0, 50.1398
15.830407460, 23.970, 2497.0, 49.9700
15.873873220, 23.970, 2527.0, 50.2693
15.917338980, 23.970, 2587.0, 50.8626
15.960804740, 23.970, 2573.0, 50.7247
16.004270500, 23.970, 2614.0, 51.1273
16.047736260, 23.970, 2615.0, 51.1371
16.091202020, 23.970, 2659.0, 51.5655
16.134667780, 23.970, 2619.0, 51.1762
16.178133540, 23.970, 2552.0, 50.5173
16.221599300, 23.970, 2618.0, 51.1664
16.265065060, 23.970, 2762.0, 52.5547
16.308530820, 23.970, 2802.0, 52.9339
16.351996580, 23.970, 2831.0, 53.2071
16.395462340, 23.970, 2742.0, 52.3641
16.438928100, 23.970, 2861.0, 53.4883
16.482393860, 23.970, 2838.0, 53.2729
16.525859620, 23.970, 2873.0, 53.6004
16.569325380, 23.970, 2877.0, 53.6377
16.612791140, 23.970, 3070.0, 55.4076
16.656256900, 23.970, 2969.0, 54.4885
16.699722660, 23.970, 3060.0, 55.3173
16.743188420, 23.970, 2973.0, 54.5252
16.786654180, 23.970, 3058.0, 55.2992
16.830119940, 23.970, 3044.0, 55.1725
16.873585700, 23.970, 2985.0, 54.6352
16.917051460, 23.970, 3169.0, 56.2939
16.960517220, 23.970, 3171.0, 56.3116
17.003982980, 23.970, 3282.0, 57.2887
17.047448740, 23.970, 3299.0, 57.4369
17.090914500, 23.970, 3308.0, 57.5152
17.134380260, 23.970, 3311.0, 57.5413
17.177846020, 23.970, 3358.0, 57.9483
17.221311780, 23.970, 3345.0, 57.8360
17.264777540, 23.970, 3455.0, 58.7792
17.308243300, 23.970, 3452.0, 58.7537
17.351709060, 23.970, 3468.0, 58.8897
17.395174820, 23.970, 3601.0, 60.0083
17.438640580, 23.970, 3596.0, 59.9667
17.482106340, 23.970, 3640.0, 60.3324
17.525572100, 23.970, 3820.0, 61.8061
17.569037860, 23.970, 3766.0, 61.3677
17.612503620, 23.970, 3821.0, 61.8142
17.655969380, 23.970, 3878.0, 62.2736
17.699435140, 23.970, 3976.0, 63.0555
17.742900900, 23.970, 4005.0, 63.2851
17.786366660, 23.970, 4040.0, 63.5610
17.829832420, 23.970, 4199.0, 64.7997
17.873298180, 23.970, 4160.0, 64.4981
17.916763940, 23.970, 4234.0, 65.0692
17.960229700, 23.970, 4199.0, 64.7997
18.003695460, 23.970, 4263.0, 65.2917
18.047161220, 23.970, 4387.0, 66.2344
18.090626980, 23.970, 4358.0, 66.0151
18.134092740, 23.970, 4433.0, 66.5808
18.177558500, 23.970, 4555.0, 67.4907
18.221024260, 23.970, 4455.0, 66.7458
18.264490020, 23.970, 4619.0, 67.9632
18.307955780, 23.970, 4626.0, 68.0147
18.351421540, 23.970, 4744.0, 68.8767
18.394887300, 23.970, 4655.0, 68.2276
18.438353060, 23.970, 4848.0, 69.6276
18.481818820, 23.970, 4860.0, 69.7137
18.525284580, 23.970, 4833.0, 69.5198
18.568750340, 23.970, 5020.0, 70.8520
18.612216100, 23.970, 4872.0, 69.7997
18.655681860, 23.970, 5180.0, 71.9722
18.699147620, 23.970, 5236.0, 72.3602
18.742613380, 23.970, 5341.0, 73.0821
18.786079140, 23.970, 5271.0, 72.6017
18.829544900, 23.970, 5336.0, 73.0479
18.873010660, 23.970, 5429.0, 73.6817
18.916476420, 23.970, 5448.0, 73.8106
18.959942180, 23.970, 5512.0, 74.2428
19.003407940, 23.970, 5578.0, 74.6860
19.046873700, 23.970, 5671.0, 75.3060
19.090339460, 23.970, 5783.0, 76.0460
19.133805220, 23.970, 5678.0, 75.3525
19.177270980, 23.970, 5735.0, 75.7298
19.220736740, 23.970, 5881.0, 76.6877
19.264202500, 23.970, 6124.0, 78.2560
19.307668260, 23.970, 6001.0, 77.4661
19.351134020, 23.970, 6133.0, 78.3135
19.394599780, 23.970, 6231.0, 78.9367
19.438065540, 23.970, 6339.0, 79.6178
19.481531300, 23.970, 6254.0, 79.0822
19.524997060, 23.970, 6287.0, 79.2906
19.568462820, 23.970, 6377.0, 79.8561
19.611928580, 23.970, 6365.0, 79.7810
19.655394340, 23.970, 6247.0, 79.0380
19.698860100, 23.970, 6314.0, 79.4607
19.742325860, 23.970, 6268.0, 79.1707
19.785791620, 23.970, 6296.0, 79.3473
19.829257380, 23.970, 6524.0, 80.7713
19.872723140, 23.970, 6516.0, 80.7217
19.916188900, 23.970, 6428.0, 80.1748
19.959654660, 23.970, 6408.0, 80.0500
20.003120420, 23.970, 6511.0, 80.6908
20.046586180, 23.970, 6566.0, 81.0309
20.090051940, 23.970, 6555.0, 80.9630
20.133517700, 23.970, 6614.0, 81.3265
20.176983460, 23.970, 6734.0, 82.0610
20.220449220, 23.970, 6759.0, 82.2131
20.263914980, 23.970, 6930.0, 83.2466
20.307380740, 23.970, 6934.0, 83.2706
20.350846500, 23.970, 7210.0, 84.9117
20.394312260, 23.970, 7274.0, 85.2877
20.437778020, 23.970, 7363.0, 85.8079
20.481243780, 23.970, 7575.0, 87.0345
20.524709540, 23.970, 7671.0, 87.5842
20.568175300, 23.970, 7851.0, 88.6059
20.611641060, 23.970, 8279.0, 90.9890
20.655106820, 23.970, 8499.0, 92.1900
20.698572580, 23.970, 9261.0, 96.2341
20.742038340, 23.970, 9694.0, 98.4581
20.785504100, 23.970, 10554.0, 102.7327
20.828969860, 23.970, 11705.0, 108.1896
20.872435620, 23.970, 13128.0, 114.5775
20.915901380, 23.970, 14523.0, 120.5114
20.959367140, 23.970, 16295.0, 127.6519
21.002832900, 23.970, 18569.0, 136.2681
21.046298660, 23.970, 21131.0, 145.3651
21.089764420, 23.970, 23508.0, 153.3232
21.133230180, 23.970, 26746.0, 163.5420
21.176695940, 23.970, 30139.0, 173.6059
21.220161700, 23.970, 34362.0, 185.3699
21.263627460, 23.970, 39065.0, 197.6487
21.307093220, 23.970, 44548.0, 211.0640
21.350558980, 23.970, 51366.0, 226.6407
21.394024740, 23.970, 59219.0, 243.3495
21.437490500, 23.970, 69246.0, 263.1463
21.480956260, 23.970, 80181.0, 283.1625
21.524422020, 23.970, 92364.0, 303.9145
21.567887780, 23.970, 102331.0, 319.8922
21.611353540, 23.970, 103757.0, 322.1133
21.654819300, 23.970, 95703.0, 309.3590
21.698285060, 23.970, 78754.0, 280.6314
21.741750820, 23.970, 58901.0, 242.6953
21.785216580, 23.970, 40112.0, 200.2798
21.828682340, 23.970, 27350.0, 165.3784
21.872148100, 23.970, 19688.0, 140.3139
21.915613860, 23.970, 14939.0, 122.2252
21.959079620, 23.970, 12087.0, 109.9409
22.002545380, 23.970, 10339.0, 101.6809
22.046011140, 23.970, 9201.0, 95.9218
22.089476900, 23.970, 8244.0, 90.7965
22.132942660, 23.970, 7426.0, 86.1742
22.176408420, 23.970, 6865.0, 82.8553
22.219874180, 23.970, 6378.0, 79.8624
22.263339940, 23.970, 6123.0, 78.2496
22.306805700, 23.970, 6004.0, 77.4855
22.350271460, 23.970, 5854.0, 76.5114
22.393737220, 23.970, 5483.0, 74.0473
22.437202980, 23.970, 5454.0, 73.8512
22.480668740, 23.970, 5377.0, 73.3280
22.524134500, 23.970, 5351.0, 73.1505
22.567600260, 23.970, 5135.0, 71.6589
22.611066020, 23.970, 5048.0, 71.0493
22.654531780, 23.970, 5132.0, 71.6380
22.697997540, 23.970, 4955.0, 70.3918
22.741463300, 23.970, 5031.0, 70.9295
22.784929060, 23.970, 4953.0, 70.3776
22.828394820, 23.970, 4933.0, 70.2353
22.871860580, 23.970, 4934.0, 70.2424
22.915326340, 23.970, 4945.0, 70.3207
22.958792100, 23.970, 4940.0, 70.2851
23.002257860, 23.970, 4997.0, 70.6895
23.045723620, 23.970, 5064.0, 71.1618
23.089189380, 23.970, 5136.0, 71.6659
23.132655140, 23.970, 5283.0, 72.6842
23.176120900, 23.970, 5526.0, 74.3371
23.219586660, 23.970, 5630.0, 75.0333
23.263052420, 23.970, 5879.0, 76.6746
23.306518180, 23.970, 6291.0, 79.3158
23.349983940, 23.970, 6588.0, 81.1665
23.393449700, 23.970, 7324.0, 85.5804
23.436915460, 23.970, 7607.0, 87.2181
23.480381220, 23.970, 8331.0, 91.2743
23.523846980, 23.970, 9098.0, 95.3834
23.567312740, 23.970, 9776.0, 98.8737
23.610778500, 23.970, 10644.0, 103.1698
23.654244260, 23.970, 11506.0, 107.2660
23.697710020, 23.970, 12605.0, 112.2720
23.741175780, 23.970, 14015.0, 118.3850
23.784641540, 23.970, 15317.0, 123.7619
23.828107300, 23.970, 17487.0, 132.2384
23.871573060, 23.970, 19152.0, 138.3908
23.915038820, 23.970, 21407.0, 146.3113
23.958504580, 23.970, 22810.0, 151.0298
24.001970340, 23.970, 23070.0, 151.8881
24.045436100, 23.970, 22320.0, 149.3988
24.088901860, 23.970, 20155.0, 141.9683
24.132367620, 23.970, 17253.0, 131.3507
24.175833380, 23.970, 13836.0, 117.6265
24.219299140, 23.970, 11022.0, 104.9857
24.262764900, 23.970, 8878.0, 94.2231
24.306230660, 23.970, 7078.0, 84.1309
24.349696420, 23.970, 6021.0, 77.5951
24.393162180, 23.970, 4852.0, 69.6563
24.436627940, 23.970, 4372.0, 66.1211
24.480093700, 23.970, 3985.0, 63.1269
24.523559460, 23.970, 3723.0, 61.0164
24.567025220, 23.970, 3394.0, 58.2580
24.610490980, 23.970, 3190.0, 56.4801
24.653956740, 23.970, 3254.0, 57.0438
24.697422500, 23.970, 2981.0, 54.5985
24.740888260, 23.970, 2956.0, 54.3691
24.784354020, 23.970, 2844.0, 53.3292
24.827819780, 23.970, 2822.0, 53.1225
24.871285540, 23.970, 2777.0, 52.6972
24.914751300, 23.970, 2557.0, 50.5668
24.958217060, 23.970, 2699.0, 51.9519
25.001682820, 23.970, 2514.0, 50.1398
25.045148580, 23.970, 2533.0, 50.3289
25.088614340, 23.970, 2491.0, 49.9099
25.132080100, 23.970, 2355.0, 48.5283
25.175545860, 23.970, 2323.0, 48.1975
25.219011620, 23.970, 2470.0, 49.6991
25.262477380, 23.970, 2339.0, 48.3632
25.305943140, 23.970, 2271.0, 47.6550
25.349408900, 23.970, 2239.0, 47.3181
25.392874660, 23.970, 2285.0, 47.8017
25.436340420, 23.970, 2176.0, 46.6476
25.479806180, 23.970, 2126.0, 46.1086
25.523271940, 23.970, 2119.0, 46.0326
25.566737700, 23.970, 2118.0, 46.0217
25.610203460, 23.970, 2124.0, 46.0869
25.653669220, 23.970, 2056.0, 45.3431
25.697134980, 23.970, 2084.0, 45.6508
25.740600740, 23.970, 1999.0, 44.7102
25.784066500, 23.970, 2039.0, 45.1553
25.827532260, 23.970, 1975.0, 44.4410
25.870998020, 23.970, 2032.0, 45.0777
25.914463780, 23.970, 1978.0, 44.4747
25.957929540, 23.970, 1998.0, 44.6990
26.001395300, 23.970, 1875.0, 43.3013
26.044861060, 23.970, 1907.0, 43.6692
26.088326820, 23.970, 1842.0, 42.9185
26.131792580, 23.970, 1959.0, 44.2606
26.175258340, 23.970, 1896.0, 43.5431
26.218724100, 23.970, 1861.0, 43.1393
26.262189860, 23.970, 1808.0, 42.5206
26.305655620, 23.970, 1794.0, 42.3556
26.349121380, 23.970, 1724.0, 41.5211
26.392587140, 23.970, 1692.0, 41.1339
26.436052900, 23.970, 1757.0, 41.9166
26.479518660, 23.970, 1781.0, 42.2019
26.522984420, 23.970, 1771.0, 42.0833
26.566450180, 23.970, 1743.0, 41.7493
26.609915940, 23.970, 1709.0, 41.3401
26.653381700, 23.970, 1781.0, 42.2019
26.696847460, 23.970, 1642.0, 40.5216
26.740313220, 23.970, 1756.0, 41.9047
26.783778980, 23.970, 1709.0, 41.3401
26.827244740, 23.970, 1570.0, 39.6232
26.870710500, 23.970, 1721.0, 41.4849
26.914176260, 23.970, 1695.0, 41.1704
26.957642020, 23.970, 1638.0, 40.4722
27.001107780, 23.970, 1641.0, 40.5093
27.044573540, 23.970, 1604.0, 40.0500
27.088039300, 23.970, 1584.0, 39.7995
27.131505060, 23.970, 1691.0, 41.1218
27.174970820, 23.970, 1567.0, 39.5854
27.218436580, 23.970, 1543.0, 39.2810
27.261902340, 23.970, 1566.0, 39.5727
27.305368100, 23.970, 1508.0, 38.8330
27.348833860, 23.970, 1470.0, 38.3406
27.392299620, 23.970, 1593.0, 39.9124
27.435765380, 23.970, 1560.0, 39.4968
27.479231140, 23.970, 1534.0, 39.1663
27.522696900, 23.970, 1525.0, 39.0512
27.566162660, 23.970, 1529.0, 39.1024
27.609628420, 23.970, 1540.0, 39.2428
27.653094180, 23.970, 1444.0, 38.0000
27.696559940, 23.970, 1486.0, 38.5487
27.740025700, 23.970, 1432.0, 37.8418
27.783491460, 23.970, 1358.0, 36.8511
27.826957220, 23.970, 1452.0, 38.1051
27.870422980, 23.970, 1464.0, 38.2623
27.913888740, 23.970, 1469.0, 38.3275
27.957354500, 23.970, 1415.0, 37.6165
28.000820260, 23.970, 1412.0, 37.5766
28.044286020, 23.970, 1413.0, 37.5899
28.087751780, 23.970, 1413.0, 37.5899
28.131217540, 23.970, 1395.0, 37.3497
28.174683300, 23.970, 1317.0, 36.2905
28.218149060, 23.970, 1395.0, 37.3497
28.261614820, 23.970, 1375.0, 37.0810
28.305080580, 23.970, 1445.0, 38.0132
28.348546340, 23.970, 1394.0, 37.3363
28.392012100, 23.970, 1356.0, 36.8239
28.435477860, 23.970, 1359.0, 36.8646
28.478943620, 23.970, 1392.0, 37.3095
28.522409380, 23.970, 1409.0, 37.5366
28.565875140, 23.970, 1376.0, 37.0945
28.609340900, 23.970, 1382.0, 37.1753
28.652806660, 23.970, 1383.0, 37.1887
28.696272420, 23.970, 1440.0, 37.9473
28.739738180, 23.970, 1554.0, 39.4208
28.783203940, 23.970, 1640.0, 40.4969
28.826669700, 23.970, 1639.0, 40.4846
28.870135460, 23.970, 1613.0, 40.1622
28.913601220, 23.970, 1452.0, 38.1051
28.957066980, 23.970, 1373.0, 37.0540
29.000532740, 23.970, 1390.0, 37.2827
29.043998500, 23.970, 1317.0, 36.2905
29.087464260, 23.970, 1349.0, 36.7287
29.130930020, 23.970, 1368.0, 36.9865
29.174395780, 23.970, 1311.0, 36.2077
29.217861540, 23.970, 1305.0, 36.1248
29.261327300, 23.970, 1361.0, 36.8917
29.304793060, 23.970, 1407.0, 37.5100
29.348258820, 23.970, 1363.0, 36.9188
29.391724580, 23.970, 1385.0, 37.2156
29.435190340, 23.970, 1420.0, 37.6829
29.478656100, 23.970, 1395.0, 37.3497
29.522121860, 23.970, 1460.0, 38.2099
29.565587620, 23.970, 1538.0, 39.2173
29.609053380, 23.970, 1543.0, 39.2810
29.652519140, 23.970, 1654.0, 40.6694
29.695984900, 23.970, 1680.0, 40.9878
29.739450660, 23.970, 1717.0, 41.4367
29.782916420, 23.970, 1719.0, 41.4608
29.826382180, 23.970, 1854.0, 43.0581
29.869847940, 23.970, 1758.0, 41.9285
29.913313700, 23.970, 1924.0, 43.8634
29.956779460, 23.970, 2048.0, 45.2548
30.000245220, 23.970, 2059.0, 45.3762
30.043710980, 23.970, 2257.0, 47.5079
30.087176740, 23.970, 2275.0, 47.6970
30.130642500, 23.970, 2319.0, 48.1560
30.174108260, 23.970, 2274.0, 47.6865
30.217574020, 23.970, 2171.0, 46.5940
30.261039780, 23.970, 1932.0, 43.9545
30.304505540, 23.970, 1833.0, 42.8135
30.347971300, 23.970, 1596.0, 39.9500
30.391437060, 23.970, 1444.0, 38.0000
30.434902820, 23.970, 1411.0, 37.5633
30.478368580, 23.970, 1418.0, 37.6563
30.521834340, 23.970, 1262.0, 35.5246
30.565300100, 23.970, 1274.0, 35.6931
30.608765860, 23.970, 1205.0, 34.7131
30.652231620, 23.970, 1212.0, 34.8138
30.695697380, 23.970, 1217.0, 34.8855
30.739163140, 23.970, 1187.0, 34.4529
30.782628900, 23.970, 1185.0, 34.4238
30.826094660, 23.970, 1252.0, 35.3836
30.869560420, 23.970, 1118.0, 33.4365
30.913026180, 23.970, 1229.0, 35.0571
30.956491940, 23.970, 1194.0, 34.5543
30.999957700, 23.970, 1151.0, 33.9264
31.043423460, 23.970, 1112.0, 33.3467
31.086889220, 23.970, 1114.0, 33.3766
31.130354980, 23.970, 1111.0, 33.3317
31.173820740, 23.970, 1181.0, 34.3657
31.217286500, 23.970, 1139.0, 33.7491
31.260752260, 23.970, 1068.0, 32.6803
31.304218020, 23.970, 1103.0, 33.2114
31.347683780, 23.970, 1093.0, 33.0606
31.391149540, 23.970, 1107.0, 33.2716
31.434615300, 23.970, 1184.0, 34.4093
31.478081060, 23.970, 1122.0, 33.4963
31.521546820, 23.970, 1052.0, 32.4345
31.565012580, 23.970, 1067.0, 32.6650
31.608478340, 23.970, 1104.0, 33.2265
31.651944100, 23.970, 1138.0, 33.7343
31.695409860, 23.970, 1122.0, 33.4963
31.738875620, 23.970, 1109.0, 33.3017
31.782341380, 23.970, 1129.0, 33.6006
31.825807140, 23.970, 1073.0, 32.7567
31.869272900, 23.970, 1075.0, 32.7872
31.912738660, 23.970, 1095.0, 33.0908
31.956204420, 23.970, 1069.0, 32.6956
31.999670180, 23.970, 1149.0, 33.8969
32.043135940, 23.970, 1075.0, 32.7872
32.086601700, 23.970, 1122.0, 33.4963
32.130067460, 23.970, 1136.0, 33.7046
32.173533220, 23.970, 1143.0, 33.8083
32.216998980, 23.970, 1054.0, 32.4654
32.260464740, 23.970, 1054.0, 32.4654
32.303930500, 23.970, 1069.0, 32.6956
32.347396260, 23.970, 1035.0, 32.1714
32.390862020, 23.970, 1097.0, 33.1210
32.434327780, 23.970, 1118.0, 33.4365
32.477793540, 23.970, 1023.0, 31.9844
32.521259300, 23.970, 1101.0, 33.1813
32.564725060, 23.970, 1058.0, 32.5269
32.608190820, 23.970, 1046.0, 32.3419
32.651656580, 23.970, 1150.0, 33.9116
32.695122340, 23.970, 1034.0, 32.1559
32.738588100, 23.970, 1031.0, 32.1092
32.782053860, 23.970, 1029.0, 32.0780
32.825519620, 23.970, 1098.0, 33.1361
32.868985380, 23.970, 1068.0, 32.6803
32.912451140, 23.970, 1039.0, 32.2335
32.955916900, 23.970, 1087.0, 32.9697
32.999382660, 23.970, 1114.0, 33.3766
33.042848420, 23.970, 977.0, 31.2570
33.086314180, 23.970, 1074.0, 32.7719
33.129779940, 23.970, 1058.0, 32.5269
33.173245700, 23.970, 1079.0, 32.8481
33.216711460, 23.970, 1133.0, 33.6601
33.260177220, 23.970, 1073.0, 32.7567
33.303642980, 23.970, 1055.0, 32.4808
33.347108740, 23.970, 1044.0, 32.3110
33.390574500, 23.970, 989.0, 31.4484
33.434040260, 23.970, 1157.0, 34.0147
33.477506020, 23.970, 1129.0, 33.6006
33.520971780, 23.970, 1085.0, 32.9393
33.564437540, 23.970, 1030.0, 32.0936
33.607903300, 23.970, 1027.0, 32.0468
33.651369060, 23.970, 1044.0, 32.3110
33.694834820, 23.970, 1040.0, 32.2490
33.738300580, 23.970, 1049.0, 32.3883
33.781766340, 23.970, 992.0, 31.4960
33.825232100, 23.970, 1037.0, 32.2025
33.868697860, 23.970, 1065.0, 32.6343
33.912163620, 23.970, 1094.0, 33.0757
33.955629380, 23.970, 1010.0, 31.7805
33.999095140, 23.970, 1073.0, 32.7567
34.042560900, 23.970, 1052.0, 32.4345
34.086026660, 23.970, 1016.0, 31.8748
34.129492420, 23.970, 1069.0, 32.6956
34.172958180, 23.970, 1026.0, 32.0312
34.216423940, 23.970, 1018.0, 31.9061
34.259889700, 23.970, 1052.0, 32.4345
34.303355460, 23.970, 1061.0, 32.5730
34.346821220, 23.970, 1075.0, 32.7872
34.390286980, 23.970, 1091.0, 33.0303
34.433752740, 23.970, 1075.0, 32.7872
34.477218500, 23.970, 1114.0, 33.3766
34.520684260, 23.970, 1168.0, 34.1760
34.564150020, 23.970, 1102.0, 33.1964
34.607615780, 23.970, 1114.0, 33.3766
34.651081540, 23.970, 1170.0, 34.2053
34.694547300, 23.970, 1144.0, 33.8231
34.738013060, 23.970, 1072.0, 32.7414
34.781478820, 23.970, 1075.0, 32.7872
34.824944580, 23.970, 1178.0, 34.3220
34.868410340, 23.970, 1096.0, 33.1059
34.911876100, 23.970, 1148.0, 33.8821
34.955341860, 23.970, 1154.0, 33.9706
34.998807620, 23.970, 1153.0, 33.9559
35.042273380, 23.970, 1203.0, 34.6843
35.085739140, 23.970, 1151.0, 33.9264
35.129204900, 23.970, 1182.0, 34.3802
35.172670660, 23.970, 1198.0, 34.6121
35.216136420, 23.970, 1188.0, 34.4674
35.259602180, 23.970, 1227.0, 35.0286
35.303067940, 23.970, 1280.0, 35.7771
35.346533700, 23.970, 1329.0, 36.4555
35.389999460, 23.970, 1315.0, 36.2629
35.433465220, 23.970, 1360.0, 36.8782
35.476930980, 23.970, 1475.0, 38.4057
35.520396740, 23.970, 1422.0, 37.7094
35.563862500, 23.970, 1491.0, 38.6135
35.607328260, 23.970, 1589.0, 39.8623
35.650794020, 23.970, 1704.0, 41.2795
35.694259780, 23.970, 1830.0, 42.7785
35.737725540, 23.970, 2012.0, 44.8553
35.781191300, 23.970, 2305.0, 48.0104
35.824657060, 23.970, 2398.0, 48.9694
35.868122820, 23.970, 2599.0, 50.9804
35.911588580, 23.970, 2833.0, 53.2259
35.955054340, 23.970, 3014.0, 54.8999
35.998520100, 23.970, 3246.0, 56.9737
36.041985860, 23.970, 3486.0, 59.0424
36.085451620, 23.970, 3684.0, 60.6960
36.128917380, 23.970, 3772.0, 61.4166
36.172383140, 23.970, 3840.0, 61.9677
36.215848900, 23.970, 4024.0, 63.4350
36.259314660, 23.970, 4027.0, 63.4586
36.302780420, 23.970, 3963.0, 62.9524
36.346246180, 23.970, 3707.0, 60.8851
36.389711940, 23.970, 3382.0, 58.1550
36.433177700, 23.970, 3086.0, 55.5518
36.476643460, 23.970, 2698.0, 51.9423
36.520109220, 23.970, 2311.0, 48.0729
36.563574980, 23.970, 2095.0, 45.7712
36.607040740, 23.970, 1867.0, 43.2088
36.650506500, 23.970, 1628.0, 40.3485
36.693972260, 23.970, 1583.0, 39.7869
36.737438020, 23.970, 1433.0, 37.8550
36.780903780, 23.970, 1334.0, 36.5240
36.824369540, 23.970, 1338.0, 36.5787
36.867835300, 23.970, 1222.0, 34.9571
36.911301060, 23.970, 1338.0, 36.5787
36.954766820, 23.970, 1263.0, 35.5387
36.998232580, 23.970, 1223.0, 34.9714
37.041698340, 23.970, 1250.0, 35.3553
37.085164100, 23.970, 1211.0, 34.7994
37.128629860, 23.970, 1180.0, 34.3511
37.172095620, 23.970, 1146.0, 33.8526
37.215561380, 23.970, 1127.0, 33.5708
37.259027140, 23.970, 1141.0, 33.7787
37.302492900, 23.970, 1238.0, 35.1852
37.345958660, 23.970, 1236.0, 35.1568
37.389424420, 23.970, 1264.0, 35.5528
37.432890180, 23.970, 1160.0, 34.0588
37.476355940, 23.970, 1206.0, 34.7275
37.519821700, 23.970, 1237.0, 35.1710
37.563287460, 23.970, 1202.0, 34.6699
37.606753220, 23.970, 1241.0, 35.2278
37.650218980, 23.970, 1220.0, 34.9285
37.693684740, 23.970, 1230.0, 35.0714
37.737150500, 23.970, 1236.0, 35.1568
37.780616260, 23.970, 1299.0, 36.0416
37.824082020, 23.970, 1256.0, 35.4401
37.867547780, 23.970, 1349.0, 36.7287
37.911013540, 23.970, 1359.0, 36.8646
37.954479300, 23.970, 1328.0, 36.4417
37.997945060, 23.970, 1384.0, 37.2022
38.041410820, 23.970, 1483.0, 38.5097
38.084876580, 23.970, 1442.0, 37.9737
38.128342340, 23.970, 1454.0, 38.1314
38.171808100, 23.970, 1517.0, 38.9487
38.215273860, 23.970, 1512.0, 38.8844
38.258739620, 23.970, 1521.0, 39.0000
38.302205380, 23.970, 1567.0, 39.5854
38.345671140, 23.970, 1523.0, 39.0256
38.389136900, 23.970, 1464.0, 38.2623
38.432602660, 23.970, 1494.0, 38.6523
38.476068420, 23.970, 1506.0, 38.8072
38.519534180, 23.970, 1451.0, 38.0920
38.562999940, 23.970, 1438.0, 37.9210
38.606465700, 23.970, 1348.0, 36.7151
38.649931460, 23.970, 1280.0, 35.7771
38.693397220, 23.970, 1358.0, 36.8511
38.736862980, 23.970, 1382.0, 37.1753
38.780328740, 23.970, 1459.0, 38.1969
38.823794500, 23.970, 1448.0, 38.0526
38.867260260, 23.970, 1454.0, 38.1314
38.910726020, 23.970, 1532.0, 39.1408
38.954191780, 23.970, 1438.0, 37.9210
38.997657540, 23.970, 1397.0, 37.3765
39.041123300, 23.970, 1443.0, 37.9868
39.084589060, 23.970, 1427.0, 37.7757
39.128054820, 23.970, 1486.0, 38.5487
39.171520580, 23.970, 1496.0, 38.6782
39.214986340, 23.970, 1568.0, 39.5980
39.258452100, 23.970, 1747.0, 41.7971
39.301917860, 23.970, 1785.0, 42.2493
39.345383620, 23.970, 1825.0, 42.7200
39.388849380, 23.970, 1889.0, 43.4626
39.432315140, 23.970, 2049.0, 45.2659
39.475780900, 23.970, 2168.0, 46.5618
39.519246660, 23.970, 2325.0, 48.2183
39.562712420, 23.970, 2407.0, 49.0612
39.606178180, 23.970, 2431.0, 49.3052
39.649643940, 23.970, 2401.0, 49.0000
39.693109700, 23.970, 2545.0, 50.4480
39.736575460, 23.970, 2564.0, 50.6360
39.780041220, 23.970, 2542.0, 50.4183
39.823506980, 23.970, 2382.0, 48.8057
39.866972740, 23.970, 2226.0, 47.1805
39.910438500, 23.970, 2294.0, 47.8957
39.953904260, 23.970, 2157.0, 46.4435
39.997370020, 23.970, 2003.0, 44.7549
40.040835780, 23.970, 2020.0, 44.9444
40.084301540, 23.970, 1894.0, 43.5201
40.127767300, 23.970, 1890.0, 43.4741
40.171233060, 23.970, 1807.0, 42.5088
40.214698820, 23.970, 1849.0, 43.0000
40.258164580, 23.970, 1814.0, 42.5911
40.301630340, 23.970, 1833.0, 42.8135
40.345096100, 23.970, 1864.0, 43.1741
40.388561860, 23.970, 1967.0, 44.3509
40.432027620, 23.970, 1934.0, 43.9773
40.475493380, 23.970, 2048.0, 45.2548
40.518959140, 23.970, 2168.0, 46.5618
40.562424900, 23.970, 2202.0, 46.9255
40.605890660, 23.970, 2262.0, 47.5605
40.649356420, 23.970, 2370.0, 48.6826
40.692822180, 23.970, 2427.0, 49.2646
40.736287940, 23.970, 2564.0, 50.6360
40.779753700, 23.970, 2483.0, 49.8297
40.823219460, 23.970, 2469.0, 49.6890
40.866685220, 23.970, 2407.0, 49.0612
40.910150980, 23.970, 2171.0, 46.5940
40.953616740, 23.970, 2166.0, 46.5403
40.997082500, 23.970, 2163.0, 46.5081
41.040548260, 23.970, 1924.0, 43.8634
41.084014020, 23.970, 1885.0, 43.4166
41.127479780, 23.970, 1828.0, 42.7551
41.170945540, 23.970, 1808.0, 42.5206
41.214411300, 23.970, 1869.0, 43.2319
41.257877060, 23.970, 1852.0, 43.0349
41.301342820, 23.970, 1870.0, 43.2435
41.344808580, 23.970, 1925.0, 43.8748
41.388274340, 23.970, 1994.0, 44.6542
41.431740100, 23.970, 1958.0, 44.2493
41.475205860, 23.970, 1959.0, 44.2606
41.518671620, 23.970, 2051.0, 45.2880
41.562137380, 23.970, 2088.0, 45.6946
41.605603140, 23.970, 2040.0, 45.1664
41.649068900, 23.970, 2052.0, 45.2990
41.692534660, 23.970, 1994.0, 44.6542
41.736000420, 23.970, 1961.0, 44.2832
41.779466180, 23.970, 1916.0, 43.7721
41.822931940, 23.970, 1841.0, 42.9069
41.866397700, 23.970, 1797.0, 42.3910
41.909863460, 23.970, 1693.0, 41.1461
41.953329220, 23.970, 1627.0, 40.3361
41.996794980, 23.970, 1574.0, 39.6737
42.040260740, 23.970, 1542.0, 39.2683
42.083726500, 23.970, 1513.0, 38.8973
42.127192260, 23.970, 1446.0, 38.0263
42.170658020, 23.970, 1431.0, 37.8286
42.214123780, 23.970, 1437.0, 37.9078
42.257589540, 23.970, 1479.0, 38.4578
42.301055300, 23.970, 1488.0, 38.5746
42.344521060, 23.970, 1573.0, 39.6611
42.387986820, 23.970, 1572.0, 39.6485
42.431452580, 23.970, 1627.0, 40.3361
42.474918340, 23.970, 1729.0, 41.5812
42.518384100, 23.970, 1782.0, 42.2137
42.561849860, 23.970, 1963.0, 44.3058
42.605315620, 23.970, 1946.0, 44.1135
42.648781380, 23.970, 2043.0, 45.1996
42.692247140, 23.970, 1995.0, 44.6654
42.735712900, 23.970, 2034.0, 45.0999
42.779178660, 23.970, 2089.0, 45.7056
42.822644420, 23.970, 2035.0, 45.1110
42.866110180, 23.970, 2136.0, 46.2169
42.909575940, 23.970, 2115.0, 45.9891
42.953041700, 23.970, 2246.0, 47.3920
42.996507460, 23.970, 2185.0, 46.7440
43.039973220, 23.970, 2153.0, 46.4004
43.083438980, 23.970, 2052.0, 45.2990
43.126904740, 23.970, 2008.0, 44.8107
43.170370500, 23.970, 1880.0, 43.3590
43.213836260, 23.970, 1788.0, 42.2847
43.257302020, 23.970, 1649.0, 40.6079
43.300767780, 23.970, 1571.0, 39.6358
43.344233540, 23.970, 1635.0, 40.4351
43.387699300, 23.970, 1547.0, 39.3319
43.431165060, 23.970, 1610.0, 40.1248
43.474630820, 23.970, 1565.0, 39.5601
43.518096580, 23.970, 1578.0, 39.7240
43.561562340, 23.970, 1630.0, 40.3733
43.605028100, 23.970, 1692.0, 41.1339
43.648493860, 23.970, 1649.0, 40.6079
43.691959620, 23.970, 1715.0, 41.4126
43.735425380, 23.970, 1702.0, 41.2553
43.778891140, 23.970, 1709.0, 41.3401
43.822356900, 23.970, 1866.0, 43.1972
43.865822660, 23.970, 1874.0, 43.2897
43.909288420, 23.970, 1898.0, 43.5660
43.952754180, 23.970, 1900.0, 43.5890
43.996219940, 23.970, 1894.0, 43.5201
44.039685700, 23.970, 1863.0, 43.1625
44.083151460, 23.970, 1763.0, 41.9881
44.126617220, 23.970, 1665.0, 40.8044
44.170082980, 23.970, 1616.0, 40.1995
44.213548740, 23.970, 1530.0, 39.1152
44.257014500, 23.970, 1361.0, 36.8917
44.300480260, 23.970, 1352.0, 36.7696
44.343946020, 23.970, 1217.0, 34.8855
44.387411780, 23.970, 1219.0, 34.9142
44.430877540, 23.970, 1180.0, 34.3511
44.474343300, 23.970, 1132.0, 33.6452
44.517809060, 23.970, 1162.0, 34.0881
44.561274820, 23.970, 1164.0, 34.1174
44.604740580, 23.970, 1122.0, 33.4963
44.648206340, 23.970, 1129.0, 33.6006
44.691672100, 23.970, 1139.0, 33.7491
44.735137860, 23.970, 1113.0, 33.3617
44.778603620, 23.970, 1046.0, 32.3419
44.822069380, 23.970, 1093.0, 33.0606
44.865535140, 23.970, 1138.0, 33.7343
44.909000900, 23.970, 1053.0, 32.4500
44.952466660, 23.970, 1060.0, 32.5576
44.995932420, 23.970, 1044.0, 32.3110
45.039398180, 23.970, 1143.0, 33.8083
45.082863940, 23.970, 1040.0, 32.2490
45.126329700, 23.970, 1105.0, 33.2415
45.169795460, 23.970, 1049.0, 32.3883
45.213261220, 23.970, 1059.0, 32.5423
45.256726980, 23.970, 1090.0, 33.0151
45.300192740, 23.970, 1029.0, 32.0780
45.343658500, 23.970, 1017.0, 31.8904
45.387124260, 23.970, 960.0, 30.9839
45.430590020, 23.970, 1077.0, 32.8177
45.474055780, 23.970, 1113.0, 33.3617
45.517521540, 23.970, 1075.0, 32.7872
45.560987300, 23.970, 1084.0, 32.9242
45.604453060, 23.970, 1082.0, 32.8938
45.647918820, 23.970, 1075.0, 32.7872
45.691384580, 23.970, 1049.0, 32.3883
45.734850340, 23.970, 1057.0, 32.5115
45.778316100, 23.970, 1082.0, 32.8938
45.821781860, 23.970, 1024.0, 32.0000
45.865247620, 23.970, 1083.0, 32.9090
45.908713380, 23.970, 1066.0, 32.6497
45.952179140, 23.970, 1049.0, 32.3883
45.995644900, 23.970, 1017.0, 31.8904
46.039110660, 23.970, 1047.0, 32.3574
46.082576420, 23.970, 1066.0, 32.6497
46.126042180, 23.970, 1126.0, 33.5559
46.169507940, 23.970, 1131.0, 33.6303
46.212973700, 23.970, 1081.0, 32.8786
46.256439460, 23.970, 1170.0, 34.2053
46.299905220, 23.970, 1194.0, 34.5543
46.343370980, 23.970, 1148.0, 33.8821
46.386836740, 23.970, 1231.0, 35.0856
46.430302500, 23.970, 1281.0, 35.7911
46.473768260, 23.970, 1334.0, 36.5240
46.517234020, 23.970, 1495.0, 38.6652
46.560699780, 23.970, 1526.0, 39.0640
46.604165540, 23.970, 1496.0, 38.6782
46.647631300, 23.970, 1421.0, 37.6962
46.691097060, 23.970, 1478.0, 38.4448
46.734562820, 23.970, 1531.0, 39.1280
46.778028580, 23.970, 1595.0, 39.9375
46.821494340, 23.970, 1581.0, 39.7618
46.864960100, 23.970, 1753.0, 41.8688
46.908425860, 23.970, 1864.0, 43.1741
46.951891620, 23.970, 1854.0, 43.0581
46.995357380, 23.970, 1859.0, 43.1161
47.038823140, 23.970, 1784.0, 42.2374
47.082288900, 23.970, 1597.0, 39.9625
47.125754660, 23.970, 1512.0, 38.8844
47.169220420, 23.970, 1342.0, 36.6333
47.212686180, 23.970, 1305.0, 36.1248
47.256151940, 23.970, 1086.0, 32.9545
47.299617700, 23.970, 1119.0, 33.4515
47.343083460, 23.970, 1110.0, 33.3167
47.386549220, 23.970, 1094.0, 33.0757
47.430014980, 23.970, 1092.0, 33.0454
47.473480740, 23.970, 1061.0, 32.5730
47.516946500, 23.970, 1055.0, 32.4808
47.560412260, 23.970, 1005.0, 31.7017
47.603878020, 23.970, 1013.0, 31.8277
47.647343780, 23.970, 1020.0, 31.9374
47.690809540, 23.970, 1049.0, 32.3883
47.734275300, 23.970, 1050.0, 32.4037
47.777741060, 23.970, 1015.0, 31.8591
47.821206820, 23.970, 1087.0, 32.9697
47.864672580, 23.970, 1162.0, 34.0881
47.908138340, 23.970, 1252.0, 35.3836
47.951604100, 23.970, 1372.0, 37.0405
47.995069860, 23.970, 1303.0, 36.0971
48.038535620, 23.970, 1225.0, 35.0000
48.082001380, 23.970, 1131.0, 33.6303
48.125467140, 23.970, 1090.0, 33.0151
48.168932900, 23.970, 1035.0, 32.1714
48.212398660, 23.970, 1019.0, 31.9218
48.255864420, 23.970, 1011.0, 31.7962
48.299330180, 23.970, 1000.0, 31.6228
48.342795940, 23.970, 965.0, 31.0644
48.386261700, 23.970, 995.0, 31.5436
48.429727460, 23.970, 978.0, 31.2730
48.473193220, 23.970, 1001.0, 31.6386
48.516658980, 23.970, 1029.0, 32.0780
48.560124740, 23.970, 1074.0, 32.7719
48.603590500, 23.970, 1009.0, 31.7648
48.647056260, 23.970, 1031.0, 32.1092
48.690522020, 23.970, 1069.0, 32.6956
48.733987780, 23.970, 1073.0, 32.7567
48.777453540, 23.970, 1084.0, 32.9242
48.820919300, 23.970, 1049.0, 32.3883
48.864385060, 23.970, 1114.0, 33.3766
48.907850820, 23.970, 1076.0, 32.8024
48.951316580, 23.970, 1056.0, 32.4962
48.994782340, 23.970, 1109.0, 33.3017
49.038248100, 23.970, 1060.0, 32.5576
49.081713860, 23.970, 1120.0, 33.4664
49.125179620, 23.970, 1111.0, 33.3317
49.168645380, 23.970, 1063.0, 32.6037
49.212111140, 23.970, 1086.0, 32.9545
49.255576900, 23.970, 1020.0, 31.9374
49.299042660, 23.970, 1060.0, 32.5576
49.342508420, 23.970, 1020.0, 31.9374
49.385974180, 23.970, 1035.0, 32.1714
49.429439940, 23.970, 955.0, 30.9031
49.472905700, 23.970, 941.0, 30.6757
49.516371460, 23.970, 973.0, 31.1929
49.559837220, 23.970, 984.0, 31.3688
49.603302980, 23.970, 938.0, 30.6268
49.646768740, 23.970, 887.0, 29.7825
49.690234500, 23.970, 913.0, 30.2159
49.733700260, 23.970, 906.0, 30.0998
49.777166020, 23.970, 939.0, 30.6431
49.820631780, 23.970, 990.0, 31.4643
49.864097540, 23.970, 926.0, 30.4302
49.907563300, 23.970, 861.0, 29.3428
49.951029060, 23.970, 865.0, 29.4109
49.994494820, 23.970, 886.0, 29.7658