File: data/XRD/HDPE.csv
[Measurement conditions]
Sample identification,HDPE
Comment,
Anode material,Cu
K-Alpha1 wavelength,1.5405980
K-Alpha2 wavelength,1.5444260
Ratio K-Alpha2/K-Alpha1,0.500
Divergence slit,Fixed,0.38mm
Monochromator used,NO
Generator voltage, 40
Tube current, 15
File date and time,26/Feb/2025 10:57
Unit cell,
h k l, 0 0 0
Scan axis,Gonio
Scan range,5.002000000,49.999928040
Scan step size,0.0108664
No. of points, 4141
Scan type,CONTINUOUS
Time per step,23.970
[Scan points]
Angle, TimePerStep, Intensity, ESD
5.007433220, 23.970, 1413.0, 37.5899
5.050898980, 23.970, 1462.0, 38.2361
5.094364740, 23.970, 1577.0, 39.7115
5.137830500, 23.970, 1565.0, 39.5601
5.181296260, 23.970, 1573.0, 39.6611
5.224762020, 23.970, 1613.0, 40.1622
5.268227780, 23.970, 1571.0, 39.6358
5.311693540, 23.970, 1572.0, 39.6485
5.355159300, 23.970, 1622.0, 40.2741
5.398625060, 23.970, 1614.0, 40.1746
5.442090820, 23.970, 1650.0, 40.6202
5.485556580, 23.970, 1725.0, 41.5331
5.529022340, 23.970, 1772.0, 42.0951
5.572488100, 23.970, 1759.0, 41.9404
5.615953860, 23.970, 1757.0, 41.9166
5.659419620, 23.970, 1750.0, 41.8330
5.702885380, 23.970, 1831.0, 42.7902
5.746351140, 23.970, 1782.0, 42.2137
5.789816900, 23.970, 1890.0, 43.4741
5.833282660, 23.970, 1857.0, 43.0929
5.876748420, 23.970, 1908.0, 43.6807
5.920214180, 23.970, 1891.0, 43.4856
5.963679940, 23.970, 1930.0, 43.9318
6.007145700, 23.970, 1918.0, 43.7950
6.050611460, 23.970, 1856.0, 43.0813
6.094077220, 23.970, 1978.0, 44.4747
6.137542980, 23.970, 1983.0, 44.5309
6.181008740, 23.970, 1955.0, 44.2154
6.224474500, 23.970, 2012.0, 44.8553
6.267940260, 23.970, 2047.0, 45.2438
6.311406020, 23.970, 2046.0, 45.2327
6.354871780, 23.970, 2057.0, 45.3542
6.398337540, 23.970, 2085.0, 45.6618
6.441803300, 23.970, 2170.0, 46.5833
6.485269060, 23.970, 2091.0, 45.7275
6.528734820, 23.970, 2186.0, 46.7547
6.572200580, 23.970, 2160.0, 46.4758
6.615666340, 23.970, 2172.0, 46.6047
6.659132100, 23.970, 2229.0, 47.2123
6.702597860, 23.970, 2125.0, 46.0977
6.746063620, 23.970, 2155.0, 46.4220
6.789529380, 23.970, 2183.0, 46.7226
6.832995140, 23.970, 2198.0, 46.8828
6.876460900, 23.970, 2293.0, 47.8853
6.919926660, 23.970, 2232.0, 47.2440
6.963392420, 23.970, 2237.0, 47.2969
7.006858180, 23.970, 2267.0, 47.6130
7.050323940, 23.970, 2241.0, 47.3392
7.093789700, 23.970, 2260.0, 47.5395
7.137255460, 23.970, 2397.0, 48.9592
7.180721220, 23.970, 2393.0, 48.9183
7.224186980, 23.970, 2464.0, 49.6387
7.267652740, 23.970, 2403.0, 49.0204
7.311118500, 23.970, 2283.0, 47.7807
7.354584260, 23.970, 2395.0, 48.9387
7.398050020, 23.970, 2272.0, 47.6655
7.441515780, 23.970, 2466.0, 49.6588
7.484981540, 23.970, 2451.0, 49.5076
7.528447300, 23.970, 2425.0, 49.2443
7.571913060, 23.970, 2469.0, 49.6890
7.615378820, 23.970, 2470.0, 49.6991
7.658844580, 23.970, 2418.0, 49.1732
7.702310340, 23.970, 2464.0, 49.6387
7.745776100, 23.970, 2366.0, 48.6415
7.789241860, 23.970, 2547.0, 50.4678
7.832707620, 23.970, 2488.0, 49.8799
7.876173380, 23.970, 2478.0, 49.7795
7.919639140, 23.970, 2507.0, 50.0700
7.963104900, 23.970, 2475.0, 49.7494
8.006570660, 23.970, 2561.0, 50.6063
8.050036420, 23.970, 2460.0, 49.5984
8.093502180, 23.970, 2480.0, 49.7996
8.136967940, 23.970, 2518.0, 50.1797
8.180433700, 23.970, 2506.0, 50.0600
8.223899460, 23.970, 2563.0, 50.6261
8.267365220, 23.970, 2448.0, 49.4773
8.310830980, 23.970, 2500.0, 50.0000
8.354296740, 23.970, 2530.0, 50.2991
8.397762500, 23.970, 2584.0, 50.8331
8.441228260, 23.970, 2644.0, 51.4198
8.484694020, 23.970, 2591.0, 50.9019
8.528159780, 23.970, 2489.0, 49.8899
8.571625540, 23.970, 2543.0, 50.4282
8.615091300, 23.970, 2549.0, 50.4876
8.658557060, 23.970, 2512.0, 50.1199
8.702022820, 23.970, 2546.0, 50.4579
8.745488580, 23.970, 2597.0, 50.9608
8.788954340, 23.970, 2503.0, 50.0300
8.832420100, 23.970, 2546.0, 50.4579
8.875885860, 23.970, 2557.0, 50.5668
8.919351620, 23.970, 2687.0, 51.8363
8.962817380, 23.970, 2572.0, 50.7149
9.006283140, 23.970, 2510.0, 50.0999
9.049748900, 23.970, 2559.0, 50.5866
9.093214660, 23.970, 2564.0, 50.6360
9.136680420, 23.970, 2551.0, 50.5074
9.180146180, 23.970, 2509.0, 50.0899
9.223611940, 23.970, 2584.0, 50.8331
9.267077700, 23.970, 2593.0, 50.9215
9.310543460, 23.970, 2572.0, 50.7149
9.354009220, 23.970, 2536.0, 50.3587
9.397474980, 23.970, 2541.0, 50.4083
9.440940740, 23.970, 2582.0, 50.8134
9.484406500, 23.970, 2566.0, 50.6557
9.527872260, 23.970, 2583.0, 50.8232
9.571338020, 23.970, 2469.0, 49.6890
9.614803780, 23.970, 2427.0, 49.2646
9.658269540, 23.970, 2503.0, 50.0300
9.701735300, 23.970, 2566.0, 50.6557
9.745201060, 23.970, 2542.0, 50.4183
9.788666820, 23.970, 2572.0, 50.7149
9.832132580, 23.970, 2507.0, 50.0700
9.875598340, 23.970, 2451.0, 49.5076
9.919064100, 23.970, 2486.0, 49.8598
9.962529860, 23.970, 2498.0, 49.9800
10.005995620, 23.970, 2538.0, 50.3786
10.049461380, 23.970, 2459.0, 49.5883
10.092927140, 23.970, 2409.0, 49.0816
10.136392900, 23.970, 2374.0, 48.7237
10.179858660, 23.970, 2342.0, 48.3942
10.223324420, 23.970, 2352.0, 48.4974
10.266790180, 23.970, 2396.0, 48.9490
10.310255940, 23.970, 2333.0, 48.3011
10.353721700, 23.970, 2445.0, 49.4469
10.397187460, 23.970, 2333.0, 48.3011
10.440653220, 23.970, 2342.0, 48.3942
10.484118980, 23.970, 2429.0, 49.2849
10.527584740, 23.970, 2347.0, 48.4458
10.571050500, 23.970, 2301.0, 47.9687
10.614516260, 23.970, 2323.0, 48.1975
10.657982020, 23.970, 2295.0, 47.9062
10.701447780, 23.970, 2374.0, 48.7237
10.744913540, 23.970, 2261.0, 47.5500
10.788379300, 23.970, 2299.0, 47.9479
10.831845060, 23.970, 2306.0, 48.0208
10.875310820, 23.970, 2284.0, 47.7912
10.918776580, 23.970, 2189.0, 46.7868
10.962242340, 23.970, 2226.0, 47.1805
11.005708100, 23.970, 2279.0, 47.7389
11.049173860, 23.970, 2222.0, 47.1381
11.092639620, 23.970, 2276.0, 47.7074
11.136105380, 23.970, 2239.0, 47.3181
11.179571140, 23.970, 2247.0, 47.4025
11.223036900, 23.970, 2258.0, 47.5184
11.266502660, 23.970, 2158.0, 46.4543
11.309968420, 23.970, 2159.0, 46.4650
11.353434180, 23.970, 2179.0, 46.6798
11.396899940, 23.970, 2183.0, 46.7226
11.440365700, 23.970, 2087.0, 45.6837
11.483831460, 23.970, 2229.0, 47.2123
11.527297220, 23.970, 2126.0, 46.1086
11.570762980, 23.970, 2097.0, 45.7930
11.614228740, 23.970, 2273.0, 47.6760
11.657694500, 23.970, 2064.0, 45.4313
11.701160260, 23.970, 2112.0, 45.9565
11.744626020, 23.970, 2189.0, 46.7868
11.788091780, 23.970, 2099.0, 45.8148
11.831557540, 23.970, 2181.0, 46.7012
11.875023300, 23.970, 2118.0, 46.0217
11.918489060, 23.970, 2138.0, 46.2385
11.961954820, 23.970, 2107.0, 45.9021
12.005420580, 23.970, 2094.0, 45.7602
12.048886340, 23.970, 2060.0, 45.3872
12.092352100, 23.970, 2011.0, 44.8442
12.135817860, 23.970, 2109.0, 45.9239
12.179283620, 23.970, 2106.0, 45.8912
12.222749380, 23.970, 2081.0, 45.6180
12.266215140, 23.970, 2059.0, 45.3762
12.309680900, 23.970, 1974.0, 44.4297
12.353146660, 23.970, 2019.0, 44.9333
12.396612420, 23.970, 1994.0, 44.6542
12.440078180, 23.970, 1939.0, 44.0341
12.483543940, 23.970, 1998.0, 44.6990
12.527009700, 23.970, 1975.0, 44.4410
12.570475460, 23.970, 1971.0, 44.3959
12.613941220, 23.970, 2041.0, 45.1774
12.657406980, 23.970, 1982.0, 44.5197
12.700872740, 23.970, 1976.0, 44.4522
12.744338500, 23.970, 1985.0, 44.5533
12.787804260, 23.970, 1968.0, 44.3621
12.831270020, 23.970, 1936.0, 44.0000
12.874735780, 23.970, 2002.0, 44.7437
12.918201540, 23.970, 1937.0, 44.0114
12.961667300, 23.970, 1981.0, 44.5084
13.005133060, 23.970, 1916.0, 43.7721
13.048598820, 23.970, 1955.0, 44.2154
13.092064580, 23.970, 1967.0, 44.3509
13.135530340, 23.970, 1974.0, 44.4297
13.178996100, 23.970, 1937.0, 44.0114
13.222461860, 23.970, 1959.0, 44.2606
13.265927620, 23.970, 2018.0, 44.9222
13.309393380, 23.970, 1972.0, 44.4072
13.352859140, 23.970, 1979.0, 44.4860
13.396324900, 23.970, 1922.0, 43.8406
13.439790660, 23.970, 1994.0, 44.6542
13.483256420, 23.970, 1972.0, 44.4072
13.526722180, 23.970, 1973.0, 44.4185
13.570187940, 23.970, 1902.0, 43.6119
13.613653700, 23.970, 1951.0, 44.1701
13.657119460, 23.970, 1952.0, 44.1814
13.700585220, 23.970, 1912.0, 43.7264
13.744050980, 23.970, 1957.0, 44.2380
13.787516740, 23.970, 1977.0, 44.4635
13.830982500, 23.970, 2014.0, 44.8776
13.874448260, 23.970, 1901.0, 43.6005
13.917914020, 23.970, 2011.0, 44.8442
13.961379780, 23.970, 2038.0, 45.1442
14.004845540, 23.970, 1938.0, 44.0227
14.048311300, 23.970, 1898.0, 43.5660
14.091777060, 23.970, 1988.0, 44.5870
14.135242820, 23.970, 1973.0, 44.4185
14.178708580, 23.970, 1960.0, 44.2719
14.222174340, 23.970, 1949.0, 44.1475
14.265640100, 23.970, 1873.0, 43.2782
14.309105860, 23.970, 1968.0, 44.3621
14.352571620, 23.970, 2038.0, 45.1442
14.396037380, 23.970, 2035.0, 45.1110
14.439503140, 23.970, 1994.0, 44.6542
14.482968900, 23.970, 2018.0, 44.9222
14.526434660, 23.970, 1997.0, 44.6878
14.569900420, 23.970, 2034.0, 45.0999
14.613366180, 23.970, 1953.0, 44.1928
14.656831940, 23.970, 2074.0, 45.5412
14.700297700, 23.970, 2125.0, 46.0977
14.743763460, 23.970, 2077.0, 45.5741
14.787229220, 23.970, 2126.0, 46.1086
14.830694980, 23.970, 1945.0, 44.1022
14.874160740, 23.970, 2105.0, 45.8803
14.917626500, 23.970, 2062.0, 45.4093
14.961092260, 23.970, 2024.0, 44.9889
15.004558020, 23.970, 2073.0, 45.5302
15.048023780, 23.970, 2193.0, 46.8295
15.091489540, 23.970, 2121.0, 46.0543
15.134955300, 23.970, 2199.0, 46.8935
15.178421060, 23.970, 2137.0, 46.2277
15.221886820, 23.970, 2089.0, 45.7056
15.265352580, 23.970, 2226.0, 47.1805
15.308818340, 23.970, 2171.0, 46.5940
15.352284100, 23.970, 2147.0, 46.3357
15.395749860, 23.970, 2197.0, 46.8722
15.439215620, 23.970, 2174.0, 46.6262
15.482681380, 23.970, 2173.0, 46.6154
15.526147140, 23.970, 2287.0, 47.8226
15.569612900, 23.970, 2177.0, 46.6583
15.613078660, 23.970, 2269.0, 47.6340
15.656544420, 23.970, 2306.0, 48.0208
15.700010180, 23.970, 2282.0, 47.7703
15.743475940, 23.970, 2329.0, 48.2597
15.786941700, 23.970, 2322.0, 48.1871
15.830407460, 23.970, 2339.0, 48.3632
15.873873220, 23.970, 2376.0, 48.7442
15.917338980, 23.970, 2401.0, 49.0000
15.960804740, 23.970, 2299.0, 47.9479
16.004270500, 23.970, 2371.0, 48.6929
16.047736260, 23.970, 2378.0, 48.7647
16.091202020, 23.970, 2358.0, 48.5592
16.134667780, 23.970, 2401.0, 49.0000
16.178133540, 23.970, 2528.0, 50.2792
16.221599300, 23.970, 2504.0, 50.0400
16.265065060, 23.970, 2526.0, 50.2593
16.308530820, 23.970, 2575.0, 50.7445
16.351996580, 23.970, 2571.0, 50.7050
16.395462340, 23.970, 2566.0, 50.6557
16.438928100, 23.970, 2559.0, 50.5866
16.482393860, 23.970, 2620.0, 51.1859
16.525859620, 23.970, 2648.0, 51.4587
16.569325380, 23.970, 2709.0, 52.0481
16.612791140, 23.970, 2684.0, 51.8073
16.656256900, 23.970, 2846.0, 53.3479
16.699722660, 23.970, 2629.0, 51.2738
16.743188420, 23.970, 2830.0, 53.1977
16.786654180, 23.970, 2744.0, 52.3832
16.830119940, 23.970, 2733.0, 52.2781
16.873585700, 23.970, 2836.0, 53.2541
16.917051460, 23.970, 2869.0, 53.5630
16.960517220, 23.970, 2968.0, 54.4794
17.003982980, 23.970, 3049.0, 55.2178
17.047448740, 23.970, 3104.0, 55.7136
17.090914500, 23.970, 3069.0, 55.3986
17.134380260, 23.970, 3156.0, 56.1783
17.177846020, 23.970, 3152.0, 56.1427
17.221311780, 23.970, 3059.0, 55.3082
17.264777540, 23.970, 3203.0, 56.5951
17.308243300, 23.970, 3241.0, 56.9298
17.351709060, 23.970, 3168.0, 56.2850
17.395174820, 23.970, 3382.0, 58.1550
17.438640580, 23.970, 3313.0, 57.5587
17.482106340, 23.970, 3388.0, 58.2065
17.525572100, 23.970, 3415.0, 58.4380
17.569037860, 23.970, 3556.0, 59.6322
17.612503620, 23.970, 3443.0, 58.6771
17.655969380, 23.970, 3581.0, 59.8415
17.699435140, 23.970, 3625.0, 60.2080
17.742900900, 23.970, 3691.0, 60.7536
17.786366660, 23.970, 3576.0, 59.7997
17.829832420, 23.970, 3651.0, 60.4235
17.873298180, 23.970, 3732.0, 61.0901
17.916763940, 23.970, 3874.0, 62.2415
17.960229700, 23.970, 3846.0, 62.0161
18.003695460, 23.970, 3872.0, 62.2254
18.047161220, 23.970, 4007.0, 63.3009
18.090626980, 23.970, 4051.0, 63.6475
18.134092740, 23.970, 4109.0, 64.1015
18.177558500, 23.970, 4079.0, 63.8670
18.221024260, 23.970, 4254.0, 65.2227
18.264490020, 23.970, 4268.0, 65.3299
18.307955780, 23.970, 4197.0, 64.7843
18.351421540, 23.970, 4375.0, 66.1438
18.394887300, 23.970, 4495.0, 67.0448
18.438353060, 23.970, 4491.0, 67.0149
18.481818820, 23.970, 4353.0, 65.9773
18.525284580, 23.970, 4516.0, 67.2012
18.568750340, 23.970, 4689.0, 68.4763
18.612216100, 23.970, 4660.0, 68.2642
18.655681860, 23.970, 4783.0, 69.1592
18.699147620, 23.970, 4718.0, 68.6877
18.742613380, 23.970, 4797.0, 69.2604
18.786079140, 23.970, 4963.0, 70.4486
18.829544900, 23.970, 5011.0, 70.7884
18.873010660, 23.970, 4934.0, 70.2424
18.916476420, 23.970, 5189.0, 72.0347
18.959942180, 23.970, 5077.0, 71.2531
19.003407940, 23.970, 5192.0, 72.0555
19.046873700, 23.970, 5354.0, 73.1710
19.090339460, 23.970, 5208.0, 72.1665
19.133805220, 23.970, 5275.0, 72.6292
19.177270980, 23.970, 5448.0, 73.8106
19.220736740, 23.970, 5447.0, 73.8038
19.264202500, 23.970, 5527.0, 74.3438
19.307668260, 23.970, 5427.0, 73.6682
19.351134020, 23.970, 5698.0, 75.4851
19.394599780, 23.970, 5718.0, 75.6175
19.438065540, 23.970, 5735.0, 75.7298
19.481531300, 23.970, 5839.0, 76.4133
19.524997060, 23.970, 5940.0, 77.0714
19.568462820, 23.970, 5957.0, 77.1816
19.611928580, 23.970, 5928.0, 76.9935
19.655394340, 23.970, 5865.0, 76.5833
19.698860100, 23.970, 5893.0, 76.7659
19.742325860, 23.970, 5923.0, 76.9610
19.785791620, 23.970, 5825.0, 76.3217
19.829257380, 23.970, 5884.0, 76.7072
19.872723140, 23.970, 5903.0, 76.8310
19.916188900, 23.970, 6009.0, 77.5177
19.959654660, 23.970, 6130.0, 78.2943
20.003120420, 23.970, 5897.0, 76.7919
20.046586180, 23.970, 6168.0, 78.5366
20.090051940, 23.970, 6126.0, 78.2688
20.133517700, 23.970, 6110.0, 78.1665
20.176983460, 23.970, 6227.0, 78.9113
20.220449220, 23.970, 6277.0, 79.2275
20.263914980, 23.970, 6326.0, 79.5362
20.307380740, 23.970, 6234.0, 78.9557
20.350846500, 23.970, 6267.0, 79.1644
20.394312260, 23.970, 6359.0, 79.7433
20.437778020, 23.970, 6485.0, 80.5295
20.481243780, 23.970, 6704.0, 81.8780
20.524709540, 23.970, 6771.0, 82.2861
20.568175300, 23.970, 6890.0, 83.0060
20.611641060, 23.970, 7164.0, 84.6404
20.655106820, 23.970, 7329.0, 85.6096
20.698572580, 23.970, 7499.0, 86.5968
20.742038340, 23.970, 7929.0, 89.0449
20.785504100, 23.970, 8398.0, 91.6406
20.828969860, 23.970, 8964.0, 94.6784
20.872435620, 23.970, 9619.0, 98.0765
20.915901380, 23.970, 10566.0, 102.7911
20.959367140, 23.970, 11752.0, 108.4066
21.002832900, 23.970, 12910.0, 113.6222
21.046298660, 23.970, 15006.0, 122.4990
21.089764420, 23.970, 16865.0, 129.8653
21.133230180, 23.970, 19585.0, 139.9464
21.176695940, 23.970, 22457.0, 149.8566
21.220161700, 23.970, 24890.0, 157.7656
21.263627460, 23.970, 27583.0, 166.0813
21.307093220, 23.970, 30822.0, 175.5620
21.350558980, 23.970, 34825.0, 186.6146
21.394024740, 23.970, 39396.0, 198.4843
21.437490500, 23.970, 44768.0, 211.5845
21.480956260, 23.970, 50474.0, 224.6642
21.524422020, 23.970, 56634.0, 237.9790
21.567887780, 23.970, 62847.0, 250.6930
21.611353540, 23.970, 68718.0, 262.1412
21.654819300, 23.970, 73030.0, 270.2406
21.698285060, 23.970, 73950.0, 271.9375
21.741750820, 23.970, 70157.0, 264.8717
21.785216580, 23.970, 61877.0, 248.7509
21.828682340, 23.970, 50980.0, 225.7875
21.872148100, 23.970, 38472.0, 196.1428
21.915613860, 23.970, 27936.0, 167.1407
21.959079620, 23.970, 19766.0, 140.5916
22.002545380, 23.970, 14715.0, 121.3054
22.046011140, 23.970, 11380.0, 106.6771
22.089476900, 23.970, 9395.0, 96.9278
22.132942660, 23.970, 8211.0, 90.6146
22.176408420, 23.970, 7291.0, 85.3874
22.219874180, 23.970, 6696.0, 81.8291
22.263339940, 23.970, 6013.0, 77.5435
22.306805700, 23.970, 5700.0, 75.4983
22.350271460, 23.970, 5562.0, 74.5788
22.393737220, 23.970, 5213.0, 72.2011
22.437202980, 23.970, 5201.0, 72.1180
22.480668740, 23.970, 4997.0, 70.6895
22.524134500, 23.970, 4836.0, 69.5414
22.567600260, 23.970, 4788.0, 69.1954
22.611066020, 23.970, 4690.0, 68.4836
22.654531780, 23.970, 4469.0, 66.8506
22.697997540, 23.970, 4637.0, 68.0955
22.741463300, 23.970, 4466.0, 66.8281
22.784929060, 23.970, 4357.0, 66.0076
22.828394820, 23.970, 4250.0, 65.1920
22.871860580, 23.970, 4447.0, 66.6858
22.915326340, 23.970, 4215.0, 64.9230
22.958792100, 23.970, 4332.0, 65.8179
23.002257860, 23.970, 4230.0, 65.0385
23.045723620, 23.970, 4451.0, 66.7158
23.089189380, 23.970, 4435.0, 66.5958
23.132655140, 23.970, 4393.0, 66.2797
23.176120900, 23.970, 4472.0, 66.8730
23.219586660, 23.970, 4780.0, 69.1375
23.263052420, 23.970, 4984.0, 70.5975
23.306518180, 23.970, 5126.0, 71.5961
23.349983940, 23.970, 5333.0, 73.0274
23.393449700, 23.970, 5668.0, 75.2861
23.436915460, 23.970, 6098.0, 78.0897
23.480381220, 23.970, 6487.0, 80.5419
23.523846980, 23.970, 6900.0, 83.0662
23.567312740, 23.970, 7346.0, 85.7088
23.610778500, 23.970, 7874.0, 88.7356
23.654244260, 23.970, 8463.0, 91.9946
23.697710020, 23.970, 9131.0, 95.5563
23.741175780, 23.970, 9811.0, 99.0505
23.784641540, 23.970, 10474.0, 102.3426
23.828107300, 23.970, 11143.0, 105.5604
23.871573060, 23.970, 12192.0, 110.4174
23.915038820, 23.970, 12818.0, 113.2166
23.958504580, 23.970, 13064.0, 114.2979
24.001970340, 23.970, 13156.0, 114.6996
24.045436100, 23.970, 13208.0, 114.9261
24.088901860, 23.970, 12475.0, 111.6915
24.132367620, 23.970, 11441.0, 106.9626
24.175833380, 23.970, 10247.0, 101.2275
24.219299140, 23.970, 8852.0, 94.0851
24.262764900, 23.970, 7555.0, 86.9195
24.306230660, 23.970, 6352.0, 79.6994
24.349696420, 23.970, 5492.0, 74.1080
24.393162180, 23.970, 4583.0, 67.6979
24.436627940, 23.970, 3988.0, 63.1506
24.480093700, 23.970, 3742.0, 61.1719
24.523559460, 23.970, 3374.0, 58.0861
24.567025220, 23.970, 3089.0, 55.5788
24.610490980, 23.970, 2962.0, 54.4243
24.653956740, 23.970, 2815.0, 53.0566
24.697422500, 23.970, 2700.0, 51.9615
24.740888260, 23.970, 2615.0, 51.1371
24.784354020, 23.970, 2587.0, 50.8626
24.827819780, 23.970, 2487.0, 49.8698
24.871285540, 23.970, 2534.0, 50.3389
24.914751300, 23.970, 2405.0, 49.0408
24.958217060, 23.970, 2277.0, 47.7179
25.001682820, 23.970, 2288.0, 47.8330
25.045148580, 23.970, 2302.0, 47.9792
25.088614340, 23.970, 2149.0, 46.3573
25.132080100, 23.970, 2209.0, 47.0000
25.175545860, 23.970, 2133.0, 46.1844
25.219011620, 23.970, 2186.0, 46.7547
25.262477380, 23.970, 2224.0, 47.1593
25.305943140, 23.970, 2124.0, 46.0869
25.349408900, 23.970, 2084.0, 45.6508
25.392874660, 23.970, 1967.0, 44.3509
25.436340420, 23.970, 2002.0, 44.7437
25.479806180, 23.970, 1968.0, 44.3621
25.523271940, 23.970, 2023.0, 44.9778
25.566737700, 23.970, 1988.0, 44.5870
25.610203460, 23.970, 1907.0, 43.6692
25.653669220, 23.970, 1967.0, 44.3509
25.697134980, 23.970, 1912.0, 43.7264
25.740600740, 23.970, 1907.0, 43.6692
25.784066500, 23.970, 1875.0, 43.3013
25.827532260, 23.970, 1795.0, 42.3674
25.870998020, 23.970, 1907.0, 43.6692
25.914463780, 23.970, 1826.0, 42.7317
25.957929540, 23.970, 1812.0, 42.5676
26.001395300, 23.970, 1746.0, 41.7852
26.044861060, 23.970, 1725.0, 41.5331
26.088326820, 23.970, 1784.0, 42.2374
26.131792580, 23.970, 1817.0, 42.6263
26.175258340, 23.970, 1742.0, 41.7373
26.218724100, 23.970, 1704.0, 41.2795
26.262189860, 23.970, 1696.0, 41.1825
26.305655620, 23.970, 1647.0, 40.5832
26.349121380, 23.970, 1751.0, 41.8450
26.392587140, 23.970, 1680.0, 40.9878
26.436052900, 23.970, 1656.0, 40.6940
26.479518660, 23.970, 1594.0, 39.9249
26.522984420, 23.970, 1655.0, 40.6817
26.566450180, 23.970, 1641.0, 40.5093
26.609915940, 23.970, 1596.0, 39.9500
26.653381700, 23.970, 1685.0, 41.0488
26.696847460, 23.970, 1671.0, 40.8779
26.740313220, 23.970, 1551.0, 39.3827
26.783778980, 23.970, 1591.0, 39.8873
26.827244740, 23.970, 1570.0, 39.6232
26.870710500, 23.970, 1544.0, 39.2938
26.914176260, 23.970, 1569.0, 39.6106
26.957642020, 23.970, 1503.0, 38.7685
27.001107780, 23.970, 1591.0, 39.8873
27.044573540, 23.970, 1514.0, 38.9102
27.088039300, 23.970, 1502.0, 38.7556
27.131505060, 23.970, 1521.0, 39.0000
27.174970820, 23.970, 1521.0, 39.0000
27.218436580, 23.970, 1518.0, 38.9615
27.261902340, 23.970, 1488.0, 38.5746
27.305368100, 23.970, 1461.0, 38.2230
27.348833860, 23.970, 1467.0, 38.3014
27.392299620, 23.970, 1480.0, 38.4708
27.435765380, 23.970, 1453.0, 38.1182
27.479231140, 23.970, 1378.0, 37.1214
27.522696900, 23.970, 1365.0, 36.9459
27.566162660, 23.970, 1366.0, 36.9594
27.609628420, 23.970, 1407.0, 37.5100
27.653094180, 23.970, 1493.0, 38.6394
27.696559940, 23.970, 1358.0, 36.8511
27.740025700, 23.970, 1368.0, 36.9865
27.783491460, 23.970, 1340.0, 36.6060
27.826957220, 23.970, 1328.0, 36.4417
27.870422980, 23.970, 1354.0, 36.7967
27.913888740, 23.970, 1359.0, 36.8646
27.957354500, 23.970, 1393.0, 37.3229
28.000820260, 23.970, 1372.0, 37.0405
28.044286020, 23.970, 1370.0, 37.0135
28.087751780, 23.970, 1338.0, 36.5787
28.131217540, 23.970, 1346.0, 36.6879
28.174683300, 23.970, 1340.0, 36.6060
28.218149060, 23.970, 1275.0, 35.7071
28.261614820, 23.970, 1273.0, 35.6791
28.305080580, 23.970, 1319.0, 36.3180
28.348546340, 23.970, 1228.0, 35.0428
28.392012100, 23.970, 1329.0, 36.4555
28.435477860, 23.970, 1258.0, 35.4683
28.478943620, 23.970, 1280.0, 35.7771
28.522409380, 23.970, 1344.0, 36.6606
28.565875140, 23.970, 1360.0, 36.8782
28.609340900, 23.970, 1346.0, 36.6879
28.652806660, 23.970, 1314.0, 36.2491
28.696272420, 23.970, 1302.0, 36.0832
28.739738180, 23.970, 1365.0, 36.9459
28.783203940, 23.970, 1346.0, 36.6879
28.826669700, 23.970, 1553.0, 39.4081
28.870135460, 23.970, 1648.0, 40.5956
28.913601220, 23.970, 1724.0, 41.5211
28.957066980, 23.970, 1597.0, 39.9625
29.000532740, 23.970, 1447.0, 38.0395
29.043998500, 23.970, 1374.0, 37.0675
29.087464260, 23.970, 1251.0, 35.3695
29.130930020, 23.970, 1325.0, 36.4005
29.174395780, 23.970, 1257.0, 35.4542
29.217861540, 23.970, 1317.0, 36.2905
29.261327300, 23.970, 1178.0, 34.3220
29.304793060, 23.970, 1225.0, 35.0000
29.348258820, 23.970, 1255.0, 35.4260
29.391724580, 23.970, 1260.0, 35.4965
29.435190340, 23.970, 1302.0, 36.0832
29.478656100, 23.970, 1363.0, 36.9188
29.522121860, 23.970, 1375.0, 37.0810
29.565587620, 23.970, 1402.0, 37.4433
29.609053380, 23.970, 1389.0, 37.2693
29.652519140, 23.970, 1420.0, 37.6829
29.695984900, 23.970, 1563.0, 39.5348
29.739450660, 23.970, 1567.0, 39.5854
29.782916420, 23.970, 1574.0, 39.6737
29.826382180, 23.970, 1627.0, 40.3361
29.869847940, 23.970, 1606.0, 40.0749
29.913313700, 23.970, 1642.0, 40.5216
29.956779460, 23.970, 1671.0, 40.8779
30.000245220, 23.970, 1803.0, 42.4617
30.043710980, 23.970, 1785.0, 42.2493
30.087176740, 23.970, 1780.0, 42.1900
30.130642500, 23.970, 1808.0, 42.5206
30.174108260, 23.970, 1806.0, 42.4971
30.217574020, 23.970, 1739.0, 41.7013
30.261039780, 23.970, 1750.0, 41.8330
30.304505540, 23.970, 1683.0, 41.0244
30.347971300, 23.970, 1540.0, 39.2428
30.391437060, 23.970, 1504.0, 38.7814
30.434902820, 23.970, 1374.0, 37.0675
30.478368580, 23.970, 1256.0, 35.4401
30.521834340, 23.970, 1231.0, 35.0856
30.565300100, 23.970, 1210.0, 34.7851
30.608765860, 23.970, 1196.0, 34.5832
30.652231620, 23.970, 1251.0, 35.3695
30.695697380, 23.970, 1168.0, 34.1760
30.739163140, 23.970, 1107.0, 33.2716
30.782628900, 23.970, 1182.0, 34.3802
30.826094660, 23.970, 1142.0, 33.7935
30.869560420, 23.970, 1156.0, 34.0000
30.913026180, 23.970, 1113.0, 33.3617
30.956491940, 23.970, 1136.0, 33.7046
30.999957700, 23.970, 1174.0, 34.2637
31.043423460, 23.970, 1092.0, 33.0454
31.086889220, 23.970, 1087.0, 32.9697
31.130354980, 23.970, 1117.0, 33.4215
31.173820740, 23.970, 1039.0, 32.2335
31.217286500, 23.970, 1074.0, 32.7719
31.260752260, 23.970, 1120.0, 33.4664
31.304218020, 23.970, 1087.0, 32.9697
31.347683780, 23.970, 1062.0, 32.5883
31.391149540, 23.970, 1025.0, 32.0156
31.434615300, 23.970, 1117.0, 33.4215
31.478081060, 23.970, 1080.0, 32.8634
31.521546820, 23.970, 1135.0, 33.6898
31.565012580, 23.970, 1026.0, 32.0312
31.608478340, 23.970, 1038.0, 32.2180
31.651944100, 23.970, 1061.0, 32.5730
31.695409860, 23.970, 1058.0, 32.5269
31.738875620, 23.970, 1058.0, 32.5269
31.782341380, 23.970, 1092.0, 33.0454
31.825807140, 23.970, 1023.0, 31.9844
31.869272900, 23.970, 1015.0, 31.8591
31.912738660, 23.970, 1085.0, 32.9393
31.956204420, 23.970, 1034.0, 32.1559
31.999670180, 23.970, 1047.0, 32.3574
32.043135940, 23.970, 1068.0, 32.6803
32.086601700, 23.970, 1075.0, 32.7872
32.130067460, 23.970, 1097.0, 33.1210
32.173533220, 23.970, 1080.0, 32.8634
32.216998980, 23.970, 1051.0, 32.4191
32.260464740, 23.970, 1040.0, 32.2490
32.303930500, 23.970, 1043.0, 32.2955
32.347396260, 23.970, 1042.0, 32.2800
32.390862020, 23.970, 1076.0, 32.8024
32.434327780, 23.970, 1054.0, 32.4654
32.477793540, 23.970, 1093.0, 33.0606
32.521259300, 23.970, 1024.0, 32.0000
32.564725060, 23.970, 1031.0, 32.1092
32.608190820, 23.970, 1058.0, 32.5269
32.651656580, 23.970, 1104.0, 33.2265
32.695122340, 23.970, 1060.0, 32.5576
32.738588100, 23.970, 1050.0, 32.4037
32.782053860, 23.970, 1061.0, 32.5730
32.825519620, 23.970, 1108.0, 33.2866
32.868985380, 23.970, 1045.0, 32.3265
32.912451140, 23.970, 1063.0, 32.6037
32.955916900, 23.970, 1046.0, 32.3419
32.999382660, 23.970, 1060.0, 32.5576
33.042848420, 23.970, 1040.0, 32.2490
33.086314180, 23.970, 1048.0, 32.3728
33.129779940, 23.970, 1038.0, 32.2180
33.173245700, 23.970, 1032.0, 32.1248
33.216711460, 23.970, 1095.0, 33.0908
33.260177220, 23.970, 1071.0, 32.7261
33.303642980, 23.970, 973.0, 31.1929
33.347108740, 23.970, 1039.0, 32.2335
33.390574500, 23.970, 1032.0, 32.1248
33.434040260, 23.970, 1018.0, 31.9061
33.477506020, 23.970, 1059.0, 32.5423
33.520971780, 23.970, 996.0, 31.5595
33.564437540, 23.970, 1081.0, 32.8786
33.607903300, 23.970, 1058.0, 32.5269
33.651369060, 23.970, 1063.0, 32.6037
33.694834820, 23.970, 998.0, 31.5911
33.738300580, 23.970, 1026.0, 32.0312
33.781766340, 23.970, 977.0, 31.2570
33.825232100, 23.970, 1017.0, 31.8904
33.868697860, 23.970, 1019.0, 31.9218
33.912163620, 23.970, 1096.0, 33.1059
33.955629380, 23.970, 1058.0, 32.5269
33.999095140, 23.970, 1065.0, 32.6343
34.042560900, 23.970, 1074.0, 32.7719
34.086026660, 23.970, 1115.0, 33.3916
34.129492420, 23.970, 1092.0, 33.0454
34.172958180, 23.970, 1034.0, 32.1559
34.216423940, 23.970, 1072.0, 32.7414
34.259889700, 23.970, 1105.0, 33.2415
34.303355460, 23.970, 1114.0, 33.3766
34.346821220, 23.970, 1149.0, 33.8969
34.390286980, 23.970, 1120.0, 33.4664
34.433752740, 23.970, 1038.0, 32.2180
34.477218500, 23.970, 1049.0, 32.3883
34.520684260, 23.970, 1095.0, 33.0908
34.564150020, 23.970, 1086.0, 32.9545
34.607615780, 23.970, 1042.0, 32.2800
34.651081540, 23.970, 1020.0, 31.9374
34.694547300, 23.970, 1060.0, 32.5576
34.738013060, 23.970, 1073.0, 32.7567
34.781478820, 23.970, 1037.0, 32.2025
34.824944580, 23.970, 1063.0, 32.6037
34.868410340, 23.970, 1104.0, 33.2265
34.911876100, 23.970, 1160.0, 34.0588
34.955341860, 23.970, 1130.0, 33.6155
34.998807620, 23.970, 1110.0, 33.3167
35.042273380, 23.970, 1138.0, 33.7343
35.085739140, 23.970, 1121.0, 33.4813
35.129204900, 23.970, 1088.0, 32.9848
35.172670660, 23.970, 1109.0, 33.3017
35.216136420, 23.970, 1173.0, 34.2491
35.259602180, 23.970, 1202.0, 34.6699
35.303067940, 23.970, 1174.0, 34.2637
35.346533700, 23.970, 1235.0, 35.1426
35.389999460, 23.970, 1211.0, 34.7994
35.433465220, 23.970, 1295.0, 35.9861
35.476930980, 23.970, 1305.0, 36.1248
35.520396740, 23.970, 1340.0, 36.6060
35.563862500, 23.970, 1428.0, 37.7889
35.607328260, 23.970, 1320.0, 36.3318
35.650794020, 23.970, 1447.0, 38.0395
35.694259780, 23.970, 1490.0, 38.6005
35.737725540, 23.970, 1627.0, 40.3361
35.781191300, 23.970, 1711.0, 41.3642
35.824657060, 23.970, 1914.0, 43.7493
35.868122820, 23.970, 2049.0, 45.2659
35.911588580, 23.970, 2289.0, 47.8435
35.955054340, 23.970, 2398.0, 48.9694
35.998520100, 23.970, 2577.0, 50.7642
36.041985860, 23.970, 2869.0, 53.5630
36.085451620, 23.970, 3215.0, 56.7010
36.128917380, 23.970, 3479.0, 58.9830
36.172383140, 23.970, 3711.0, 60.9180
36.215848900, 23.970, 3946.0, 62.8172
36.259314660, 23.970, 4162.0, 64.5136
36.302780420, 23.970, 4343.0, 65.9014
36.346246180, 23.970, 4371.0, 66.1135
36.389711940, 23.970, 4437.0, 66.6108
36.433177700, 23.970, 4175.0, 64.6142
36.476643460, 23.970, 3904.0, 62.4820
36.520109220, 23.970, 3635.0, 60.2910
36.563574980, 23.970, 3302.0, 57.4630
36.607040740, 23.970, 2860.0, 53.4790
36.650506500, 23.970, 2405.0, 49.0408
36.693972260, 23.970, 2056.0, 45.3431
36.737438020, 23.970, 1972.0, 44.4072
36.780903780, 23.970, 1680.0, 40.9878
36.824369540, 23.970, 1639.0, 40.4846
36.867835300, 23.970, 1501.0, 38.7427
36.911301060, 23.970, 1395.0, 37.3497
36.954766820, 23.970, 1359.0, 36.8646
36.998232580, 23.970, 1278.0, 35.7491
37.041698340, 23.970, 1323.0, 36.3731
37.085164100, 23.970, 1307.0, 36.1525
37.128629860, 23.970, 1259.0, 35.4824
37.172095620, 23.970, 1219.0, 34.9142
37.215561380, 23.970, 1216.0, 34.8712
37.259027140, 23.970, 1205.0, 34.7131
37.302492900, 23.970, 1181.0, 34.3657
37.345958660, 23.970, 1244.0, 35.2704
37.389424420, 23.970, 1197.0, 34.5977
37.432890180, 23.970, 1169.0, 34.1906
37.476355940, 23.970, 1181.0, 34.3657
37.519821700, 23.970, 1163.0, 34.1028
37.563287460, 23.970, 1202.0, 34.6699
37.606753220, 23.970, 1216.0, 34.8712
37.650218980, 23.970, 1295.0, 35.9861
37.693684740, 23.970, 1198.0, 34.6121
37.737150500, 23.970, 1188.0, 34.4674
37.780616260, 23.970, 1174.0, 34.2637
37.824082020, 23.970, 1249.0, 35.3412
37.867547780, 23.970, 1240.0, 35.2136
37.911013540, 23.970, 1303.0, 36.0971
37.954479300, 23.970, 1297.0, 36.0139
37.997945060, 23.970, 1342.0, 36.6333
38.041410820, 23.970, 1372.0, 37.0405
38.084876580, 23.970, 1332.0, 36.4966
38.128342340, 23.970, 1446.0, 38.0263
38.171808100, 23.970, 1472.0, 38.3667
38.215273860, 23.970, 1433.0, 37.8550
38.258739620, 23.970, 1455.0, 38.1445
38.302205380, 23.970, 1444.0, 38.0000
38.345671140, 23.970, 1542.0, 39.2683
38.389136900, 23.970, 1520.0, 38.9872
38.432602660, 23.970, 1583.0, 39.7869
38.476068420, 23.970, 1573.0, 39.6611
38.519534180, 23.970, 1496.0, 38.6782
38.562999940, 23.970, 1514.0, 38.9102
38.606465700, 23.970, 1438.0, 37.9210
38.649931460, 23.970, 1397.0, 37.3765
38.693397220, 23.970, 1409.0, 37.5366
38.736862980, 23.970, 1355.0, 36.8103
38.780328740, 23.970, 1357.0, 36.8375
38.823794500, 23.970, 1425.0, 37.7492
38.867260260, 23.970, 1413.0, 37.5899
38.910726020, 23.970, 1547.0, 39.3319
38.954191780, 23.970, 1528.0, 39.0896
38.997657540, 23.970, 1470.0, 38.3406
39.041123300, 23.970, 1446.0, 38.0263
39.084589060, 23.970, 1321.0, 36.3456
39.128054820, 23.970, 1360.0, 36.8782
39.171520580, 23.970, 1448.0, 38.0526
39.214986340, 23.970, 1479.0, 38.4578
39.258452100, 23.970, 1529.0, 39.1024
39.301917860, 23.970, 1591.0, 39.8873
39.345383620, 23.970, 1698.0, 41.2068
39.388849380, 23.970, 1720.0, 41.4729
39.432315140, 23.970, 1908.0, 43.6807
39.475780900, 23.970, 1846.0, 42.9651
39.519246660, 23.970, 2059.0, 45.3762
39.562712420, 23.970, 2188.0, 46.7761
39.606178180, 23.970, 2254.0, 47.4763
39.649643940, 23.970, 2425.0, 49.2443
39.693109700, 23.970, 2514.0, 50.1398
39.736575460, 23.970, 2539.0, 50.3885
39.780041220, 23.970, 2502.0, 50.0200
39.823506980, 23.970, 2670.0, 51.6720
39.866972740, 23.970, 2590.0, 50.8920
39.910438500, 23.970, 2548.0, 50.4777
39.953904260, 23.970, 2431.0, 49.3052
39.997370020, 23.970, 2443.0, 49.4267
40.040835780, 23.970, 2354.0, 48.5180
40.084301540, 23.970, 2291.0, 47.8644
40.127767300, 23.970, 2025.0, 45.0000
40.171233060, 23.970, 2037.0, 45.1331
40.214698820, 23.970, 1979.0, 44.4860
40.258164580, 23.970, 1940.0, 44.0454
40.301630340, 23.970, 1858.0, 43.1045
40.345096100, 23.970, 1917.0, 43.7836
40.388561860, 23.970, 2003.0, 44.7549
40.432027620, 23.970, 1898.0, 43.5660
40.475493380, 23.970, 1922.0, 43.8406
40.518959140, 23.970, 2046.0, 45.2327
40.562424900, 23.970, 2100.0, 45.8258
40.605890660, 23.970, 2094.0, 45.7602
40.649356420, 23.970, 2041.0, 45.1774
40.692822180, 23.970, 2106.0, 45.8912
40.736287940, 23.970, 2142.0, 46.2817
40.779753700, 23.970, 2096.0, 45.7821
40.823219460, 23.970, 2099.0, 45.8148
40.866685220, 23.970, 2010.0, 44.8330
40.910150980, 23.970, 1957.0, 44.2380
40.953616740, 23.970, 1925.0, 43.8748
40.997082500, 23.970, 1822.0, 42.6849
41.040548260, 23.970, 1802.0, 42.4500
41.084014020, 23.970, 1822.0, 42.6849
41.127479780, 23.970, 1754.0, 41.8808
41.170945540, 23.970, 1677.0, 40.9512
41.214411300, 23.970, 1635.0, 40.4351
41.257877060, 23.970, 1725.0, 41.5331
41.301342820, 23.970, 1734.0, 41.6413
41.344808580, 23.970, 1794.0, 42.3556
41.388274340, 23.970, 1832.0, 42.8019
41.431740100, 23.970, 1881.0, 43.3705
41.475205860, 23.970, 1912.0, 43.7264
41.518671620, 23.970, 1970.0, 44.3847
41.562137380, 23.970, 1951.0, 44.1701
41.605603140, 23.970, 2162.0, 46.4973
41.649068900, 23.970, 2114.0, 45.9783
41.692534660, 23.970, 2064.0, 45.4313
41.736000420, 23.970, 2116.0, 46.0000
41.779466180, 23.970, 2130.0, 46.1519
41.822931940, 23.970, 2001.0, 44.7325
41.866397700, 23.970, 1947.0, 44.1248
41.909863460, 23.970, 1876.0, 43.3128
41.953329220, 23.970, 1897.0, 43.5546
41.996794980, 23.970, 1774.0, 42.1189
42.040260740, 23.970, 1639.0, 40.4846
42.083726500, 23.970, 1544.0, 39.2938
42.127192260, 23.970, 1584.0, 39.7995
42.170658020, 23.970, 1530.0, 39.1152
42.214123780, 23.970, 1483.0, 38.5097
42.257589540, 23.970, 1406.0, 37.4967
42.301055300, 23.970, 1437.0, 37.9078
42.344521060, 23.970, 1501.0, 38.7427
42.387986820, 23.970, 1528.0, 39.0896
42.431452580, 23.970, 1557.0, 39.4588
42.474918340, 23.970, 1582.0, 39.7744
42.518384100, 23.970, 1635.0, 40.4351
42.561849860, 23.970, 1732.0, 41.6173
42.605315620, 23.970, 1803.0, 42.4617
42.648781380, 23.970, 1982.0, 44.5197
42.692247140, 23.970, 2022.0, 44.9667
42.735712900, 23.970, 2017.0, 44.9110
42.779178660, 23.970, 2089.0, 45.7056
42.822644420, 23.970, 2080.0, 45.6070
42.866110180, 23.970, 1971.0, 44.3959
42.909575940, 23.970, 2148.0, 46.3465
42.953041700, 23.970, 2106.0, 45.8912
42.996507460, 23.970, 2209.0, 47.0000
43.039973220, 23.970, 2152.0, 46.3897
43.083438980, 23.970, 2231.0, 47.2335
43.126904740, 23.970, 2262.0, 47.5605
43.170370500, 23.970, 2076.0, 45.5631
43.213836260, 23.970, 2087.0, 45.6837
43.257302020, 23.970, 1972.0, 44.4072
43.300767780, 23.970, 1941.0, 44.0568
43.344233540, 23.970, 1828.0, 42.7551
43.387699300, 23.970, 1723.0, 41.5090
43.431165060, 23.970, 1706.0, 41.3038
43.474630820, 23.970, 1739.0, 41.7013
43.518096580, 23.970, 1632.0, 40.3980
43.561562340, 23.970, 1706.0, 41.3038
43.605028100, 23.970, 1718.0, 41.4488
43.648493860, 23.970, 1691.0, 41.1218
43.691959620, 23.970, 1661.0, 40.7554
43.735425380, 23.970, 1624.0, 40.2989
43.778891140, 23.970, 1738.0, 41.6893
43.822356900, 23.970, 1700.0, 41.2311
43.865822660, 23.970, 1734.0, 41.6413
43.909288420, 23.970, 1685.0, 41.0488
43.952754180, 23.970, 1770.0, 42.0714
43.996219940, 23.970, 1744.0, 41.7612
44.039685700, 23.970, 1716.0, 41.4246
44.083151460, 23.970, 1711.0, 41.3642
44.126617220, 23.970, 1728.0, 41.5692
44.170082980, 23.970, 1598.0, 39.9750
44.213548740, 23.970, 1585.0, 39.8121
44.257014500, 23.970, 1516.0, 38.9358
44.300480260, 23.970, 1351.0, 36.7560
44.343946020, 23.970, 1405.0, 37.4833
44.387411780, 23.970, 1285.0, 35.8469
44.430877540, 23.970, 1237.0, 35.1710
44.474343300, 23.970, 1200.0, 34.6410
44.517809060, 23.970, 1178.0, 34.3220
44.561274820, 23.970, 1150.0, 33.9116
44.604740580, 23.970, 1125.0, 33.5410
44.648206340, 23.970, 1131.0, 33.6303
44.691672100, 23.970, 1093.0, 33.0606
44.735137860, 23.970, 1100.0, 33.1662
44.778603620, 23.970, 1062.0, 32.5883
44.822069380, 23.970, 1033.0, 32.1403
44.865535140, 23.970, 1080.0, 32.8634
44.909000900, 23.970, 1080.0, 32.8634
44.952466660, 23.970, 1037.0, 32.2025
44.995932420, 23.970, 1136.0, 33.7046
45.039398180, 23.970, 1075.0, 32.7872
45.082863940, 23.970, 1076.0, 32.8024
45.126329700, 23.970, 1075.0, 32.7872
45.169795460, 23.970, 983.0, 31.3528
45.213261220, 23.970, 1041.0, 32.2645
45.256726980, 23.970, 1017.0, 31.8904
45.300192740, 23.970, 1099.0, 33.1512
45.343658500, 23.970, 1084.0, 32.9242
45.387124260, 23.970, 1106.0, 33.2566
45.430590020, 23.970, 1036.0, 32.1870
45.474055780, 23.970, 955.0, 30.9031
45.517521540, 23.970, 1033.0, 32.1403
45.560987300, 23.970, 1070.0, 32.7109
45.604453060, 23.970, 1039.0, 32.2335
45.647918820, 23.970, 1055.0, 32.4808
45.691384580, 23.970, 994.0, 31.5278
45.734850340, 23.970, 1041.0, 32.2645
45.778316100, 23.970, 1058.0, 32.5269
45.821781860, 23.970, 950.0, 30.8221
45.865247620, 23.970, 1075.0, 32.7872
45.908713380, 23.970, 986.0, 31.4006
45.952179140, 23.970, 1059.0, 32.5423
45.995644900, 23.970, 1046.0, 32.3419
46.039110660, 23.970, 1035.0, 32.1714
46.082576420, 23.970, 1060.0, 32.5576
46.126042180, 23.970, 1131.0, 33.6303
46.169507940, 23.970, 1080.0, 32.8634
46.212973700, 23.970, 1047.0, 32.3574
46.256439460, 23.970, 1128.0, 33.5857
46.299905220, 23.970, 1105.0, 33.2415
46.343370980, 23.970, 1107.0, 33.2716
46.386836740, 23.970, 1118.0, 33.4365
46.430302500, 23.970, 1139.0, 33.7491
46.473768260, 23.970, 1312.0, 36.2215
46.517234020, 23.970, 1237.0, 35.1710
46.560699780, 23.970, 1324.0, 36.3868
46.604165540, 23.970, 1418.0, 37.6563
46.647631300, 23.970, 1434.0, 37.8682
46.691097060, 23.970, 1482.0, 38.4968
46.734562820, 23.970, 1470.0, 38.3406
46.778028580, 23.970, 1573.0, 39.6611
46.821494340, 23.970, 1622.0, 40.2741
46.864960100, 23.970, 1684.0, 41.0366
46.908425860, 23.970, 1657.0, 40.7063
46.951891620, 23.970, 1796.0, 42.3792
46.995357380, 23.970, 1937.0, 44.0114
47.038823140, 23.970, 1999.0, 44.7102
47.082288900, 23.970, 1761.0, 41.9643
47.125754660, 23.970, 1831.0, 42.7902
47.169220420, 23.970, 1623.0, 40.2865
47.212686180, 23.970, 1550.0, 39.3700
47.256151940, 23.970, 1421.0, 37.6962
47.299617700, 23.970, 1315.0, 36.2629
47.343083460, 23.970, 1297.0, 36.0139
47.386549220, 23.970, 1236.0, 35.1568
47.430014980, 23.970, 1268.0, 35.6090
47.473480740, 23.970, 1126.0, 33.5559
47.516946500, 23.970, 1039.0, 32.2335
47.560412260, 23.970, 1090.0, 33.0151
47.603878020, 23.970, 1022.0, 31.9687
47.647343780, 23.970, 1079.0, 32.8481
47.690809540, 23.970, 990.0, 31.4643
47.734275300, 23.970, 1044.0, 32.3110
47.777741060, 23.970, 1054.0, 32.4654
47.821206820, 23.970, 1076.0, 32.8024
47.864672580, 23.970, 1073.0, 32.7567
47.908138340, 23.970, 1109.0, 33.3017
47.951604100, 23.970, 1146.0, 33.8526
47.995069860, 23.970, 1204.0, 34.6987
48.038535620, 23.970, 1286.0, 35.8608
48.082001380, 23.970, 1209.0, 34.7707
48.125467140, 23.970, 1268.0, 35.6090
48.168932900, 23.970, 1159.0, 34.0441
48.212398660, 23.970, 1067.0, 32.6650
48.255864420, 23.970, 1031.0, 32.1092
48.299330180, 23.970, 974.0, 31.2090
48.342795940, 23.970, 1002.0, 31.6544
48.386261700, 23.970, 1020.0, 31.9374
48.429727460, 23.970, 1000.0, 31.6228
48.473193220, 23.970, 1008.0, 31.7490
48.516658980, 23.970, 1013.0, 31.8277
48.560124740, 23.970, 957.0, 30.9354
48.603590500, 23.970, 938.0, 30.6268
48.647056260, 23.970, 1035.0, 32.1714
48.690522020, 23.970, 1000.0, 31.6228
48.733987780, 23.970, 1055.0, 32.4808
48.777453540, 23.970, 1050.0, 32.4037
48.820919300, 23.970, 1055.0, 32.4808
48.864385060, 23.970, 1053.0, 32.4500
48.907850820, 23.970, 1030.0, 32.0936
48.951316580, 23.970, 1094.0, 33.0757
48.994782340, 23.970, 991.0, 31.4802
49.038248100, 23.970, 1068.0, 32.6803
49.081713860, 23.970, 1024.0, 32.0000
49.125179620, 23.970, 1086.0, 32.9545
49.168645380, 23.970, 1001.0, 31.6386
49.212111140, 23.970, 1021.0, 31.9531
49.255576900, 23.970, 1043.0, 32.2955
49.299042660, 23.970, 958.0, 30.9516
49.342508420, 23.970, 1015.0, 31.8591
49.385974180, 23.970, 975.0, 31.2250
49.429439940, 23.970, 973.0, 31.1929
49.472905700, 23.970, 938.0, 30.6268
49.516371460, 23.970, 955.0, 30.9031
49.559837220, 23.970, 916.0, 30.2655
49.603302980, 23.970, 884.0, 29.7321
49.646768740, 23.970, 918.0, 30.2985
49.690234500, 23.970, 950.0, 30.8221
49.733700260, 23.970, 893.0, 29.8831
49.777166020, 23.970, 904.0, 30.0666
49.820631780, 23.970, 942.0, 30.6920
49.864097540, 23.970, 904.0, 30.0666
49.907563300, 23.970, 895.0, 29.9166
49.951029060, 23.970, 851.0, 29.1719
49.994494820, 23.970, 853.0, 29.2062